File: data/Raman/poly_smoothed/Thy_30_10_29_1x_45s_532 nm_x100_100%_600 gr_mm_01.txt
#Acq. time (s)=	45
#Accumulations=	2
#Range (cm-¹)=	200...3150
#Windows=	2
#Auto scanning=	Off
#Autofocus=	Off
#Macrospot=	Off
#AutoExposure=	Off
#Spike filter=	Multiple accum.
#Delay time (s)=	0
#Binning=	1
#Readout mode=	Signal
#DeNoise=	Off
#ICS correction=	On
#Dark correction=	Off
#Inst. Process=	Off
#Detector Gain=	Best Dynamic Range
#Detector ADC=	20 kHz
#Detector temperature (°C)=	-69.85
#Instrument=	LabRAM HR Evol
#Detector=	Synapse
#Objective=	x100
#Grating=	600 gr/mm
#ND Filter=	100%
#Laser (nm)=	532
#Hole=	100.021
#Range=	Auto
#Laser Pol.=	No
#Raman. Pol.=	No
#Laser Pol. (°)=	-0.0007625
#Raman Pol. (°)=	89.9995
#Collection=	Microscope
#StageXY=	Marzhauser
#StageZ=	Marzhauser
#X (µm)=	4758.7
#Y (µm)=	-7712.4
#Z (µm)=	584.4
#Full time(mm:ss)=	3:18
#Project=
#Sample=
#Site=
#Title=	Thy_30_10_29_2x_45s_532 nm_x100_100%_600 gr_mm
#Remark=
#Date=	30.06.2022 13:32
#Acquired=	30.06.2022 13:32:57
#Base:Fit=	10.08.2022 09:58:11
#Base:Sub=	10.08.2022 09:58:44
#Filter:Polynom=	16.08.2022 10:22:53
#AxisType[0]=Intens
#AxisUnit[0]=Cnt
#AxisType[1]=Spectr
#AxisUnit[1]=1/cm
200.533	32.0665
204.162	31.6351
207.792	29.6397
211.418	28.487
215.044	27.753
218.667	26.9392
222.289	24.3856
225.912	22.92
229.531	20.2989
233.148	16.1986
236.766	15.2716
240.381	13.9998
243.994	12.541
247.606	11.3011
251.217	9.38234
254.828	8.97269
258.436	8.57121
262.042	7.04415
265.647	6.47763
269.25	7.15909
272.852	7.04743
276.453	8.37726
280.052	8.26131
283.65	8.77812
287.247	10.059
290.842	11.1801
294.436	13.3726
298.028	16.0118
301.617	18.0161
305.206	18.9653
308.794	19.9627
312.381	20.9676
315.964	20.8491
319.548	21.0248
323.131	21.731
326.71	23.7015
330.29	23.1634
333.868	22.0411
337.443	21.6551
341.018	21.273
344.591	21.189
348.163	19.3774
351.733	17.6755
355.303	15.0272
358.869	12.9567
362.435	11.9747
366.001	10.0064
369.563	8.97328
373.124	7.95975
376.686	6.40714
380.244	6.96546
383.801	7.99846
387.357	7.50376
390.911	8.00345
394.466	8.15233
398.018	9.06675
401.568	9.18951
405.117	9.34298
408.664	9.50309
412.21	11.7905
415.755	12.3559
419.298	10.859
422.84	12.189
426.38	12.2635
429.919	12.6799
433.455	11.2095
436.992	10.6625
440.527	9.75708
444.06	7.82294
447.593	7.46833
451.122	7.21316
454.651	7.02051
458.18	7.54321
461.705	6.74884
465.23	6.93072
468.752	6.92225
472.275	7.60173
475.797	6.70173
479.315	7.78833
482.834	9.01795
486.349	10.8453
489.863	11.975
493.378	14.2006
496.889	15.4409
500.401	17.7877
503.91	18.6848
507.417	20.0064
510.923	20.7808
514.43	20.86
517.933	21.6067
521.435	20.3737
524.936	20.6046
528.435	19.7431
531.933	18.6393
535.43	19.3382
538.927	18.5828
542.421	17.2819
545.913	15.8646
549.403	12.7813
552.893	11.9712
556.381	10.5361
559.868	8.54575
563.354	8.04405
566.839	7.51097
570.322	6.64081
573.802	5.3731
577.283	4.12659
580.762	3.41967
584.24	3.10208
587.714	3.46176
591.19	2.62204
594.663	1.09275
598.134	0.695975
601.605	0.0878779
605.073	0.0844952
608.542	0.492164
612.007	0.792732
615.473	1.7291
618.936	2.98097
622.397	5.19102
625.859	6.262
629.318	6.08535
632.775	5.74825
636.233	7.62776
639.688	9.3134
643.142	11.3029
646.594	12.0684
650.045	14.013
653.496	15.286
656.944	16.4799
660.391	18.4557
663.837	20.2763
667.281	20.8443
670.724	22.7897
674.166	24.188
677.606	25.5951
681.045	26.5575
684.483	28.1077
687.917	29.2755
691.352	30.5314
694.786	32.4194
698.219	34.6747
701.65	36.4977
705.078	37.1662
708.506	38.6112
711.934	37.7465
715.358	37.9477
718.782	39.8579
722.204	41.1791
725.626	43.3751
729.045	44.6273
732.464	45.7677
735.881	47.8747
739.297	49.0767
742.711	49.5715
746.125	50.8167
749.537	51.7034
752.946	53.6166
756.357	55.3375
759.764	56.8103
763.17	57.1982
766.575	58.293
769.978	60.0497
773.382	60.3357
776.783	62.7104
780.182	65.694
783.581	66.4132
786.978	67.2869
790.373	69.8992
793.768	72.2001
797.161	74.2698
800.552	76.5721
803.941	79.2641
807.33	80.7442
810.718	82.3831
814.105	83.884
817.49	86.6564
820.873	85.5997
824.256	85.9846
827.637	86.7335
831.016	87.7874
834.395	86.8041
837.772	85.137
841.147	82.9762
844.522	80.4125
847.894	78.1191
851.267	75.0964
854.637	71.4833
858.007	69.5709
861.374	68.0418
864.739	65.7784
868.106	63.8227
871.469	62.3329
874.831	62.1045
878.193	60.997
881.553	59.6207
884.911	60.5773
888.268	59.5522
891.623	58.2941
894.978	58.8444
898.331	59.3358
901.683	60.2183
905.033	60.8296
908.383	60.7432
911.731	60.5497
915.078	60.226
918.423	59.1975
921.768	58.4074
925.111	59.0009
928.452	58.2009
931.791	57.1609
935.13	55.0243
938.468	53.5977
941.803	51.1335
945.139	49.8787
948.473	48.2119
951.804	49.2692
955.136	49.7713
958.465	50.6728
961.794	49.5498
965.12	50.8276
968.447	51.8009
971.771	51.8417
975.095	52.4163
978.417	53.924
981.737	54.6162
985.057	54.2652
988.375	53.9055
991.691	53.3818
995.006	51.1261
998.32	49.6798
1001.63	48.2643
1004.95	47.0619
1008.26	46.5315
1011.56	45.1824
1014.87	43.2068
1018.18	41.5175
1021.48	40.2558
1024.79	40.4531
1028.09	39.2858
1031.39	39.9822
1034.69	39.4416
1037.99	37.0593
1041.29	36.2751
1044.58	35.1244
1047.88	34.1111
1051.17	34.1701
1054.46	33.7284
1057.75	32.8863
1061.04	31.2182
1064.33	31.356
1067.62	29.9508
1070.9	29.457
1074.19	27.6839
1077.47	25.84
1080.76	25.6935
1084.04	27.1194
1087.32	28.0528
1090.59	27.6757
1093.87	28.7133
1097.15	29.8368
1100.42	30.5456
1103.69	30.5508
1106.97	29.8891
1110.24	29.1793
1113.51	28.0299
1116.77	26.3998
1120.04	26.1528
1123.31	24.1759
1126.57	24.4254
1129.83	23.9767
1133.1	24.1177
1136.36	23.3976
1139.62	22.5937
1142.87	22.7123
1146.13	21.6688
1149.38	20.2378
1152.64	18.4045
1155.89	15.3079
1159.14	13.1505
1162.39	11.6717
1165.64	11.1678
1168.89	10.2368
1172.14	10.471
1175.38	10.3059
1178.63	9.72685
1181.87	8.421
1185.11	8.52106
1188.35	8.81395
1191.59	8.98019
1194.83	10.2492
1198.07	12.3957
1201.3	13.3038
1204.53	16.1411
1207.77	19.5245
1211	22.5651
1214.23	26.1032
1217.46	30.0546
1220.69	33.768
1223.91	38.2554
1227.14	41.5565
1230.36	45.0204
1233.59	48.5592
1236.81	50.9212
1240.03	53.8827
1243.25	56.312
1246.46	59.8761
1249.68	61.8957
1252.9	62.9531
1256.11	63.812
1259.32	64.6202
1262.54	65.7774
1265.75	67.0165
1268.96	66.6933
1272.16	67.1176
1275.37	66.7972
1278.57	67.2714
1281.78	66.8193
1284.98	67.1646
1288.18	65.653
1291.38	66.9747
1294.58	66.158
1297.78	65.8414
1300.98	66.5119
1304.17	67.5128
1307.37	67.0447
1310.56	67.6717
1313.76	66.6645
1316.95	66.1709
1320.14	64.6999
1323.32	63.5517
1326.51	63.6715
1329.7	61.3011
1332.88	59.5632
1336.07	58.0186
1339.25	55.8468
1342.43	54.2363
1345.61	51.8765
1348.79	49.8434
1351.96	48.3786
1355.14	45.5194
1358.31	43.09
1361.49	41.5047
1364.66	38.9879
1367.83	35.4573
1371	33.1017
1374.17	30.5175
1377.34	28.7599
1380.5	27.3536
1383.67	27.9301
1386.83	27.3595
1390	26.0029
1393.16	23.7898
1396.32	22.2969
1399.48	22.291
1402.64	21.8577
1405.79	20.5625
1408.95	21.4688
1412.1	22.286
1415.26	26.2388
1418.41	30.095
1421.56	34.368
1424.71	38.8542
1427.86	45.0352
1431	51.1972
1434.15	57.6231
1437.29	62.7597
1440.44	65.8156
1443.58	68.3826
1446.72	71.6026
1449.86	73.358
1453	73.2289
1456.14	73.2942
1459.27	72.0438
1462.41	69.1421
1465.54	63.728
1468.67	56.2518
1471.81	51.3708
1474.94	45.0268
1478.07	38.5929
1481.19	31.372
1484.32	25.96
1487.45	21.8582
1490.57	18.9632
1493.69	15.8402
1496.82	12.9897
1499.94	10.5594
1503.06	8.78889
1506.17	8.31935
1509.29	9.40743
1512.41	8.38684
1515.52	8.76107
1518.64	9.75143
1521.75	11.4523
1524.86	11.5119
1527.97	11.5132
1531.08	11.3925
1534.19	13.3744
1537.29	13.8554
1540.4	14.7749
1543.5	16.3411
1546.61	18.5199
1549.71	20.538
1552.81	21.1389
1555.91	23.1886
1559.01	23.8517
1562.11	26.4368
1565.2	28.1442
1568.29	30.5488
1571.39	32.1116
1574.48	33.8871
1577.57	36.2504
1580.66	38.4888
1583.75	41.1494
1586.84	42.9386
1589.93	44.0974
1593.01	44.9161
1596.1	45.1951
1599.18	44.7902
1602.26	44.8451
1605.34	45.189
1608.42	44.6322
1611.5	45.2344
1614.58	47.1313
1617.65	47.3128
1620.73	49.137
1623.8	50.2365
1626.87	51.5661
1629.95	54.169
1633.02	55.7111
1636.09	59.3176
1639.15	62.8162
1642.22	66.5381
1645.29	71.2297
1648.35	74.123
1651.42	75.8479
1654.48	77.3516
1657.54	78.0532
1660.6	77.5327
1663.66	77.0925
1666.72	74.904
1669.77	71.3135
1672.83	67.1402
1675.88	62.7686
1678.93	57.2483
1681.99	51.5832
1685.04	46.791
1688.09	42.205
1691.13	37.7742
1694.18	31.361
1697.23	26.2465
1700.27	21.0836
1703.32	17.2805
1706.36	14.1183
1709.4	11.5311
1712.44	9.81516
1715.48	8.27887
1718.52	7.33205
1721.56	5.32854
1724.59	4.20222
1727.63	2.84362
1730.66	3.17542
1733.69	2.11296
1736.72	2.13405
1739.75	1.93149
1742.78	1.72823
1745.81	1.5128
1748.84	2.06777
1751.86	1.4759
1754.89	1.78704
1757.91	1.93033
1760.93	2.31934
1763.95	2.21378
1766.97	2.17286
1769.99	0.996128
1773.01	0.199093
1776.03	0.0513972
1779.04	0.925721
1782.06	1.29091
1785.07	0.211914
1788.08	-0.0247322
1791.09	-0.144888
1794.1	-0.495498
1797.11	-0.660759
1800.12	-0.770258
1803.12	-0.912311
1806.13	-0.122497
1809.13	-0.319562
1812.14	-5.49834e-005
1815.14	0.53349
1818.14	0.579205
1821.14	0.945929
1824.14	1.20978
1827.13	1.18522
1830.13	1.63345
1833.12	1.93218
1836.12	2.2212
1839.11	2.93348
1842.1	2.74383
1845.09	2.3745
1848.08	2.32925
1851.07	2.99861
1854.06	2.98727
1857.04	2.62921
1860.03	2.60797
1863.01	3.02834
1866	3.91135
1868.98	3.99219
1871.96	5.2715
1874.94	5.81604
1877.92	6.16928
1880.89	5.7451
1882.48	5.62825
1885.47	5.3797
1888.46	5.11005
1891.44	5.66588
1894.43	5.47852
1897.41	5.49115
1900.4	5.52846
1903.38	5.18956
1906.36	4.8704
1909.34	4.84614
1912.32	5.27067
1915.29	4.24953
1918.27	4.13698
1921.25	4.65468
1924.22	4.29802
1927.2	4.81989
1930.17	5.25709
1933.14	5.34733
1936.11	5.89045
1939.08	5.63544
1942.05	6.76657
1945.01	7.64257
1947.98	8.02529
1950.94	8.52777
1953.91	8.21702
1956.87	8.5216
1959.83	8.92644
1962.79	8.95172
1965.75	9.32168
1968.71	9.16813
1971.67	9.84933
1974.62	9.22705
1977.58	8.69975
1980.53	9.61974
1983.48	9.27217
1986.43	9.52594
1989.38	9.30217
1992.33	9.70273
1995.28	10.1252
1998.23	9.40214
2001.18	8.78647
2004.12	8.69229
2007.06	8.67719
2010.01	8.8549
2012.95	9.46945
2015.89	9.82704
2018.83	9.55401
2021.77	8.51775
2024.71	8.0308
2027.64	6.7372
2030.58	6.9769
2033.51	7.65026
2036.45	7.88108
2039.38	8.99299
2042.31	9.23483
2045.24	10.7097
2048.17	11.1684
2051.1	11.9878
2054.02	12.2067
2056.95	12.6795
2059.87	13.6757
2062.8	14.7138
2065.72	16.045
2068.64	17.0345
2071.56	17.9909
2074.48	19.648
2077.4	20.7344
2080.31	21.5807
2083.23	22.3715
2086.14	22.5963
2089.06	22.307
2091.97	22.9293
2094.88	23.7721
2097.79	24.6298
2100.7	25.0057
2103.61	26.8169
2106.52	28.3766
2109.43	30.2547
2112.33	33.1122
2115.24	35.185
2118.14	37.0525
2121.04	38.9045
2123.94	41.5129
2126.84	44.2402
2129.74	47.2194
2132.64	51.4514
2135.54	55.172
2138.43	58.299
2141.33	62.0161
2144.22	65.7837
2147.11	67.9539
2150.01	69.676
2152.9	72.2118
2155.79	74.4629
2158.67	76.5135
2161.56	78.7671
2164.45	80.0154
2167.33	81.2265
2170.22	81.7589
2173.1	82.0137
2175.98	82.4792
2178.86	81.8162
2181.74	80.4761
2184.62	79.7533
2187.5	77.282
2190.38	74.2498
2193.25	72.2253
2196.13	69.7188
2199	67.0633
2201.88	64.5984
2204.75	61.2487
2207.62	57.8387
2210.49	54.1346
2213.36	51.6678
2216.22	48.3131
2219.09	45.5332
2221.96	43.2748
2224.82	41.6093
2227.68	39.8966
2230.55	38.3015
2233.41	36.3987
2236.27	35.3791
2239.12	34.4604
2241.98	32.9388
2244.84	31.8464
2247.7	30.9653
2250.55	29.4127
2253.41	28.9177
2256.26	28.4616
2259.11	26.8264
2261.96	25.5296
2264.81	24.0156
2267.66	22.9082
2270.51	21.3028
2273.35	19.9492
2276.2	19.4649
2279.04	18.8499
2281.89	17.9225
2284.73	17.4026
2287.57	16.2782
2290.41	15.3586
2293.25	14.9775
2296.09	15.2251
2298.93	15.3239
2301.76	15.6914
2304.6	16.5735
2307.44	17.3124
2310.27	17.7736
2313.1	18.7562
2315.93	18.4101
2318.76	19.5866
2321.59	20.0845
2324.42	20.4073
2327.25	19.87
2330.07	18.6104
2332.9	18.3518
2335.72	16.8866
2338.55	16.4969
2341.37	15.0241
2344.19	14.8505
2347.01	14.268
2349.83	13.0197
2352.65	10.8694
2355.46	10.058
2358.28	8.86486
2361.09	8.7368
2363.91	8.90839
2366.72	8.50227
2369.53	7.25513
2372.34	7.41366
2375.15	6.82055
2377.96	6.74261
2380.77	6.52915
2383.58	7.08668
2386.38	6.88161
2389.19	6.3462
2391.99	6.77642
2394.8	6.37733
2397.6	5.89009
2400.4	6.04836
2403.2	4.97951
2406	5.32243
2408.79	5.15339
2411.59	5.86861
2414.39	6.01305
2417.18	5.37512
2419.98	5.52747
2422.77	5.91265
2425.56	6.09511
2428.35	5.69255
2431.14	5.686
2433.93	4.10882
2436.72	3.64862
2439.5	3.51038
2442.29	4.19448
2445.07	4.17683
2447.86	3.82595
2450.64	4.51833
2453.42	4.36486
2456.2	4.16624
2458.98	4.237
2461.76	4.55467
2464.54	3.67023
2467.32	3.93939
2470.09	4.5762
2472.87	4.48931
2475.64	4.6148
2478.41	5.01574
2481.18	5.62767
2483.95	5.36474
2486.72	5.00414
2489.49	5.16162
2492.26	4.44724
2495.03	2.97114
2497.79	1.22311
2500.56	0.557968
2503.32	-0.355064
2506.09	-0.258683
2508.85	-0.259685
2511.61	-0.173784
2514.37	-0.676232
2517.13	-1.10565
2519.89	-0.785362
2522.64	-0.220409
2525.4	-0.554238
2528.15	0.610594
2530.91	1.30621
2533.66	2.40466
2536.41	2.66569
2539.16	2.65953
2541.91	2.96034
2544.66	3.596
2547.41	3.05717
2550.16	2.93112
2552.9	3.05743
2555.65	2.60662
2558.39	2.19274
2561.13	2.4773
2563.88	2.4231
2566.62	2.49036
2569.36	3.02554
2572.1	4.00717
2574.84	4.39967
2577.57	4.01615
2580.31	4.13531
2583.05	4.09752
2585.78	4.14414
2588.51	4.38816
2591.24	4.42622
2593.98	5.21889
2596.71	5.52874
2599.44	4.83332
2602.16	4.12637
2604.89	3.79108
2607.62	3.19232
2610.34	3.13941
2613.07	2.32324
2615.79	1.77837
2618.52	1.64746
2621.24	1.18857
2623.96	1.6163
2626.68	2.70681
2629.4	2.37243
2632.11	2.71839
2634.83	2.21975
2637.55	2.13718
2640.26	2.41597
2642.98	1.65773
2645.69	1.42543
2648.4	1.18148
2651.11	0.248523
2653.82	0.018533
2656.53	0.0908748
2659.24	0.652937
2661.95	1.15542
2664.65	0.936052
2667.36	2.16179
2670.06	1.8963
2672.76	1.82261
2675.47	1.02314
2678.17	1.53129
2680.87	1.05174
2683.57	1.69079
2686.27	2.77844
2688.97	3.22446
2691.66	3.89725
2694.36	4.42163
2697.05	4.77399
2699.75	4.87934
2702.44	5.93618
2705.13	7.35051
2707.82	7.70105
2710.51	9.17595
2713.2	8.94714
2715.89	9.69447
2718.57	10.2403
2721.26	11.3518
2723.95	11.5536
2726.63	12.0648
2729.31	11.7024
2732	11.7877
2734.68	10.62
2737.36	9.47717
2740.04	8.85187
2742.72	8.65871
2745.39	8.35606
2748.07	7.95849
2750.75	7.3027
2753.42	6.1063
2756.09	5.51559
2758.77	5.25707
2761.44	5.45122
2764.11	4.36363
2766.78	4.40644
2769.45	4.70858
2772.12	4.77936
2774.78	4.17638
2777.45	3.66772
2780.12	3.79296
2782.78	3.09411
2785.44	3.21786
2788.11	2.33888
2790.77	2.39054
2793.43	2.32087
2796.09	2.61724
2798.75	2.66743
2801.4	2.79196
2804.06	3.07685
2806.72	3.85752
2809.37	3.93819
2812.03	3.96746
2814.68	3.87707
2817.33	4.03282
2819.98	5.14469
2822.63	7.27177
2825.28	10.3369
2827.93	14.0457
2830.58	18.4536
2833.23	22.2104
2835.87	26.6135
2838.52	31.6369
2841.16	37.8038
2843.8	44.6645
2846.44	51.6871
2849.08	59.4146
2851.73	68.1735
2854.36	76.7964
2857	86.2228
2859.64	94.6236
2862.28	102.892
2864.91	110.446
2867.55	118.719
2870.18	125.166
2872.81	130.44
2875.44	135.376
2878.07	139.427
2880.7	143.496
2883.33	148.182
2885.96	152.151
2888.59	157.146
2891.21	161.493
2893.84	166.065
2896.46	170.264
2899.09	176.578
2901.71	183.59
2904.33	192.156
2906.95	202.335
2909.57	212.881
2912.19	223.261
2914.81	235.163
2917.43	245.874
2920.04	255.452
2922.66	263.038
2925.27	269.938
2927.88	274.828
2930.5	277.303
2933.11	278.014
2935.72	275.884
2938.33	273.116
2940.94	267.414
2943.54	260.283
2946.15	252.336
2948.76	242.663
2951.36	231.773
2953.97	221.496
2956.57	210.459
2959.17	200.281
2961.77	190.201
2964.37	181.876
2966.97	173.106
2969.57	166.354
2972.17	159.13
2974.77	151.013
2977.36	142.835
2979.96	135.196
2982.55	126.475
2985.15	118.408
2987.74	110.753
2990.33	102.069
2992.92	93.4511
2995.51	86.1688
2998.1	78.5379
3000.69	70.9395
3003.27	63.7329
3005.86	55.976
3008.44	49.6223
3011.03	44.314
3013.61	38.4192
3016.19	34.3904
3018.78	30.218
3021.36	27.6113
3023.94	25.4411
3026.51	23.1491
3029.09	22.0894
3031.67	21.5263
3034.24	21.3072
3036.82	20.2622
3039.39	21.504
3041.97	21.6318
3044.54	21.9846
3047.11	23.1989
3049.68	24.6361
3052.25	24.8571
3054.82	24.9409
3057.39	25.075
3059.96	25.0138
3062.52	24.1172
3065.09	23.394
3067.65	22.5277
3070.22	21.4224
3072.78	20.7
3075.34	18.632
3077.9	16.3122
3080.46	14.6262
3083.02	12.741
3085.58	11.3729
3088.14	9.2129
3090.69	8.01573
3093.25	6.46555
3095.8	5.18936
3098.36	4.38828
3100.91	3.64328
3103.46	2.39232
3106.01	1.18737
3108.56	0.97786
3111.11	0.582425
3113.66	0.646585
3116.21	-0.126114
3118.76	-0.395888
3121.3	-0.457901
3123.85	-0.13791
3126.39	-0.0649632
3128.93	0.774693
3131.48	0.469175
3134.02	0.991612
3136.56	0.599301
3139.1	0.762437
3141.64	0.910752
3144.17	0.546174
3146.71	-0.0126519
3149.25	-1.55969