File: data/Raman/poly_smoothed/Thy_50_12_42_1x_45s_532 nm_x100_100%_600 gr_mm_01.txt
#Acq. time (s)=	45
#Accumulations=	2
#Range (cm-¹)=	200...3150
#Windows=	2
#Auto scanning=	Off
#Autofocus=	Off
#Macrospot=	Off
#AutoExposure=	Off
#Spike filter=	Multiple accum.
#Delay time (s)=	0
#Binning=	1
#Readout mode=	Signal
#DeNoise=	Off
#ICS correction=	On
#Dark correction=	Off
#Inst. Process=	Off
#Detector Gain=	Best Dynamic Range
#Detector ADC=	20 kHz
#Detector temperature (°C)=	-69.85
#Instrument=	LabRAM HR Evol
#Detector=	Synapse
#Objective=	x100
#Grating=	600 gr/mm
#ND Filter=	100%
#Laser (nm)=	532
#Hole=	100.021
#Range=	Auto
#Laser Pol.=	No
#Raman. Pol.=	No
#Laser Pol. (°)=	-0.0007625
#Raman Pol. (°)=	89.9995
#Collection=	Microscope
#StageXY=	Marzhauser
#StageZ=	Marzhauser
#X (µm)=	-5121.8
#Y (µm)=	1515.8
#Z (µm)=	63.25
#Full time(mm:ss)=	3:18
#Project=
#Sample=
#Site=
#Title=	Thy_50_12_42_2x_45s_532 nm_x100_100%_600 gr_mm
#Remark=
#Date=	07.07.2022 12:20
#Acquired=	07.07.2022 12:20:12
#Base:Fit=	10.08.2022 10:04:30
#Base:Sub=	10.08.2022 10:04:45
#Filter:Polynom=	16.08.2022 10:20:25
#AxisType[0]=Intens
#AxisUnit[0]=Cnt
#AxisType[1]=Spectr
#AxisUnit[1]=1/cm
200.43	0.0521175
204.061	3.33429
207.688	5.63283
211.316	6.25199
214.941	6.62274
218.566	7.12447
222.188	6.8187
225.809	5.98886
229.43	5.70466
233.047	5.39854
236.663	6.09802
240.278	5.64636
243.894	4.99381
247.506	4.05071
251.116	2.92032
254.725	2.1601
258.333	2.14907
261.939	2.42668
265.546	3.37104
269.15	0.592122
272.752	0.0288383
276.353	1.84615
279.952	2.059
283.55	2.62277
287.146	3.12351
290.739	4.13995
294.333	4.81032
297.925	6.56852
301.516	8.62505
305.106	10.2003
308.694	11.1622
312.279	10.8509
315.864	10.0482
319.448	11.3804
323.029	12.7053
326.61	13.298
330.19	13.3109
333.766	13.3737
337.343	13.6769
340.917	12.819
344.491	12.6972
348.062	12.2619
351.633	12.88
355.201	10.286
358.77	10.6626
362.335	11.9143
365.899	11.0725
369.464	9.47082
373.025	10.8559
376.585	10.6735
380.143	12.0772
383.702	12.6208
387.258	12.6879
390.812	11.8575
394.365	11.0737
397.916	10.9353
401.467	10.242
405.015	10.0711
408.565	10.5926
412.111	10.8478
415.656	11.4376
419.197	9.74982
422.739	7.20799
426.279	6.42694
429.819	5.92723
433.356	4.98289
436.893	4.15013
440.428	4.35397
443.96	4.66772
447.492	4.65232
451.023	4.18852
454.553	3.8659
458.079	5.4006
461.606	7.2793
465.132	8.91463
468.654	11.1844
472.177	12.1326
475.696	15.4532
479.217	18.5059
482.733	21.1809
486.251	24.432
489.765	25.2323
493.278	27.4595
496.791	29.3657
500.301	30.9002
503.81	30.6307
507.319	29.3356
510.825	30.6959
514.33	30.3825
517.833	31.908
521.337	32.512
524.838	32.5869
528.337	32.7825
531.835	30.7819
535.332	27.4312
538.827	24.5346
542.321	23.6782
545.814	22.266
549.305	19.7765
552.795	19.2245
556.284	17.3468
559.771	16.9763
563.257	16.0758
566.742	14.4543
570.223	13.6509
573.705	11.2812
577.185	9.68163
580.665	9.01951
584.141	7.76386
587.617	7.74764
591.092	7.0031
594.564	6.85294
598.037	7.46149
601.506	8.97436
604.976	10.4718
608.443	11.6496
611.91	13.3456
615.374	13.5535
618.839	13.5174
622.3	15.0108
625.761	15.2332
629.221	17.2929
632.679	17.9545
636.135	19.695
639.592	22.1379
643.045	23.3013
646.497	25.0315
649.948	27.0321
653.398	28.0757
656.846	28.6466
660.293	30.4918
663.738	31.9752
667.185	32.5691
670.628	33.3432
674.067	33.5759
677.508	33.5786
680.947	34.7864
684.385	36.0905
687.821	37.7222
691.256	40.5182
694.69	39.8288
698.121	39.0959
701.552	39.7883
704.982	40.2242
708.41	39.3092
711.836	39.8531
715.262	41.7055
718.685	41.0048
722.108	43.3368
725.53	43.6198
728.949	44.5145
732.369	45.6933
735.785	46.4885
739.2	48.8371
742.616	51.8027
746.028	53.7992
749.441	56.7978
752.851	58.5782
756.26	61.1219
759.667	62.3444
763.075	65.5215
766.479	68.983
769.883	72.5519
773.285	72.9871
776.686	73.2262
780.085	74.5106
783.484	74.7952
786.881	75.074
790.276	73.6118
793.671	73.0786
797.064	76.5622
800.456	76.0593
803.846	76.4172
807.236	76.8559
810.624	75.844
814.01	75.6584
817.394	77.0998
820.778	79.6567
824.161	80.8493
827.543	81.8737
830.921	80.5482
834.3	78.0631
837.676	75.2266
841.053	73.7172
844.426	72.6596
847.8	71.2408
851.171	70.7587
854.542	66.8989
857.911	64.2309
861.279	63.1557
864.645	59.678
868.01	56.3834
871.375	54.0378
874.737	52.1716
878.097	52.393
881.457	50.7442
884.817	48.9111
888.174	48.9766
891.53	47.7321
894.884	48.5532
898.237	48.4962
901.589	48.3735
904.94	46.4094
908.289	42.5232
911.637	39.6845
914.984	36.5325
918.33	34.4613
921.674	33.3058
925.015	31.7015
928.357	30.022
931.698	28.8113
935.037	26.6146
938.373	26.3538
941.71	25.707
945.046	22.5253
948.378	20.7457
951.711	19.2921
955.043	19.6409
958.372	19.8401
961.701	20.8448
965.027	23.9043
968.354	26.9617
971.678	28.6415
975	29.5439
978.324	30.6321
981.644	30.8654
984.962	31.5892
988.282	30.0878
991.598	30.8846
994.913	32.0046
998.227	30.3851
1001.54	28.6342
1004.85	28.5971
1008.16	29.6162
1011.47	28.8626
1014.78	29.424
1018.08	30.6845
1021.39	31.3591
1024.69	30.4369
1028	31.627
1031.3	32.7526
1034.6	34.5422
1037.9	35.7916
1041.19	36.6193
1044.49	37.8399
1047.79	38.39
1051.08	36.6596
1054.37	32.9019
1057.66	30.7004
1060.95	28.3471
1064.24	26.7941
1067.53	23.9554
1070.81	22.0658
1074.1	19.7864
1077.38	17.9146
1080.66	13.9438
1083.94	14.1555
1087.22	14.9064
1090.5	16.4042
1093.78	16.8849
1097.05	16.9987
1100.33	18.9178
1103.6	20.4995
1106.87	20.1069
1110.15	21.0597
1113.41	21.1679
1116.68	21.1629
1119.95	19.3473
1123.21	18.6151
1126.48	16.2064
1129.74	14.3246
1133	11.8007
1136.26	9.55463
1139.52	8.85624
1142.78	7.67091
1146.04	5.21391
1149.29	3.75602
1152.55	1.2698
1155.8	-0.019898
1159.05	0.269907
1162.3	-1.04954
1165.55	-0.180746
1168.8	-0.697494
1172.05	-1.05146
1175.29	-2.20858
1178.54	-1.32755
1181.78	-0.433256
1185.02	-0.800996
1188.26	-0.497495
1191.5	0.557551
1194.74	1.8947
1197.97	3.83808
1201.21	6.46241
1204.44	8.50965
1207.68	11.3289
1210.91	14.1577
1214.14	16.12
1217.37	20.1767
1220.6	24.6469
1223.82	27.1681
1227.05	30.6524
1230.27	34.7266
1233.49	38.229
1236.72	41.6233
1239.94	46.1803
1243.16	50.4261
1246.37	53.4949
1249.59	55.4816
1252.8	57.9896
1256.02	62.2229
1259.23	63.1422
1262.44	65.2789
1265.66	67.2828
1268.87	69.539
1272.07	73.7695
1275.28	75.8397
1278.48	78.1692
1281.69	79.8398
1284.89	80.7036
1288.09	81.7526
1291.3	82.3266
1294.49	83.347
1297.69	83.6892
1300.89	83.0037
1304.09	84.1443
1307.28	83.946
1310.47	84.6882
1313.66	86.2289
1316.86	87.1063
1320.05	86.4432
1323.23	84.8489
1326.42	82.1478
1329.61	79.3182
1332.79	76.3182
1335.98	73.1395
1339.16	70.3952
1342.34	68.0413
1345.52	65.385
1348.7	63.1853
1351.87	60.5712
1355.05	58.8499
1358.23	56.3178
1361.4	52.2859
1364.57	50.1497
1367.74	47.9446
1370.91	46.5181
1374.08	44.6619
1377.25	43.5498
1380.42	43.3708
1383.58	43.3265
1386.75	43.3903
1389.91	42.5978
1393.07	42.2843
1396.23	42.6192
1399.39	42.1794
1402.55	42.3419
1405.7	44.612
1408.86	46.37
1412.01	49.9385
1415.17	52.9395
1418.32	57.423
1421.47	62.0712
1424.62	68.3003
1427.77	73.8453
1430.92	81.2337
1434.06	87.1351
1437.2	91.4496
1440.35	95.5474
1443.49	99.3588
1446.63	99.0681
1449.77	99.7969
1452.91	98.3541
1456.05	96.0139
1459.18	91.7603
1462.32	86.6532
1465.45	81.2497
1468.59	72.9148
1471.72	65.9224
1474.85	60.0028
1477.98	52.5416
1481.11	45.4668
1484.23	39.1554
1487.36	34.205
1490.48	28.8002
1493.61	25.5356
1496.73	24.151
1499.85	22.0213
1502.97	23.6718
1506.09	24.4548
1509.2	24.798
1512.32	25.5849
1515.44	26.6252
1518.55	28.6991
1521.66	31.2281
1524.77	34.1525
1527.88	36.2134
1530.99	38.2572
1534.1	40.3747
1537.21	43.213
1540.31	47.7572
1543.42	51.3163
1546.52	55.2588
1549.62	59.3394
1552.72	63.4665
1555.82	67.8523
1558.92	70.73
1562.02	73.4822
1565.11	77.1114
1568.21	80.1737
1571.3	84.7815
1574.39	89.5694
1577.49	92.3866
1580.58	93.5616
1583.67	95.2885
1586.75	97.7331
1589.84	98.123
1592.93	97.97
1596.01	97.917
1599.09	96.7738
1602.18	92.8418
1605.26	90.9361
1608.34	89.0916
1611.41	89.5194
1614.49	89.7976
1617.57	89.9793
1620.64	90.4092
1623.72	91.741
1626.79	92.8553
1629.86	94.7574
1632.93	95.45
1636	97.3107
1639.07	100.152
1642.14	103.741
1645.2	106.613
1648.27	109.169
1651.33	109.911
1654.39	110.812
1657.45	111.193
1660.51	110.997
1663.57	108.73
1666.63	105.403
1669.69	101.188
1672.74	95.6568
1675.79	89.1288
1678.85	81.8609
1681.9	74.4926
1684.95	68.562
1688	60.7698
1691.05	52.209
1694.1	45.6837
1697.14	38.6293
1700.19	33.3854
1703.23	27.205
1706.27	22.4084
1709.32	19.3038
1712.35	16.4441
1715.39	14.2511
1718.43	12.1331
1721.47	11.5443
1724.5	10.1463
1727.54	10.7439
1730.57	10.9531
1733.61	11.244
1736.64	9.91453
1739.67	9.99318
1742.7	10.5727
1745.72	11.1138
1748.75	9.84324
1751.78	9.82556
1754.8	8.4278
1757.82	7.79489
1760.85	5.821
1763.87	4.12089
1766.89	3.4497
1769.91	3.46128
1772.92	2.72687
1775.94	3.08395
1778.96	3.20224
1781.97	4.11262
1784.98	4.83503
1788	6.08283
1791.01	6.1234
1794.01	5.74592
1797.02	5.49066
1800.03	5.55819
1803.04	5.62447
1806.04	5.17081
1809.05	5.19579
1812.05	5.32558
1815.05	5.43144
1818.05	5.32811
1821.05	5.2202
1824.05	4.20258
1827.05	3.61389
1830.04	3.09697
1833.04	1.59427
1836.03	1.22609
1839.03	1.71546
1842.02	1.58236
1845.01	0.923373
1848	1.03747
1850.99	0.805422
1853.97	0.649815
1856.96	1.872
1859.94	1.08346
1862.93	1.83573
1865.91	1.67917
1868.89	1.62477
1871.87	2.40106
1874.85	3.53903
1877.83	2.91993
1880.81	3.33777
1882.56	3.83605
1885.55	4.48702
1888.54	4.67694
1891.52	4.84665
1894.51	5.3825
1897.49	5.52876
1900.48	5.29864
1903.46	3.84366
1906.44	2.90914
1909.42	2.64418
1912.4	2.81142
1915.38	1.74764
1918.35	1.03015
1921.33	0.085345
1924.3	0.0956699
1927.28	-0.0960301
1930.25	-0.319068
1933.22	-0.856216
1936.19	-0.290008
1939.16	-0.174243
1942.13	0.398233
1945.09	1.74469
1948.06	1.69972
1951.03	2.09493
1953.99	2.6538
1956.95	3.13595
1959.91	3.36698
1962.87	3.64499
1965.83	4.96684
1968.79	6.0391
1971.75	7.12988
1974.7	6.47747
1977.66	6.68263
1980.61	6.65112
1983.56	7.64256
1986.52	7.08835
1989.47	6.73717
1992.41	6.45176
1995.36	8.07889
1998.31	7.70632
2001.26	6.54033
2004.2	6.8194
2007.15	6.60275
2010.09	7.06841
2013.03	7.16372
2015.97	6.81627
2018.91	6.06456
2021.85	4.96353
2024.79	5.59897
2027.72	6.19855
2030.66	6.82297
2033.59	7.43579
2036.53	8.97998
2039.46	11.4742
2042.39	13.845
2045.32	15.1942
2048.25	16.7198
2051.18	17.1391
2054.1	17.7309
2057.03	18.2565
2059.95	19.7574
2062.88	21.8234
2065.8	23.1405
2068.72	23.7213
2071.64	24.7506
2074.56	26.071
2077.48	27.2459
2080.39	29.3442
2083.31	30.464
2086.22	31.5016
2089.14	33.3076
2092.05	36.2319
2094.96	39.3388
2097.87	42.6459
2100.78	44.8021
2103.69	49.2709
2106.6	54.1554
2109.51	58.7115
2112.41	63.8447
2115.32	67.5653
2118.22	71.54
2121.12	75.2357
2124.02	79.3622
2126.92	83.4091
2129.82	87.4656
2132.72	92.3566
2135.62	96.6023
2138.51	101.433
2141.41	105.231
2144.3	109.59
2147.19	114.602
2150.09	118.049
2152.97	121.902
2155.86	125.041
2158.75	128.055
2161.64	131.566
2164.53	133.859
2167.41	134.822
2170.3	135.001
2173.18	135.684
2176.06	134.011
2178.94	132.31
2181.82	130.016
2184.7	128.479
2187.58	125.141
2190.46	120.608
2193.33	117.913
2196.21	114.066
2199.08	109.802
2201.95	105.377
2204.83	101.172
2207.7	97.3294
2210.57	92.5231
2213.43	87.658
2216.3	83.4353
2219.17	79.5338
2222.03	73.9162
2224.9	69.2678
2227.76	64.9357
2230.62	60.9038
2233.49	56.8518
2236.34	52.8043
2239.2	46.9715
2242.06	43.1382
2244.92	39.2446
2247.78	37.0461
2250.63	35.0695
2253.48	33.1964
2256.34	30.9464
2259.19	30.0634
2262.04	29.7872
2264.89	29.5871
2267.74	28.6246
2270.59	27.9754
2273.43	27.3532
2276.28	27.6543
2279.12	26.8753
2281.97	25.2669
2284.81	24.656
2287.65	23.3183
2290.49	21.5006
2293.33	18.3434
2296.17	18.0903
2299.01	17.1599
2301.84	16.9898
2304.68	16.1615
2307.51	14.5892
2310.35	13.6185
2313.18	13.3735
2316.01	13.0566
2318.84	13.4865
2321.67	12.9792
2324.5	12.1542
2327.33	12.1633
2330.15	12.5059
2332.98	11.7125
2335.8	10.7172
2338.62	9.63542
2341.45	9.19975
2344.27	8.2239
2347.09	6.77073
2349.91	5.10506
2352.72	4.08746
2355.54	2.64498
2358.36	0.755486
2361.17	0.443379
2363.98	1.01771
2366.8	2.54431
2369.61	2.01826
2372.42	2.61076
2375.23	1.42421
2378.04	1.56223
2380.85	1.93304
2383.66	3.23591
2386.46	2.98891
2389.26	3.88417
2392.07	4.21345
2394.87	4.39234
2397.67	4.68902
2400.47	4.47433
2403.27	4.59536
2406.07	5.1904
2408.87	5.78338
2411.67	5.54193
2414.46	5.89772
2417.26	7.10846
2420.05	7.53124
2422.84	8.19254
2425.64	8.59544
2428.43	10.4215
2431.22	12.5135
2434.01	11.8786
2436.79	12.2692
2439.58	12.3975
2442.37	11.221
2445.15	9.98378
2447.93	9.71991
2450.72	8.9281
2453.5	8.4023
2456.28	7.90992
2459.06	8.10275
2461.84	6.98241
2464.62	6.50591
2467.39	6.15775
2470.17	6.12399
2472.94	6.30587
2475.72	6.76923
2478.49	6.55243
2481.26	7.1498
2484.03	7.9042
2486.8	7.82175
2489.57	7.498
2492.34	6.86298
2495.1	6.51164
2497.87	6.0879
2500.63	5.93944
2503.4	5.77739
2506.16	4.85178
2508.92	3.58121
2511.68	2.69469
2514.44	2.38975
2517.2	2.42838
2519.96	2.0197
2522.72	2.56984
2525.47	1.65899
2528.23	1.09589
2530.98	1.42375
2533.74	1.44273
2536.49	1.65134
2539.24	2.38466
2541.99	2.90146
2544.74	3.85072
2547.49	3.98001
2550.23	4.47125
2552.98	3.55394
2555.72	3.60115
2558.47	3.50856
2561.21	4.93928
2563.95	4.17805
2566.69	6.24855
2569.43	6.27977
2572.17	7.17122
2574.91	7.38123
2577.65	7.61382
2580.39	6.85865
2583.12	6.56381
2585.85	5.47835
2588.59	5.18784
2591.32	5.13204
2594.05	3.84767
2596.78	4.66631
2599.51	4.1977
2602.24	3.64818
2604.97	3.79524
2607.69	2.97504
2610.42	2.99899
2613.14	3.45526
2615.87	2.70166
2618.59	3.06436
2621.31	3.34591
2624.03	4.68965
2626.75	5.18558
2629.47	5.49838
2632.19	5.61833
2634.91	6.85277
2637.62	7.02015
2640.34	7.79397
2643.05	7.42887
2645.76	7.05965
2648.48	7.83971
2651.19	8.32096
2653.9	7.97081
2656.6	8.43442
2659.31	8.80356
2662.02	8.70883
2664.73	9.81725
2667.43	8.35559
2670.14	8.47013
2672.84	8.24359
2675.54	8.20695
2678.24	9.19517
2680.94	9.15647
2683.64	9.1329
2686.34	9.94105
2689.04	10.0249
2691.74	10.3287
2694.43	11.1198
2697.13	11.0133
2699.82	11.161
2702.51	10.7109
2705.21	11.4524
2707.9	12.5146
2710.58	12.8766
2713.27	13.7676
2715.96	14.6734
2718.65	13.4799
2721.33	13.3905
2724.02	13.5048
2726.71	14.2774
2729.39	13.8004
2732.07	13.1473
2734.75	12.1874
2737.43	11.6856
2740.11	11.0223
2742.79	11.6803
2745.47	11.3086
2748.14	9.92877
2750.82	9.20044
2753.49	8.89212
2756.17	7.82318
2758.84	7.27929
2761.51	6.74814
2764.18	5.60491
2766.85	5.21001
2769.52	5.25374
2772.19	5.81271
2774.86	4.51076
2777.52	4.14706
2780.19	3.61253
2782.85	2.13512
2785.52	1.6144
2788.18	1.48851
2790.84	0.553549
2793.5	0.0605448
2796.16	-0.76442
2798.82	-1.00964
2801.48	-1.59794
2804.13	-2.36358
2806.79	-1.64363
2809.45	-1.36451
2812.1	-1.81377
2814.75	-1.5642
2817.41	-0.156781
2820.06	1.99368
2822.71	7.0974
2825.36	12.2372
2828	18.7344
2830.65	25.2352
2833.3	32.1258
2835.94	39.0437
2838.59	47.0318
2841.23	55.1736
2843.87	64.4381
2846.52	74.2342
2849.16	85.2933
2851.8	96.0566
2854.44	106.589
2857.08	117.632
2859.71	128.534
2862.35	137.832
2864.98	145.641
2867.62	152.727
2870.25	159.089
2872.88	164.637
2875.52	168.251
2878.15	173.071
2880.78	178.1
2883.41	182.112
2886.03	187.537
2888.66	192.01
2891.29	195.907
2893.91	200.434
2896.54	203.87
2899.16	209.33
2901.78	216.554
2904.4	225.725
2907.02	236.121
2909.64	249.173
2912.26	261.737
2914.88	274.945
2917.5	287.024
2920.11	298.249
2922.73	307.861
2925.34	314.697
2927.96	318.403
2930.57	320.789
2933.18	319.566
2935.79	317.978
2938.4	314.275
2941.01	309.038
2943.62	301.477
2946.22	292.789
2948.83	280.991
2951.43	268.425
2954.04	254.882
2956.64	241.05
2959.24	227.145
2961.84	214.166
2964.45	201.791
2967.05	190.788
2969.64	179.568
2972.24	168.296
2974.84	158.637
2977.43	147.606
2980.03	137.175
2982.62	125.43
2985.22	114.728
2987.81	103.604
2990.4	91.6183
2992.99	80.1624
2995.58	70.4404
2998.17	62.2339
3000.76	55.0397
3003.34	47.5364
3005.93	40.4997
3008.52	34.7482
3011.1	29.3286
3013.68	24.6295
3016.27	20.4453
3018.85	17.6137
3021.43	15.7885
3024.01	13.8738
3026.59	12.025
3029.16	11.565
3031.74	11.5637
3034.32	11.6395
3036.89	13.3826
3039.47	14.2616
3042.04	14.846
3044.61	16.0949
3047.18	17.1122
3049.75	17.4021
3052.32	16.7045
3054.89	16.1241
3057.46	16.3059
3060.03	15.8182
3062.59	15.5712
3065.16	14.6157
3067.72	13.3783
3070.29	12.5102
3072.85	11.1776
3075.41	10.0356
3077.97	8.13845
3080.53	6.32353
3083.09	4.95877
3085.65	3.76536
3088.21	2.69341
3090.76	2.56489
3093.32	2.24887
3095.87	2.4586
3098.43	2.63836
3100.98	2.70617
3103.53	2.76687
3106.08	3.52755
3108.63	3.65814
3111.18	4.07846
3113.73	4.19889
3116.28	5.87398
3118.83	7.55183
3121.37	8.95102
3123.92	10.5186
3126.46	13.2534
3129	15.4048
3131.55	17.5624
3134.09	19.0508
3136.63	20.6186
3139.17	23.5709
3141.71	26.3982
3144.24	29.3486
3146.78	32.0851
3149.32	33.7254