File: data/Raman/poly_smoothed/Thy_50_12_40_1x_45s_532 nm_x100_100%_600 gr_mm_01.txt
#Acq. time (s)=	45
#Accumulations=	2
#Range (cm-¹)=	200...3150
#Windows=	2
#Auto scanning=	Off
#Autofocus=	Off
#Macrospot=	Off
#AutoExposure=	Off
#Spike filter=	Multiple accum.
#Delay time (s)=	0
#Binning=	1
#Readout mode=	Signal
#DeNoise=	Off
#ICS correction=	On
#Dark correction=	Off
#Inst. Process=	Off
#Detector Gain=	Best Dynamic Range
#Detector ADC=	20 kHz
#Detector temperature (°C)=	-69.85
#Instrument=	LabRAM HR Evol
#Detector=	Synapse
#Objective=	x100
#Grating=	600 gr/mm
#ND Filter=	100%
#Laser (nm)=	532
#Hole=	100.021
#Range=	Auto
#Laser Pol.=	No
#Raman. Pol.=	No
#Laser Pol. (°)=	-0.0007625
#Raman Pol. (°)=	89.9995
#Collection=	Microscope
#StageXY=	Marzhauser
#StageZ=	Marzhauser
#X (µm)=	-5126.9
#Y (µm)=	1517.1
#Z (µm)=	63.4
#Full time(mm:ss)=	3:18
#Project=
#Sample=
#Site=
#Title=	Thy_50_12_40_2x_45s_532 nm_x100_100%_600 gr_mm
#Remark=
#Date=	07.07.2022 12:12
#Acquired=	07.07.2022 12:12:08
#Base:Fit=	10.08.2022 10:04:30
#Base:Sub=	10.08.2022 10:04:45
#Filter:Polynom=	16.08.2022 10:20:25
#AxisType[0]=Intens
#AxisUnit[0]=Cnt
#AxisType[1]=Spectr
#AxisUnit[1]=1/cm
200.43	27.9642
204.061	32.335
207.688	30.1356
211.316	26.7594
214.941	23.7064
218.566	22.3979
222.188	19.4379
225.809	17.1688
229.43	13.2442
233.047	13.3297
236.663	12.9125
240.278	11.2674
243.894	12.021
247.506	12.3737
251.116	11.4669
254.725	12.7076
258.333	13.9525
261.939	16.8309
265.546	18.1911
269.15	19.7115
272.752	20.6136
276.353	20.5638
279.952	21.073
283.55	21.1526
287.146	22.047
290.739	22.0228
294.333	23.6473
297.925	25.6968
301.516	26.95
305.106	27.3325
308.694	26.3166
312.279	25.2483
315.864	24.9851
319.448	24.7956
323.029	24.9579
326.61	22.7812
330.19	20.8214
333.766	20.8993
337.343	20.8434
340.917	19.9566
344.491	17.2136
348.062	15.7936
351.633	13.3162
355.201	11.1555
358.77	8.30478
362.335	6.84158
365.899	6.76447
369.464	5.98665
373.025	5.88721
376.585	5.83216
380.143	6.4281
383.702	7.47383
387.258	5.69721
390.812	7.5502
394.365	7.83745
397.916	8.77671
401.467	8.54691
405.015	9.56189
408.565	8.28336
412.111	6.92381
415.656	6.70123
419.197	9.64034
422.739	12.0384
426.279	12.8112
429.819	14.6053
433.356	16.3266
436.893	17.5318
440.428	18.6916
443.96	19.544
447.492	21.3788
451.023	22.8069
454.553	23.7222
458.079	25.597
461.606	27.5255
465.132	28.1845
468.654	29.4697
472.177	30.8249
475.696	33.9439
479.217	36.6547
482.733	37.5974
486.251	36.5276
489.765	37.706
493.278	38.0556
496.791	38.4246
500.301	38.3565
503.81	39.6414
507.319	38.6629
510.825	36.6344
514.33	36.6062
517.833	36.9208
521.337	36.3313
524.838	35.44
528.337	34.812
531.835	34.3556
535.332	31.3842
538.827	30.3817
542.321	28.6867
545.814	28.2301
549.305	26.0748
552.795	24.7604
556.284	23.7021
559.771	25.9435
563.257	25.9326
566.742	24.4598
570.223	24.1652
573.705	23.2616
577.185	24.0039
580.665	23.4113
584.141	20.776
587.617	19.6066
591.092	16.064
594.564	13.4223
598.037	12.6178
601.506	13.6953
604.976	13.3707
608.443	12.8329
611.91	13.0461
615.374	14.7551
618.839	13.9559
622.3	12.6081
625.761	11.3731
629.221	11.4452
632.679	11.9561
636.135	13.6107
639.592	15.861
643.045	18.9171
646.497	20.1007
649.948	21.7711
653.398	23.4703
656.846	25.7503
660.293	26.1493
663.738	26.6057
667.185	25.4317
670.628	25.8995
674.067	29.6468
677.508	31.3598
680.947	33.4082
684.385	36.6031
687.821	39.5492
691.256	41.8917
694.69	43.1008
698.121	47.5136
701.552	49.0039
704.982	49.3294
708.41	49.9798
711.836	52.4302
715.262	53.5048
718.685	55.2959
722.108	57.5218
725.53	59.5643
728.949	60.9945
732.369	61.7746
735.785	61.5565
739.2	61.137
742.616	60.943
746.028	60.3675
749.441	60.3199
752.851	63.7685
756.26	66.5582
759.667	67.9681
763.075	71.3018
766.479	71.7738
769.883	72.1816
773.285	74.2263
776.686	77.398
780.085	78.1157
783.484	75.1644
786.881	79.2418
790.276	83.9894
793.671	87.0444
797.064	89.0711
800.456	91.0476
803.846	93.5702
807.236	94.0098
810.624	96.3072
814.01	95.5181
817.394	93.5228
820.778	92.1664
824.161	90.4801
827.543	89.158
830.921	87.9375
834.3	86.5045
837.676	84.8372
841.053	82.9338
844.426	79.744
847.8	75.9604
851.171	71.6566
854.542	69.3333
857.911	66.7056
861.279	63.42
864.645	58.3043
868.01	61.7984
871.375	64.675
874.737	62.5208
878.097	58.6066
881.457	57.33
884.817	54.7996
888.174	52.7846
891.53	51.7792
894.884	50.6546
898.237	48.3768
901.589	46.6088
904.94	44.9755
908.289	43.5496
911.637	41.3872
914.984	40.0874
918.33	37.1612
921.674	35.9252
925.015	34.9129
928.357	32.3895
931.698	31.0618
935.037	28.3357
938.373	26.0745
941.71	24.2513
945.046	23.2919
948.378	22.2719
951.711	25.0492
955.043	26.0758
958.372	24.8885
961.701	25.8579
965.027	27.4806
968.354	29.9061
971.678	30.3424
975	33.5687
978.324	35.323
981.644	37.529
984.962	39.9619
988.282	42.3864
991.598	43.6606
994.913	43.0713
998.227	43.413
1001.54	43.2437
1004.85	44.0593
1008.16	44.3602
1011.47	43.7698
1014.78	43.3569
1018.08	44.3855
1021.39	44.8176
1024.69	46.8361
1028	49.606
1031.3	50.987
1034.6	53.1029
1037.9	51.0744
1041.19	50.1328
1044.49	50.2525
1047.79	49.7009
1051.08	48.3278
1054.37	47.5736
1057.66	47.1672
1060.95	45.1524
1064.24	43.7261
1067.53	40.1136
1070.81	36.2236
1074.1	32.7275
1077.38	29.7043
1080.66	25.9703
1083.94	24.1544
1087.22	22.4046
1090.5	23.639
1093.78	23.76
1097.05	25.701
1100.33	27.9984
1103.6	29.3602
1106.87	32.1876
1110.15	31.9882
1113.41	32.4873
1116.68	31.7837
1119.95	32.2099
1123.21	32.0941
1126.48	31.4842
1129.74	31.757
1133	30.105
1136.26	27.0593
1139.52	24.1968
1142.78	20.6635
1146.04	17.4459
1149.29	14.4082
1152.55	9.78895
1155.8	7.64519
1159.05	4.64109
1162.3	3.28297
1165.55	1.24241
1168.8	3.19441
1172.05	4.22204
1175.29	5.82145
1178.54	5.70274
1181.78	6.32997
1185.02	8.33951
1188.26	8.7851
1191.5	5.98066
1194.74	7.96403
1197.97	10.2433
1201.21	10.2199
1204.44	12.4385
1207.68	16.8473
1210.91	18.1572
1214.14	20.3422
1217.37	23.3931
1220.6	27.5968
1223.82	33.8971
1227.05	38.2223
1230.27	42.1081
1233.49	46.0519
1236.72	51.1731
1239.94	57.4943
1243.16	63.0923
1246.37	68.311
1249.59	71.7791
1252.8	74.4866
1256.02	78.7233
1259.23	80.9805
1262.44	85.3872
1265.66	89.9304
1268.87	93.0023
1272.07	98.1043
1275.28	99.2408
1278.48	102.08
1281.69	105.086
1284.89	108.331
1288.09	109.013
1291.3	110.337
1294.49	111.562
1297.69	111.559
1300.89	113.101
1304.09	113.239
1307.28	111.943
1310.47	110.885
1313.66	109.774
1316.86	109.867
1320.05	108.162
1323.23	106.763
1326.42	105.456
1329.61	104.031
1332.79	100.939
1335.98	98.9516
1339.16	98.3734
1342.34	96.9069
1345.52	95.0226
1348.7	92.6458
1351.87	89.4296
1355.05	86.7375
1358.23	84.3609
1361.4	81.5685
1364.57	75.8396
1367.74	73.7326
1370.91	72.2392
1374.08	71.3551
1377.25	70.4733
1380.42	70.2001
1383.58	69.9059
1386.75	68.3157
1389.91	67.9271
1393.07	67.4873
1396.23	69.1441
1399.39	67.6812
1402.55	68.9869
1405.7	68.7309
1408.86	70.248
1412.01	72.7271
1415.17	76.7745
1418.32	79.9335
1421.47	85.5374
1424.62	92.2451
1427.77	100.888
1430.92	108.06
1434.06	113.469
1437.2	120.633
1440.35	125.117
1443.49	128.88
1446.63	132.087
1449.77	133.323
1452.91	131.859
1456.05	129.676
1459.18	124.769
1462.32	117.975
1465.45	110.942
1468.59	102.112
1471.72	90.8268
1474.85	80.2867
1477.98	67.5355
1481.11	58.097
1484.23	47.7293
1487.36	39.7538
1490.48	30.9339
1493.61	25.8585
1496.73	22.0627
1499.85	21.6093
1502.97	21.9145
1506.09	22.2781
1509.2	22.5912
1512.32	24.1793
1515.44	25.1055
1518.55	27.1972
1521.66	30.0943
1524.77	35.3558
1527.88	39.7836
1530.99	42.7443
1534.1	47.6058
1537.21	50.6179
1540.31	57.4968
1543.42	62.8378
1546.52	68.9862
1549.62	75.0695
1552.72	81.0413
1555.82	88.0476
1558.92	92.8484
1562.02	98.5235
1565.11	103.83
1568.21	108.443
1571.3	113.409
1574.39	118.073
1577.49	121.04
1580.58	122.029
1583.67	122.138
1586.75	123.002
1589.84	121.77
1592.93	121.24
1596.01	119.178
1599.09	117.987
1602.18	114.686
1605.26	111.907
1608.34	108.908
1611.41	106.688
1614.49	105.467
1617.57	106.255
1620.64	107.066
1623.72	108.606
1626.79	110.849
1629.86	113.499
1632.93	115.783
1636	118.084
1639.07	121.926
1642.14	124.509
1645.2	127.977
1648.27	132.026
1651.33	131.918
1654.39	129.887
1657.45	131.465
1660.51	128.508
1663.57	126.132
1666.63	121.039
1669.69	115.531
1672.74	108.862
1675.79	101.298
1678.85	92.517
1681.9	84.0304
1684.95	74.9121
1688	66.8456
1691.05	58.7751
1694.1	51.4166
1697.14	44.7825
1700.19	38.3171
1703.23	33.2927
1706.27	29.4452
1709.32	25.8836
1712.35	21.973
1715.39	18.7834
1718.43	16.8125
1721.47	14.9091
1724.5	13.1686
1727.54	10.5719
1730.57	10.923
1733.61	10.3518
1736.64	8.85468
1739.67	8.35585
1742.7	6.98435
1745.72	6.87434
1748.75	5.98042
1751.78	5.78113
1754.8	5.85349
1757.82	5.18958
1760.85	4.42912
1763.87	4.13353
1766.89	3.97069
1769.91	3.65423
1772.92	3.53266
1775.94	4.54081
1778.96	3.50553
1781.97	3.31616
1784.98	2.47155
1788	2.15542
1791.01	0.846036
1794.01	0.347402
1797.02	-0.766751
1800.03	0.00737647
1803.04	0.463166
1806.04	-0.20593
1809.05	0.00858295
1812.05	-1.14221
1815.05	-0.808455
1818.05	-0.394921
1821.05	0.278735
1824.05	0.653319
1827.05	0.516676
1830.04	0.251069
1833.04	0.26868
1836.03	0.98258
1839.03	1.42325
1842.02	1.8115
1845.01	2.32964
1848	2.72469
1850.99	3.40942
1853.97	3.65565
1856.96	3.90624
1859.94	4.51876
1862.93	3.75487
1865.91	4.61863
1868.89	3.94147
1871.87	3.94644
1874.85	3.32747
1877.83	2.79652
1880.81	3.78083
1882.56	4.23208
1885.55	3.83538
1888.54	4.6863
1891.52	4.32831
1894.51	4.24248
1897.49	3.69149
1900.48	4.90622
1903.46	4.50136
1906.44	4.52945
1909.42	5.44605
1912.4	4.80937
1915.38	6.35577
1918.35	6.50116
1921.33	5.18954
1924.3	5.29535
1927.28	4.75905
1930.25	4.2087
1933.22	3.32498
1936.19	3.25814
1939.16	2.01274
1942.13	1.40523
1945.09	1.65509
1948.06	0.909055
1951.03	1.00869
1953.99	1.57443
1956.95	0.689261
1959.91	1.03137
1962.87	0.232249
1965.83	0.534313
1968.79	0.790578
1971.75	1.77374
1974.7	1.54426
1977.66	1.52534
1980.61	2.46852
1983.56	1.41347
1986.52	2.78498
1989.47	2.47675
1992.41	2.4205
1995.36	1.98827
1998.31	2.67937
2001.26	4.11967
2004.2	4.51994
2007.15	5.53225
2010.09	5.63498
2013.03	4.93489
2015.97	4.98015
2018.91	4.62611
2021.85	4.45527
2024.79	4.13553
2027.72	4.08386
2030.66	4.66968
2033.59	4.55959
2036.53	5.02175
2039.46	5.04698
2042.39	6.00299
2045.32	7.32422
2048.25	7.93568
2051.18	7.68212
2054.1	8.09935
2057.03	8.61491
2059.95	10.9098
2062.88	12.1727
2065.8	13.9761
2068.72	16.6833
2071.64	20.1143
2074.56	22.6923
2077.48	25.4424
2080.39	27.697
2083.31	29.892
2086.22	32.3668
2089.14	35.5541
2092.05	37.83
2094.96	41.1488
2097.87	45.265
2100.78	50.121
2103.69	54.8755
2106.6	59.9968
2109.51	64.8654
2112.41	71.3434
2115.32	76.9619
2118.22	82.6999
2121.12	87.3719
2124.02	92.8066
2126.92	99.2828
2129.82	105.081
2132.72	112.306
2135.62	120.515
2138.51	127.764
2141.41	132.722
2144.3	137.317
2147.19	143.261
2150.09	147.743
2152.97	152.299
2155.86	154.728
2158.75	158.748
2161.64	160.029
2164.53	161.465
2167.41	162.677
2170.3	164.194
2173.18	163.485
2176.06	162.201
2178.94	160.014
2181.82	155.864
2184.7	153.217
2187.58	148.647
2190.46	143.638
2193.33	139.2
2196.21	134.931
2199.08	129.381
2201.95	125.671
2204.83	120.622
2207.7	113.573
2210.57	107.64
2213.43	100.965
2216.3	95.8736
2219.17	90.9824
2222.03	84.6756
2224.9	79.6972
2227.76	75.0509
2230.62	70.7807
2233.49	66.6176
2236.34	62.9214
2239.2	60.0096
2242.06	56.0675
2244.92	52.4804
2247.78	49.2099
2250.63	45.7468
2253.48	43.9522
2256.34	41.8349
2259.19	39.3003
2262.04	38.5605
2264.89	37.7657
2267.74	35.772
2270.59	33.9813
2273.43	32.9117
2276.28	30.743
2279.12	28.4927
2281.97	27.6837
2284.81	24.7341
2287.65	23.4488
2290.49	21.1677
2293.33	19.1263
2296.17	19.3038
2299.01	18.5325
2301.84	18.7581
2304.68	17.3233
2307.51	16.498
2310.35	15.6003
2313.18	15.1603
2316.01	15.073
2318.84	13.9355
2321.67	13.9155
2324.5	14.7783
2327.33	13.4755
2330.15	13.01
2332.98	12.9048
2335.8	12.5987
2338.62	10.9317
2341.45	10.0274
2344.27	8.13944
2347.09	6.68367
2349.91	6.00064
2352.72	4.90578
2355.54	3.04419
2358.36	2.37625
2361.17	1.13291
2363.98	1.54852
2366.8	0.402442
2369.61	-0.318575
2372.42	0.102601
2375.23	-0.425414
2378.04	0.741612
2380.85	1.40247
2383.66	2.13026
2386.46	2.23838
2389.26	2.43727
2392.07	3.77905
2394.87	4.53394
2397.67	4.80468
2400.47	5.78384
2403.27	6.33908
2406.07	6.42586
2408.87	6.48238
2411.67	8.09647
2414.46	7.94123
2417.26	7.83958
2420.05	8.40952
2422.84	7.35381
2425.64	8.75759
2428.43	8.42457
2431.22	8.80423
2434.01	8.55958
2436.79	8.19959
2439.58	9.25291
2442.37	10.3348
2445.15	10.2251
2447.93	10.5107
2450.72	9.79307
2453.5	9.36656
2456.28	8.33453
2459.06	7.52974
2461.84	7.24574
2464.62	7.54652
2467.39	7.35388
2470.17	7.17378
2472.94	7.2423
2475.72	7.40224
2478.49	7.72222
2481.26	7.09731
2484.03	6.29538
2486.8	6.10512
2489.57	6.03635
2492.34	5.39446
2495.1	5.91903
2497.87	6.34452
2500.63	7.03499
2503.4	6.81728
2506.16	7.14688
2508.92	7.43604
2511.68	7.65171
2514.44	7.47269
2517.2	7.19718
2519.96	5.35757
2522.72	5.00112
2525.47	5.50802
2528.23	5.03071
2530.98	5.51501
2533.74	5.6225
2536.49	5.50319
2539.24	5.44093
2541.99	5.89438
2544.74	6.75347
2547.49	6.77071
2550.23	6.13301
2552.98	5.78529
2555.72	5.87307
2558.47	5.39682
2561.21	4.02583
2563.95	4.58619
2566.69	4.02439
2569.43	3.6361
2572.17	2.92912
2574.91	2.8353
2577.65	3.13127
2580.39	2.68512
2583.12	2.43207
2585.85	1.47581
2588.59	1.12084
2591.32	1.45655
2594.05	1.66864
2596.78	0.831362
2599.51	1.46375
2602.24	2.02457
2604.97	1.39276
2607.69	2.99252
2610.42	4.01247
2613.14	3.98492
2615.87	3.56158
2618.59	3.16437
2621.31	3.44761
2624.03	3.99262
2626.75	3.43123
2629.47	3.71099
2632.19	4.07033
2634.91	3.26445
2637.62	3.17322
2640.34	2.70667
2643.05	3.02961
2645.76	2.84257
2648.48	1.92811
2651.19	1.18951
2653.9	1.29015
2656.6	2.47825
2659.31	2.9848
2662.02	2.03799
2664.73	2.08919
2667.43	2.65904
2670.14	3.09394
2672.84	2.95476
2675.54	4.71025
2678.24	4.75677
2680.94	4.63906
2683.64	5.60247
2686.34	5.96527
2689.04	6.97228
2691.74	7.88707
2694.43	7.93717
2697.13	8.04134
2699.82	8.44946
2702.51	7.58313
2705.21	7.83724
2707.9	9.2572
2710.58	10.3166
2713.27	10.6019
2715.96	12.0417
2718.65	13.4833
2721.33	14.0659
2724.02	14.5024
2726.71	14.1738
2729.39	15.0954
2732.07	15.8745
2734.75	14.8091
2737.43	14.5646
2740.11	14.2055
2742.79	12.5432
2745.47	11.6906
2748.14	10.2067
2750.82	9.4298
2753.49	8.25211
2756.17	6.48167
2758.84	6.11409
2761.51	5.14416
2764.18	3.48121
2766.85	2.77707
2769.52	2.35374
2772.19	2.09913
2774.86	2.19992
2777.52	1.20124
2780.19	1.37644
2782.85	1.66751
2785.52	0.320096
2788.18	0.56268
2790.84	0.928078
2793.5	0.75581
2796.16	0.797562
2798.82	0.13849
2801.48	-0.348453
2804.13	-0.639035
2806.79	-2.67813
2809.45	-3.6902
2812.1	-4.20807
2814.75	-3.7481
2817.41	-2.60766
2820.06	1.31157
2822.71	6.30529
2825.36	13.0473
2828	19.6231
2830.65	28.2631
2833.3	36.6948
2835.94	45.0406
2838.59	54.5186
2841.23	63.9987
2843.87	75.1765
2846.52	86.6808
2849.16	100.305
2851.8	115.38
2854.44	130.291
2857.08	145.594
2859.71	159.786
2862.35	171.89
2864.98	182.626
2867.62	192.721
2870.25	200.705
2872.88	208.583
2875.52	215.981
2878.15	221.789
2880.78	229.475
2883.41	236.654
2886.03	243.315
2888.66	249.784
2891.29	255.425
2893.91	261.961
2896.54	270.016
2899.16	276.515
2901.78	286.379
2904.4	296.319
2907.02	308.806
2909.64	323.148
2912.26	339.647
2914.88	356.098
2917.5	371.091
2920.11	383.839
2922.73	393.968
2925.34	400.646
2927.96	405.214
2930.57	407.93
2933.18	407.314
2935.79	404.227
2938.4	397.841
2941.01	389.724
2943.62	378.174
2946.22	365.689
2948.83	351.731
2951.43	336.551
2954.04	320.047
2956.64	303.296
2959.24	288.169
2961.84	273.491
2964.45	258.976
2967.05	245.251
2969.64	231.515
2972.24	219.119
2974.84	205.721
2977.43	193.267
2980.03	179.59
2982.62	165.374
2985.22	150.818
2987.81	136.16
2990.4	122.959
2992.99	109.593
2995.58	96.6815
2998.17	84.3022
3000.76	71.8663
3003.34	60.5565
3005.93	49.6418
3008.52	39.0925
3011.1	31.2375
3013.68	22.7191
3016.27	17.4293
3018.85	12.6391
3021.43	9.21357
3024.01	6.82403
3026.59	4.65989
3029.16	3.00487
3031.74	2.28691
3034.32	3.64745
3036.89	4.88352
3039.47	6.52141
3042.04	8.87385
3044.61	11.0473
3047.18	12.4699
3049.75	13.2614
3052.32	14.1147
3054.89	14.78
3057.46	14.8068
3060.03	13.7841
3062.59	13.3548
3065.16	12.169
3067.72	10.4658
3070.29	8.99267
3072.85	7.83939
3075.41	6.12676
3077.97	4.83392
3080.53	3.62375
3083.09	1.86948
3085.65	0.305218
3088.21	-0.664472
3090.76	-1.21271
3093.32	-1.53254
3095.87	-0.162037
3098.43	1.56489
3100.98	2.58032
3103.53	3.90692
3106.08	5.18784
3108.63	6.54172
3111.18	7.50505
3113.73	9.66161
3116.28	11.6909
3118.83	13.4681
3121.37	15.4763
3123.92	18.0804
3126.46	21.1542
3129	23.2384
3131.55	24.7652
3134.09	27.0371
3136.63	30.0767
3139.17	32.5373
3141.71	34.9909
3144.24	37.062
3146.78	39.7674
3149.32	42.6671