File: data/Raman/poly_smoothed/Thy_50_12_03_1x_45s_532 nm_x100_100%_600 gr_mm_01.txt
#Acq. time (s)=	45
#Accumulations=	2
#Range (cm-¹)=	200...3150
#Windows=	2
#Auto scanning=	Off
#Autofocus=	Off
#Macrospot=	Off
#AutoExposure=	Off
#Spike filter=	Multiple accum.
#Delay time (s)=	0
#Binning=	1
#Readout mode=	Signal
#DeNoise=	Off
#ICS correction=	On
#Dark correction=	Off
#Inst. Process=	Off
#Detector Gain=	Best Dynamic Range
#Detector ADC=	20 kHz
#Detector temperature (°C)=	-69.85
#Instrument=	LabRAM HR Evol
#Detector=	Synapse
#Objective=	x100
#Grating=	600 gr/mm
#ND Filter=	100%
#Laser (nm)=	532
#Hole=	100.021
#Range=	Auto
#Laser Pol.=	No
#Raman. Pol.=	No
#Laser Pol. (°)=	-0.0007625
#Raman Pol. (°)=	89.9995
#Collection=	Microscope
#StageXY=	Marzhauser
#StageZ=	Marzhauser
#X (µm)=	-5089
#Y (µm)=	1503.4
#Z (µm)=	62.65
#Full time(mm:ss)=	3:18
#Project=
#Sample=
#Site=
#Title=	Thy_50_12_03_2x_45s_532 nm_x100_100%_600 gr_mm
#Remark=
#Date=	07.07.2022 09:21
#Acquired=	07.07.2022 09:21:48
#Base:Fit=	10.08.2022 10:03:08
#Base:Fit=	10.08.2022 10:03:15
#Base:Fit=	10.08.2022 10:03:19
#Base:Fit=	10.08.2022 10:04:29
#Base:Sub=	10.08.2022 10:04:45
#Filter:Polynom=	16.08.2022 10:20:24
#AxisType[0]=Intens
#AxisUnit[0]=Cnt
#AxisType[1]=Spectr
#AxisUnit[1]=1/cm
200.43	0.808368
204.061	4.3583
207.688	5.18069
211.316	5.29298
214.941	4.56301
218.566	4.46701
222.188	5.57555
225.809	4.83576
229.43	4.83884
233.047	5.06242
236.663	4.77301
240.278	4.8376
243.894	4.997
247.506	4.29804
251.116	4.68659
254.725	4.69561
258.333	4.22847
261.939	4.97866
265.546	4.74256
269.15	6.52112
272.752	7.4687
276.353	8.03608
279.952	8.38333
283.55	9.82912
287.146	11.6802
290.739	12.7598
294.333	13.7262
297.925	14.696
301.516	16.1546
305.106	17.271
308.694	19.8777
312.279	20.9282
315.864	20.5613
319.448	19.7022
323.029	20.4982
326.61	17.8881
330.19	17.3705
333.766	15.8085
337.343	14.8343
340.917	13.1783
344.491	11.2906
348.062	8.99664
351.633	9.12651
355.201	6.51857
358.77	4.79017
362.335	2.82613
365.899	3.1871
369.464	4.30105
373.025	5.53606
376.585	5.84672
380.143	6.506
383.702	6.5586
387.258	8.9949
390.812	10.1259
394.365	12.2907
397.916	13.5833
401.467	14.1235
405.015	14.5548
408.565	15.9887
412.111	15.0209
415.656	14.8438
419.197	16.9741
422.739	17.1454
426.279	17.3945
429.819	17.2741
433.356	16.8295
436.893	18.3703
440.428	18.0655
443.96	17.8129
447.492	18.5381
451.023	19.6095
454.553	20.9639
458.079	22.4053
461.606	22.08
465.132	21.9026
468.654	21.7216
472.177	22.4739
475.696	22.0158
479.217	23.113
482.733	23.2779
486.251	23.4567
489.765	23.0701
493.278	23.6043
496.791	25.2655
500.301	25.886
503.81	25.3574
507.319	26.7341
510.825	25.4801
514.33	25.1784
517.833	24.8783
521.337	25.4721
524.838	24.9734
528.337	23.9008
531.835	24.0357
535.332	25.4648
538.827	23.4864
542.321	23.238
545.814	21.0432
549.305	19.8309
552.795	16.9651
556.284	15.698
559.771	13.9957
563.257	12.7582
566.742	11.9656
570.223	9.60132
573.705	8.14428
577.185	8.76616
580.665	9.30622
584.141	10.0058
587.617	7.97443
591.092	5.76409
594.564	5.27758
598.037	4.02114
601.506	4.45883
604.976	4.78328
608.443	5.03986
611.91	5.25245
615.374	8.18455
618.839	9.0589
622.3	9.19498
625.761	9.5676
629.221	12.5609
632.679	14.8089
636.135	16.7093
639.592	17.1557
643.045	17.0873
646.497	17.705
649.948	18.4508
653.398	19.5051
656.846	20.4799
660.293	20.1444
663.738	22.0406
667.185	22.3754
670.628	22.5731
674.067	21.2209
677.508	21.2879
680.947	21.5776
684.385	21.3683
687.821	22.9049
691.256	24.7706
694.69	27.0347
698.121	30.1365
701.552	33.2227
704.982	34.2187
708.41	37.9023
711.836	40.9269
715.262	43.6139
718.685	45.7865
722.108	47.4362
725.53	48.8553
728.949	50.5983
732.369	52.7249
735.785	52.8671
739.2	53.7948
742.616	54.6927
746.028	57.5999
749.441	60.0366
752.851	61.7412
756.26	63.9133
759.667	65.3256
763.075	67.6412
766.479	70.8417
769.883	73.0875
773.285	77.3639
776.686	81.2796
780.085	83.5027
783.484	85.3757
786.881	86.5521
790.276	88.4887
793.671	90.1978
797.064	90.4858
800.456	91.2629
803.846	91.8597
807.236	89.6884
810.624	88.0458
814.01	86.3559
817.394	83.6896
820.778	81.8321
824.161	80.47
827.543	77.9947
830.921	75.9335
834.3	74.6393
837.676	73.1124
841.053	72.4727
844.426	70.3028
847.8	69.5622
851.171	66.3451
854.542	65.0492
857.911	64.9401
861.279	65.1301
864.645	63.8633
868.01	63.8858
871.375	61.9903
874.737	61.7515
878.097	58.649
881.457	57.8249
884.817	55.5412
888.174	52.0312
891.53	49.8271
894.884	48.0391
898.237	46.3678
901.589	44.1369
904.94	42.5417
908.289	42.5342
911.637	40.9468
914.984	42.234
918.33	42.445
921.674	42.3963
925.015	41.2255
928.357	39.7621
931.698	39.2731
935.037	37.1601
938.373	36.7138
941.71	37.7022
945.046	36.5013
948.378	36.5238
951.711	35.7612
955.043	35.8111
958.372	35.5486
961.701	33.6626
965.027	33.6785
968.354	31.7201
971.678	32.2336
975	32.8932
978.324	32.873
981.644	33.5933
984.962	34.6394
988.282	35.6724
991.598	35.1412
994.913	34.6312
998.227	33.7391
1001.54	31.6313
1004.85	29.885
1008.16	28.5601
1011.47	27.1085
1014.78	25.9056
1018.08	25.5884
1021.39	26.1596
1024.69	24.3824
1028	24.6253
1031.3	26.4068
1034.6	25.0849
1037.9	25.9424
1041.19	26.4043
1044.49	25.945
1047.79	26.509
1051.08	27.0435
1054.37	26.8928
1057.66	27.5856
1060.95	27.3773
1064.24	27.6653
1067.53	27.2565
1070.81	25.6699
1074.1	24.6685
1077.38	23.0244
1080.66	21.3192
1083.94	20.5415
1087.22	19.7326
1090.5	19.3096
1093.78	18.7269
1097.05	17.6149
1100.33	17.1749
1103.6	16.04
1106.87	15.2875
1110.15	17.0135
1113.41	16.5612
1116.68	16.0456
1119.95	16.5349
1123.21	15.471
1126.48	14.0767
1129.74	12.1182
1133	10.54
1136.26	10.0744
1139.52	10.5066
1142.78	10.8069
1146.04	10.4966
1149.29	10.0943
1152.55	9.61058
1155.8	7.69742
1159.05	6.88269
1162.3	6.77889
1165.55	6.64862
1168.8	6.91671
1172.05	8.31828
1175.29	8.17999
1178.54	9.13341
1181.78	8.29503
1185.02	8.22618
1188.26	9.47282
1191.5	9.31618
1194.74	10.3905
1197.97	10.3583
1201.21	10.5631
1204.44	9.91718
1207.68	10.3807
1210.91	13.0407
1214.14	16.2274
1217.37	19.2261
1220.6	22.2563
1223.82	24.3723
1227.05	26.6165
1230.27	28.8592
1233.49	32.0315
1236.72	35.9995
1239.94	37.5777
1243.16	39.9376
1246.37	42.3858
1249.59	46.1682
1252.8	49.46
1256.02	51.809
1259.23	54.4931
1262.44	55.2972
1265.66	58.3038
1268.87	60.9093
1272.07	63.3489
1275.28	65.3921
1278.48	67.6541
1281.69	69.9513
1284.89	71.3496
1288.09	74.2051
1291.3	76.1216
1294.49	76.9628
1297.69	76.4214
1300.89	76.851
1304.09	77.5025
1307.28	77.7409
1310.47	77.004
1313.66	76.8118
1316.86	75.8357
1320.05	75.0808
1323.23	74.6895
1326.42	74.4703
1329.61	73.0631
1332.79	70.7829
1335.98	69.3984
1339.16	66.6546
1342.34	64.9805
1345.52	63.4457
1348.7	61.3621
1351.87	59.9244
1355.05	58.5433
1358.23	55.1527
1361.4	52.6203
1364.57	48.6674
1367.74	45.6719
1370.91	43.3703
1374.08	40.9673
1377.25	40.5816
1380.42	39.046
1383.58	38.3401
1386.75	37.0691
1389.91	35.927
1393.07	36.3929
1396.23	36.5202
1399.39	35.2498
1402.55	35.8473
1405.7	37.5142
1408.86	39.6572
1412.01	41.2784
1415.17	45.3982
1418.32	49.0662
1421.47	52.8187
1424.62	57.547
1427.77	62.5074
1430.92	67.3208
1434.06	72.0161
1437.2	75.2979
1440.35	76.8693
1443.49	78.6891
1446.63	80.4558
1449.77	81.7383
1452.91	80.7118
1456.05	78.1141
1459.18	75.9806
1462.32	73.3201
1465.45	69.792
1468.59	64.1621
1471.72	59.7269
1474.85	54.9914
1477.98	49.6982
1481.11	45.3929
1484.23	40.5841
1487.36	36.1999
1490.48	32.055
1493.61	28.1798
1496.73	27.2252
1499.85	25.6789
1502.97	25.0832
1506.09	24.6489
1509.2	23.6683
1512.32	22.7608
1515.44	22.1824
1518.55	22.7658
1521.66	23.7627
1524.77	25.6188
1527.88	24.9815
1530.99	27.0504
1534.1	29.9547
1537.21	31.8484
1540.31	34.1394
1543.42	37.0082
1546.52	40.0566
1549.62	43.3569
1552.72	46.8382
1555.82	51.3482
1558.92	52.8684
1562.02	54.8916
1565.11	59.1888
1568.21	63.1149
1571.3	66.8699
1574.39	72.0245
1577.49	73.5407
1580.58	76.8522
1583.67	77.5307
1586.75	79.2605
1589.84	79.7607
1592.93	80.7659
1596.01	80.6841
1599.09	78.6748
1602.18	77.374
1605.26	75.3987
1608.34	73.7956
1611.41	71.4387
1614.49	69.224
1617.57	67.1113
1620.64	65.7173
1623.72	63.8777
1626.79	62.2569
1629.86	62.2188
1632.93	62.4355
1636	61.9906
1639.07	62.9832
1642.14	65.6814
1645.2	67.5528
1648.27	69.4563
1651.33	70.7536
1654.39	71.8163
1657.45	72.9135
1660.51	74.1453
1663.57	74.0753
1666.63	72.5366
1669.69	72.9204
1672.74	68.5905
1675.79	65.0016
1678.85	61.3979
1681.9	57.1656
1684.95	51.5874
1688	47.0588
1691.05	41.846
1694.1	37.3784
1697.14	33.4055
1700.19	28.9703
1703.23	24.5668
1706.27	21.217
1709.32	18.269
1712.35	14.9037
1715.39	14.0004
1718.43	12.2447
1721.47	10.5534
1724.5	9.17117
1727.54	9.66982
1730.57	10.2978
1733.61	9.83613
1736.64	8.03689
1739.67	8.63657
1742.7	6.96123
1745.72	5.56549
1748.75	4.56645
1751.78	4.89864
1754.8	3.99201
1757.82	4.05334
1760.85	3.84033
1763.87	3.1917
1766.89	3.26518
1769.91	3.42282
1772.92	3.73986
1775.94	2.38641
1778.96	3.19743
1781.97	4.21973
1784.98	4.0798
1788	4.25328
1791.01	4.47028
1794.01	4.58773
1797.02	4.6203
1800.03	5.22714
1803.04	3.90615
1806.04	3.46153
1809.05	2.54997
1812.05	3.09647
1815.05	3.06539
1818.05	3.48275
1821.05	4.03187
1824.05	3.94327
1827.05	3.61692
1830.04	3.72218
1833.04	3.59143
1836.03	3.51015
1839.03	4.21755
1842.02	4.66061
1845.01	4.24264
1848	4.37527
1850.99	3.78718
1853.97	4.03907
1856.96	4.4147
1859.94	4.85211
1862.93	5.49886
1865.91	5.05804
1868.89	4.05849
1871.87	3.62923
1874.85	2.7402
1877.83	3.30425
1880.81	3.80855
1882.56	3.63132
1885.55	4.67264
1888.54	5.02707
1891.52	5.82229
1894.51	5.84725
1897.49	5.58669
1900.48	5.51307
1903.46	6.57973
1906.44	7.28144
1909.42	6.93461
1912.4	7.24133
1915.38	6.25844
1918.35	6.59204
1921.33	5.8473
1924.3	5.49607
1927.28	5.59454
1930.25	4.99883
1933.22	5.26415
1936.19	3.48448
1939.16	2.20793
1942.13	2.30056
1945.09	1.06863
1948.06	1.35317
1951.03	1.27192
1953.99	0.934567
1956.95	1.07058
1959.91	1.88022
1962.87	1.2786
1965.83	0.622486
1968.79	0.118542
1971.75	0.0248775
1974.7	0.502134
1977.66	0.74033
1980.61	0.673497
1983.56	0.603037
1986.52	-0.222244
1989.47	-0.313597
1992.41	0.398491
1995.36	0.484257
1998.31	0.90291
2001.26	0.597511
2004.2	0.675757
2007.15	-0.408742
2010.09	0.329657
2013.03	0.387756
2015.97	0.666127
2018.91	1.36762
2021.85	2.40777
2024.79	2.90855
2027.72	3.37003
2030.66	3.95982
2033.59	4.81899
2036.53	5.73635
2039.46	6.55393
2042.39	7.07066
2045.32	7.48114
2048.25	9.15167
2051.18	9.58222
2054.1	10.6423
2057.03	10.5895
2059.95	11.9161
2062.88	13.3809
2065.8	14.273
2068.72	14.2301
2071.64	15.6706
2074.56	15.9028
2077.48	16.9661
2080.39	18.4972
2083.31	19.8956
2086.22	20.5795
2089.14	21.6769
2092.05	22.8527
2094.96	24.3079
2097.87	25.1847
2100.78	27.1248
2103.69	29.2888
2106.6	31.5911
2109.51	33.4318
2112.41	35.096
2115.32	37.3157
2118.22	39.4399
2121.12	41.2096
2124.02	43.8944
2126.92	45.6744
2129.82	49.6553
2132.72	52.9607
2135.62	56.8769
2138.51	60.7663
2141.41	64.414
2144.3	67.9736
2147.19	70.3896
2150.09	73.6085
2152.97	76.0523
2155.86	78.8848
2158.75	82.0075
2161.64	83.3301
2164.53	83.9303
2167.41	85.1344
2170.3	86.5863
2173.18	86.5902
2176.06	85.4527
2178.94	84.1137
2181.82	81.5977
2184.7	80.018
2187.58	76.5249
2190.46	73.0993
2193.33	70.5901
2196.21	67.3861
2199.08	65.147
2201.95	62.2822
2204.83	59.8906
2207.7	56.4893
2210.57	54.8333
2213.43	51.4154
2216.3	48.4359
2219.17	45.9529
2222.03	44.8293
2224.9	43.2901
2227.76	42.381
2230.62	41.5759
2233.49	39.3403
2236.34	38.3983
2239.2	37.2041
2242.06	35.931
2244.92	33.6762
2247.78	31.8447
2250.63	29.9458
2253.48	28.3173
2256.34	27.0048
2259.19	24.865
2262.04	23.2317
2264.89	21.3239
2267.74	19.095
2270.59	17.5938
2273.43	16.6689
2276.28	15.2351
2279.12	14.3266
2281.97	13.3309
2284.81	11.7346
2287.65	10.139
2290.49	10.1058
2293.33	8.55266
2296.17	8.00374
2299.01	9.65434
2301.84	10.7293
2304.68	11.2362
2307.51	11.1768
2310.35	10.8386
2313.18	11.493
2316.01	11.1321
2318.84	11.0138
2321.67	10.8268
2324.5	10.9864
2327.33	10.4522
2330.15	9.80462
2332.98	9.62821
2335.8	9.19505
2338.62	7.85315
2341.45	7.65968
2344.27	6.91151
2347.09	5.77425
2349.91	4.54403
2352.72	3.4256
2355.54	1.77783
2358.36	1.34318
2361.17	1.22308
2363.98	1.45429
2366.8	2.6985
2369.61	4.29788
2372.42	3.99525
2375.23	4.16872
2378.04	4.39003
2380.85	4.72815
2383.66	5.25527
2386.46	5.09222
2389.26	5.69762
2392.07	4.92225
2394.87	6.47022
2397.67	6.27103
2400.47	6.08098
2403.27	6.04734
2406.07	4.65276
2408.87	5.78284
2411.67	5.46587
2414.46	5.11775
2417.26	3.86135
2420.05	4.18561
2422.84	4.67414
2425.64	4.90066
2428.43	5.1312
2431.22	4.92407
2434.01	5.22177
2436.79	5.14831
2439.58	5.59067
2442.37	6.09346
2445.15	7.27364
2447.93	7.60286
2450.72	7.37997
2453.5	7.71939
2456.28	7.73108
2459.06	7.19686
2461.84	7.4422
2464.62	7.10438
2467.39	6.51322
2470.17	6.64973
2472.94	5.60021
2475.72	5.59477
2478.49	4.88033
2481.26	3.40907
2484.03	2.98188
2486.8	2.96399
2489.57	3.11459
2492.34	1.63285
2495.1	1.4994
2497.87	1.46452
2500.63	1.06792
2503.4	0.971056
2506.16	0.745871
2508.92	1.14323
2511.68	0.761009
2514.44	1.33307
2517.2	0.894715
2519.96	0.639099
2522.72	1.44541
2525.47	1.26987
2528.23	1.83275
2530.98	2.40969
2533.74	2.6859
2536.49	2.70714
2539.24	3.11839
2541.99	2.73253
2544.74	2.79302
2547.49	3.87125
2550.23	4.33483
2552.98	5.63318
2555.72	6.55467
2558.47	7.06143
2561.21	7.64073
2563.95	7.80297
2566.69	7.06477
2569.43	6.91294
2572.17	6.80955
2574.91	6.53126
2577.65	5.54856
2580.39	5.24369
2583.12	5.8106
2585.85	5.08839
2588.59	4.71693
2591.32	4.85715
2594.05	5.00682
2596.78	5.43235
2599.51	5.11305
2602.24	4.70275
2604.97	5.69358
2607.69	6.35321
2610.42	5.91518
2613.14	6.19067
2615.87	6.74285
2618.59	6.48636
2621.31	6.16646
2624.03	5.69457
2626.75	4.14174
2629.47	4.54994
2632.19	3.51009
2634.91	3.06507
2637.62	2.78948
2640.34	3.26171
2643.05	3.36287
2645.76	3.46991
2648.48	3.90146
2651.19	3.6507
2653.9	4.40087
2656.6	4.00842
2659.31	4.55363
2662.02	5.29055
2664.73	6.27071
2667.43	5.75666
2670.14	5.92389
2672.84	5.20156
2675.54	4.38371
2678.24	3.50488
2680.94	2.93165
2683.64	3.0339
2686.34	2.62708
2689.04	2.50131
2691.74	1.68603
2694.43	1.85506
2697.13	2.97271
2699.82	3.81445
2702.51	5.41834
2705.21	7.21065
2707.9	7.64064
2710.58	7.98619
2713.27	8.59551
2715.96	8.84909
2718.65	10.4619
2721.33	11.2445
2724.02	13.2324
2726.71	14.9037
2729.39	15.2276
2732.07	14.7407
2734.75	14.1488
2737.43	13.386
2740.11	13.1025
2742.79	12.6136
2745.47	11.7224
2748.14	10.8525
2750.82	9.88527
2753.49	8.97273
2756.17	7.43035
2758.84	6.51912
2761.51	6.14319
2764.18	5.32934
2766.85	4.29391
2769.52	3.61545
2772.19	1.71106
2774.86	1.14705
2777.52	-0.452346
2780.19	-0.480499
2782.85	0.378954
2785.52	0.388459
2788.18	0.030996
2790.84	0.813163
2793.5	0.837164
2796.16	0.206261
2798.82	-0.0197325
2801.48	-0.209547
2804.13	-0.200602
2806.79	-0.431598
2809.45	-1.12461
2812.1	-2.27091
2814.75	-2.4776
2817.41	-0.806423
2820.06	0.294119
2822.71	2.07053
2825.36	4.01747
2828	6.6884
2830.65	10.0553
2833.3	13.0185
2835.94	15.4143
2838.59	18.8235
2841.23	23.1344
2843.87	28.4423
2846.52	34.0972
2849.16	39.4078
2851.8	45.5819
2854.44	52.7649
2857.08	59.4295
2859.71	65.9298
2862.35	71.7875
2864.98	77.3744
2867.62	81.6981
2870.25	85.2948
2872.88	89.4494
2875.52	93.2649
2878.15	96.1915
2880.78	100.06
2883.41	103.244
2886.03	106.219
2888.66	108.866
2891.29	110.218
2893.91	113.799
2896.54	116.002
2899.16	119.496
2901.78	123.566
2904.4	128.903
2907.02	136.168
2909.64	143.808
2912.26	150.812
2914.88	157.734
2917.5	165.146
2920.11	171.592
2922.73	176.921
2925.34	181.33
2927.96	184.554
2930.57	185.798
2933.18	187.063
2935.79	186.625
2938.4	185.02
2941.01	181.921
2943.62	178.566
2946.22	174.135
2948.83	167.848
2951.43	161.94
2954.04	155.104
2956.64	148.632
2959.24	141.461
2961.84	134.414
2964.45	127.878
2967.05	120.743
2969.64	115.261
2972.24	109.498
2974.84	102.671
2977.43	96.8067
2980.03	90.7153
2982.62	83.3828
2985.22	76.4793
2987.81	69.2501
2990.4	62.3644
2992.99	55.6584
2995.58	49.1921
2998.17	43.0737
3000.76	37.4578
3003.34	32.4289
3005.93	27.4015
3008.52	22.9627
3011.1	18.5621
3013.68	15.686
3016.27	12.8247
3018.85	9.66169
3021.43	7.74558
3024.01	6.07897
3026.59	4.8763
3029.16	3.71233
3031.74	3.56881
3034.32	5.10489
3036.89	5.60032
3039.47	6.52231
3042.04	7.11963
3044.61	6.70413
3047.18	7.48715
3049.75	8.09546
3052.32	8.95029
3054.89	9.42269
3057.46	10.2264
3060.03	10.1356
3062.59	10.1253
3065.16	10.092
3067.72	8.78672
3070.29	8.40168
3072.85	7.1357
3075.41	6.27513
3077.97	5.34383
3080.53	4.43465
3083.09	3.39973
3085.65	2.60925
3088.21	2.31216
3090.76	1.8005
3093.32	2.20789
3095.87	2.92409
3098.43	3.30995
3100.98	3.50409
3103.53	4.454
3106.08	5.18836
3108.63	6.69193
3111.18	8.00578
3113.73	9.02915
3116.28	11.2561
3118.83	12.5503
3121.37	14.2527
3123.92	15.7158
3126.46	17.2199
3129	17.9502
3131.55	19.965
3134.09	21.1438
3136.63	22.9157
3139.17	24.3931
3141.71	25.7908
3144.24	27.6621
3146.78	29.4443
3149.32	31.6763