File: data/Raman/poly_smoothed/Thy_50_12_50_1x_45s_532 nm_x100_100%_600 gr_mm_01.txt
#Acq. time (s)=	45
#Accumulations=	2
#Range (cm-¹)=	200...3150
#Windows=	2
#Auto scanning=	Off
#Autofocus=	Off
#Macrospot=	Off
#AutoExposure=	Off
#Spike filter=	Multiple accum.
#Delay time (s)=	0
#Binning=	1
#Readout mode=	Signal
#DeNoise=	Off
#ICS correction=	On
#Dark correction=	Off
#Inst. Process=	Off
#Detector Gain=	Best Dynamic Range
#Detector ADC=	20 kHz
#Detector temperature (°C)=	-69.85
#Instrument=	LabRAM HR Evol
#Detector=	Synapse
#Objective=	x100
#Grating=	600 gr/mm
#ND Filter=	100%
#Laser (nm)=	532
#Hole=	100.021
#Range=	Auto
#Laser Pol.=	No
#Raman. Pol.=	No
#Laser Pol. (°)=	-0.0007625
#Raman Pol. (°)=	89.9995
#Collection=	Microscope
#StageXY=	Marzhauser
#StageZ=	Marzhauser
#X (µm)=	-5090.6
#Y (µm)=	1478.6
#Z (µm)=	63.8
#Full time(mm:ss)=	3:18
#Project=
#Sample=
#Site=
#Title=	Thy_50_12_50_2x_45s_532 nm_x100_100%_600 gr_mm
#Remark=
#Date=	07.07.2022 12:57
#Acquired=	07.07.2022 12:57:09
#Base:Fit=	10.08.2022 10:04:30
#Base:Sub=	10.08.2022 10:04:45
#Filter:Polynom=	16.08.2022 10:20:25
#AxisType[0]=Intens
#AxisUnit[0]=Cnt
#AxisType[1]=Spectr
#AxisUnit[1]=1/cm
200.43	29.1147
204.061	21.3376
207.688	17.4772
211.316	13.7677
214.941	11.3409
218.566	9.1137
222.188	7.48446
225.809	5.84625
229.43	4.60535
233.047	3.57231
236.663	3.51988
240.278	2.2395
243.894	2.28584
247.506	2.72799
251.116	4.08422
254.725	5.21185
258.333	6.17884
261.939	7.52723
265.546	8.43112
269.15	11.0941
272.752	12.4563
276.353	14.35
279.952	12.7786
283.55	15.2639
287.146	15.1619
290.739	17.1761
294.333	17.9907
297.925	16.7639
301.516	16.6131
305.106	17.7289
308.694	18.8436
312.279	18.1712
315.864	17.1259
319.448	15.9783
323.029	15.1768
326.61	14.4222
330.19	13.9199
333.766	14.1847
337.343	15.4167
340.917	15.177
344.491	16.3696
348.062	17.4987
351.633	18.2097
355.201	18.4952
358.77	18.2061
362.335	15.9801
365.899	15.6116
369.464	14.1179
373.025	14.0633
376.585	14.4002
380.143	13.8565
383.702	10.8232
387.258	9.4197
390.812	10.1319
394.365	9.29091
397.916	7.74307
401.467	4.73878
405.015	3.4382
408.565	2.73054
412.111	4.38446
415.656	4.89274
419.197	6.46349
422.739	7.99663
426.279	9.18063
429.819	11.778
433.356	13.2311
436.893	13.0425
440.428	12.8856
443.96	11.5579
447.492	11.7494
451.023	12.3527
454.553	13.1899
458.079	14.0038
461.606	14.5734
465.132	14.8304
468.654	13.3161
472.177	13.3241
475.696	13.2932
479.217	13.8839
482.733	14.9242
486.251	14.8969
489.765	15.6009
493.278	16.9756
496.791	17.9876
500.301	18.0336
503.81	19.0819
507.319	21.2721
510.825	22.0688
514.33	21.8992
517.833	22.2441
521.337	21.0393
524.838	18.8695
528.337	18.0292
531.835	17.0419
535.332	15.5776
538.827	14.8439
542.321	14.0423
545.814	13.0667
549.305	11.6067
552.795	9.8542
556.284	10.1754
559.771	8.35861
563.257	9.1743
566.742	8.19837
570.223	7.0899
573.705	5.60528
577.185	5.21082
580.665	5.65721
584.141	4.36404
587.617	4.53383
591.092	2.94397
594.564	4.09789
598.037	2.78071
601.506	2.49668
604.976	2.35611
608.443	2.24656
611.91	3.03253
615.374	3.7733
618.839	4.87783
622.3	6.39325
625.761	8.30045
629.221	9.04193
632.679	8.93665
636.135	9.39722
639.592	11.3361
643.045	12.2986
646.497	12.675
649.948	14.6092
653.398	16.5001
656.846	17.2738
660.293	18.5234
663.738	19.8428
667.185	19.5515
670.628	19.1146
674.067	18.9203
677.508	20.0271
680.947	20.9689
684.385	21.7925
687.821	24.4587
691.256	26.1211
694.69	28.1953
698.121	29.6001
701.552	30.6377
704.982	32.252
708.41	32.9973
711.836	32.6261
715.262	31.4745
718.685	32.8802
722.108	33.8429
725.53	35.6405
728.949	36.5425
732.369	38.6533
735.785	39.2232
739.2	38.9903
742.616	40.1751
746.028	42.1345
749.441	43.0335
752.851	43.9108
756.26	45.5674
759.667	49.391
763.075	51.556
766.479	53.9487
769.883	57.2418
773.285	60.5361
776.686	62.3433
780.085	64.9119
783.484	67.0377
786.881	69.1345
790.276	69.6238
793.671	69.9329
797.064	69.6289
800.456	71.4564
803.846	72.4912
807.236	71.7708
810.624	72.1242
814.01	70.6542
817.394	70.8287
820.778	71.1792
824.161	70.0361
827.543	70.0814
830.921	67.0748
834.3	65.5309
837.676	65.2806
841.053	63.3891
844.426	61.5537
847.8	59.5911
851.171	55.4141
854.542	54.0009
857.911	51.7827
861.279	49.4877
864.645	48.4816
868.01	46.0791
871.375	44.7356
874.737	42.0702
878.097	42.4516
881.457	42.2113
884.817	42.1511
888.174	40.7649
891.53	40.5635
894.884	40.6448
898.237	41.8468
901.589	43.1987
904.94	43.0201
908.289	43.3853
911.637	41.969
914.984	42.2974
918.33	40.8893
921.674	40.819
925.015	42.2211
928.357	40.7342
931.698	38.8639
935.037	38.2021
938.373	38.7485
941.71	36.6805
945.046	35.0234
948.378	34.0105
951.711	34.7413
955.043	35.1018
958.372	34.5372
961.701	34.36
965.027	34.2994
968.354	33.0182
971.678	33.2931
975	32.605
978.324	33.5354
981.644	32.1629
984.962	31.1496
988.282	31.1235
991.598	29.886
994.913	29.5517
998.227	28.7446
1001.54	26.8456
1004.85	28.5836
1008.16	27.9099
1011.47	26.866
1014.78	27.6114
1018.08	29.6407
1021.39	28.3966
1024.69	29.0068
1028	30.3272
1031.3	32.6011
1034.6	34.6811
1037.9	34.8398
1041.19	35.0868
1044.49	35.734
1047.79	34.4814
1051.08	33.4563
1054.37	33.138
1057.66	31.7674
1060.95	30.3258
1064.24	28.2964
1067.53	27.5072
1070.81	25.2854
1074.1	22.8142
1077.38	21.2595
1080.66	19.2817
1083.94	18.7539
1087.22	16.9054
1090.5	17.1843
1093.78	17.8708
1097.05	18.1751
1100.33	19.56
1103.6	19.304
1106.87	19.081
1110.15	18.8965
1113.41	17.9629
1116.68	16.5606
1119.95	15.6473
1123.21	15.1452
1126.48	13.5919
1129.74	12.2684
1133	12.1474
1136.26	10.9838
1139.52	11.4755
1142.78	10.7415
1146.04	9.78212
1149.29	7.96815
1152.55	6.48726
1155.8	4.99887
1159.05	4.79311
1162.3	3.88971
1165.55	4.76882
1168.8	6.10891
1172.05	8.16164
1175.29	8.14405
1178.54	7.81381
1181.78	7.31199
1185.02	6.90589
1188.26	5.55563
1191.5	5.93173
1194.74	6.99771
1197.97	8.44929
1201.21	8.59276
1204.44	10.326
1207.68	11.9261
1210.91	14.7529
1214.14	17.872
1217.37	20.1874
1220.6	22.0911
1223.82	22.8879
1227.05	24.0111
1230.27	26.2019
1233.49	27.3469
1236.72	28.5423
1239.94	30.9812
1243.16	33.8755
1246.37	35.8608
1249.59	37.2284
1252.8	38.1218
1256.02	39.3624
1259.23	41.1632
1262.44	42.2593
1265.66	42.5204
1268.87	43.8119
1272.07	46.6663
1275.28	49.3856
1278.48	50.7396
1281.69	52.7399
1284.89	54.7714
1288.09	56.4615
1291.3	57.4002
1294.49	59.0761
1297.69	59.4911
1300.89	58.5746
1304.09	59.6094
1307.28	60.6013
1310.47	60.4669
1313.66	59.4754
1316.86	60.1987
1320.05	60.094
1323.23	58.3323
1326.42	57.7862
1329.61	57.3686
1332.79	55.532
1335.98	53.5474
1339.16	53.1344
1342.34	52.5612
1345.52	50.846
1348.7	48.7234
1351.87	47.304
1355.05	44.6221
1358.23	42.4986
1361.4	40.0826
1364.57	38.6811
1367.74	36.8374
1370.91	35.6601
1374.08	33.6618
1377.25	32.1181
1380.42	31.5611
1383.58	32.4094
1386.75	33.853
1389.91	32.8784
1393.07	33.0052
1396.23	33.9574
1399.39	32.4086
1402.55	32.5333
1405.7	34.6109
1408.86	36.792
1412.01	39.5526
1415.17	42.9689
1418.32	47.027
1421.47	51.1688
1424.62	54.4721
1427.77	58.5032
1430.92	61.1723
1434.06	64.5042
1437.2	67.2705
1440.35	70.3841
1443.49	72.2178
1446.63	72.4146
1449.77	73.316
1452.91	73.4389
1456.05	71.493
1459.18	70.318
1462.32	67.3539
1465.45	63.2816
1468.59	57.553
1471.72	51.955
1474.85	45.6283
1477.98	40.1645
1481.11	35.7342
1484.23	32.5188
1487.36	29.0452
1490.48	25.4237
1493.61	22.5379
1496.73	19.9831
1499.85	18.4638
1502.97	16.9463
1506.09	14.9462
1509.2	14.7029
1512.32	14.157
1515.44	15.4627
1518.55	16.5121
1521.66	18.5974
1524.77	19.917
1527.88	20.8655
1530.99	23.034
1534.1	25.0299
1537.21	27.8979
1540.31	29.2627
1543.42	32.4039
1546.52	35.623
1549.62	39.8133
1552.72	43.3958
1555.82	47.4182
1558.92	50.6419
1562.02	52.6143
1565.11	54.8126
1568.21	57.4967
1571.3	59.1129
1574.39	60.5677
1577.49	62.8677
1580.58	63.3262
1583.67	64.5904
1586.75	65.0131
1589.84	65.9806
1592.93	65.3692
1596.01	64.1918
1599.09	64.1982
1602.18	62.112
1605.26	59.2637
1608.34	58.3776
1611.41	57.6858
1614.49	55.6924
1617.57	57.358
1620.64	57.4979
1623.72	57.7809
1626.79	58.3642
1629.86	59.1317
1632.93	58.3574
1636	58.9508
1639.07	61.1465
1642.14	61.5117
1645.2	63.1608
1648.27	63.8719
1651.33	65.3258
1654.39	65.7408
1657.45	65.2028
1660.51	65.6652
1663.57	65.0471
1666.63	63.0252
1669.69	60.5257
1672.74	57.3614
1675.79	53.1246
1678.85	48.7619
1681.9	44.5279
1684.95	41.7092
1688	37.5451
1691.05	35.1036
1694.1	30.0548
1697.14	26.9674
1700.19	21.5734
1703.23	19.0384
1706.27	17.0998
1709.32	14.3153
1712.35	14.0612
1715.39	11.5041
1718.43	10.1827
1721.47	9.3038
1724.5	7.10067
1727.54	6.84579
1730.57	6.74992
1733.61	7.4699
1736.64	8.04405
1739.67	7.16128
1742.7	5.92369
1745.72	5.23988
1748.75	4.84893
1751.78	4.9819
1754.8	4.93009
1757.82	4.80777
1760.85	5.11425
1763.87	4.44794
1766.89	2.71054
1769.91	3.30227
1772.92	3.59592
1775.94	3.7923
1778.96	4.85599
1781.97	5.02475
1784.98	4.58188
1788	3.42128
1791.01	2.56407
1794.01	2.53145
1797.02	2.886
1800.03	2.68434
1803.04	2.88147
1806.04	2.62299
1809.05	2.63728
1812.05	3.10606
1815.05	2.94908
1818.05	2.80183
1821.05	2.97177
1824.05	3.28409
1827.05	2.96116
1830.04	3.47827
1833.04	4.36338
1836.03	4.74005
1839.03	4.14806
1842.02	5.16786
1845.01	5.3894
1848	5.49206
1850.99	5.23575
1853.97	4.90273
1856.96	4.94039
1859.94	4.14132
1862.93	4.77922
1865.91	4.53885
1868.89	4.23744
1871.87	3.36419
1874.85	1.70554
1877.83	0.723999
1880.81	2.10524
1882.56	2.49733
1885.55	1.15608
1888.54	1.0073
1891.52	0.156201
1894.51	0.42777
1897.49	-0.152986
1900.48	0.0593463
1903.46	1.09014
1906.44	1.4362
1909.42	1.25591
1912.4	2.65631
1915.38	1.91031
1918.35	1.60465
1921.33	2.03341
1924.3	2.05483
1927.28	3.10551
1930.25	2.76701
1933.22	4.13184
1936.19	4.26727
1939.16	3.55647
1942.13	4.43191
1945.09	3.89953
1948.06	4.39433
1951.03	4.47231
1953.99	4.41538
1956.95	3.25797
1959.91	2.63122
1962.87	2.13159
1965.83	1.77243
1968.79	1.25234
1971.75	0.450264
1974.7	0.597428
1977.66	2.80876
1980.61	1.99001
1983.56	2.59805
1986.52	2.53494
1989.47	2.98965
1992.41	3.84689
1995.36	3.84643
1998.31	5.07488
2001.26	7.25514
2004.2	8.11984
2007.15	8.51431
2010.09	9.04254
2013.03	10.3603
2015.97	10.5562
2018.91	10.653
2021.85	10.5759
2024.79	10.4493
2027.72	10.3837
2030.66	10.2975
2033.59	10.384
2036.53	9.87885
2039.46	8.80571
2042.39	9.13993
2045.32	10.0601
2048.25	10.6429
2051.18	10.8637
2054.1	10.4051
2057.03	10.572
2059.95	10.0831
2062.88	10.1996
2065.8	10.5626
2068.72	12.7707
2071.64	12.4933
2074.56	12.847
2077.48	13.1769
2080.39	14.4419
2083.31	16.3427
2086.22	17.484
2089.14	18.9018
2092.05	20.1763
2094.96	21.2993
2097.87	23.7692
2100.78	25.2862
2103.69	27.7991
2106.6	29.6219
2109.51	31.449
2112.41	32.9003
2115.32	34.6913
2118.22	35.7749
2121.12	37.2988
2124.02	40.1224
2126.92	42.3083
2129.82	45.7441
2132.72	48.3973
2135.62	50.5934
2138.51	53.7493
2141.41	57.6694
2144.3	60.0649
2147.19	64.1876
2150.09	68.3017
2152.97	72.315
2155.86	75.3611
2158.75	77.9308
2161.64	80.0588
2164.53	81.4133
2167.41	83.472
2170.3	85.3196
2173.18	85.4088
2176.06	84.8544
2178.94	82.9591
2181.82	80.4162
2184.7	79.191
2187.58	75.8516
2190.46	73.8834
2193.33	71.4553
2196.21	68.9139
2199.08	65.4938
2201.95	62.5124
2204.83	59.077
2207.7	56.8499
2210.57	55.1949
2213.43	52.3215
2216.3	50.8777
2219.17	48.4922
2222.03	46.8923
2224.9	44.6698
2227.76	41.9015
2230.62	40.6278
2233.49	37.5414
2236.34	35.9107
2239.2	35.5578
2242.06	33.192
2244.92	31.3797
2247.78	30.3095
2250.63	29.408
2253.48	27.9583
2256.34	26.0684
2259.19	25.4206
2262.04	24.1513
2264.89	22.9916
2267.74	21.8537
2270.59	20.6335
2273.43	19.9787
2276.28	19.4389
2279.12	18.927
2281.97	18.0501
2284.81	17.1551
2287.65	16.4716
2290.49	13.8236
2293.33	12.4094
2296.17	11.4845
2299.01	10.4369
2301.84	10.0609
2304.68	8.46439
2307.51	9.1209
2310.35	7.95656
2313.18	7.74067
2316.01	8.85828
2318.84	8.54132
2321.67	8.92616
2324.5	8.38308
2327.33	9.50235
2330.15	9.78886
2332.98	10.0586
2335.8	9.20387
2338.62	9.85373
2341.45	9.27302
2344.27	8.73941
2347.09	9.19621
2349.91	9.02349
2352.72	8.93954
2355.54	7.2459
2358.36	7.07311
2361.17	6.11121
2363.98	5.95801
2366.8	6.73202
2369.61	5.55897
2372.42	4.7338
2375.23	4.13504
2378.04	3.54029
2380.85	3.29844
2383.66	3.78474
2386.46	3.79776
2389.26	3.09997
2392.07	3.73274
2394.87	3.39609
2397.67	3.57905
2400.47	2.79996
2403.27	2.71198
2406.07	3.09039
2408.87	2.3166
2411.67	2.94401
2414.46	3.81557
2417.26	4.16187
2420.05	5.03668
2422.84	5.74357
2425.64	6.94494
2428.43	8.09101
2431.22	8.16026
2434.01	8.69282
2436.79	8.68425
2439.58	7.81759
2442.37	7.32639
2445.15	6.4322
2447.93	6.33203
2450.72	6.68411
2453.5	6.89052
2456.28	5.99651
2459.06	5.58577
2461.84	5.16073
2464.62	4.13636
2467.39	3.11838
2470.17	2.41784
2472.94	2.63092
2475.72	2.35766
2478.49	2.42351
2481.26	2.34542
2484.03	2.9741
2486.8	4.03767
2489.57	3.30427
2492.34	4.2423
2495.1	3.20496
2497.87	2.82136
2500.63	1.82187
2503.4	1.57808
2506.16	1.16315
2508.92	0.212619
2511.68	-0.0607513
2514.44	-0.304031
2517.2	-1.04289
2519.96	-0.0420952
2522.72	0.0247498
2525.47	-0.382724
2528.23	-0.0314816
2530.98	-1.19174
2533.74	-0.298821
2536.49	-0.252762
2539.24	-0.811474
2541.99	0.3775
2544.74	2.45449
2547.49	3.22451
2550.23	4.10269
2552.98	5.21343
2555.72	5.32328
2558.47	5.41552
2561.21	6.42197
2563.95	6.15714
2566.69	6.14332
2569.43	7.3178
2572.17	8.17738
2574.91	7.76984
2577.65	7.69291
2580.39	7.74729
2583.12	7.37973
2585.85	7.00585
2588.59	7.14133
2591.32	6.44467
2594.05	6.64258
2596.78	6.55874
2599.51	5.79056
2602.24	4.43169
2604.97	3.96601
2607.69	4.16692
2610.42	5.50079
2613.14	5.34527
2615.87	4.47205
2618.59	3.74284
2621.31	4.97514
2624.03	4.76634
2626.75	4.58695
2629.47	3.83095
2632.19	4.40343
2634.91	5.5
2637.62	5.63156
2640.34	4.82357
2643.05	5.56118
2645.76	5.59273
2648.48	5.49136
2651.19	6.39144
2653.9	6.21404
2656.6	6.72503
2659.31	7.5816
2662.02	7.16669
2664.73	5.8355
2667.43	4.79604
2670.14	4.40842
2672.84	4.28233
2675.54	4.14223
2678.24	4.0845
2680.94	4.31247
2683.64	3.93882
2686.34	3.89563
2689.04	4.63049
2691.74	5.1182
2694.43	4.37473
2697.13	5.13754
2699.82	6.54315
2702.51	6.91212
2705.21	7.72566
2707.9	8.97071
2710.58	10.1619
2713.27	11.4209
2715.96	11.9009
2718.65	13.4495
2721.33	13.5766
2724.02	13.9889
2726.71	14.1522
2729.39	14.02
2732.07	13.9294
2734.75	13.5154
2737.43	12.6893
2740.11	11.6648
2742.79	11.8348
2745.47	11.4089
2748.14	10.8316
2750.82	9.86496
2753.49	8.73517
2756.17	8.17796
2758.84	7.45334
2761.51	6.60583
2764.18	7.40211
2766.85	7.53686
2769.52	6.5788
2772.19	6.27843
2774.86	4.59396
2777.52	4.09542
2780.19	4.0888
2782.85	4.34952
2785.52	3.40311
2788.18	3.8967
2790.84	4.62411
2793.5	4.76614
2796.16	4.90951
2798.82	5.1547
2801.48	4.65468
2804.13	4.74327
2806.79	5.52159
2809.45	6.03814
2812.1	6.80761
2814.75	7.40618
2817.41	7.55872
2820.06	9.50348
2822.71	12.7999
2825.36	15.7162
2828	19.9848
2830.65	24.5967
2833.3	27.4918
2835.94	31.3634
2838.59	35.005
2841.23	38.3663
2843.87	44.3699
2846.52	49.1844
2849.16	55.0464
2851.8	61.7026
2854.44	68.2457
2857.08	74.5847
2859.71	80.9968
2862.35	87.8317
2864.98	93.5704
2867.62	98.1387
2870.25	102.211
2872.88	107.136
2875.52	110.547
2878.15	113.623
2880.78	117.511
2883.41	121.672
2886.03	125.459
2888.66	128.859
2891.29	132.525
2893.91	136.36
2896.54	140.2
2899.16	144.87
2901.78	149.817
2904.4	156.021
2907.02	162.892
2909.64	170.656
2912.26	178.345
2914.88	185.861
2917.5	192.588
2920.11	199.948
2922.73	205.136
2925.34	208.799
2927.96	211.644
2930.57	213.005
2933.18	213.196
2935.79	211.293
2938.4	208.194
2941.01	203.539
2943.62	198.506
2946.22	193.131
2948.83	186.126
2951.43	177.776
2954.04	170.313
2956.64	162.19
2959.24	154.55
2961.84	147.984
2964.45	141.106
2967.05	134.641
2969.64	127.717
2972.24	121.057
2974.84	114.443
2977.43	107.153
2980.03	100.861
2982.62	93.976
2985.22	86.5665
2987.81	79.5584
2990.4	72.7867
2992.99	65.9948
2995.58	59.6443
2998.17	52.4255
3000.76	46.571
3003.34	41.717
3005.93	36.4801
3008.52	32.7569
3011.1	27.8843
3013.68	24.1827
3016.27	20.7534
3018.85	17.6741
3021.43	15.662
3024.01	13.7029
3026.59	12.6093
3029.16	11.7118
3031.74	10.603
3034.32	11.1284
3036.89	11.8874
3039.47	11.286
3042.04	11.6648
3044.61	12.1172
3047.18	12.8192
3049.75	12.9131
3052.32	14.0523
3054.89	14.0666
3057.46	14.2801
3060.03	14.3814
3062.59	14.5429
3065.16	13.3725
3067.72	11.3308
3070.29	10.9841
3072.85	9.89002
3075.41	8.24007
3077.97	6.75879
3080.53	5.57206
3083.09	4.87424
3085.65	4.94304
3088.21	4.7169
3090.76	4.56405
3093.32	4.86718
3095.87	4.22181
3098.43	4.30842
3100.98	4.33666
3103.53	4.39819
3106.08	4.59115
3108.63	4.78809
3111.18	6.10321
3113.73	6.17443
3116.28	6.5017
3118.83	6.96042
3121.37	6.92326
3123.92	7.22915
3126.46	6.81393
3129	5.89659
3131.55	5.94138
3134.09	6.62436
3136.63	6.54218
3139.17	6.70193
3141.71	8.37409
3144.24	9.31054
3146.78	10.4928
3149.32	9.8698