File: data/Raman/poly_smoothed/Thy_00_07_14_1x_45s_532 nm_x100_100%_600 gr_mm_01.txt
#Acq. time (s)=	45
#Accumulations=	2
#Range (cm-¹)=	200...3150
#Windows=	2
#Auto scanning=	Off
#Autofocus=	Off
#Macrospot=	Off
#AutoExposure=	Off
#Spike filter=	Multiple accum.
#Delay time (s)=	0
#Binning=	1
#Readout mode=	Signal
#DeNoise=	Off
#ICS correction=	On
#Dark correction=	Off
#Inst. Process=	Off
#Detector Gain=	Best Dynamic Range
#Detector ADC=	20 kHz
#Detector temperature (°C)=	-69.85
#Instrument=	LabRAM HR Evol
#Detector=	Synapse
#Objective=	x100
#Grating=	600 gr/mm
#ND Filter=	100%
#Laser (nm)=	532
#Hole=	100.021
#Range=	Auto
#Laser Pol.=	No
#Raman. Pol.=	No
#Laser Pol. (°)=	-0.0007625
#Raman Pol. (°)=	89.9995
#Collection=	Microscope
#StageXY=	Marzhauser
#StageZ=	Marzhauser
#X (µm)=	9025.6
#Y (µm)=	-3089.3
#Z (µm)=	-55.2
#Full time(mm:ss)=	3:05
#Project=
#Sample=
#Site=
#Title=	Thy_00_07_14_2x_45s_532 nm_x100_100%_600 gr_mm
#Remark=
#Date=	28.06.2022 11:06
#Acquired=	28.06.2022 11:06:46
#Base:Fit=	10.08.2022 10:06:44
#Base:Fit=	10.08.2022 10:07:16
#Base:Fit=	10.08.2022 10:07:25
#Base:Fit=	10.08.2022 10:07:44
#Base:Fit=	10.08.2022 10:07:56
#Base:Sub=	10.08.2022 10:08:40
#Filter:Polynom=	16.08.2022 10:26:06
#AxisType[0]=Intens
#AxisUnit[0]=Cnt
#AxisType[1]=Spectr
#AxisUnit[1]=1/cm
200.407	12.5314
204.035	16.0574
207.665	17.0153
211.291	17.6163
214.916	18.3606
218.541	18.8266
222.163	18.1117
225.785	16.2176
229.404	16.3443
233.022	14.3651
236.638	12.9112
240.255	11.9855
243.868	10.9197
247.48	8.93842
251.091	5.80801
254.702	4.45274
258.31	5.1761
261.916	3.23094
265.521	2.71035
269.125	2.34801
272.727	2.96955
276.328	1.35031
279.927	1.33885
283.525	1.09272
287.121	1.70543
290.716	0.964697
294.31	1.90663
297.9	4.59927
301.491	4.99883
305.081	6.59821
308.669	7.34452
312.256	8.56104
315.839	9.26515
319.423	11.7365
323.006	11.3846
326.585	12.4362
330.165	12.5103
333.741	13.2312
337.318	12.3267
340.894	10.9616
344.466	10.28
348.039	9.50697
351.608	8.179
355.176	8.47322
358.745	7.68484
362.31	5.31816
365.876	4.51863
369.439	4.56057
373	2.97543
376.56	1.52914
380.12	0.691511
383.677	1.54001
387.233	1.26395
390.787	1.36747
394.34	1.41325
397.894	1.65985
401.444	2.1934
404.993	2.1052
408.54	2.90798
412.086	2.58071
415.631	2.42633
419.174	4.08909
422.716	4.37339
426.257	4.49375
429.794	4.40227
433.332	5.15828
436.868	5.4404
440.403	5.02738
443.937	5.75059
447.468	6.17025
450.999	6.67817
454.528	8.22023
458.057	7.60399
461.582	8.6363
465.107	9.4764
468.629	9.56763
472.152	11.1445
475.672	12.3993
479.192	12.1419
482.709	12.3612
486.226	12.1942
489.74	12.4451
493.255	13.9748
496.767	15.5236
500.277	16.0712
503.788	16.775
507.295	17.7177
510.801	18.0435
514.308	18.98
517.811	19.2832
521.313	18.066
524.814	17.5457
528.313	19.2164
531.811	19.4689
535.308	19.7634
538.803	19.8039
542.297	18.9436
545.789	17.914
549.281	17.224
552.771	15.5365
556.259	14.1476
559.747	13.3352
563.233	10.4915
566.717	8.36334
570.2	6.24496
573.68	5.20939
577.161	4.59895
580.64	3.2636
584.118	1.95878
587.593	1.2763
591.068	0.994939
594.54	1.64344
598.013	1.38058
601.484	0.757177
604.952	1.13754
608.421	1.74875
611.886	3.19647
615.35	4.92499
618.815	5.51045
622.276	6.71256
625.738	8.49616
629.197	9.96515
632.655	10.2306
636.113	10.7094
639.568	10.9543
643.021	12.3882
646.473	14.2661
649.924	15.3526
653.376	17.109
656.824	17.9118
660.271	18.8796
663.716	19.8368
667.161	19.6105
670.604	19.8742
674.045	20.6407
677.486	21.1136
680.925	20.4565
684.361	21.6036
687.797	22.0216
691.232	22.9518
694.666	25.1075
698.099	26.5283
701.528	26.6011
704.958	27.8213
708.387	28.564
711.814	29.6549
715.238	31.5901
718.663	31.5865
722.084	33.8551
725.506	36.9995
728.925	39.5713
732.345	42.164
735.761	43.7826
739.178	44.4718
742.592	46.9125
746.006	49.7683
749.417	53.0604
752.827	55.624
756.236	59.7519
759.645	62.5965
763.051	64.6835
766.456	67.68
769.859	68.5337
773.261	70.683
776.664	71.2945
780.064	71.9539
783.462	73.2764
786.859	73.8057
790.255	75.2083
793.649	76.2535
797.042	76.6593
800.434	76.7268
803.823	75.6578
807.212	75.5114
810.6	75.7642
813.987	74.9123
817.372	74.292
820.754	73.5222
824.137	73.3626
827.519	74.802
830.897	75.4377
834.276	74.9191
837.654	75.0791
841.029	73.3183
844.404	70.4583
847.776	69.1135
851.149	66.2209
854.519	64.0825
857.889	62.392
861.256	60.8117
864.622	60.2229
867.988	58.671
871.351	58.3073
874.713	56.9959
878.074	56.236
881.435	53.1393
884.794	52.1196
888.15	49.6632
891.506	46.9492
894.861	46.0864
898.214	45.3088
901.566	45.5257
904.916	43.694
908.266	43.6614
911.614	43.1267
914.961	42.7259
918.306	43.2533
921.651	41.278
924.994	40.3503
928.336	40.3058
931.674	40.5702
935.014	40.6175
938.352	42.4861
941.687	43.4537
945.022	44.4297
948.357	44.6772
951.688	47.5311
955.02	49.0903
958.348	47.6097
961.678	45.5024
965.004	47.6655
968.331	49.9738
971.655	53.0642
974.979	55.5474
978.3	57.5462
981.62	57.8613
984.941	59.077
988.259	59.0022
991.575	58.2186
994.89	56.521
998.204	55.4412
1001.52	55.6254
1004.83	54.2009
1008.14	54.2412
1011.45	54.0833
1014.76	52.2847
1018.06	50.1531
1021.37	48.4145
1024.67	45.3536
1027.97	42.4511
1031.27	39.4064
1034.57	37.4385
1037.87	34.4672
1041.17	30.8105
1044.47	31.8116
1047.76	33.3013
1051.06	31.2862
1054.35	29.8322
1057.64	27.1814
1060.93	25.1984
1064.22	24.3082
1067.5	22.3632
1070.79	20.5496
1074.08	21.6137
1077.36	21.1593
1080.64	21.3662
1083.92	22.205
1087.2	22.5736
1090.48	23.341
1093.76	23.408
1097.03	24.2847
1100.31	25.305
1103.58	24.9823
1106.85	25.145
1110.12	25.335
1113.39	24.3297
1116.66	24.796
1119.93	23.9662
1123.19	20.7341
1126.46	18.8023
1129.72	17.4226
1132.98	14.6436
1136.24	13.2718
1139.5	11.8812
1142.76	10.826
1146.01	9.3478
1149.27	7.93235
1152.53	6.74602
1155.78	5.9003
1159.03	3.62854
1162.28	2.54041
1165.53	1.67727
1168.78	2.0581
1172.02	3.44773
1175.27	5.17895
1178.51	8.56944
1181.76	9.59917
1185	12.1181
1188.24	14.7891
1191.48	17.0624
1194.71	20.3615
1197.95	22.9113
1201.19	25.8277
1204.42	29.0898
1207.65	32.6637
1210.88	38.4054
1214.12	41.9684
1217.35	45.6092
1220.57	49.6708
1223.8	54.1554
1227.03	57.3023
1230.25	61.7646
1233.47	63.6037
1236.69	64.8985
1239.92	65.5943
1243.13	66.8608
1246.35	67.688
1249.57	69.0322
1252.78	69.6256
1256	70.0522
1259.21	69.62
1262.42	69.1334
1265.63	69.1315
1268.84	68.7863
1272.05	68.7991
1275.26	67.0326
1278.46	66.6937
1281.67	69.9193
1284.87	70.0626
1288.07	71.3487
1291.27	71.9928
1294.47	74.5262
1297.67	77.5186
1300.87	79.5892
1304.06	82.2847
1307.26	85.2185
1310.45	88.3563
1313.64	89.8923
1316.83	92.6464
1320.02	93.8512
1323.21	94.3724
1326.4	94.0349
1329.59	93.3709
1332.77	93.1291
1335.95	92.1009
1339.14	90.5919
1342.32	88.4673
1345.5	87.0771
1348.67	82.5704
1351.85	78.4815
1355.03	75.5876
1358.2	72.841
1361.38	69.3108
1364.55	65.2572
1367.72	61.6092
1370.89	58.8005
1374.06	56.641
1377.23	53.7854
1380.39	50.5242
1383.56	50.1081
1386.72	48.9521
1389.89	48.791
1393.05	46.361
1396.21	44.5763
1399.37	41.8715
1402.52	41.7618
1405.68	42.9061
1408.84	46.2573
1411.99	49.43
1415.15	53.145
1418.3	58.3498
1421.45	64.9729
1424.6	72.3576
1427.75	79.313
1430.89	87.7962
1434.04	95.2062
1437.18	101.571
1440.33	107.275
1443.47	112.169
1446.61	115.453
1449.75	116.767
1452.89	116.704
1456.03	114.645
1459.16	111.511
1462.3	106.991
1465.43	101.025
1468.56	91.9189
1471.7	82.7622
1474.83	72.5013
1477.96	63.2434
1481.08	54.9782
1484.21	47.287
1487.34	40.0648
1490.46	32.9143
1493.58	27.9833
1496.71	24.3278
1499.83	21.8193
1502.95	20.6596
1506.07	19.1683
1509.18	18.4583
1512.3	17.587
1515.41	17.7868
1518.53	18.4821
1521.64	19.6573
1524.75	20.8844
1527.86	22.779
1530.97	25.7564
1534.08	29.1588
1537.19	30.5824
1540.29	32.6922
1543.4	34.7872
1546.5	37.0389
1549.6	40.1389
1552.7	43.8876
1555.8	46.8768
1558.9	50.3501
1562	52.4393
1565.09	55.1895
1568.19	58.9868
1571.28	62.2394
1574.37	65.6152
1577.47	70.455
1580.56	73.7841
1583.64	77.1443
1586.73	80.4925
1589.82	83.6267
1592.9	85.3884
1595.99	85.9781
1599.07	87.2603
1602.15	87.2729
1605.23	87.0738
1608.31	85.3928
1611.39	82.9184
1614.47	80.7647
1617.55	79.2678
1620.62	78.4384
1623.7	77.9039
1626.77	77.1854
1629.84	77.2563
1632.91	77.5589
1635.98	78.2169
1639.05	80.0503
1642.11	82.222
1645.18	86.4816
1648.24	89.8433
1651.31	93.2278
1654.37	97.4842
1657.43	99.7026
1660.49	102.082
1663.55	102.009
1666.61	101.648
1669.66	99.353
1672.72	96.5818
1675.77	92.575
1678.83	87.1595
1681.88	80.917
1684.93	75.2491
1687.98	68.838
1691.03	61.791
1694.07	55.9636
1697.12	50.1607
1700.17	44.362
1703.21	39.4682
1706.25	34.3236
1709.29	29.1423
1712.33	25.3138
1715.37	21.9981
1718.41	20.2254
1721.45	18.4971
1724.49	17.2174
1727.52	16.2436
1730.55	15.635
1733.59	14.5906
1736.62	13.5656
1739.65	13.3077
1742.68	12.7058
1745.7	11.009
1748.73	9.51758
1751.76	8.26599
1754.78	7.66137
1757.8	6.86516
1760.83	6.9103
1763.85	6.60432
1766.87	5.6139
1769.89	5.47937
1772.9	5.09299
1775.92	4.07163
1778.94	3.19289
1781.95	2.29581
1784.96	1.96026
1787.97	1.82083
1790.99	2.18599
1794	2.18308
1797	2.36849
1800.01	2.2605
1803.02	1.76187
1806.02	2.19921
1809.03	1.99152
1812.03	3.07797
1815.03	3.08695
1818.03	2.91854
1821.03	2.65615
1824.03	3.13183
1827.03	3.93748
1830.02	3.27211
1833.02	4.34029
1836.01	4.08442
1839.01	4.19849
1842	3.79328
1844.99	3.37982
1847.98	1.89333
1850.97	1.56189
1853.95	1.16484
1856.94	1.46182
1859.93	1.39776
1862.91	1.05433
1865.89	0.525247
1868.87	0.968601
1871.85	1.22909
1874.83	1.22416
1877.81	2.03904
1880.79	2.14492
1882.52	2.66042
1885.51	2.97334
1888.5	3.35528
1891.49	3.78763
1894.47	4.54579
1897.46	4.52862
1900.44	4.33901
1903.42	4.79169
1906.4	4.52958
1909.38	3.0614
1912.36	2.70545
1915.34	2.00275
1918.32	1.57184
1921.29	2.99651
1924.27	4.03593
1927.24	4.07362
1930.21	3.69143
1933.18	3.47362
1936.15	3.17754
1939.12	4.96655
1942.09	4.58402
1945.06	4.35297
1948.02	4.80001
1950.99	5.40021
1953.95	4.70335
1956.91	6.10346
1959.88	6.62589
1962.84	6.82496
1965.8	7.46375
1968.75	7.80512
1971.71	7.36699
1974.67	6.53937
1977.62	6.18847
1980.58	5.61317
1983.53	4.04479
1986.48	4.68662
1989.43	4.14432
1992.38	4.78193
1995.33	5.04553
1998.27	3.94281
2001.22	3.07469
2004.16	2.11138
2007.11	2.36336
2010.05	1.92001
2012.99	2.3576
2015.93	2.30103
2018.87	2.53994
2021.81	4.57261
2024.75	4.47291
2027.69	4.80033
2030.62	6.39004
2033.56	6.8396
2036.49	6.21981
2039.42	6.84683
2042.35	6.28544
2045.28	5.56442
2048.21	6.01743
2051.14	5.11595
2054.07	5.22134
2056.99	4.43787
2059.92	5.31147
2062.84	5.37523
2065.76	6.65028
2068.68	6.53167
2071.6	6.20668
2074.52	6.31153
2077.44	8.0169
2080.36	7.60407
2083.27	8.3379
2086.19	7.88559
2089.1	8.49803
2092.02	8.59541
2094.93	8.68139
2097.84	7.44439
2100.75	7.09148
2103.66	6.89297
2106.56	5.14798
2109.47	5.00804
2112.38	4.33473
2115.28	4.32871
2118.18	3.93121
2121.09	3.23344
2123.99	2.84667
2126.89	2.92141
2129.79	2.86959
2132.68	3.93293
2135.58	3.84102
2138.48	3.54075
2141.37	3.6383
2144.27	4.59595
2147.16	5.76018
2150.05	5.28307
2152.94	5.45204
2155.83	5.72076
2158.72	6.49742
2161.6	7.32727
2164.49	6.65864
2167.38	6.1194
2170.26	5.19511
2173.14	5.05929
2176.03	5.22299
2178.91	4.99119
2181.79	5.60662
2184.67	5.19263
2187.54	5.28251
2190.42	3.96797
2193.3	3.64763
2196.17	3.20327
2199.05	2.26445
2201.92	2.48675
2204.79	3.20395
2207.66	2.72587
2210.53	2.83403
2213.4	3.28477
2216.27	4.08899
2219.13	5.03617
2222	6.21051
2224.86	6.38736
2227.72	7.24953
2230.59	7.05325
2233.45	7.14485
2236.31	6.96707
2239.17	6.17073
2242.03	7.22216
2244.88	7.74755
2247.74	8.40768
2250.59	8.50343
2253.45	8.39283
2256.3	7.97415
2259.15	7.18431
2262	7.04668
2264.85	6.94603
2267.7	5.46982
2270.55	5.87766
2273.4	6.55738
2276.24	6.03522
2279.09	6.25948
2281.93	6.30378
2284.77	6.34444
2287.62	6.21233
2290.46	5.87532
2293.3	4.50085
2296.13	3.76365
2298.97	4.19436
2301.81	5.10527
2304.64	6.03546
2307.48	6.79238
2310.31	6.61383
2313.14	7.39752
2315.98	5.86236
2318.81	6.45574
2321.64	6.71513
2324.46	5.85153
2327.29	5.1472
2330.12	4.92248
2332.94	4.54667
2335.77	4.30191
2338.59	3.92182
2341.41	4.7229
2344.23	5.12181
2347.05	4.93848
2349.87	3.33539
2352.69	2.64308
2355.51	1.69811
2358.32	0.88771
2361.14	-0.0576491
2363.95	0.60996
2366.76	1.83699
2369.58	2.30473
2372.39	1.43072
2375.2	1.26488
2378	1.42414
2380.81	1.38273
2383.62	1.16351
2386.43	1.39239
2389.23	0.799777
2392.03	1.17825
2394.84	1.67854
2397.64	1.82714
2400.44	2.75663
2403.24	4.04356
2406.04	5.08736
2408.84	6.6465
2411.63	8.03163
2414.43	8.48534
2417.22	8.53379
2420.02	8.49442
2422.81	8.70715
2425.6	9.03243
2428.39	8.87122
2431.18	8.14514
2433.97	8.35157
2436.76	7.01688
2439.54	5.99268
2442.33	5.3792
2445.12	4.20097
2447.9	3.80233
2450.68	2.45157
2453.46	1.00457
2456.24	1.01719
2459.02	0.600192
2461.8	1.08961
2464.58	1.37547
2467.36	1.68693
2470.13	2.17838
2472.91	2.22227
2475.68	2.84871
2478.45	2.71738
2481.23	2.51789
2484	2.48868
2486.77	2.61825
2489.54	2.86156
2492.3	2.67003
2495.07	2.87253
2497.84	1.8897
2500.6	2.37308
2503.36	1.47999
2506.13	1.8997
2508.89	1.34642
2511.65	0.806055
2514.41	0.771659
2517.17	1.14786
2519.93	1.90337
2522.68	2.46006
2525.44	2.88389
2528.19	2.94875
2530.95	3.71614
2533.7	3.84245
2536.45	3.90539
2539.2	3.49512
2541.95	3.80651
2544.7	3.94935
2547.45	3.91619
2550.2	3.91414
2552.94	3.31218
2555.69	3.8048
2558.43	3.55298
2561.18	3.73811
2563.92	3.79717
2566.66	4.19752
2569.4	4.64373
2572.14	5.35792
2574.88	5.78293
2577.61	4.63202
2580.35	4.36214
2583.09	4.23871
2585.82	4.96336
2588.55	5.05953
2591.29	4.24994
2594.02	4.58593
2596.75	4.9816
2599.48	4.61847
2602.21	4.45679
2604.93	5.0337
2607.66	5.06854
2610.39	4.68341
2613.11	4.40796
2615.83	5.22867
2618.56	5.90163
2621.28	6.50005
2624	6.3595
2626.72	7.0307
2629.44	7.2814
2632.15	7.99823
2634.87	9.02444
2637.59	9.75045
2640.3	9.9001
2643.02	9.28128
2645.73	8.69582
2648.44	8.85705
2651.15	9.45235
2653.86	9.16354
2656.57	9.05138
2659.28	9.129
2661.99	9.3145
2664.69	9.42795
2667.4	9.06945
2670.1	9.16574
2672.81	9.73155
2675.51	9.6748
2678.21	8.84923
2680.91	9.86655
2683.61	9.67645
2686.31	9.88488
2689	9.31254
2691.7	8.75775
2694.4	9.33296
2697.09	9.41015
2699.79	9.91179
2702.48	9.81142
2705.17	10.1097
2707.86	9.91954
2710.55	10.5895
2713.24	11.548
2715.93	12.2902
2718.62	13.2297
2721.3	13.6333
2723.99	14.8037
2726.67	15.943
2729.35	15.4706
2732.04	15.0596
2734.72	15.0686
2737.4	15.4284
2740.08	15.2814
2742.76	14.5877
2745.43	14.5199
2748.11	14.078
2750.79	13.5278
2753.46	13.015
2756.14	12.057
2758.81	10.6102
2761.48	10.0239
2764.15	8.49073
2766.82	6.90576
2769.49	6.49039
2772.16	6.76212
2774.82	5.63586
2777.49	5.45034
2780.16	4.8534
2782.82	4.3865
2785.48	2.97726
2788.15	3.38778
2790.81	2.5718
2793.47	0.824363
2796.13	0.360415
2798.79	0.924508
2801.44	1.45103
2804.1	1.6492
2806.76	1.54953
2809.41	0.981446
2812.07	1.44753
2814.72	1.87046
2817.37	3.0887
2820.02	4.97211
2822.67	7.65144
2825.32	11.5435
2827.97	15.6752
2830.62	20.9332
2833.26	26.2249
2835.91	32.9964
2838.56	38.9985
2841.2	46.8854
2843.84	56.4898
2846.48	67.2705
2849.12	79.9812
2851.77	92.9908
2854.4	107.424
2857.04	120.061
2859.68	134.67
2862.32	148.348
2864.95	160.518
2867.59	171.892
2870.22	181.958
2872.85	190.606
2875.48	198.944
2878.11	206.667
2880.74	213.189
2883.37	219.882
2886	225.76
2888.63	230.305
2891.25	236.269
2893.88	242.46
2896.5	248.175
2899.13	255.956
2901.75	264.726
2904.37	275.463
2906.99	289.208
2909.61	304.727
2912.23	320.438
2914.85	336.433
2917.46	351.397
2920.08	365.223
2922.7	376.473
2925.31	386.001
2927.92	392.285
2930.54	395.623
2933.15	395.362
2935.76	392.042
2938.37	386.669
2940.98	378.155
2943.58	367.979
2946.19	355.104
2948.8	340.726
2951.4	328.059
2954.01	314.34
2956.61	300.934
2959.21	286.207
2961.81	271.913
2964.41	259.821
2967.01	248.026
2969.61	236.577
2972.21	227.361
2974.81	216.256
2977.4	206.111
2980	195.37
2982.59	183.337
2985.18	171.187
2987.78	158.177
2990.37	144.986
2992.96	132.152
2995.55	119.103
2998.14	106.169
3000.73	93.2396
3003.31	80.4898
3005.9	68.9076
3008.48	59.0867
3011.07	50.4352
3013.65	43.8856
3016.23	37.2325
3018.81	30.9857
3021.4	27.5899
3023.97	23.8265
3026.55	21.3239
3029.13	18.5819
3031.71	18.2379
3034.28	19.1858
3036.86	20.0732
3039.43	21.2829
3042.01	22.8065
3044.58	25.3207
3047.15	26.5792
3049.72	28.0835
3052.29	30.0493
3054.86	31.5573
3057.43	31.7462
3060	30.9872
3062.56	30.082
3065.13	28.264
3067.69	26.761
3070.26	25.7175
3072.82	23.9839
3075.38	21.271
3077.94	17.6816
3080.5	14.9306
3083.06	12.3972
3085.62	9.02807
3088.18	6.70721
3090.73	3.99732
3093.29	2.05368
3095.84	0.639489
3098.4	-0.52669
3100.95	-0.413469
3103.5	0.35702
3106.05	1.56629
3108.6	1.62178
3111.15	2.32159
3113.7	4.45794
3116.25	5.18661
3118.79	6.31903
3121.34	7.75769
3123.88	9.38993
3126.43	10.1244
3128.97	12.231
3131.51	14.4381
3134.06	16.0956
3136.6	17.557
3139.14	18.8687
3141.67	19.773
3144.21	20.4276
3146.75	21.4142
3149.29	20.9044