File: data/Raman/poly_smoothed/Thy_00_07_41_1x_45s_532 nm_x100_100%_600 gr_mm_01.txt
#Acq. time (s)=	45
#Accumulations=	2
#Range (cm-¹)=	200...3150
#Windows=	2
#Auto scanning=	Off
#Autofocus=	Off
#Macrospot=	Off
#AutoExposure=	Off
#Spike filter=	Multiple accum.
#Delay time (s)=	0
#Binning=	1
#Readout mode=	Signal
#DeNoise=	Off
#ICS correction=	On
#Dark correction=	Off
#Inst. Process=	Off
#Detector Gain=	Best Dynamic Range
#Detector ADC=	20 kHz
#Detector temperature (°C)=	-69.85
#Instrument=	LabRAM HR Evol
#Detector=	Synapse
#Objective=	x100
#Grating=	600 gr/mm
#ND Filter=	100%
#Laser (nm)=	532
#Hole=	100.021
#Range=	Auto
#Laser Pol.=	No
#Raman. Pol.=	No
#Laser Pol. (°)=	-0.0007625
#Raman Pol. (°)=	89.9995
#Collection=	Microscope
#StageXY=	Marzhauser
#StageZ=	Marzhauser
#X (µm)=	-1462.5
#Y (µm)=	-619.9
#Z (µm)=	-228.45
#Full time(mm:ss)=	3:19
#Project=
#Sample=
#Site=
#Title=	Thy_00_07_41_2x_45s_532 nm_x100_100%_600 gr_mm
#Remark=
#Date=	29.06.2022 09:22
#Acquired=	29.06.2022 09:22:49
#Base:Fit=	10.08.2022 10:07:56
#Base:Sub=	10.08.2022 10:08:40
#Filter:Polynom=	16.08.2022 10:26:06
#AxisType[0]=Intens
#AxisUnit[0]=Cnt
#AxisType[1]=Spectr
#AxisUnit[1]=1/cm
200.523	22.7522
204.154	16.2656
207.781	12.205
211.409	9.71168
215.034	6.71306
218.659	6.94097
222.281	6.07806
225.903	4.59183
229.522	3.48921
233.14	4.77555
236.756	4.17118
240.373	5.32304
243.986	5.49825
247.598	6.2379
251.208	7.8849
254.818	8.1174
258.427	7.92984
262.034	7.90424
265.638	6.67233
269.242	6.50096
272.844	5.65181
276.445	6.28364
280.044	7.02243
283.642	6.11994
287.238	7.33467
290.833	8.16168
294.425	10.0579
298.017	11.6696
301.608	11.8937
305.198	13.2082
308.786	13.4498
312.371	13.0289
315.956	14.9821
319.54	16.6513
323.122	18.1967
326.701	19.3458
330.281	18.9106
333.857	20.0072
337.434	20.1669
341.008	19.9137
344.582	17.761
348.153	17.3737
351.724	15.5064
355.292	14.074
358.861	12.5327
362.426	13.3652
365.99	12.3549
369.555	10.7458
373.116	10.9572
376.676	11.7504
380.236	12.1673
383.793	10.3808
387.349	9.80696
390.903	8.39028
394.456	7.38964
398.007	6.50866
401.56	6.01903
405.108	6.22809
408.656	5.61951
412.202	5.72515
415.746	5.21086
419.29	4.23399
422.831	3.52938
426.37	4.61814
429.909	4.50921
433.447	2.95499
436.983	4.00779
440.519	5.14565
444.052	7.12761
447.583	8.86422
451.114	8.95181
454.643	9.13382
458.169	10.3695
461.696	13.0909
465.222	14.2743
468.744	14.4191
472.267	14.6171
475.787	14.7329
479.307	14.6895
482.823	14.3437
486.341	14.763
489.855	16.1764
493.37	17.8311
496.881	18.8999
500.391	18.8383
503.902	18.7828
507.409	17.9712
510.915	18.6743
514.42	19.2516
517.925	17.9006
521.427	18.4874
524.928	18.9561
528.427	19.7946
531.925	16.8819
535.422	15.3619
538.917	13.455
542.411	13.27
545.903	11.242
549.395	9.93544
552.884	7.12124
556.373	4.77377
559.86	4.37211
563.346	3.39814
566.831	3.70074
570.314	5.0598
573.794	6.51899
577.274	7.72507
580.754	9.22688
584.23	8.43335
587.706	9.30309
591.181	8.9176
594.653	9.148
598.126	10.3979
601.595	10.2746
605.065	11.2541
608.532	11.5503
611.999	11.1947
615.463	10.5943
618.928	10.294
622.389	9.69186
625.851	8.95796
629.31	9.05076
632.767	9.06581
636.223	10.3978
639.68	10.5773
643.134	11.7123
646.586	12.2958
650.037	13.6599
653.486	15.9303
656.936	16.7105
660.383	16.9513
663.829	18.2582
667.273	19.4407
670.716	18.9756
674.158	19.7516
677.598	19.3848
681.035	18.804
684.473	19.1705
687.909	21.3446
691.344	21.2418
694.778	22.406
698.211	23.9981
701.64	27.8883
705.07	28.4147
708.498	29.8376
711.924	31.9386
715.35	36.1767
718.774	39.0521
722.196	41.0492
725.618	40.7574
729.037	42.3851
732.456	44.0922
735.873	45.9474
739.289	48.4975
742.703	51.1428
746.116	53.6954
749.529	55.7618
752.938	58.4523
756.347	61.0818
759.756	64.1261
763.162	66.0724
766.567	68.9421
769.97	71.5516
773.372	74.4556
776.773	76.8661
780.174	78.5916
783.573	80.194
786.97	80.0323
790.365	80.1383
793.76	80.768
797.153	79.9243
800.543	79.7416
803.933	78.793
807.322	75.9243
810.71	74.7162
814.097	74.3822
817.483	75.1794
820.865	74.9694
824.248	73.8676
827.629	72.71
831.008	71.5652
834.387	72.1868
837.765	70.566
841.139	71.0578
844.514	69.6552
847.886	66.0079
851.259	64.0133
854.629	63.8008
857.997	61.193
861.366	58.2059
864.732	54.3765
868.098	53.0381
871.461	50.6111
874.823	48.198
878.184	45.2361
881.545	43.8656
884.903	44.2061
888.26	43.7036
891.616	43.9582
894.97	44.7314
898.323	46.9977
901.675	48.5641
905.026	47.5539
908.375	48.2276
911.723	49.2397
915.07	49.1263
918.415	50.4361
921.76	51.2063
925.103	50.2185
928.443	49.7445
931.783	48.3595
935.123	47.0644
938.461	46.2152
941.796	43.8559
945.131	40.1496
948.465	37.1919
951.797	35.06
955.128	32.5952
958.457	28.879
961.786	26.7616
965.113	27.749
968.44	27.1588
971.763	28.2251
975.086	28.8667
978.409	30.4424
981.729	30.9193
985.048	30.0356
988.367	28.9202
991.683	26.9691
994.998	26.5612
998.312	26.875
1001.62	27.5922
1004.94	28.1534
1008.25	29.2298
1011.56	27.8428
1014.86	26.3898
1018.17	25.6325
1021.48	25.3541
1024.78	22.6315
1028.08	20.6845
1031.38	20.2557
1034.68	19.162
1037.98	18.7038
1041.28	17.9293
1044.57	18.799
1047.87	19.23
1051.16	18.4861
1054.45	17.7563
1057.75	17.0524
1061.04	15.9467
1064.32	13.65
1067.61	13.1092
1070.9	11.9892
1074.18	11.7073
1077.47	12.3651
1080.75	12.837
1084.03	14.5613
1087.31	14.1389
1090.59	13.2867
1093.86	15.1246
1097.14	15.5159
1100.41	16.509
1103.69	16.538
1106.96	18.1331
1110.23	17.6255
1113.5	17.1109
1116.77	16.5888
1120.03	15.3494
1123.3	13.0912
1126.56	11.9002
1129.83	10.7548
1133.09	9.19225
1136.35	7.95672
1139.61	8.37609
1142.86	5.37531
1146.12	5.06178
1149.38	3.92238
1152.63	2.8206
1155.88	2.94875
1159.14	3.06683
1162.39	2.82758
1165.63	2.9839
1168.88	2.30251
1172.13	3.08623
1175.38	3.63017
1178.62	4.45155
1181.86	5.02593
1185.1	5.49991
1188.34	4.85287
1191.58	5.66434
1194.82	7.76657
1198.06	8.62274
1201.29	10.378
1204.53	13.0492
1207.76	16.1084
1210.99	18.2054
1214.22	21.2906
1217.45	24.2848
1220.68	28.1813
1223.91	33.8452
1227.13	37.0348
1230.36	40.5184
1233.58	42.8632
1236.8	44.759
1240.02	46.0949
1243.24	46.523
1246.46	47.0448
1249.67	47.0445
1252.89	47.2777
1256.1	47.8077
1259.32	45.2673
1262.53	42.8291
1265.74	42.6342
1268.95	40.6433
1272.15	41.4317
1275.36	40.767
1278.57	40.6568
1281.77	40.0436
1284.97	40.8155
1288.18	41.9756
1291.38	43.3659
1294.58	45.6478
1297.78	48.3067
1300.97	51.8333
1304.17	54.389
1307.36	58.2862
1310.55	62.2342
1313.75	64.6434
1316.94	66.1327
1320.13	67.11
1323.32	68.5527
1326.5	68.8923
1329.69	69.2565
1332.87	68.9308
1336.06	66.5736
1339.24	64.2819
1342.42	62.6068
1345.6	60.8113
1348.78	58.3043
1351.96	56.8901
1355.13	54.0469
1358.31	51.5398
1361.48	50.0061
1364.65	48.8266
1367.82	46.8368
1370.99	44.9865
1374.16	42.5428
1377.33	41.7541
1380.5	41.8381
1383.66	41.568
1386.83	41.5084
1389.99	39.8048
1393.15	37.685
1396.31	36.8227
1399.47	35.8464
1402.63	33.1157
1405.78	31.2668
1408.94	31.1947
1412.1	30.992
1415.25	32.2418
1418.4	34.6077
1421.55	37.2411
1424.7	41.2775
1427.85	45.6171
1431	49.7204
1434.14	53.8968
1437.29	59.615
1440.43	64.7597
1443.57	67.9194
1446.71	69.7571
1449.85	72.0481
1452.99	72.2313
1456.13	72.257
1459.26	73.5863
1462.4	71.836
1465.54	68.7452
1468.67	63.0724
1471.8	57.6024
1474.93	52.9579
1478.06	45.2145
1481.19	40.4484
1484.31	36.0336
1487.44	31.2323
1490.56	26.6408
1493.69	23.597
1496.81	19.7987
1499.93	17.1662
1503.05	15.3244
1506.17	13.9696
1509.28	12.8116
1512.4	12.107
1515.52	10.7202
1518.63	10.6559
1521.74	10.229
1524.85	12.4707
1527.96	13.5301
1531.07	13.8796
1534.18	16.3293
1537.29	17.4126
1540.39	18.5392
1543.5	18.7736
1546.6	21.5081
1549.7	23.9772
1552.8	26.5274
1555.9	28.5446
1559	31.0722
1562.1	33.3135
1565.19	34.4343
1568.29	36.6436
1571.38	39.4547
1574.47	41.598
1577.56	43.3308
1580.66	46.5334
1583.74	48.7987
1586.83	50.5429
1589.92	52.2703
1593.01	53.4416
1596.09	55.2991
1599.17	55.807
1602.25	55.3376
1605.34	54.6549
1608.41	54.9543
1611.49	54.698
1614.57	52.7888
1617.65	52.0737
1620.72	52.1774
1623.79	51.6857
1626.87	52.5128
1629.94	53.8157
1633.01	53.9987
1636.08	54.7171
1639.15	55.9859
1642.21	56.3235
1645.28	59.2872
1648.34	60.0256
1651.41	62.9032
1654.47	64.5491
1657.53	65.6762
1660.59	66.6973
1663.65	68.1965
1666.71	67.4068
1669.76	65.6052
1672.82	63.1138
1675.87	60.1727
1678.93	56.9087
1681.98	53.4319
1685.03	49.0851
1688.08	43.4853
1691.13	38.9278
1694.17	34.8077
1697.22	31.8792
1700.27	28.1735
1703.31	24.9628
1706.35	22.3013
1709.39	18.9107
1712.43	16.405
1715.47	14.5738
1718.51	12.942
1721.55	10.813
1724.58	9.88202
1727.62	9.51962
1730.65	7.85229
1733.68	7.81238
1736.72	8.50418
1739.74	8.17944
1742.77	7.69576
1745.8	7.62206
1748.83	7.00134
1751.85	7.17691
1754.88	6.34605
1757.9	5.56506
1760.92	4.5928
1763.95	5.60247
1766.96	5.55084
1769.98	5.10167
1773	5.72644
1776.02	5.38917
1779.03	4.82038
1782.05	4.71053
1785.06	4.7669
1788.07	4.52196
1791.08	3.40974
1794.09	2.83166
1797.1	2.18292
1800.11	2.51622
1803.12	2.05591
1806.12	1.85698
1809.12	1.78468
1812.13	1.88792
1815.13	2.50098
1818.13	3.49389
1821.13	4.07506
1824.13	3.60491
1827.13	4.12369
1830.12	3.12488
1833.12	3.83203
1836.11	4.07191
1839.1	4.67993
1842.09	4.73073
1845.09	5.6969
1848.08	6.27335
1851.06	6.45341
1854.05	5.60165
1857.04	6.18561
1860.02	5.63616
1863.01	5.32506
1865.99	4.75385
1868.97	5.24044
1871.95	4.63582
1874.93	4.5235
1877.91	3.84651
1880.89	3.02717
1882.46	3.32355
1885.45	3.43395
1888.43	3.69054
1891.42	2.90146
1894.41	2.36135
1897.39	2.14997
1900.37	1.03383
1903.36	1.07698
1906.34	2.92392
1909.32	3.413
1912.29	4.43409
1915.27	4.45837
1918.25	6.28328
1921.23	6.15205
1924.2	6.80914
1927.17	7.22853
1930.15	7.13917
1933.12	6.4703
1936.09	6.92931
1939.06	8.16942
1942.02	7.94926
1944.99	7.42084
1947.96	6.10837
1950.92	4.72746
1953.88	3.69809
1956.85	2.48708
1959.81	1.1779
1962.77	0.633465
1965.73	-0.251197
1968.69	-0.384919
1971.64	-0.98232
1974.6	-0.320029
1977.55	0.794148
1980.51	1.43148
1983.46	1.12709
1986.41	1.59127
1989.36	3.33437
1992.31	4.27207
1995.26	5.38037
1998.21	6.07439
2001.15	5.72328
2004.1	6.28746
2007.04	7.24005
2009.99	8.19415
2012.93	7.55713
2015.87	7.8799
2018.81	6.83161
2021.75	6.31483
2024.68	6.58136
2027.62	6.49508
2030.56	6.39813
2033.49	7.73373
2036.42	8.10426
2039.36	8.27455
2042.29	8.62517
2045.22	8.75059
2048.14	9.9607
2051.07	10.0619
2054	10.0988
2056.93	10.2186
2059.85	11.312
2062.77	11.4101
2065.7	11.4173
2068.62	11.2386
2071.54	11.4148
2074.46	11.1918
2077.38	11.3562
2080.29	11.8607
2083.21	12.4085
2086.12	12.1657
2089.04	12.2305
2091.95	12.2815
2094.86	11.5651
2097.77	10.8509
2100.68	9.72257
2103.59	9.59253
2106.5	9.07573
2109.41	8.37911
2112.31	7.58706
2115.21	8.12231
2118.12	7.80838
2121.02	7.185
2123.92	6.18841
2126.82	6.37662
2129.72	6.80506
2132.62	6.22887
2135.51	6.38373
2138.41	7.24371
2141.31	7.83301
2144.2	8.38275
2147.09	9.48633
2149.98	10.1861
2152.87	10.8434
2155.76	10.2257
2158.65	11.1586
2161.54	11.1613
2164.43	11.4192
2167.31	11.4539
2170.2	11.9505
2173.08	12.0375
2175.96	13.0717
2178.84	13.0174
2181.72	12.4561
2184.6	12.3909
2187.48	11.6923
2190.36	10.0978
2193.23	10.0597
2196.11	10.4557
2198.98	10.973
2201.85	10.5682
2204.72	11.1321
2207.59	11.1438
2210.46	11.0937
2213.33	10.1911
2216.2	10.0363
2219.07	9.2689
2221.93	8.50743
2224.8	8.6542
2227.66	8.188
2230.52	8.15382
2233.39	7.87694
2236.25	8.38128
2239.1	7.92608
2241.96	7.61508
2244.82	6.97798
2247.68	6.61149
2250.53	4.66893
2253.38	3.09782
2256.24	3.49749
2259.09	3.67041
2261.94	4.34162
2264.79	4.37213
2267.64	5.12288
2270.49	5.33088
2273.33	5.30744
2276.18	5.79563
2279.02	4.70897
2281.87	4.85233
2284.71	5.53997
2287.55	6.89256
2290.39	6.45439
2293.23	5.72837
2296.07	6.24179
2298.91	6.56382
2301.74	7.71612
2304.58	8.69843
2307.41	9.70299
2310.25	9.50079
2313.08	10.5722
2315.91	11.2675
2318.74	11.3041
2321.57	10.9616
2324.4	11.7369
2327.23	12.0478
2330.05	12.6818
2332.88	11.5516
2335.7	11.1874
2338.52	9.90665
2341.35	9.06289
2344.17	8.95051
2346.99	8.35155
2349.81	7.92963
2352.62	7.45676
2355.44	7.26948
2358.26	6.14934
2361.07	4.12704
2363.89	5.04744
2366.7	5.66273
2369.51	4.70356
2372.32	3.50414
2375.13	3.81516
2377.94	2.65253
2380.75	2.9903
2383.56	3.00021
2386.36	3.02351
2389.17	3.18185
2391.97	2.81844
2394.77	3.21627
2397.58	3.27046
2400.38	3.58246
2403.18	3.43039
2405.97	2.72608
2408.77	3.59455
2411.57	5.15021
2414.37	6.34906
2417.16	7.09413
2419.95	8.30605
2422.75	8.27971
2425.54	8.89674
2428.33	8.94758
2431.12	9.6711
2433.91	9.0059
2436.7	8.06878
2439.48	7.28982
2442.27	7.3327
2445.05	6.26532
2447.84	5.37306
2450.62	4.34694
2453.4	4.39553
2456.18	3.89384
2458.96	3.39741
2461.74	3.04669
2464.52	1.95186
2467.29	1.91028
2470.07	1.75245
2472.85	0.982399
2475.62	1.32569
2478.39	1.12188
2481.16	1.18086
2483.93	1.25404
2486.7	0.868031
2489.47	-0.449286
2492.24	-0.32183
2495.01	0.665248
2497.77	0.412452
2500.54	0.36868
2503.3	-0.610172
2506.06	-1.27384
2508.83	-1.22374
2511.59	-1.31634
2514.35	-1.81099
2517.11	-1.38404
2519.86	-0.636137
2522.62	0.292622
2525.38	0.411601
2528.13	0.778023
2530.89	1.22868
2533.64	1.64068
2536.39	1.09175
2539.14	1.33078
2541.89	1.55561
2544.64	1.49397
2547.39	1.74572
2550.14	2.06915
2552.88	1.88921
2555.63	0.92902
2558.37	1.26728
2561.11	2.5626
2563.86	2.02707
2566.6	1.97861
2569.34	1.62713
2572.08	1.90071
2574.82	2.18916
2577.55	3.11613
2580.29	3.73408
2583.02	4.00906
2585.76	4.25636
2588.49	5.37047
2591.22	4.4141
2593.96	4.7649
2596.69	5.27686
2599.42	5.79277
2602.14	5.12319
2604.87	4.6652
2607.6	5.26244
2610.32	4.36044
2613.05	3.93871
2615.77	4.08999
2618.49	4.18324
2621.22	3.2589
2623.94	3.61457
2626.66	3.93577
2629.37	3.82809
2632.09	3.15123
2634.81	3.36956
2637.53	2.8258
2640.24	3.44423
2642.96	4.00286
2645.67	3.78229
2648.38	3.69167
2651.09	3.70749
2653.8	3.76028
2656.51	3.75406
2659.22	4.5192
2661.93	5.78658
2664.63	4.811
2667.34	4.34056
2670.04	3.87154
2672.75	3.84081
2675.45	3.33702
2678.15	2.40484
2680.85	2.12431
2683.55	2.50435
2686.25	2.50389
2688.94	3.13696
2691.64	4.33062
2694.34	5.06339
2697.03	4.74922
2699.73	4.57342
2702.42	5.05758
2705.11	5.71842
2707.8	6.82672
2710.49	7.07283
2713.18	7.84897
2715.87	10.3146
2718.55	11.0781
2721.24	12.2019
2723.93	14.1836
2726.61	14.6689
2729.29	14.5902
2731.98	15.1766
2734.66	15.7991
2737.34	16.1018
2740.02	14.8742
2742.7	14.0246
2745.37	13.6002
2748.05	13.7655
2750.72	13.8549
2753.4	13.5489
2756.07	12.6057
2758.75	11.3363
2761.42	9.11483
2764.09	7.79523
2766.76	6.20361
2769.43	4.8769
2772.1	3.94638
2774.76	3.63505
2777.43	4.30432
2780.1	3.88731
2782.76	4.79684
2785.42	4.60375
2788.09	4.59686
2790.75	4.87162
2793.41	4.03151
2796.07	4.01077
2798.73	3.26207
2801.39	2.62724
2804.04	2.53047
2806.7	2.28098
2809.35	2.60374
2812.01	3.26649
2814.66	3.1383
2817.31	3.41181
2819.96	5.15592
2822.61	6.29785
2825.26	7.22616
2827.91	9.45253
2830.56	13.0239
2833.21	15.2371
2835.85	17.7008
2838.5	22.187
2841.14	27.7584
2843.78	33.5604
2846.42	40.7592
2849.06	47.8339
2851.71	55.4004
2854.34	63.0067
2856.98	70.2087
2859.62	77.6497
2862.26	86.0247
2864.89	94.0952
2867.53	100.942
2870.16	107.085
2872.79	113.241
2875.42	118.212
2878.05	124.077
2880.68	129.197
2883.31	134.106
2885.94	139.066
2888.57	141.977
2891.19	146.29
2893.82	150.248
2896.44	155.004
2899.07	159.509
2901.69	166.311
2904.31	173.979
2906.93	183.42
2909.55	192.264
2912.17	202.095
2914.79	210.579
2917.41	219.38
2920.02	226.033
2922.64	232.468
2925.25	238.039
2927.86	241.228
2930.48	241.691
2933.09	240.733
2935.7	239.675
2938.31	237.29
2940.92	232.037
2943.53	227.584
2946.13	220.825
2948.74	213.731
2951.34	206.499
2953.95	198.725
2956.55	191.718
2959.15	185.315
2961.75	178.779
2964.35	171.386
2966.95	165.06
2969.55	157.971
2972.15	152.245
2974.75	146.116
2977.34	138.858
2979.94	131.4
2982.53	123.683
2985.13	115.196
2987.72	106.701
2990.31	98.161
2992.9	89.9943
2995.49	81.5715
2998.08	73.1166
3000.67	64.356
3003.25	55.892
3005.84	49.188
3008.42	43.3291
3011.01	37.1849
3013.59	32.4384
3016.17	28.8378
3018.76	25.9911
3021.34	23.1065
3023.92	21.0827
3026.49	19.6417
3029.07	17.6073
3031.65	17.8129
3034.23	19.3366
3036.8	19.495
3039.38	20.1029
3041.95	20.8999
3044.52	21.9841
3047.09	23.1882
3049.66	24.1047
3052.23	24.718
3054.8	24.0672
3057.37	23.2425
3059.94	22.15
3062.5	21.0907
3065.07	20.2911
3067.63	19.129
3070.2	18.3752
3072.76	17.1161
3075.32	14.8101
3077.88	13.0408
3080.44	10.8727
3083	8.89052
3085.56	7.44754
3088.12	6.9351
3090.67	5.62312
3093.23	4.99492
3095.78	4.52666
3098.34	3.95407
3100.89	3.74161
3103.44	5.2475
3105.99	4.89528
3108.54	5.14128
3111.09	5.18203
3113.64	5.42712
3116.19	4.73644
3118.74	5.58674
3121.28	6.20332
3123.83	7.15422
3126.37	7.56998
3128.91	8.90601
3131.46	9.85577
3134	10.0142
3136.54	10.0436
3139.08	10.119
3141.62	10.9338
3144.16	11.8024
3146.69	13.0227
3149.23	13.9335