File: data/Raman/poly_smoothed/Thy_20_09_41_1x_45s_532 nm_x100_100%_600 gr_mm_01.txt
#Acq. time (s)=	45
#Accumulations=	2
#Range (cm-¹)=	200...3150
#Windows=	2
#Auto scanning=	Off
#Autofocus=	Off
#Macrospot=	Off
#AutoExposure=	Off
#Spike filter=	Multiple accum.
#Delay time (s)=	0
#Binning=	1
#Readout mode=	Signal
#DeNoise=	Off
#ICS correction=	On
#Dark correction=	Off
#Inst. Process=	Off
#Detector Gain=	Best Dynamic Range
#Detector ADC=	20 kHz
#Detector temperature (°C)=	-69.85
#Instrument=	LabRAM HR Evol
#Detector=	Synapse
#Objective=	x100
#Grating=	600 gr/mm
#ND Filter=	100%
#Laser (nm)=	532
#Hole=	100.021
#Range=	Auto
#Laser Pol.=	No
#Raman. Pol.=	No
#Laser Pol. (°)=	-0.0007625
#Raman Pol. (°)=	89.9995
#Collection=	Microscope
#StageXY=	Marzhauser
#StageZ=	Marzhauser
#X (µm)=	-5916.5
#Y (µm)=	2858.6
#Z (µm)=	-224.15
#Full time(mm:ss)=	3:19
#Project=
#Sample=
#Site=
#Title=	Thy_20_09_41_2x_45s_532 nm_x100_100%_600 gr_mm
#Remark=
#Date=	29.06.2022 13:33
#Acquired=	29.06.2022 13:33:09
#Base:Fit=	10.08.2022 09:52:02
#Base:Fit=	10.08.2022 09:52:12
#Base:Sub=	10.08.2022 09:54:21
#Filter:Polynom=	16.08.2022 10:24:04
#AxisType[0]=Intens
#AxisUnit[0]=Cnt
#AxisType[1]=Spectr
#AxisUnit[1]=1/cm
200.523	22.0132
204.154	17.7828
207.781	14.488
211.409	12.4487
215.034	11.8077
218.659	11.3738
222.281	10.9802
225.903	9.28951
229.522	9.16685
233.14	9.66328
236.756	8.66069
240.373	7.612
243.986	6.02945
247.598	5.26779
251.208	4.61875
254.818	4.60027
258.427	5.40385
262.034	5.03677
265.638	5.12369
269.242	4.90092
272.844	5.20871
276.445	2.82178
280.044	2.14495
283.642	2.85254
287.238	4.87296
290.833	4.35619
294.425	5.21743
298.017	6.25273
301.608	9.07669
305.198	8.96773
308.786	10.6455
312.371	10.8324
315.956	10.9712
319.54	12.0707
323.122	10.7974
326.701	9.5288
330.281	9.27453
333.857	8.2372
337.434	8.03791
341.008	6.36556
344.582	6.72605
348.153	5.75322
351.724	4.74608
355.292	3.48205
358.861	3.00399
362.426	1.10635
365.99	0.158382
369.555	2.18802
373.116	1.91919
376.676	1.71249
380.236	1.66692
383.793	2.72473
387.349	3.20189
390.903	3.73715
394.456	2.7564
398.007	4.79562
401.56	4.5826
405.108	5.84346
408.656	5.66666
412.202	6.34136
415.746	7.20162
419.29	7.02408
422.831	6.68301
426.37	6.33554
429.909	6.54808
433.447	6.64892
436.983	5.92652
440.519	5.86565
444.052	5.49547
447.583	6.31601
451.114	6.16516
454.643	6.33747
458.169	8.29574
461.696	7.7822
465.222	8.5334
468.744	9.61082
472.267	10.6695
475.787	12.3449
479.307	13.0005
482.823	14.7573
486.341	16.4421
489.855	16.5435
493.37	17.4835
496.881	19.8816
500.391	20.8416
503.902	20.7085
507.409	20.4836
510.915	19.6942
514.42	18.5754
517.925	16.7458
521.427	14.4457
524.928	13.4835
528.427	13.2999
531.925	14.4197
535.422	13.2994
538.917	12.0242
542.411	11.2922
545.903	12.0778
549.395	11.41
552.884	11.654
556.373	12.0443
559.86	10.5931
563.346	9.92406
566.831	9.38537
570.314	8.67489
573.794	7.8214
577.274	8.20153
580.754	9.32884
584.23	8.50933
587.706	6.74227
591.181	5.36481
594.653	2.88291
598.126	0.440885
601.595	0.519527
605.065	0.974448
608.532	2.96928
611.999	5.70021
615.463	8.48564
618.928	10.0023
622.389	11.2129
625.851	12.8436
629.31	14.7125
632.767	16.6058
636.223	17.5176
639.68	18.5442
643.134	19.0724
646.586	20.096
650.037	22.5354
653.486	23.409
656.936	24.6329
660.383	25.2594
663.829	25.6182
667.273	25.9024
670.716	26.3232
674.158	25.5202
677.598	24.9834
681.035	24.9081
684.473	26.0748
687.909	28.7821
691.344	29.3706
694.778	31.0818
698.211	30.1257
701.64	30.1877
705.07	30.2275
708.498	29.8552
711.924	29.6583
715.35	31.0804
718.774	32.9001
722.196	33.5716
725.618	34.9306
729.037	38.0913
732.456	39.1134
735.873	40.9959
739.289	41.3919
742.703	43.8363
746.116	46.7817
749.529	49.4767
752.938	52.4962
756.347	54.8108
759.756	57.4328
763.162	60.8318
766.567	63.7438
769.97	67.6825
773.372	67.5895
776.773	68.1889
780.174	69.8735
783.573	71.7152
786.97	72.5646
790.365	74.5488
793.76	75.9541
797.153	76.9735
800.543	79.3145
803.933	80.6326
807.322	82.116
810.71	83.0217
814.097	83.0319
817.483	83.3751
820.865	83.13
824.248	84.8747
827.629	84.1201
831.008	82.3636
834.387	78.7947
837.765	76.7051
841.139	74.4649
844.514	71.7121
847.886	67.7784
851.259	64.5323
854.629	60.1186
857.997	57.3717
861.366	53.0921
864.732	50.7405
868.098	48.4403
871.461	47.5398
874.823	45.9378
878.184	45.7032
881.545	43.941
884.903	44.3399
888.26	46.0638
891.616	46.8088
894.97	46.4431
898.323	47.7936
901.675	49.4688
905.026	49.3647
908.375	49.4182
911.723	48.6709
915.07	48.1174
918.415	47.546
921.76	47.2233
925.103	46.7547
928.443	45.0318
931.783	44.4216
935.123	44.3611
938.461	43.1379
941.796	41.1686
945.131	39.7287
948.465	37.5051
951.797	36.6869
955.128	35.8995
958.457	33.5974
961.786	30.2741
965.113	29.9255
968.44	30.3115
971.763	32.8568
975.086	30.1832
978.409	32.0889
981.729	33.7151
985.048	34.344
988.367	34.7509
991.683	34.318
994.998	34.5852
998.312	34.1707
1001.62	33.9332
1004.94	32.5871
1008.25	32.1718
1011.56	30.8529
1014.86	30.529
1018.17	29.7082
1021.48	28.8424
1024.78	28.2438
1028.08	27.0528
1031.38	25.0033
1034.68	23.777
1037.98	21.783
1041.28	19.3983
1044.57	20.8609
1047.87	23.0134
1051.16	22.9344
1054.45	22.5041
1057.75	20.9074
1061.04	21.0318
1064.32	19.6722
1067.61	17.6462
1070.9	14.548
1074.18	14.8461
1077.47	13.0626
1080.75	11.578
1084.03	8.93082
1087.31	9.5194
1090.59	9.84079
1093.86	9.45438
1097.14	10.4427
1100.41	11.5017
1103.69	11.9704
1106.96	11.8
1110.23	10.666
1113.5	10.6338
1116.77	10.029
1120.03	10.7877
1123.3	10.9023
1126.56	10.3063
1129.83	10.3216
1133.09	9.91648
1136.35	10.082
1139.61	9.98213
1142.86	10.9208
1146.12	10.7562
1149.38	8.88374
1152.63	9.84449
1155.88	9.85369
1159.14	9.84534
1162.39	8.27853
1165.63	9.16877
1168.88	10.9121
1172.13	10.6303
1175.38	10.9811
1178.62	12.2421
1181.86	13.6091
1185.1	13.5161
1188.34	14.3433
1191.58	14.2325
1194.82	16.4469
1198.06	17.2899
1201.29	19.325
1204.53	21.443
1207.76	24.4093
1210.99	29.7545
1214.22	33.3767
1217.45	38.0301
1220.68	42.0976
1223.91	45.3292
1227.13	47.5766
1230.36	50.9383
1233.58	54.7091
1236.8	57.931
1240.02	60.0136
1243.24	62.9846
1246.46	67.6128
1249.67	70.1974
1252.89	72.4508
1256.1	72.7779
1259.32	74.4864
1262.53	75.7229
1265.74	78.6358
1268.95	78.9828
1272.15	80.6442
1275.36	81.916
1278.57	84.624
1281.77	87.4648
1284.97	89.683
1288.18	92.4644
1291.38	96.0436
1294.58	97.8247
1297.78	100.047
1300.97	101.073
1304.17	103.789
1307.36	107.14
1310.55	109.714
1313.75	113.346
1316.94	116.148
1320.13	119.54
1323.32	122.208
1326.5	124.091
1329.69	125.253
1332.87	123.925
1336.06	122.134
1339.24	121.159
1342.42	120.629
1345.6	117.992
1348.78	114.144
1351.96	111.694
1355.13	110.244
1358.31	103.896
1361.48	99.4295
1364.65	93.9849
1367.82	89.5868
1370.99	83.7765
1374.16	77.0175
1377.33	70.6177
1380.5	67.5516
1383.66	65.7906
1386.83	64.0331
1389.99	61.6613
1393.15	59.1795
1396.31	58.9618
1399.47	57.1984
1402.63	57.3809
1405.78	57.1279
1408.94	56.215
1412.1	58.5574
1415.25	60.6928
1418.4	64.5822
1421.55	70.2347
1424.7	75.5726
1427.85	80.4378
1431	87.1536
1434.14	93.3315
1437.29	98.0606
1440.43	102.227
1443.57	103.634
1446.71	104.58
1449.85	103.498
1452.99	103.159
1456.13	103.596
1459.26	101.152
1462.4	96.7924
1465.54	91.6893
1468.67	84.8955
1471.8	76.8852
1474.93	70.1953
1478.06	61.9443
1481.19	56.4766
1484.31	48.9614
1487.44	44.0288
1490.56	39.2304
1493.69	36.7152
1496.81	34.5791
1499.93	34.0745
1503.05	33.8276
1506.17	33.1469
1509.28	34.1703
1512.4	34.0001
1515.52	33.4412
1518.63	34.4867
1521.74	35.2543
1524.85	37.9074
1527.96	39.2972
1531.07	41.7409
1534.18	42.5439
1537.29	44.6315
1540.39	48.2159
1543.5	50.6217
1546.6	53.9658
1549.7	56.9148
1552.8	59.114
1555.9	64.0477
1559	66.4761
1562.1	70.4397
1565.19	74.6432
1568.29	78.4721
1571.38	82.094
1574.47	85.5602
1577.56	90.0416
1580.66	92.9627
1583.74	95.7683
1586.83	98.0045
1589.92	99.2013
1593.01	102.076
1596.09	103.012
1599.17	104.31
1602.25	103.483
1605.34	102.584
1608.41	102.074
1611.49	98.3261
1614.57	95.3406
1617.65	92.4373
1620.72	90.1923
1623.79	88.2232
1626.87	86.1345
1629.94	83.7529
1633.01	83.7911
1636.08	84.3288
1639.15	84.4
1642.21	85.3446
1645.28	85.9797
1648.34	87.1009
1651.41	88.3626
1654.47	88.7028
1657.53	89.8946
1660.59	90.3923
1663.65	89.9295
1666.71	89.3212
1669.76	86.9864
1672.82	83.6627
1675.87	80.0473
1678.93	75.5239
1681.98	69.4103
1685.03	61.3905
1688.08	54.8837
1691.13	48.795
1694.17	42.6427
1697.22	36.4924
1700.27	29.8935
1703.31	24.3705
1706.35	20.4517
1709.39	18.6487
1712.43	14.631
1715.47	12.3784
1718.51	10.0202
1721.55	9.27961
1724.58	7.76058
1727.62	8.69044
1730.65	7.14291
1733.68	7.70608
1736.72	7.9099
1739.74	8.44938
1742.77	8.5928
1745.8	9.04753
1748.83	9.10828
1751.85	9.64629
1754.88	9.50926
1757.9	9.13013
1760.92	8.45193
1763.95	7.65345
1766.96	6.66978
1769.98	5.73974
1773	4.36603
1776.02	4.1039
1779.03	3.63438
1782.05	3.29076
1785.06	3.02414
1788.07	2.30364
1791.08	2.03199
1794.09	1.86411
1797.1	1.224
1800.11	0.288079
1803.12	-1.1172
1806.12	-1.54995
1809.12	-0.560359
1812.13	0.394843
1815.13	1.3681
1818.13	1.73016
1821.13	1.71599
1824.13	1.84382
1827.13	2.06585
1830.12	2.3451
1833.12	1.95376
1836.11	2.77267
1839.1	4.05957
1842.09	4.0447
1845.09	4.15854
1848.08	3.74745
1851.06	3.03589
1854.05	2.94299
1857.04	3.67906
1860.02	4.02921
1863.01	4.03659
1865.99	3.84474
1868.97	3.2148
1871.95	2.75309
1874.93	4.09842
1877.91	4.91006
1880.89	5.56758
1882.46	5.70044
1885.45	6.53541
1888.43	7.8756
1891.42	8.2946
1894.41	7.60633
1897.39	7.2989
1900.37	7.25731
1903.36	7.61995
1906.34	7.14513
1909.32	7.49831
1912.29	6.16716
1915.27	5.15738
1918.25	3.50012
1921.23	3.62066
1924.2	3.61165
1927.17	4.10113
1930.15	3.80105
1933.12	3.21683
1936.09	2.9676
1939.06	2.91653
1942.02	3.13704
1944.99	3.44773
1947.96	4.14949
1950.92	4.05011
1953.88	3.91055
1956.85	4.67376
1959.81	5.70293
1962.77	5.50501
1965.73	4.77383
1968.69	4.38211
1971.64	4.99908
1974.6	5.37422
1977.55	5.64761
1980.51	5.63042
1983.46	6.41163
1986.41	6.65186
1989.36	7.55958
1992.31	7.42978
1995.26	7.54769
1998.21	6.74966
2001.15	7.14217
2004.1	6.65129
2007.04	6.50814
2009.99	6.13295
2012.93	5.88786
2015.87	5.60351
2018.81	5.18355
2021.75	5.26631
2024.68	6.23859
2027.62	6.7713
2030.56	7.87
2033.49	7.5333
2036.42	7.5681
2039.36	7.71756
2042.29	8.93349
2045.22	10.9441
2048.14	12.7116
2051.07	13.495
2054	14.9856
2056.93	16.1743
2059.85	17.1904
2062.77	17.1505
2065.7	17.1864
2068.62	17.9574
2071.54	18.85
2074.46	19.3406
2077.38	20.4212
2080.29	19.4403
2083.21	18.9391
2086.12	18.9743
2089.04	19.2997
2091.95	18.8865
2094.86	18.6902
2097.77	18.6796
2100.68	18.7944
2103.59	18.2756
2106.5	18.1116
2109.41	19.0831
2112.31	20.793
2115.21	22.6819
2118.12	23.5787
2121.02	24.8071
2123.92	27.0508
2126.82	28.6728
2129.72	31.9909
2132.62	33.4023
2135.51	36.6064
2138.41	39.6541
2141.31	43.2245
2144.2	44.7558
2147.09	46.7735
2149.98	48.3957
2152.87	50.9704
2155.76	53.1413
2158.65	55.8142
2161.54	57.3483
2164.43	58.4367
2167.31	59.7149
2170.2	60.5031
2173.08	60.6246
2175.96	61.3626
2178.84	61.201
2181.72	61.2026
2184.6	60.8591
2187.48	59.8734
2190.36	58.2468
2193.23	57.3007
2196.11	55.4702
2198.98	53.5696
2201.85	51.0683
2204.72	47.8326
2207.59	44.9296
2210.46	41.9065
2213.33	38.3048
2216.2	34.5253
2219.07	32.055
2221.93	29.2039
2224.8	27.0768
2227.66	24.6373
2230.52	22.5467
2233.39	19.7774
2236.25	17.7606
2239.1	16.6364
2241.96	16.3964
2244.82	15.5917
2247.68	15.4778
2250.53	14.9178
2253.38	15.8545
2256.24	15.883
2259.09	16.2041
2261.94	15.9176
2264.79	15.8579
2267.64	15.0771
2270.49	15.3203
2273.33	14.762
2276.18	14.2652
2279.02	13.3665
2281.87	12.5784
2284.71	12.965
2287.55	12.5392
2290.39	11.2343
2293.23	9.60718
2296.07	8.65857
2298.91	8.39662
2301.74	7.5961
2304.58	7.31603
2307.41	8.0141
2310.25	9.43888
2313.08	8.63072
2315.91	8.72655
2318.74	9.40506
2321.57	8.69677
2324.4	8.7926
2327.23	8.30503
2330.05	8.63494
2332.88	7.83226
2335.7	7.28834
2338.52	7.56616
2341.35	7.27788
2344.17	6.65514
2346.99	6.55015
2349.81	5.8134
2352.62	4.99998
2355.44	4.59718
2358.26	2.42379
2361.07	1.54213
2363.89	1.14401
2366.7	1.06194
2369.51	0.924725
2372.32	1.00025
2375.13	0.860835
2377.94	0.663269
2380.75	0.0526235
2383.56	-0.74754
2386.36	-0.562608
2389.17	-0.974924
2391.97	-1.22765
2394.77	0.16775
2397.58	1.22671
2400.38	1.35719
2403.18	1.64822
2405.97	2.09567
2408.77	3.39948
2411.57	4.56905
2414.37	4.85203
2417.16	5.37432
2419.95	5.91321
2422.75	5.93954
2425.54	6.09081
2428.33	7.21755
2431.12	7.70608
2433.91	8.53006
2436.7	7.98856
2439.48	8.17336
2442.27	6.81259
2445.05	6.68506
2447.84	6.29908
2450.62	5.76876
2453.4	5.75094
2456.18	5.85886
2458.96	5.23709
2461.74	6.45757
2464.52	5.4024
2467.29	3.72412
2470.07	3.43742
2472.85	3.16921
2475.62	3.05085
2478.39	3.1543
2481.16	2.08169
2483.93	1.58293
2486.7	1.88059
2489.47	1.0078
2492.24	0.880199
2495.01	1.67073
2497.77	1.46087
2500.54	1.02031
2503.3	1.178
2506.06	-0.626171
2508.83	-0.3145
2511.59	-0.235417
2514.35	-0.0682609
2517.11	-0.339909
2519.86	0.599439
2522.62	1.46845
2525.38	2.44807
2528.13	3.30432
2530.89	2.98833
2533.64	3.24223
2536.39	3.99196
2539.14	3.64056
2541.89	4.43177
2544.64	5.00637
2547.39	5.30264
2550.14	6.103
2552.88	6.15172
2555.63	5.88777
2558.37	6.10022
2561.11	4.99235
2563.86	4.89502
2566.6	4.38198
2569.34	4.30921
2572.08	3.54301
2574.82	2.91033
2577.55	2.35627
2580.29	2.30653
2583.02	1.51875
2585.76	1.86277
2588.49	2.46995
2591.22	2.88673
2593.96	2.83859
2596.69	2.85543
2599.42	2.97637
2602.14	3.32073
2604.87	2.41789
2607.6	2.26078
2610.32	3.18808
2613.05	3.16466
2615.77	3.82778
2618.49	3.69183
2621.22	4.21154
2623.94	4.88443
2626.66	3.92154
2629.37	4.20176
2632.09	4.73497
2634.81	4.92847
2637.53	6.10457
2640.24	5.42431
2642.96	5.60592
2645.67	5.95733
2648.38	5.90405
2651.09	5.83995
2653.8	7.66305
2656.51	7.49941
2659.22	8.1172
2661.93	7.86568
2664.63	8.35279
2667.34	8.59356
2670.04	8.6444
2672.75	8.47017
2675.45	8.18617
2678.15	7.9736
2680.85	7.80021
2683.55	7.55139
2686.25	7.35838
2688.94	6.9772
2691.64	6.64506
2694.34	6.5422
2697.03	7.29564
2699.73	8.18865
2702.42	8.20565
2705.11	8.76266
2707.8	8.08242
2710.49	9.2837
2713.18	9.82718
2715.87	10.7595
2718.55	12.0511
2721.24	12.3401
2723.93	13.5723
2726.61	14.0303
2729.29	14.4174
2731.98	15.4843
2734.66	14.7758
2737.34	14.2811
2740.02	13.1797
2742.7	12.798
2745.37	12.6684
2748.05	12.4542
2750.72	11.7585
2753.4	10.8934
2756.07	10.0245
2758.75	8.05192
2761.42	7.2761
2764.09	6.61411
2766.76	6.24544
2769.43	5.25692
2772.1	3.85145
2774.76	3.56981
2777.43	3.96972
2780.1	3.59944
2782.76	3.65861
2785.42	3.24644
2788.09	2.6013
2790.75	2.68685
2793.41	1.88703
2796.07	1.88639
2798.73	2.03853
2801.39	2.37037
2804.04	3.17347
2806.7	3.39114
2809.35	3.36719
2812.01	3.03466
2814.66	2.16488
2817.31	2.23731
2819.96	4.62168
2822.61	6.89572
2825.26	10.7453
2827.91	16.1502
2830.56	21.0584
2833.21	26.7306
2835.85	32.433
2838.5	39.1575
2841.14	46.193
2843.78	55.2191
2846.42	64.8825
2849.06	75.4535
2851.71	85.9755
2854.34	96.9058
2856.98	109.119
2859.62	119.905
2862.26	129.966
2864.89	139.133
2867.53	147.233
2870.16	154.361
2872.79	161.327
2875.42	167.325
2878.05	172.305
2880.68	177.467
2883.31	183.141
2885.94	188.564
2888.57	193.334
2891.19	198.381
2893.82	202.888
2896.44	207.562
2899.07	212.942
2901.69	221.419
2904.31	230.065
2906.93	240.715
2909.55	252.693
2912.17	265.454
2914.79	277.875
2917.41	289.166
2920.02	298.915
2922.64	305.66
2925.25	310.413
2927.86	312.54
2930.48	313.683
2933.09	312.864
2935.7	309.974
2938.31	305.1
2940.92	297.684
2943.53	290.077
2946.13	280.863
2948.74	269.617
2951.34	258.205
2953.95	246.565
2956.55	235.234
2959.15	224.177
2961.75	213.037
2964.35	202.628
2966.95	193.223
2969.55	183.552
2972.15	174.79
2974.75	166.621
2977.34	157.962
2979.94	146.867
2982.53	135.634
2985.13	125.079
2987.72	113.349
2990.31	103.579
2992.9	92.6572
2995.49	82.878
2998.08	73.4798
3000.67	64.6439
3003.25	57.0859
3005.84	49.9321
3008.42	43.6665
3011.01	37.0805
3013.59	31.2995
3016.17	27.0646
3018.76	23.5799
3021.34	20.3313
3023.92	17.0494
3026.49	14.8402
3029.07	13.5336
3031.65	12.9484
3034.23	12.9435
3036.8	13.7062
3039.38	14.6216
3041.95	14.4018
3044.52	15.7785
3047.09	17.3778
3049.66	19.1761
3052.23	20.5014
3054.8	20.94
3057.37	20.8099
3059.94	19.7659
3062.5	20.1198
3065.07	19.6301
3067.63	18.2901
3070.2	16.3006
3072.76	14.5302
3075.32	12.2608
3077.88	10.3979
3080.44	8.76142
3083	7.35485
3085.56	4.14401
3088.12	2.22217
3090.67	1.41337
3093.23	0.863397
3095.78	0.687211
3098.34	0.905406
3100.89	0.135274
3103.44	-0.0869618
3105.99	-0.0221439
3108.54	1.62967
3111.09	1.31103
3113.64	1.68102
3116.19	2.01386
3118.74	2.24347
3121.28	2.34704
3123.83	2.7884
3126.37	3.98963
3128.91	3.41684
3131.46	3.2224
3134	3.60227
3136.54	4.02444
3139.08	4.56949
3141.62	4.46754
3144.16	4.28603
3146.69	4.5864
3149.23	4.60817