File: data/Raman/poly_smoothed/Thy_40_11_23_1x_45s_532 nm_x100_100%_600 gr_mm_01.txt
#Acq. time (s)=	45
#Accumulations=	2
#Range (cm-¹)=	200...3150
#Windows=	2
#Auto scanning=	Off
#Autofocus=	Off
#Macrospot=	Off
#AutoExposure=	Off
#Spike filter=	Multiple accum.
#Delay time (s)=	0
#Binning=	1
#Readout mode=	Signal
#DeNoise=	Off
#ICS correction=	On
#Dark correction=	Off
#Inst. Process=	Off
#Detector Gain=	Best Dynamic Range
#Detector ADC=	20 kHz
#Detector temperature (°C)=	-69.85
#Instrument=	LabRAM HR Evol
#Detector=	Synapse
#Objective=	x100
#Grating=	600 gr/mm
#ND Filter=	100%
#Laser (nm)=	532
#Hole=	100.021
#Range=	Auto
#Laser Pol.=	No
#Raman. Pol.=	No
#Laser Pol. (°)=	-0.0007625
#Raman Pol. (°)=	89.9995
#Collection=	Microscope
#StageXY=	Marzhauser
#StageZ=	Marzhauser
#X (µm)=	1956.2
#Y (µm)=	-46.2
#Z (µm)=	425.15
#Full time(mm:ss)=	3:18
#Project=
#Sample=
#Site=
#Title=	Thy_40_11_23_2x_45s_532 nm_x100_100%_600 gr_mm
#Remark=
#Date=	05.07.2022 11:29
#Acquired=	05.07.2022 11:29:56
#Base:Fit=	10.08.2022 10:01:35
#Base:Sub=	10.08.2022 10:01:52
#Filter:Polynom=	16.08.2022 10:21:53
#AxisType[0]=Intens
#AxisUnit[0]=Cnt
#AxisType[1]=Spectr
#AxisUnit[1]=1/cm
200.43	3.22802
204.059	3.79794
207.688	4.00281
211.314	3.52739
214.941	2.68783
218.564	3.73532
222.186	2.0165
225.809	1.50411
229.428	1.90769
233.045	0.757869
236.663	1.09077
240.278	0.269468
243.891	-0.312311
247.503	0.298309
251.116	0.117607
254.725	0.788478
258.333	0.293382
261.939	0.76044
265.544	1.06706
269.148	2.83145
272.75	1.94128
276.351	2.07587
279.95	3.51501
283.548	3.95043
287.144	3.98913
290.739	6.03613
294.333	5.88404
297.925	6.40887
301.514	6.96021
305.104	8.26724
308.692	7.92283
312.279	8.39586
315.862	9.20804
319.446	10.2491
323.029	10.5051
326.608	11.8909
330.188	12.1352
333.766	13.3871
337.341	14.617
340.917	14.1533
344.489	15.5229
348.062	15.9786
351.631	15.0303
355.201	14.3845
358.768	13.822
362.333	12.8257
365.899	13.3118
369.462	12.6114
373.023	10.4347
376.585	9.22962
380.143	8.69795
383.7	7.90582
387.256	7.74554
390.812	6.76999
394.365	5.67852
397.916	5.75481
401.467	5.50406
405.015	6.62246
408.563	7.46915
412.109	8.16547
415.654	10.3875
419.197	10.4788
422.739	11.1774
426.279	12.6382
429.819	13.5843
433.356	16.3107
436.891	16.118
440.426	16.3338
443.96	16.1563
447.492	18.6746
451.021	19.6236
454.551	20.4403
458.079	20.9068
461.604	22.0577
465.13	24.2039
468.654	25.307
472.175	26.3631
475.696	25.8638
479.215	25.2116
482.733	26.0071
486.249	26.7331
489.765	26.4648
493.278	26.8234
496.789	25.7208
500.301	26.443
503.81	26.6129
507.317	25.7924
510.825	25.5035
514.33	24.111
517.833	23.5347
521.335	21.8536
524.836	20.8421
528.335	20.3196
531.835	20.7161
535.332	19.996
538.827	21.0875
542.321	21.2164
545.814	21.5574
549.305	21.6435
552.795	21.9787
556.282	21.4196
559.769	19.8911
563.255	17.2239
566.739	17.2385
570.223	16.1407
573.705	14.4429
577.183	13.9874
580.663	11.5075
584.141	10.8801
587.615	11.6276
591.09	8.8105
594.564	7.42753
598.035	6.02397
601.506	4.40506
604.974	4.52807
608.443	5.07947
611.908	6.5251
615.374	7.31689
618.837	7.23491
622.3	7.92307
625.761	8.58509
629.219	9.60025
632.677	10.5202
636.135	11.3719
639.59	11.7783
643.043	13.183
646.495	13.6501
649.948	14.067
653.398	14.3526
656.846	15.1157
660.293	15.0431
663.738	15.3794
667.183	17.0271
670.626	17.9531
674.067	19.5569
677.508	19.8074
680.947	22.4695
684.385	22.9056
687.821	24.6908
691.254	27.3558
694.688	29.3045
698.121	30.5677
701.552	30.819
704.98	32.3019
708.409	33.8098
711.836	37.2467
715.26	39.3954
718.685	41.0016
722.108	43.1849
725.528	46.1019
728.949	46.3163
732.367	47.5868
735.785	49.7302
739.2	51.4778
742.614	52.6768
746.028	54.4224
749.439	56.712
752.849	58.9055
756.26	59.8372
759.667	60.2831
763.073	61.1017
766.477	62.3971
769.883	63.4299
773.285	66.2721
776.686	68.9857
780.085	72.1451
783.484	72.6909
786.881	76.3423
790.276	77.5225
793.671	78.7128
797.064	80.7572
800.456	81.8556
803.846	83.7364
807.234	85.9656
810.622	85.973
814.008	86.9897
817.394	89.7837
820.778	90.3864
824.159	89.1532
827.541	89.889
830.921	88.2911
834.298	86.7583
837.676	84.1452
841.051	82.2963
844.426	80.0116
847.798	77.0515
851.171	75.6075
854.54	71.7535
857.911	71.9173
861.278	69.8021
864.645	66.6278
868.01	63.4228
871.373	60.6083
874.735	57.041
878.097	55.1838
881.457	52.2142
884.815	52.199
888.172	50.3368
891.528	50.0667
894.882	47.8316
898.237	48.1551
901.589	46.8131
904.94	46.8884
908.289	45.793
911.635	46.2773
914.982	46.0328
918.328	46.3285
921.672	45.9695
925.015	46.7891
928.357	45.2695
931.698	46.2017
935.035	45.9715
938.373	47.0306
941.71	46.9672
945.044	45.382
948.378	44.6336
951.709	43.4063
955.041	42.4815
958.372	41.228
961.699	40.4506
965.027	40.2141
968.352	39.8601
971.676	39.0196
975	38.3721
978.322	36.994
981.642	36.228
984.962	35.4281
988.28	35.5157
991.596	35.855
994.911	36.4504
998.227	35.0499
1001.54	34.5696
1004.85	34.1774
1008.16	35.0314
1011.47	34.6353
1014.78	35.6582
1018.08	34.9603
1021.39	34.7511
1024.69	33.1385
1028	34.4363
1031.3	35.2144
1034.6	35.3588
1037.9	34.5874
1041.19	33.1798
1044.49	31.2915
1047.78	31.3467
1051.08	31.6624
1054.37	30.2627
1057.66	29.736
1060.95	29.4624
1064.24	28.7532
1067.53	29.0974
1070.81	28.766
1074.1	29.5689
1077.38	28.6462
1080.66	27.8031
1083.94	28.3201
1087.22	30.6335
1090.5	30.0575
1093.78	29.9084
1097.05	29.6386
1100.33	29.3916
1103.6	29.6198
1106.87	28.9161
1110.14	28.2077
1113.41	25.8745
1116.68	23.8882
1119.95	20.7089
1123.21	19.5497
1126.48	18.5472
1129.74	17.6297
1133	15.5116
1136.26	14.6647
1139.52	14.1668
1142.78	12.2668
1146.04	9.79428
1149.29	7.84835
1152.55	6.80542
1155.8	6.15908
1159.05	5.39232
1162.3	5.29035
1165.55	4.45247
1168.8	5.21377
1172.05	4.41356
1175.29	3.63123
1178.54	4.48407
1181.78	3.94766
1185.02	4.43414
1188.26	4.2665
1191.5	3.65791
1194.74	3.46113
1197.97	4.89193
1201.21	5.94006
1204.44	7.12689
1207.68	8.46848
1210.91	10.8228
1214.14	13.6237
1217.37	15.2988
1220.59	17.8898
1223.82	18.5268
1227.05	21.1736
1230.27	24.1836
1233.49	27.3237
1236.72	30.2454
1239.94	32.6447
1243.16	35.2168
1246.37	38.1656
1249.59	41.2371
1252.8	41.9319
1256.02	44.829
1259.23	46.4955
1262.44	49.2257
1265.66	50.6222
1268.86	52.1879
1272.07	53.8525
1275.28	55.4622
1278.48	57.0996
1281.69	58.3919
1284.89	60.147
1288.09	61.2975
1291.29	62.883
1294.49	63.7642
1297.69	65.4087
1300.89	65.7821
1304.08	67.3758
1307.28	68.2997
1310.47	68.8742
1313.66	69.5572
1316.85	69.325
1320.04	68.7698
1323.23	68.4196
1326.42	66.5851
1329.61	65.1371
1332.79	64.074
1335.97	63.3064
1339.16	60.8444
1342.34	59.3681
1345.52	56.436
1348.7	53.6923
1351.87	50.9502
1355.05	46.915
1358.22	44.9964
1361.4	42.8858
1364.57	40.5946
1367.74	39.5728
1370.91	38.2546
1374.08	37.9942
1377.25	36.6802
1380.41	37.0331
1383.58	36.4586
1386.74	34.6677
1389.91	33.7859
1393.07	32.5693
1396.23	32.4839
1399.39	30.9507
1402.55	30.0557
1405.7	30.7582
1408.86	29.9418
1412.01	30.8817
1415.17	32.2278
1418.32	33.5455
1421.47	36.5518
1424.62	38.9298
1427.77	42.0996
1430.91	47.4509
1434.06	51.7222
1437.2	56.6616
1440.35	59.0088
1443.49	62.3976
1446.63	64.5569
1449.77	65.1708
1452.91	65.1014
1456.05	63.7221
1459.18	61.4597
1462.32	58.5838
1465.45	54.7248
1468.59	50.7725
1471.72	46.6306
1474.85	42.2455
1477.98	37.1501
1481.1	32.8252
1484.23	28.7379
1487.36	22.9012
1490.48	20.9395
1493.61	17.2922
1496.73	15.1732
1499.85	14.291
1502.97	13.9373
1506.09	13.7879
1509.2	14.7343
1512.32	16.1802
1515.43	15.8635
1518.55	15.7357
1521.66	17.5924
1524.77	18.6591
1527.88	20.1194
1530.99	21.2698
1534.1	23.4279
1537.21	25.3272
1540.31	26.9553
1543.42	28.4415
1546.52	31.1465
1549.62	32.2929
1552.72	33.3905
1555.82	34.3379
1558.92	33.7454
1562.02	34.7932
1565.11	35.6496
1568.21	37.1372
1571.3	37.6199
1574.39	39.7538
1577.49	40.7946
1580.57	42.4362
1583.66	45.8714
1586.75	47.245
1589.84	48.2232
1592.92	48.5903
1596.01	50.8988
1599.09	51.0606
1602.17	51.9674
1605.25	51.8505
1608.33	51.83
1611.41	51.3563
1614.49	51.1464
1617.57	50.8509
1620.64	51.0986
1623.72	51.6797
1626.79	52.2076
1629.86	53.6453
1632.93	56.1998
1636	57.2231
1639.07	59.3416
1642.13	61.3275
1645.2	62.9255
1648.26	63.8346
1651.33	66.3596
1654.39	68.514
1657.45	68.9205
1660.51	69.7487
1663.57	68.1672
1666.63	65.7126
1669.68	63.5309
1672.74	61.1016
1675.79	57.0107
1678.85	54.3251
1681.9	49.4902
1684.95	44.9155
1688	39.6318
1691.05	36.0754
1694.09	33.2144
1697.14	29.5294
1700.18	26.0836
1703.23	22.9256
1706.27	20.5111
1709.31	17.6902
1712.35	14.5525
1715.39	13.3252
1718.43	11.3862
1721.47	9.7831
1724.5	8.71047
1727.54	9.50162
1730.57	9.09488
1733.61	8.5126
1736.64	8.12182
1739.67	7.22211
1742.7	6.90382
1745.72	7.00559
1748.75	6.51986
1751.77	6.98797
1754.8	5.6005
1757.82	4.43023
1760.84	4.65248
1763.87	5.27701
1766.89	6.00206
1769.91	5.77207
1772.92	4.59604
1775.94	4.81729
1778.95	5.05396
1781.97	4.18412
1784.98	3.84116
1787.99	3.08199
1791.01	2.15104
1794.01	1.71974
1797.02	1.96415
1800.03	2.1447
1803.04	2.77029
1806.04	2.93064
1809.05	2.46198
1812.05	1.44195
1815.05	1.08803
1818.05	1.03825
1821.05	1.02943
1824.05	1.64539
1827.05	1.39635
1830.04	1.27381
1833.04	1.73294
1836.03	2.14988
1839.03	1.7491
1842.02	2.07647
1845.01	1.01803
1848	1.28873
1850.99	1.28082
1853.97	0.323589
1856.96	-0.148631
1859.94	-0.185623
1862.93	0.441756
1865.91	1.07324
1868.89	0.9041
1871.87	1.51318
1874.85	1.95357
1877.83	2.85358
1880.81	3.21706
1882.57	3.32622
1885.56	3.8097
1888.55	4.47109
1891.54	5.37958
1894.52	5.23994
1897.51	6.04156
1900.49	6.95319
1903.47	6.9088
1906.45	7.87672
1909.43	7.21293
1912.41	7.51352
1915.39	6.50545
1918.37	6.10492
1921.34	5.89799
1924.32	4.56788
1927.29	4.67724
1930.26	3.72055
1933.23	3.89007
1936.2	2.89319
1939.17	1.79632
1942.14	2.04726
1945.11	2.13414
1948.07	1.73288
1951.04	1.25866
1954	0.611063
1956.96	0.102505
1959.93	-0.517764
1962.89	0.266024
1965.85	0.176257
1968.8	1.23608
1971.76	2.16363
1974.72	2.88961
1977.67	3.19912
1980.63	2.58863
1983.58	3.7068
1986.53	3.38309
1989.48	3.12381
1992.43	3.46181
1995.38	3.91944
1998.32	4.69902
2001.27	5.03834
2004.22	5.09233
2007.16	5.28487
2010.1	5.03428
2013.04	5.67335
2015.98	5.94672
2018.92	5.11019
2021.86	4.24255
2024.8	3.47245
2027.74	3.09593
2030.67	3.68857
2033.61	4.48802
2036.54	5.67635
2039.47	6.26611
2042.4	5.7908
2045.33	6.49368
2048.26	7.99906
2051.19	8.78006
2054.12	10.0711
2057.04	10.9661
2059.97	11.1344
2062.89	12.0056
2065.81	13.6498
2068.73	15.1497
2071.65	16.3692
2074.57	17.2788
2077.49	18.3133
2080.41	19.0418
2083.32	19.7945
2086.24	20.7427
2089.15	20.851
2092.07	21.5988
2094.98	23.158
2097.89	24.4545
2100.8	27.3309
2103.71	29.3716
2106.61	31.7009
2109.52	33.7544
2112.43	36.9346
2115.33	38.7564
2118.23	40.7573
2121.13	43.2982
2124.04	45.8812
2126.94	48.2313
2129.83	51.1057
2132.73	53.4924
2135.63	55.7741
2138.53	58.7634
2141.42	61.4338
2144.31	64.4649
2147.21	67.2093
2150.1	68.4929
2152.99	70.4678
2155.88	72.8967
2158.77	75.3029
2161.65	77.5512
2164.54	80.005
2167.43	81.8551
2170.31	81.693
2173.19	83.1048
2176.07	82.7101
2178.96	82.3696
2181.84	81.7013
2184.72	79.8425
2187.59	77.8491
2190.47	75.6302
2193.35	73.8899
2196.22	71.6118
2199.09	68.4204
2201.97	65.5685
2204.84	61.3028
2207.71	58.3745
2210.58	55.0807
2213.45	51.6958
2216.31	48.0551
2219.18	43.8216
2222.05	41.0347
2224.91	38.9608
2227.78	36.3056
2230.64	33.9604
2233.5	32.6277
2236.36	31.2469
2239.22	28.4163
2242.08	27.3343
2244.93	26.3939
2247.79	25.4162
2250.64	24.169
2253.5	23.1265
2256.35	22.4376
2259.2	20.7801
2262.05	20.0982
2264.9	19.4417
2267.75	17.948
2270.6	18.2664
2273.45	17.5956
2276.29	15.965
2279.14	14.7965
2281.98	13.821
2284.82	13.4177
2287.66	13.0904
2290.5	12.3796
2293.34	11.5953
2296.18	10.516
2299.02	10.9402
2301.86	11.9803
2304.69	11.4184
2307.53	10.9972
2310.36	11.1429
2313.19	11.4018
2316.02	10.8399
2318.85	9.225
2321.68	8.26789
2324.51	7.94902
2327.34	6.32799
2330.16	5.20687
2332.99	4.21734
2335.81	3.03119
2338.64	2.6451
2341.46	1.22181
2344.28	0.631705
2347.1	-0.416612
2349.92	-0.477546
2352.74	-0.456807
2355.55	-0.532334
2358.37	-0.382208
2361.19	-0.415613
2364	0.510071
2366.81	2.47743
2369.62	3.04616
2372.44	3.84299
2375.24	4.6797
2378.05	6.45816
2380.86	6.91093
2383.67	6.80423
2386.47	7.3188
2389.28	6.91404
2392.08	7.46509
2394.89	7.32525
2397.69	6.59667
2400.49	7.05889
2403.29	6.74571
2406.09	6.76746
2408.88	7.0036
2411.68	7.52437
2414.48	8.40669
2417.27	9.10245
2420.06	8.69235
2422.86	8.72441
2425.65	8.5113
2428.44	8.66091
2431.23	8.32983
2434.02	7.91744
2436.81	8.40713
2439.59	7.42793
2442.38	7.89585
2445.16	8.38147
2447.95	7.71262
2450.73	6.62667
2453.51	6.66128
2456.29	6.12251
2459.07	4.52886
2461.85	4.49179
2464.63	3.27851
2467.4	2.43006
2470.18	2.53621
2472.95	2.66643
2475.73	2.72348
2478.5	3.48939
2481.27	4.22166
2484.04	3.61156
2486.81	3.95624
2489.58	3.20869
2492.35	2.794
2495.12	2.83615
2497.88	2.97752
2500.65	4.03946
2503.41	4.25678
2506.17	4.48454
2508.94	4.62419
2511.7	5.50391
2514.46	4.80216
2517.22	4.94435
2519.97	5.14753
2522.73	4.40321
2525.49	4.76939
2528.24	5.16188
2530.99	5.7769
2533.75	6.01006
2536.5	6.9633
2539.25	7.72107
2542	7.51346
2544.75	7.35993
2547.5	7.19751
2550.24	7.73022
2552.99	8.29188
2555.74	8.68756
2558.48	8.29899
2561.22	7.95454
2563.96	7.53251
2566.71	7.23592
2569.45	6.6951
2572.18	5.71928
2574.92	5.18946
2577.66	4.72559
2580.4	3.6446
2583.13	2.16865
2585.87	2.41095
2588.6	1.07797
2591.33	1.28092
2594.06	1.49231
2596.79	1.91085
2599.52	2.09132
2602.25	1.6403
2604.98	1.5928
2607.71	1.38215
2610.43	1.42371
2613.16	2.12003
2615.88	3.04547
2618.6	4.06289
2621.32	3.93664
2624.04	3.69401
2626.76	2.65885
2629.48	2.70593
2632.2	2.5496
2634.92	3.02208
2637.63	2.37809
2640.35	2.96609
2643.06	3.90194
2645.77	3.91793
2648.49	3.33137
2651.2	4.50242
2653.91	4.55026
2656.62	5.46306
2659.33	6.3189
2662.03	6.7607
2664.74	7.44004
2667.44	7.49812
2670.15	7.51541
2672.85	7.35942
2675.55	8.43139
2678.26	8.18333
2680.96	8.04053
2683.66	8.00282
2686.35	7.83609
2689.05	7.05654
2691.75	6.49914
2694.44	5.96922
2697.14	6.22441
2699.83	7.42159
2702.52	8.13821
2705.22	7.82039
2707.91	9.1445
2710.6	9.637
2713.29	9.43266
2715.97	10.237
2718.66	10.7428
2721.35	11.919
2724.03	13.0951
2726.72	12.5129
2729.4	11.6667
2732.08	11.1229
2734.76	10.4016
2737.44	9.64287
2740.12	9.51406
2742.8	8.77999
2745.48	7.3138
2748.16	6.70776
2750.83	6.58362
2753.51	5.81446
2756.18	5.44458
2758.85	4.81761
2761.53	4.36571
2764.2	5.89295
2766.87	4.89957
2769.54	4.38153
2772.2	3.38017
2774.87	4.07101
2777.54	4.35542
2780.2	3.23483
2782.87	3.0847
2785.53	2.99463
2788.19	2.45369
2790.85	1.28252
2793.51	0.592652
2796.17	0.276252
2798.83	0.696964
2801.49	0.160054
2804.15	-0.0180982
2806.8	-0.0837607
2809.46	0.162913
2812.11	0.77438
2814.76	1.29415
2817.42	1.72719
2820.07	3.03862
2822.72	4.09066
2825.37	6.06844
2828.02	8.85716
2830.66	10.7355
2833.31	12.6549
2835.96	15.0857
2838.6	17.7715
2841.24	19.9618
2843.89	22.6947
2846.53	26.1779
2849.17	30.3395
2851.81	35.689
2854.45	40.8216
2857.09	47.2905
2859.72	53.2294
2862.36	59.6474
2865	65.8146
2867.63	71.4729
2870.26	76.9169
2872.9	82.1683
2875.53	87.0056
2878.16	92.202
2880.79	96.7244
2883.42	101.627
2886.05	106.007
2888.67	109.994
2891.3	114.223
2893.92	118.427
2896.55	122.305
2899.17	126.934
2901.79	131.57
2904.42	136.706
2907.04	143.515
2909.66	151.866
2912.27	159.077
2914.89	167.257
2917.51	175.647
2920.13	182.787
2922.74	189.467
2925.35	194.491
2927.97	198.282
2930.58	201.432
2933.19	201.868
2935.8	201.671
2938.41	201.316
2941.02	198.885
2943.63	195.364
2946.24	190.281
2948.84	184.678
2951.45	178.251
2954.05	170.751
2956.65	162.935
2959.26	154.779
2961.86	146.888
2964.46	139.483
2967.06	131.888
2969.66	124.747
2972.25	117.365
2974.85	110.94
2977.45	104.137
2980.04	97.5686
2982.64	90.8499
2985.23	83.9792
2987.82	76.2573
2990.41	69.7027
2993	63.6232
2995.59	57.3092
2998.18	51.5332
3000.77	46.155
3003.36	40.892
3005.94	35.4551
3008.53	30.7914
3011.11	26.524
3013.69	23.0015
3016.28	19.2203
3018.86	16.8201
3021.44	14.7
3024.02	12.5723
3026.6	11.0835
3029.18	10.6795
3031.75	9.98675
3034.33	9.87896
3036.9	10.8764
3039.48	11.5829
3042.05	11.7093
3044.62	12.7485
3047.19	13.1988
3049.77	13.1876
3052.34	13.5544
3054.9	14.0454
3057.47	13.6492
3060.04	13.1924
3062.61	12.47
3065.17	11.491
3067.74	10.607
3070.3	9.91546
3072.86	8.80326
3075.42	8.38444
3077.99	7.56107
3080.54	5.62802
3083.1	4.39429
3085.66	2.49097
3088.22	1.3449
3090.78	1.40989
3093.33	1.57223
3095.89	1.36567
3098.44	1.58558
3100.99	1.8658
3103.54	2.35091
3106.1	2.78399
3108.65	3.74337
3111.2	4.55752
3113.74	5.55533
3116.29	7.33881
3118.84	8.59972
3121.38	10.1793
3123.93	11.8699
3126.47	13.7892
3129.01	16.0183
3131.56	18.5424
3134.1	20.5288
3136.64	22.4127
3139.18	23.8092
3141.72	24.9181
3144.26	26.3026
3146.79	28.5184
3149.33	30.05