File: data/Raman/poly_smoothed/Thy_50_12_18_1x_45s_532 nm_x100_100%_600 gr_mm_01.txt
#Acq. time (s)=	45
#Accumulations=	2
#Range (cm-¹)=	200...3150
#Windows=	2
#Auto scanning=	Off
#Autofocus=	Off
#Macrospot=	Off
#AutoExposure=	Off
#Spike filter=	Multiple accum.
#Delay time (s)=	0
#Binning=	1
#Readout mode=	Signal
#DeNoise=	Off
#ICS correction=	On
#Dark correction=	Off
#Inst. Process=	Off
#Detector Gain=	Best Dynamic Range
#Detector ADC=	20 kHz
#Detector temperature (°C)=	-69.85
#Instrument=	LabRAM HR Evol
#Detector=	Synapse
#Objective=	x100
#Grating=	600 gr/mm
#ND Filter=	100%
#Laser (nm)=	532
#Hole=	100.021
#Range=	Auto
#Laser Pol.=	No
#Raman. Pol.=	No
#Laser Pol. (°)=	-0.0007625
#Raman Pol. (°)=	89.9995
#Collection=	Microscope
#StageXY=	Marzhauser
#StageZ=	Marzhauser
#X (µm)=	-5137.4
#Y (µm)=	1476.2
#Z (µm)=	63.15
#Full time(mm:ss)=	3:19
#Project=
#Sample=
#Site=
#Title=	Thy_50_12_18_2x_45s_532 nm_x100_100%_600 gr_mm
#Remark=
#Date=	07.07.2022 10:33
#Acquired=	07.07.2022 10:33:09
#Base:Fit=	10.08.2022 10:04:29
#Base:Sub=	10.08.2022 10:04:45
#Filter:Polynom=	16.08.2022 10:20:24
#AxisType[0]=Intens
#AxisUnit[0]=Cnt
#AxisType[1]=Spectr
#AxisUnit[1]=1/cm
200.43	-1.7125
204.061	3.56903
207.688	7.27108
211.316	10.2687
214.941	12.5837
218.566	13.3297
222.188	14.6144
225.809	17.0111
229.43	18.3827
233.047	19.3567
236.663	19.1162
240.278	18.8415
243.894	19.5603
247.506	18.1524
251.116	16.6026
254.725	16.1553
258.333	15.0622
261.939	15.5271
265.546	15.3034
269.15	15.5568
272.752	14.9998
276.353	15.5204
279.952	15.7736
283.55	16.9853
287.146	16.8077
290.739	18.6169
294.333	20.2731
297.925	21.7303
301.516	22.2602
305.106	23.8839
308.694	24.849
312.279	26.23
315.864	28.0172
319.448	27.0515
323.029	26.637
326.61	26.099
330.19	25.9659
333.766	25.1377
337.343	23.9084
340.917	23.6153
344.491	22.2647
348.062	20.9311
351.633	19.5068
355.201	18.2258
358.77	15.682
362.335	13.4068
365.899	13.6563
369.464	15.095
373.025	16.6607
376.585	15.0194
380.143	15.7189
383.702	15.6242
387.258	13.9271
390.812	13.1271
394.365	14.2074
397.916	12.3529
401.467	11.145
405.015	9.05015
408.565	8.30434
412.111	7.77253
415.656	5.82652
419.197	5.03027
422.739	4.24969
426.279	4.34575
429.819	1.97059
433.356	1.86521
436.893	1.18305
440.428	1.64452
443.96	2.48179
447.492	4.27713
451.023	6.26564
454.553	9.05254
458.079	9.1456
461.606	8.89984
465.132	11.171
468.654	11.1745
472.177	11.6638
475.696	12.1167
479.217	13.061
482.733	13.3632
486.251	13.4008
489.765	13.3409
493.278	14.4365
496.791	15.6827
500.301	15.3962
503.81	14.3991
507.319	14.9472
510.825	15.0616
514.33	12.6018
517.833	13.8152
521.337	13.9575
524.838	14.6053
528.337	14.2673
531.835	14.3376
535.332	12.91
538.827	11.2022
542.321	10.7501
545.814	8.82
549.305	7.75543
552.795	7.88128
556.284	6.27857
559.771	4.98397
563.257	4.48085
566.742	4.2437
570.223	3.0572
573.705	2.45101
577.185	2.44924
580.665	3.86386
584.141	2.44949
587.617	1.20326
591.092	1.2626
594.564	0.0808041
598.037	0.545847
601.506	0.941147
604.976	1.72321
608.443	3.03374
611.91	5.00129
615.374	4.66675
618.839	4.95469
622.3	5.71942
625.761	5.25397
629.221	6.41292
632.679	6.67158
636.135	7.95633
639.592	8.70411
643.045	8.16478
646.497	8.30137
649.948	9.05678
653.398	9.52614
656.846	12.3263
660.293	12.7576
663.738	14.8505
667.185	15.7683
670.628	15.7491
674.067	17.022
677.508	20.5406
680.947	21.2068
684.385	23.5269
687.821	25.1607
691.256	27.0816
694.69	29.2972
698.121	31.4497
701.552	31.7933
704.982	33.4283
708.41	33.8268
711.836	33.8464
715.262	34.2471
718.685	35.4699
722.108	33.5519
725.53	32.9094
728.949	33.2851
732.369	35.0987
735.785	36.4019
739.2	37.9815
742.616	40.3917
746.028	41.8866
749.441	44.5482
752.851	46.562
756.26	49.5684
759.667	53.1616
763.075	55.2066
766.479	56.9721
769.883	61.2651
773.285	63.3369
776.686	66.2615
780.085	69.8267
783.484	70.8326
786.881	72.8492
790.276	73.9867
793.671	75.5
797.064	75.3742
800.456	77.2669
803.846	78.6281
807.236	77.591
810.624	78.3914
814.01	78.3568
817.394	78.2147
820.778	78.5013
824.161	76.9878
827.543	74.6139
830.921	72.5552
834.3	70.8089
837.676	68.6641
841.053	64.5188
844.426	60.9428
847.8	58.3827
851.171	55.2539
854.542	53.7385
857.911	50.0351
861.279	48.7001
864.645	47.496
868.01	46.8866
871.375	46.9996
874.737	46.8688
878.097	46.6958
881.457	46.2945
884.817	46.6784
888.174	46.6703
891.53	47.1519
894.884	48.3974
898.237	47.4602
901.589	47.4753
904.94	46.9833
908.289	45.4465
911.637	46.1551
914.984	46.1947
918.33	45.2247
921.674	45.5173
925.015	43.3078
928.357	42.626
931.698	42.8997
935.037	41.6814
938.373	40.3127
941.71	39.1324
945.046	38.9655
948.378	38.6127
951.711	36.7302
955.043	36.1426
958.372	34.4751
961.701	31.9811
965.027	30.9641
968.354	29.7178
971.678	27.9413
975	25.8896
978.324	24.0885
981.644	21.9622
984.962	21.6194
988.282	21.686
991.598	19.961
994.913	21.5638
998.227	20.7398
1001.54	20.6408
1004.85	20.3459
1008.16	19.0336
1011.47	18.5235
1014.78	18.7067
1018.08	20.2014
1021.39	20.9335
1024.69	21.5059
1028	23.4705
1031.3	25.0509
1034.6	27.1519
1037.9	27.9108
1041.19	27.7842
1044.49	27.4263
1047.79	27.3349
1051.08	26.2511
1054.37	25.7777
1057.66	26.848
1060.95	26.8381
1064.24	26.9637
1067.53	25.8002
1070.81	26.8382
1074.1	24.96
1077.38	23.0983
1080.66	21.4932
1083.94	18.7581
1087.22	15.9874
1090.5	14.4341
1093.78	12.781
1097.05	13.2315
1100.33	11.0647
1103.6	10.3954
1106.87	10.6993
1110.15	10.7592
1113.41	10.7088
1116.68	9.51352
1119.95	7.15462
1123.21	6.21681
1126.48	5.16819
1129.74	4.59522
1133	5.147
1136.26	6.33766
1139.52	6.11236
1142.78	5.1475
1146.04	5.7443
1149.29	6.32135
1152.55	8.60572
1155.8	7.84643
1159.05	7.20051
1162.3	6.94785
1165.55	5.71984
1168.8	5.84522
1172.05	7.1752
1175.29	7.40174
1178.54	8.18781
1181.78	8.88326
1185.02	11.8852
1188.26	12.7583
1191.5	12.882
1194.74	13.0852
1197.97	12.9613
1201.21	11.6298
1204.44	12.0563
1207.68	12.6486
1210.91	13.6196
1214.14	16.3567
1217.37	17.8118
1220.6	19.7466
1223.82	21.7071
1227.05	25.8395
1230.27	29.1662
1233.49	30.5471
1236.72	33.4947
1239.94	34.9379
1243.16	37.4886
1246.37	40.6352
1249.59	43.0176
1252.8	44.7121
1256.02	46.7131
1259.23	49.7475
1262.44	52.2287
1265.66	52.8976
1268.87	53.753
1272.07	55.7743
1275.28	56.8762
1278.48	57.3783
1281.69	57.3656
1284.89	60.3836
1288.09	61.6431
1291.3	62.738
1294.49	63.266
1297.69	64.0315
1300.89	64.6114
1304.09	64.2707
1307.28	65.4881
1310.47	64.3987
1313.66	63.586
1316.86	62.2994
1320.05	60.2994
1323.23	59.632
1326.42	59.0217
1329.61	55.0696
1332.79	55.6788
1335.98	55.4184
1339.16	54.4385
1342.34	52.1043
1345.52	50.561
1348.7	49.2944
1351.87	46.4294
1355.05	44.1196
1358.23	40.9349
1361.4	39.5061
1364.57	37.4592
1367.74	35.906
1370.91	35.4852
1374.08	33.1947
1377.25	31.0218
1380.42	30.2251
1383.58	30.4454
1386.75	29.9074
1389.91	29.5249
1393.07	29.3287
1396.23	29.3891
1399.39	31.6726
1402.55	34.251
1405.7	37.2967
1408.86	39.2608
1412.01	42.3308
1415.17	44.1016
1418.32	47.3443
1421.47	50.7126
1424.62	54.5963
1427.77	57.1768
1430.92	60.5543
1434.06	63.5313
1437.2	65.6727
1440.35	67.6882
1443.49	69.3713
1446.63	70.9933
1449.77	70.5042
1452.91	69.1084
1456.05	68.1156
1459.18	66.0398
1462.32	62.6847
1465.45	58.6087
1468.59	53.3151
1471.72	49.0391
1474.85	46.0413
1477.98	41.8774
1481.11	35.8021
1484.23	31.3694
1487.36	26.2413
1490.48	23.4588
1493.61	21.9821
1496.73	19.6449
1499.85	18.2794
1502.97	17.679
1506.09	16.3595
1509.2	16.3459
1512.32	16.1328
1515.44	17.0873
1518.55	19.1471
1521.66	19.8671
1524.77	22.0861
1527.88	23.6342
1530.99	24.0127
1534.1	27.9216
1537.21	30.8458
1540.31	34.1926
1543.42	37.1274
1546.52	41.1268
1549.62	45.2841
1552.72	48.9639
1555.82	51.6546
1558.92	55.4423
1562.02	58.7821
1565.11	62.9483
1568.21	66.3863
1571.3	68.4931
1574.39	70.6892
1577.49	72.3007
1580.58	73.5916
1583.67	72.8855
1586.75	72.2493
1589.84	72.1954
1592.93	70.8028
1596.01	69.3087
1599.09	68.2945
1602.18	64.5904
1605.26	62.3109
1608.34	62.0408
1611.41	60.008
1614.49	58.7446
1617.57	56.3428
1620.64	55.6938
1623.72	54.8389
1626.79	55.4692
1629.86	56.7826
1632.93	57.829
1636	58.8985
1639.07	61.159
1642.14	62.9363
1645.2	63.8038
1648.27	64.6338
1651.33	63.9973
1654.39	62.698
1657.45	63.2487
1660.51	63.0513
1663.57	62.1776
1666.63	60.7138
1669.69	58.8695
1672.74	56.5498
1675.79	51.5237
1678.85	46.2237
1681.9	42.8148
1684.95	38.4625
1688	34.2021
1691.05	30.1137
1694.1	26.7406
1697.14	23.1472
1700.19	21.3823
1703.23	19.982
1706.27	17.9681
1709.32	14.9284
1712.35	13.6688
1715.39	13.1122
1718.43	11.5091
1721.47	10.3126
1724.5	8.84649
1727.54	9.56439
1730.57	10.7149
1733.61	12.2264
1736.64	13.0263
1739.67	13.4036
1742.7	13.8312
1745.72	13.3963
1748.75	11.8442
1751.78	10.5607
1754.8	10.894
1757.82	10.6763
1760.85	9.93112
1763.87	9.34466
1766.89	8.37749
1769.91	8.01932
1772.92	8.09626
1775.94	7.55359
1778.96	6.18233
1781.97	4.53421
1784.98	4.28625
1788	5.02851
1791.01	3.91323
1794.01	2.64682
1797.02	2.96815
1800.03	2.93606
1803.04	3.35553
1806.04	4.62508
1809.05	5.8443
1812.05	5.76809
1815.05	5.74037
1818.05	5.10626
1821.05	5.55942
1824.05	5.64617
1827.05	6.1158
1830.04	6.44036
1833.04	5.8305
1836.03	5.87972
1839.03	6.02232
1842.02	4.98413
1845.01	5.22401
1848	5.13031
1850.99	3.8998
1853.97	3.36152
1856.96	2.65255
1859.94	1.94137
1862.93	0.855125
1865.91	-0.403858
1868.89	-1.35794
1871.87	-0.623152
1874.85	0.189538
1877.83	1.109
1880.81	1.01788
1882.56	0.785504
1885.55	1.39327
1888.54	3.07353
1891.52	4.0185
1894.51	5.94519
1897.49	6.33847
1900.48	7.25395
1903.46	8.14925
1906.44	8.33772
1909.42	9.99496
1912.4	10.7697
1915.38	9.99472
1918.35	9.23571
1921.33	8.8969
1924.3	8.12544
1927.28	8.26125
1930.25	6.76628
1933.22	6.71468
1936.19	5.46466
1939.16	4.14783
1942.13	3.31612
1945.09	3.45456
1948.06	2.10326
1951.03	1.67589
1953.99	1.48711
1956.95	1.30355
1959.91	1.69912
1962.87	1.18013
1965.83	2.011
1968.79	2.39047
1971.75	1.89288
1974.7	3.12587
1977.66	3.63499
1980.61	3.85017
1983.56	4.54388
1986.52	3.46217
1989.47	3.92449
1992.41	5.72328
1995.36	6.35673
1998.31	6.72762
2001.26	7.60911
2004.2	6.35064
2007.15	6.9802
2010.09	6.66685
2013.03	7.0279
2015.97	7.5221
2018.91	7.73997
2021.85	7.70797
2024.79	8.54572
2027.72	7.89309
2030.66	8.38646
2033.59	8.48863
2036.53	8.89745
2039.46	9.1428
2042.39	9.39584
2045.32	9.95862
2048.25	11.2885
2051.18	11.5987
2054.1	12.1431
2057.03	12.8217
2059.95	14.0652
2062.88	14.3471
2065.8	14.7085
2068.72	15.2713
2071.64	15.4749
2074.56	15.6418
2077.48	16.1372
2080.39	17.0024
2083.31	17.1312
2086.22	18.512
2089.14	18.9088
2092.05	19.0105
2094.96	19.8914
2097.87	21.6543
2100.78	23.821
2103.69	24.693
2106.6	26.7848
2109.51	28.6043
2112.41	30.968
2115.32	33.8596
2118.22	37.3619
2121.12	39.4363
2124.02	42.0507
2126.92	45.6142
2129.82	48.4529
2132.72	51.8081
2135.62	55.6283
2138.51	58.85
2141.41	61.7338
2144.3	64.1962
2147.19	67.3155
2150.09	70.5348
2152.97	73.2228
2155.86	75.7212
2158.75	77.3173
2161.64	78.271
2164.53	79.2721
2167.41	80.7322
2170.3	81.1648
2173.18	80.482
2176.06	78.9856
2178.94	76.8024
2181.82	75.7413
2184.7	74.0973
2187.58	72.0874
2190.46	69.7245
2193.33	68.416
2196.21	66.6599
2199.08	64.3453
2201.95	63.054
2204.83	61.0733
2207.7	58.4628
2210.57	55.4656
2213.43	52.3305
2216.3	50.2222
2219.17	47.7732
2222.03	46.1024
2224.9	43.8826
2227.76	41.8006
2230.62	38.8052
2233.49	35.9509
2236.34	34.7183
2239.2	33.0534
2242.06	30.4642
2244.92	28.5066
2247.78	28.194
2250.63	26.4328
2253.48	26.1335
2256.34	23.7628
2259.19	23.3012
2262.04	23.0536
2264.89	22.6535
2267.74	21.6402
2270.59	20.8149
2273.43	20.1827
2276.28	18.293
2279.12	16.4741
2281.97	14.6293
2284.81	13.3098
2287.65	12.1474
2290.49	10.1553
2293.33	8.85601
2296.17	7.5327
2299.01	6.27214
2301.84	6.28359
2304.68	6.3069
2307.51	7.43196
2310.35	7.38782
2313.18	8.40158
2316.01	8.15836
2318.84	7.58918
2321.67	7.49602
2324.5	7.8712
2327.33	7.61605
2330.15	8.78824
2332.98	9.56171
2335.8	9.86227
2338.62	10.0453
2341.45	9.68141
2344.27	8.8698
2347.09	7.9709
2349.91	6.47351
2352.72	6.14821
2355.54	5.21427
2358.36	4.62
2361.17	3.92531
2363.98	5.06854
2366.8	5.22112
2369.61	5.32125
2372.42	5.32117
2375.23	5.20006
2378.04	5.63891
2380.85	5.58548
2383.66	5.06366
2386.46	4.56357
2389.26	3.53608
2392.07	3.39778
2394.87	3.31865
2397.67	3.05955
2400.47	3.32487
2403.27	3.10295
2406.07	2.11846
2408.87	2.21494
2411.67	2.22808
2414.46	1.80949
2417.26	2.92748
2420.05	3.81138
2422.84	3.35293
2425.64	4.36825
2428.43	4.63987
2431.22	5.28485
2434.01	4.82543
2436.79	5.31867
2439.58	5.30684
2442.37	5.54607
2445.15	3.87003
2447.93	3.1137
2450.72	3.5552
2453.5	3.11357
2456.28	3.80004
2459.06	4.6377
2461.84	5.53592
2464.62	6.1583
2467.39	5.40822
2470.17	5.84177
2472.94	6.43311
2475.72	6.21353
2478.49	7.06713
2481.26	6.24879
2484.03	5.17742
2486.8	5.0081
2489.57	4.97895
2492.34	4.31602
2495.1	2.75698
2497.87	3.29148
2500.63	2.80181
2503.4	2.46972
2506.16	1.68191
2508.92	0.0439508
2511.68	-0.87124
2514.44	-1.26285
2517.2	-0.00186381
2519.96	2.05165
2522.72	2.29777
2525.47	2.55581
2528.23	2.45157
2530.98	3.14949
2533.74	4.01813
2536.49	4.08188
2539.24	4.56156
2541.99	5.11424
2544.74	6.71259
2547.49	6.30957
2550.23	6.2505
2552.98	5.73616
2555.72	6.58941
2558.47	6.39798
2561.21	6.37058
2563.95	7.21946
2566.69	7.32076
2569.43	7.09594
2572.17	7.23578
2574.91	6.26794
2577.65	5.43429
2580.39	4.87617
2583.12	4.7896
2585.85	4.20211
2588.59	4.88328
2591.32	3.95075
2594.05	4.13803
2596.78	4.6836
2599.51	4.8726
2602.24	4.13596
2604.97	3.89135
2607.69	4.11674
2610.42	4.62733
2613.14	3.61001
2615.87	2.50295
2618.59	1.1538
2621.31	1.36171
2624.03	1.46901
2626.75	1.68215
2629.47	2.02156
2632.19	2.9227
2634.91	3.33448
2637.62	4.62315
2640.34	4.99368
2643.05	5.07422
2645.76	5.16963
2648.48	6.11402
2651.19	6.84491
2653.9	6.84321
2656.6	7.51534
2659.31	7.41951
2662.02	7.32941
2664.73	6.71383
2667.43	5.46759
2670.14	5.46206
2672.84	4.8488
2675.54	3.86411
2678.24	3.10675
2680.94	1.53217
2683.64	1.85539
2686.34	0.702324
2689.04	1.59501
2691.74	2.30187
2694.43	2.95076
2697.13	3.93447
2699.82	4.4003
2702.51	5.4046
2705.21	5.89384
2707.9	5.76875
2710.58	5.23812
2713.27	5.87627
2715.96	6.47078
2718.65	6.66623
2721.33	7.41057
2724.02	7.55706
2726.71	7.74629
2729.39	7.33151
2732.07	7.23767
2734.75	6.62247
2737.43	6.05884
2740.11	5.64041
2742.79	4.7866
2745.47	4.57351
2748.14	4.22549
2750.82	4.77401
2753.49	4.32906
2756.17	3.86601
2758.84	4.21941
2761.51	3.86039
2764.18	2.48074
2766.85	1.65707
2769.52	1.60772
2772.19	1.3302
2774.86	1.51705
2777.52	1.41152
2780.19	1.14444
2782.85	1.50079
2785.52	1.30995
2788.18	2.24098
2790.84	0.899033
2793.5	0.740286
2796.16	0.0396629
2798.82	-0.121857
2801.48	0.0810549
2804.13	0.63389
2806.79	0.587162
2809.45	0.629822
2812.1	1.10189
2814.75	1.82673
2817.41	2.1746
2820.06	3.21633
2822.71	5.80802
2825.36	9.22561
2828	11.9801
2830.65	15.0225
2833.3	19.4109
2835.94	23.3249
2838.59	26.7392
2841.23	29.4476
2843.87	33.21
2846.52	37.8939
2849.16	43.8303
2851.8	50.3457
2854.44	56.3883
2857.08	63.023
2859.71	68.5479
2862.35	74.9963
2864.98	80.1142
2867.62	84.4285
2870.25	88.5277
2872.88	91.8541
2875.52	94.8032
2878.15	98.6982
2880.78	101.988
2883.41	104.17
2886.03	108.25
2888.66	111.364
2891.29	113.484
2893.91	115.495
2896.54	118.346
2899.16	119.941
2901.78	122.327
2904.4	125.681
2907.02	130.843
2909.64	137.53
2912.26	145.115
2914.88	152.217
2917.5	158.776
2920.11	164.809
2922.73	167.74
2925.34	171.718
2927.96	174.235
2930.57	175.709
2933.18	176.203
2935.79	176.198
2938.4	173.518
2941.01	170.754
2943.62	167.427
2946.22	162.218
2948.83	156.447
2951.43	151.503
2954.04	143.986
2956.64	137.969
2959.24	131.768
2961.84	125.037
2964.45	118.148
2967.05	111.86
2969.64	107.342
2972.24	101.847
2974.84	95.7296
2977.43	90.1343
2980.03	85.0639
2982.62	78.887
2985.22	71.6823
2987.81	65.5143
2990.4	59.9801
2992.99	53.4563
2995.58	47.8344
2998.17	42.9154
3000.76	37.4081
3003.34	32.2602
3005.93	28.2828
3008.52	24.5674
3011.1	20.6143
3013.68	18.4563
3016.27	16.2422
3018.85	13.9052
3021.43	11.9843
3024.01	10.8631
3026.59	8.98003
3029.16	7.91509
3031.74	7.98752
3034.32	7.61679
3036.89	7.26464
3039.47	8.08727
3042.04	8.20876
3044.61	9.37778
3047.18	9.00676
3049.75	9.60914
3052.32	9.81677
3054.89	9.45331
3057.46	8.84775
3060.03	8.35298
3062.59	8.44767
3065.16	8.22427
3067.72	7.99568
3070.29	7.12693
3072.85	6.19139
3075.41	5.38589
3077.97	4.54855
3080.53	3.36075
3083.09	1.91073
3085.65	1.45102
3088.21	0.105249
3090.76	0.203669
3093.32	-0.0875492
3095.87	-0.3039
3098.43	0.347891
3100.98	1.53815
3103.53	1.89934
3106.08	1.43987
3108.63	1.75122
3111.18	1.82412
3113.73	2.24545
3116.28	2.77904
3118.83	3.07328
3121.37	3.39218
3123.92	3.87167
3126.46	5.33192
3129	6.35643
3131.55	6.43902
3134.09	7.12876
3136.63	7.94031
3139.17	8.77373
3141.71	9.84111
3144.24	11.2384
3146.78	13.6602
3149.32	14.5791