File: data/Raman/poly_smoothed/Thy_10_08_41_1x_45s_532 nm_x100_100%_600 gr_mm_01.txt
#Acq. time (s)=	45
#Accumulations=	2
#Range (cm-¹)=	200...3150
#Windows=	2
#Auto scanning=	Off
#Autofocus=	Off
#Macrospot=	Off
#AutoExposure=	Off
#Spike filter=	Multiple accum.
#Delay time (s)=	0
#Binning=	1
#Readout mode=	Signal
#DeNoise=	Off
#ICS correction=	On
#Dark correction=	Off
#Inst. Process=	Off
#Detector Gain=	Best Dynamic Range
#Detector ADC=	20 kHz
#Detector temperature (°C)=	-69.85
#Instrument=	LabRAM HR Evol
#Detector=	Synapse
#Objective=	x100
#Grating=	600 gr/mm
#ND Filter=	100%
#Laser (nm)=	532
#Hole=	100.021
#Range=	Auto
#Laser Pol.=	No
#Raman. Pol.=	No
#Laser Pol. (°)=	-0.0007625
#Raman Pol. (°)=	89.9995
#Collection=	Microscope
#StageXY=	Marzhauser
#StageZ=	Marzhauser
#X (µm)=	-2364.3
#Y (µm)=	230.8
#Z (µm)=	521.55
#Full time(mm:ss)=	3:18
#Project=
#Sample=
#Site=
#Title=	Thy_10_08_41_2x_45s_532 nm_x100_100%_600 gr_mm
#Remark=
#Date=	06.07.2022 14:43
#Acquired=	06.07.2022 14:43:20
#Base:Fit=	10.08.2022 09:46:25
#Base:Sub=	10.08.2022 09:46:49
#Filter:Polynom=	16.08.2022 10:24:56
#AxisType[0]=Intens
#AxisUnit[0]=Cnt
#AxisType[1]=Spectr
#AxisUnit[1]=1/cm
200.398	21.3685
204.027	19.5483
207.657	17.6151
211.283	15.4541
214.909	13.638
218.533	11.9019
222.157	11.5267
225.777	10.6954
229.396	9.82429
233.016	9.87052
236.632	7.81519
240.247	7.31157
243.86	5.26531
247.474	5.33044
251.085	5.01764
254.694	5.6625
258.301	4.08285
261.908	3.81622
265.513	4.18557
269.116	3.4023
272.718	4.05286
276.319	6.50112
279.918	6.8855
283.516	7.26244
287.113	7.06429
290.708	7.8335
294.302	8.54198
297.894	8.65558
301.485	9.48001
305.073	10.8417
308.661	10.5052
312.247	12.1382
315.833	12.5023
319.415	12.553
322.997	12.868
326.579	13.249
330.156	13.2999
333.735	13.0726
337.31	13.7271
340.885	14.2683
344.458	15.2871
348.03	14.9082
351.6	14.166
355.17	13.6685
358.737	12.8144
362.304	12.2816
365.868	11.1438
369.431	10.1026
372.994	10.0906
376.554	9.29453
380.112	8.62817
383.669	7.34311
387.225	7.43142
390.781	6.23004
394.334	6.54802
397.885	6.61833
401.436	6.0926
404.984	5.67669
408.532	7.64473
412.078	8.37668
415.623	9.0442
419.166	9.88856
422.708	11.2498
426.248	10.3757
429.788	10.8775
433.326	10.4016
436.86	8.32144
440.395	7.18747
443.929	6.00034
447.461	5.68304
450.99	3.99593
454.52	4.36245
458.048	5.88111
461.573	5.8824
465.099	5.48222
468.623	6.46243
472.144	8.01685
475.666	8.47637
479.184	8.05162
482.703	9.64972
486.218	11.8223
489.734	12.8639
493.247	14.321
496.759	15.5639
500.271	16.0344
503.779	17.6603
507.287	18.5827
510.795	18.8869
514.299	18.4225
517.803	18.504
521.305	17.4766
524.805	16.5427
528.307	16.7196
531.805	16.7228
535.301	15.3093
538.797	16.2558
542.291	16.9731
545.783	16.3149
549.275	16.4439
552.765	16.4305
556.253	15.7033
559.738	15.3522
563.224	15.4659
566.709	14.0977
570.192	14.0015
573.674	12.322
577.153	11.114
580.632	9.95253
584.11	9.62388
587.587	9.6191
591.06	9.30169
594.534	9.11516
598.005	7.46575
601.476	7.78931
604.944	7.71174
608.413	8.83538
611.878	8.46982
615.344	7.99332
618.807	8.41753
622.27	8.29924
625.73	11.1406
629.189	11.1319
632.648	12.8353
636.105	13.1734
639.559	13.9032
643.013	14.7779
646.467	17.975
649.918	18.0456
653.368	17.837
656.816	18.7489
660.263	20.1068
663.708	22.594
667.153	22.4562
670.596	23.1344
674.037	24.4716
677.478	25.0852
680.917	25.5056
684.355	27.3922
687.791	28.1728
691.224	28.0109
694.658	29.5423
698.091	30.1534
701.522	31.0935
704.95	32.7627
708.379	34.0042
711.806	36.0211
715.23	38.002
718.655	40.0435
722.078	42.9614
725.498	44.9722
728.919	47.4607
732.337	48.1535
735.755	49.2812
739.17	51.2565
742.584	54.2134
745.998	56.6916
749.409	57.9704
752.819	60.5561
756.23	61.7782
759.637	64.1911
763.043	65.6251
766.448	67.8411
769.853	69.8365
773.255	71.4403
776.656	73.585
780.056	75.8241
783.454	76.1175
786.851	79.3997
790.247	81.554
793.641	83.2799
797.034	84.9866
800.426	87.0707
803.817	88.4979
807.206	89.1963
810.592	87.2678
813.979	86.7252
817.364	86.9082
820.748	88.0822
824.129	87.3028
827.511	86.7384
830.891	84.8333
834.269	82.5938
837.646	80.9898
841.023	79.8408
844.396	77.0476
847.77	76.2446
851.141	74.9435
854.513	73.0577
857.881	71.3057
861.248	69.9787
864.616	68.3291
867.98	66.6011
871.343	66.3741
874.707	65.2146
878.068	64.7348
881.428	65.0535
884.786	65.959
888.143	65.2767
891.498	64.3804
894.855	63.5725
898.208	64.2137
901.56	64.4365
904.91	63.4911
908.26	62.2809
911.608	61.0043
914.955	60.6388
918.298	59.667
921.643	59.525
924.986	59.1226
928.328	58.9887
931.668	59.0279
935.006	58.6945
938.344	55.8057
941.681	53.8612
945.014	50.2466
948.349	48.3713
951.682	48.2478
955.012	46.299
958.343	45.1333
961.67	44.1834
964.998	45.814
968.323	47.1275
971.649	47.7135
974.971	49.2198
978.293	49.8452
981.615	50.8083
984.933	50.8842
988.251	50.6609
991.567	51.9527
994.884	51.4061
998.198	51.3649
1001.51	48.6125
1004.82	47.8217
1008.13	46.9848
1011.44	45.8693
1014.75	43.4978
1018.06	39.2059
1021.36	34.7309
1024.66	31.6906
1027.97	30.3472
1031.27	28.2859
1034.57	25.1095
1037.87	23.706
1041.16	23.2776
1044.46	24.842
1047.76	25.3305
1051.05	24.8231
1054.34	25.3994
1057.63	24.2103
1060.92	24.2703
1064.21	23.8234
1067.5	23.6936
1070.78	24.3457
1074.07	24.0121
1077.35	22.8769
1080.63	22.2176
1083.91	21.2853
1087.19	21.898
1090.47	22.1512
1093.75	21.345
1097.03	21.2192
1100.3	21.7552
1103.57	23.2893
1106.84	24.0178
1110.11	24.1628
1113.38	23.1516
1116.65	23.0676
1119.92	23.4874
1123.19	22.8933
1126.45	21.8124
1129.71	21.2452
1132.97	19.8821
1136.23	20.119
1139.49	20.0624
1142.75	19.6063
1146.01	18.7228
1149.26	18.3141
1152.52	16.2081
1155.77	14.449
1159.02	13.4227
1162.27	10.296
1165.52	8.67612
1168.77	7.43527
1172.02	8.65412
1175.26	8.42665
1178.51	9.09555
1181.75	9.25573
1184.99	8.26637
1188.23	10.4554
1191.47	11.3055
1194.71	13.4738
1197.94	17.2924
1201.18	20.5069
1204.41	23.4385
1207.65	28.7623
1210.88	32.9126
1214.11	38.5388
1217.34	43.3045
1220.57	46.9428
1223.79	49.5619
1227.02	51.3645
1230.24	53.5249
1233.47	53.8561
1236.69	54.0154
1239.91	53.941
1243.13	53.2628
1246.34	54.2839
1249.56	54.1393
1252.78	53.519
1255.99	51.8455
1259.2	50.1742
1262.42	49.5047
1265.63	50.0711
1268.84	51.6074
1272.04	50.1379
1275.25	51.0437
1278.46	51.6024
1281.66	53.2018
1284.86	55.3126
1288.07	56.845
1291.27	58.0095
1294.47	59.6323
1297.66	60.3708
1300.86	62.0844
1304.06	63.3314
1307.25	63.4581
1310.44	64.2652
1313.64	64.7846
1316.83	65.8295
1320.02	66.7853
1323.2	67.8143
1326.39	67.0064
1329.58	65.391
1332.76	64.4364
1335.95	64.0262
1339.13	63.1108
1342.31	63.0976
1345.49	60.7622
1348.67	59.4483
1351.85	56.4275
1355.02	55.0847
1358.2	53.748
1361.37	51.6237
1364.54	48.8504
1367.71	47.4725
1370.88	45.4756
1374.05	44.107
1377.22	44.205
1380.39	43.7599
1383.55	43.5242
1386.72	41.6253
1389.88	41.7348
1393.04	40.5445
1396.2	40.5297
1399.36	39.4295
1402.52	38.7121
1405.68	39.695
1408.83	41.1393
1411.98	43.2342
1415.14	44.5754
1418.29	48.5602
1421.44	52.205
1424.59	56.1724
1427.74	61.3189
1430.89	63.85
1434.03	67.8068
1437.18	70.1062
1440.32	71.9891
1443.46	74.9019
1446.6	74.6659
1449.74	74.3132
1452.88	73.8421
1456.02	71.3099
1459.16	67.6823
1462.29	62.6704
1465.43	57.676
1468.56	50.8742
1471.69	44.5712
1474.82	39.0184
1477.95	33.3289
1481.08	28.8248
1484.2	23.323
1487.33	20.074
1490.46	17.0848
1493.58	15.5419
1496.7	15.3859
1499.82	14.0138
1502.94	13.8423
1506.06	13.0405
1509.18	13.3626
1512.29	13.6613
1515.41	14.2937
1518.52	16.6296
1521.63	17.9921
1524.75	19.2901
1527.85	21.8658
1530.96	24.306
1534.07	26.1586
1537.18	27.0964
1540.28	29.5416
1543.39	30.4303
1546.49	32.9371
1549.59	37.0802
1552.69	39.8682
1555.79	43.3726
1558.89	44.8278
1561.99	46.7682
1565.08	49.3437
1568.18	51.626
1571.27	55.2529
1574.37	57.8944
1577.46	59.1856
1580.55	60.3677
1583.64	61.951
1586.73	63.153
1589.81	64.9881
1592.9	65.1016
1595.98	64.5906
1599.06	63.1665
1602.15	63.6116
1605.23	62.7526
1608.31	61.4872
1611.39	60.0068
1614.46	58.9997
1617.54	58.8502
1620.61	58.3064
1623.69	59.6381
1626.76	59.6431
1629.83	59.7316
1632.9	60.2704
1635.97	61.7806
1639.04	63.6777
1642.11	66.0214
1645.17	68.1953
1648.24	70.3737
1651.3	69.9742
1654.36	70.5531
1657.42	70.5644
1660.48	70.8251
1663.54	68.7886
1666.6	65.8535
1669.66	63.3027
1672.71	60.2835
1675.77	57.5466
1678.82	54.3143
1681.87	50.3804
1684.92	46.09
1687.97	42.5737
1691.02	38.3913
1694.07	34.1832
1697.11	29.2279
1700.16	25.4419
1703.2	22.2087
1706.25	18.4934
1709.29	16.1405
1712.33	13.9327
1715.37	11.4153
1718.41	9.96052
1721.44	8.80737
1724.48	7.54936
1727.51	6.04109
1730.55	6.01426
1733.58	6.08271
1736.61	4.8829
1739.64	4.40864
1742.67	5.85833
1745.7	6.12795
1748.72	5.77954
1751.75	5.644
1754.77	5.42382
1757.8	6.16252
1760.82	6.44707
1763.84	5.93544
1766.86	5.06831
1769.88	3.82344
1772.9	3.14247
1775.91	2.77354
1778.93	1.6287
1781.94	1.15486
1784.96	1.0779
1787.97	0.516625
1790.98	0.146494
1793.99	-0.0434419
1797	-1.02406
1800.01	-1.9052
1803.01	-1.7192
1806.02	-1.88938
1809.02	-1.83435
1812.02	-1.10937
1815.02	0.0988412
1818.03	0.755274
1821.02	1.11311
1824.02	1.72364
1827.02	3.1596
1830.02	3.52731
1833.01	4.5974
1836.01	5.07193
1839	5.35478
1841.99	5.66569
1844.98	5.64889
1847.97	5.72673
1850.96	6.55834
1853.95	6.2554
1856.93	5.29857
1859.92	4.33684
1862.9	4.13701
1865.88	4.02518
1868.87	3.44651
1871.85	3.25755
1874.83	3.1675
1877.81	2.90667
1880.78	2.93164
1882.53	3.64938
1885.52	3.5781
1888.51	4.413
1891.5	3.90008
1894.48	3.90196
1897.47	3.78527
1900.45	4.10033
1903.43	3.87565
1906.41	3.78446
1909.39	4.1207
1912.37	4.2782
1915.35	3.96498
1918.33	3.40637
1921.3	3.80203
1924.28	2.62854
1927.25	2.34104
1930.22	3.17563
1933.19	4.23074
1936.16	5.46207
1939.13	6.45836
1942.1	7.28703
1945.07	7.18272
1948.03	6.74869
1951	6.60319
1953.96	5.89329
1956.92	6.21426
1959.88	5.89758
1962.84	5.22991
1965.8	4.62545
1968.76	4.89224
1971.72	4.59057
1974.67	3.69088
1977.63	2.27861
1980.58	1.90218
1983.54	1.95576
1986.49	1.89537
1989.44	1.60824
1992.39	1.60368
1995.33	2.14278
1998.28	2.95511
2001.23	4.93699
2004.17	5.064
2007.12	5.75863
2010.06	6.82174
2013	6.33035
2015.94	6.4923
2018.88	6.80071
2021.82	6.99561
2024.76	6.72825
2027.69	7.78372
2030.63	8.52963
2033.56	9.31007
2036.5	9.22682
2039.43	10.2646
2042.36	10.8485
2045.29	10.5639
2048.22	10.1004
2051.15	10.5365
2054.07	10.5491
2057	11.162
2059.92	11.4021
2062.85	11.7097
2065.77	11.8063
2068.69	12.9076
2071.61	13.1138
2074.53	12.8757
2077.45	12.9269
2080.37	13.0335
2083.28	13.1741
2086.2	13.4056
2089.11	13.9137
2092.02	14.2854
2094.94	13.0087
2097.85	13.05
2100.76	12.786
2103.66	13.3702
2106.57	12.9746
2109.48	13.325
2112.38	13.6215
2115.29	13.41
2118.19	13.381
2121.09	12.4466
2123.99	13.3385
2126.89	14.5187
2129.79	15.1883
2132.69	16.3828
2135.59	17.6796
2138.48	17.9881
2141.38	19.4539
2144.27	18.4341
2147.17	20.7595
2150.06	23.0754
2152.95	25.3635
2155.84	27.832
2158.73	29.7479
2161.61	30.8431
2164.5	31.8208
2167.38	32.8198
2170.27	33.6483
2173.15	34.2443
2176.03	35.6285
2178.91	36.0913
2181.8	35.4193
2184.67	33.3367
2187.55	32.1088
2190.43	31.3392
2193.3	30.3067
2196.18	28.8143
2199.05	27.4896
2201.93	25.9709
2204.8	23.6091
2207.67	22.4183
2210.54	19.9692
2213.41	18.9855
2216.27	18.5212
2219.14	18.9758
2222.01	18.865
2224.87	19.2306
2227.73	19.3423
2230.6	19.3587
2233.46	19.069
2236.32	19.0178
2239.18	19.2522
2242.03	18.6438
2244.89	18.6739
2247.75	18.5988
2250.6	18.2998
2253.46	17.1303
2256.31	16.4751
2259.16	17.646
2262.01	17.3084
2264.86	16.8631
2267.71	15.9535
2270.56	15.3225
2273.4	13.9081
2276.25	13.2975
2279.09	12.4876
2281.94	11.5949
2284.78	12.7639
2287.62	11.955
2290.46	11.7889
2293.3	11.3719
2296.14	11.5225
2298.98	12.179
2301.82	12.7937
2304.65	13.338
2307.49	14.2596
2310.32	13.4765
2313.15	13.8816
2315.98	14.524
2318.81	14.6318
2321.64	14.1064
2324.47	13.8739
2327.3	13.7676
2330.12	13.378
2332.95	12.0949
2335.77	10.8507
2338.6	9.88082
2341.42	8.89226
2344.24	8.06914
2347.06	7.09797
2349.88	6.5176
2352.7	6.03268
2355.51	5.27094
2358.33	4.61179
2361.14	4.03713
2363.96	4.52905
2366.77	5.06667
2369.58	4.85664
2372.39	5.47126
2375.2	5.4742
2378.01	4.46454
2380.82	4.71044
2383.63	4.65602
2386.43	5.11307
2389.24	4.94179
2392.04	5.17415
2394.84	6.06848
2397.65	5.84224
2400.45	6.31877
2403.25	6.5698
2406.05	7.37938
2408.84	7.48691
2411.64	7.78452
2414.44	8.1749
2417.23	9.01599
2420.02	8.91022
2422.82	9.82742
2425.61	10.2446
2428.4	9.87368
2431.19	9.3313
2433.98	8.73833
2436.77	8.486
2439.55	8.19562
2442.34	7.82109
2445.12	7.43022
2447.91	6.63442
2450.69	6.36058
2453.47	6.18885
2456.25	5.77303
2459.03	5.03732
2461.81	4.39619
2464.59	3.66695
2467.36	3.82148
2470.14	4.23946
2472.92	4.35946
2475.69	4.63453
2478.46	5.0041
2481.23	5.309
2484	5.32422
2486.77	6.20028
2489.54	5.52256
2492.31	5.14539
2495.08	3.84339
2497.84	3.54838
2500.61	3.28626
2503.37	3.04222
2506.13	2.22274
2508.9	1.92703
2511.66	0.767238
2514.42	0.0898257
2517.18	0.270939
2519.93	0.433183
2522.69	0.132423
2525.45	-0.41418
2528.2	0.352441
2530.95	0.0796111
2533.71	0.0100328
2536.46	1.0495
2539.21	1.3086
2541.96	1.69184
2544.71	2.23465
2547.46	3.56442
2550.2	3.85562
2552.95	4.42579
2555.7	3.88514
2558.44	3.11194
2561.18	2.29529
2563.93	2.43701
2566.67	2.55146
2569.41	2.73221
2572.15	2.78072
2574.88	2.05085
2577.62	1.73058
2580.36	2.08975
2583.09	2.14551
2585.83	1.88271
2588.56	1.35051
2591.29	0.592745
2594.02	1.16914
2596.75	0.312239
2599.48	-0.625186
2602.21	0.103597
2604.94	-0.186525
2607.67	-0.401006
2610.39	-0.398264
2613.12	0.0923707
2615.84	-0.18941
2618.56	-1.55279
2621.28	-1.96598
2624.01	-1.87895
2626.72	-1.30952
2629.44	-0.887384
2632.16	0.646364
2634.88	0.659444
2637.59	0.695638
2640.31	0.865603
2643.02	1.55294
2645.74	1.95192
2648.45	2.02108
2651.16	2.44165
2653.87	2.63119
2656.58	2.47764
2659.29	3.51649
2661.99	4.14288
2664.7	4.10063
2667.41	3.72809
2670.11	3.87448
2672.81	3.55179
2675.51	3.18389
2678.22	2.76379
2680.92	2.30123
2683.62	2.18426
2686.31	2.33706
2689.01	2.77045
2691.71	4.30775
2694.4	4.52369
2697.1	4.4955
2699.79	4.21009
2702.49	4.16595
2705.18	4.03501
2707.87	4.49054
2710.56	3.9302
2713.25	3.76856
2715.94	4.01411
2718.62	4.08722
2721.31	4.23163
2723.99	4.64658
2726.68	4.69859
2729.36	5.30067
2732.04	4.89142
2734.73	4.8476
2737.41	4.99537
2740.08	4.29719
2742.76	3.4918
2745.44	3.28101
2748.12	4.43505
2750.79	4.51548
2753.47	4.8926
2756.14	5.29344
2758.81	5.23075
2761.49	4.48985
2764.16	4.2276
2766.83	4.13361
2769.5	4.12209
2772.16	3.81953
2774.83	2.44009
2777.5	1.87881
2780.16	1.92499
2782.83	2.34294
2785.49	2.34466
2788.15	3.36679
2790.82	3.72615
2793.48	4.23706
2796.14	3.45202
2798.79	3.68395
2801.45	3.99827
2804.11	4.53953
2806.76	4.08275
2809.42	4.81891
2812.07	5.1812
2814.73	5.34385
2817.38	6.6311
2820.03	8.11095
2822.68	9.44352
2825.33	10.7983
2827.98	13.2558
2830.63	15.4518
2833.27	19.1606
2835.92	22.8366
2838.56	26.3214
2841.21	30.4724
2843.85	36.535
2846.49	43.083
2849.13	50.6428
2851.77	58.6345
2854.41	66.4878
2857.05	74.8421
2859.69	83.0008
2862.32	89.7606
2864.96	96.6249
2867.59	103.039
2870.23	108.588
2872.86	113.537
2875.49	117.689
2878.12	121.664
2880.75	125.253
2883.38	128.223
2886.01	130.047
2888.63	133.558
2891.26	137.759
2893.89	141.298
2896.51	145.41
2899.13	150.796
2901.76	156.233
2904.38	162.676
2907	170.996
2909.62	180.624
2912.24	190.854
2914.85	201.261
2917.47	209.226
2920.09	217.37
2922.7	223.519
2925.32	227.197
2927.93	229.331
2930.54	231.487
2933.15	230.374
2935.76	228.221
2938.37	223.776
2940.98	218.578
2943.59	212.493
2946.2	205.665
2948.8	197.714
2951.41	189.999
2954.01	182.694
2956.62	173.918
2959.22	166.59
2961.82	159.074
2964.42	151.656
2967.02	145.278
2969.62	139.716
2972.22	134.612
2974.81	128.139
2977.41	122.203
2980	114.14
2982.6	107.034
2985.19	99.997
2987.78	91.8789
2990.38	83.7471
2992.97	76.5103
2995.56	68.6485
2998.14	61.7601
3000.73	55.2996
3003.32	48.4111
3005.91	43.0936
3008.49	37.7509
3011.07	33.1215
3013.66	28.601
3016.24	25.848
3018.82	23.6935
3021.4	21.1358
3023.98	19.753
3026.56	18.9286
3029.14	19.5078
3031.71	19.7432
3034.29	20.8258
3036.87	21.7419
3039.44	22.6639
3042.01	24.4389
3044.59	26.3229
3047.16	27.3385
3049.73	27.8591
3052.3	28.4486
3054.87	29.0364
3057.43	29.5801
3060	29.1483
3062.57	28.806
3065.13	27.4799
3067.7	26.9745
3070.26	24.6014
3072.82	22.2263
3075.39	19.7301
3077.95	17.3095
3080.51	14.4832
3083.07	11.1739
3085.63	9.02103
3088.18	7.02672
3090.74	5.41764
3093.29	3.35614
3095.85	2.30336
3098.4	1.76375
3100.95	0.456035
3103.51	0.704329
3106.06	0.688945
3108.61	-0.448518
3111.16	-0.880653
3113.71	-0.0764143
3116.25	0.11967
3118.8	-0.217029
3121.35	0.695902
3123.89	0.726111
3126.44	1.6413
3128.98	1.91189
3131.52	1.20477
3134.06	1.50495
3136.6	1.70817
3139.14	0.867059
3141.68	0.343572
3144.22	0.325361
3146.76	0.148219
3149.29	-0.542858