File: data/Raman/poly_smoothed/Thy_50_12_35_1x_45s_532 nm_x100_100%_600 gr_mm_01.txt
#Acq. time (s)=	45
#Accumulations=	2
#Range (cm-¹)=	200...3150
#Windows=	2
#Auto scanning=	Off
#Autofocus=	Off
#Macrospot=	Off
#AutoExposure=	Off
#Spike filter=	Multiple accum.
#Delay time (s)=	0
#Binning=	1
#Readout mode=	Signal
#DeNoise=	Off
#ICS correction=	On
#Dark correction=	Off
#Inst. Process=	Off
#Detector Gain=	Best Dynamic Range
#Detector ADC=	20 kHz
#Detector temperature (°C)=	-69.85
#Instrument=	LabRAM HR Evol
#Detector=	Synapse
#Objective=	x100
#Grating=	600 gr/mm
#ND Filter=	100%
#Laser (nm)=	532
#Hole=	100.021
#Range=	Auto
#Laser Pol.=	No
#Raman. Pol.=	No
#Laser Pol. (°)=	-0.0007625
#Raman Pol. (°)=	89.9995
#Collection=	Microscope
#StageXY=	Marzhauser
#StageZ=	Marzhauser
#X (µm)=	-5134.4
#Y (µm)=	1516.7
#Z (µm)=	63.7
#Full time(mm:ss)=	3:19
#Project=
#Sample=
#Site=
#Title=	Thy_50_12_35_2x_45s_532 nm_x100_100%_600 gr_mm
#Remark=
#Date=	07.07.2022 11:50
#Acquired=	07.07.2022 11:50:24
#Base:Fit=	10.08.2022 10:04:30
#Base:Sub=	10.08.2022 10:04:45
#Filter:Polynom=	16.08.2022 10:20:25
#AxisType[0]=Intens
#AxisUnit[0]=Cnt
#AxisType[1]=Spectr
#AxisUnit[1]=1/cm
200.43	23.8028
204.061	30.3646
207.688	32.4693
211.316	31.1847
214.941	29.2651
218.566	26.7118
222.188	25.0923
225.809	22.4754
229.43	20.7609
233.047	18.3594
236.663	14.6944
240.278	13.4086
243.894	10.7177
247.506	9.14038
251.116	8.38109
254.725	7.24389
258.333	7.72523
261.939	7.1667
265.546	5.96075
269.15	6.8739
272.752	6.98762
276.353	7.33256
279.952	8.26518
283.55	9.69717
287.146	10.0636
290.739	10.7451
294.333	10.5757
297.925	10.3317
301.516	11.3412
305.106	11.6749
308.694	13.7369
312.279	12.4677
315.864	12.2694
319.448	11.4366
323.029	10.065
326.61	9.75888
330.19	8.71567
333.766	8.67955
337.343	9.06478
340.917	10.3714
344.491	10.1942
348.062	9.86298
351.633	8.42474
355.201	6.79493
358.77	5.80653
362.335	4.28954
365.899	3.83758
369.464	5.36851
373.025	5.58068
376.585	5.72061
380.143	5.92595
383.702	5.97458
387.258	5.15128
390.812	5.81233
394.365	7.2604
397.916	7.03172
401.467	5.89164
405.015	5.39118
408.565	4.82814
412.111	5.42866
415.656	5.37022
419.197	5.33287
422.739	5.5163
426.279	5.73987
429.819	4.71321
433.356	4.26433
436.893	5.00349
440.428	3.96614
443.96	3.78615
447.492	4.53551
451.023	5.62922
454.553	7.70342
458.079	10.1599
461.606	11.8512
465.132	13.2437
468.654	14.0927
472.177	15.9521
475.696	17.7991
479.217	20.7556
482.733	21.7884
486.251	23.7045
489.765	25.5448
493.278	27.7582
496.791	30.0893
500.301	31.0796
503.81	31.1364
507.319	32.375
510.825	34.2653
514.33	34.2573
517.833	33.2699
521.337	33.6367
524.838	33.7136
528.337	34.1826
531.835	33.2243
535.332	31.7082
538.827	29.6541
542.321	27.5459
545.814	25.7588
549.305	23.7091
552.795	21.1742
556.284	19.6851
559.771	16.2924
563.257	13.5739
566.742	11.7119
570.223	10.8587
573.705	8.36982
577.185	6.42649
580.665	5.0298
584.141	2.41993
587.617	0.868161
591.092	1.42364
594.564	3.30675
598.037	3.39167
601.506	3.4025
604.976	4.1119
608.443	7.11684
611.91	9.04617
615.374	10.954
618.839	10.2047
622.3	10.69
625.761	13.1431
629.221	13.9152
632.679	15.6995
636.135	16.6761
639.592	17.2111
643.045	17.5382
646.497	17.3142
649.948	17.2656
653.398	17.8239
656.846	16.6209
660.293	15.6024
663.738	15.3685
667.185	16.6958
670.628	16.4891
674.067	19.4283
677.508	21.0513
680.947	23.4733
684.385	24.7402
687.821	28.6308
691.256	31.3141
694.69	33.175
698.121	36.1018
701.552	38.7832
704.982	42.8213
708.41	45.414
711.836	48.5183
715.262	50.0413
718.685	51.1143
722.108	52.599
725.53	54.3555
728.949	54.6781
732.369	56.0697
735.785	56.0615
739.2	57.2775
742.616	58.4132
746.028	61.9005
749.441	66.5127
752.851	69.7558
756.26	71.4944
759.667	74.8442
763.075	75.8888
766.479	78.2307
769.883	79.9387
773.285	82.0386
776.686	83.6578
780.085	84.904
783.484	88.1819
786.881	89.8403
790.276	88.9048
793.671	89.1249
797.064	89.7039
800.456	88.6952
803.846	89.3986
807.236	88.3648
810.624	89.0357
814.01	86.6085
817.394	85.9723
820.778	84.4895
824.161	84.1714
827.543	83.6348
830.921	84.537
834.3	83.5523
837.676	80.2447
841.053	77.8766
844.426	75.0568
847.8	71.3003
851.171	68.5988
854.542	66.8634
857.911	63.2287
861.279	62.1194
864.645	61.1964
868.01	59.9652
871.375	57.1938
874.737	57.0248
878.097	57.7799
881.457	57.0213
884.817	57.3044
888.174	57.3661
891.53	56.5654
894.884	56.5174
898.237	55.8101
901.589	56.7062
904.94	56.112
908.289	54.7329
911.637	54.604
914.984	53.1836
918.33	52.3163
921.674	51.4173
925.015	49.8296
928.357	47.1908
931.698	45.445
935.037	44.321
938.373	42.7606
941.71	41.2628
945.046	39.2044
948.378	38.6173
951.711	38.9023
955.043	39.2278
958.372	39.9314
961.701	37.9287
965.027	38.7363
968.354	40.8009
971.678	41.4155
975	41.933
978.324	41.4355
981.644	42.5667
984.962	42.6252
988.282	42.8324
991.598	43.0147
994.913	43.9292
998.227	45.7744
1001.54	47.6662
1004.85	47.2531
1008.16	46.5798
1011.47	47.7802
1014.78	50.3423
1018.08	51.9054
1021.39	51.3306
1024.69	51.4647
1028	53.4278
1031.3	55.0975
1034.6	56.1855
1037.9	54.5761
1041.19	53.318
1044.49	52.4424
1047.79	53.4352
1051.08	50.3792
1054.37	47.0484
1057.66	45.5954
1060.95	41.4422
1064.24	38.3428
1067.53	35.4762
1070.81	34.7864
1074.1	33.4394
1077.38	31.5424
1080.66	29.7686
1083.94	27.6765
1087.22	26.4306
1090.5	25.0026
1093.78	27.031
1097.05	27.6436
1100.33	26.3925
1103.6	26.6751
1106.87	26.5905
1110.15	25.3602
1113.41	25.3887
1116.68	24.7256
1119.95	23.4414
1123.21	21.5822
1126.48	20.6942
1129.74	20.0522
1133	17.6132
1136.26	16.6244
1139.52	14.835
1142.78	12.8482
1146.04	12.0507
1149.29	11.5877
1152.55	9.59595
1155.8	7.23323
1159.05	4.39598
1162.3	3.23442
1165.55	3.06974
1168.8	4.49056
1172.05	5.51757
1175.29	5.82547
1178.54	6.63778
1181.78	6.88649
1185.02	7.5559
1188.26	9.22041
1191.5	10.8488
1194.74	12.864
1197.97	14.4692
1201.21	18.5654
1204.44	20.9949
1207.68	23.1211
1210.91	25.3523
1214.14	28.244
1217.37	32.9058
1220.6	36.5294
1223.82	39.1988
1227.05	43.7906
1230.27	47.9061
1233.49	52.8196
1236.72	54.3341
1239.94	58.245
1243.16	61.2776
1246.37	64.1775
1249.59	68.438
1252.8	70.2217
1256.02	71.6945
1259.23	74.483
1262.44	76.8066
1265.66	79.4738
1268.87	82.4337
1272.07	85.2816
1275.28	86.5944
1278.48	89.3955
1281.69	90.7403
1284.89	91.5372
1288.09	95.244
1291.3	97.5624
1294.49	99.0834
1297.69	100.081
1300.89	100.719
1304.09	101.306
1307.28	101.841
1310.47	101.666
1313.66	98.5211
1316.86	97.7692
1320.05	95.6213
1323.23	93.4229
1326.42	91.4078
1329.61	88.0971
1332.79	83.9269
1335.98	80.7667
1339.16	77.3189
1342.34	74.7445
1345.52	71.707
1348.7	68.8591
1351.87	65.4856
1355.05	64.3574
1358.23	60.8929
1361.4	57.38
1364.57	57.763
1367.74	55.9333
1370.91	52.9452
1374.08	52.8977
1377.25	50.3075
1380.42	50.1951
1383.58	48.8885
1386.75	48.4584
1389.91	47.2282
1393.07	47.3784
1396.23	46.233
1399.39	45.6267
1402.55	45.0731
1405.7	45.8079
1408.86	45.2447
1412.01	48.3985
1415.17	51.4561
1418.32	55.2319
1421.47	60.3892
1424.62	66.8204
1427.77	73.6644
1430.92	81.4495
1434.06	87.673
1437.2	94.2131
1440.35	100.863
1443.49	104.449
1446.63	108.35
1449.77	110.257
1452.91	108.807
1456.05	105.659
1459.18	102.9
1462.32	98.5569
1465.45	93.8737
1468.59	86.6093
1471.72	79.7492
1474.85	72.3661
1477.98	66.7426
1481.11	58.1188
1484.23	51.9229
1487.36	45.6336
1490.48	40.7259
1493.61	36.7412
1496.73	32.0755
1499.85	29.376
1502.97	28.1253
1506.09	26.1646
1509.2	26.0211
1512.32	25.5387
1515.44	25.7417
1518.55	25.6547
1521.66	26.2655
1524.77	28.0822
1527.88	29.5021
1530.99	30.8214
1534.1	34.73
1537.21	38.8974
1540.31	44.4163
1543.42	48.6707
1546.52	53.7159
1549.62	59.4381
1552.72	65.1171
1555.82	69.3569
1558.92	72.3691
1562.02	76.4637
1565.11	81.1755
1568.21	84.2818
1571.3	87.1284
1574.39	90.0172
1577.49	92.2335
1580.58	94.3131
1583.67	95.876
1586.75	96.3396
1589.84	95.4385
1592.93	93.8827
1596.01	92.5072
1599.09	90.891
1602.18	89.6164
1605.26	88.6055
1608.34	87.1977
1611.41	85.9659
1614.49	84.0394
1617.57	83.6304
1620.64	83.6727
1623.72	84.8042
1626.79	85.469
1629.86	86.852
1632.93	90.0091
1636	89.2897
1639.07	92.5792
1642.14	97.7937
1645.2	102.364
1648.27	106.882
1651.33	109.5
1654.39	112.297
1657.45	114.213
1660.51	114.613
1663.57	111.709
1666.63	108.236
1669.69	105.356
1672.74	100.897
1675.79	94.8185
1678.85	87.8234
1681.9	80.1053
1684.95	72.3487
1688	64.7655
1691.05	56.0362
1694.1	48.4231
1697.14	40.7456
1700.19	33.2603
1703.23	26.643
1706.27	18.7121
1709.32	12.6704
1712.35	8.39591
1715.39	8.4291
1718.43	7.37187
1721.47	6.38055
1724.5	5.83789
1727.54	6.64965
1730.57	6.48804
1733.61	6.27642
1736.64	6.00864
1739.67	5.66206
1742.7	5.55667
1745.72	6.08964
1748.75	6.09437
1751.78	6.17553
1754.8	5.46929
1757.82	5.68625
1760.85	5.14605
1763.87	3.97248
1766.89	2.97268
1769.91	2.38201
1772.92	3.1284
1775.94	2.33064
1778.96	0.932429
1781.97	-0.138549
1784.98	0.340135
1788	0.169414
1791.01	0.994046
1794.01	1.28458
1797.02	1.00239
1800.03	1.87991
1803.04	2.07159
1806.04	1.5173
1809.05	1.96138
1812.05	1.75484
1815.05	1.20837
1818.05	1.50178
1821.05	0.861729
1824.05	0.108449
1827.05	0.476634
1830.04	-0.160721
1833.04	-0.0151429
1836.03	-0.450416
1839.03	0.219796
1842.02	0.623067
1845.01	1.0247
1848	1.15326
1850.99	0.556418
1853.97	0.781956
1856.96	1.37722
1859.94	2.01007
1862.93	2.50548
1865.91	2.1784
1868.89	2.24359
1871.87	2.64172
1874.85	2.81266
1877.83	2.73576
1880.81	2.87792
1882.56	2.07219
1885.55	2.41774
1888.54	2.60417
1891.52	2.47701
1894.51	2.46296
1897.49	3.15639
1900.48	2.91286
1903.46	3.18786
1906.44	3.87486
1909.42	4.25919
1912.4	3.92181
1915.38	4.21283
1918.35	3.97959
1921.33	3.88488
1924.3	4.15428
1927.28	4.42843
1930.25	4.30532
1933.22	3.29484
1936.19	2.51799
1939.16	3.31513
1942.13	3.3188
1945.09	2.9712
1948.06	2.84647
1951.03	3.38268
1953.99	2.75922
1956.95	3.23709
1959.91	3.41439
1962.87	3.05563
1965.83	3.34191
1968.79	4.31782
1971.75	4.95692
1974.7	3.88537
1977.66	4.4963
1980.61	4.57977
1983.56	4.17498
1986.52	3.79726
1989.47	3.84031
1992.41	4.0714
1995.36	4.92036
1998.31	5.78994
2001.26	6.4601
2004.2	6.24539
2007.15	6.577
2010.09	7.42359
2013.03	7.14123
2015.97	7.32948
2018.91	7.41595
2021.85	8.38133
2024.79	9.05014
2027.72	9.04257
2030.66	9.39982
2033.59	9.90788
2036.53	9.96327
2039.46	10.877
2042.39	12.0639
2045.32	12.9464
2048.25	14.4594
2051.18	15.8795
2054.1	17.2595
2057.03	17.6745
2059.95	19.8788
2062.88	22.3062
2065.8	24.0015
2068.72	25.52
2071.64	27.1539
2074.56	28.4882
2077.48	30.0764
2080.39	31.9183
2083.31	34.562
2086.22	36.8642
2089.14	40.0737
2092.05	42.8348
2094.96	45.8507
2097.87	48.7899
2100.78	51.6383
2103.69	56.2185
2106.6	60.454
2109.51	64.9027
2112.41	70.4721
2115.32	75.8755
2118.22	81.8173
2121.12	87.1359
2124.02	93.2756
2126.92	99.7727
2129.82	105.843
2132.72	111.073
2135.62	114.435
2138.51	119.645
2141.41	122.997
2144.3	127.726
2147.19	132.039
2150.09	135.524
2152.97	139.72
2155.86	142.282
2158.75	144.851
2161.64	147.077
2164.53	147.037
2167.41	147.43
2170.3	148.307
2173.18	147.01
2176.06	146.439
2178.94	143.381
2181.82	141.707
2184.7	138.844
2187.58	135.987
2190.46	133.192
2193.33	128.663
2196.21	125.13
2199.08	119.481
2201.95	113.433
2204.83	106.859
2207.7	102.263
2210.57	97.0593
2213.43	92.1854
2216.3	88.1813
2219.17	83.1586
2222.03	79.2618
2224.9	74.6747
2227.76	70.0067
2230.62	65.2739
2233.49	60.6437
2236.34	57.552
2239.2	53.8934
2242.06	49.4
2244.92	46.2155
2247.78	44.2448
2250.63	41.6077
2253.48	39.1693
2256.34	37.1704
2259.19	34.05
2262.04	32.0175
2264.89	28.9064
2267.74	27.6162
2270.59	25.6203
2273.43	23.6101
2276.28	22.3162
2279.12	22.0388
2281.97	20.589
2284.81	19.9656
2287.65	17.5489
2290.49	16.2364
2293.33	14.1365
2296.17	13.1427
2299.01	13.1411
2301.84	13.6609
2304.68	13.8809
2307.51	14.459
2310.35	14.6997
2313.18	15.2871
2316.01	15.6263
2318.84	14.768
2321.67	14.5092
2324.5	14.1032
2327.33	13.5481
2330.15	12.0478
2332.98	11.829
2335.8	11.6777
2338.62	11.0086
2341.45	9.0282
2344.27	7.78349
2347.09	6.56867
2349.91	5.66895
2352.72	4.39125
2355.54	1.98741
2358.36	-0.0598272
2361.17	-1.00456
2363.98	-0.181365
2366.8	0.785516
2369.61	0.637329
2372.42	0.170148
2375.23	0.605521
2378.04	1.05573
2380.85	1.07786
2383.66	1.24323
2386.46	1.34649
2389.26	1.7626
2392.07	2.61372
2394.87	3.41901
2397.67	3.68587
2400.47	3.64616
2403.27	4.51115
2406.07	5.28346
2408.87	6.5804
2411.67	6.85035
2414.46	8.10775
2417.26	8.52836
2420.05	8.99648
2422.84	8.08446
2425.64	7.67958
2428.43	7.98996
2431.22	8.50737
2434.01	7.44675
2436.79	6.89849
2439.58	6.24969
2442.37	5.55365
2445.15	5.49215
2447.93	5.47871
2450.72	6.40567
2453.5	6.76535
2456.28	6.55726
2459.06	6.27915
2461.84	5.45307
2464.62	5.0088
2467.39	5.29702
2470.17	6.11283
2472.94	6.97297
2475.72	7.55849
2478.49	7.12625
2481.26	7.02312
2484.03	7.36795
2486.8	7.26708
2489.57	6.7497
2492.34	6.6758
2495.1	7.09057
2497.87	6.45309
2500.63	5.78092
2503.4	4.57941
2506.16	4.40873
2508.92	3.84034
2511.68	3.48495
2514.44	3.88904
2517.2	3.75855
2519.96	3.31449
2522.72	3.59017
2525.47	3.06514
2528.23	2.14734
2530.98	1.20392
2533.74	1.09731
2536.49	1.53594
2539.24	1.92997
2541.99	2.55105
2544.74	2.36469
2547.49	3.50473
2550.23	3.99186
2552.98	4.95935
2555.72	5.36423
2558.47	5.5477
2561.21	6.64769
2563.95	7.21105
2566.69	7.46332
2569.43	7.03999
2572.17	6.25622
2574.91	6.45492
2577.65	5.99203
2580.39	6.37694
2583.12	6.1066
2585.85	5.57524
2588.59	5.16597
2591.32	4.04175
2594.05	2.88481
2596.78	2.3297
2599.51	1.83772
2602.24	1.94272
2604.97	2.16058
2607.69	1.9642
2610.42	1.78386
2613.14	1.97999
2615.87	1.73925
2618.59	1.46432
2621.31	1.26165
2624.03	1.31865
2626.75	1.13779
2629.47	2.1526
2632.19	2.05934
2634.91	2.23446
2637.62	2.67233
2640.34	2.83259
2643.05	2.674
2645.76	2.63374
2648.48	2.95138
2651.19	2.96238
2653.9	3.2794
2656.6	3.49075
2659.31	2.69948
2662.02	2.12119
2664.73	2.30382
2667.43	2.4183
2670.14	1.61857
2672.84	1.85406
2675.54	2.45043
2678.24	2.48387
2680.94	2.25608
2683.64	1.83226
2686.34	1.86947
2689.04	3.00594
2691.74	3.50312
2694.43	3.8265
2697.13	3.99064
2699.82	4.20494
2702.51	4.76933
2705.21	4.47776
2707.9	4.87287
2710.58	5.88577
2713.27	6.7326
2715.96	7.7092
2718.65	8.16881
2721.33	8.69117
2724.02	8.88357
2726.71	8.54723
2729.39	8.08639
2732.07	8.03506
2734.75	7.73726
2737.43	7.79172
2740.11	7.13296
2742.79	7.29544
2745.47	7.24593
2748.14	6.99312
2750.82	6.70817
2753.49	6.02136
2756.17	5.3166
2758.84	4.01268
2761.51	2.62913
2764.18	2.35601
2766.85	2.21421
2769.52	1.11279
2772.19	1.86322
2774.86	1.6164
2777.52	1.42387
2780.19	0.985353
2782.85	1.19436
2785.52	1.70147
2788.18	1.71806
2790.84	0.450007
2793.5	0.252236
2796.16	-0.617977
2798.82	-0.0317998
2801.48	0.274969
2804.13	0.395489
2806.79	0.776461
2809.45	-0.18113
2812.1	-1.20236
2814.75	-1.54182
2817.41	-0.228249
2820.06	2.41881
2822.71	6.77358
2825.36	12.3719
2828	19.6342
2830.65	27.211
2833.3	35.6183
2835.94	43.822
2838.59	51.9916
2841.23	60.6033
2843.87	70.5317
2846.52	81.5313
2849.16	95.6136
2851.8	107.147
2854.44	120.484
2857.08	132.909
2859.71	146.87
2862.35	157.966
2864.98	170.085
2867.62	179.432
2870.25	187.246
2872.88	194.079
2875.52	199.305
2878.15	206.497
2880.78	210.721
2883.41	217.508
2886.03	223.381
2888.66	229.347
2891.29	235.117
2893.91	240.068
2896.54	246.093
2899.16	252.024
2901.78	258.578
2904.4	267.781
2907.02	279.13
2909.64	292.445
2912.26	305.38
2914.88	320.907
2917.5	334.84
2920.11	347.203
2922.73	357.29
2925.34	365.699
2927.96	372.103
2930.57	375.191
2933.18	374.79
2935.79	373.202
2938.4	368.912
2941.01	362.223
2943.62	352.683
2946.22	341.588
2948.83	330.452
2951.43	317.206
2954.04	302.327
2956.64	286.832
2959.24	272.832
2961.84	257.768
2964.45	244.148
2967.05	230.969
2969.64	218.265
2972.24	206.82
2974.84	194.315
2977.43	182.101
2980.03	170.941
2982.62	157.309
2985.22	143.649
2987.81	130.493
2990.4	117.722
2992.99	104.964
2995.58	93.2318
2998.17	82.5337
3000.76	72.8262
3003.34	62.5309
3005.93	53.8799
3008.52	46.876
3011.1	40.6633
3013.68	34.1277
3016.27	28.2193
3018.85	23.2733
3021.43	20.9175
3024.01	19.5252
3026.59	18.6641
3029.16	18.2848
3031.74	18.7383
3034.32	19.6443
3036.89	21.1607
3039.47	22.7705
3042.04	24.3479
3044.61	25.5511
3047.18	26.5004
3049.75	27.6061
3052.32	28.1524
3054.89	28.1575
3057.46	27.8333
3060.03	27.2498
3062.59	25.8373
3065.16	24.126
3067.72	22.3079
3070.29	21.0209
3072.85	17.6901
3075.41	14.5291
3077.97	11.8026
3080.53	9.0458
3083.09	6.78676
3085.65	5.59861
3088.21	4.12631
3090.76	1.68242
3093.32	0.728636
3095.87	0.235477
3098.43	0.53511
3100.98	0.732999
3103.53	-0.0892999
3106.08	-0.163068
3108.63	-0.00343094
3111.18	0.62745
3113.73	0.667641
3116.28	0.389941
3118.83	0.297621
3121.37	1.20736
3123.92	1.73486
3126.46	2.45923
3129	3.57202
3131.55	4.30028
3134.09	4.89346
3136.63	5.76481
3139.17	7.60315
3141.71	9.37291
3144.24	11.4158
3146.78	13.3736
3149.32	15.1911