File: data/Raman/poly_smoothed/Thy_40_11_47_1x_45s_532 nm_x100_100%_600 gr_mm_01.txt
#Acq. time (s)=	45
#Accumulations=	2
#Range (cm-¹)=	200...3150
#Windows=	2
#Auto scanning=	Off
#Autofocus=	Off
#Macrospot=	Off
#AutoExposure=	Off
#Spike filter=	Multiple accum.
#Delay time (s)=	0
#Binning=	1
#Readout mode=	Signal
#DeNoise=	Off
#ICS correction=	On
#Dark correction=	Off
#Inst. Process=	Off
#Detector Gain=	Best Dynamic Range
#Detector ADC=	20 kHz
#Detector temperature (°C)=	-69.85
#Instrument=	LabRAM HR Evol
#Detector=	Synapse
#Objective=	x100
#Grating=	600 gr/mm
#ND Filter=	100%
#Laser (nm)=	532
#Hole=	100.021
#Range=	Auto
#Laser Pol.=	No
#Raman. Pol.=	No
#Laser Pol. (°)=	-0.0007625
#Raman Pol. (°)=	89.9995
#Collection=	Microscope
#StageXY=	Marzhauser
#StageZ=	Marzhauser
#X (µm)=	254.5
#Y (µm)=	1691.2
#Z (µm)=	427.7
#Full time(mm:ss)=	3:18
#Project=
#Sample=
#Site=
#Title=	Thy_40_11_47_2x_45s_532 nm_x100_100%_600 gr_mm
#Remark=
#Date=	05.07.2022 13:21
#Acquired=	05.07.2022 13:21:00
#Base:Fit=	10.08.2022 10:01:35
#Base:Sub=	10.08.2022 10:01:52
#Filter:Polynom=	16.08.2022 10:21:53
#AxisType[0]=Intens
#AxisUnit[0]=Cnt
#AxisType[1]=Spectr
#AxisUnit[1]=1/cm
200.43	12.6545
204.059	11.7488
207.688	9.58398
211.314	7.98809
214.941	6.89271
218.564	5.11462
222.186	4.31558
225.809	3.30438
229.428	3.18117
233.045	1.70336
236.663	1.5632
240.278	1.66298
243.891	2.80108
247.503	3.68037
251.116	4.3003
254.725	3.97273
258.333	4.7961
261.939	4.32029
265.544	4.16179
269.148	3.64302
272.75	2.72667
276.351	3.76214
279.95	3.41955
283.548	4.02535
287.144	4.41632
290.739	5.45562
294.333	6.52594
297.925	6.52154
301.514	8.29166
305.104	8.29139
308.692	8.53049
312.279	8.70876
315.862	8.50555
319.446	7.97846
323.029	6.93013
326.608	8.21941
330.188	9.01614
333.766	9.57348
337.341	9.48343
340.917	7.52115
344.489	8.04039
348.062	8.12776
351.631	7.62967
355.201	6.93001
358.768	7.97094
362.333	7.89882
365.899	8.6603
369.462	9.39063
373.023	8.57589
376.585	9.55423
380.143	10.2172
383.7	10.2205
387.256	10.6221
390.812	10.6786
394.365	10.6117
397.916	9.66883
401.467	9.7736
405.015	8.27728
408.563	7.24388
412.109	7.55113
415.654	8.88078
419.197	9.29709
422.739	9.64081
426.279	9.25801
429.819	9.42719
433.356	10.2515
436.891	10.4692
440.426	9.52236
443.96	9.57467
447.492	10.339
451.021	9.77973
454.551	9.70829
458.079	9.38722
461.604	9.01304
465.13	9.73527
468.654	9.33732
472.175	10.1423
475.696	11.4436
479.215	12.7426
482.733	13.5824
486.249	14.0477
489.765	13.9257
493.278	13.3309
496.789	15.1958
500.301	16.0244
503.81	16.9074
507.317	17.2398
510.825	15.0865
514.33	15.5527
517.833	15.5699
521.335	14.8344
524.836	14.5124
528.335	13.9741
531.835	13.3697
535.332	11.9466
538.827	10.5342
542.321	10.6984
545.814	11.0518
549.305	9.84355
552.795	10.7
556.282	11.8475
559.769	12.5995
563.255	12.9817
566.739	13.644
570.223	11.9689
573.705	10.1852
577.183	9.15753
580.663	9.85995
584.141	10.7612
587.615	10.058
591.09	9.50192
594.564	8.22378
598.035	8.01729
601.506	8.84452
604.974	8.80007
608.443	8.17311
611.908	7.36905
615.374	7.14592
618.837	7.2925
622.3	6.82447
625.761	6.84893
629.219	7.49556
632.677	7.03713
636.135	9.59865
639.59	11.6311
643.043	13.2106
646.495	13.7054
649.948	13.5498
653.398	15.6556
656.846	15.8938
660.293	17.2081
663.738	20.4904
667.183	22.8831
670.626	24.7187
674.067	24.9217
677.508	27.0862
680.947	29.4296
684.385	30.8934
687.821	34.2011
691.254	34.6857
694.688	37.0021
698.121	37.0541
701.552	37.8225
704.98	37.9344
708.409	39.0124
711.836	39.8905
715.26	42.8294
718.685	44.0182
722.108	46.0353
725.528	48.2065
728.949	49.6328
732.367	49.7699
735.785	51.2642
739.2	54.3876
742.614	55.1492
746.028	56.7953
749.439	56.986
752.849	59.4048
756.26	60.8678
759.667	63.3877
763.073	66.3617
766.477	69.4932
769.883	72.1533
773.285	75.232
776.686	76.5716
780.085	78.0668
783.484	77.9997
786.881	79.0789
790.276	79.8724
793.671	82.2705
797.064	83.2823
800.456	84.6015
803.846	84.0345
807.234	83.4983
810.622	81.2067
814.008	80.6582
817.394	80.4832
820.778	79.4972
824.159	79.1937
827.541	76.5529
830.921	75.3711
834.298	73.7172
837.676	75.2747
841.051	73.8008
844.426	73.0556
847.798	72.3961
851.171	71.5729
854.54	68.838
857.911	67.1453
861.278	66.5089
864.645	63.0148
868.01	61.105
871.373	60.4566
874.735	60.6751
878.097	59.7294
881.457	57.5248
884.815	55.083
888.172	52.6855
891.528	51.1233
894.882	50.4321
898.237	50.3597
901.589	48.8892
904.94	48.6858
908.289	47.1858
911.635	46.3635
914.982	45.3606
918.328	44.4014
921.672	44.5722
925.015	44.3914
928.357	43.1281
931.698	41.0178
935.035	39.3965
938.373	38.8597
941.71	37.2089
945.044	35.7196
948.378	35.5999
951.709	35.6439
955.041	36.9521
958.372	35.702
961.699	33.1771
965.027	32.3915
968.352	31.3782
971.676	30.124
975	30.0346
978.322	30.1342
981.642	28.4091
984.962	28.5443
988.28	29.1863
991.596	27.3571
994.911	27.7349
998.227	28.0797
1001.54	28.4017
1004.85	29.7024
1008.16	27.8643
1011.47	26.2741
1014.78	26.7469
1018.08	27.3704
1021.39	26.901
1024.69	27.3958
1028	27.4271
1031.3	27.199
1034.6	27.7836
1037.9	25.5221
1041.19	23.2363
1044.49	21.3052
1047.78	21.2748
1051.08	18.994
1054.37	18.1727
1057.66	17.3379
1060.95	16.1044
1064.24	14.2612
1067.53	13.8273
1070.81	12.3928
1074.1	12.2802
1077.38	11.9751
1080.66	12.3846
1083.94	12.6479
1087.22	12.7796
1090.5	12.3677
1093.78	12.3093
1097.05	12.193
1100.33	12.0611
1103.6	11.8547
1106.87	13.1661
1110.14	13.952
1113.41	12.5595
1116.68	13.1455
1119.95	12.7851
1123.21	12.7371
1126.48	12.1022
1129.74	11.3412
1133	9.58725
1136.26	9.22185
1139.52	8.04214
1142.78	7.74657
1146.04	6.79935
1149.29	6.16039
1152.55	5.85508
1155.8	4.57195
1159.05	4.6418
1162.3	4.85493
1165.55	2.89389
1168.8	2.6231
1172.05	0.542315
1175.29	-0.189178
1178.54	0.31802
1181.78	0.787036
1185.02	1.59768
1188.26	3.19771
1191.5	3.32262
1194.74	3.7023
1197.97	5.15355
1201.21	5.44766
1204.44	8.25793
1207.68	9.60784
1210.91	11.1365
1214.14	14.7012
1217.37	17.8047
1220.59	20.3033
1223.82	21.8609
1227.05	23.8552
1230.27	25.549
1233.49	27.4142
1236.72	29.9064
1239.94	32.7243
1243.16	32.6659
1246.37	34.0337
1249.59	36.0729
1252.8	37.2714
1256.02	39.6991
1259.23	40.2298
1262.44	40.9413
1265.66	41.2794
1268.86	42.6953
1272.07	44.4357
1275.28	45.1463
1278.48	46.0654
1281.69	47.9969
1284.89	48.9366
1288.09	49.2903
1291.29	50.1569
1294.49	50.5307
1297.69	49.3216
1300.89	49.0996
1304.08	48.8134
1307.28	49.2343
1310.47	50.2858
1313.66	52.4283
1316.85	51.403
1320.04	51.9212
1323.23	52.1534
1326.42	53.5394
1329.61	53.6475
1332.79	53.4903
1335.97	51.3984
1339.16	48.8741
1342.34	46.6084
1345.52	45.1276
1348.7	45.1948
1351.87	42.3619
1355.05	39.2688
1358.22	37.7224
1361.4	35.0489
1364.57	31.7887
1367.74	28.9691
1370.91	26.8057
1374.08	24.1032
1377.25	23.0612
1380.41	22.2418
1383.58	22.1684
1386.74	21.8209
1389.91	20.8865
1393.07	21.0124
1396.23	20.3698
1399.39	19.9271
1402.55	20.1267
1405.7	21.4363
1408.86	20.1131
1412.01	20.7528
1415.17	22.1973
1418.32	24.6747
1421.47	28.4842
1424.62	32.1785
1427.77	34.011
1430.91	38.3939
1434.06	42.4899
1437.2	47.0675
1440.35	49.6547
1443.49	51.4956
1446.63	53.3459
1449.77	54.0438
1452.91	54.1148
1456.05	53.2567
1459.18	53.1222
1462.32	49.6506
1465.45	46.7467
1468.59	42.221
1471.72	38.9409
1474.85	35.5473
1477.98	32.279
1481.1	28.7826
1484.23	24.1986
1487.36	21.4213
1490.48	20.7079
1493.61	18.9877
1496.73	17.518
1499.85	16.2125
1502.97	15.1709
1506.09	15.7182
1509.2	16.4541
1512.32	16.3177
1515.43	14.8785
1518.55	15.7024
1521.66	15.7884
1524.77	15.1676
1527.88	15.233
1530.99	15.575
1534.1	16.1598
1537.21	16.5872
1540.31	16.3475
1543.42	17.3722
1546.52	19.6973
1549.62	22.2243
1552.72	25.2553
1555.82	27.8172
1558.92	28.8027
1562.02	30.7382
1565.11	32.8455
1568.21	35.1221
1571.3	37.9076
1574.39	40.531
1577.49	43.7024
1580.57	46.2436
1583.66	47.5139
1586.75	48.846
1589.84	48.9765
1592.92	49.8476
1596.01	49.4673
1599.09	48.5403
1602.17	48.329
1605.25	47.3873
1608.33	46.905
1611.41	45.013
1614.49	44.5213
1617.57	44.0123
1620.64	44.4394
1623.72	44.6218
1626.79	45.0734
1629.86	46.3404
1632.93	47.1932
1636	47.3565
1639.07	48.8736
1642.13	50.7305
1645.2	54.9666
1648.26	57.5906
1651.33	60.6074
1654.39	60.5758
1657.45	62.2604
1660.51	62.3271
1663.57	62.3978
1666.63	60.8134
1669.68	58.8816
1672.74	56.7218
1675.79	54.5072
1678.85	51.4646
1681.9	47.3277
1684.95	44.0305
1688	39.1034
1691.05	34.9826
1694.09	30.4582
1697.14	27.5838
1700.18	24.2428
1703.23	21.5058
1706.27	17.8343
1709.31	15.4172
1712.35	13.4002
1715.39	12.2111
1718.43	11.8005
1721.47	11.6263
1724.5	10.9392
1727.54	11.2837
1730.57	10.6307
1733.61	10.9282
1736.64	10.8432
1739.67	9.68478
1742.7	9.41273
1745.72	9.77451
1748.75	9.60001
1751.77	8.97469
1754.8	9.04798
1757.82	8.60264
1760.84	7.78291
1763.87	6.09744
1766.89	4.88887
1769.91	5.19546
1772.92	4.20295
1775.94	3.85185
1778.95	3.97228
1781.97	4.40348
1784.98	4.45435
1787.99	3.80456
1791.01	3.71943
1794.01	3.34181
1797.02	2.91906
1800.03	3.28211
1803.04	2.09534
1806.04	1.56691
1809.05	1.73097
1812.05	2.03321
1815.05	1.81824
1818.05	2.48338
1821.05	2.63432
1824.05	2.48282
1827.05	3.06294
1830.04	3.00226
1833.04	2.98936
1836.03	2.04683
1839.03	2.04361
1842.02	2.37839
1845.01	2.31981
1848	2.15222
1850.99	2.81335
1853.97	2.41782
1856.96	2.30563
1859.94	1.59262
1862.93	1.25579
1865.91	1.94496
1868.89	1.82825
1871.87	1.69398
1874.85	1.43204
1877.83	2.43375
1880.81	2.46031
1882.57	2.3299
1885.56	3.02077
1888.55	4.29584
1891.54	5.47969
1894.52	6.5874
1897.51	8.48126
1900.49	8.58338
1903.47	8.32204
1906.45	7.84899
1909.43	7.57101
1912.41	7.2342
1915.39	6.19568
1918.37	5.67145
1921.34	4.76847
1924.32	5.46813
1927.29	4.74463
1930.26	3.78894
1933.23	3.08028
1936.2	3.28883
1939.17	3.22611
1942.14	3.34768
1945.11	2.74346
1948.07	3.29919
1951.04	3.98647
1954	5.3658
1956.96	5.57642
1959.93	7.30013
1962.89	7.28738
1965.85	8.05429
1968.8	8.48353
1971.76	8.5492
1974.72	8.61817
1977.67	8.28963
1980.63	7.62798
1983.58	7.26059
1986.53	6.72091
1989.48	6.50716
1992.43	6.82077
1995.38	7.21403
1998.32	6.81721
2001.27	6.43705
2004.22	7.39363
2007.16	8.01936
2010.1	7.65795
2013.04	7.86601
2015.98	7.19452
2018.92	7.53996
2021.86	7.61088
2024.8	7.76187
2027.74	8.04523
2030.67	8.29787
2033.61	8.44745
2036.54	8.44707
2039.47	7.77096
2042.4	7.7932
2045.33	7.58192
2048.26	6.726
2051.19	6.89776
2054.12	7.22888
2057.04	7.08671
2059.97	7.52775
2062.89	8.54697
2065.81	9.41968
2068.73	10.3378
2071.65	11.1161
2074.57	12.2723
2077.49	13.1712
2080.41	13.7586
2083.32	14.8571
2086.24	15.5982
2089.15	16.4301
2092.07	17.7158
2094.98	19.3874
2097.89	21.3978
2100.8	23.1782
2103.71	24.5436
2106.61	25.5191
2109.52	26.5083
2112.43	28.0186
2115.33	29.703
2118.23	30.7662
2121.13	32.3983
2124.04	34.6143
2126.94	35.744
2129.83	37.4664
2132.73	39.7506
2135.63	42.6897
2138.53	46.0896
2141.42	48.6468
2144.31	52.0093
2147.21	55.0124
2150.1	58.638
2152.99	61.1763
2155.88	62.9159
2158.77	64.8113
2161.65	66.8828
2164.54	69.2944
2167.43	71.0088
2170.31	71.5364
2173.19	72.0242
2176.07	71.7088
2178.96	71.5858
2181.84	70.2487
2184.72	68.2171
2187.59	66.0124
2190.47	63.8613
2193.35	60.6612
2196.22	57.6276
2199.09	54.3343
2201.97	51.7229
2204.84	49.8462
2207.71	47.879
2210.58	44.5378
2213.45	41.6433
2216.31	39.498
2219.18	36.8674
2222.05	34.4157
2224.91	32.0711
2227.78	29.9097
2230.64	27.7212
2233.5	26.6204
2236.36	24.8331
2239.22	23.3417
2242.08	22.4202
2244.93	21.2388
2247.79	20.811
2250.64	20.0373
2253.5	18.8831
2256.35	18.4454
2259.2	17.6147
2262.05	16.4674
2264.9	16.4012
2267.75	15.6841
2270.6	15.6979
2273.45	15.5791
2276.29	14.3466
2279.14	13.4726
2281.98	12.8104
2284.82	13.1074
2287.66	12.5647
2290.5	10.8985
2293.34	10.2368
2296.18	10.6479
2299.02	10.5912
2301.86	10.236
2304.69	11.0573
2307.53	10.5601
2310.36	10.3271
2313.19	9.7558
2316.02	9.25351
2318.85	8.36022
2321.68	7.57813
2324.51	7.97997
2327.34	8.30056
2330.16	8.71186
2332.99	9.33888
2335.81	9.8819
2338.64	9.35792
2341.46	9.43677
2344.28	9.09427
2347.1	8.91198
2349.92	8.56538
2352.74	8.78973
2355.55	9.57682
2358.37	9.03879
2361.19	9.34605
2364	10.3142
2366.81	10.9703
2369.62	10.6741
2372.44	9.7451
2375.24	8.42992
2378.05	7.5858
2380.86	5.82377
2383.67	4.60962
2386.47	3.92163
2389.28	3.73299
2392.08	3.94904
2394.89	3.79233
2397.69	3.57013
2400.49	2.83416
2403.29	2.11292
2406.09	1.43657
2408.88	1.33372
2411.68	1.07266
2414.48	1.39116
2417.27	1.87707
2420.06	3.1764
2422.86	3.96837
2425.65	4.41505
2428.44	4.83541
2431.23	4.8043
2434.02	4.92977
2436.81	4.5908
2439.59	4.40844
2442.38	3.90986
2445.16	4.56235
2447.95	4.96233
2450.73	4.82833
2453.51	5.4817
2456.29	5.77553
2459.07	5.50625
2461.85	5.20224
2464.63	5.41349
2467.4	5.37086
2470.18	4.99855
2472.95	5.105
2475.73	5.49635
2478.5	5.4066
2481.27	5.25978
2484.04	4.72052
2486.81	3.99112
2489.58	3.35141
2492.35	2.09881
2495.12	1.66887
2497.88	0.833932
2500.65	1.12144
2503.41	0.411309
2506.17	-0.176787
2508.94	-0.0652032
2511.7	1.14342
2514.46	0.65619
2517.22	1.04251
2519.97	0.930646
2522.73	2.51372
2525.49	3.02308
2528.24	3.89567
2530.99	4.23153
2533.75	4.63948
2536.5	5.00562
2539.25	4.69394
2542	4.92137
2544.75	4.4716
2547.5	3.6485
2550.24	2.49787
2552.99	1.84937
2555.74	2.18839
2558.48	2.00974
2561.22	2.07667
2563.96	2.60606
2566.71	2.40937
2569.45	2.16952
2572.18	2.1689
2574.92	1.97941
2577.66	1.82182
2580.4	2.13625
2583.13	3.49135
2585.87	3.35729
2588.6	3.00572
2591.33	3.2603
2594.06	3.09486
2596.79	2.51848
2599.52	2.55779
2602.25	2.26069
2604.98	2.24351
2607.71	1.41517
2610.43	1.6989
2613.16	1.58365
2615.88	1.51472
2618.6	1.47221
2621.32	2.33272
2624.04	2.45099
2626.76	2.72247
2629.48	3.55709
2632.2	3.66302
2634.92	4.24121
2637.63	5.18026
2640.35	5.05998
2643.06	6.12231
2645.77	6.84172
2648.49	6.88436
2651.2	6.97805
2653.91	6.24353
2656.62	6.35612
2659.33	6.57807
2662.03	6.25892
2664.74	6.13788
2667.44	5.50316
2670.15	5.1619
2672.85	4.59835
2675.55	3.78751
2678.26	3.61569
2680.96	2.61919
2683.66	2.1451
2686.35	2.67175
2689.05	2.56485
2691.75	3.37772
2694.44	3.84492
2697.14	4.07818
2699.83	4.08107
2702.52	5.19895
2705.22	5.69317
2707.91	6.56828
2710.6	7.00366
2713.29	7.04543
2715.97	7.77097
2718.66	8.62454
2721.35	9.32591
2724.03	9.25686
2726.72	10.0968
2729.4	10.1057
2732.08	10.3681
2734.76	10.5625
2737.44	10.5176
2740.12	9.73815
2742.8	9.16814
2745.48	8.03869
2748.16	7.24734
2750.83	7.33988
2753.51	7.23357
2756.18	6.78634
2758.85	5.64664
2761.53	5.26974
2764.2	4.47826
2766.87	4.93984
2769.54	4.07232
2772.2	4.16393
2774.87	3.97572
2777.54	3.032
2780.2	3.14983
2782.87	3.42584
2785.53	3.04016
2788.19	2.71032
2790.85	2.73967
2793.51	2.73263
2796.17	2.7872
2798.83	2.29794
2801.49	1.65205
2804.15	0.599637
2806.8	-0.351479
2809.46	-1.26016
2812.11	-2.02571
2814.76	-2.02231
2817.42	-1.92129
2820.07	-1.5955
2822.72	-0.91989
2825.37	0.897825
2828.02	3.47604
2830.66	6.47292
2833.31	9.54442
2835.96	12.2684
2838.6	15.8848
2841.24	18.8655
2843.89	23.5643
2846.53	29.2973
2849.17	35.2333
2851.81	41.0001
2854.45	46.8141
2857.09	52.7321
2859.72	58.6971
2862.36	63.5676
2865	68.124
2867.63	73.4413
2870.26	77.2726
2872.9	80.1501
2875.53	83.0347
2878.16	85.7686
2880.79	88.2893
2883.42	90.633
2886.05	92.6175
2888.67	95.5959
2891.3	98.4631
2893.92	101.46
2896.55	104.792
2899.17	108.498
2901.79	112.384
2904.42	118.452
2907.04	125.766
2909.66	134.147
2912.27	142.015
2914.89	149.964
2917.51	157.14
2920.13	163.86
2922.74	169.751
2925.35	174.135
2927.97	177.652
2930.58	179.668
2933.19	180.325
2935.8	178.836
2938.41	176.911
2941.02	173.213
2943.63	168.38
2946.24	162.741
2948.84	156.849
2951.45	149.969
2954.05	143.434
2956.65	136.436
2959.26	129.795
2961.86	122.462
2964.46	115.555
2967.06	109.985
2969.66	104.137
2972.25	99.0288
2974.85	92.6631
2977.45	87.1147
2980.04	81.394
2982.64	74.9383
2985.23	68.908
2987.82	62.7279
2990.41	56.6328
2993	51.1409
2995.59	45.9739
2998.18	40.9662
3000.77	36.1178
3003.36	31.4935
3005.94	26.4728
3008.53	22.7528
3011.11	19.6083
3013.69	16.149
3016.28	13.5881
3018.86	11.7434
3021.44	10.0775
3024.02	8.42493
3026.6	6.72859
3029.18	6.56648
3031.75	5.61033
3034.33	5.77918
3036.9	5.67543
3039.48	5.45983
3042.05	6.12974
3044.62	7.06955
3047.19	8.2685
3049.77	9.66444
3052.34	10.5256
3054.9	10.7551
3057.47	10.8842
3060.04	10.2804
3062.61	9.70681
3065.17	9.24363
3067.74	8.29294
3070.3	7.3419
3072.86	6.98312
3075.42	5.44896
3077.99	5.01272
3080.54	4.48837
3083.1	3.86647
3085.66	2.90322
3088.22	2.14556
3090.78	1.4927
3093.33	1.16505
3095.89	1.10078
3098.44	1.45805
3100.99	0.828508
3103.54	0.833615
3106.1	1.71088
3108.65	2.26664
3111.2	2.22876
3113.74	1.8734
3116.29	1.25574
3118.84	0.0831165
3121.38	-0.0535295
3123.93	0.0483498
3126.47	-0.0478966
3129.01	0.0347297
3131.56	0.771707
3134.1	0.577934
3136.64	0.671146
3139.18	1.11259
3141.72	2.4801
3144.26	3.75146
3146.79	5.2076
3149.33	8.65058