File: data/Raman/poly_smoothed/Thy_20_09_28_1x_45s_532 nm_x100_100%_600 gr_mm_01.txt
#Acq. time (s)=	45
#Accumulations=	2
#Range (cm-¹)=	200...3150
#Windows=	2
#Auto scanning=	Off
#Autofocus=	Off
#Macrospot=	Off
#AutoExposure=	Off
#Spike filter=	Multiple accum.
#Delay time (s)=	0
#Binning=	1
#Readout mode=	Signal
#DeNoise=	Off
#ICS correction=	On
#Dark correction=	Off
#Inst. Process=	Off
#Detector Gain=	Best Dynamic Range
#Detector ADC=	20 kHz
#Detector temperature (°C)=	-69.85
#Instrument=	LabRAM HR Evol
#Detector=	Synapse
#Objective=	x100
#Grating=	600 gr/mm
#ND Filter=	100%
#Laser (nm)=	532
#Hole=	100.021
#Range=	Auto
#Laser Pol.=	No
#Raman. Pol.=	No
#Laser Pol. (°)=	-0.0007625
#Raman Pol. (°)=	89.9995
#Collection=	Microscope
#StageXY=	Marzhauser
#StageZ=	Marzhauser
#X (µm)=	-5919.4
#Y (µm)=	2884.6
#Z (µm)=	-223.4
#Full time(mm:ss)=	3:18
#Project=
#Sample=
#Site=
#Title=	Thy_20_09_28_2x_45s_532 nm_x100_100%_600 gr_mm
#Remark=
#Date=	29.06.2022 12:36
#Acquired=	29.06.2022 12:36:45
#Base:Fit=	10.08.2022 09:52:02
#Base:Fit=	10.08.2022 09:52:12
#Base:Sub=	10.08.2022 09:54:21
#Filter:Polynom=	16.08.2022 10:24:04
#AxisType[0]=Intens
#AxisUnit[0]=Cnt
#AxisType[1]=Spectr
#AxisUnit[1]=1/cm
200.523	36.2791
204.154	31.2008
207.781	26.999
211.409	23.9251
215.034	21.2672
218.659	19.9922
222.281	16.7602
225.903	13.7193
229.522	11.5042
233.14	9.54722
236.756	8.32116
240.373	7.02002
243.986	5.91113
247.598	4.39083
251.208	4.0923
254.818	3.48079
258.427	3.9332
262.034	2.91059
265.638	2.16943
269.242	2.6738
272.844	2.76142
276.445	3.44666
280.044	3.78897
283.642	4.37834
287.238	5.13583
290.833	7.19028
294.425	8.73619
298.017	10.2858
301.608	11.5016
305.198	12.1402
308.786	13.4126
312.371	14.3847
315.956	14.9484
319.54	15.0307
323.122	14.7997
326.701	13.955
330.281	12.9692
333.857	13.1345
337.434	12.6604
341.008	11.3784
344.582	9.79575
348.153	8.43016
351.724	7.09382
355.292	5.66818
358.861	4.37514
362.426	2.85144
365.99	2.19607
369.555	2.25341
373.116	2.13484
376.676	0.53287
380.236	0.229811
383.793	0.675231
387.349	0.826911
390.903	1.28894
394.456	2.84731
398.007	3.10683
401.56	2.92656
405.108	1.48079
408.656	0.968815
412.202	2.25511
415.746	3.3015
419.29	5.14756
422.831	4.24468
426.37	3.34443
429.909	2.80939
433.447	3.31242
436.983	3.38758
440.519	3.23436
444.052	3.31683
447.583	5.05429
451.114	6.00458
454.643	7.43616
458.169	7.93076
461.696	9.29014
465.222	10.976
468.744	13.4478
472.267	16.0493
475.787	16.284
479.307	16.9259
482.823	17.5925
486.341	16.5675
489.855	17.0801
493.37	17.4225
496.881	18.6384
500.391	18.7566
503.902	17.5756
507.409	17.9047
510.915	15.7277
514.42	13.4286
517.925	13.451
521.427	11.276
524.928	8.89537
528.427	8.92807
531.925	9.35595
535.422	8.88579
538.917	8.78346
542.411	8.33393
545.903	8.69868
549.395	9.83846
552.884	10.845
556.373	11.0049
559.86	9.30574
563.346	8.28761
566.831	6.82233
570.314	6.74672
573.794	7.27584
577.274	6.47742
580.754	7.1069
584.23	7.50971
587.706	7.37174
591.181	7.69728
594.653	7.06402
598.126	6.1328
601.595	6.39634
605.065	7.59295
608.532	6.97265
611.999	6.7045
615.463	6.88404
618.928	6.26662
622.389	7.05452
625.851	8.51184
629.31	9.65672
632.767	10.0857
636.223	11.0078
639.68	11.5216
643.134	10.0315
646.586	11.6629
650.037	11.7383
653.486	12.8241
656.936	13.3761
660.383	14.1771
663.829	15.3745
667.273	17.8429
670.716	19.1005
674.158	19.1949
677.598	19.9694
681.035	21.5906
684.473	22.8007
687.909	24.1884
691.344	24.9915
694.778	24.4856
698.211	24.8793
701.64	25.4874
705.07	28.0184
708.498	27.9317
711.924	30.3542
715.35	33.231
718.774	32.7404
722.196	34.3336
725.618	35.7104
729.037	36.5908
732.456	39.0487
735.873	41.3056
739.289	42.0226
742.703	44.4578
746.116	46.0885
749.529	50.0433
752.938	53.6214
756.347	55.8967
759.756	59.7263
763.162	62.9467
766.567	65.9906
769.97	68.5454
773.372	69.7204
776.773	72.1144
780.174	72.7798
783.573	74.6275
786.97	76.4825
790.365	77.7922
793.76	79.4055
797.153	79.1427
800.543	80.1757
803.933	79.3365
807.322	78.4715
810.71	76.0717
814.097	75.481
817.483	73.1763
820.865	71.7795
824.248	69.9022
827.629	69.7429
831.008	69.7897
834.387	69.7681
837.765	68.5416
841.139	66.1858
844.514	64.9235
847.886	62.1165
851.259	58.6188
854.629	54.9969
857.997	52.5383
861.366	49.5442
864.732	48.0097
868.098	45.434
871.461	44.7216
874.823	41.5905
878.184	40.966
881.545	40.4256
884.903	40.0153
888.26	36.3769
891.616	35.2245
894.97	34.7894
898.323	33.312
901.675	33.0357
905.026	33.849
908.375	33.3109
911.723	34.0583
915.07	34.5474
918.415	34.0164
921.76	32.6707
925.103	30.3383
928.443	29.4301
931.783	27.4864
935.123	25.7545
938.461	25.1687
941.796	24.5618
945.131	23.6632
948.465	22.3402
951.797	22.701
955.128	23.3501
958.457	22.9302
961.786	20.5857
965.113	22.201
968.44	21.4854
971.763	23.9565
975.086	24.0728
978.409	24.1757
981.729	24.601
985.048	25.2452
988.367	23.5105
991.683	23.752
994.998	23.0023
998.312	20.8409
1001.62	18.7763
1004.94	17.1069
1008.25	15.8445
1011.56	15.4414
1014.86	12.7316
1018.17	13.4698
1021.48	13.3361
1024.78	12.6805
1028.08	10.2826
1031.38	10.9843
1034.68	11.0075
1037.98	11.127
1041.28	9.90252
1044.57	11.9771
1047.87	13.2607
1051.16	15.3452
1054.45	15.3733
1057.75	14.122
1061.04	15.0564
1064.32	15.1497
1067.61	16.3225
1070.9	15.1686
1074.18	15.6896
1077.47	16.4551
1080.75	16.7704
1084.03	16.8537
1087.31	18.349
1090.59	17.8271
1093.86	16.8563
1097.14	16.9463
1100.41	17.2792
1103.69	16.8833
1106.96	15.8472
1110.23	14.6589
1113.5	13.7847
1116.77	12.3633
1120.03	9.58407
1123.3	9.59303
1126.56	8.85484
1129.83	7.7369
1133.09	6.61884
1136.35	5.6139
1139.61	3.49339
1142.86	4.35534
1146.12	4.40073
1149.38	3.71698
1152.63	3.25514
1155.88	4.20779
1159.14	4.61784
1162.39	3.72891
1165.63	2.58514
1168.88	2.32827
1172.13	2.10334
1175.38	2.09136
1178.62	3.14747
1181.86	5.0954
1185.1	5.0605
1188.34	5.13949
1191.58	6.93206
1194.82	8.45599
1198.06	9.11313
1201.29	11.4037
1204.53	15.4917
1207.76	18.6425
1210.99	22.5193
1214.22	26.1492
1217.45	28.813
1220.68	31.7716
1223.91	34.2516
1227.13	38.112
1230.36	40.9552
1233.58	43.33
1236.8	43.7143
1240.02	44.4991
1243.24	47.6983
1246.46	50.2578
1249.67	52.092
1252.89	51.6638
1256.1	52.6506
1259.32	54.9045
1262.53	57.3942
1265.74	58.807
1268.95	60.9877
1272.15	62.8933
1275.36	66.4868
1278.57	70.0313
1281.77	75.158
1284.97	79.2849
1288.18	82.323
1291.38	85.4925
1294.58	88.2987
1297.78	90.4924
1300.97	93.023
1304.17	96.2441
1307.36	100.581
1310.55	100.973
1313.75	102.116
1316.94	104.315
1320.13	105.971
1323.32	106.278
1326.5	105.451
1329.69	103.657
1332.87	102.289
1336.06	101.528
1339.24	100.309
1342.42	96.4418
1345.6	93.2114
1348.78	90.3153
1351.96	88.2992
1355.13	84.4151
1358.31	81.4532
1361.48	78.3313
1364.65	75.6074
1367.82	73.2653
1370.99	71.4346
1374.16	69.755
1377.33	68.6517
1380.5	65.9888
1383.66	62.4528
1386.83	60.2818
1389.99	59.6015
1393.15	58.6855
1396.31	57.3095
1399.47	55.3405
1402.63	55.9132
1405.78	55.2362
1408.94	54.8087
1412.1	55.3679
1415.25	57.4245
1418.4	57.8734
1421.55	58.9996
1424.7	61.7857
1427.85	67.242
1431	72.0561
1434.14	77.0284
1437.29	80.7837
1440.43	84.2571
1443.57	87.2252
1446.71	89.2215
1449.85	90.3884
1452.99	89.2147
1456.13	85.9959
1459.26	82.7647
1462.4	81.7765
1465.54	79.5937
1468.67	73.877
1471.8	68.0972
1474.93	62.3847
1478.06	57.6324
1481.19	52.0155
1484.31	46.8664
1487.44	42.9932
1490.56	39.8739
1493.69	38.107
1496.81	34.8334
1499.93	33.4622
1503.05	33.623
1506.17	33.471
1509.28	32.8831
1512.4	31.4922
1515.52	30.7495
1518.63	31.546
1521.74	31.9583
1524.85	33.7925
1527.96	35.5957
1531.07	36.7441
1534.18	38.4345
1537.29	41.707
1540.39	44.0273
1543.5	46.4737
1546.6	50.0967
1549.7	53.3917
1552.8	59.2601
1555.9	64.1224
1559	69.1874
1562.1	74.1413
1565.19	78.1304
1568.29	82.6686
1571.38	86.5941
1574.47	90.7168
1577.56	92.2873
1580.66	95.3816
1583.74	97.0857
1586.83	97.725
1589.92	99.0667
1593.01	97.4412
1596.09	97.2471
1599.17	96.5132
1602.25	94.1881
1605.34	90.9171
1608.41	87.8393
1611.49	84.5379
1614.57	83.5716
1617.65	80.6902
1620.72	78.2505
1623.79	77.7638
1626.87	77.4931
1629.94	76.957
1633.01	77.5527
1636.08	77.9085
1639.15	78.4555
1642.21	79.7019
1645.28	81.139
1648.34	83.4469
1651.41	82.9656
1654.47	84.4552
1657.53	84.7854
1660.59	83.7512
1663.65	83.3006
1666.71	81.8813
1669.76	79.6984
1672.82	77.8039
1675.87	73.7731
1678.93	67.9907
1681.98	63.3355
1685.03	58.414
1688.08	53.2894
1691.13	46.0908
1694.17	40.9867
1697.22	37.0451
1700.27	34.0005
1703.31	29.4923
1706.35	24.539
1709.39	20.3727
1712.43	16.1666
1715.47	13.7776
1718.51	10.9709
1721.55	9.61986
1724.58	8.79445
1727.62	7.57228
1730.65	6.85612
1733.68	5.96045
1736.72	6.7276
1739.74	7.48607
1742.77	6.81403
1745.8	6.96578
1748.83	6.15497
1751.85	6.27357
1754.88	6.40094
1757.9	6.82736
1760.92	6.58664
1763.95	7.18128
1766.96	7.69712
1769.98	8.92668
1773	8.72738
1776.02	7.88617
1779.03	6.92303
1782.05	6.03439
1785.06	6.31595
1788.07	5.85057
1791.08	5.67402
1794.09	5.70088
1797.1	5.73825
1800.11	5.43393
1803.12	4.91867
1806.12	4.4481
1809.12	4.43068
1812.13	4.2137
1815.13	4.0162
1818.13	3.648
1821.13	3.6775
1824.13	3.88813
1827.13	4.2332
1830.12	4.7416
1833.12	5.05993
1836.11	5.80734
1839.1	6.69636
1842.09	6.48622
1845.09	6.71798
1848.08	6.26207
1851.06	5.48305
1854.05	6.09611
1857.04	4.98567
1860.02	4.14562
1863.01	3.73785
1865.99	4.39228
1868.97	4.06212
1871.95	3.09894
1874.93	1.95092
1877.91	1.29496
1880.89	1.18394
1882.46	1.26512
1885.45	1.07261
1888.43	0.744225
1891.42	0.627569
1894.41	0.918298
1897.39	1.13049
1900.37	1.72706
1903.36	2.87014
1906.34	3.84646
1909.32	5.27188
1912.29	6.43783
1915.27	6.754
1918.25	6.55018
1921.23	7.54293
1924.2	7.44904
1927.17	7.98814
1930.15	8.44955
1933.12	8.98359
1936.09	9.8173
1939.06	9.76688
1942.02	8.36794
1944.99	8.55945
1947.96	8.0374
1950.92	7.75151
1953.88	7.34256
1956.85	7.47807
1959.81	6.82986
1962.77	6.25368
1965.73	4.8398
1968.69	4.01914
1971.64	4.12266
1974.6	3.7548
1977.55	3.38749
1980.51	3.85089
1983.46	3.59429
1986.41	3.59316
1989.36	2.65465
1992.31	2.32826
1995.26	3.1107
1998.21	2.61085
2001.15	2.74558
2004.1	3.05307
2007.04	2.77406
2009.99	3.225
2012.93	3.80427
2015.87	3.24657
2018.81	3.97171
2021.75	3.8518
2024.68	4.18752
2027.62	4.26326
2030.56	5.50057
2033.49	4.50224
2036.42	4.38793
2039.36	5.19427
2042.29	5.2749
2045.22	6.98852
2048.14	7.46711
2051.07	7.002
2054	8.31822
2056.93	7.76594
2059.85	7.10242
2062.77	6.88319
2065.7	6.74013
2068.62	6.92676
2071.54	6.89946
2074.46	7.86253
2077.38	8.22497
2080.29	8.52971
2083.21	8.30074
2086.12	8.87123
2089.04	9.26401
2091.95	9.16727
2094.86	10.1071
2097.77	11.1025
2100.68	11.3459
2103.59	12.1936
2106.5	12.926
2109.41	14.2918
2112.31	15.9373
2115.21	15.5631
2118.12	17.311
2121.02	17.6573
2123.92	18.9203
2126.82	20.2675
2129.72	21.9429
2132.62	23.2309
2135.51	25.7748
2138.41	28.6975
2141.31	31.646
2144.2	34.5824
2147.09	37.0839
2149.98	39.3782
2152.87	41.0073
2155.76	42.9328
2158.65	46.3533
2161.54	48.4333
2164.43	49.1523
2167.31	49.0754
2170.2	49.3415
2173.08	48.4314
2175.96	48.187
2178.84	46.9943
2181.72	44.7833
2184.6	43.6273
2187.48	41.5173
2190.36	39.8674
2193.23	37.0573
2196.11	35.2472
2198.98	33.7147
2201.85	31.5221
2204.72	29.2003
2207.59	27.5823
2210.46	25.3413
2213.33	24.9021
2216.2	21.5166
2219.07	20.2718
2221.93	20.309
2224.8	19.8906
2227.66	18.8353
2230.52	17.7901
2233.39	16.5171
2236.25	15.4297
2239.1	16.3908
2241.96	16.2905
2244.82	15.5985
2247.68	15.3274
2250.53	13.8452
2253.38	13.013
2256.24	12.2284
2259.09	11.6839
2261.94	12.6598
2264.79	12.2918
2267.64	10.828
2270.49	10.6419
2273.33	9.99256
2276.18	8.81618
2279.02	8.82017
2281.87	8.24755
2284.71	7.43933
2287.55	7.33524
2290.39	7.47879
2293.23	6.36213
2296.07	6.26524
2298.91	7.3362
2301.74	8.49456
2304.58	8.93366
2307.41	9.82285
2310.25	10.1054
2313.08	9.11055
2315.91	9.0985
2318.74	9.21155
2321.57	10.0261
2324.4	10.4608
2327.23	10.5541
2330.05	10.7481
2332.88	10.275
2335.7	8.51518
2338.52	7.1618
2341.35	6.65902
2344.17	4.29922
2346.99	3.87352
2349.81	3.14272
2352.62	2.03862
2355.44	0.528685
2358.26	-0.0099949
2361.07	-0.542786
2363.89	0.451076
2366.7	2.0666
2369.51	1.38573
2372.32	0.928944
2375.13	0.889817
2377.94	1.09515
2380.75	2.09421
2383.56	2.2315
2386.36	3.13808
2389.17	4.15208
2391.97	5.19182
2394.77	4.8951
2397.58	5.11557
2400.38	4.75397
2403.18	4.36356
2405.97	3.82591
2408.77	3.42926
2411.57	3.34436
2414.37	4.16282
2417.16	3.82194
2419.95	4.00033
2422.75	3.71734
2425.54	3.93161
2428.33	3.56266
2431.12	3.02056
2433.91	3.49742
2436.7	3.88673
2439.48	3.27618
2442.27	3.12761
2445.05	3.3871
2447.84	3.04223
2450.62	3.22656
2453.4	2.8868
2456.18	3.01862
2458.96	2.81649
2461.74	2.49349
2464.52	2.59769
2467.29	2.13146
2470.07	1.97872
2472.85	0.954325
2475.62	0.949937
2478.39	1.50708
2481.16	1.57049
2483.93	1.2286
2486.7	0.346001
2489.47	0.558114
2492.24	1.16665
2495.01	1.13346
2497.77	1.32918
2500.54	3.06337
2503.3	3.77804
2506.06	3.99735
2508.83	3.95472
2511.59	4.09904
2514.35	4.32956
2517.11	4.75578
2519.86	5.04003
2522.62	4.83369
2525.38	6.14039
2528.13	6.85676
2530.89	8.86601
2533.64	9.07536
2536.39	8.79603
2539.14	8.60136
2541.89	8.1437
2544.64	8.67532
2547.39	8.74344
2550.14	8.20732
2552.88	8.31744
2555.63	9.32311
2558.37	8.87178
2561.11	8.24297
2563.86	8.70899
2566.6	8.90601
2569.34	7.34935
2572.08	6.45586
2574.82	6.08647
2577.55	5.97495
2580.29	6.04554
2583.02	5.62772
2585.76	6.37196
2588.49	6.22603
2591.22	7.41135
2593.96	7.60793
2596.69	7.38236
2599.42	7.99088
2602.14	7.38263
2604.87	7.05873
2607.6	8.05622
2610.32	8.13564
2613.05	8.89841
2615.77	8.59641
2618.49	9.68869
2621.22	10.3524
2623.94	10.3703
2626.66	10.1034
2629.37	11.1927
2632.09	11.909
2634.81	11.4998
2637.53	12.1021
2640.24	12.7194
2642.96	12.7562
2645.67	13.6145
2648.38	12.6115
2651.09	12.2582
2653.8	12.3262
2656.51	11.486
2659.22	10.9573
2661.93	10.7032
2664.63	10.3164
2667.34	10.4271
2670.04	9.54251
2672.75	10.3044
2675.45	10.0957
2678.15	8.96834
2680.85	8.7063
2683.55	8.45669
2686.25	8.75903
2688.94	9.22717
2691.64	8.57386
2694.34	8.85158
2697.03	9.27822
2699.73	10.0163
2702.42	10.7991
2705.11	11.7431
2707.8	11.3256
2710.49	12.46
2713.18	13.2202
2715.87	13.4995
2718.55	14.3154
2721.24	15.0618
2723.93	15.815
2726.61	15.8454
2729.29	16.8512
2731.98	17.2628
2734.66	16.3345
2737.34	15.5802
2740.02	15.9833
2742.7	14.1901
2745.37	13.6611
2748.05	12.9103
2750.72	11.7357
2753.4	11.2034
2756.07	10.2078
2758.75	9.85187
2761.42	9.11574
2764.09	7.80817
2766.76	5.99383
2769.43	6.33362
2772.1	5.35898
2774.76	3.19466
2777.43	3.1274
2780.1	3.2054
2782.76	2.08441
2785.42	1.7977
2788.09	1.43203
2790.75	0.379441
2793.41	0.389247
2796.07	-0.202244
2798.73	0.0945209
2801.39	-0.4546
2804.04	0.0150304
2806.7	0.211541
2809.35	0.313703
2812.01	1.05352
2814.66	2.32513
2817.31	2.9509
2819.96	5.46217
2822.61	6.3681
2825.26	9.59643
2827.91	11.4714
2830.56	14.4138
2833.21	17.9738
2835.85	20.5037
2838.5	24.1769
2841.14	29.0911
2843.78	35.3451
2846.42	41.747
2849.06	48.1754
2851.71	55.2539
2854.34	63.6284
2856.98	71.8761
2859.62	80.1393
2862.26	89.1719
2864.89	95.5961
2867.53	102.923
2870.16	109.314
2872.79	114.647
2875.42	120.599
2878.05	124.95
2880.68	130.369
2883.31	134.429
2885.94	139.812
2888.57	144.815
2891.19	149.082
2893.82	153.037
2896.44	158.779
2899.07	163.868
2901.69	170.154
2904.31	177.891
2906.93	187.153
2909.55	196.58
2912.17	206.334
2914.79	216.314
2917.41	225.689
2920.02	233.725
2922.64	239.877
2925.25	244.477
2927.86	246.893
2930.48	247.227
2933.09	246.358
2935.7	243.142
2938.31	237.943
2940.92	230.602
2943.53	223.943
2946.13	216.595
2948.74	208.957
2951.34	200.191
2953.95	191.006
2956.55	182.092
2959.15	173.847
2961.75	164.677
2964.35	157.064
2966.95	148.682
2969.55	141.842
2972.15	135.26
2974.75	128.013
2977.34	120.344
2979.94	112.935
2982.53	104.183
2985.13	95.295
2987.72	85.3006
2990.31	76.3874
2992.9	67.7061
2995.49	59.2666
2998.08	50.2146
3000.67	43.0383
3003.25	36.2459
3005.84	29.5275
3008.42	24.1581
3011.01	19.3627
3013.59	15.4873
3016.17	12.2808
3018.76	9.32375
3021.34	7.35958
3023.92	5.6556
3026.49	4.04974
3029.07	4.31647
3031.65	4.77352
3034.23	5.45177
3036.8	6.5979
3039.38	7.74355
3041.95	7.9036
3044.52	8.82605
3047.09	9.97873
3049.66	11.9642
3052.23	13.8366
3054.8	15.6332
3057.37	16.3836
3059.94	17.6624
3062.5	17.6477
3065.07	17.4889
3067.63	16.0551
3070.2	14.5393
3072.76	13.892
3075.32	12.2618
3077.88	11.2952
3080.44	9.24566
3083	8.13801
3085.56	6.66929
3088.12	5.43121
3090.67	5.28275
3093.23	5.29793
3095.78	4.99176
3098.34	6.10939
3100.89	6.55953
3103.44	7.44966
3105.99	8.91713
3108.54	10.554
3111.09	11.8244
3113.64	13.3696
3116.19	15.0302
3118.74	17.319
3121.28	19.1799
3123.83	21.0758
3126.37	21.7074
3128.91	23.327
3131.46	24.1611
3134	26.1581
3136.54	28.2257
3139.08	30.488
3141.62	32.255
3144.16	34.3154
3146.69	36.9172
3149.23	41.0429