File: data/Raman/poly_smoothed/Thy_50_12_02_1x_45s_532 nm_x100_100%_600 gr_mm_01.txt
#Acq. time (s)=	45
#Accumulations=	2
#Range (cm-¹)=	200...3150
#Windows=	2
#Auto scanning=	Off
#Autofocus=	Off
#Macrospot=	Off
#AutoExposure=	Off
#Spike filter=	Multiple accum.
#Delay time (s)=	0
#Binning=	1
#Readout mode=	Signal
#DeNoise=	Off
#ICS correction=	On
#Dark correction=	Off
#Inst. Process=	Off
#Detector Gain=	Best Dynamic Range
#Detector ADC=	20 kHz
#Detector temperature (°C)=	-69.85
#Instrument=	LabRAM HR Evol
#Detector=	Synapse
#Objective=	x100
#Grating=	600 gr/mm
#ND Filter=	100%
#Laser (nm)=	532
#Hole=	100.021
#Range=	Auto
#Laser Pol.=	No
#Raman. Pol.=	No
#Laser Pol. (°)=	-0.0007625
#Raman Pol. (°)=	89.9995
#Collection=	Microscope
#StageXY=	Marzhauser
#StageZ=	Marzhauser
#X (µm)=	-5086.4
#Y (µm)=	1505.1
#Z (µm)=	62.8
#Full time(mm:ss)=	3:18
#Project=
#Sample=
#Site=
#Title=	Thy_50_12_02_2x_45s_532 nm_x100_100%_600 gr_mm
#Remark=
#Date=	07.07.2022 09:15
#Acquired=	07.07.2022 09:15:06
#Base:Fit=	10.08.2022 10:03:08
#Base:Fit=	10.08.2022 10:03:15
#Base:Fit=	10.08.2022 10:03:19
#Base:Fit=	10.08.2022 10:04:29
#Base:Sub=	10.08.2022 10:04:45
#Filter:Polynom=	16.08.2022 10:20:24
#AxisType[0]=Intens
#AxisUnit[0]=Cnt
#AxisType[1]=Spectr
#AxisUnit[1]=1/cm
200.43	37.0608
204.061	30.9427
207.688	28.0601
211.316	26.4415
214.941	24.0271
218.566	20.7835
222.188	17.719
225.809	15.4989
229.43	14.2047
233.047	13.5529
236.663	13.6177
240.278	13.0334
243.894	12.4049
247.506	13.1755
251.116	14.1215
254.725	14.3892
258.333	14.6725
261.939	14.6078
265.546	13.8752
269.15	11.2619
272.752	12.0736
276.353	10.8393
279.952	10.918
283.55	12.1832
287.146	12.0972
290.739	12.7074
294.333	13.2308
297.925	12.2042
301.516	12.317
305.106	12.2671
308.694	13.3912
312.279	13.3648
315.864	13.9973
319.448	14.2766
323.029	15.8098
326.61	14.9052
330.19	16.0083
333.766	16.9568
337.343	17.3942
340.917	16.5842
344.491	16.0331
348.062	16.3802
351.633	14.2061
355.201	12.6239
358.77	12.6798
362.335	11.6478
365.899	12.0327
369.464	12.6563
373.025	12.5695
376.585	12.6125
380.143	13.1417
383.702	13.6202
387.258	14.1538
390.812	15.3259
394.365	13.9416
397.916	11.9446
401.467	10.5321
405.015	10.3054
408.565	9.77076
412.111	8.82683
415.656	8.4803
419.197	8.88251
422.739	7.88946
426.279	7.24562
429.819	6.48587
433.356	5.85896
436.893	4.2932
440.428	4.86715
443.96	5.8284
447.492	6.63482
451.023	7.65192
454.553	9.51068
458.079	10.7182
461.606	11.6576
465.132	11.2818
468.654	12.0558
472.177	14.1178
475.696	14.7285
479.217	15.4748
482.733	16.9469
486.251	17.58
489.765	18.7647
493.278	20.4665
496.791	19.9178
500.301	20.3668
503.81	22.1752
507.319	21.9967
510.825	22.7499
514.33	22.6729
517.833	23.1119
521.337	22.7813
524.838	24.069
528.337	24.0009
531.835	23.4108
535.332	23.7075
538.827	21.2086
542.321	20.6364
545.814	19.2447
549.305	16.5652
552.795	16.023
556.284	15.0806
559.771	14.2143
563.257	12.2639
566.742	11.7431
570.223	9.56314
573.705	7.4076
577.185	4.7758
580.665	3.65348
584.141	2.49699
587.617	1.92223
591.092	1.74327
594.564	1.85742
598.037	2.65989
601.506	3.3506
604.976	4.35843
608.443	5.09542
611.91	6.29433
615.374	6.92782
618.839	8.04142
622.3	7.71332
625.761	8.01805
629.221	8.79872
632.679	11.0943
636.135	11.9558
639.592	12.9898
643.045	13.8007
646.497	14.0107
649.948	14.7304
653.398	15.7831
656.846	16.8037
660.293	16.8325
663.738	18.0442
667.185	18.0407
670.628	18.9471
674.067	21.1585
677.508	22.5679
680.947	22.9818
684.385	25.798
687.821	26.9075
691.256	27.6575
694.69	28.4389
698.121	29.5432
701.552	31.4843
704.982	32.9538
708.41	33.6352
711.836	37.097
715.262	41.3128
718.685	43.5571
722.108	46.805
725.53	46.8501
728.949	47.9993
732.369	48.8903
735.785	50.8017
739.2	53.1373
742.616	54.6513
746.028	55.6126
749.441	57.8915
752.851	61.4446
756.26	64.3454
759.667	67.3351
763.075	69.2802
766.479	70.3805
769.883	70.5023
773.285	71.4881
776.686	72.6238
780.085	73.633
783.484	76.2752
786.881	78.6152
790.276	78.9972
793.671	80.9243
797.064	82.9029
800.456	81.9219
803.846	82.3009
807.236	81.9936
810.624	79.2769
814.01	79.2132
817.394	79.6093
820.778	78.9962
824.161	79.2143
827.543	78.2204
830.921	78.1602
834.3	77.4584
837.676	77.7503
841.053	75.0215
844.426	72.8778
847.8	69.3216
851.171	67.308
854.542	64.2605
857.911	63.0501
861.279	60.1405
864.645	59.5158
868.01	57.3084
871.375	56.2537
874.737	53.5093
878.097	51.1391
881.457	49.3751
884.817	48.6823
888.174	47.9287
891.53	46.4523
894.884	45.9757
898.237	47.8734
901.589	48.0871
904.94	49.4939
908.289	48.5268
911.637	48.0038
914.984	47.7845
918.33	48.0313
921.674	48.1411
925.015	46.2995
928.357	44.3509
931.698	42.3366
935.037	38.8999
938.373	37.6007
941.71	37.1449
945.046	34.4003
948.378	31.8998
951.711	31.6764
955.043	30.7307
958.372	28.372
961.701	28.7519
965.027	29.4078
968.354	32.3264
971.678	32.816
975	33.5233
978.324	36.0142
981.644	38.969
984.962	39.6446
988.282	41.7394
991.598	42.2728
994.913	43.6735
998.227	45.2836
1001.54	44.7803
1004.85	42.0948
1008.16	41.6518
1011.47	38.7825
1014.78	36.1245
1018.08	37.7505
1021.39	36.741
1024.69	37.4099
1028	36.4451
1031.3	36.9303
1034.6	37.9051
1037.9	37.0192
1041.19	36.53
1044.49	34.9404
1047.79	36.1081
1051.08	35.4151
1054.37	34.305
1057.66	35.73
1060.95	35.6899
1064.24	34.3364
1067.53	33.2097
1070.81	33.7651
1074.1	32.2934
1077.38	28.8315
1080.66	26.6579
1083.94	24.9225
1087.22	23.4993
1090.5	22.3416
1093.78	20.8068
1097.05	20.681
1100.33	21.2549
1103.6	20.9176
1106.87	21.478
1110.15	20.7215
1113.41	19.9051
1116.68	17.8667
1119.95	15.1643
1123.21	13.6972
1126.48	12.3498
1129.74	12.4284
1133	9.58319
1136.26	10.3965
1139.52	9.74846
1142.78	8.81407
1146.04	9.14049
1149.29	7.80077
1152.55	7.83412
1155.8	6.89749
1159.05	6.02657
1162.3	6.19047
1165.55	7.10165
1168.8	7.81726
1172.05	7.82877
1175.29	6.7566
1178.54	7.09111
1181.78	7.92341
1185.02	8.32916
1188.26	7.41488
1191.5	6.29203
1194.74	5.78605
1197.97	5.70969
1201.21	5.08274
1204.44	5.27385
1207.68	6.8748
1210.91	8.8105
1214.14	11.7899
1217.37	15.3132
1220.6	17.067
1223.82	20.8558
1227.05	24.1901
1230.27	28.4905
1233.49	30.8241
1236.72	35.2236
1239.94	38.8199
1243.16	42.8896
1246.37	48.6755
1249.59	51.3511
1252.8	53.5966
1256.02	57.0503
1259.23	60.7118
1262.44	64.7643
1265.66	66.9511
1268.87	67.2416
1272.07	69.4459
1275.28	71.659
1278.48	73.5554
1281.69	74.2273
1284.89	76.2842
1288.09	79.458
1291.3	80.2029
1294.49	81.0279
1297.69	81.6703
1300.89	81.2058
1304.09	82.8708
1307.28	83.1145
1310.47	82.1825
1313.66	80.2444
1316.86	80.4528
1320.05	78.8836
1323.23	78.9341
1326.42	77.0323
1329.61	74.8439
1332.79	72.8898
1335.98	70.0234
1339.16	66.377
1342.34	61.9502
1345.52	57.2481
1348.7	53.6484
1351.87	51.8808
1355.05	49.8406
1358.23	46.8203
1361.4	43.9332
1364.57	42.0237
1367.74	41.2599
1370.91	39.4669
1374.08	39.4922
1377.25	38.8081
1380.42	38.4916
1383.58	38.7297
1386.75	37.6055
1389.91	37.4277
1393.07	38.5443
1396.23	40.4164
1399.39	41.1695
1402.55	40.8232
1405.7	41.8283
1408.86	44.2926
1412.01	45.4064
1415.17	47.498
1418.32	49.1685
1421.47	53.2529
1424.62	59.4196
1427.77	64.226
1430.92	69.9137
1434.06	73.9597
1437.2	79.502
1440.35	83.4949
1443.49	87.3389
1446.63	90.0776
1449.77	90.548
1452.91	89.9904
1456.05	88.4067
1459.18	86.311
1462.32	83.5629
1465.45	79.9228
1468.59	75.0002
1471.72	69.0753
1474.85	63.0249
1477.98	55.7509
1481.11	51.1041
1484.23	45.3473
1487.36	39.3998
1490.48	33.054
1493.61	27.5555
1496.73	24.2643
1499.85	22.0082
1502.97	20.4586
1506.09	18.8656
1509.2	17.6044
1512.32	16.0784
1515.44	15.0563
1518.55	15.702
1521.66	17.0391
1524.77	18.4413
1527.88	20.1644
1530.99	22.5016
1534.1	25.1651
1537.21	28.9301
1540.31	32.945
1543.42	37.2336
1546.52	41.7192
1549.62	47.4072
1552.72	52.5125
1555.82	56.9889
1558.92	61.941
1562.02	65.7823
1565.11	70.6799
1568.21	74.061
1571.3	77.9063
1574.39	81.703
1577.49	83.2028
1580.58	84.972
1583.67	86.3627
1586.75	85.048
1589.84	84.5224
1592.93	84.5247
1596.01	83.8832
1599.09	81.3129
1602.18	79.3182
1605.26	76.6036
1608.34	74.1205
1611.41	73.3137
1614.49	72.2888
1617.57	72.4175
1620.64	73.1113
1623.72	72.8034
1626.79	72.6641
1629.86	75.5292
1632.93	78.4708
1636	82.7121
1639.07	86.1522
1642.14	90.7792
1645.2	94.2034
1648.27	96.2392
1651.33	98.4869
1654.39	99.2855
1657.45	99.9637
1660.51	97.9892
1663.57	96.6396
1666.63	92.4839
1669.69	88.2813
1672.74	82.8339
1675.79	76.9841
1678.85	70.4056
1681.9	63.1422
1684.95	55.3425
1688	48.7271
1691.05	41.892
1694.1	35.9785
1697.14	29.3338
1700.19	23.2056
1703.23	18.7903
1706.27	15.0817
1709.32	14.0115
1712.35	12.9542
1715.39	11.6085
1718.43	10.5835
1721.47	9.7405
1724.5	9.43063
1727.54	9.08528
1730.57	9.30176
1733.61	9.71098
1736.64	10.6124
1739.67	10.1895
1742.7	9.93139
1745.72	9.76617
1748.75	8.62901
1751.78	8.16247
1754.8	6.8535
1757.82	6.6093
1760.85	6.26276
1763.87	5.89417
1766.89	5.30541
1769.91	4.79094
1772.92	2.72386
1775.94	2.36031
1778.96	1.98152
1781.97	2.8808
1784.98	4.34785
1788	5.01104
1791.01	4.59292
1794.01	4.65378
1797.02	5.08926
1800.03	4.99179
1803.04	5.6491
1806.04	6.07984
1809.05	6.69164
1812.05	6.06946
1815.05	5.2389
1818.05	4.39256
1821.05	3.70547
1824.05	3.51284
1827.05	2.8441
1830.04	2.05032
1833.04	2.10129
1836.03	1.81601
1839.03	1.52476
1842.02	1.80613
1845.01	1.19737
1848	1.16357
1850.99	1.62015
1853.97	0.280341
1856.96	-0.350442
1859.94	-0.104878
1862.93	0.257491
1865.91	0.191058
1868.89	-0.374268
1871.87	1.05961
1874.85	0.855365
1877.83	1.51124
1880.81	2.50743
1882.56	2.64158
1885.55	2.9939
1888.54	2.61308
1891.52	3.89729
1894.51	4.97563
1897.49	4.84455
1900.48	5.61457
1903.46	6.00985
1906.44	8.05705
1909.42	8.97912
1912.4	9.99128
1915.38	10.8694
1918.35	11.3883
1921.33	10.5893
1924.3	10.1878
1927.28	9.74781
1930.25	9.82408
1933.22	10.5028
1936.19	10.2081
1939.16	10.468
1942.13	9.60051
1945.09	8.86407
1948.06	9.0253
1951.03	9.0993
1953.99	7.92404
1956.95	7.7161
1959.91	8.74222
1962.87	7.9369
1965.83	6.96488
1968.79	5.81868
1971.75	5.54685
1974.7	5.43827
1977.66	5.92068
1980.61	7.43598
1983.56	7.86811
1986.52	8.40563
1989.47	8.10358
1992.41	8.68154
1995.36	8.47149
1998.31	9.58984
2001.26	9.02619
2004.2	9.60399
2007.15	11.5063
2010.09	11.2163
2013.03	11.7899
2015.97	11.7704
2018.91	12.8526
2021.85	14.2907
2024.79	14.2586
2027.72	15.3152
2030.66	16.2336
2033.59	18.0711
2036.53	17.0365
2039.46	17.6244
2042.39	17.7391
2045.32	19.162
2048.25	19.1076
2051.18	19.5411
2054.1	18.9968
2057.03	18.3158
2059.95	18.5996
2062.88	19.1741
2065.8	20.8885
2068.72	21.6407
2071.64	22.4172
2074.56	23.9804
2077.48	26.3135
2080.39	29.8398
2083.31	31.8786
2086.22	33.7227
2089.14	35.7388
2092.05	38.1963
2094.96	42.2438
2097.87	45.8895
2100.78	49.2651
2103.69	51.1465
2106.6	55.0168
2109.51	57.018
2112.41	58.9859
2115.32	61.6458
2118.22	64.2937
2121.12	67.901
2124.02	70.3101
2126.92	73.557
2129.82	78.8554
2132.72	84.502
2135.62	89.8646
2138.51	94.8132
2141.41	99.3505
2144.3	104.381
2147.19	109.954
2150.09	115.322
2152.97	119.729
2155.86	123.008
2158.75	125.047
2161.64	127.133
2164.53	129.819
2167.41	129.656
2170.3	128.199
2173.18	128.37
2176.06	127.222
2178.94	126.299
2181.82	123.512
2184.7	121.914
2187.58	120.095
2190.46	117.524
2193.33	114.776
2196.21	110.539
2199.08	107.043
2201.95	103.986
2204.83	100.405
2207.7	95.7776
2210.57	91.9933
2213.43	88.581
2216.3	83.4895
2219.17	78.9979
2222.03	74.7484
2224.9	69.6613
2227.76	64.4174
2230.62	60.1002
2233.49	55.3064
2236.34	52.059
2239.2	47.6967
2242.06	46.5387
2244.92	44.6774
2247.78	42.8922
2250.63	41.2787
2253.48	39.6844
2256.34	38.5706
2259.19	37.0289
2262.04	36.0796
2264.89	34.3213
2267.74	32.4904
2270.59	32.1264
2273.43	31.3612
2276.28	30.1898
2279.12	28.4792
2281.97	26.7722
2284.81	24.1047
2287.65	22.5758
2290.49	20.2134
2293.33	18.2581
2296.17	16.5771
2299.01	16.0165
2301.84	15.7917
2304.68	15.2936
2307.51	15.2439
2310.35	16.4777
2313.18	15.458
2316.01	15.7774
2318.84	15.4644
2321.67	14.8776
2324.5	14.5672
2327.33	12.6515
2330.15	11.8175
2332.98	11.833
2335.8	10.9273
2338.62	10.516
2341.45	9.45215
2344.27	6.8954
2347.09	5.21814
2349.91	4.41891
2352.72	4.07006
2355.54	2.58479
2358.36	1.42055
2361.17	-0.210835
2363.98	-0.145839
2366.8	0.689533
2369.61	1.28573
2372.42	1.6408
2375.23	1.71358
2378.04	2.82161
2380.85	2.17623
2383.66	1.70037
2386.46	2.49043
2389.26	2.86988
2392.07	3.26292
2394.87	4.8641
2397.67	4.85433
2400.47	4.95387
2403.27	5.96329
2406.07	6.60175
2408.87	7.74744
2411.67	7.88008
2414.46	9.17044
2417.26	11.6228
2420.05	13.3807
2422.84	13.2136
2425.64	12.6052
2428.43	12.3542
2431.22	12.9962
2434.01	12.0529
2436.79	11.6414
2439.58	11.9653
2442.37	11.9223
2445.15	10.2861
2447.93	9.08501
2450.72	6.93251
2453.5	6.89434
2456.28	6.67727
2459.06	6.18211
2461.84	5.87783
2464.62	4.15261
2467.39	4.44919
2470.17	3.29367
2472.94	3.72285
2475.72	3.65619
2478.49	3.99535
2481.26	5.20002
2484.03	5.90743
2486.8	5.29239
2489.57	4.30263
2492.34	4.0963
2495.1	3.01073
2497.87	2.35483
2500.63	3.5569
2503.4	2.86835
2506.16	2.94693
2508.92	3.31438
2511.68	2.19319
2514.44	0.795012
2517.2	0.616586
2519.96	0.657987
2522.72	0.914993
2525.47	1.21464
2528.23	0.820751
2530.98	0.441265
2533.74	1.01043
2536.49	0.103901
2539.24	0.120383
2541.99	0.933448
2544.74	1.00105
2547.49	1.31204
2550.23	1.55102
2552.98	0.856879
2555.72	1.82053
2558.47	2.02206
2561.21	3.00023
2563.95	3.84965
2566.69	4.77512
2569.43	6.08415
2572.17	5.22176
2574.91	6.04524
2577.65	5.73683
2580.39	6.36293
2583.12	5.35697
2585.85	6.24705
2588.59	6.07975
2591.32	6.05074
2594.05	6.01894
2596.78	6.24263
2599.51	7.09044
2602.24	5.96952
2604.97	5.73315
2607.69	5.31423
2610.42	4.36868
2613.14	4.57464
2615.87	3.11614
2618.59	2.54562
2621.31	2.59652
2624.03	2.50028
2626.75	2.20949
2629.47	2.83339
2632.19	1.99894
2634.91	1.46988
2637.62	0.580301
2640.34	1.32242
2643.05	0.649799
2645.76	0.0345609
2648.48	0.133904
2651.19	0.0587862
2653.9	0.999622
2656.6	1.19454
2659.31	3.02529
2662.02	3.38412
2664.73	4.52765
2667.43	4.6004
2670.14	3.01509
2672.84	2.50271
2675.54	2.96032
2678.24	2.68024
2680.94	2.92806
2683.64	2.93526
2686.34	2.64197
2689.04	2.24377
2691.74	2.60091
2694.43	1.77007
2697.13	2.79472
2699.82	3.44398
2702.51	4.42332
2705.21	4.98221
2707.9	6.49624
2710.58	7.68428
2713.27	8.92657
2715.96	9.92424
2718.65	11.9007
2721.33	12.4048
2724.02	13.519
2726.71	14.4511
2729.39	14.87
2732.07	15.197
2734.75	13.8173
2737.43	12.7375
2740.11	12.9738
2742.79	12.9655
2745.47	12.132
2748.14	10.8897
2750.82	8.85596
2753.49	7.32101
2756.17	6.35927
2758.84	5.33983
2761.51	5.58031
2764.18	5.63599
2766.85	5.73437
2769.52	5.81456
2772.19	6.54817
2774.86	6.78157
2777.52	7.1019
2780.19	7.01843
2782.85	6.8813
2785.52	7.06589
2788.18	6.80175
2790.84	6.32276
2793.5	5.30747
2796.16	4.90573
2798.82	4.70582
2801.48	4.59269
2804.13	4.1664
2806.79	5.10913
2809.45	4.78839
2812.1	3.40961
2814.75	3.5428
2817.41	3.83057
2820.06	6.096
2822.71	9.9138
2825.36	15.4568
2828	21.9574
2830.65	27.7044
2833.3	35.3979
2835.94	42.7202
2838.59	50.2763
2841.23	58.3007
2843.87	66.4242
2846.52	74.8979
2849.16	84.4251
2851.8	94.6703
2854.44	104.999
2857.08	114.804
2859.71	125.724
2862.35	136.014
2864.98	145.568
2867.62	153.157
2870.25	160.576
2872.88	166.263
2875.52	170.946
2878.15	175.309
2880.78	179.381
2883.41	184.275
2886.03	191.838
2888.66	197.763
2891.29	202.778
2893.91	207.297
2896.54	213.544
2899.16	220.552
2901.78	228.454
2904.4	236.199
2907.02	247.354
2909.64	259.139
2912.26	270.609
2914.88	283.582
2917.5	294.768
2920.11	305.134
2922.73	314.298
2925.34	321.015
2927.96	325.305
2930.57	326.695
2933.18	326.797
2935.79	325.655
2938.4	321.134
2941.01	313.889
2943.62	306.51
2946.22	297.417
2948.83	287.18
2951.43	276.318
2954.04	264.331
2956.64	251.845
2959.24	239.654
2961.84	229.063
2964.45	217.807
2967.05	207.291
2969.64	197.793
2972.24	187.853
2974.84	178.092
2977.43	167.599
2980.03	157.009
2982.62	147.297
2985.22	135.941
2987.81	124.301
2990.4	112.152
2992.99	100.391
2995.58	90.5712
2998.17	81.4032
3000.76	72.607
3003.34	63.313
3005.93	55.5243
3008.52	48.713
3011.1	41.5741
3013.68	35.9926
3016.27	31.4358
3018.85	27.5028
3021.43	24.0019
3024.01	22.6365
3026.59	20.7602
3029.16	19.2402
3031.74	18.3801
3034.32	18.2307
3036.89	19.2842
3039.47	20.3782
3042.04	20.8166
3044.61	20.7459
3047.18	21.2122
3049.75	20.8287
3052.32	21.0077
3054.89	20.7231
3057.46	22.4693
3060.03	22.4109
3062.59	21.0987
3065.16	20.0292
3067.72	17.8823
3070.29	16.0878
3072.85	14.6464
3075.41	11.9737
3077.97	10.3921
3080.53	8.32235
3083.09	7.12569
3085.65	4.98443
3088.21	3.23742
3090.76	2.01198
3093.32	1.74617
3095.87	1.03526
3098.43	1.57195
3100.98	1.18585
3103.53	-0.123295
3106.08	-0.424676
3108.63	0.0466745
3111.18	0.522062
3113.73	1.30978
3116.28	2.1735
3118.83	2.74776
3121.37	2.00953
3123.92	2.84249
3126.46	2.78105
3129	3.38419
3131.55	4.37575
3134.09	4.68561
3136.63	5.72097
3139.17	6.89144
3141.71	8.55959
3144.24	10.2639
3146.78	12.0601
3149.32	15.6699