File: data/Raman/poly_smoothed/Thy_00_07_30_1x_45s_532 nm_x100_100%_600 gr_mm_01.txt
#Acq. time (s)=	45
#Accumulations=	2
#Range (cm-¹)=	200...3150
#Windows=	2
#Auto scanning=	Off
#Autofocus=	Off
#Macrospot=	Off
#AutoExposure=	Off
#Spike filter=	Multiple accum.
#Delay time (s)=	0
#Binning=	1
#Readout mode=	Signal
#DeNoise=	Off
#ICS correction=	On
#Dark correction=	Off
#Inst. Process=	Off
#Detector Gain=	Best Dynamic Range
#Detector ADC=	20 kHz
#Detector temperature (°C)=	-69.85
#Instrument=	LabRAM HR Evol
#Detector=	Synapse
#Objective=	x100
#Grating=	600 gr/mm
#ND Filter=	100%
#Laser (nm)=	532
#Hole=	100.021
#Range=	Auto
#Laser Pol.=	No
#Raman. Pol.=	No
#Laser Pol. (°)=	-0.0007625
#Raman Pol. (°)=	89.9995
#Collection=	Microscope
#StageXY=	Marzhauser
#StageZ=	Marzhauser
#X (µm)=	8979.4
#Y (µm)=	-3061.9
#Z (µm)=	-55.1
#Full time(mm:ss)=	3:19
#Project=
#Sample=
#Site=
#Title=	Thy_00_07_30_2x_45s_532 nm_x100_100%_600 gr_mm
#Remark=
#Date=	28.06.2022 12:18
#Acquired=	28.06.2022 12:18:15
#Base:Fit=	10.08.2022 10:07:56
#Base:Sub=	10.08.2022 10:08:40
#Filter:Polynom=	16.08.2022 10:26:06
#AxisType[0]=Intens
#AxisUnit[0]=Cnt
#AxisType[1]=Spectr
#AxisUnit[1]=1/cm
200.407	62.5282
204.035	49.8921
207.665	40.1461
211.291	32.7786
214.916	27.7274
218.541	23.4513
222.163	19.4939
225.785	17.7369
229.404	16.7416
233.022	12.8898
236.638	11.258
240.255	9.13674
243.868	8.20255
247.48	8.36992
251.091	9.50709
254.702	8.37505
258.31	10.8823
261.916	11.707
265.521	13.4286
269.125	15.6712
272.727	13.5405
276.328	14.5032
279.927	13.4312
283.525	12.8555
287.121	13.4039
290.716	14.055
294.31	12.8167
297.9	13.9067
301.491	14.2022
305.081	13.2982
308.669	14.747
312.256	14.8076
315.839	14.2071
319.423	13.0835
323.006	11.3139
326.585	13.0972
330.165	12.8721
333.741	12.721
337.318	12.7864
340.894	13.7956
344.466	12.6704
348.039	14.918
351.608	15.1615
355.176	13.255
358.745	13.3543
362.31	11.5391
365.876	11.4538
369.439	10.2293
373	8.47904
376.56	8.01138
380.12	6.50251
383.677	5.50263
387.233	5.78488
390.787	5.09479
394.34	5.78681
397.894	6.45666
401.444	6.61206
404.993	6.96786
408.54	7.89189
412.086	9.09167
415.631	9.93799
419.174	10.2282
422.716	12.7049
426.257	14.4123
429.794	15.1619
433.332	14.7874
436.868	14.5377
440.403	13.624
443.937	14.5633
447.468	14.3159
450.999	14.6082
454.528	16.4288
458.057	18.1042
461.582	19.6213
465.107	20.0808
468.629	19.7804
472.152	20.4053
475.672	21.2211
479.192	21.9753
482.709	23.5098
486.226	25.484
489.74	26.3026
493.255	27.7889
496.767	28.6823
500.277	31.1084
503.788	30.7849
507.295	30.3721
510.801	28.7401
514.308	26.3863
517.811	23.4384
521.313	21.7893
524.814	19.6721
528.313	17.9458
531.811	17.4868
535.308	17.2656
538.803	17.8304
542.297	16.9127
545.789	14.648
549.281	11.6846
552.771	10.2922
556.259	9.05885
559.747	7.55825
563.233	7.59425
566.717	8.22207
570.2	9.41887
573.68	9.65662
577.161	10.1791
580.64	11.8538
584.118	11.8374
587.593	11.4744
591.068	12.0529
594.54	10.8439
598.013	8.852
601.484	8.05563
604.952	8.04813
608.421	7.35298
611.886	7.46867
615.35	6.76358
618.815	4.88225
622.276	3.89843
625.738	3.03424
629.197	3.41806
632.655	2.65172
636.113	3.17031
639.568	3.84122
643.021	3.72257
646.473	4.6358
649.924	6.26784
653.376	7.69297
656.824	9.32085
660.271	11.2046
663.716	12.3444
667.161	13.9199
670.604	15.2842
674.045	16.5255
677.486	18.5283
680.925	18.6571
684.361	20.3099
687.797	22.6709
691.232	23.1719
694.666	24.4309
698.099	23.4411
701.528	22.4867
704.958	22.7493
708.387	23.8797
711.814	24.133
715.238	26.1153
718.663	26.1748
722.084	28.058
725.506	29.5569
728.925	31.7342
732.345	33.9861
735.761	36.544
739.178	38.7794
742.592	42.532
746.006	44.8596
749.417	49.2653
752.827	53.7922
756.236	57.4965
759.645	59.6732
763.051	62.8139
766.456	65.3512
769.859	68.2736
773.261	69.8265
776.664	70.4244
780.064	70.0406
783.462	67.5409
786.859	66.7084
790.255	64.2659
793.649	64.5213
797.042	64.8103
800.434	63.7412
803.823	64.0878
807.212	64.5902
810.6	62.9843
813.987	62.9577
817.372	62.589
820.754	63.1063
824.137	64.7391
827.519	66.7894
830.897	67.8854
834.276	69.9702
837.654	69.2898
841.029	68.5095
844.404	66.4091
847.776	65.6243
851.149	63.3068
854.519	62.1223
857.889	58.8315
861.256	55.0799
864.622	52.1106
867.988	49.1553
871.351	48.6117
874.713	47.3331
878.074	46.6763
881.435	44.5247
884.794	44.1391
888.15	42.333
891.506	42.0742
894.861	40.7005
898.214	41.819
901.566	42.8618
904.916	44.1785
908.266	47.7732
911.614	49.1365
914.961	50.5219
918.306	50.5699
921.651	51.0331
924.994	49.942
928.336	49.2863
931.674	48.007
935.014	47.5436
938.352	46.0667
941.687	43.6724
945.022	41.1444
948.357	39.1047
951.688	37.1345
955.02	35.0599
958.348	30.3623
961.678	25.4617
965.004	23.4897
968.331	23.2854
971.655	24.6473
974.979	27.0791
978.3	28.2879
981.62	32.3826
984.941	34.0531
988.259	34.2219
991.575	36.5053
994.89	38.2414
998.204	38.8369
1001.52	40.7881
1004.83	42.1659
1008.14	42.3989
1011.45	41.8226
1014.76	41.7041
1018.06	41.7866
1021.37	39.4558
1024.67	35.3478
1027.97	33.6117
1031.27	29.5363
1034.57	23.3162
1037.87	18.0936
1041.17	13.5302
1044.47	11.4196
1047.76	13.5299
1051.06	15.0615
1054.35	14.2829
1057.64	14.6881
1060.93	13.4157
1064.22	14.4377
1067.5	13.8675
1070.79	14.6626
1074.08	17.7013
1077.36	19.3045
1080.64	19.3482
1083.92	19.9853
1087.2	21.7911
1090.48	24.0022
1093.76	28.3142
1097.03	31.3032
1100.31	33.5725
1103.58	34.1286
1106.85	35.926
1110.12	34.9793
1113.39	32.386
1116.66	30.773
1119.93	30.8375
1123.19	29.8751
1126.46	29.2132
1129.72	28.1369
1132.98	26.9763
1136.24	25.2554
1139.5	23.9963
1142.76	22.1077
1146.01	20.4569
1149.27	19.835
1152.53	17.8738
1155.78	15.3355
1159.03	12.3755
1162.28	9.38138
1165.53	8.29032
1168.78	8.53406
1172.02	8.44932
1175.27	8.52149
1178.51	8.74428
1181.76	7.76496
1185	9.13558
1188.24	8.98329
1191.48	8.12315
1194.71	8.02123
1197.95	8.74621
1201.19	10.3151
1204.42	12.3347
1207.65	14.7115
1210.88	18.9009
1214.12	24.3695
1217.35	27.1724
1220.57	32.7322
1223.8	37.6912
1227.03	40.7611
1230.25	44.5514
1233.47	48.5863
1236.69	51.2562
1239.92	55.2698
1243.13	55.1672
1246.35	56.8569
1249.57	59.5053
1252.78	62.3326
1256	61.818
1259.21	60.3586
1262.42	60.3161
1265.63	59.9598
1268.84	59.2626
1272.05	59.559
1275.26	58.7456
1278.46	59.3192
1281.67	61.9702
1284.87	63.8939
1288.07	67.7224
1291.27	69.543
1294.47	71.8355
1297.67	73.9924
1300.87	76.2562
1304.06	79.122
1307.26	83.5649
1310.45	88.9611
1313.64	93.0806
1316.83	98.4781
1320.02	99.607
1323.21	103.105
1326.4	103.276
1329.59	104.418
1332.77	102.398
1335.95	99.9994
1339.14	99.763
1342.32	97.8311
1345.5	96.2085
1348.67	92.9525
1351.85	89.4051
1355.03	84.8092
1358.2	82.0047
1361.38	79.1429
1364.55	75.8184
1367.72	72.8589
1370.89	69.9961
1374.06	66.9287
1377.23	63.5427
1380.39	64.0994
1383.56	64.4223
1386.72	64.1843
1389.89	63.7982
1393.05	61.7333
1396.21	61.3134
1399.37	59.4825
1402.52	59.1313
1405.68	57.2806
1408.84	56.517
1411.99	59.1295
1415.15	62.2934
1418.3	66.6361
1421.45	71.4517
1424.6	76.0268
1427.75	81.6289
1430.89	88.1962
1434.04	94.9948
1437.18	101.854
1440.33	106.689
1443.47	109.923
1446.61	112.284
1449.75	113.467
1452.89	113.234
1456.03	112.414
1459.16	109.694
1462.3	103.315
1465.43	98.2388
1468.56	90.5868
1471.7	82.107
1474.83	72.9324
1477.96	64.8613
1481.08	56.2261
1484.21	47.4052
1487.34	42.1356
1490.46	36.3507
1493.58	31.1616
1496.71	29.0546
1499.83	27.0501
1502.95	24.5793
1506.07	24.7315
1509.18	24.6809
1512.3	23.1382
1515.41	22.6814
1518.53	22.1232
1521.64	22.0971
1524.75	23.5992
1527.86	25.3125
1530.97	27.559
1534.08	29.4969
1537.19	31.5309
1540.29	33.856
1543.4	37.6059
1546.5	40.6609
1549.6	43.9433
1552.7	48.528
1555.8	52.6441
1558.9	56.544
1562	60.8029
1565.09	62.7998
1568.19	67.3161
1571.28	70.6309
1574.37	74.0562
1577.47	77.6557
1580.56	79.8408
1583.64	82.524
1586.73	83.8366
1589.82	86.3041
1592.9	89.1978
1595.99	89.8332
1599.07	90.4665
1602.15	91.2254
1605.23	89.9655
1608.31	88.6741
1611.39	87.5008
1614.47	84.6453
1617.55	84.5084
1620.62	85.305
1623.7	85.5682
1626.77	86.9109
1629.84	88.3155
1632.91	89.481
1635.98	90.9456
1639.05	92.3242
1642.11	93.9003
1645.18	96.9701
1648.24	99.5892
1651.31	102.705
1654.37	105.464
1657.43	107.301
1660.49	109.036
1663.55	109.786
1666.61	108.668
1669.66	105.455
1672.72	101.113
1675.77	96.0534
1678.83	89.8801
1681.88	82.6172
1684.93	76.7395
1687.98	69.2849
1691.03	62.2068
1694.07	56.2984
1697.12	51.0829
1700.17	44.6421
1703.21	39.1618
1706.25	34.2042
1709.29	31.0584
1712.33	27.7135
1715.37	23.9463
1718.41	22.1206
1721.45	19.8874
1724.49	18.0421
1727.52	16.933
1730.55	15.2813
1733.59	14.9082
1736.62	14.729
1739.65	13.5208
1742.68	12.2954
1745.7	11.1802
1748.73	11.0015
1751.76	9.95704
1754.78	9.97055
1757.8	10.3723
1760.83	9.39981
1763.85	8.01461
1766.87	9.02179
1769.89	9.28955
1772.9	9.28157
1775.92	9.10425
1778.94	8.98279
1781.95	8.70118
1784.96	8.36254
1787.97	7.5005
1790.99	6.55992
1794	5.73142
1797	4.91386
1800.01	3.92675
1803.02	3.14013
1806.02	2.28079
1809.03	1.58263
1812.03	1.8403
1815.03	0.884506
1818.03	0.0360134
1821.03	-0.151959
1824.03	-0.264042
1827.03	-0.0833892
1830.02	-0.24333
1833.02	0.0218269
1836.01	-0.000973332
1839.01	1.26426
1842	1.75572
1844.99	2.40074
1847.98	3.00135
1850.97	4.00497
1853.95	4.18023
1856.94	5.25319
1859.93	5.48413
1862.91	6.03188
1865.89	5.8343
1868.87	6.04771
1871.85	6.33844
1874.83	6.24517
1877.81	6.2253
1880.79	6.60738
1882.52	6.29581
1885.51	6.44287
1888.5	5.92925
1891.49	6.11785
1894.47	4.8135
1897.46	4.69214
1900.44	4.57044
1903.42	2.43635
1906.4	2.14624
1909.38	2.14765
1912.36	1.43838
1915.34	0.800718
1918.32	1.65506
1921.29	1.11349
1924.27	1.01308
1927.24	0.907386
1930.21	1.26777
1933.18	1.0987
1936.15	1.08287
1939.12	1.46371
1942.09	1.65366
1945.06	2.49027
1948.02	2.44024
1950.99	3.2294
1953.95	4.04264
1956.91	3.82013
1959.88	4.97781
1962.84	5.17869
1965.8	4.85507
1968.75	4.77437
1971.71	6.54716
1974.67	6.2835
1977.62	6.78009
1980.58	7.45516
1983.53	7.20375
1986.48	7.09835
1989.43	6.95472
1992.38	6.34149
1995.33	5.63821
1998.27	5.84213
2001.22	5.93666
2004.16	6.05298
2007.11	5.94271
2010.05	6.11337
2012.99	5.95054
2015.93	6.14424
2018.87	5.67658
2021.81	5.3837
2024.75	5.0405
2027.69	4.65173
2030.62	3.82276
2033.56	3.46599
2036.49	2.31232
2039.42	1.81777
2042.35	2.90464
2045.28	3.68815
2048.21	3.52222
2051.14	2.70699
2054.07	2.18528
2056.99	2.30715
2059.92	2.52919
2062.84	2.70406
2065.76	2.87941
2068.68	4.19036
2071.6	5.31494
2074.52	5.94418
2077.44	5.97938
2080.36	6.31296
2083.27	6.76743
2086.19	7.55017
2089.1	7.21337
2092.02	7.07517
2094.93	7.2024
2097.84	6.97347
2100.75	7.343
2103.66	6.63274
2106.56	5.86941
2109.47	5.82039
2112.38	6.35166
2115.28	6.68739
2118.18	6.41202
2121.09	5.94696
2123.99	7.41637
2126.89	7.91637
2129.79	8.99094
2132.68	8.43717
2135.58	8.52031
2138.48	8.74642
2141.37	8.52019
2144.27	7.25859
2147.16	5.77587
2150.05	4.46552
2152.94	4.04909
2155.83	4.76355
2158.72	3.95211
2161.6	3.66196
2164.49	3.39157
2167.38	3.20322
2170.26	3.22295
2173.14	3.13558
2176.03	2.98271
2178.91	4.07566
2181.79	4.41768
2184.67	5.05633
2187.54	5.40168
2190.42	6.49699
2193.3	6.58708
2196.17	7.58269
2199.05	8.16054
2201.92	8.56119
2204.79	8.5224
2207.66	9.20917
2210.53	8.92659
2213.4	9.00393
2216.27	9.70463
2219.13	9.94158
2222	10.8213
2224.86	11.9999
2227.72	12.4466
2230.59	12.3999
2233.45	11.5985
2236.31	10.9763
2239.17	11.1709
2242.03	10.2523
2244.88	9.00989
2247.74	8.71036
2250.59	7.73371
2253.45	5.77777
2256.3	4.6744
2259.15	3.75638
2262	3.60329
2264.85	3.17962
2267.7	2.63202
2270.55	2.91394
2273.4	2.59229
2276.24	4.43205
2279.09	5.10716
2281.93	6.00963
2284.77	6.30676
2287.62	6.89317
2290.46	6.09489
2293.3	6.55831
2296.13	7.14215
2298.97	7.08747
2301.81	7.37016
2304.64	7.95839
2307.48	8.67505
2310.31	8.89371
2313.14	8.69348
2315.98	8.73961
2318.81	7.93881
2321.64	8.52193
2324.46	7.89176
2327.29	7.62395
2330.12	7.8713
2332.94	8.37993
2335.77	8.83898
2338.59	8.22893
2341.41	8.63021
2344.23	7.73142
2347.05	6.31365
2349.87	5.79203
2352.69	4.49949
2355.51	2.6666
2358.32	1.56623
2361.14	1.60634
2363.95	1.93368
2366.76	1.80989
2369.58	1.55272
2372.39	2.22823
2375.2	2.67272
2378	3.75386
2380.81	3.18985
2383.62	3.25941
2386.43	3.4005
2389.23	4.40484
2392.03	5.15869
2394.84	5.60669
2397.64	6.0906
2400.44	7.29104
2403.24	7.53183
2406.04	7.02557
2408.84	7.69712
2411.63	8.12498
2414.43	8.7923
2417.22	8.99287
2420.02	9.18686
2422.81	8.23218
2425.6	9.11432
2428.39	8.84955
2431.18	8.83618
2433.97	8.18161
2436.76	7.6484
2439.54	7.82261
2442.33	7.47295
2445.12	7.46117
2447.9	6.77098
2450.68	5.79917
2453.46	5.9423
2456.24	5.32615
2459.02	3.62814
2461.8	2.9111
2464.58	2.49364
2467.36	1.27912
2470.13	1.86206
2472.91	1.77427
2475.68	3.55776
2478.45	5.26678
2481.23	5.88022
2484	6.35826
2486.77	6.69506
2489.54	7.06725
2492.3	7.62423
2495.07	7.85726
2497.84	8.10424
2500.6	9.0823
2503.36	9.98103
2506.13	11.1977
2508.89	10.8666
2511.65	9.75722
2514.41	8.262
2517.17	7.61196
2519.93	6.60608
2522.68	6.54014
2525.44	4.83468
2528.19	4.07179
2530.95	3.79949
2533.7	3.07269
2536.45	3.73848
2539.2	4.69735
2541.95	5.47721
2544.7	6.67725
2547.45	7.50346
2550.2	8.31752
2552.94	7.68005
2555.69	7.48963
2558.43	8.06708
2561.18	8.45393
2563.92	8.57948
2566.66	10.0036
2569.4	9.95638
2572.14	9.93018
2574.88	8.43562
2577.61	7.73084
2580.35	7.01999
2583.09	6.69515
2585.82	7.67866
2588.55	7.85182
2591.29	8.18763
2594.02	8.06953
2596.75	7.46539
2599.48	8.25173
2602.21	8.18002
2604.93	8.80846
2607.66	9.24713
2610.39	8.64069
2613.11	9.17227
2615.83	9.73168
2618.56	9.52427
2621.28	8.54684
2624	8.09557
2626.72	7.44881
2629.44	6.86853
2632.15	6.76102
2634.87	6.94435
2637.59	5.7036
2640.3	5.60045
2643.02	5.01769
2645.73	4.68786
2648.44	4.33316
2651.15	4.38999
2653.86	4.5669
2656.57	5.75628
2659.28	5.8705
2661.99	5.4397
2664.69	5.85083
2667.4	5.73951
2670.1	5.88542
2672.81	5.57261
2675.51	6.12187
2678.21	6.14938
2680.91	6.71839
2683.61	7.06413
2686.31	6.76852
2689	6.24181
2691.7	6.65085
2694.4	6.92999
2697.09	7.48351
2699.79	7.71629
2702.48	8.29737
2705.17	8.94458
2707.86	9.24218
2710.55	10.1422
2713.24	11.2039
2715.93	12.4565
2718.62	12.7134
2721.3	13.8394
2723.99	14.0539
2726.67	13.9401
2729.35	14.3209
2732.04	14.2234
2734.72	13.3881
2737.4	12.5413
2740.08	11.7335
2742.76	10.3129
2745.43	10.1911
2748.11	8.28929
2750.79	7.10381
2753.46	5.63363
2756.14	4.75525
2758.81	3.6797
2761.48	3.53981
2764.15	2.42729
2766.82	1.46728
2769.49	1.87331
2772.16	1.30277
2774.82	1.57291
2777.49	1.52446
2780.16	0.41348
2782.82	-0.390556
2785.48	-0.824935
2788.15	0.287814
2790.81	1.35935
2793.47	1.62369
2796.13	1.2274
2798.79	1.69547
2801.44	1.74553
2804.1	1.77001
2806.76	0.718085
2809.41	1.0251
2812.07	-0.137748
2814.72	-0.253134
2817.37	1.17616
2820.02	3.21828
2822.67	7.06395
2825.32	11.4965
2827.97	16.2816
2830.62	20.8867
2833.26	27.0691
2835.91	33.7179
2838.56	39.969
2841.2	47.5721
2843.84	55.6933
2846.48	66.9081
2849.12	79.9328
2851.77	93.8388
2854.4	108.121
2857.04	121.673
2859.68	135.275
2862.32	148.867
2864.95	162.858
2867.59	174.823
2870.22	185.989
2872.85	196.466
2875.48	206.26
2878.11	214.813
2880.74	223.275
2883.37	231.791
2886	238.496
2888.63	245.663
2891.25	252.935
2893.88	259.766
2896.5	266.196
2899.13	272.79
2901.75	282.157
2904.37	291.989
2906.99	302.936
2909.61	316.293
2912.23	330.738
2914.85	343.967
2917.46	356.701
2920.08	367.621
2922.7	376.471
2925.31	382.752
2927.92	387.96
2930.54	388.762
2933.15	386.928
2935.76	382.617
2938.37	375.366
2940.98	366.19
2943.58	353.817
2946.19	342.784
2948.8	329.835
2951.4	315.947
2954.01	301.894
2956.61	287.45
2959.21	271.909
2961.81	258.188
2964.41	244.633
2967.01	231.995
2969.61	219.571
2972.21	208.621
2974.81	197.448
2977.4	186.172
2980	174.232
2982.59	161.66
2985.18	148.128
2987.78	133.696
2990.37	120.864
2992.96	107.83
2995.55	94.6407
2998.14	81.7278
3000.73	70.4216
3003.31	59.3823
3005.9	50.0131
3008.48	41.1966
3011.07	32.6239
3013.65	25.8609
3016.23	18.8864
3018.81	13.8628
3021.4	9.59862
3023.97	5.7886
3026.55	3.86518
3029.13	1.42081
3031.71	0.0812155
3034.28	-0.773221
3036.86	-0.0948375
3039.43	0.630823
3042.01	2.2261
3044.58	3.70525
3047.15	6.13137
3049.72	7.70248
3052.29	10.4969
3054.86	12.4397
3057.43	13.2438
3060	14.3316
3062.56	14.087
3065.13	14.7141
3067.69	13.2822
3070.26	12.2034
3072.82	11.485
3075.38	10.5515
3077.94	9.13363
3080.5	8.06939
3083.06	7.13919
3085.62	5.62976
3088.18	5.28846
3090.73	4.5253
3093.29	3.34971
3095.84	3.78124
3098.4	3.3948
3100.95	4.19612
3103.5	5.58894
3106.05	6.51951
3108.6	8.44339
3111.15	10.4232
3113.7	11.7965
3116.25	14.4474
3118.79	15.6338
3121.34	17.9254
3123.88	20.0653
3126.43	21.6001
3128.97	23.5288
3131.51	25.9983
3134.06	29.3717
3136.6	32.5743
3139.14	35.9717
3141.67	39.9381
3144.21	43.7512
3146.75	47.0901
3149.29	49.4551