File: data/Raman/poly_smoothed/Thy_30_10_46_1x_45s_532 nm_x100_100%_600 gr_mm_01.txt
#Acq. time (s)=	45
#Accumulations=	2
#Range (cm-¹)=	200...3150
#Windows=	2
#Auto scanning=	Off
#Autofocus=	Off
#Macrospot=	Off
#AutoExposure=	Off
#Spike filter=	Multiple accum.
#Delay time (s)=	0
#Binning=	1
#Readout mode=	Signal
#DeNoise=	Off
#ICS correction=	On
#Dark correction=	Off
#Inst. Process=	Off
#Detector Gain=	Best Dynamic Range
#Detector ADC=	20 kHz
#Detector temperature (°C)=	-69.85
#Instrument=	LabRAM HR Evol
#Detector=	Synapse
#Objective=	x100
#Grating=	600 gr/mm
#ND Filter=	100%
#Laser (nm)=	532
#Hole=	100.021
#Range=	Auto
#Laser Pol.=	No
#Raman. Pol.=	No
#Laser Pol. (°)=	-0.0007625
#Raman Pol. (°)=	89.9995
#Collection=	Microscope
#StageXY=	Marzhauser
#StageZ=	Marzhauser
#X (µm)=	4716.6
#Y (µm)=	-7698.4
#Z (µm)=	584.35
#Full time(mm:ss)=	3:19
#Project=
#Sample=
#Site=
#Title=	Thy_30_10_46_2x_45s_532 nm_x100_100%_600 gr_mm
#Remark=
#Date=	30.06.2022 14:42
#Acquired=	30.06.2022 14:42:48
#Base:Fit=	10.08.2022 09:58:11
#Base:Sub=	10.08.2022 09:58:44
#Filter:Polynom=	16.08.2022 10:22:53
#AxisType[0]=Intens
#AxisUnit[0]=Cnt
#AxisType[1]=Spectr
#AxisUnit[1]=1/cm
200.533	3.31701
204.162	6.35685
207.792	6.6745
211.418	7.2298
215.044	6.78091
218.667	7.02325
222.289	6.37577
225.912	6.07255
229.531	5.94873
233.148	5.61655
236.766	4.85348
240.381	5.54076
243.994	5.52867
247.606	4.83866
251.217	4.08935
254.828	2.38152
258.436	2.37602
262.042	2.66622
265.647	2.20527
269.25	1.1185
272.852	1.04789
276.453	0.924652
280.052	2.1624
283.65	3.16159
287.247	3.14782
290.842	4.0758
294.436	5.79866
298.028	6.88353
301.617	9.44025
305.206	8.7886
308.794	11.3166
312.381	12.2021
315.964	13.3028
319.548	15.1005
323.131	15.977
326.71	16.7733
330.29	16.5753
333.868	16.0183
337.443	15.9316
341.018	13.1633
344.591	13.3763
348.163	13.4235
351.733	12.0371
355.303	10.3165
358.869	9.44543
362.435	9.73511
366.001	10.154
369.563	8.32583
373.124	8.64745
376.686	8.08437
380.244	7.19026
383.801	7.59651
387.357	7.18822
390.911	6.28255
394.466	5.81374
398.018	5.84619
401.568	4.14363
405.117	4.60795
408.664	4.63115
412.21	4.79664
415.755	4.17641
419.298	5.56636
422.84	5.95383
426.38	5.49406
429.919	6.22581
433.455	7.3914
436.992	6.76267
440.527	6.06114
444.06	5.73004
447.593	7.2334
451.122	7.14943
454.651	6.86862
458.18	6.4379
461.705	6.67137
465.23	6.8413
468.752	8.29956
472.275	8.7678
475.797	9.24372
479.315	10.9349
482.834	11.503
486.349	12.5983
489.863	14.5135
493.378	15.8837
496.889	17.581
500.401	19.283
503.91	20.7491
507.417	20.8038
510.923	19.7699
514.43	18.4285
517.933	18.2039
521.435	18.5669
524.936	19.1456
528.435	19.0727
531.933	18.4304
535.43	17.6306
538.927	17.5718
542.421	15.2034
545.913	15.1346
549.403	13.9874
552.893	13.2506
556.381	12.1969
559.868	11.1301
563.354	10.4013
566.839	10.9235
570.322	8.95603
573.802	7.57861
577.283	8.03222
580.762	5.99536
584.24	6.21685
587.714	4.81876
591.19	2.37544
594.663	1.36235
598.134	0.841305
601.605	0.610412
605.073	2.6115
608.542	3.95658
612.007	3.48989
615.473	4.07334
618.936	5.52654
622.397	7.03432
625.859	7.74807
629.318	9.20921
632.775	10.4058
636.233	10.9402
639.688	13.3861
643.142	15.0606
646.594	16.2425
650.045	17.4049
653.496	18.3165
656.944	18.8729
660.391	20.0228
663.837	19.5146
667.281	20.0624
670.724	20.7228
674.166	20.4369
677.606	21.707
681.045	21.8903
684.483	22.7668
687.917	22.8895
691.352	24.6219
694.786	24.157
698.219	24.9031
701.65	27.0917
705.078	28.4119
708.506	30.5631
711.934	31.8034
715.358	32.6229
718.782	34.4858
722.204	36.0658
725.626	35.9582
729.045	38.8095
732.464	39.3363
735.881	40.9766
739.297	41.5128
742.711	42.1688
746.125	44.4454
749.537	46.4307
752.946	49.0968
756.357	52.5844
759.764	55.3536
763.17	57.8804
766.575	60.3178
769.978	63.0805
773.382	65.1637
776.783	67.0422
780.182	69.8442
783.581	71.4526
786.978	73.5492
790.373	75.7867
793.768	76.5668
797.161	77.091
800.552	77.8784
803.941	78.7213
807.33	78.2912
810.718	79.2242
814.105	79.3109
817.49	78.0488
820.873	77.4441
824.256	76.1338
827.637	75.9319
831.016	75.1324
834.395	73.5295
837.772	70.6474
841.147	69.8717
844.522	68.4858
847.894	67.1011
851.267	65.85
854.637	63.4565
858.007	62.2917
861.374	59.4066
864.739	57.2229
868.106	55.7395
871.469	54.7962
874.831	54.1878
878.193	52.6188
881.553	53.6061
884.911	52.7185
888.268	52.282
891.623	53.5395
894.978	52.9744
898.331	51.9293
901.683	53.889
905.033	53.2283
908.383	50.9898
911.731	49.0298
915.078	46.6282
918.423	45.8443
921.768	45.0345
925.111	44.5663
928.452	43.8318
931.791	42.6092
935.13	41.6471
938.468	38.7662
941.803	36.3666
945.139	34.6274
948.473	34.323
951.804	33.7925
955.136	32.7633
958.465	33.0722
961.794	32.1635
965.12	31.6953
968.447	31.4401
971.771	32.4575
975.095	32.8359
978.417	33.7079
981.737	33.9057
985.057	34.2623
988.375	32.3821
991.691	31.6713
995.006	30.7743
998.32	30.6467
1001.63	30.8997
1004.95	31.9652
1008.26	30.839
1011.56	30.8851
1014.87	30.8102
1018.18	30.0364
1021.48	29.2586
1024.79	27.8601
1028.09	27.358
1031.39	26.3634
1034.69	24.2211
1037.99	23.7384
1041.29	22.4279
1044.58	22.1375
1047.88	24.3792
1051.17	25.3676
1054.46	24.8404
1057.75	25.3147
1061.04	24.7178
1064.33	24.574
1067.62	24.5957
1070.9	24.2033
1074.19	24.1463
1077.47	24.2538
1080.76	25.4988
1084.04	26.2792
1087.32	26.6047
1090.59	26.8887
1093.87	27.8613
1097.15	27.1394
1100.42	26.6382
1103.69	25.1153
1106.97	25.0096
1110.24	23.098
1113.51	20.3353
1116.77	19.3481
1120.04	18.3374
1123.31	17.3777
1126.57	16.9502
1129.83	16.2104
1133.1	14.2385
1136.36	12.9416
1139.62	12.5075
1142.87	9.82924
1146.13	10.8709
1149.38	10.2672
1152.64	9.19543
1155.89	7.45325
1159.14	6.91957
1162.39	7.27267
1165.64	5.5355
1168.89	6.66295
1172.14	6.13356
1175.38	5.56296
1178.63	6.85235
1181.87	5.79026
1185.11	7.13603
1188.35	7.86643
1191.59	7.84727
1194.83	8.28177
1198.07	9.0123
1201.3	10.616
1204.53	13.3056
1207.77	15.4216
1211	18.6982
1214.23	21.0876
1217.46	22.2457
1220.69	24.7064
1223.91	27.3542
1227.14	31.2545
1230.36	33.4532
1233.59	35.3653
1236.81	39.0088
1240.03	42.1568
1243.25	43.3023
1246.46	46.0422
1249.68	48.2567
1252.9	49.4532
1256.11	50.3785
1259.32	50.3079
1262.54	51.3745
1265.75	51.8468
1268.96	51.2724
1272.16	51.01
1275.37	51.5968
1278.57	52.8628
1281.78	54.917
1284.98	54.7025
1288.18	55.5839
1291.38	56.1322
1294.58	55.3368
1297.78	55.3507
1300.98	56.0522
1304.17	56.0446
1307.37	56.5282
1310.56	56.675
1313.76	57.3955
1316.95	57.684
1320.14	55.7469
1323.32	55.4729
1326.51	55.0678
1329.7	54.271
1332.88	52.6184
1336.07	49.8954
1339.25	49.4902
1342.43	48.3363
1345.61	46.7444
1348.79	45.5152
1351.96	45.5122
1355.14	44.3944
1358.31	43.3341
1361.49	42.117
1364.66	40.1457
1367.83	39.5351
1371	37.0697
1374.17	36.2729
1377.34	34.9507
1380.5	34.1181
1383.67	32.7949
1386.83	33.6821
1390	32.8033
1393.16	31.4487
1396.32	29.5097
1399.48	28.3713
1402.64	28.3737
1405.79	27.0365
1408.95	26.2386
1412.1	26.6796
1415.26	28.1513
1418.41	31.6448
1421.56	33.6607
1424.71	35.3498
1427.86	39.1639
1431	40.8287
1434.15	45.8604
1437.29	50.2089
1440.44	53.7044
1443.58	56.1654
1446.72	56.9826
1449.86	57.9977
1453	58.2342
1456.14	57.5628
1459.27	56.5042
1462.41	53.656
1465.54	49.6321
1468.67	45.1868
1471.81	40.2963
1474.94	35.0409
1478.07	31.6858
1481.19	27.3064
1484.32	23.773
1487.45	21.0755
1490.57	20.2978
1493.69	18.0666
1496.82	17.4466
1499.94	17.2066
1503.06	17.1167
1506.17	17.4127
1509.29	18.9372
1512.41	20.1034
1515.52	19.5336
1518.64	20.3098
1521.75	20.6043
1524.86	21.949
1527.97	22.0311
1531.08	21.4772
1534.19	23.2352
1537.29	23.0732
1540.4	23.6949
1543.5	25.4086
1546.61	27.3522
1549.71	30.2821
1552.81	32.8403
1555.91	35.1043
1559.01	39.1253
1562.11	42.6331
1565.2	45.0366
1568.29	46.0336
1571.39	47.855
1574.48	50.0074
1577.57	51.4072
1580.66	54.4009
1583.75	56.4851
1586.84	55.9598
1589.93	56.305
1593.01	57.5059
1596.1	58.4817
1599.18	57.1914
1602.26	55.9558
1605.34	54.4242
1608.42	53.7486
1611.5	52.8779
1614.58	52.4347
1617.65	52.7027
1620.73	52.949
1623.8	53.5311
1626.87	54.1292
1629.95	54.1081
1633.02	54.7436
1636.09	54.4814
1639.15	54.2536
1642.22	53.4612
1645.29	54.2913
1648.35	53.2409
1651.42	55.2352
1654.48	56.2547
1657.54	55.151
1660.6	54.03
1663.66	53.2373
1666.72	52.7435
1669.77	50.5465
1672.83	47.5402
1675.88	45.0821
1678.93	42.7563
1681.99	39.1503
1685.04	36.3988
1688.09	31.7437
1691.13	28.4013
1694.18	25.2327
1697.23	22.1245
1700.27	19.3534
1703.32	17.557
1706.36	14.9325
1709.4	13.7197
1712.44	11.8169
1715.48	10.626
1718.52	9.21534
1721.56	7.76866
1724.59	7.79748
1727.63	9.20214
1730.66	8.48583
1733.69	7.86161
1736.72	7.51261
1739.75	7.19601
1742.78	6.02506
1745.81	5.25966
1748.84	4.44486
1751.86	3.47154
1754.89	2.92052
1757.91	1.74707
1760.93	1.14119
1763.95	-0.0708426
1766.97	-0.409425
1769.99	-0.0595231
1773.01	0.680811
1776.03	-0.215859
1779.04	0.120197
1782.06	-0.101838
1785.07	0.397075
1788.08	0.634486
1791.09	0.308674
1794.1	0.69525
1797.11	1.79675
1800.12	2.96609
1803.12	2.7785
1806.13	2.45127
1809.13	2.75306
1812.14	2.0676
1815.14	2.13683
1818.14	2.62016
1821.14	2.27951
1824.14	2.74977
1827.13	2.77494
1830.13	2.83563
1833.12	2.47271
1836.12	2.80381
1839.11	2.59474
1842.1	2.25634
1845.09	2.1296
1848.08	1.97521
1851.07	2.35376
1854.06	3.66469
1857.04	4.06182
1860.03	4.52374
1863.01	4.96776
1866	6.29459
1868.98	7.42255
1871.96	8.06695
1874.94	8.65269
1877.92	9.29221
1880.89	9.09591
1882.48	9.24155
1885.47	9.44727
1888.46	9.62179
1891.44	9.70842
1894.43	9.34708
1897.41	8.95535
1900.4	8.55204
1903.38	9.01155
1906.36	8.05703
1909.34	7.29611
1912.32	7.51772
1915.29	6.90564
1918.27	7.35711
1921.25	8.71359
1924.22	9.83615
1927.2	9.81243
1930.17	9.84172
1933.14	9.5729
1936.11	9.87054
1939.08	10.3811
1942.05	10.3621
1945.01	10.4761
1947.98	11.0384
1950.94	10.6246
1953.91	10.1492
1956.87	9.85715
1959.83	9.61303
1962.79	8.82317
1965.75	8.25215
1968.71	8.7757
1971.67	8.28869
1974.62	8.4529
1977.58	7.70165
1980.53	6.89911
1983.48	7.47044
1986.43	7.97618
1989.38	8.28037
1992.33	9.70122
1995.28	9.65134
1998.23	9.26299
2001.18	9.06137
2004.12	9.30232
2007.06	9.74832
2010.01	9.81395
2012.95	9.96045
2015.89	9.97824
2018.83	10.2854
2021.77	10.5819
2024.71	10.4127
2027.64	10.3452
2030.58	11.7451
2033.51	11.8285
2036.45	11.6895
2039.38	12.2943
2042.31	12.2109
2045.24	12.5545
2048.17	13.1007
2051.1	13.4477
2054.02	14.2739
2056.95	15.2092
2059.87	15.4972
2062.8	15.4331
2065.72	15.7257
2068.64	16.241
2071.56	16.8263
2074.48	17.2848
2077.4	18.6013
2080.31	19.0928
2083.23	19.5984
2086.14	19.8124
2089.06	20.9107
2091.97	20.826
2094.88	21.2709
2097.79	22.7378
2100.7	24.0239
2103.61	24.693
2106.52	25.0451
2109.43	26.211
2112.33	27.597
2115.24	29.7378
2118.14	31.9143
2121.04	34.1894
2123.94	36.2894
2126.84	36.5445
2129.74	37.9663
2132.64	39.5183
2135.54	41.952
2138.43	45.0229
2141.33	47.0801
2144.22	49.5466
2147.11	52.1522
2150.01	54.3725
2152.9	54.9764
2155.79	55.7317
2158.67	56.2025
2161.56	57.3799
2164.45	57.7958
2167.33	59.1645
2170.22	60.3893
2173.1	59.8257
2175.98	60.0839
2178.86	60.6259
2181.74	60.6503
2184.62	59.6857
2187.5	59.4482
2190.38	58.5962
2193.25	56.8163
2196.13	54.0187
2199	52.7462
2201.88	51.8671
2204.75	50.2655
2207.62	48.7227
2210.49	45.797
2213.36	44.9184
2216.22	42.6531
2219.09	40.4852
2221.96	38.4352
2224.82	36.5893
2227.68	34.9461
2230.55	33.0168
2233.41	31.2422
2236.27	29.3195
2239.12	28.443
2241.98	27.6702
2244.84	25.9804
2247.7	25.7289
2250.55	24.9247
2253.41	23.4829
2256.26	22.6708
2259.11	23.1388
2261.96	22.0182
2264.81	21.7874
2267.66	21.0675
2270.51	21.064
2273.35	21.003
2276.2	20.0925
2279.04	20.2408
2281.89	20.6921
2284.73	20.0861
2287.57	18.9573
2290.41	18.4085
2293.25	17.5513
2296.09	16.7152
2298.93	16.7933
2301.76	17.2603
2304.6	17.3707
2307.44	17.7976
2310.27	17.2991
2313.1	16.4792
2315.93	16.341
2318.76	15.5833
2321.59	15.3265
2324.42	16.2341
2327.25	16.4232
2330.07	16.4822
2332.9	16.1466
2335.72	15.9617
2338.55	15.4525
2341.37	14.455
2344.19	13.8422
2347.01	13.6116
2349.83	12.6625
2352.65	10.4842
2355.46	9.13332
2358.28	7.37463
2361.09	6.13035
2363.91	6.5453
2366.72	6.09671
2369.53	5.49112
2372.34	3.91308
2375.15	2.87022
2377.96	2.2148
2380.77	1.60717
2383.58	1.70845
2386.38	1.07282
2389.19	1.12027
2391.99	2.79043
2394.8	4.30448
2397.6	5.08752
2400.4	6.26432
2403.2	7.67259
2406	8.95126
2408.79	9.79227
2411.59	10.6407
2414.39	12.0813
2417.18	12.3117
2419.98	13.3618
2422.77	14.0288
2425.56	14.3302
2428.35	14.9594
2431.14	15.0785
2433.93	14.4544
2436.72	13.196
2439.5	12.9361
2442.29	12.5751
2445.07	11.2867
2447.86	10.9124
2450.64	9.53432
2453.42	7.80393
2456.2	7.3311
2458.98	7.74589
2461.76	8.16163
2464.54	7.40252
2467.32	5.92295
2470.09	5.59666
2472.87	4.6045
2475.64	4.51756
2478.41	3.1522
2481.18	2.79445
2483.95	2.44776
2486.72	1.7709
2489.49	1.23809
2492.26	1.26484
2495.03	1.17235
2497.79	1.17501
2500.56	-0.17197
2503.32	-0.300433
2506.09	0.00683772
2508.85	1.07281
2511.61	0.910685
2514.37	0.63566
2517.13	0.68735
2519.89	0.298575
2522.64	0.980659
2525.4	2.06557
2528.15	1.85793
2530.91	2.24412
2533.66	2.4155
2536.41	2.67023
2539.16	3.05668
2541.91	3.33362
2544.66	3.73174
2547.41	3.99638
2550.16	4.58005
2552.9	5.31686
2555.65	5.85699
2558.39	6.88483
2561.13	7.562
2563.88	7.93113
2566.62	8.13196
2569.36	8.40664
2572.1	9.11623
2574.84	9.00611
2577.57	9.07748
2580.31	8.75125
2583.05	8.17332
2585.78	6.93632
2588.51	6.8947
2591.24	6.09002
2593.98	5.23556
2596.71	5.14427
2599.44	4.29921
2602.16	3.83746
2604.89	3.19154
2607.62	2.80174
2610.34	2.99447
2613.07	2.94186
2615.79	3.43794
2618.52	3.67453
2621.24	3.27059
2623.96	2.85767
2626.68	3.76979
2629.4	3.62467
2632.11	2.9709
2634.83	3.2437
2637.55	3.28081
2640.26	3.72551
2642.98	3.77451
2645.69	3.93839
2648.4	3.06312
2651.11	1.56924
2653.82	1.23165
2656.53	0.838578
2659.24	0.558735
2661.95	0.53944
2664.65	0.146221
2667.36	0.375731
2670.06	0.320232
2672.76	-0.217585
2675.47	-0.313223
2678.17	0.615245
2680.87	0.752099
2683.57	1.01469
2686.27	1.00385
2688.97	1.12933
2691.66	1.35417
2694.36	1.82615
2697.05	2.19159
2699.75	2.94657
2702.44	4.10499
2705.13	5.16304
2707.82	5.61442
2710.51	4.94337
2713.2	5.21717
2715.89	4.7966
2718.57	5.77433
2721.26	5.689
2723.95	6.34041
2726.63	5.68691
2729.31	5.51193
2732	5.26605
2734.68	6.31264
2737.36	5.97121
2740.04	5.84963
2742.72	6.03222
2745.39	5.70639
2748.07	5.26648
2750.75	4.95921
2753.42	4.83584
2756.09	4.49594
2758.77	3.70545
2761.44	3.25968
2764.11	3.47421
2766.78	3.05308
2769.45	2.92627
2772.12	2.094
2774.78	0.639782
2777.45	1.10343
2780.12	0.793887
2782.78	0.928183
2785.44	0.553687
2788.11	-0.0654476
2790.77	0.115872
2793.43	0.275916
2796.09	0.5888
2798.75	0.711209
2801.4	0.804707
2804.06	0.874976
2806.72	1.41341
2809.37	0.847099
2812.03	1.70873
2814.68	1.85815
2817.33	2.43714
2819.98	3.26231
2822.63	3.35456
2825.28	5.50912
2827.93	7.13771
2830.58	8.78367
2833.23	10.7902
2835.87	12.7749
2838.52	15.2708
2841.16	19.2367
2843.8	23.0855
2846.44	27.3624
2849.08	32.7243
2851.73	37.4367
2854.36	42.5062
2857	47.5862
2859.64	53.0822
2862.28	58.3381
2864.91	62.9415
2867.55	67.4872
2870.18	71.3007
2872.81	74.7131
2875.44	78.4025
2878.07	81.4786
2880.7	83.7283
2883.33	87.5547
2885.96	90.5459
2888.59	92.7642
2891.21	95.1605
2893.84	97.8776
2896.46	101.117
2899.09	104.83
2901.71	110.599
2904.33	115.362
2906.95	121.798
2909.57	129.009
2912.19	136.236
2914.81	143.407
2917.43	150.361
2920.04	156.764
2922.66	162.748
2925.27	167.123
2927.88	170.602
2930.5	173.099
2933.11	173.929
2935.72	174.097
2938.33	173.274
2940.94	171.771
2943.54	168.596
2946.15	165.12
2948.76	160.893
2951.36	155.498
2953.97	149.966
2956.57	144.615
2959.17	138.383
2961.77	132.051
2964.37	126.485
2966.97	121.168
2969.57	114.767
2972.17	110.004
2974.77	103.817
2977.36	98.1563
2979.96	91.8427
2982.55	85.7956
2985.15	79.4147
2987.74	73.4243
2990.33	67.4859
2992.92	61.1038
2995.51	54.6812
2998.1	49.4444
3000.69	44.6271
3003.27	39.465
3005.86	35.3416
3008.44	31.4084
3011.03	28.7027
3013.61	25.75
3016.19	22.4682
3018.78	20.4259
3021.36	18.2237
3023.94	16.8354
3026.51	16.1955
3029.09	15.766
3031.67	15.4334
3034.24	15.8227
3036.82	16.7487
3039.39	16.7971
3041.97	17.5128
3044.54	18.1566
3047.11	19.2494
3049.68	19.0449
3052.25	19.436
3054.82	20.2713
3057.39	19.7714
3059.96	19.9037
3062.52	20.101
3065.09	18.9176
3067.65	17.1788
3070.22	16.7259
3072.78	15.164
3075.34	13.7895
3077.9	11.9172
3080.46	9.49356
3083.02	7.71821
3085.58	6.20551
3088.14	4.69103
3090.69	3.57595
3093.25	3.02729
3095.8	2.61423
3098.36	2.51969
3100.91	1.90759
3103.46	1.36464
3106.01	1.06915
3108.56	1.94532
3111.11	1.93837
3113.66	1.78198
3116.21	2.57649
3118.76	2.20808
3121.3	2.23779
3123.85	2.58197
3126.39	2.69527
3128.93	2.54006
3131.48	2.36935
3134.02	1.99207
3136.56	1.21949
3139.1	0.399258
3141.64	-0.114224
3144.17	-0.517237
3146.71	-0.771676
3149.25	0.254695