File: data/Raman/poly_smoothed/Thy_50_12_15_1x_45s_532 nm_x100_100%_600 gr_mm_01.txt
#Acq. time (s)=	45
#Accumulations=	2
#Range (cm-¹)=	200...3150
#Windows=	2
#Auto scanning=	Off
#Autofocus=	Off
#Macrospot=	Off
#AutoExposure=	Off
#Spike filter=	Multiple accum.
#Delay time (s)=	0
#Binning=	1
#Readout mode=	Signal
#DeNoise=	Off
#ICS correction=	On
#Dark correction=	Off
#Inst. Process=	Off
#Detector Gain=	Best Dynamic Range
#Detector ADC=	20 kHz
#Detector temperature (°C)=	-69.85
#Instrument=	LabRAM HR Evol
#Detector=	Synapse
#Objective=	x100
#Grating=	600 gr/mm
#ND Filter=	100%
#Laser (nm)=	532
#Hole=	100.021
#Range=	Auto
#Laser Pol.=	No
#Raman. Pol.=	No
#Laser Pol. (°)=	-0.0007625
#Raman Pol. (°)=	89.9995
#Collection=	Microscope
#StageXY=	Marzhauser
#StageZ=	Marzhauser
#X (µm)=	-5126
#Y (µm)=	1482.5
#Z (µm)=	62.85
#Full time(mm:ss)=	3:19
#Project=
#Sample=
#Site=
#Title=	Thy_50_12_15_2x_45s_532 nm_x100_100%_600 gr_mm
#Remark=
#Date=	07.07.2022 10:20
#Acquired=	07.07.2022 10:20:50
#Base:Fit=	10.08.2022 10:04:29
#Base:Sub=	10.08.2022 10:04:45
#Filter:Polynom=	16.08.2022 10:20:24
#AxisType[0]=Intens
#AxisUnit[0]=Cnt
#AxisType[1]=Spectr
#AxisUnit[1]=1/cm
200.43	-4.35993
204.061	0.608089
207.688	2.18344
211.316	2.94414
214.941	3.36748
218.566	4.36811
222.188	4.13598
225.809	5.25262
229.43	4.85767
233.047	5.62473
236.663	5.58579
240.278	5.51855
243.894	6.26977
247.506	5.78271
251.116	5.20794
254.725	4.43503
258.333	3.56728
261.939	3.162
265.546	3.64743
269.15	3.03907
272.752	3.12097
276.353	2.96934
279.952	2.74601
283.55	2.90762
287.146	3.86763
290.739	3.37393
294.333	2.53673
297.925	3.85298
301.516	4.4862
305.106	4.96533
308.694	6.82847
312.279	7.63285
315.864	7.96593
319.448	7.47195
323.029	8.52132
326.61	8.64792
330.19	9.38068
333.766	9.35244
337.343	9.88002
340.917	8.47203
344.491	9.12479
348.062	9.53234
351.633	9.30277
355.201	10.1697
358.77	10.0203
362.335	9.91266
365.899	9.4242
369.464	10.8145
373.025	11.789
376.585	11.9621
380.143	11.7557
383.702	11.9155
387.258	11.4252
390.812	13.5366
394.365	13.7037
397.916	12.7391
401.467	12.8995
405.015	12.1838
408.565	10.5555
412.111	9.97786
415.656	7.78425
419.197	8.23408
422.739	6.81088
426.279	5.80858
429.819	5.46338
433.356	4.57881
436.893	4.35017
440.428	5.77964
443.96	6.02408
447.492	5.47718
451.023	4.03253
454.553	4.74725
458.079	4.80962
461.606	5.05616
465.132	5.63352
468.654	6.209
472.177	9.03865
475.696	11.0264
479.217	11.8828
482.733	12.1011
486.251	12.6651
489.765	11.4618
493.278	11.3192
496.791	10.2894
500.301	10.8441
503.81	11.0289
507.319	11.8452
510.825	12.7823
514.33	12.2932
517.833	13.2371
521.337	15.2801
524.838	15.8531
528.337	15.9798
531.835	15.0907
535.332	14.5702
538.827	15.9072
542.321	16.1875
545.814	15.3815
549.305	15.9288
552.795	15.7986
556.284	15.7029
559.771	14.7394
563.257	13.4917
566.742	12.9247
570.223	11.8728
573.705	10.3539
577.185	9.3666
580.665	9.25378
584.141	8.33938
587.617	7.84169
591.092	8.2079
594.564	7.89356
598.037	8.048
601.506	9.81591
604.976	10.9565
608.443	12.6538
611.91	12.9074
615.374	13.0309
618.839	13.7653
622.3	15.2638
625.761	15.3763
629.221	15.3528
632.679	16.2031
636.135	16.1716
639.592	15.9257
643.045	17.979
646.497	18.2179
649.948	18.3478
653.398	19.2901
656.846	18.9072
660.293	17.4432
663.738	17.207
667.185	18.1059
670.628	19.9568
674.067	21.9267
677.508	23.0969
680.947	25.2311
684.385	27.3182
687.821	28.5026
691.256	28.6948
694.69	30.8972
698.121	33.5703
701.552	34.9252
704.982	37.0581
708.41	39.0115
711.836	40.6463
715.262	42.7103
718.685	44.0221
722.108	45.6605
725.53	48.1898
728.949	48.4074
732.369	49.0116
735.785	48.6204
739.2	50.0572
742.616	50.5009
746.028	52.2376
749.441	55.8806
752.851	58.0108
756.26	58.6417
759.667	61.6111
763.075	62.691
766.479	64.7305
769.883	66.2992
773.285	67.2049
776.686	68.641
780.085	71.5036
783.484	73.8014
786.881	73.4473
790.276	75.115
793.671	77.1182
797.064	79.0242
800.456	79.9179
803.846	82.0613
807.236	81.9756
810.624	82.4127
814.01	81.2982
817.394	79.3914
820.778	77.7163
824.161	78.0943
827.543	76.5654
830.921	74.6522
834.3	72.6773
837.676	70.9767
841.053	69.396
844.426	67.6586
847.8	66.1303
851.171	63.1021
854.542	60.7006
857.911	60.0209
861.279	58.4872
864.645	58.2138
868.01	57.0915
871.375	55.4446
874.737	54.9421
878.097	54.3522
881.457	54.2366
884.817	54.0757
888.174	52.6978
891.53	52.4858
894.884	51.7335
898.237	49.108
901.589	48.3567
904.94	48.3434
908.289	49.9152
911.637	49.3312
914.984	48.5342
918.33	48.1332
921.674	45.4776
925.015	44.2332
928.357	42.7031
931.698	40.1278
935.037	39.0362
938.373	38.4479
941.71	36.5368
945.046	34.9447
948.378	33.5622
951.711	34.8336
955.043	34.8904
958.372	32.9617
961.701	32.7477
965.027	33.2527
968.354	32.6924
971.678	31.1308
975	31.2473
978.324	31.0788
981.644	30.1909
984.962	32.2754
988.282	33.0493
991.598	32.8625
994.913	31.8444
998.227	30.4143
1001.54	29.6291
1004.85	28.6054
1008.16	28.9376
1011.47	29.1229
1014.78	28.0198
1018.08	26.5816
1021.39	25.8135
1024.69	26.8419
1028	28.3748
1031.3	30.2886
1034.6	30.9363
1037.9	30.2617
1041.19	29.7078
1044.49	29.2702
1047.79	26.428
1051.08	25.9647
1054.37	25.1626
1057.66	23.4638
1060.95	21.7657
1064.24	21.3629
1067.53	18.8667
1070.81	18.9213
1074.1	18.0613
1077.38	16.3149
1080.66	18.1586
1083.94	18.3334
1087.22	18.1566
1090.5	18.217
1093.78	16.5097
1097.05	14.825
1100.33	14.6159
1103.6	15.2844
1106.87	15.3334
1110.15	14.5752
1113.41	14.706
1116.68	13.3783
1119.95	11.1479
1123.21	7.99865
1126.48	5.43749
1129.74	5.59817
1133	4.78354
1136.26	3.53785
1139.52	2.52061
1142.78	1.20322
1146.04	1.17164
1149.29	1.16019
1152.55	1.98418
1155.8	3.2311
1159.05	4.3198
1162.3	6.88269
1165.55	7.023
1168.8	7.11933
1172.05	7.08077
1175.29	6.85505
1178.54	6.0175
1181.78	6.1228
1185.02	6.832
1188.26	5.43216
1191.5	5.25961
1194.74	4.2058
1197.97	2.99535
1201.21	3.30842
1204.44	3.84866
1207.68	4.76887
1210.91	6.94028
1214.14	7.67963
1217.37	8.01547
1220.6	10.1727
1223.82	11.9697
1227.05	14.3185
1230.27	15.2574
1233.49	18.191
1236.72	19.7396
1239.94	21.8228
1243.16	23.579
1246.37	24.4952
1249.59	26.2027
1252.8	27.7085
1256.02	29.3284
1259.23	32.1788
1262.44	34.4751
1265.66	35.7551
1268.87	37.0706
1272.07	37.0998
1275.28	40.069
1278.48	43.2268
1281.69	45.0207
1284.89	47.1193
1288.09	48.9137
1291.3	49.5727
1294.49	50.5298
1297.69	51.3374
1300.89	49.9194
1304.09	50.0577
1307.28	49.0793
1310.47	47.5177
1313.66	46.2723
1316.86	46.1213
1320.05	44.9153
1323.23	45.1282
1326.42	43.9654
1329.61	44.7592
1332.79	45.7621
1335.98	45.0055
1339.16	43.7955
1342.34	41.6481
1345.52	41.1004
1348.7	39.6872
1351.87	38.9835
1355.05	38.3061
1358.23	38.179
1361.4	36.0811
1364.57	35.54
1367.74	34.3731
1370.91	33.1772
1374.08	32.1291
1377.25	30.2458
1380.42	30.1052
1383.58	29.8482
1386.75	27.0213
1389.91	24.7624
1393.07	22.9515
1396.23	21.7853
1399.39	21.6523
1402.55	21.5882
1405.7	22.6651
1408.86	23.4029
1412.01	23.1276
1415.17	23.7661
1418.32	24.5763
1421.47	27.8696
1424.62	29.7939
1427.77	32.7783
1430.92	36.1931
1434.06	39.148
1437.2	42.4881
1440.35	46.2214
1443.49	49.5215
1446.63	51.027
1449.77	52.9791
1452.91	54.8589
1456.05	54.32
1459.18	52.7622
1462.32	49.5391
1465.45	46.394
1468.59	43.3854
1471.72	39.5489
1474.85	35.8871
1477.98	33.7268
1481.11	30.9729
1484.23	26.3502
1487.36	23.0858
1490.48	20.6498
1493.61	16.9671
1496.73	15.7331
1499.85	13.8477
1502.97	13.7535
1506.09	14.0777
1509.2	13.7257
1512.32	13.7853
1515.44	14.2826
1518.55	13.8951
1521.66	16.5701
1524.77	17.9025
1527.88	20.2717
1530.99	22.5563
1534.1	24.2306
1537.21	25.8473
1540.31	28.8539
1543.42	33.65
1546.52	37.4283
1549.62	41.914
1552.72	47.5073
1555.82	50.7562
1558.92	54.0504
1562.02	56.3507
1565.11	59.5745
1568.21	60.1209
1571.3	61.9208
1574.39	64.0568
1577.49	65.8367
1580.58	66.3984
1583.67	65.0347
1586.75	63.9521
1589.84	62.2396
1592.93	61.2231
1596.01	60.2124
1599.09	57.4253
1602.18	54.6873
1605.26	52.8184
1608.34	51.6403
1611.41	50.0451
1614.49	49.0925
1617.57	49.3571
1620.64	49.7176
1623.72	50.8866
1626.79	53.0589
1629.86	53.5406
1632.93	53.4651
1636	54.9073
1639.07	54.8181
1642.14	55.8042
1645.2	56.8928
1648.27	58.5714
1651.33	57.6529
1654.39	58.4391
1657.45	57.2888
1660.51	56.0495
1663.57	55.043
1666.63	52.6925
1669.69	49.7754
1672.74	45.4654
1675.79	40.3502
1678.85	36.97
1681.9	33.4716
1684.95	30.5652
1688	25.5715
1691.05	22.538
1694.1	20.0396
1697.14	16.8651
1700.19	15.8236
1703.23	12.7852
1706.27	10.4363
1709.32	9.59712
1712.35	7.71571
1715.39	6.81716
1718.43	7.39036
1721.47	6.3448
1724.5	6.12023
1727.54	6.16912
1730.57	6.99321
1733.61	5.64259
1736.64	4.67721
1739.67	5.02891
1742.7	3.79504
1745.72	3.41551
1748.75	2.57079
1751.78	2.68046
1754.8	2.94273
1757.82	2.85062
1760.85	3.92315
1763.87	3.5767
1766.89	3.17247
1769.91	2.86981
1772.92	2.68415
1775.94	1.27273
1778.96	1.90666
1781.97	2.77211
1784.98	3.36693
1788	4.11383
1791.01	4.16019
1794.01	5.54077
1797.02	6.39265
1800.03	6.36888
1803.04	7.2268
1806.04	6.85783
1809.05	7.41655
1812.05	8.56801
1815.05	8.69329
1818.05	8.3724
1821.05	8.27131
1824.05	7.77592
1827.05	7.45187
1830.04	7.75992
1833.04	7.82287
1836.03	6.85727
1839.03	5.90192
1842.02	5.12819
1845.01	3.46369
1848	2.57981
1850.99	3.06983
1853.97	4.73037
1856.96	5.60827
1859.94	6.20799
1862.93	6.21058
1865.91	5.77879
1868.89	6.33286
1871.87	4.90068
1874.85	3.82894
1877.83	3.21197
1880.81	2.96626
1882.56	2.95754
1885.55	2.59757
1888.54	1.9469
1891.52	1.67245
1894.51	2.03921
1897.49	3.09248
1900.48	3.56462
1903.46	3.78816
1906.44	4.89761
1909.42	5.97254
1912.4	6.83659
1915.38	7.47508
1918.35	7.82418
1921.33	8.96061
1924.3	9.68801
1927.28	10.1172
1930.25	9.50288
1933.22	8.94015
1936.19	8.67781
1939.16	7.41695
1942.13	6.41117
1945.09	4.93627
1948.06	4.82
1951.03	4.49117
1953.99	4.54744
1956.95	4.87438
1959.91	4.15913
1962.87	4.84893
1965.83	5.8623
1968.79	6.18374
1971.75	7.24111
1974.7	6.34206
1977.66	7.28182
1980.61	8.34198
1983.56	8.83893
1986.52	8.40189
1989.47	8.63338
1992.41	8.2302
1995.36	7.55924
1998.31	7.49313
2001.26	7.16411
2004.2	7.88996
2007.15	8.04994
2010.09	7.45288
2013.03	6.11667
2015.97	6.38404
2018.91	7.10424
2021.85	6.10034
2024.79	6.63751
2027.72	7.81278
2030.66	7.66229
2033.59	8.32673
2036.53	9.31522
2039.46	8.65461
2042.39	9.13004
2045.32	9.77816
2048.25	10.5293
2051.18	11.5289
2054.1	13.3506
2057.03	15.0741
2059.95	16.406
2062.88	16.6583
2065.8	17.3049
2068.72	18.0015
2071.64	19.4985
2074.56	20.1769
2077.48	20.9537
2080.39	21.8141
2083.31	21.6977
2086.22	22.3065
2089.14	23.2733
2092.05	22.9497
2094.96	23.34
2097.87	24.2657
2100.78	25.4509
2103.69	26.0304
2106.6	28.0228
2109.51	29.4615
2112.41	32.1253
2115.32	34.6698
2118.22	37.5092
2121.12	39.3505
2124.02	42.1176
2126.92	46.6621
2129.82	49.7323
2132.72	52.2174
2135.62	55.1023
2138.51	57.3736
2141.41	60.4449
2144.3	64.1
2147.19	66.3165
2150.09	69.3025
2152.97	70.4551
2155.86	72.1367
2158.75	74.0084
2161.64	75.4398
2164.53	76.2998
2167.41	75.8895
2170.3	75.9943
2173.18	75.0562
2176.06	73.941
2178.94	72.9705
2181.82	70.8816
2184.7	69.1313
2187.58	66.5682
2190.46	64.7073
2193.33	62.4596
2196.21	61.3302
2199.08	60.1485
2201.95	57.483
2204.83	55.6901
2207.7	52.8932
2210.57	51.4196
2213.43	50.0693
2216.3	48.0816
2219.17	46.5295
2222.03	44.7239
2224.9	44.1732
2227.76	42.2924
2230.62	40.3846
2233.49	38.2683
2236.34	35.9125
2239.2	32.9056
2242.06	31.831
2244.92	29.326
2247.78	27.166
2250.63	25.2346
2253.48	24.4966
2256.34	23.2795
2259.19	22.3812
2262.04	21.1732
2264.89	20.2546
2267.74	20.4081
2270.59	19.1304
2273.43	18.004
2276.28	16.9358
2279.12	16.8821
2281.97	16.8883
2284.81	15.5671
2287.65	15.0747
2290.49	14.3288
2293.33	13.1341
2296.17	12.9878
2299.01	11.8194
2301.84	11.3579
2304.68	12.4224
2307.51	11.9094
2310.35	11.4121
2313.18	10.891
2316.01	10.7386
2318.84	9.34409
2321.67	9.91439
2324.5	9.44815
2327.33	9.39554
2330.15	8.76931
2332.98	8.64755
2335.8	9.56794
2338.62	9.12196
2341.45	9.15882
2344.27	9.31114
2347.09	8.20126
2349.91	6.82596
2352.72	6.60496
2355.54	5.57594
2358.36	5.05673
2361.17	4.25664
2363.98	4.51335
2366.8	5.57971
2369.61	5.17826
2372.42	5.01377
2375.23	4.28502
2378.04	3.36136
2380.85	2.50872
2383.66	2.91924
2386.46	2.30095
2389.26	3.13523
2392.07	3.92636
2394.87	3.80563
2397.67	4.17712
2400.47	4.82877
2403.27	5.43415
2406.07	6.04637
2408.87	6.62285
2411.67	7.54518
2414.46	6.95245
2417.26	7.02758
2420.05	7.1258
2422.84	8.0064
2425.64	8.06912
2428.43	7.287
2431.22	7.23607
2434.01	7.35588
2436.79	6.97723
2439.58	5.68458
2442.37	4.3945
2445.15	3.7246
2447.93	3.48947
2450.72	2.87902
2453.5	3.61701
2456.28	3.82075
2459.06	3.97481
2461.84	3.74978
2464.62	4.20148
2467.39	4.19699
2470.17	4.66859
2472.94	4.71103
2475.72	4.60644
2478.49	5.53053
2481.26	5.88394
2484.03	5.33209
2486.8	6.13479
2489.57	6.85961
2492.34	6.39503
2495.1	5.99734
2497.87	5.76288
2500.63	5.16793
2503.4	3.86271
2506.16	2.72381
2508.92	2.06245
2511.68	1.84457
2514.44	1.07016
2517.2	-0.268495
2519.96	-0.183191
2522.72	0.554893
2525.47	0.652195
2528.23	0.769198
2530.98	0.373316
2533.74	0.29302
2536.49	0.00815601
2539.24	-0.215743
2541.99	0.119043
2544.74	1.10551
2547.49	2.38836
2550.23	2.38497
2552.98	2.08821
2555.72	2.80589
2558.47	3.94671
2561.21	3.81383
2563.95	3.40035
2566.69	3.37889
2569.43	3.10402
2572.17	2.25239
2574.91	3.01762
2577.65	2.98533
2580.39	1.66169
2583.12	1.70072
2585.85	2.16922
2588.59	2.59524
2591.32	2.94151
2594.05	2.84773
2596.78	3.49728
2599.51	3.64762
2602.24	2.9365
2604.97	3.27611
2607.69	3.39662
2610.42	4.77227
2613.14	3.7865
2615.87	3.74353
2618.59	3.43363
2621.31	4.15009
2624.03	4.61286
2626.75	5.24505
2629.47	5.09742
2632.19	4.57732
2634.91	4.78613
2637.62	4.48546
2640.34	4.49287
2643.05	4.57194
2645.76	4.57426
2648.48	4.76423
2651.19	5.07191
2653.9	5.82634
2656.6	5.74312
2659.31	6.22171
2662.02	5.77396
2664.73	6.05315
2667.43	5.37354
2670.14	4.62387
2672.84	4.56855
2675.54	4.02454
2678.24	3.99491
2680.94	2.48346
2683.64	2.31064
2686.34	2.67627
2689.04	3.18542
2691.74	3.1769
2694.43	4.56893
2697.13	4.24389
2699.82	3.57701
2702.51	3.7875
2705.21	4.40245
2707.9	3.99812
2710.58	4.51975
2713.27	5.24543
2715.96	5.35505
2718.65	5.92996
2721.33	5.91496
2724.02	5.16568
2726.71	4.90635
2729.39	5.91055
2732.07	5.60447
2734.75	4.61978
2737.43	5.04535
2740.11	5.51165
2742.79	5.02994
2745.47	4.9691
2748.14	4.60097
2750.82	5.4299
2753.49	4.94939
2756.17	4.57413
2758.84	4.99176
2761.51	4.25698
2764.18	3.62633
2766.85	3.55633
2769.52	3.91749
2772.19	3.74816
2774.86	3.28275
2777.52	2.98253
2780.19	1.92872
2782.85	1.3621
2785.52	0.527825
2788.18	0.154272
2790.84	-0.210787
2793.5	-0.0662844
2796.16	-0.250411
2798.82	-0.744514
2801.48	-0.742002
2804.13	-0.404461
2806.79	-0.58894
2809.45	-0.512496
2812.1	-0.916292
2814.75	-1.17967
2817.41	-0.512249
2820.06	-0.0711867
2822.71	1.70426
2825.36	4.66008
2828	7.66354
2830.65	9.98098
2833.3	14.0235
2835.94	17.7327
2838.59	21.8191
2841.23	24.9245
2843.87	29.6714
2846.52	34.4776
2849.16	39.2823
2851.8	45.1335
2854.44	50.3296
2857.08	55.4165
2859.71	61.0395
2862.35	65.5502
2864.98	70.4948
2867.62	75.7694
2870.25	79.3725
2872.88	83.0841
2875.52	85.3777
2878.15	87.5969
2880.78	90.4408
2883.41	92.9715
2886.03	95.9209
2888.66	99.3975
2891.29	102.048
2893.91	104.056
2896.54	106.717
2899.16	109.989
2901.78	114.852
2904.4	119.365
2907.02	124.088
2909.64	130.283
2912.26	136.444
2914.88	142.594
2917.5	147.911
2920.11	153.256
2922.73	156.253
2925.34	159.969
2927.96	161.977
2930.57	164.343
2933.18	163.913
2935.79	162.794
2938.4	161.089
2941.01	158.286
2943.62	153.719
2946.22	149.216
2948.83	143.684
2951.43	137.809
2954.04	131.475
2956.64	124.839
2959.24	118.352
2961.84	112.466
2964.45	106.739
2967.05	101.436
2969.64	96.267
2972.24	90.3276
2974.84	85.4104
2977.43	80.008
2980.03	73.1089
2982.62	68.0017
2985.22	62.2637
2987.81	57.4908
2990.4	52.7233
2992.99	47.8618
2995.58	42.9752
2998.17	37.8731
3000.76	33.2552
3003.34	28.5336
3005.93	23.6901
3008.52	19.5623
3011.1	16.3558
3013.68	13.3206
3016.27	11.5054
3018.85	9.59165
3021.43	8.26088
3024.01	6.95382
3026.59	4.78737
3029.16	4.78516
3031.74	4.97014
3034.32	5.18021
3036.89	4.44812
3039.47	4.57356
3042.04	5.1958
3044.61	5.82038
3047.18	7.47654
3049.75	7.94044
3052.32	8.36134
3054.89	8.5421
3057.46	8.57727
3060.03	8.11654
3062.59	6.35681
3065.16	6.84774
3067.72	5.9688
3070.29	5.56291
3072.85	5.42829
3075.41	4.30872
3077.97	3.26357
3080.53	1.9229
3083.09	1.41022
3085.65	0.325302
3088.21	-0.192269
3090.76	-0.0112553
3093.32	1.13493
3095.87	0.607445
3098.43	0.493246
3100.98	0.487717
3103.53	1.06057
3106.08	2.04755
3108.63	3.30855
3111.18	3.92299
3113.73	5.06523
3116.28	6.39729
3118.83	7.95953
3121.37	9.16659
3123.92	10.3503
3126.46	11.8555
3129	13.7881
3131.55	15.4965
3134.09	16.3184
3136.63	17.8608
3139.17	18.4559
3141.71	20.2362
3144.24	21.6645
3146.78	22.768
3149.32	23.7152