File: data/Raman/poly_smoothed/Thy_20_09_04_1x_45s_532 nm_x100_100%_600 gr_mm_01.txt
#Acq. time (s)=	45
#Accumulations=	2
#Range (cm-¹)=	200...3150
#Windows=	2
#Auto scanning=	Off
#Autofocus=	Off
#Macrospot=	Off
#AutoExposure=	Off
#Spike filter=	Multiple accum.
#Delay time (s)=	0
#Binning=	1
#Readout mode=	Signal
#DeNoise=	Off
#ICS correction=	On
#Dark correction=	Off
#Inst. Process=	Off
#Detector Gain=	Best Dynamic Range
#Detector ADC=	20 kHz
#Detector temperature (°C)=	-69.85
#Instrument=	LabRAM HR Evol
#Detector=	Synapse
#Objective=	x100
#Grating=	600 gr/mm
#ND Filter=	100%
#Laser (nm)=	532
#Hole=	100.021
#Range=	Auto
#Laser Pol.=	No
#Raman. Pol.=	No
#Laser Pol. (°)=	-0.0007625
#Raman Pol. (°)=	89.9995
#Collection=	Microscope
#StageXY=	Marzhauser
#StageZ=	Marzhauser
#X (µm)=	-5921.9
#Y (µm)=	2830.8
#Z (µm)=	-223.35
#Full time(mm:ss)=	3:18
#Project=
#Sample=
#Site=
#Title=	Thy_20_09_04_2x_45s_532 nm_x100_100%_600 gr_mm
#Remark=
#Date=	29.06.2022 11:00
#Acquired=	29.06.2022 11:00:27
#Base:Fit=	10.08.2022 09:49:32
#Base:Fit=	10.08.2022 09:49:42
#Base:Fit=	10.08.2022 09:49:53
#Base:Fit=	10.08.2022 09:50:12
#Base:Fit=	10.08.2022 09:50:26
#Base:Fit=	10.08.2022 09:50:30
#Base:Fit=	10.08.2022 09:50:43
#Base:Fit=	10.08.2022 09:52:02
#Base:Fit=	10.08.2022 09:52:12
#Base:Sub=	10.08.2022 09:54:21
#Filter:Polynom=	16.08.2022 10:24:04
#AxisType[0]=Intens
#AxisUnit[0]=Cnt
#AxisType[1]=Spectr
#AxisUnit[1]=1/cm
200.523	68.8599
204.154	54.5469
207.781	42.3827
211.409	32.427
215.034	24.5339
218.659	18.8084
222.281	14.1541
225.903	11.4179
229.522	9.74038
233.14	9.40468
236.756	9.87645
240.373	7.98031
243.986	7.02477
247.598	6.25973
251.208	7.24191
254.818	8.54007
258.427	8.00321
262.034	8.87346
265.638	9.14313
269.242	11.0463
272.844	12.5524
276.445	11.6873
280.044	11.1927
283.642	10.9872
287.238	10.3239
290.833	9.21881
294.425	8.6117
298.017	9.53344
301.608	8.9532
305.198	9.8014
308.786	9.64196
312.371	9.31059
315.956	9.27317
319.54	9.45484
323.122	10.1741
326.701	8.12684
330.281	6.95767
333.857	5.55518
337.434	3.44112
341.008	3.70333
344.582	3.0738
348.153	3.17322
351.724	2.60298
355.292	4.05868
358.861	2.45622
362.426	2.31511
365.99	3.02437
369.555	2.34645
373.116	2.81128
376.676	1.90967
380.236	2.43154
383.793	3.66327
387.349	4.19153
390.903	3.46034
394.456	3.90793
398.007	3.78546
401.56	5.59483
405.108	6.5603
408.656	7.60907
412.202	6.72561
415.746	7.20424
419.29	7.24061
422.831	6.11239
426.37	5.92243
429.909	6.59448
433.447	7.32716
436.983	7.64338
440.519	8.10916
444.052	8.73023
447.583	9.37672
451.114	11.8032
454.643	10.8566
458.169	9.40943
461.696	10.6474
465.222	11.1791
468.744	12.6725
472.267	13.2158
475.787	13.2957
479.307	14.4114
482.823	15.2541
486.341	17.6969
489.855	17.0719
493.37	16.8516
496.881	18.4927
500.391	18.6209
503.902	18.4023
507.409	17.444
510.915	17.3898
514.42	17.8342
517.925	18.5815
521.427	18.3418
524.928	18.1077
528.427	16.4721
531.925	16.0837
535.422	13.9227
538.917	11.3142
542.411	12.1682
545.903	12.0732
549.395	14.0242
552.884	14.3765
556.373	14.2577
559.86	13.659
563.346	13.6702
566.831	13.0228
570.314	14.0775
573.794	13.7681
577.274	14.4524
580.754	15.1954
584.23	14.0672
587.706	13.4786
591.181	13.5193
594.653	12.6387
598.126	9.4162
601.595	8.42064
605.065	7.94465
608.532	6.58147
611.999	3.4405
615.463	4.63965
618.928	2.94253
622.389	2.79328
625.851	2.40163
629.31	3.97277
632.767	5.69058
636.223	7.18157
639.68	8.68775
643.134	8.43558
646.586	10.3531
650.037	11.4231
653.486	14.0443
656.936	17.157
660.383	19.2744
663.829	19.2799
667.273	21.3719
670.716	22.8499
674.158	24.2112
677.598	27.7807
681.035	28.6929
684.473	31.6421
687.909	35.438
691.344	38.9119
694.778	39.7896
698.211	41.436
701.64	42.0206
705.07	43.4135
708.498	46.0034
711.924	47.4372
715.35	49.6084
718.774	50.8136
722.196	51.5653
725.618	51.7764
729.037	53.287
732.456	54.9582
735.873	55.2559
739.289	55.9758
742.703	56.1521
746.116	57.3821
749.529	59.4348
752.938	60.8503
756.347	62.851
759.756	65.1558
763.162	67.8275
766.567	70.3016
769.97	71.7485
773.372	72.8287
776.773	75.4957
780.174	75.8423
783.573	76.8364
786.97	79.4825
790.365	81.8015
793.76	82.9418
797.153	83.9671
800.543	85.6064
803.933	87.2473
807.322	88.5132
810.71	89.7321
814.097	90.2456
817.483	91.1699
820.865	92.7125
824.248	93.4784
827.629	92.7528
831.008	93.8693
834.387	93.3946
837.765	91.357
841.139	89.7367
844.514	86.0329
847.886	81.9023
851.259	77.8595
854.629	73.6427
857.997	71.1268
861.366	68.2086
864.732	64.9391
868.098	63.1013
871.461	60.0386
874.823	58.0667
878.184	56.6296
881.545	54.7117
884.903	52.8103
888.26	52.2346
891.616	53.354
894.97	54.95
898.323	55.8035
901.675	56.2009
905.026	55.7154
908.375	54.7958
911.723	54.8863
915.07	54.7497
918.415	55.1583
921.76	52.561
925.103	50.3464
928.443	48.638
931.783	45.3797
935.123	43.7067
938.461	41.032
941.796	40.6387
945.131	40.8636
948.465	38.4868
951.797	36.7619
955.128	35.1626
958.457	32.7549
961.786	31.5136
965.113	31.3133
968.44	30.7959
971.763	31.3166
975.086	31.5531
978.409	30.7978
981.729	27.2355
985.048	26.7905
988.367	26.5231
991.683	25.8298
994.998	25.0778
998.312	24.4379
1001.62	23.5256
1004.94	22.9466
1008.25	22.3496
1011.56	20.6068
1014.86	18.3162
1018.17	17.494
1021.48	17.1296
1024.78	17.5603
1028.08	19.6476
1031.38	18.7414
1034.68	16.3521
1037.98	15.6676
1041.28	14.4078
1044.57	14.6087
1047.87	12.9238
1051.16	12.9713
1054.45	13.1529
1057.75	12.4572
1061.04	10.604
1064.32	11.0151
1067.61	11.1973
1070.9	10.5345
1074.18	10.4543
1077.47	10.3921
1080.75	11.2236
1084.03	10.2359
1087.31	11.857
1090.59	11.7671
1093.86	12.2998
1097.14	13.3464
1100.41	14.5607
1103.69	16.513
1106.96	19.6946
1110.23	20.0192
1113.5	17.7275
1116.77	16.8559
1120.03	16.4136
1123.3	16.2321
1126.56	15.4116
1129.83	14.7363
1133.09	14.2566
1136.35	12.7958
1139.61	12.1996
1142.86	11.0623
1146.12	12.0195
1149.38	11.4589
1152.63	9.94168
1155.88	7.62001
1159.14	5.54361
1162.39	4.89877
1165.63	3.9986
1168.88	4.99572
1172.13	6.28321
1175.38	7.68784
1178.62	8.62013
1181.86	9.39992
1185.1	11.3223
1188.34	11.6701
1191.58	11.0699
1194.82	13.3408
1198.06	14.7824
1201.29	18.0218
1204.53	19.9497
1207.76	21.4896
1210.99	23.9525
1214.22	27.2082
1217.45	31.2892
1220.68	34.3889
1223.91	37.6634
1227.13	39.9458
1230.36	42.1969
1233.58	42.8475
1236.8	43.3141
1240.02	44.5517
1243.24	47.6453
1246.46	49.312
1249.67	51.4748
1252.89	53.2372
1256.1	53.472
1259.32	54.7784
1262.53	57.3101
1265.74	58.6626
1268.95	59.0616
1272.15	61.9197
1275.36	66.1853
1278.57	69.6517
1281.77	70.9481
1284.97	74.8126
1288.18	77.0825
1291.38	80.1426
1294.58	84.4875
1297.78	88.2496
1300.97	92.5077
1304.17	95.9142
1307.36	97.5696
1310.55	102.056
1313.75	104.652
1316.94	106.837
1320.13	107.253
1323.32	108.546
1326.5	108.581
1329.69	110.241
1332.87	110.057
1336.06	109.408
1339.24	108.866
1342.42	108.536
1345.6	107.839
1348.78	108.144
1351.96	107.311
1355.13	104.636
1358.31	102.481
1361.48	100.102
1364.65	96.5573
1367.82	92.1714
1370.99	91.1322
1374.16	88.5483
1377.33	87.0101
1380.5	85.0181
1383.66	81.3265
1386.83	78.3155
1389.99	76.1348
1393.15	74.0289
1396.31	71.469
1399.47	71.3407
1402.63	70.0183
1405.78	68.4521
1408.94	68.1375
1412.1	69.7096
1415.25	71.5929
1418.4	75.1351
1421.55	78.3508
1424.7	81.8381
1427.85	85.1331
1431	88.0881
1434.14	92.218
1437.29	94.5967
1440.43	94.5096
1443.57	97.6992
1446.71	102.049
1449.85	101.754
1452.99	100.604
1456.13	98.6462
1459.26	94.2597
1462.4	89.8806
1465.54	84.5541
1468.67	80.9312
1471.8	76.1448
1474.93	69.9394
1478.06	63.8499
1481.19	58.8374
1484.31	54.8989
1487.44	52.1005
1490.56	48.1312
1493.69	46.3993
1496.81	44.6748
1499.93	41.2566
1503.05	40.9573
1506.17	41.2476
1509.28	41.3106
1512.4	41.3801
1515.52	42.64
1518.63	43.7875
1521.74	47.3793
1524.85	47.6416
1527.96	49.3799
1531.07	51.7161
1534.18	53.0232
1537.29	56.101
1540.39	59.0354
1543.5	63.1335
1546.6	68.1632
1549.7	71.911
1552.8	79.5787
1555.9	85.1827
1559	91.28
1562.1	96.0737
1565.19	99.6446
1568.29	105.05
1571.38	109.944
1574.47	114.451
1577.56	118.55
1580.66	121.501
1583.74	124.25
1586.83	124.664
1589.92	124.021
1593.01	122.73
1596.09	120.634
1599.17	118.349
1602.25	115.736
1605.34	113.143
1608.41	108.771
1611.49	104.373
1614.57	101.331
1617.65	97.9708
1620.72	96.733
1623.79	93.3823
1626.87	91.0616
1629.94	89.3712
1633.01	85.6278
1636.08	83.8666
1639.15	83.5107
1642.21	82.2017
1645.28	83.125
1648.34	81.4556
1651.41	81.3835
1654.47	80.5832
1657.53	77.7211
1660.59	76.2956
1663.65	72.616
1666.71	69.8229
1669.76	65.5686
1672.82	62.3315
1675.87	59.7398
1678.93	54.0089
1681.98	49.1963
1685.03	43.5448
1688.08	39.9334
1691.13	36.123
1694.17	32.5996
1697.22	28.7662
1700.27	24.8431
1703.31	20.6775
1706.35	17.4247
1709.39	15.0153
1712.43	11.8885
1715.47	10.4726
1718.51	8.74532
1721.55	7.54316
1724.58	7.45573
1727.62	6.39312
1730.65	6.35668
1733.68	5.79211
1736.72	4.6984
1739.74	4.41579
1742.77	4.08597
1745.8	3.25371
1748.83	3.38624
1751.85	2.72457
1754.88	2.76897
1757.9	2.38002
1760.92	3.63134
1763.95	3.39943
1766.96	3.32781
1769.98	3.40795
1773	4.12513
1776.02	3.51802
1779.03	2.31522
1782.05	2.55887
1785.06	3.53024
1788.07	4.86387
1791.08	4.42226
1794.09	4.60962
1797.1	4.81305
1800.11	5.00261
1803.12	4.2828
1806.12	5.11162
1809.12	4.39848
1812.13	4.21271
1815.13	3.29222
1818.13	2.25977
1821.13	2.33551
1824.13	2.73523
1827.13	1.81901
1830.12	1.38919
1833.12	2.09701
1836.11	3.07743
1839.1	2.6246
1842.09	3.37208
1845.09	3.78303
1848.08	4.54762
1851.06	4.78848
1854.05	5.34067
1857.04	7.23206
1860.02	7.71291
1863.01	7.70771
1865.99	7.59042
1868.97	8.84893
1871.95	7.05004
1874.93	6.68462
1877.91	6.85746
1880.89	7.17614
1882.46	7.54512
1885.45	8.36097
1888.43	8.4439
1891.42	7.90111
1894.41	7.91817
1897.39	6.33642
1900.37	6.33028
1903.36	5.26182
1906.34	6.0894
1909.32	5.44571
1912.29	6.38709
1915.27	6.29088
1918.25	6.7766
1921.23	7.08727
1924.2	7.42442
1927.17	7.52709
1930.15	8.3337
1933.12	8.29294
1936.09	8.98098
1939.06	9.8251
1942.02	10.3571
1944.99	11.1832
1947.96	12.2077
1950.92	12.3836
1953.88	13.5514
1956.85	13.8309
1959.81	13.9495
1962.77	11.5336
1965.73	11.165
1968.69	9.32243
1971.64	8.7143
1974.6	7.52202
1977.55	6.25545
1980.51	7.34004
1983.46	6.28728
1986.41	5.90774
1989.36	4.89813
1992.31	4.47013
1995.26	5.46048
1998.21	5.26496
2001.15	4.37799
2004.1	4.79812
2007.04	4.89624
2009.99	7.37197
2012.93	8.33101
2015.87	8.65486
2018.81	7.82451
2021.75	7.74944
2024.68	7.65135
2027.62	7.70759
2030.56	7.35937
2033.49	7.98869
2036.42	8.86558
2039.36	9.86283
2042.29	11.4434
2045.22	11.3286
2048.14	12.5491
2051.07	12.4205
2054	11.5902
2056.93	10.9436
2059.85	12.6872
2062.77	13.6291
2065.7	14.3175
2068.62	14.3576
2071.54	13.8008
2074.46	14.7278
2077.38	16.3397
2080.29	16.4598
2083.21	17.4702
2086.12	17.3181
2089.04	17.9222
2091.95	18.4957
2094.86	19.0536
2097.77	19.8539
2100.68	19.6624
2103.59	20.969
2106.5	22.0691
2109.41	23.3656
2112.31	23.731
2115.21	23.8985
2118.12	24.5005
2121.02	25.3329
2123.92	25.0609
2126.82	27.0488
2129.72	29.8407
2132.62	30.1278
2135.51	31.3691
2138.41	32.4869
2141.31	33.012
2144.2	35.4829
2147.09	36.5454
2149.98	38.2372
2152.87	38.8582
2155.76	40.6809
2158.65	42.551
2161.54	44.8615
2164.43	45.267
2167.31	46.1629
2170.2	45.6406
2173.08	45.6476
2175.96	45.5659
2178.84	45.209
2181.72	44.8834
2184.6	44.5524
2187.48	43.5008
2190.36	42.7574
2193.23	41.8095
2196.11	40.4874
2198.98	38.8294
2201.85	37.39
2204.72	35.2655
2207.59	33.0511
2210.46	31.1402
2213.33	28.5247
2216.2	26.6826
2219.07	23.8874
2221.93	22.2812
2224.8	22.0111
2227.66	22.1607
2230.52	21.2402
2233.39	18.5066
2236.25	18.0035
2239.1	16.5334
2241.96	15.3039
2244.82	14.4644
2247.68	13.8667
2250.53	12.8077
2253.38	13.8188
2256.24	13.8208
2259.09	13.6015
2261.94	14.5562
2264.79	14.4468
2267.64	13.2644
2270.49	14.5233
2273.33	14.3591
2276.18	13.3108
2279.02	12.8494
2281.87	11.5766
2284.71	11.3395
2287.55	12.5309
2290.39	13.8886
2293.23	14.239
2296.07	14.7565
2298.91	15.282
2301.74	14.2327
2304.58	15.8166
2307.41	15.5804
2310.25	15.0978
2313.08	15.4266
2315.91	15.4848
2318.74	15.3149
2321.57	16.0298
2324.4	17.1295
2327.23	16.4397
2330.05	15.767
2332.88	15.1322
2335.7	14.3797
2338.52	14.0854
2341.35	14.5703
2344.17	13.6198
2346.99	12.4397
2349.81	11.6665
2352.62	10.6756
2355.44	10.5888
2358.26	9.73379
2361.07	10.029
2363.89	8.86109
2366.7	8.47007
2369.51	7.3303
2372.32	6.87366
2375.13	5.8042
2377.94	5.05787
2380.75	5.09128
2383.56	3.2337
2386.36	4.0261
2389.17	3.50918
2391.97	4.1896
2394.77	4.63724
2397.58	4.53663
2400.38	4.81611
2403.18	5.06195
2405.97	6.12174
2408.77	7.5169
2411.57	7.32302
2414.37	8.15933
2417.16	8.92448
2419.95	10.1425
2422.75	10.5917
2425.54	11.2534
2428.33	10.8817
2431.12	10.5425
2433.91	9.26785
2436.7	9.5496
2439.48	7.09574
2442.27	7.11426
2445.05	7.94595
2447.84	7.61448
2450.62	7.22531
2453.4	6.70063
2456.18	6.38253
2458.96	6.78603
2461.74	6.24523
2464.52	5.90102
2467.29	6.60482
2470.07	5.35685
2472.85	4.96924
2475.62	5.15716
2478.39	5.09605
2481.16	5.4958
2483.93	7.7041
2486.7	7.1498
2489.47	6.0571
2492.24	4.13871
2495.01	4.83071
2497.77	3.95619
2500.54	2.89188
2503.3	2.95641
2506.06	2.33838
2508.83	2.16892
2511.59	2.74988
2514.35	2.32146
2517.11	1.25396
2519.86	1.76973
2522.62	3.47667
2525.38	4.65326
2528.13	5.40196
2530.89	4.92388
2533.64	5.8464
2536.39	7.12536
2539.14	7.27644
2541.89	8.88927
2544.64	10.3997
2547.39	10.5542
2550.14	9.94281
2552.88	8.95172
2555.63	8.49722
2558.37	8.87259
2561.11	9.2829
2563.86	8.75356
2566.6	8.18988
2569.34	6.73094
2572.08	6.50106
2574.82	5.7802
2577.55	4.61109
2580.29	2.97845
2583.02	2.27536
2585.76	3.41632
2588.49	4.5858
2591.22	5.06914
2593.96	4.59321
2596.69	4.26571
2599.42	4.33544
2602.14	4.56409
2604.87	5.6693
2607.6	4.92661
2610.32	4.45287
2613.05	3.24266
2615.77	2.37269
2618.49	2.74439
2621.22	3.7666
2623.94	5.35353
2626.66	4.85856
2629.37	5.7037
2632.09	4.79925
2634.81	4.66525
2637.53	4.09835
2640.24	3.45576
2642.96	3.63886
2645.67	3.02479
2648.38	2.89549
2651.09	2.69722
2653.8	2.98627
2656.51	4.17868
2659.22	3.41013
2661.93	2.74034
2664.63	3.08088
2667.34	2.8477
2670.04	2.00546
2672.75	2.71261
2675.45	2.34007
2678.15	2.67308
2680.85	3.59613
2683.55	4.33867
2686.25	4.45988
2688.94	6.18826
2691.64	7.77918
2694.34	8.68882
2697.03	9.85507
2699.73	10.2188
2702.42	10.5205
2705.11	11.0873
2707.8	12.5918
2710.49	13.7736
2713.18	12.9002
2715.87	13.4044
2718.55	13.7552
2721.24	13.9315
2723.93	13.5521
2726.61	12.7362
2729.29	12.3821
2731.98	11.3121
2734.66	10.3004
2737.34	10.5321
2740.02	9.99873
2742.7	7.97054
2745.37	7.27274
2748.05	6.5925
2750.72	5.75346
2753.4	5.99064
2756.07	5.93832
2758.75	5.35041
2761.42	4.6196
2764.09	5.06552
2766.76	4.37051
2769.43	3.82868
2772.1	3.42957
2774.76	3.0722
2777.43	2.55217
2780.1	1.91938
2782.76	1.8242
2785.42	0.354633
2788.09	0.0082596
2790.75	0.225344
2793.41	0.470114
2796.07	0.234839
2798.73	0.466268
2801.39	0.667478
2804.04	0.599301
2806.7	0.12
2809.35	0.077619
2812.01	1.24846
2814.66	2.32825
2817.31	3.02816
2819.96	4.27804
2822.61	5.22113
2825.26	7.73572
2827.91	11.203
2830.56	13.7186
2833.21	16.7029
2835.85	20.0652
2838.5	23.4622
2841.14	26.4502
2843.78	30.952
2846.42	35.6253
2849.06	41.1539
2851.71	47.9812
2854.34	54.7789
2856.98	62.4074
2859.62	67.8525
2862.26	73.3445
2864.89	78.1867
2867.53	82.4497
2870.16	86.7545
2872.79	91.2478
2875.42	95.7175
2878.05	99.6666
2880.68	102.658
2883.31	105.426
2885.94	109.102
2888.57	112.16
2891.19	116.289
2893.82	119.22
2896.44	122.814
2899.07	125.668
2901.69	129.414
2904.31	135.634
2906.93	142.591
2909.55	150.455
2912.17	158.79
2914.79	167.047
2917.41	174.515
2920.02	179.838
2922.64	183.957
2925.25	185.948
2927.86	187.249
2930.48	187.732
2933.09	188.198
2935.7	185.623
2938.31	183.072
2940.92	179.086
2943.53	173.543
2946.13	167.664
2948.74	161.113
2951.34	154.286
2953.95	147.47
2956.55	139.588
2959.15	133.072
2961.75	127.122
2964.35	120.112
2966.95	114.078
2969.55	107.691
2972.15	101.469
2974.75	96.4316
2977.34	90.5559
2979.94	83.0311
2982.53	75.4008
2985.13	69.1245
2987.72	61.4025
2990.31	54.4332
2992.9	47.9443
2995.49	42.7645
2998.08	36.5991
3000.67	31.0423
3003.25	27.3349
3005.84	22.0117
3008.42	19.1579
3011.01	15.9633
3013.59	12.7904
3016.17	10.6669
3018.76	9.05007
3021.34	6.95423
3023.92	5.82406
3026.49	3.42798
3029.07	2.36098
3031.65	2.28704
3034.23	2.0526
3036.8	2.646
3039.38	4.18911
3041.95	3.60518
3044.52	4.32249
3047.09	4.645
3049.66	4.41893
3052.23	5.2664
3054.8	6.5455
3057.37	7.15575
3059.94	6.4623
3062.5	6.62567
3065.07	7.07856
3067.63	6.88293
3070.2	6.42419
3072.76	5.8376
3075.32	4.62542
3077.88	3.92254
3080.44	3.34753
3083	2.03152
3085.56	0.965997
3088.12	0.307886
3090.67	-0.562094
3093.23	-0.469905
3095.78	-0.659849
3098.34	-0.500279
3100.89	0.9285
3103.44	0.554984
3105.99	1.51598
3108.54	2.38987
3111.09	2.84668
3113.64	3.81065
3116.19	5.74611
3118.74	6.63401
3121.28	8.06319
3123.83	9.2104
3126.37	10.442
3128.91	11.6342
3131.46	12.9833
3134	14.5663
3136.54	15.4366
3139.08	16.2316
3141.62	16.5735
3144.16	16.9029
3146.69	17.1069
3149.23	17.7038