File: data/Raman/poly_smoothed/Thy_30_10_38_1x_45s_532 nm_x100_100%_600 gr_mm_01.txt
#Acq. time (s)=	45
#Accumulations=	2
#Range (cm-¹)=	200...3150
#Windows=	2
#Auto scanning=	Off
#Autofocus=	Off
#Macrospot=	Off
#AutoExposure=	Off
#Spike filter=	Multiple accum.
#Delay time (s)=	0
#Binning=	1
#Readout mode=	Signal
#DeNoise=	Off
#ICS correction=	On
#Dark correction=	Off
#Inst. Process=	Off
#Detector Gain=	Best Dynamic Range
#Detector ADC=	20 kHz
#Detector temperature (°C)=	-69.85
#Instrument=	LabRAM HR Evol
#Detector=	Synapse
#Objective=	x100
#Grating=	600 gr/mm
#ND Filter=	100%
#Laser (nm)=	532
#Hole=	100.021
#Range=	Auto
#Laser Pol.=	No
#Raman. Pol.=	No
#Laser Pol. (°)=	-0.0007625
#Raman Pol. (°)=	89.9995
#Collection=	Microscope
#StageXY=	Marzhauser
#StageZ=	Marzhauser
#X (µm)=	4724.5
#Y (µm)=	-7717.6
#Z (µm)=	584.8
#Full time(mm:ss)=	3:18
#Project=
#Sample=
#Site=
#Title=	Thy_30_10_38_2x_45s_532 nm_x100_100%_600 gr_mm
#Remark=
#Date=	30.06.2022 14:10
#Acquired=	30.06.2022 14:10:12
#Base:Fit=	10.08.2022 09:58:11
#Base:Sub=	10.08.2022 09:58:44
#Filter:Polynom=	16.08.2022 10:22:53
#AxisType[0]=Intens
#AxisUnit[0]=Cnt
#AxisType[1]=Spectr
#AxisUnit[1]=1/cm
200.533	8.36724
204.162	5.96172
207.792	4.30975
211.418	4.22795
215.044	5.59188
218.667	5.01597
222.289	5.23776
225.912	5.13731
229.531	4.74043
233.148	4.43883
236.766	4.19659
240.381	3.9039
243.994	4.28565
247.606	4.20162
251.217	4.56248
254.828	5.01079
258.436	4.30422
262.042	3.44329
265.647	3.67889
269.25	3.93694
272.852	3.4383
276.453	3.05823
280.052	3.07333
283.65	2.89162
287.247	3.03538
290.842	3.04411
294.436	3.18065
298.028	4.34239
301.617	4.76036
305.206	5.10524
308.794	4.75988
312.381	5.36142
315.964	5.36053
319.548	5.74065
323.131	5.4178
326.71	5.49647
330.29	5.78639
333.868	6.37555
337.443	5.54055
341.018	4.88226
344.591	5.23721
348.163	5.56342
351.733	6.8222
355.303	7.98669
358.869	7.00054
362.435	7.95627
366.001	7.4035
369.563	7.36514
373.124	6.54634
376.686	5.19756
380.244	5.58626
383.801	5.85527
387.357	5.57459
390.911	5.46514
394.466	5.64728
398.018	4.51997
401.568	4.56518
405.117	5.14072
408.664	4.83971
412.21	3.35034
415.755	3.21098
419.298	3.62548
422.84	2.10914
426.38	1.73345
429.919	2.46608
433.455	2.55505
436.992	2.82867
440.527	2.66536
444.06	2.35359
447.593	3.45975
451.122	3.63429
454.651	2.93676
458.18	4.16719
461.705	4.20129
465.23	4.59307
468.752	6.78096
472.275	7.77527
475.797	8.24205
479.315	9.8529
482.834	11.4426
486.349	11.4205
489.863	12.3859
493.378	12.3875
496.889	12.5076
500.401	13.197
503.91	12.8678
507.417	12.6677
510.923	11.5348
514.43	11.3493
517.933	11.0533
521.435	10.2001
524.936	8.88718
528.435	8.05491
531.933	7.33441
535.43	7.32872
538.927	5.33399
542.421	5.13349
545.913	5.85758
549.403	4.85193
552.893	5.41822
556.381	5.68976
559.868	5.72009
563.354	4.56314
566.839	4.6908
570.322	2.64468
573.802	3.04059
577.283	3.39604
580.762	3.21344
584.24	3.91576
587.714	2.82332
591.19	3.0654
594.663	2.4744
598.134	2.19586
601.605	2.36741
605.073	1.63382
608.542	1.25452
612.007	1.18771
615.473	1.08463
618.936	2.07179
622.397	2.9096
625.859	3.07189
629.318	4.36485
632.775	6.05712
636.233	6.656
639.688	7.90566
643.142	8.48745
646.594	8.83834
650.045	9.1395
653.496	10.4062
656.944	11.2938
660.391	12.224
663.837	12.5251
667.281	12.7364
670.724	13.117
674.166	13.534
677.606	14.7344
681.045	14.4556
684.483	15.8103
687.917	16.897
691.352	17.4619
694.786	18.9559
698.219	20.7299
701.65	22.5172
705.078	23.1891
708.506	25.4487
711.934	27.3247
715.358	29.0457
718.782	31.1064
722.204	33.9229
725.626	35.9099
729.045	37.2752
732.464	39.7888
735.881	42.6062
739.297	43.5164
742.711	45.1822
746.125	46.7139
749.537	47.8866
752.946	49.038
756.357	51.5151
759.764	53.8987
763.17	56.1948
766.575	58.3631
769.978	60.3013
773.382	61.5285
776.783	62.4498
780.182	63.3858
783.581	64.9609
786.978	65.5051
790.373	66.275
793.768	68.154
797.161	70.3426
800.552	73.2321
803.941	74.6933
807.33	77.6536
810.718	78.4675
814.105	78.6554
817.49	78.5204
820.873	77.9098
824.256	76.26
827.637	74.0819
831.016	74.3336
834.395	74.2982
837.772	72.5304
841.147	71.2523
844.522	69.9983
847.894	67.0778
851.267	64.4536
854.637	61.3319
858.007	58.022
861.374	57.3664
864.739	55.1142
868.106	53.3781
871.469	51.793
874.831	51.9664
878.193	52.6949
881.553	51.953
884.911	51.4513
888.268	50.7622
891.623	50.7444
894.978	48.8988
898.331	47.4245
901.683	46.61
905.033	44.3874
908.383	43.8013
911.731	44.5339
915.078	43.9644
918.423	42.0512
921.768	42.2241
925.111	42.248
928.452	42.0419
931.791	41.5729
935.13	40.9699
938.468	41.1353
941.803	41.8924
945.139	41.668
948.473	40.8795
951.804	40.4923
955.136	40.0377
958.465	40.0042
961.794	38.7703
965.12	38.7193
968.447	38.1229
971.771	36.9533
975.095	36.5312
978.417	35.8271
981.737	34.5602
985.057	34.7776
988.375	33.2617
991.691	32.9278
995.006	33.586
998.32	31.3884
1001.63	30.5006
1004.95	29.9608
1008.26	29.0814
1011.56	29.301
1014.87	27.8145
1018.18	27.2094
1021.48	26.6976
1024.79	25.9714
1028.09	24.2276
1031.39	23.1216
1034.69	22.7123
1037.99	20.9545
1041.29	20.031
1044.58	19.5321
1047.88	19.0025
1051.17	18.643
1054.46	19.8427
1057.75	20.1024
1061.04	19.9228
1064.33	19.2809
1067.62	18.2587
1070.9	18.6845
1074.19	19.1929
1077.47	18.2431
1080.76	18.23
1084.04	20.2939
1087.32	20.3331
1090.59	20.5311
1093.87	19.9623
1097.15	20.5157
1100.42	20.444
1103.69	21.1074
1106.97	20.6839
1110.24	20.2734
1113.51	18.9712
1116.77	18.09
1120.04	17.0475
1123.31	17.115
1126.57	17.5168
1129.83	18.1106
1133.1	18.7677
1136.36	18.4586
1139.62	15.9237
1142.87	16.1018
1146.13	13.8999
1149.38	13.8003
1152.64	14.6762
1155.89	14.187
1159.14	13.3888
1162.39	13.3157
1165.64	11.7438
1168.89	10.6462
1172.14	9.45877
1175.38	8.94801
1178.63	7.93755
1181.87	7.89905
1185.11	7.06406
1188.35	6.1579
1191.59	6.99701
1194.83	7.58473
1198.07	8.78435
1201.3	10.9421
1204.53	13.721
1207.77	15.9146
1211	18.0291
1214.23	19.0379
1217.46	21.5462
1220.69	23.0582
1223.91	25.5071
1227.14	28.8503
1230.36	31.2965
1233.59	31.4974
1236.81	31.8647
1240.03	33.3531
1243.25	34.7133
1246.46	35.7514
1249.68	37.1681
1252.9	38.1654
1256.11	39.9383
1259.32	40.2927
1262.54	41.4817
1265.75	42.5243
1268.96	42.5129
1272.16	43.0143
1275.37	42.7697
1278.57	44.0526
1281.78	45.5387
1284.98	45.7829
1288.18	46.6257
1291.38	48.216
1294.58	48.8199
1297.78	48.2553
1300.98	48.2686
1304.17	49.4345
1307.37	49.6592
1310.56	49.0961
1313.76	49.308
1316.95	49.2592
1320.14	49.2469
1323.32	49.1246
1326.51	49.6414
1329.7	49.6831
1332.88	48.9247
1336.07	47.5877
1339.25	46.4405
1342.43	45.8367
1345.61	43.6293
1348.79	42.4574
1351.96	41.2165
1355.14	40.6398
1358.31	40.0281
1361.49	38.6721
1364.66	38.5773
1367.83	37.4864
1371	36.7696
1374.17	35.044
1377.34	33.5425
1380.5	32.1627
1383.67	30.9643
1386.83	30.1986
1390	28.048
1393.16	26.1198
1396.32	25.1059
1399.48	24.0338
1402.64	23.6177
1405.79	22.4731
1408.95	22.3362
1412.1	23.7781
1415.26	24.7599
1418.41	25.6047
1421.56	27.1979
1424.71	30.1142
1427.86	31.3251
1431	35.7646
1434.15	39.1571
1437.29	41.7473
1440.44	44.3262
1443.58	46.8895
1446.72	47.8492
1449.86	49.5905
1453	49.353
1456.14	48.5445
1459.27	47.8619
1462.41	46.44
1465.54	43.5739
1468.67	39.9969
1471.81	37.1932
1474.94	33.6334
1478.07	30.3018
1481.19	27.2339
1484.32	23.9171
1487.45	22.5331
1490.57	19.8717
1493.69	17.7305
1496.82	16.0614
1499.94	16.571
1503.06	14.8409
1506.17	15.298
1509.29	15.2013
1512.41	15.0041
1515.52	15.4139
1518.64	15.0827
1521.75	16.6845
1524.86	17.4773
1527.97	17.9943
1531.08	18.3879
1534.19	19.4554
1537.29	19.5934
1540.4	19.4765
1543.5	20.3643
1546.61	22.8425
1549.71	24.3729
1552.81	26.4931
1555.91	27.9739
1559.01	30.932
1562.11	33.1654
1565.2	34.9372
1568.29	37.0603
1571.39	39.0385
1574.48	40.3326
1577.57	41.0902
1580.66	41.992
1583.75	42.1758
1586.84	43.537
1589.93	44.425
1593.01	44.748
1596.1	43.9184
1599.18	42.5838
1602.26	41.3417
1605.34	40.3074
1608.42	38.5443
1611.5	37.1985
1614.58	35.3841
1617.65	35.1371
1620.73	35.7996
1623.8	35.5942
1626.87	35.6973
1629.95	35.1471
1633.02	36.1001
1636.09	37.547
1639.15	38.7091
1642.22	41.1355
1645.29	41.1919
1648.35	42.1424
1651.42	42.1288
1654.48	43.0564
1657.54	44.1087
1660.6	44.1412
1663.66	43.4868
1666.72	42.9262
1669.77	41.0431
1672.83	38.1478
1675.88	35.3601
1678.93	33.8001
1681.99	30.6748
1685.04	27.5762
1688.09	23.9646
1691.13	22.7541
1694.18	20.4874
1697.23	17.0894
1700.27	14.2663
1703.32	12.3971
1706.36	10.7003
1709.4	8.80866
1712.44	6.27219
1715.48	5.15024
1718.52	3.91961
1721.56	2.77437
1724.59	2.58064
1727.63	3.00715
1730.66	3.35221
1733.69	2.52263
1736.72	2.43071
1739.75	2.59091
1742.78	2.89071
1745.81	3.85951
1748.84	3.13697
1751.86	3.88209
1754.89	4.57769
1757.91	4.40484
1760.93	4.66285
1763.95	5.04125
1766.97	4.8667
1769.99	3.79197
1773.01	3.19708
1776.03	2.57324
1779.04	1.85757
1782.06	0.649888
1785.07	0.910508
1788.08	0.653637
1791.09	0.767535
1794.1	1.38742
1797.11	1.52897
1800.12	1.46315
1803.12	1.23312
1806.13	0.591284
1809.13	0.614937
1812.14	1.54096
1815.14	2.64049
1818.14	3.00382
1821.14	3.14546
1824.14	2.73012
1827.13	2.59906
1830.13	3.11774
1833.12	2.79617
1836.12	2.99625
1839.11	3.72658
1842.1	3.87968
1845.09	3.38238
1848.08	3.63288
1851.07	3.81316
1854.06	4.87999
1857.04	5.67343
1860.03	5.50881
1863.01	5.82767
1866	6.77009
1868.98	7.04671
1871.96	7.00978
1874.94	7.16106
1877.92	6.71758
1880.89	6.36269
1882.48	6.65155
1885.47	6.41614
1888.46	5.54526
1891.44	5.42734
1894.43	5.20572
1897.41	4.72665
1900.4	5.58665
1903.38	5.75633
1906.36	6.07036
1909.34	7.10491
1912.32	6.88279
1915.29	7.01226
1918.27	7.46531
1921.25	8.00228
1924.22	8.21739
1927.2	8.22538
1930.17	8.08754
1933.14	7.33207
1936.11	8.61239
1939.08	8.30917
1942.05	8.15954
1945.01	8.51482
1947.98	8.11048
1950.94	7.54664
1953.91	7.93627
1956.87	7.35941
1959.83	7.22984
1962.79	8.10313
1965.75	7.832
1968.71	6.86116
1971.67	7.07943
1974.62	7.63513
1977.58	7.53158
1980.53	8.92998
1983.48	8.41206
1986.43	8.11343
1989.38	7.7891
1992.33	7.19083
1995.28	6.62317
1998.23	6.62747
2001.18	6.5746
2004.12	7.13645
2007.06	7.12439
2010.01	7.01401
2012.95	7.3131
2015.89	7.44968
2018.83	7.79359
2021.77	7.30409
2024.71	8.20833
2027.64	8.78591
2030.58	9.43368
2033.51	10.142
2036.45	9.48538
2039.38	9.25072
2042.31	9.37927
2045.24	9.68655
2048.17	10.7277
2051.1	11.0189
2054.02	11.5892
2056.95	11.163
2059.87	11.6878
2062.8	11.592
2065.72	11.8605
2068.64	12.8558
2071.56	13.4871
2074.48	13.8689
2077.4	14.2284
2080.31	14.3916
2083.23	15.2029
2086.14	16.1449
2089.06	16.943
2091.97	17.4377
2094.88	18.2356
2097.79	18.8452
2100.7	19.2339
2103.61	19.7206
2106.52	19.8971
2109.43	19.32
2112.33	19.6821
2115.24	20.5218
2118.14	20.3427
2121.04	21.592
2123.94	22.2596
2126.84	22.9681
2129.74	24.1586
2132.64	25.1561
2135.54	26.7966
2138.43	29.1856
2141.33	30.7344
2144.22	32.4804
2147.11	34.5673
2150.01	36.8452
2152.9	38.5585
2155.79	40.5827
2158.67	42.065
2161.56	43.9658
2164.45	45.214
2167.33	46.2935
2170.22	47.0752
2173.1	47.4381
2175.98	48.056
2178.86	47.5159
2181.74	47.2189
2184.62	46.6381
2187.5	45.6773
2190.38	44.8803
2193.25	44.1745
2196.13	42.3398
2199	40.9362
2201.88	39.4609
2204.75	37.9075
2207.62	36.1552
2210.49	35.0338
2213.36	32.8981
2216.22	32.5162
2219.09	30.477
2221.96	29.3725
2224.82	27.9653
2227.68	26.4711
2230.55	25.1787
2233.41	24.4039
2236.27	22.2994
2239.12	21.986
2241.98	20.3367
2244.84	19.8408
2247.7	19.1352
2250.55	18.2285
2253.41	17.1163
2256.26	15.743
2259.11	15.6724
2261.96	15.1144
2264.81	14.126
2267.66	13.3254
2270.51	13.6543
2273.35	14.2839
2276.2	13.927
2279.04	14.4833
2281.89	14.5242
2284.73	13.9801
2287.57	13.9087
2290.41	12.4673
2293.25	11.184
2296.09	11.2736
2298.93	11.0275
2301.76	11.5089
2304.6	11.7714
2307.44	12.3835
2310.27	12.7762
2313.1	12.5722
2315.93	12.581
2318.76	12.6007
2321.59	12.4271
2324.42	12.6105
2327.25	12.5174
2330.07	11.7005
2332.9	10.8996
2335.72	10.2312
2338.55	9.94068
2341.37	9.59065
2344.19	9.17614
2347.01	7.95549
2349.83	7.43058
2352.65	6.18007
2355.46	4.59817
2358.28	3.18231
2361.09	2.59425
2363.91	2.76009
2366.72	2.95647
2369.53	2.86005
2372.34	2.3006
2375.15	2.86132
2377.96	3.16365
2380.77	3.95254
2383.58	4.25363
2386.38	3.93089
2389.19	3.37976
2391.99	3.54971
2394.8	3.24733
2397.6	2.67487
2400.4	2.24017
2403.2	2.42408
2406	2.69009
2408.79	3.2336
2411.59	3.32141
2414.39	4.11682
2417.18	4.19875
2419.98	4.12253
2422.77	4.08174
2425.56	3.8856
2428.35	3.93233
2431.14	4.34918
2433.93	3.95418
2436.72	3.84082
2439.5	4.52907
2442.29	4.95079
2445.07	5.33154
2447.86	5.83086
2450.64	5.58399
2453.42	4.89266
2456.2	4.24546
2458.98	4.66711
2461.76	4.06863
2464.54	4.40941
2467.32	4.04492
2470.09	3.96186
2472.87	4.20489
2475.64	4.48986
2478.41	4.59253
2481.18	4.54221
2483.95	4.51711
2486.72	3.98886
2489.49	2.78343
2492.26	1.80978
2495.03	1.20366
2497.79	1.20394
2500.56	0.786689
2503.32	1.42346
2506.09	1.54166
2508.85	1.87819
2511.61	2.19177
2514.37	2.10631
2517.13	1.84412
2519.89	1.95097
2522.64	1.70752
2525.4	1.62771
2528.15	1.44898
2530.91	1.92715
2533.66	2.39219
2536.41	2.69775
2539.16	2.41766
2541.91	2.55533
2544.66	2.4723
2547.41	1.67677
2550.16	1.63076
2552.9	1.11171
2555.65	0.872475
2558.39	0.540116
2561.13	1.35606
2563.88	1.78112
2566.62	1.65652
2569.36	2.64691
2572.1	3.53557
2574.84	3.94354
2577.57	3.93759
2580.31	4.01244
2583.05	3.66283
2585.78	3.82636
2588.51	3.84912
2591.24	3.88643
2593.98	4.04193
2596.71	4.55069
2599.44	4.35313
2602.16	4.49461
2604.89	4.23585
2607.62	3.6953
2610.34	4.37069
2613.07	3.47001
2615.79	2.97169
2618.52	3.44192
2621.24	3.86178
2623.96	3.7468
2626.68	3.94924
2629.4	4.11518
2632.11	3.92983
2634.83	3.54028
2637.55	3.43101
2640.26	3.04979
2642.98	2.21611
2645.69	0.933776
2648.4	0.57538
2651.11	0.656762
2653.82	0.784567
2656.53	0.520893
2659.24	0.411543
2661.95	0.448849
2664.65	0.733054
2667.36	1.104
2670.06	1.14674
2672.76	0.880266
2675.47	1.07914
2678.17	0.983894
2680.87	1.00732
2683.57	1.14353
2686.27	1.26542
2688.97	1.74809
2691.66	2.25162
2694.36	3.02446
2697.05	2.96666
2699.75	2.81214
2702.44	2.897
2705.13	3.22443
2707.82	3.53612
2710.51	3.14421
2713.2	3.97885
2715.89	5.34532
2718.57	5.81642
2721.26	6.07754
2723.95	6.18429
2726.63	5.96664
2729.31	5.55606
2732	5.44481
2734.68	4.94575
2737.36	4.61158
2740.04	4.4325
2742.72	3.34121
2745.39	3.93581
2748.07	3.63091
2750.75	3.69519
2753.42	4.11527
2756.09	4.39865
2758.77	4.56459
2761.44	4.3724
2764.11	3.68967
2766.78	3.72718
2769.45	4.20226
2772.12	4.17517
2774.78	4.0804
2777.45	4.88017
2780.12	4.93773
2782.78	4.88434
2785.44	4.64161
2788.11	4.32809
2790.77	4.55319
2793.43	5.06423
2796.09	5.13373
2798.75	4.98075
2801.4	5.12053
2804.06	5.50079
2806.72	4.77609
2809.37	4.07923
2812.03	3.86616
2814.68	3.07741
2817.33	3.3419
2819.98	4.59131
2822.63	4.66932
2825.28	5.28994
2827.93	6.6916
2830.58	8.58867
2833.23	11.4183
2835.87	13.2822
2838.52	16.456
2841.16	18.2953
2843.8	22.4746
2846.44	25.5109
2849.08	29.9786
2851.73	34.5192
2854.36	39.4063
2857	43.6774
2859.64	47.7692
2862.28	51.3366
2864.91	55.5539
2867.55	58.7905
2870.18	61.5656
2872.81	64.3536
2875.44	67.1201
2878.07	69.1421
2880.7	71.6302
2883.33	74.3993
2885.96	76.9676
2888.59	79.8726
2891.21	82.1453
2893.84	84.7457
2896.46	87.1194
2899.09	89.2867
2901.71	93.3996
2904.33	97.3169
2906.95	101.994
2909.57	108.218
2912.19	113.621
2914.81	119.517
2917.43	124.95
2920.04	129.495
2922.66	133.413
2925.27	136.792
2927.88	139.224
2930.5	141.236
2933.11	142.926
2935.72	143.013
2938.33	141.817
2940.94	138.923
2943.54	135.677
2946.15	132.216
2948.76	129.312
2951.36	123.685
2953.97	119.356
2956.57	113.646
2959.17	108.868
2961.77	103.441
2964.37	98.995
2966.97	95.2641
2969.57	91.0753
2972.17	86.9144
2974.77	83.724
2977.36	79.5176
2979.96	75.2704
2982.55	70.8347
2985.15	65.83
2987.74	61.1809
2990.33	56.6868
2992.92	52.5969
2995.51	48.6012
2998.1	44.0468
3000.69	39.8053
3003.27	36.6007
3005.86	33.1919
3008.44	30.9998
3011.03	27.6462
3013.61	24.9303
3016.19	22.9824
3018.78	21.502
3021.36	19.6809
3023.94	18.2741
3026.51	16.8241
3029.09	15.9144
3031.67	15.9106
3034.24	15.6796
3036.82	16.2923
3039.39	16.4154
3041.97	16.5128
3044.54	17.3318
3047.11	17.4738
3049.68	17.3906
3052.25	17.0497
3054.82	16.6514
3057.39	16.6289
3059.96	16.0177
3062.52	15.6163
3065.09	14.8129
3067.65	14.5847
3070.22	13.2701
3072.78	11.9741
3075.34	11.0182
3077.9	10.1745
3080.46	8.28931
3083.02	7.04582
3085.58	5.66708
3088.14	4.69858
3090.69	4.3796
3093.25	3.89522
3095.8	4.63667
3098.36	4.54968
3100.91	4.06412
3103.46	3.99743
3106.01	4.09964
3108.56	3.74371
3111.11	3.50526
3113.66	3.19151
3116.21	2.7029
3118.76	2.41808
3121.3	2.11072
3123.85	1.79599
3126.39	1.54313
3128.93	1.92224
3131.48	1.55689
3134.02	0.844123
3136.56	0.475599
3139.1	0.225596
3141.64	0.152482
3144.17	0.363975
3146.71	0.954631
3149.25	1.84722