File: data/Raman/poly_smoothed/Thy_30_10_43_1x_45s_532 nm_x100_100%_600 gr_mm_01.txt
#Acq. time (s)=	45
#Accumulations=	2
#Range (cm-¹)=	200...3150
#Windows=	2
#Auto scanning=	Off
#Autofocus=	Off
#Macrospot=	Off
#AutoExposure=	Off
#Spike filter=	Multiple accum.
#Delay time (s)=	0
#Binning=	1
#Readout mode=	Signal
#DeNoise=	Off
#ICS correction=	On
#Dark correction=	Off
#Inst. Process=	Off
#Detector Gain=	Best Dynamic Range
#Detector ADC=	20 kHz
#Detector temperature (°C)=	-69.85
#Instrument=	LabRAM HR Evol
#Detector=	Synapse
#Objective=	x100
#Grating=	600 gr/mm
#ND Filter=	100%
#Laser (nm)=	532
#Hole=	100.021
#Range=	Auto
#Laser Pol.=	No
#Raman. Pol.=	No
#Laser Pol. (°)=	-0.0007625
#Raman Pol. (°)=	89.9995
#Collection=	Microscope
#StageXY=	Marzhauser
#StageZ=	Marzhauser
#X (µm)=	4715.5
#Y (µm)=	-7713.6
#Z (µm)=	584.4
#Full time(mm:ss)=	3:18
#Project=
#Sample=
#Site=
#Title=	Thy_30_10_43_2x_45s_532 nm_x100_100%_600 gr_mm
#Remark=
#Date=	30.06.2022 14:30
#Acquired=	30.06.2022 14:30:41
#Base:Fit=	10.08.2022 09:58:11
#Base:Sub=	10.08.2022 09:58:44
#Filter:Polynom=	16.08.2022 10:22:53
#AxisType[0]=Intens
#AxisUnit[0]=Cnt
#AxisType[1]=Spectr
#AxisUnit[1]=1/cm
200.533	19.7554
204.162	18.0456
207.792	16.0492
211.418	13.5491
215.044	11.1306
218.667	8.55375
222.289	7.94224
225.912	6.22905
229.531	5.20991
233.148	2.80505
236.766	2.81975
240.381	1.88372
243.994	1.69772
247.606	0.536245
251.217	0.303382
254.828	0.747027
258.436	1.57756
262.042	2.20373
265.647	2.00246
269.25	3.00096
272.852	3.00175
276.453	3.62834
280.052	4.30288
283.65	5.68568
287.247	6.23967
290.842	7.85604
294.436	8.29154
298.028	9.03894
301.617	9.54604
305.206	9.52375
308.794	10.5357
312.381	8.49058
315.964	7.75176
319.548	8.33359
323.131	8.23075
326.71	8.3386
330.29	6.49839
333.868	6.51727
337.443	6.97851
341.018	6.89647
344.591	6.52364
348.163	7.18479
351.733	6.67022
355.303	7.53247
358.869	7.00442
362.435	7.35307
366.001	7.81992
369.563	7.70036
373.124	8.84383
376.686	9.58387
380.244	8.35335
383.801	9.08382
387.357	9.26537
390.911	7.99698
394.466	6.80607
398.018	6.20049
401.568	6.90559
405.117	7.97247
408.664	8.42988
412.21	9.32649
415.755	7.82213
419.298	7.3916
422.84	7.91284
426.38	7.48041
429.919	6.78449
433.455	7.61119
436.992	8.3564
440.527	7.57317
444.06	6.84339
447.593	6.66184
451.122	7.08463
454.651	5.94991
458.18	5.82659
461.705	7.15207
465.23	6.90297
468.752	7.04193
472.275	7.43927
475.797	7.80891
479.315	7.78693
482.834	9.28344
486.349	10.5697
489.863	11.4259
493.378	13.1933
496.889	14.894
500.401	16.0469
503.91	15.0502
507.417	16.918
510.923	17.7872
514.43	18.3595
517.933	19.5637
521.435	20.6975
524.936	20.3337
528.435	19.647
531.933	20.3295
535.43	19.4868
538.927	18.9958
542.421	17.9571
545.913	17.0841
549.403	15.2978
552.893	13.5322
556.381	12.5768
559.868	11.6743
563.354	11.0883
566.839	10.9349
570.322	10.6475
573.802	9.04106
577.283	7.94721
580.762	7.68316
584.24	6.77024
587.714	5.43022
591.19	5.18394
594.663	5.7836
598.134	5.87606
601.605	7.05159
605.073	9.28266
608.542	9.22985
612.007	11.2506
615.473	13.5284
618.936	14.3548
622.397	15.0918
625.859	14.1008
629.318	16.0278
632.775	17.9469
636.233	19.9242
639.688	22.7619
643.142	23.8566
646.594	25.7125
650.045	26.3478
653.496	27.1981
656.944	27.1196
660.391	27.875
663.837	27.7512
667.281	28.237
670.724	28.1012
674.166	28.8256
677.606	30.765
681.045	31.8181
684.483	33.1769
687.917	35.0095
691.352	36.9063
694.786	38.637
698.219	40.4765
701.65	41.1304
705.078	41.6229
708.506	43.415
711.934	43.8552
715.358	45.9501
718.782	46.3817
722.204	47.6344
725.626	48.4541
729.045	48.5772
732.464	49.2808
735.881	51.201
739.297	51.3418
742.711	53.3557
746.125	55.4544
749.537	56.7616
752.946	58.2893
756.357	60.5176
759.764	62.5696
763.17	65.5428
766.575	67.5575
769.978	69.6368
773.382	71.811
776.783	74.1267
780.182	76.2824
783.581	77.8972
786.978	78.2857
790.373	79.4718
793.768	81.7099
797.161	83.8567
800.552	85.0862
803.941	85.1467
807.33	84.4192
810.718	83.7291
814.105	82.9621
817.49	82.7954
820.873	84.0283
824.256	84.4086
827.637	85.8704
831.016	85.7506
834.395	83.5585
837.772	81.9191
841.147	81.1591
844.522	79.4516
847.894	77.5883
851.267	75.9108
854.637	72.6495
858.007	70.9262
861.374	68.805
864.739	68.22
868.106	66.9265
871.469	67.2745
874.831	66.4771
878.193	64.5155
881.553	63.8049
884.911	61.3138
888.268	58.8981
891.623	58.4999
894.978	57.3698
898.331	56.671
901.683	57.5084
905.033	57.9003
908.383	57.3319
911.731	57.5191
915.078	56.3279
918.423	54.5253
921.768	54.5292
925.111	52.8666
928.452	51.4041
931.791	51.1332
935.13	49.5227
938.468	48.1665
941.803	49.4764
945.139	48.774
948.473	49.4492
951.804	48.9144
955.136	48.7198
958.465	48.04
961.794	45.5407
965.12	45.1808
968.447	45.4229
971.771	46.6359
975.095	46.8989
978.417	46.8821
981.737	48.708
985.057	50.4348
988.375	51.2713
991.691	51.4709
995.006	52.0868
998.32	51.4406
1001.63	50.7798
1004.95	50.1974
1008.26	49.4785
1011.56	48.243
1014.87	47.3683
1018.18	46.4383
1021.48	44.4646
1024.79	43.7636
1028.09	42.3884
1031.39	42.0511
1034.69	39.9376
1037.99	38.4936
1041.29	36.8642
1044.58	35.4509
1047.88	35.0901
1051.17	34.8812
1054.46	33.9515
1057.75	32.6373
1061.04	32.6075
1064.33	32.5543
1067.62	32.1121
1070.9	32.1435
1074.19	33.4255
1077.47	34.3863
1080.76	33.6854
1084.04	33.0602
1087.32	32.9996
1090.59	32.9669
1093.87	32.4508
1097.15	32.1641
1100.42	32.4124
1103.69	32.7237
1106.97	33.8872
1110.24	34.5571
1113.51	33.4741
1116.77	33.8149
1120.04	32.9919
1123.31	31.0257
1126.57	29.09
1129.83	27.201
1133.1	25.4394
1136.36	23.397
1139.62	22.2832
1142.87	20.908
1146.13	17.8606
1149.38	16.2694
1152.64	14.1351
1155.89	12.4801
1159.14	10.0531
1162.39	9.41657
1165.64	6.69445
1168.89	5.94794
1172.14	4.84909
1175.38	7.10835
1178.63	6.86254
1181.87	8.17097
1185.11	9.71717
1188.35	12.0859
1191.59	12.9222
1194.83	13.8093
1198.07	15.8125
1201.3	16.81
1204.53	18.9122
1207.77	21.1235
1211	24.264
1214.23	28.3512
1217.46	32.0768
1220.69	35.4224
1223.91	37.8187
1227.14	39.8607
1230.36	43.8116
1233.59	45.4566
1236.81	47.5985
1240.03	49.8918
1243.25	52.0325
1246.46	54.3593
1249.68	56.3846
1252.9	57.5314
1256.11	58.6261
1259.32	59.303
1262.54	61.371
1265.75	62.7604
1268.96	64.2924
1272.16	64.1006
1275.37	64.3272
1278.57	64.5107
1281.78	64.7949
1284.98	66.0048
1288.18	68.326
1291.38	69.1672
1294.58	69.7409
1297.78	70.2965
1300.98	69.943
1304.17	68.2435
1307.37	66.8999
1310.56	66.1146
1313.76	64.909
1316.95	64.7833
1320.14	64.1687
1323.32	64.0121
1326.51	62.4798
1329.7	60.1447
1332.88	59.037
1336.07	58.0438
1339.25	56.915
1342.43	56.0922
1345.61	54.6382
1348.79	53.1992
1351.96	49.805
1355.14	47.4173
1358.31	46.1023
1361.49	44.3811
1364.66	42.5679
1367.83	40.6217
1371	38.8902
1374.17	37.7943
1377.34	35.5527
1380.5	35.068
1383.67	32.4121
1386.83	31.7916
1390	31.5276
1393.16	31.4604
1396.32	29.7976
1399.48	29.4398
1402.64	28.5972
1405.79	27.5722
1408.95	28.4781
1412.1	28.5457
1415.26	29.8702
1418.41	31.993
1421.56	34.8793
1424.71	37.244
1427.86	41.9186
1431	45.7351
1434.15	51.7738
1437.29	56.3436
1440.44	59.93
1443.58	63.1496
1446.72	67.0852
1449.86	67.3513
1453	67.1281
1456.14	66.4282
1459.27	64.2673
1462.41	61.1584
1465.54	57.756
1468.67	52.6927
1471.81	46.0367
1474.94	40.5945
1478.07	35.113
1481.19	29.9067
1484.32	24.9396
1487.45	21.6821
1490.57	17.5239
1493.69	14.484
1496.82	12.4319
1499.94	10.4786
1503.06	8.45008
1506.17	7.35145
1509.29	8.29406
1512.41	8.75793
1515.52	8.93857
1518.64	8.09066
1521.75	9.15887
1524.86	9.43992
1527.97	8.47475
1531.08	10.0016
1534.19	10.7365
1537.29	12.9349
1540.4	13.6306
1543.5	15.5513
1546.61	17.7494
1549.71	21.1255
1552.81	23.9348
1555.91	27.0743
1559.01	30.4438
1562.11	32.9801
1565.2	34.2927
1568.29	36.5384
1571.39	39.1614
1574.48	39.5696
1577.57	40.2909
1580.66	41.8413
1583.75	45.6559
1586.84	47.7232
1589.93	47.2548
1593.01	47.6442
1596.1	48.8405
1599.18	49.4776
1602.26	47.9187
1605.34	47.2886
1608.42	46.6679
1611.5	47.0228
1614.58	46.8175
1617.65	46.4402
1620.73	48.0394
1623.8	50.2309
1626.87	51.8495
1629.95	52.5932
1633.02	53.8779
1636.09	55.8986
1639.15	57.3924
1642.22	60.4135
1645.29	63.4119
1648.35	65.7571
1651.42	68.308
1654.48	71.2113
1657.54	73.3658
1660.6	73.8914
1663.66	71.5612
1666.72	69.652
1669.77	67.6534
1672.83	65.5475
1675.88	61.1612
1678.93	55.5648
1681.99	49.62
1685.04	43.9658
1688.09	38.4095
1691.13	33.2504
1694.18	27.553
1697.23	22.9717
1700.27	17.7103
1703.32	13.6991
1706.36	8.49874
1709.4	4.12503
1712.44	2.30546
1715.48	0.78524
1718.52	0.607192
1721.56	-0.400992
1724.59	0.391584
1727.63	1.58479
1730.66	1.50797
1733.69	2.0736
1736.72	1.81324
1739.75	2.27298
1742.78	2.1196
1745.81	2.46588
1748.84	3.15448
1751.86	2.07579
1754.89	1.78785
1757.91	1.29731
1760.93	1.2833
1763.95	0.898274
1766.97	1.17102
1769.99	0.634021
1773.01	0.0377592
1776.03	-1.08655
1779.04	-1.44718
1782.06	-1.97739
1785.07	-1.47968
1788.08	-0.121491
1791.09	0.382122
1794.1	0.926632
1797.11	1.05182
1800.12	1.59971
1803.12	2.03626
1806.13	2.4719
1809.13	2.80108
1812.14	3.08546
1815.14	3.20656
1818.14	3.96229
1821.14	4.02292
1824.14	4.37642
1827.13	4.67897
1830.13	4.99356
1833.12	4.92405
1836.12	4.9018
1839.11	5.30062
1842.1	6.24904
1845.09	6.185
1848.08	6.31832
1851.07	6.52851
1854.06	7.14467
1857.04	8.20357
1860.03	7.77253
1863.01	8.80701
1866	8.90119
1868.98	8.2735
1871.96	8.81553
1874.94	9.80153
1877.92	10.802
1880.89	11.4756
1882.48	12.7222
1885.47	13.4395
1888.46	14.0549
1891.44	13.9028
1894.43	14.9042
1897.41	15.6382
1900.4	15.3392
1903.38	15.3213
1906.36	14.5005
1909.34	13.8576
1912.32	14.166
1915.29	14.2029
1918.27	13.3805
1921.25	12.8097
1924.22	12.2584
1927.2	11.965
1930.17	11.2886
1933.14	10.444
1936.11	10.4422
1939.08	10.2719
1942.05	10.7026
1945.01	10.7047
1947.98	10.5464
1950.94	11.1617
1953.91	11.3203
1956.87	10.7938
1959.83	11.0434
1962.79	10.6743
1965.75	11.3025
1968.71	12.1791
1971.67	11.0834
1974.62	10.1073
1977.58	9.92741
1980.53	9.53822
1983.48	9.43898
1986.43	9.61032
1989.38	10.0463
1992.33	10.7138
1995.28	11.5838
1998.23	12.0888
2001.18	12.2194
2004.12	13.2747
2007.06	13.3309
2010.01	14.8799
2012.95	15.7151
2015.89	15.2496
2018.83	15.7302
2021.77	16.0756
2024.71	16.5693
2027.64	16.4766
2030.58	17.5145
2033.51	18.0253
2036.45	17.8363
2039.38	18.1304
2042.31	18.8167
2045.24	18.1662
2048.17	17.7245
2051.1	18.3714
2054.02	17.7963
2056.95	18.4427
2059.87	19.4899
2062.8	20.1314
2065.72	20.4703
2068.64	20.6791
2071.56	19.9464
2074.48	20.4185
2077.4	20.2667
2080.31	20.8655
2083.23	20.7734
2086.14	20.4144
2089.06	21.5456
2091.97	23.182
2094.88	24.0343
2097.79	25.4849
2100.7	25.7801
2103.61	27.025
2106.52	28.4687
2109.43	30.0869
2112.33	31.8369
2115.24	32.7699
2118.14	34.6335
2121.04	37.1724
2123.94	40.3109
2126.84	43.3771
2129.74	46.1148
2132.64	48.69
2135.54	51.6089
2138.43	55.2692
2141.33	57.8825
2144.22	60.0026
2147.11	63.3552
2150.01	65.8265
2152.9	68.8563
2155.79	71.4082
2158.67	73.7989
2161.56	75.9702
2164.45	77.4788
2167.33	79.5856
2170.22	80.2079
2173.1	81.0353
2175.98	81.014
2178.86	80.4156
2181.74	79.4994
2184.62	77.7227
2187.5	75.3545
2190.38	73.6648
2193.25	71.3212
2196.13	68.0074
2199	65.1746
2201.88	62.9378
2204.75	59.6676
2207.62	57.0617
2210.49	54.3582
2213.36	49.9504
2216.22	47.8556
2219.09	45.8101
2221.96	43.2008
2224.82	41.06
2227.68	38.7437
2230.55	37.4819
2233.41	36.2852
2236.27	35.6956
2239.12	34.4438
2241.98	33.3329
2244.84	31.365
2247.7	30.3042
2250.55	29.9214
2253.41	28.2411
2256.26	26.806
2259.11	25.5647
2261.96	24.4546
2264.81	24.0022
2267.66	23.2432
2270.51	22.3486
2273.35	19.9339
2276.2	18.403
2279.04	17.1089
2281.89	16.0164
2284.73	15.014
2287.57	15.1041
2290.41	13.2601
2293.25	11.4441
2296.09	11.7706
2298.93	12.2457
2301.76	12.3242
2304.6	12.0102
2307.44	11.583
2310.27	11.3528
2313.1	10.238
2315.93	11.03
2318.76	11.5081
2321.59	11.4133
2324.42	11.8325
2327.25	11.5902
2330.07	10.4402
2332.9	10.5605
2335.72	10.4605
2338.55	9.0107
2341.37	8.82961
2344.19	8.5022
2347.01	8.60619
2349.83	7.50608
2352.65	7.4894
2355.46	6.37516
2358.28	5.66737
2361.09	5.2037
2363.91	5.7807
2366.72	5.55508
2369.53	5.3334
2372.34	5.20511
2375.15	3.4364
2377.96	3.19137
2380.77	3.01192
2383.58	3.37116
2386.38	3.4701
2389.19	3.56018
2391.99	4.04872
2394.8	4.53222
2397.6	4.2837
2400.4	4.83176
2403.2	4.95511
2406	4.88586
2408.79	5.97373
2411.59	6.68499
2414.39	6.46697
2417.18	6.03269
2419.98	6.53802
2422.77	6.18007
2425.56	5.51694
2428.35	5.01242
2431.14	4.16961
2433.93	3.87477
2436.72	3.99582
2439.5	4.22504
2442.29	2.90323
2445.07	2.84345
2447.86	2.5912
2450.64	2.14509
2453.42	2.07167
2456.2	1.91861
2458.98	2.40062
2461.76	3.51451
2464.54	3.26078
2467.32	2.71511
2470.09	3.09074
2472.87	3.15512
2475.64	3.5374
2478.41	4.30355
2481.18	5.1722
2483.95	4.51256
2486.72	4.25549
2489.49	4.03525
2492.26	3.79121
2495.03	3.29649
2497.79	2.56465
2500.56	3.39384
2503.32	3.40179
2506.09	2.68542
2508.85	2.12789
2511.61	1.76103
2514.37	2.02877
2517.13	0.986115
2519.89	-0.370746
2522.64	-0.261652
2525.4	0.111238
2528.15	0.15884
2530.91	-0.277568
2533.66	-0.813662
2536.41	-0.632904
2539.16	0.176933
2541.91	0.334077
2544.66	0.470184
2547.41	0.553814
2550.16	0.587165
2552.9	-0.130202
2555.65	0.299387
2558.39	1.56743
2561.13	2.03996
2563.88	2.32159
2566.62	4.06215
2569.36	4.39909
2572.1	4.00911
2574.84	3.11794
2577.57	2.5884
2580.31	2.83082
2583.05	2.32869
2585.78	1.55422
2588.51	1.32348
2591.24	0.677061
2593.98	0.062272
2596.71	-1.06079
2599.44	-2.04649
2602.16	-2.30289
2604.89	-2.89274
2607.62	-2.97739
2610.34	-3.1737
2613.07	-3.3666
2615.79	-2.88527
2618.52	-2.09496
2621.24	-1.80065
2623.96	-1.2056
2626.68	-0.331059
2629.4	-0.0940817
2632.11	0.560724
2634.83	0.523812
2637.55	1.21072
2640.26	1.52739
2642.98	1.9132
2645.69	3.12845
2648.4	3.74656
2651.11	3.29354
2653.82	3.77835
2656.53	3.93968
2659.24	4.62631
2661.95	4.33865
2664.65	5.59632
2667.36	6.20536
2670.06	6.80403
2672.76	7.80504
2675.47	7.74581
2678.17	7.26434
2680.87	6.63328
2683.57	6.53844
2686.27	6.03214
2688.97	5.83584
2691.66	5.77462
2694.36	5.0239
2697.05	5.23977
2699.75	6.1418
2702.44	6.85
2705.13	7.33501
2707.82	7.63699
2710.51	7.93802
2713.2	8.2326
2715.89	8.85831
2718.57	9.50813
2721.26	10.0202
2723.95	11.248
2726.63	10.9667
2729.31	10.6121
2732	10.9785
2734.68	11.0231
2737.36	10.5006
2740.04	10.2863
2742.72	9.87081
2745.39	9.27866
2748.07	8.83264
2750.75	8.68531
2753.42	8.37674
2756.09	8.57215
2758.77	8.38933
2761.44	9.00305
2764.11	9.62612
2766.78	9.29754
2769.45	9.00216
2772.12	8.74302
2774.78	8.70386
2777.45	8.97661
2780.12	8.52725
2782.78	7.85677
2785.44	7.7863
2788.11	7.85555
2790.77	7.16188
2793.43	6.12795
2796.09	5.84566
2798.75	6.29153
2801.4	6.14165
2804.06	6.18192
2806.72	6.07256
2809.37	5.88434
2812.03	6.343
2814.68	7.1616
2817.33	7.76819
2819.98	8.98141
2822.63	11.5869
2825.28	13.9901
2827.93	17.5694
2830.58	20.8521
2833.23	24.6956
2835.87	27.3948
2838.52	31.7954
2841.16	37.3588
2843.8	43.0773
2846.44	49.1069
2849.08	56.4284
2851.73	64.0286
2854.36	71.8793
2857	79.4275
2859.64	87.0107
2862.28	95.0056
2864.91	101.765
2867.55	107.895
2870.18	113.809
2872.81	118.191
2875.44	123.777
2878.07	129.191
2880.7	133.95
2883.33	138.568
2885.96	143.435
2888.59	148.489
2891.21	153.08
2893.84	157.417
2896.46	161.77
2899.09	166.469
2901.71	172.921
2904.33	180.78
2906.95	188.581
2909.57	197.82
2912.19	206.899
2914.81	216.112
2917.43	224.894
2920.04	232.671
2922.66	238.904
2925.27	243.562
2927.88	246.107
2930.5	246.401
2933.11	246.574
2935.72	245.344
2938.33	242.822
2940.94	238.887
2943.54	233.808
2946.15	228.108
2948.76	220.932
2951.36	213.733
2953.97	206.64
2956.57	197.979
2959.17	189.823
2961.77	181.791
2964.37	174.585
2966.97	168.457
2969.57	162.54
2972.17	155.963
2974.77	149.717
2977.36	142.454
2979.96	134.998
2982.55	127.463
2985.15	119.503
2987.74	111.677
2990.33	102.678
2992.92	94.1014
2995.51	85.8536
2998.1	78.0275
3000.69	70.426
3003.27	63.5869
3005.86	57.0809
3008.44	51.8821
3011.03	47.7562
3013.61	42.1261
3016.19	38.8139
3018.78	36.2562
3021.36	33.3883
3023.94	31.8458
3026.51	30.764
3029.09	30.6838
3031.67	31.5606
3034.24	31.7861
3036.82	31.9988
3039.39	32.3988
3041.97	32.5673
3044.54	34.0871
3047.11	34.5231
3049.68	35.3368
3052.25	35.1424
3054.82	34.4053
3057.39	33.7305
3059.96	32.7944
3062.52	31.072
3065.09	30.3353
3067.65	28.4842
3070.22	26.4437
3072.78	25.3082
3075.34	23.3125
3077.9	21.344
3080.46	20.1764
3083.02	18.3008
3085.58	15.8275
3088.14	14.7742
3090.69	14.2019
3093.25	13.6219
3095.8	13.9225
3098.36	13.6556
3100.91	13.3362
3103.46	13.2944
3106.01	12.9546
3108.56	12.5394
3111.11	11.08
3113.66	10.6253
3116.21	9.50467
3118.76	8.34394
3121.3	8.32731
3123.85	7.21892
3126.39	7.17679
3128.93	6.58427
3131.48	6.11626
3134.02	5.87517
3136.56	5.2731
3139.1	5.11806
3141.64	5.57776
3144.17	7.10785
3146.71	10.2906
3149.25	14.947