File: data/Raman/poly_smoothed/Thy_40_11_43_1x_45s_532 nm_x100_100%_600 gr_mm_01.txt
#Acq. time (s)=	45
#Accumulations=	2
#Range (cm-¹)=	200...3150
#Windows=	2
#Auto scanning=	Off
#Autofocus=	Off
#Macrospot=	Off
#AutoExposure=	Off
#Spike filter=	Multiple accum.
#Delay time (s)=	0
#Binning=	1
#Readout mode=	Signal
#DeNoise=	Off
#ICS correction=	On
#Dark correction=	Off
#Inst. Process=	Off
#Detector Gain=	Best Dynamic Range
#Detector ADC=	20 kHz
#Detector temperature (°C)=	-69.85
#Instrument=	LabRAM HR Evol
#Detector=	Synapse
#Objective=	x100
#Grating=	600 gr/mm
#ND Filter=	100%
#Laser (nm)=	532
#Hole=	100.021
#Range=	Auto
#Laser Pol.=	No
#Raman. Pol.=	No
#Laser Pol. (°)=	-0.0007625
#Raman Pol. (°)=	89.9995
#Collection=	Microscope
#StageXY=	Marzhauser
#StageZ=	Marzhauser
#X (µm)=	254.7
#Y (µm)=	1682.1
#Z (µm)=	426.4
#Full time(mm:ss)=	3:19
#Project=
#Sample=
#Site=
#Title=	Thy_40_11_43_2x_45s_532 nm_x100_100%_600 gr_mm
#Remark=
#Date=	05.07.2022 13:03
#Acquired=	05.07.2022 13:03:16
#Base:Fit=	10.08.2022 10:01:35
#Base:Sub=	10.08.2022 10:01:52
#Filter:Polynom=	16.08.2022 10:21:53
#AxisType[0]=Intens
#AxisUnit[0]=Cnt
#AxisType[1]=Spectr
#AxisUnit[1]=1/cm
200.43	-1.07693
204.059	0.585689
207.688	2.39702
211.314	3.93568
214.941	4.32427
218.564	4.5997
222.186	4.75107
225.809	5.94174
229.428	5.71195
233.045	4.96147
236.663	5.18562
240.278	6.16678
243.891	7.43078
247.503	7.7643
251.116	7.77965
254.725	9.16188
258.333	10.609
261.939	10.083
265.544	8.23487
269.148	7.64566
272.75	6.90964
276.351	6.41187
279.95	7.45443
283.548	7.34307
287.144	8.53442
290.739	7.69041
294.333	8.63783
297.925	8.75826
301.514	8.46623
305.104	9.45115
308.692	11.1585
312.279	11.6092
315.862	10.4192
319.446	10.1884
323.029	11.2684
326.608	12.7312
330.188	15.0086
333.766	14.4288
337.341	13.5093
340.917	13.4982
344.489	13.6056
348.062	12.1944
351.631	10.0209
355.201	8.33149
358.768	8.15668
362.333	8.13514
365.899	8.94168
369.462	8.8284
373.023	9.92775
376.585	8.79439
380.143	8.68374
383.7	8.84721
387.256	8.78861
390.812	8.40787
394.365	8.27942
397.916	7.18698
401.467	6.35047
405.015	5.59651
408.563	6.63617
412.109	7.30797
415.654	6.91289
419.197	5.88681
422.739	4.47918
426.279	5.81774
429.819	5.76199
433.356	5.96401
436.891	5.29079
440.426	5.17043
443.96	5.28074
447.492	7.73025
451.021	7.233
454.551	8.76191
458.079	10.2753
461.604	11.6921
465.13	11.0555
468.654	12.2118
472.175	13.4032
475.696	14.6551
479.215	15.912
482.733	16.9656
486.249	18.2888
489.765	20.7545
493.278	20.6953
496.789	22.7867
500.301	23.5743
503.81	24.4874
507.317	25.4105
510.825	25.5747
514.33	25.6739
517.833	24.92
521.335	22.7704
524.836	21.8531
528.335	21.6442
531.835	20.4123
535.332	18.7564
538.827	17.5553
542.321	16.5859
545.814	15.6191
549.305	14.9911
552.795	14.8704
556.282	14.2571
559.769	12.9942
563.255	12.0777
566.739	12.7033
570.223	12.0493
573.705	12.1845
577.183	13.104
580.663	11.9295
584.141	12.8835
587.615	11.4051
591.09	10.1887
594.564	9.01229
598.035	7.98905
601.506	6.90272
604.974	6.03297
608.443	6.66728
611.908	8.40658
615.374	8.72969
618.837	8.80902
622.3	11.1395
625.761	11.9441
629.219	13.3342
632.677	15.2761
636.135	17.1076
639.59	19.2203
643.043	18.8394
646.495	19.3617
649.948	22.3358
653.398	22.439
656.846	23.9777
660.293	24.4399
663.738	25.2632
667.183	24.5511
670.626	25.2235
674.067	26.1747
677.508	25.993
680.947	27.5595
684.385	29.1175
687.821	31.2478
691.254	34.3085
694.688	37.4682
698.121	40.7717
701.552	42.8656
704.98	44.4961
708.409	47.1641
711.836	47.4944
715.26	49.5765
718.685	51.8176
722.108	52.9819
725.528	52.5337
728.949	51.5734
732.367	52.023
735.785	52.5201
739.2	52.8388
742.614	54.6789
746.028	55.4601
749.439	57.1805
752.849	59.3837
756.26	60.8665
759.667	63.7461
763.073	64.5853
766.477	67.0709
769.883	69.1135
773.285	71.3673
776.686	74.0001
780.085	76.2816
783.484	78.2308
786.881	81.6332
790.276	85.1903
793.671	88.5864
797.064	91.0821
800.456	92.7291
803.846	93.5666
807.234	94.1983
810.622	94.9152
814.008	94.3351
817.394	94.7231
820.778	94.3888
824.159	93.4465
827.541	92.5836
830.921	90.1841
834.298	87.1727
837.676	83.3914
841.051	79.8086
844.426	76.4725
847.798	72.4934
851.171	70.2084
854.54	66.7169
857.911	64.5791
861.278	63.5549
864.645	61.7678
868.01	60.461
871.373	60.2295
874.735	60.0548
878.097	60.0531
881.457	59.3356
884.815	58.6134
888.172	57.7575
891.528	57.0278
894.882	55.5384
898.237	54.7727
901.589	54.9777
904.94	54.6848
908.289	53.9322
911.635	50.9679
914.982	50.343
918.328	50.7992
921.672	49.422
925.015	48.1856
928.357	48.7324
931.698	46.2182
935.035	45.6206
938.373	44.0686
941.71	43.2641
945.044	42.0411
948.378	39.8972
951.709	39.9014
955.041	41.1895
958.372	39.3057
961.699	39.4429
965.027	39.8753
968.352	40.0963
971.676	40.8457
975	41.6097
978.322	43.1349
981.642	45.4705
984.962	46.034
988.28	46.1946
991.596	46.9858
994.911	46.3863
998.227	47.0984
1001.54	45.7369
1004.85	44.0399
1008.16	44.1682
1011.47	45.0397
1014.78	44.231
1018.08	44.0691
1021.39	43.8228
1024.69	42.5936
1028	41.1663
1031.3	40.4165
1034.6	39.8672
1037.9	37.9292
1041.19	35.5733
1044.49	35.7793
1047.78	34.2856
1051.08	34.1185
1054.37	34.2032
1057.66	32.5015
1060.95	30.785
1064.24	28.7074
1067.53	28.4859
1070.81	27.7468
1074.1	27.2761
1077.38	26.9664
1080.66	26.848
1083.94	28.2897
1087.22	30.0152
1090.5	31.1018
1093.78	32.7872
1097.05	33.195
1100.33	33.2128
1103.6	32.2032
1106.87	32.6151
1110.14	30.6332
1113.41	29.9242
1116.68	28.2461
1119.95	26.4538
1123.21	23.5291
1126.48	21.307
1129.74	19.1422
1133	18.2806
1136.26	15.7991
1139.52	13.5064
1142.78	12.7861
1146.04	12.076
1149.29	10.9345
1152.55	9.6192
1155.8	9.28133
1159.05	7.15102
1162.3	6.39232
1165.55	4.55585
1168.8	4.06658
1172.05	3.65838
1175.29	4.37582
1178.54	4.36533
1181.78	3.71778
1185.02	5.76084
1188.26	6.17301
1191.5	6.89321
1194.74	7.83125
1197.97	8.71701
1201.21	9.28568
1204.44	10.7909
1207.68	13.6178
1210.91	16.371
1214.14	18.6325
1217.37	22.3517
1220.59	27.2919
1223.82	31.6507
1227.05	36.2683
1230.27	39.9671
1233.49	43.3046
1236.72	46.3478
1239.94	47.5526
1243.16	50.5721
1246.37	53.4425
1249.59	55.5563
1252.8	57.8853
1256.02	57.1081
1259.23	60.451
1262.44	64.011
1265.66	66.5931
1268.86	68.548
1272.07	69.8136
1275.28	70.9297
1278.48	72.2251
1281.69	74.4505
1284.89	74.8893
1288.09	76.7225
1291.29	78.54
1294.49	80.8787
1297.69	83.7641
1300.89	84.867
1304.08	85.2009
1307.28	86.9036
1310.47	86.7871
1313.66	86.2454
1316.85	85.062
1320.04	84.7515
1323.23	82.9043
1326.42	79.8251
1329.61	77.0335
1332.79	74.05
1335.97	72.5734
1339.16	72.0401
1342.34	70.7356
1345.52	68.3855
1348.7	65.9544
1351.87	62.2873
1355.05	59.4812
1358.22	56.3317
1361.4	52.8733
1364.57	51.407
1367.74	49.2995
1370.91	46.5056
1374.08	44.0692
1377.25	43.0712
1380.41	40.8956
1383.58	40.1171
1386.74	39.5583
1389.91	37.7146
1393.07	36.5902
1396.23	37.3986
1399.39	36.4922
1402.55	33.4094
1405.7	33.0584
1408.86	32.8352
1412.01	33.2712
1415.17	34.9942
1418.32	37.9411
1421.47	42.1738
1424.62	45.3552
1427.77	49.6006
1430.91	51.7663
1434.06	56.2528
1437.2	59.8848
1440.35	62.9177
1443.49	66.4454
1446.63	68.1818
1449.77	69.4371
1452.91	68.9533
1456.05	67.824
1459.18	65.7743
1462.32	63.4367
1465.45	60.3294
1468.59	56.393
1471.72	51.8024
1474.85	45.1105
1477.98	39.2776
1481.1	34.1095
1484.23	30.227
1487.36	25.1082
1490.48	21.4286
1493.61	20.7351
1496.73	18.4753
1499.85	17.7478
1502.97	17.309
1506.09	17.1349
1509.2	17.1782
1512.32	18.1343
1515.43	18.3866
1518.55	20.2091
1521.66	21.7021
1524.77	22.3011
1527.88	22.7342
1530.99	23.4811
1534.1	25.8099
1537.21	26.9561
1540.31	29.5551
1543.42	31.7038
1546.52	33.5729
1549.62	36.144
1552.72	38.8815
1555.82	41.6601
1558.92	44.3663
1562.02	46.5021
1565.11	48.5745
1568.21	50.8323
1571.3	53.5119
1574.39	55.264
1577.49	57.3428
1580.57	60.0484
1583.66	61.5941
1586.75	62.1995
1589.84	62.1294
1592.92	62.7786
1596.01	63.9855
1599.09	63.8291
1602.17	61.8538
1605.25	62.3472
1608.33	61.054
1611.41	59.6895
1614.49	58.063
1617.57	58.0228
1620.64	58.6847
1623.72	60.0901
1626.79	61.7727
1629.86	63.9961
1632.93	64.841
1636	68.496
1639.07	70.1646
1642.13	72.7674
1645.2	74.686
1648.26	78.3791
1651.33	80.5174
1654.39	81.1945
1657.45	80.3421
1660.51	81.609
1663.57	80.3351
1666.63	79.3372
1669.68	77.9377
1672.74	74.8243
1675.79	69.4363
1678.85	63.5579
1681.9	58.1331
1684.95	50.7153
1688	45.8437
1691.05	41.9943
1694.09	37.6021
1697.14	32.3217
1700.18	28.3738
1703.23	24.3348
1706.27	19.9671
1709.31	17.5032
1712.35	14.4536
1715.39	12.0048
1718.43	10.8234
1721.47	9.41641
1724.5	8.04631
1727.54	6.95356
1730.57	5.39617
1733.61	5.18263
1736.64	5.46238
1739.67	4.47881
1742.7	3.89719
1745.72	3.3607
1748.75	2.62373
1751.77	2.56809
1754.8	1.90198
1757.82	1.68774
1760.84	2.97189
1763.87	3.46865
1766.89	3.73299
1769.91	3.23435
1772.92	2.5953
1775.94	2.64334
1778.95	1.98401
1781.97	1.97319
1784.98	2.79773
1787.99	1.92214
1791.01	1.39389
1794.01	0.785391
1797.02	0.156312
1800.03	0.405805
1803.04	-0.0222633
1806.04	-0.0654113
1809.05	-0.31585
1812.05	-0.092152
1815.05	-0.699742
1818.05	-0.400497
1821.05	0.00927218
1824.05	0.130726
1827.05	-0.0594463
1830.04	0.644467
1833.04	1.96322
1836.03	3.31698
1839.03	3.64639
1842.02	3.68772
1845.01	4.19693
1848	3.85432
1850.99	3.46885
1853.97	3.79931
1856.96	3.84483
1859.94	3.76573
1862.93	3.06339
1865.91	3.18365
1868.89	3.67788
1871.87	4.40406
1874.85	5.45422
1877.83	4.94648
1880.81	5.50175
1882.57	5.68464
1885.56	5.75401
1888.55	6.49825
1891.54	7.35684
1894.52	7.7012
1897.51	7.60331
1900.49	7.73289
1903.47	7.93619
1906.45	7.87353
1909.43	7.46608
1912.41	7.44183
1915.39	7.55704
1918.37	7.57256
1921.34	8.39683
1924.32	8.40883
1927.29	8.91241
1930.26	8.21851
1933.23	7.90196
1936.2	7.63335
1939.17	8.2228
1942.14	8.02062
1945.11	8.98987
1948.07	9.0867
1951.04	9.32823
1954	9.39329
1956.96	9.47542
1959.93	9.70894
1962.89	9.68516
1965.85	9.30548
1968.8	8.54922
1971.76	7.83266
1974.72	7.31113
1977.67	7.75827
1980.63	7.82066
1983.58	8.11137
1986.53	8.35529
1989.48	9.82461
1992.43	10.1024
1995.38	10.4623
1998.32	11.1028
2001.27	11.027
2004.22	11.664
2007.16	12.0237
2010.1	12.8443
2013.04	13.8137
2015.98	14.0971
2018.92	14.9973
2021.86	15.1936
2024.8	15.1964
2027.74	15.7239
2030.67	16.4319
2033.61	16.2542
2036.54	15.849
2039.47	16.2792
2042.4	15.956
2045.33	15.926
2048.26	16.287
2051.19	16.662
2054.12	17.0485
2057.04	17.1954
2059.97	18.2847
2062.89	19.7307
2065.81	20.6771
2068.73	22.0845
2071.65	22.9384
2074.57	23.8366
2077.49	23.8365
2080.41	24.7151
2083.32	25.4873
2086.24	25.9621
2089.15	26.9084
2092.07	28.5075
2094.98	29.3507
2097.89	31.5886
2100.8	33.1379
2103.71	35.6607
2106.61	37.8999
2109.52	40.1211
2112.43	42.3808
2115.33	44.7553
2118.23	47.8355
2121.13	51.3636
2124.04	54.1624
2126.94	57.8779
2129.83	62.1309
2132.73	66.8026
2135.63	70.5224
2138.53	74.1152
2141.42	77.884
2144.31	80.5912
2147.21	83.8454
2150.1	87.0986
2152.99	90.2857
2155.88	92.9954
2158.77	96.2988
2161.65	98.5956
2164.54	100.347
2167.43	101.017
2170.31	102.517
2173.19	103.003
2176.07	102.941
2178.96	101.437
2181.84	100.536
2184.72	98.5064
2187.59	95.9489
2190.47	93.9709
2193.35	91.4888
2196.22	88.1408
2199.09	85.2307
2201.97	81.5107
2204.84	77.6542
2207.71	73.3991
2210.58	69.0232
2213.45	64.4739
2216.31	60.7187
2219.18	57.293
2222.05	53.8883
2224.91	51.7057
2227.78	48.8015
2230.64	45.7795
2233.5	43.6449
2236.36	41.617
2239.22	39.3614
2242.08	38.0754
2244.93	36.1776
2247.79	35.5511
2250.64	34.0769
2253.5	31.7018
2256.35	30.8282
2259.2	30.6811
2262.05	30.1
2264.9	28.8398
2267.75	27.4012
2270.6	25.256
2273.45	24.1259
2276.29	23.1174
2279.14	20.5488
2281.98	18.6498
2284.82	17.1332
2287.66	15.7763
2290.5	14.3609
2293.34	13.0424
2296.18	11.6882
2299.02	12.3338
2301.86	11.3759
2304.69	10.5943
2307.53	11.2371
2310.36	10.8541
2313.19	11.2106
2316.02	11.989
2318.85	12.0484
2321.68	11.4259
2324.51	11.4971
2327.34	11.9433
2330.16	11.9327
2332.99	11.5408
2335.81	11.1746
2338.64	10.4586
2341.46	10.4611
2344.28	9.69976
2347.1	8.37485
2349.92	6.65535
2352.74	6.8927
2355.55	5.91702
2358.37	6.02086
2361.19	5.09217
2364	5.1918
2366.81	5.8475
2369.62	5.41195
2372.44	4.03498
2375.24	3.65864
2378.05	3.20234
2380.86	2.65765
2383.67	3.62536
2386.47	3.62136
2389.28	2.86422
2392.08	3.75346
2394.89	3.01669
2397.69	2.9029
2400.49	2.22559
2403.29	1.96183
2406.09	2.34447
2408.88	2.64117
2411.68	3.40879
2414.48	4.09157
2417.27	4.45744
2420.06	5.31449
2422.86	6.50503
2425.65	6.54138
2428.44	5.89024
2431.23	6.94214
2434.02	7.70461
2436.81	7.08194
2439.59	6.22297
2442.38	6.30071
2445.16	6.39939
2447.95	6.88413
2450.73	6.32611
2453.51	6.64749
2456.29	5.67525
2459.07	4.69109
2461.85	3.49515
2464.63	1.66172
2467.4	1.63453
2470.18	1.72567
2472.95	1.78082
2475.73	1.17227
2478.5	1.27086
2481.27	1.40653
2484.04	1.70336
2486.81	1.24819
2489.58	1.14219
2492.35	0.635945
2495.12	0.946093
2497.88	1.5624
2500.65	2.73704
2503.41	2.48768
2506.17	2.92865
2508.94	2.68657
2511.7	1.85823
2514.46	2.68282
2517.22	3.12051
2519.97	3.07177
2522.73	2.37384
2525.49	1.89873
2528.24	1.73102
2530.99	1.80653
2533.75	2.1735
2536.5	2.72549
2539.25	3.23729
2542	3.26226
2544.75	2.92812
2547.5	3.53292
2550.24	4.18034
2552.99	4.18109
2555.74	4.05225
2558.48	4.61638
2561.22	5.1511
2563.96	5.13622
2566.71	5.32688
2569.45	5.8046
2572.18	5.48141
2574.92	4.99605
2577.66	4.90851
2580.4	4.68817
2583.13	4.88568
2585.87	4.36613
2588.6	3.90931
2591.33	3.10096
2594.06	2.8011
2596.79	3.21077
2599.52	2.91162
2602.25	2.82773
2604.98	3.0189
2607.71	1.59752
2610.43	1.35857
2613.16	1.5196
2615.88	1.4881
2618.6	0.63221
2621.32	0.723361
2624.04	0.965996
2626.76	0.612683
2629.48	0.0137645
2632.2	0.278216
2634.92	0.645217
2637.63	1.28391
2640.35	1.61276
2643.06	2.71795
2645.77	3.00303
2648.49	3.27229
2651.2	3.09923
2653.91	3.45759
2656.62	3.8293
2659.33	4.00823
2662.03	4.61458
2664.74	4.30046
2667.44	4.49535
2670.15	4.39141
2672.85	3.9108
2675.55	3.5124
2678.26	3.25412
2680.96	2.32998
2683.66	1.27425
2686.35	0.875136
2689.05	1.11376
2691.75	1.13456
2694.44	0.888884
2697.14	0.856911
2699.83	1.50601
2702.52	2.05438
2705.22	3.54249
2707.91	4.41875
2710.6	5.41835
2713.29	5.69333
2715.97	5.76595
2718.66	6.53664
2721.35	7.49821
2724.03	7.96933
2726.72	8.4324
2729.4	8.58093
2732.08	7.94071
2734.76	8.48988
2737.44	8.15479
2740.12	7.64481
2742.8	7.1993
2745.48	6.77352
2748.16	5.85606
2750.83	5.54371
2753.51	5.37509
2756.18	5.2579
2758.85	4.61024
2761.53	4.04251
2764.2	3.84265
2766.87	3.39232
2769.54	3.29416
2772.2	4.32382
2774.87	4.31329
2777.54	3.96642
2780.2	2.86226
2782.87	2.483
2785.53	2.23893
2788.19	1.63242
2790.85	1.01855
2793.51	0.705588
2796.17	0.664778
2798.83	-0.475727
2801.49	0.208802
2804.15	-0.170432
2806.8	-0.843226
2809.46	-1.55496
2812.11	-2.00738
2814.76	-2.55655
2817.42	-2.07071
2820.07	-1.12136
2822.72	0.679889
2825.37	4.21633
2828.02	7.34591
2830.66	12.3097
2833.31	17.7478
2835.96	23.8837
2838.6	29.1695
2841.24	34.6024
2843.89	40.8784
2846.53	48.3203
2849.17	57.369
2851.81	65.6563
2854.45	75.7888
2857.09	85.2239
2859.72	94.1718
2862.36	102.615
2865	110.666
2867.63	118.227
2870.26	123.415
2872.9	128.598
2875.53	133.28
2878.16	137.282
2880.79	140.426
2883.42	145.135
2886.05	149.121
2888.67	153.175
2891.3	157
2893.92	161.259
2896.55	166.599
2899.17	171.875
2901.79	178.588
2904.42	186.296
2907.04	196.588
2909.66	207.455
2912.27	218.845
2914.89	232.002
2917.51	243.384
2920.13	253.704
2922.74	263.416
2925.35	270.726
2927.97	276.305
2930.58	279.651
2933.19	281.296
2935.8	281.089
2938.41	278.506
2941.02	273.955
2943.63	267.298
2946.24	259.193
2948.84	249.647
2951.45	239.232
2954.05	228.74
2956.65	217.28
2959.26	205.432
2961.86	195.389
2964.46	185.214
2967.06	175.224
2969.66	165.519
2972.25	155.657
2974.85	147.282
2977.45	138.4
2980.04	129.273
2982.64	120.248
2985.23	110.546
2987.82	101.602
2990.41	92.2738
2993	84.5864
2995.59	75.9554
2998.18	69.4096
3000.77	61.3761
3003.36	54.5001
3005.94	48.4717
3008.53	42.6479
3011.11	37.0839
3013.69	33.0049
3016.28	28.7043
3018.86	25.8288
3021.44	23.6951
3024.02	22.2516
3026.6	20.7765
3029.18	19.4111
3031.75	18.0979
3034.33	17.2655
3036.9	17.3118
3039.48	17.6152
3042.05	17.0833
3044.62	18.1672
3047.19	18.4838
3049.77	18.6192
3052.34	19.019
3054.9	19.2534
3057.47	18.6588
3060.04	18.141
3062.61	16.9731
3065.17	15.7586
3067.74	15.2392
3070.3	13.5955
3072.86	11.8411
3075.42	10.4398
3077.99	9.19662
3080.54	7.84359
3083.1	6.28967
3085.66	4.91626
3088.22	3.62338
3090.78	3.01005
3093.33	1.87424
3095.89	0.486425
3098.44	-0.0809871
3100.99	-0.291235
3103.54	-0.736131
3106.1	-0.723146
3108.65	-0.589967
3111.2	-0.455231
3113.74	-0.421968
3116.29	0.486119
3118.84	0.767367
3121.38	1.05061
3123.93	1.25035
3126.47	1.49288
3129.01	2.26112
3131.56	2.88825
3134.1	3.21198
3136.64	3.41464
3139.18	3.88643
3141.72	4.01204
3144.26	4.27239
3146.79	4.49562
3149.33	4.03043