File: data/Raman/poly_smoothed/Thy_10_08_23_1x_45s_532 nm_x100_100%_600 gr_mm_01.txt
#Acq. time (s)=	45
#Accumulations=	2
#Range (cm-¹)=	200...3150
#Windows=	2
#Auto scanning=	Off
#Autofocus=	Off
#Macrospot=	Off
#AutoExposure=	Off
#Spike filter=	Multiple accum.
#Delay time (s)=	0
#Binning=	1
#Readout mode=	Signal
#DeNoise=	Off
#ICS correction=	On
#Dark correction=	Off
#Inst. Process=	Off
#Detector Gain=	Best Dynamic Range
#Detector ADC=	20 kHz
#Detector temperature (°C)=	-69.85
#Instrument=	LabRAM HR Evol
#Detector=	Synapse
#Objective=	x100
#Grating=	600 gr/mm
#ND Filter=	100%
#Laser (nm)=	532
#Hole=	100.021
#Range=	Auto
#Laser Pol.=	No
#Raman. Pol.=	No
#Laser Pol. (°)=	-0.0007625
#Raman Pol. (°)=	89.9995
#Collection=	Microscope
#StageXY=	Marzhauser
#StageZ=	Marzhauser
#X (µm)=	2204.6
#Y (µm)=	1225.1
#Z (µm)=	442.15
#Full time(mm:ss)=	3:19
#Project=
#Sample=
#Site=
#Title=	Thy_10_08_23_2x_45s_532 nm_x100_100%_600 gr_mm
#Remark=
#Date=	05.07.2022 15:48
#Acquired=	05.07.2022 15:48:39
#Base:Fit=	10.08.2022 09:46:25
#Base:Sub=	10.08.2022 09:46:49
#Filter:Polynom=	16.08.2022 10:24:56
#AxisType[0]=Intens
#AxisUnit[0]=Cnt
#AxisType[1]=Spectr
#AxisUnit[1]=1/cm
200.43	12.6176
204.059	15.8845
207.688	14.4344
211.314	11.8206
214.941	10.0351
218.564	9.62533
222.186	9.12412
225.809	7.55322
229.428	8.82972
233.045	7.35519
236.663	4.91858
240.278	5.59473
243.891	6.37819
247.503	6.53375
251.116	6.20827
254.725	5.92803
258.333	6.58932
261.939	6.35903
265.544	6.53098
269.148	6.19475
272.75	6.75402
276.351	8.00391
279.95	7.05255
283.548	8.24022
287.144	8.20905
290.739	7.04615
294.333	7.39789
297.925	7.832
301.514	9.81551
305.104	10.4373
308.692	11.7719
312.279	11.7298
315.862	13.791
319.446	13.6911
323.029	12.8831
326.608	15.2594
330.188	15.6072
333.766	15.8083
337.341	16.5913
340.917	16.8873
344.489	17.4458
348.062	17.3725
351.631	15.0632
355.201	13.678
358.768	13.5812
362.333	12.3323
365.899	12.0753
369.462	11.2126
373.023	9.40057
376.585	8.06691
380.143	8.9064
383.7	10.3658
387.256	11.8927
390.812	13.6573
394.365	13.9536
397.916	15.8968
401.467	15.8823
405.015	16.341
408.563	16.6702
412.109	17.421
415.654	18.1383
419.197	18.5952
422.739	20.8258
426.279	20.8131
429.819	19.7018
433.356	18.3768
436.891	16.8565
440.426	16.5363
443.96	15.7167
447.492	15.8338
451.021	14.9742
454.551	14.3421
458.079	12.8728
461.604	13.8022
465.13	15.306
468.654	18.0429
472.175	20.4003
475.696	21.3427
479.215	21.2089
482.733	22.495
486.249	24.365
489.765	24.454
493.278	26.3599
496.789	27.896
500.301	29.4186
503.81	29.8782
507.317	30.5169
510.825	30.9743
514.33	32.179
517.833	31.9029
521.335	32.5704
524.836	33.957
528.335	33.3707
531.835	33.3909
535.332	32.7941
538.827	32.2676
542.321	32.4573
545.814	32.081
549.305	31.3342
552.795	30.8061
556.282	30.1333
559.769	30.0234
563.255	27.8361
566.739	27.8063
570.223	25.6383
573.705	22.3757
577.183	20.3036
580.663	19.074
584.141	16.1203
587.615	14.5658
591.09	13.9514
594.564	12.6821
598.035	11.8659
601.506	12.7258
604.974	12.6585
608.443	12.9745
611.908	13.3442
615.374	15.0122
618.837	16.0097
622.3	16.4244
625.761	17.6605
629.219	18.7657
632.677	19.7857
636.135	22.2186
639.59	25.6047
643.043	27.1529
646.495	28.4913
649.948	28.0117
653.398	26.0937
656.846	25.3181
660.293	26.3525
663.738	28.832
667.183	30.4807
670.626	31.5653
674.067	34.6688
677.508	35.1348
680.947	35.8735
684.385	38.2145
687.821	40.6781
691.254	41.7356
694.688	43.8069
698.121	44.6091
701.552	46.828
704.98	46.9488
708.409	48.1636
711.836	49.9206
715.26	50.9952
718.685	52.7176
722.108	54.9474
725.528	56.0165
728.949	56.8884
732.367	57.408
735.785	58.61
739.2	59.2913
742.614	62.2749
746.028	65.9471
749.439	69.9176
752.849	72.015
756.26	76.5908
759.667	79.5346
763.073	81.3109
766.477	83.3466
769.883	86.2041
773.285	88.0814
776.686	89.2366
780.085	89.2661
783.484	89.928
786.881	91.3488
790.276	93.0051
793.671	93.7225
797.064	94.9214
800.456	95.8178
803.846	96.1555
807.234	97.0379
810.622	95.267
814.008	95.1924
817.394	95.5718
820.778	95.3358
824.159	95.6956
827.541	96.2373
830.921	96.6794
834.298	95.459
837.676	93.4985
841.051	93.3396
844.426	91.2846
847.798	89.434
851.171	85.76
854.54	84.0049
857.911	80.9963
861.278	79.1412
864.645	77.2253
868.01	75.0769
871.373	72.9913
874.735	71.806
878.097	70.8039
881.457	68.2372
884.815	65.4627
888.172	64.1338
891.528	63.2009
894.882	61.2868
898.237	61.6544
901.589	61.8891
904.94	63.3183
908.289	63.0141
911.635	63.7708
914.982	64.8196
918.328	64.8678
921.672	65.3061
925.015	65.3916
928.357	65.4437
931.698	65.6939
935.035	67.163
938.373	66.3133
941.71	66.7434
945.044	65.0837
948.378	62.6141
951.709	61.1815
955.041	59.9074
958.372	57.1689
961.699	53.65
965.027	51.7515
968.352	52.7248
971.676	54.1351
975	55.1628
978.322	56.1907
981.642	57.3483
984.962	59.6862
988.28	60.0493
991.596	59.8774
994.911	60.2299
998.227	61.5484
1001.54	61.1776
1004.85	59.5729
1008.16	60.2027
1011.47	58.4077
1014.78	58.7633
1018.08	54.6185
1021.39	52.3931
1024.69	47.8665
1028	43.7217
1031.3	41.0967
1034.6	39.5696
1037.9	34.7695
1041.19	31.1403
1044.49	30.9801
1047.78	30.8418
1051.08	30.8521
1054.37	30.5957
1057.66	30.5732
1060.95	30.7489
1064.24	30.327
1067.53	28.8073
1070.81	29.8012
1074.1	30.4629
1077.38	30.3461
1080.66	30.3498
1083.94	30.4358
1087.22	30.5563
1090.5	29.4383
1093.78	30.4244
1097.05	29.9016
1100.33	29.9376
1103.6	30.3289
1106.87	30.5642
1110.14	30.979
1113.41	30.2267
1116.68	27.4247
1119.95	24.1352
1123.21	22.3655
1126.48	21.1975
1129.74	20.4644
1133	20.843
1136.26	19.4569
1139.52	18.2502
1142.78	17.3915
1146.04	15.5046
1149.29	15.989
1152.55	12.9459
1155.8	10.5796
1159.05	8.71606
1162.3	7.65705
1165.55	6.7342
1168.8	7.70982
1172.05	9.47546
1175.29	9.03075
1178.54	11.2845
1181.78	13.7628
1185.02	14.7577
1188.26	15.6757
1191.5	17.6439
1194.74	18.7924
1197.97	22.4667
1201.21	25.5218
1204.44	31.9482
1207.68	37.7235
1210.91	43.3835
1214.14	48.1548
1217.37	51.561
1220.59	56.8328
1223.82	62.0901
1227.05	64.8019
1230.27	66.8446
1233.49	68.0924
1236.72	70.8235
1239.94	72.2592
1243.16	74.3372
1246.37	76.3263
1249.59	76.6865
1252.8	75.7939
1256.02	74.5741
1259.23	74.252
1262.44	72.1674
1265.66	71.4246
1268.86	70.9915
1272.07	72.7875
1275.28	73.4844
1278.48	75.2426
1281.69	77.0248
1284.89	78.7346
1288.09	79.9604
1291.29	81.1173
1294.49	82.8224
1297.69	84.9674
1300.89	87.5084
1304.08	89.5087
1307.28	91.1521
1310.47	93.6693
1313.66	98.1181
1316.85	100.976
1320.04	102.605
1323.23	103.225
1326.42	101.763
1329.61	101.411
1332.79	100.009
1335.97	98.7594
1339.16	96.7321
1342.34	95.0158
1345.52	93.9863
1348.7	92.6352
1351.87	89.9618
1355.05	85.0016
1358.22	80.5163
1361.4	77.8767
1364.57	74.6968
1367.74	71.1515
1370.91	67.5565
1374.08	62.3664
1377.25	59.4559
1380.41	58.1561
1383.58	55.5644
1386.74	54.3237
1389.91	52.8702
1393.07	51.7285
1396.23	49.4599
1399.39	46.3304
1402.55	43.9839
1405.7	43.1712
1408.86	44.4323
1412.01	46.6896
1415.17	49.937
1418.32	55.2971
1421.47	61.4371
1424.62	67.7115
1427.77	74.1923
1430.91	82.2527
1434.06	89.6579
1437.2	97.701
1440.35	104.275
1443.49	108.4
1446.63	111.099
1449.77	112.576
1452.91	112.322
1456.05	110.519
1459.18	106.456
1462.32	99.8335
1465.45	94.2572
1468.59	84.9191
1471.72	75.7262
1474.85	66.8461
1477.98	56.9846
1481.1	47.9343
1484.23	39.8826
1487.36	33.9619
1490.48	27.7427
1493.61	25.0835
1496.73	20.5009
1499.85	19.498
1502.97	19.301
1506.09	20.0698
1509.2	21.252
1512.32	22.236
1515.43	23.7227
1518.55	24.5098
1521.66	27.0086
1524.77	29.1726
1527.88	30.6803
1530.99	33.5941
1534.1	34.5396
1537.21	36.9781
1540.31	39.7161
1543.42	43.6155
1546.52	46.7146
1549.62	50.651
1552.72	55.9341
1555.82	58.7702
1558.92	61.251
1562.02	63.8054
1565.11	65.7228
1568.21	70.0718
1571.3	73.9965
1574.39	76.8368
1577.49	80.8909
1580.57	83.1852
1583.66	85.3813
1586.75	87.3367
1589.84	88.6872
1592.92	89.3473
1596.01	89.3581
1599.09	89.4221
1602.17	89.0836
1605.25	87.2327
1608.33	86.5681
1611.41	86.0135
1614.49	84.2229
1617.57	82.965
1620.64	83.1103
1623.72	81.7288
1626.79	82.0145
1629.86	80.4601
1632.93	81.7641
1636	84.1701
1639.07	87.5964
1642.13	91.6274
1645.2	94.4389
1648.26	98.3472
1651.33	101.589
1654.39	104.43
1657.45	106.09
1660.51	107.031
1663.57	106.274
1666.63	104.378
1669.68	102.17
1672.74	97.3218
1675.79	91.981
1678.85	86.4078
1681.9	80.5747
1684.95	73.5408
1688	65.2266
1691.05	58.9457
1694.09	51.6451
1697.14	44.7776
1700.18	37.4856
1703.23	31.7544
1706.27	27.8515
1709.31	25.1443
1712.35	22.4743
1715.39	19.1364
1718.43	17.196
1721.47	15.5309
1724.5	15.186
1727.54	14.2176
1730.57	12.8767
1733.61	12.0463
1736.64	10.6831
1739.67	9.99145
1742.7	8.08332
1745.72	7.83731
1748.75	6.66517
1751.77	6.85483
1754.8	6.97566
1757.82	6.79644
1760.84	6.24136
1763.87	6.60426
1766.89	6.25518
1769.91	5.40046
1772.92	4.18418
1775.94	4.47965
1778.95	4.96404
1781.97	5.27725
1784.98	4.27946
1787.99	4.51323
1791.01	4.25306
1794.01	4.51138
1797.02	4.1891
1800.03	3.89943
1803.04	3.13348
1806.04	3.67107
1809.05	3.75252
1812.05	3.09147
1815.05	3.04966
1818.05	3.70453
1821.05	3.82973
1824.05	3.59229
1827.05	4.06903
1830.04	3.52542
1833.04	2.83349
1836.03	2.17751
1839.03	1.45114
1842.02	1.0096
1845.01	0.829388
1848	1.98556
1850.99	2.3094
1853.97	1.32691
1856.96	0.00346333
1859.94	-0.661712
1862.93	-1.77637
1865.91	-1.67564
1868.89	-1.29336
1871.87	-0.889201
1874.85	-1.18547
1877.83	-0.341081
1880.81	1.31473
1882.57	2.15506
1885.56	3.59422
1888.55	5.63798
1891.54	7.15141
1894.52	7.92614
1897.51	8.9494
1900.49	10.2976
1903.47	11.7276
1906.45	11.7355
1909.43	11.5759
1912.41	11.6095
1915.39	11.8521
1918.37	12.1092
1921.34	11.0719
1924.32	9.07235
1927.29	7.58601
1930.26	7.14959
1933.23	5.11764
1936.2	4.3537
1939.17	4.53793
1942.14	3.25713
1945.11	2.93763
1948.07	2.81098
1951.04	4.53548
1954	3.9047
1956.96	4.4546
1959.93	4.94288
1962.89	6.1456
1965.85	7.05497
1968.8	7.5858
1971.76	9.75749
1974.72	9.86959
1977.67	9.81667
1980.63	9.50942
1983.58	9.9689
1986.53	10.6528
1989.48	11.1642
1992.43	11.9419
1995.38	12.4001
1998.32	13.1038
2001.27	13.8426
2004.22	14.3846
2007.16	15.2403
2010.1	16.48
2013.04	17.1275
2015.98	18.1525
2018.92	18.784
2021.86	19.7456
2024.8	19.8556
2027.74	20.533
2030.67	21.1932
2033.61	21.3186
2036.54	21.5124
2039.47	22.8784
2042.4	23.4214
2045.33	22.5323
2048.26	23.1928
2051.19	22.7509
2054.12	22.0533
2057.04	22.1731
2059.97	21.4131
2062.89	21.5388
2065.81	21.0369
2068.73	21.5803
2071.65	21.8491
2074.57	22.403
2077.49	22.8991
2080.41	22.3073
2083.32	23.0519
2086.24	22.927
2089.15	23.675
2092.07	24.0941
2094.98	22.7985
2097.89	22.9328
2100.8	22.6906
2103.71	22.5953
2106.61	22.9966
2109.52	24.0185
2112.43	25.6877
2115.33	25.4406
2118.23	26.903
2121.13	27.4005
2124.04	28.2435
2126.94	29.7496
2129.83	31.2884
2132.73	32.6878
2135.63	33.4634
2138.53	35.4321
2141.42	37.6894
2144.31	39.8143
2147.21	42.133
2150.1	43.8509
2152.99	45.2512
2155.88	46.5891
2158.77	47.9468
2161.65	49.5044
2164.54	50.3204
2167.43	51.387
2170.31	52.5636
2173.19	53.5263
2176.07	54.5623
2178.96	54.1016
2181.84	54.9272
2184.72	55.4538
2187.59	54.4528
2190.47	53.5421
2193.35	51.7104
2196.22	49.9438
2199.09	47.8699
2201.97	46.3936
2204.84	43.8504
2207.71	42.7423
2210.58	40.9753
2213.45	38.8641
2216.31	35.9906
2219.18	33.2556
2222.05	31.6725
2224.91	29.796
2227.78	27.2812
2230.64	25.5483
2233.5	24.4595
2236.36	24.7181
2239.22	25.6122
2242.08	24.9401
2244.93	23.7851
2247.79	22.8774
2250.64	22.7818
2253.5	22.4166
2256.35	22.6486
2259.2	21.5015
2262.05	22.0464
2264.9	22.6354
2267.75	23.6372
2270.6	25.009
2273.45	26.1938
2276.29	25.9801
2279.14	26.4671
2281.98	26.1762
2284.82	25.5455
2287.66	25.9942
2290.5	25.7233
2293.34	24.0212
2296.18	23.3269
2299.02	23.4268
2301.86	24.1142
2304.69	24.7275
2307.53	24.7353
2310.36	24.4265
2313.19	22.9532
2316.02	21.8871
2318.85	21.0219
2321.68	20.9194
2324.51	21.6288
2327.34	21.6917
2330.16	21.9791
2332.99	22.1589
2335.81	21.9784
2338.64	21.1242
2341.46	20.5777
2344.28	19.6629
2347.1	18.7181
2349.92	18.8092
2352.74	17.6107
2355.55	15.888
2358.37	14.7598
2361.19	13.0614
2364	13.4012
2366.81	14.1847
2369.62	13.8871
2372.44	12.971
2375.24	12.3949
2378.05	12.8967
2380.86	11.8472
2383.67	11.4116
2386.47	10.7527
2389.28	11.692
2392.08	11.6923
2394.89	11.8219
2397.69	11.063
2400.49	10.8688
2403.29	11.2756
2406.09	10.5352
2408.88	11.8076
2411.68	11.894
2414.48	11.4324
2417.27	11.3609
2420.06	11.4601
2422.86	11.1381
2425.65	12.1577
2428.44	12.2057
2431.23	12.9112
2434.02	12.8013
2436.81	12.1034
2439.59	11.8502
2442.38	11.0008
2445.16	10.9977
2447.95	10.4744
2450.73	8.9997
2453.51	8.26466
2456.29	7.45038
2459.07	6.51225
2461.85	4.92891
2464.63	5.31666
2467.4	5.04554
2470.18	3.95802
2472.95	4.11853
2475.73	3.56403
2478.5	2.86332
2481.27	2.85423
2484.04	3.317
2486.81	3.74235
2489.58	5.27737
2492.35	5.11231
2495.12	5.37038
2497.88	5.21504
2500.65	5.69006
2503.41	5.4568
2506.17	5.53497
2508.94	5.78805
2511.7	6.41152
2514.46	5.64445
2517.22	5.69637
2519.97	6.10132
2522.73	6.01813
2525.49	6.46327
2528.24	6.12016
2530.99	5.88893
2533.75	6.1237
2536.5	5.00072
2539.25	4.04517
2542	3.67358
2544.75	3.93769
2547.5	4.67704
2550.24	4.9232
2552.99	5.00734
2555.74	4.80204
2558.48	4.35469
2561.22	2.97181
2563.96	1.93703
2566.71	2.68227
2569.45	2.47993
2572.18	1.80692
2574.92	2.03592
2577.66	1.05488
2580.4	1.24675
2583.13	0.269467
2585.87	0.0666694
2588.6	-0.270825
2591.33	0.39074
2594.06	0.179989
2596.79	-0.835328
2599.52	-1.44443
2602.25	-2.1316
2604.98	-1.68382
2607.71	-1.31346
2610.43	0.290094
2613.16	1.2386
2615.88	1.09803
2618.6	1.50466
2621.32	2.05445
2624.04	1.5197
2626.76	1.71604
2629.48	1.9037
2632.2	2.80103
2634.92	3.47048
2637.63	2.96501
2640.35	2.99401
2643.06	2.60461
2645.77	1.66065
2648.49	1.3207
2651.2	0.455149
2653.91	0.0492642
2656.62	0.829894
2659.33	0.439779
2662.03	0.890777
2664.74	0.79116
2667.44	0.722077
2670.15	0.870766
2672.85	1.89922
2675.55	2.70178
2678.26	2.78338
2680.96	2.77167
2683.66	3.23833
2686.35	3.25673
2689.05	3.43162
2691.75	4.24303
2694.44	5.0547
2697.14	5.55969
2699.83	6.77888
2702.52	7.19329
2705.22	8.1517
2707.91	8.83977
2710.6	8.6964
2713.29	9.79536
2715.97	10.7315
2718.66	11.5284
2721.35	13.633
2724.03	14.48
2726.72	15.2792
2729.4	15.9879
2732.08	16.1156
2734.76	16.4303
2737.44	16.1814
2740.12	16.1483
2742.8	14.8512
2745.48	14.0649
2748.16	12.2193
2750.83	10.6721
2753.51	9.6223
2756.18	8.82059
2758.85	7.53572
2761.53	5.43346
2764.2	4.47578
2766.87	3.12507
2769.54	2.38784
2772.2	1.43028
2774.87	0.399526
2777.54	0.0642365
2780.2	-0.243046
2782.87	-0.713013
2785.53	-0.81187
2788.19	-1.63744
2790.85	-0.896418
2793.51	-0.486487
2796.17	-0.95576
2798.83	-0.34562
2801.49	0.120052
2804.15	0.625074
2806.8	1.26392
2809.46	0.970223
2812.11	0.911013
2814.76	1.06788
2817.42	1.91353
2820.07	4.5686
2822.72	7.0787
2825.37	10.6349
2828.02	15.9548
2830.66	21.5127
2833.31	27.061
2835.96	33.8521
2838.6	41.2875
2841.24	50.0133
2843.89	59.4836
2846.53	70.4179
2849.17	82.8911
2851.81	94.5601
2854.45	107.953
2857.09	121.798
2859.72	134.91
2862.36	146.497
2865	158.367
2867.63	169.024
2870.26	179.233
2872.9	187.551
2875.53	194.782
2878.16	201.054
2880.79	207.325
2883.42	214.277
2886.05	220.653
2888.67	226.283
2891.3	232.763
2893.92	238.224
2896.55	244.568
2899.17	251.596
2901.79	260.433
2904.42	270.797
2907.04	282.715
2909.66	296.86
2912.27	312.093
2914.89	327.012
2917.51	341.102
2920.13	354.884
2922.74	366.068
2925.35	373.967
2927.97	380.349
2930.58	384.492
2933.19	386.168
2935.8	382.739
2938.41	378.983
2941.02	371.598
2943.63	362.484
2946.24	351.857
2948.84	340.451
2951.45	327.29
2954.05	314.661
2956.65	301.21
2959.26	286.724
2961.86	273.91
2964.46	260.289
2967.06	248.445
2969.66	235.444
2972.25	225.025
2974.85	214.644
2977.45	203.766
2980.04	192.592
2982.64	180.867
2985.23	168.355
2987.82	155.869
2990.41	143.437
2993	130.44
2995.59	117.596
2998.18	105.858
3000.77	95.0439
3003.36	84.4487
3005.94	74.9114
3008.53	66.7908
3011.11	59.7055
3013.69	54.018
3016.28	49.4213
3018.86	44.1192
3021.44	39.35
3024.02	35.2812
3026.6	32.751
3029.18	29.8487
3031.75	28.5432
3034.33	27.6284
3036.9	28.3446
3039.48	29.557
3042.05	31.6611
3044.62	32.3824
3047.19	34.4131
3049.77	36.1495
3052.34	37.3645
3054.9	38.2616
3057.47	38.9688
3060.04	39.2535
3062.61	38.9928
3065.17	38.2366
3067.74	36.9217
3070.3	35.7599
3072.86	32.7583
3075.42	29.9817
3077.99	26.3342
3080.54	22.7012
3083.1	19.1326
3085.66	15.7301
3088.22	12.5016
3090.78	9.37279
3093.33	7.41428
3095.89	5.5945
3098.44	3.94495
3100.99	1.89357
3103.54	2.00747
3106.1	1.15785
3108.65	1.06195
3111.2	1.08328
3113.74	-0.0454871
3116.29	0.102797
3118.84	-0.275723
3121.38	-0.172925
3123.93	0.4946
3126.47	0.620112
3129.01	0.220997
3131.56	-0.0938929
3134.1	0.276852
3136.64	0.274772
3139.18	1.25918
3141.72	1.70179
3144.26	2.25676
3146.79	2.72644
3149.33	3.38295