File: data/Raman/poly_smoothed/Thy_50_12_11_1x_45s_532 nm_x100_100%_600 gr_mm_01.txt
#Acq. time (s)=	45
#Accumulations=	2
#Range (cm-¹)=	200...3150
#Windows=	2
#Auto scanning=	Off
#Autofocus=	Off
#Macrospot=	Off
#AutoExposure=	Off
#Spike filter=	Multiple accum.
#Delay time (s)=	0
#Binning=	1
#Readout mode=	Signal
#DeNoise=	Off
#ICS correction=	On
#Dark correction=	Off
#Inst. Process=	Off
#Detector Gain=	Best Dynamic Range
#Detector ADC=	20 kHz
#Detector temperature (°C)=	-69.85
#Instrument=	LabRAM HR Evol
#Detector=	Synapse
#Objective=	x100
#Grating=	600 gr/mm
#ND Filter=	100%
#Laser (nm)=	532
#Hole=	100.021
#Range=	Auto
#Laser Pol.=	No
#Raman. Pol.=	No
#Laser Pol. (°)=	-0.0007625
#Raman Pol. (°)=	89.9995
#Collection=	Microscope
#StageXY=	Marzhauser
#StageZ=	Marzhauser
#X (µm)=	-5109.9
#Y (µm)=	1497
#Z (µm)=	63.1
#Full time(mm:ss)=	3:18
#Project=
#Sample=
#Site=
#Title=	Thy_50_12_11_2x_45s_532 nm_x100_100%_600 gr_mm
#Remark=
#Date=	07.07.2022 10:01
#Acquired=	07.07.2022 10:01:11
#Base:Fit=	10.08.2022 10:04:29
#Base:Sub=	10.08.2022 10:04:45
#Filter:Polynom=	16.08.2022 10:20:24
#AxisType[0]=Intens
#AxisUnit[0]=Cnt
#AxisType[1]=Spectr
#AxisUnit[1]=1/cm
200.43	12.9618
204.061	13.2165
207.688	13.2652
211.316	13.4524
214.941	11.7527
218.566	12.0612
222.188	11.47
225.809	9.87501
229.43	7.94433
233.047	8.42211
236.663	7.56687
240.278	5.39514
243.894	4.0168
247.506	3.28701
251.116	2.37034
254.725	2.38903
258.333	1.61756
261.939	0.473003
265.546	1.01716
269.15	-0.288497
272.752	-0.458429
276.353	1.42348
279.952	2.31261
283.55	2.46561
287.146	3.90391
290.739	4.00738
294.333	5.47053
297.925	5.31344
301.516	5.24137
305.106	4.7886
308.694	5.0687
312.279	6.14102
315.864	6.913
319.448	7.34255
323.029	7.51349
326.61	7.36019
330.19	7.4103
333.766	9.76438
337.343	9.6041
340.917	9.22651
344.491	8.39901
348.062	8.66087
351.633	8.00959
355.201	6.91744
358.77	5.84717
362.335	6.91747
365.899	7.97654
369.464	7.47614
373.025	7.35829
376.585	5.47617
380.143	5.01819
383.702	2.96329
387.258	2.51772
390.812	3.18635
394.365	4.08817
397.916	5.54044
401.467	6.2063
405.015	5.89517
408.565	5.4134
412.111	6.70915
415.656	5.75801
419.197	6.94011
422.739	5.78144
426.279	6.01134
429.819	6.77365
433.356	7.65951
436.893	8.67894
440.428	9.51642
443.96	8.95931
447.492	10.169
451.023	10.4169
454.553	11.6268
458.079	11.1277
461.606	10.8973
465.132	11.2733
468.654	12.9397
472.177	15.5982
475.696	17.2816
479.217	17.9287
482.733	19.6023
486.251	20.8968
489.765	21.7797
493.278	22.8045
496.791	21.2191
500.301	22.842
503.81	24.3646
507.319	24.5836
510.825	25.5895
514.33	26.913
517.833	26.554
521.337	26.7013
524.838	25.7497
528.337	23.7756
531.835	21.3452
535.332	19.9657
538.827	19.8854
542.321	18.62
545.814	17.6668
549.305	16.4077
552.795	15.2659
556.284	16.0824
559.771	15.0165
563.257	14.1194
566.742	14.4012
570.223	15.2843
573.705	13.5564
577.185	11.5105
580.665	9.8066
584.141	9.38179
587.617	9.37415
591.092	9.00757
594.564	7.89503
598.037	7.21394
601.506	6.55122
604.976	6.57568
608.443	6.29687
611.91	6.90701
615.374	6.45455
618.839	7.40083
622.3	8.3989
625.761	11.1037
629.221	12.7018
632.679	12.4737
636.135	13.8412
639.592	18.3531
643.045	21.2839
646.497	21.7514
649.948	21.6793
653.398	22.5927
656.846	22.1877
660.293	22.2042
663.738	23.2197
667.185	22.6027
670.628	24.0178
674.067	24.8721
677.508	27.5719
680.947	30.0423
684.385	33.2037
687.821	34.5677
691.256	35.6456
694.69	36.8319
698.121	39.0404
701.552	41.1302
704.982	44.618
708.41	48.0532
711.836	49.9617
715.262	52.9103
718.685	55.2584
722.108	56.9298
725.53	57.0918
728.949	57.1245
732.369	57.0943
735.785	57.0239
739.2	58.2976
742.616	59.3027
746.028	61.5798
749.441	62.3851
752.851	64.0181
756.26	65.5911
759.667	67.8356
763.075	71.4367
766.479	71.6998
769.883	72.5167
773.285	73.2023
776.686	75.1554
780.085	76.7287
783.484	79.3182
786.881	80.5193
790.276	83.266
793.671	84.9249
797.064	85.3402
800.456	87.9012
803.846	86.9727
807.236	87.7609
810.624	89.7326
814.01	91.5106
817.394	91.1928
820.778	90.4071
824.161	90.5315
827.543	88.9037
830.921	88.5328
834.3	85.98
837.676	83.7151
841.053	80.742
844.426	78.3018
847.8	76.1623
851.171	72.1202
854.542	68.4559
857.911	65.3503
861.279	62.8802
864.645	58.9933
868.01	56.6382
871.375	54.722
874.737	53.8628
878.097	52.9709
881.457	52.244
884.817	50.8479
888.174	49.9868
891.53	50.8646
894.884	50.0071
898.237	49.6794
901.589	46.8318
904.94	45.343
908.289	42.6106
911.637	42.3901
914.984	42.8707
918.33	40.4465
921.674	38.9002
925.015	37.7031
928.357	36.4945
931.698	34.3575
935.037	33.128
938.373	32.1325
941.71	31.4356
945.046	29.9249
948.378	28.2535
951.711	29.3381
955.043	28.759
958.372	28.2861
961.701	29.9093
965.027	31.1257
968.354	33.3255
971.678	32.7616
975	33.0191
978.324	33.7051
981.644	34.0448
984.962	35.3024
988.282	36.1182
991.598	36.6569
994.913	38.1859
998.227	37.637
1001.54	36.7462
1004.85	34.91
1008.16	34.2151
1011.47	32.909
1014.78	34.3616
1018.08	34.3314
1021.39	32.6615
1024.69	32.3174
1028	31.3606
1031.3	30.7079
1034.6	31.6171
1037.9	30.6256
1041.19	30.2293
1044.49	30.962
1047.79	30.2472
1051.08	27.7104
1054.37	27.2826
1057.66	26.1743
1060.95	26.2425
1064.24	25.6236
1067.53	24.8425
1070.81	22.76
1074.1	22.3073
1077.38	20.0373
1080.66	17.7914
1083.94	17.2882
1087.22	17.7786
1090.5	17.2764
1093.78	16.1179
1097.05	14.9399
1100.33	16.994
1103.6	19.6327
1106.87	21.35
1110.15	21.6192
1113.41	23.5391
1116.68	24.9328
1119.95	23.2026
1123.21	23.3272
1126.48	21.5657
1129.74	21.3315
1133	19.3283
1136.26	17.5184
1139.52	16.5014
1142.78	15.8504
1146.04	13.7701
1149.29	12.2615
1152.55	10.0108
1155.8	9.40986
1159.05	6.16329
1162.3	5.16494
1165.55	3.74141
1168.8	1.77987
1172.05	0.864515
1175.29	0.00317216
1178.54	4.23994
1181.78	6.15762
1185.02	6.8122
1188.26	7.15634
1191.5	7.47765
1194.74	7.90317
1197.97	8.60322
1201.21	7.8808
1204.44	10.414
1207.68	11.6801
1210.91	11.9341
1214.14	14.7978
1217.37	17.8498
1220.6	20.8087
1223.82	22.5136
1227.05	24.9891
1230.27	27.6476
1233.49	31.8741
1236.72	34.9287
1239.94	38.1776
1243.16	41.4707
1246.37	45.0785
1249.59	48.2498
1252.8	51.6935
1256.02	55.3065
1259.23	58.902
1262.44	61.7524
1265.66	63.8639
1268.87	66.3342
1272.07	68.5922
1275.28	71.5121
1278.48	73.5783
1281.69	73.6599
1284.89	74.7029
1288.09	74.382
1291.3	74.7231
1294.49	75.2701
1297.69	74.7404
1300.89	74.9428
1304.09	74.5719
1307.28	76.1438
1310.47	77.3039
1313.66	77.4816
1316.86	76.871
1320.05	76.7351
1323.23	76.0253
1326.42	76.5146
1329.61	75.5577
1332.79	75.3795
1335.98	73.16
1339.16	71.9175
1342.34	71.0954
1345.52	68.0559
1348.7	66.7021
1351.87	64.3153
1355.05	62.0051
1358.23	60.2458
1361.4	57.1903
1364.57	54.1405
1367.74	49.716
1370.91	47.7691
1374.08	45.9798
1377.25	43.67
1380.42	43.0693
1383.58	42.2576
1386.75	42.7522
1389.91	41.2562
1393.07	40.2871
1396.23	40.5015
1399.39	40.2353
1402.55	41.0866
1405.7	42.425
1408.86	43.8569
1412.01	45.0452
1415.17	46.2792
1418.32	47.4788
1421.47	49.861
1424.62	52.9026
1427.77	57.6231
1430.92	61.4193
1434.06	66.6401
1437.2	69.9341
1440.35	72.3586
1443.49	73.9748
1446.63	75.36
1449.77	76.5064
1452.91	76.2944
1456.05	74.8772
1459.18	74.8891
1462.32	71.5848
1465.45	69.0662
1468.59	64.8312
1471.72	61.3612
1474.85	56.31
1477.98	51.4768
1481.11	46.2009
1484.23	40.1106
1487.36	35.4936
1490.48	30.959
1493.61	27.874
1496.73	25.3194
1499.85	23.7803
1502.97	23.4509
1506.09	23.6131
1509.2	22.5803
1512.32	23.5344
1515.44	25.1606
1518.55	25.9027
1521.66	27.7676
1524.77	28.4254
1527.88	30.8951
1530.99	33.4374
1534.1	36.3118
1537.21	39.4112
1540.31	43.3971
1543.42	46.3445
1546.52	51.0243
1549.62	55.6867
1552.72	58.8987
1555.82	62.1863
1558.92	65.3311
1562.02	68.6288
1565.11	72.3949
1568.21	77.0722
1571.3	79.8384
1574.39	81.3633
1577.49	84.5746
1580.58	85.9399
1583.67	86.302
1586.75	86.8536
1589.84	87.0275
1592.93	86.5518
1596.01	85.7418
1599.09	83.8825
1602.18	82.2703
1605.26	81.5727
1608.34	80.2685
1611.41	78.8818
1614.49	78.4593
1617.57	79.9483
1620.64	80.1829
1623.72	80.4402
1626.79	80.61
1629.86	81.453
1632.93	83.2612
1636	86.012
1639.07	88.2679
1642.14	91.6513
1645.2	93.2132
1648.27	92.3962
1651.33	92.5592
1654.39	92.6158
1657.45	91.0416
1660.51	89.4196
1663.57	87.1359
1666.63	83.8362
1669.69	81.7945
1672.74	76.5951
1675.79	71.7736
1678.85	67.4318
1681.9	62.3687
1684.95	57.4918
1688	52.8297
1691.05	48.4444
1694.1	42.4809
1697.14	36.3303
1700.19	33.0429
1703.23	29.8262
1706.27	27.0908
1709.32	25.6744
1712.35	21.8922
1715.39	19.4032
1718.43	17.4641
1721.47	14.6183
1724.5	11.8512
1727.54	11.8974
1730.57	11.7028
1733.61	11.2712
1736.64	10.6592
1739.67	10.3191
1742.7	10.8514
1745.72	10.8823
1748.75	10.8645
1751.78	10.9509
1754.8	11.209
1757.82	11.6611
1760.85	11.2821
1763.87	11.4976
1766.89	11.2297
1769.91	9.62833
1772.92	9.51799
1775.94	9.83256
1778.96	8.92052
1781.97	7.96347
1784.98	7.0685
1788	6.22982
1791.01	6.2194
1794.01	6.97364
1797.02	5.87996
1800.03	5.82737
1803.04	5.69493
1806.04	5.89506
1809.05	5.56076
1812.05	5.94242
1815.05	5.78782
1818.05	6.03063
1821.05	5.77382
1824.05	4.87797
1827.05	4.84488
1830.04	4.7745
1833.04	5.4139
1836.03	5.01081
1839.03	6.04086
1842.02	4.70329
1845.01	4.56057
1848	4.2384
1850.99	3.69206
1853.97	3.09748
1856.96	3.26686
1859.94	3.39899
1862.93	3.4736
1865.91	3.73369
1868.89	2.56059
1871.87	2.95811
1874.85	2.89455
1877.83	2.68163
1880.81	2.63693
1882.56	2.92363
1885.55	2.9358
1888.54	2.39642
1891.52	1.80402
1894.51	2.07224
1897.49	2.39745
1900.48	2.7898
1903.46	2.87825
1906.44	2.99665
1909.42	3.05935
1912.4	2.60628
1915.38	2.43555
1918.35	1.76372
1921.33	1.78654
1924.3	0.845828
1927.28	1.77058
1930.25	1.20476
1933.22	1.49621
1936.19	1.91071
1939.16	1.95855
1942.13	2.5228
1945.09	1.9206
1948.06	1.34142
1951.03	1.30637
1953.99	0.661365
1956.95	0.53764
1959.91	-0.234013
1962.87	-0.347226
1965.83	-0.0237822
1968.79	-0.234838
1971.75	0.254626
1974.7	0.441459
1977.66	0.839986
1980.61	0.963746
1983.56	1.24379
1986.52	1.66776
1989.47	2.27261
1992.41	2.88469
1995.36	3.21179
1998.31	3.90123
2001.26	4.73631
2004.2	5.14975
2007.15	5.73139
2010.09	6.19164
2013.03	5.36935
2015.97	5.10093
2018.91	3.7847
2021.85	3.05628
2024.79	3.29809
2027.72	2.8929
2030.66	1.63271
2033.59	1.23468
2036.53	1.54091
2039.46	1.87897
2042.39	3.01878
2045.32	3.75062
2048.25	4.43299
2051.18	6.0892
2054.1	7.42163
2057.03	8.60355
2059.95	10.4012
2062.88	10.7498
2065.8	12.82
2068.72	13.71
2071.64	15.6955
2074.56	17.1491
2077.48	18.3466
2080.39	19.42
2083.31	20.382
2086.22	20.8163
2089.14	22.1046
2092.05	22.8147
2094.96	25.1125
2097.87	26.8937
2100.78	27.6313
2103.69	28.9177
2106.6	31.7772
2109.51	33.7439
2112.41	37.2806
2115.32	40.0562
2118.22	42.837
2121.12	46.5323
2124.02	49.5804
2126.92	53.9158
2129.82	58.2668
2132.72	62.5234
2135.62	66.6722
2138.51	70.4904
2141.41	74.9322
2144.3	78.7523
2147.19	82.0836
2150.09	86.0343
2152.97	88.8457
2155.86	91.523
2158.75	94.2707
2161.64	97.3656
2164.53	100.076
2167.41	102.361
2170.3	102.006
2173.18	101.751
2176.06	101.063
2178.94	99.7234
2181.82	98.0053
2184.7	96.1349
2187.58	94.0481
2190.46	91.1398
2193.33	88.1421
2196.21	84.1955
2199.08	80.9524
2201.95	76.8006
2204.83	72.1465
2207.7	67.527
2210.57	62.6492
2213.43	59.1895
2216.3	54.7045
2219.17	50.7561
2222.03	46.8574
2224.9	42.9747
2227.76	41.1791
2230.62	38.363
2233.49	36.5062
2236.34	33.5147
2239.2	31.4051
2242.06	29.5277
2244.92	27.1152
2247.78	25.5355
2250.63	25.1041
2253.48	23.0955
2256.34	21.8918
2259.19	19.6063
2262.04	18.4715
2264.89	16.9331
2267.74	16.5647
2270.59	15.9126
2273.43	13.9934
2276.28	13.3172
2279.12	12.3881
2281.97	12.7979
2284.81	11.7418
2287.65	10.5699
2290.49	9.0313
2293.33	8.44152
2296.17	8.18166
2299.01	8.15039
2301.84	8.00922
2304.68	7.35753
2307.51	7.41793
2310.35	6.92533
2313.18	6.32759
2316.01	6.88094
2318.84	5.92109
2321.67	5.28046
2324.5	4.54701
2327.33	3.79897
2330.15	3.35203
2332.98	3.7158
2335.8	3.46752
2338.62	2.63642
2341.45	2.74499
2344.27	3.0793
2347.09	3.07325
2349.91	2.73642
2352.72	2.44521
2355.54	1.85224
2358.36	1.22588
2361.17	0.858247
2363.98	1.416
2366.8	2.24541
2369.61	1.85448
2372.42	2.40916
2375.23	3.10456
2378.04	3.40229
2380.85	3.46674
2383.66	3.17999
2386.46	2.68873
2389.26	2.3914
2392.07	2.15474
2394.87	2.40769
2397.67	2.7935
2400.47	2.89271
2403.27	2.62498
2406.07	2.88811
2408.87	2.93304
2411.67	3.24991
2414.46	3.11941
2417.26	3.02171
2420.05	3.52964
2422.84	3.97162
2425.64	4.28188
2428.43	4.66101
2431.22	5.9453
2434.01	7.2
2436.79	7.68009
2439.58	7.91566
2442.37	8.39586
2445.15	7.42528
2447.93	7.55094
2450.72	6.70052
2453.5	5.64836
2456.28	5.64935
2459.06	5.53844
2461.84	6.07557
2464.62	6.06119
2467.39	5.19272
2470.17	4.18564
2472.94	3.3464
2475.72	3.01313
2478.49	2.65588
2481.26	2.58075
2484.03	2.66606
2486.8	2.83403
2489.57	3.07426
2492.34	2.68758
2495.1	3.15335
2497.87	3.95232
2500.63	3.97886
2503.4	3.05954
2506.16	2.38513
2508.92	2.43262
2511.68	1.67812
2514.44	2.92526
2517.2	1.85453
2519.96	2.24208
2522.72	3.13047
2525.47	3.29685
2528.23	2.88008
2530.98	2.64557
2533.74	2.28222
2536.49	1.42758
2539.24	1.42658
2541.99	1.60557
2544.74	1.5799
2547.49	2.18103
2550.23	2.91537
2552.98	3.2961
2555.72	3.78445
2558.47	3.42569
2561.21	3.46927
2563.95	4.32799
2566.69	4.34643
2569.43	3.90411
2572.17	4.15657
2574.91	5.06113
2577.65	5.59515
2580.39	6.30134
2583.12	6.78113
2585.85	6.70048
2588.59	7.00422
2591.32	7.15194
2594.05	6.5822
2596.78	6.91975
2599.51	6.13065
2602.24	5.35582
2604.97	4.60093
2607.69	4.4721
2610.42	3.38868
2613.14	3.33259
2615.87	3.26548
2618.59	2.8385
2621.31	3.0194
2624.03	2.12561
2626.75	2.12653
2629.47	3.10067
2632.19	3.20331
2634.91	2.82241
2637.62	3.11861
2640.34	3.23051
2643.05	3.43971
2645.76	2.71838
2648.48	2.72886
2651.19	3.03785
2653.9	3.16802
2656.6	3.91853
2659.31	4.4669
2662.02	5.12841
2664.73	5.01546
2667.43	5.61246
2670.14	6.79499
2672.84	7.11709
2675.54	7.62048
2678.24	7.67406
2680.94	8.46704
2683.64	7.7622
2686.34	8.55241
2689.04	8.74757
2691.74	9.4236
2694.43	9.2811
2697.13	9.49848
2699.82	9.10822
2702.51	9.58264
2705.21	9.41443
2707.9	9.61803
2710.58	9.63774
2713.27	9.88917
2715.96	10.6893
2718.65	10.736
2721.33	10.9516
2724.02	11.3327
2726.71	12.135
2729.39	12.8275
2732.07	12.5989
2734.75	12.8756
2737.43	12.9267
2740.11	11.9727
2742.79	11.5879
2745.47	9.94157
2748.14	9.03059
2750.82	7.95935
2753.49	7.5725
2756.17	7.1511
2758.84	6.69128
2761.51	6.73462
2764.18	5.40899
2766.85	4.79214
2769.52	4.33745
2772.19	3.58051
2774.86	3.05125
2777.52	2.61732
2780.19	2.73737
2782.85	2.20229
2785.52	1.62869
2788.18	1.84367
2790.84	2.17651
2793.5	2.19081
2796.16	2.27606
2798.82	1.74176
2801.48	2.00262
2804.13	1.5484
2806.79	0.961862
2809.45	0.184123
2812.1	-0.331018
2814.75	-0.388936
2817.41	0.399125
2820.06	1.62028
2822.71	3.08364
2825.36	4.97848
2828	7.36851
2830.65	9.296
2833.3	12.868
2835.94	16.5598
2838.59	20.0701
2841.23	25.0784
2843.87	31.3577
2846.52	38.5217
2849.16	46.1995
2851.8	53.5892
2854.44	61.7585
2857.08	69.1082
2859.71	76.5522
2862.35	83.8577
2864.98	91.2104
2867.62	97.2052
2870.25	102.033
2872.88	107.168
2875.52	111.562
2878.15	115.952
2880.78	118.974
2883.41	122.822
2886.03	126.709
2888.66	130.2
2891.29	133.618
2893.91	136.72
2896.54	141.514
2899.16	146.603
2901.78	153.583
2904.4	161.037
2907.02	170.472
2909.64	180.548
2912.26	191.184
2914.88	201.841
2917.5	212.083
2920.11	223.276
2922.73	230.106
2925.34	237.807
2927.96	242.575
2930.57	245.098
2933.18	246.275
2935.79	244.851
2938.4	242.715
2941.01	238.209
2943.62	232.109
2946.22	224.717
2948.83	216.202
2951.43	206.838
2954.04	196.22
2956.64	185.28
2959.24	174.789
2961.84	163.975
2964.45	153.504
2967.05	143.929
2969.64	134.528
2972.24	125.912
2974.84	117.303
2977.43	109.557
2980.03	101.811
2982.62	92.3442
2985.22	83.6338
2987.81	74.3273
2990.4	65.8712
2992.99	57.8142
2995.58	50.5054
2998.17	43.4176
3000.76	36.6002
3003.34	30.2606
3005.93	24.7927
3008.52	19.9238
3011.1	15.9772
3013.68	11.7377
3016.27	8.17731
3018.85	5.64378
3021.43	2.67616
3024.01	1.3364
3026.59	0.876158
3029.16	1.01587
3031.74	1.60304
3034.32	1.73238
3036.89	2.30879
3039.47	3.04514
3042.04	4.43043
3044.61	4.92293
3047.18	6.1244
3049.75	6.35876
3052.32	7.06742
3054.89	7.33054
3057.46	7.84462
3060.03	8.40287
3062.59	7.36433
3065.16	6.3657
3067.72	6.09778
3070.29	5.90164
3072.85	4.58329
3075.41	3.45222
3077.97	2.79683
3080.53	1.86971
3083.09	1.25783
3085.65	0.164735
3088.21	0.04781
3090.76	-0.378594
3093.32	-0.754385
3095.87	-0.875386
3098.43	-0.924205
3100.98	-0.137715
3103.53	1.25008
3106.08	1.90627
3108.63	2.01104
3111.18	3.20674
3113.73	4.21537
3116.28	5.89336
3118.83	7.18199
3121.37	8.90426
3123.92	9.85571
3126.46	11.1404
3129	13.0325
3131.55	15.7198
3134.09	16.9289
3136.63	19.2049
3139.17	21.3292
3141.71	23.0015
3144.24	24.6355
3146.78	26.2119
3149.32	29.3502