File: data/Raman/poly_smoothed/Thy_40_11_27_1x_45s_532 nm_x100_100%_600 gr_mm_01.txt
#Acq. time (s)=	45
#Accumulations=	2
#Range (cm-¹)=	200...3150
#Windows=	2
#Auto scanning=	Off
#Autofocus=	Off
#Macrospot=	Off
#AutoExposure=	Off
#Spike filter=	Multiple accum.
#Delay time (s)=	0
#Binning=	1
#Readout mode=	Signal
#DeNoise=	Off
#ICS correction=	On
#Dark correction=	Off
#Inst. Process=	Off
#Detector Gain=	Best Dynamic Range
#Detector ADC=	20 kHz
#Detector temperature (°C)=	-69.85
#Instrument=	LabRAM HR Evol
#Detector=	Synapse
#Objective=	x100
#Grating=	600 gr/mm
#ND Filter=	100%
#Laser (nm)=	532
#Hole=	100.021
#Range=	Auto
#Laser Pol.=	No
#Raman. Pol.=	No
#Laser Pol. (°)=	-0.0007625
#Raman Pol. (°)=	89.9995
#Collection=	Microscope
#StageXY=	Marzhauser
#StageZ=	Marzhauser
#X (µm)=	1938.9
#Y (µm)=	-59.5
#Z (µm)=	425.2
#Full time(mm:ss)=	3:19
#Project=
#Sample=
#Site=
#Title=	Thy_40_11_27_2x_45s_532 nm_x100_100%_600 gr_mm
#Remark=
#Date=	05.07.2022 11:47
#Acquired=	05.07.2022 11:47:03
#Base:Fit=	10.08.2022 10:01:35
#Base:Sub=	10.08.2022 10:01:52
#Filter:Polynom=	16.08.2022 10:21:53
#AxisType[0]=Intens
#AxisUnit[0]=Cnt
#AxisType[1]=Spectr
#AxisUnit[1]=1/cm
200.43	16.1424
204.059	16.9176
207.688	15.5857
211.314	13.5186
214.941	11.2682
218.564	11.0693
222.186	12.1908
225.809	12.1406
229.428	12.434
233.045	12.4352
236.663	12.6248
240.278	12.104
243.891	11.3678
247.503	10.3111
251.116	7.95328
254.725	7.6091
258.333	7.4842
261.939	6.20275
265.544	6.08199
269.148	8.15314
272.75	8.18425
276.351	7.1557
279.95	7.25301
283.548	6.38415
287.144	5.39782
290.739	5.44299
294.333	5.72823
297.925	5.94699
301.514	6.53644
305.104	8.28236
308.692	9.60403
312.279	9.21215
315.862	9.79814
319.446	10.3122
323.029	11.0797
326.608	11.6097
330.188	9.70509
333.766	10.5359
337.341	11.6845
340.917	10.6699
344.489	11.534
348.062	12.1282
351.631	12.2775
355.201	13.5236
358.768	13.6896
362.333	11.9118
365.899	12.2084
369.462	14.6859
373.023	14.3406
376.585	12.7361
380.143	12.9412
383.7	12.5057
387.256	11.5652
390.812	10.9707
394.365	9.32553
397.916	7.61412
401.467	8.09907
405.015	6.53018
408.563	5.30196
412.109	4.32902
415.654	5.09809
419.197	4.61037
422.739	6.21192
426.279	5.47945
429.819	4.08679
433.356	4.22441
436.891	4.24113
440.426	5.21465
443.96	6.4331
447.492	8.55752
451.021	10.551
454.551	12.5576
458.079	13.0103
461.604	11.5663
465.13	13.5209
468.654	13.3566
472.175	13.7656
475.696	14.7131
479.215	15.3379
482.733	15.6576
486.249	16.8463
489.765	15.6121
493.278	15.9983
496.789	16.7115
500.301	16.9806
503.81	16.4158
507.317	15.3349
510.825	16.3068
514.33	16.2198
517.833	15.4283
521.335	15.5229
524.836	16.1706
528.335	15.8396
531.835	14.6837
535.332	12.6899
538.827	11.629
542.321	8.93674
545.814	8.25187
549.305	7.55838
552.795	8.02542
556.282	7.76957
559.769	6.75661
563.255	7.22393
566.739	7.17376
570.223	6.41515
573.705	6.05114
577.183	6.38819
580.663	8.64637
584.141	8.50707
587.615	8.91611
591.09	9.37482
594.564	11.7688
598.035	11.5561
601.506	12.7253
604.974	13.2629
608.443	13.7451
611.908	13.1734
615.374	14.3459
618.837	14.1322
622.3	15.388
625.761	15.8646
629.219	16.5144
632.677	18.3768
636.135	18.711
639.59	19.0501
643.043	17.7197
646.495	18.3041
649.948	20.2927
653.398	21.501
656.846	23.3924
660.293	24.3195
663.738	26.2521
667.183	27.4907
670.626	27.9163
674.067	30.3533
677.508	32.1651
680.947	33.973
684.385	34.679
687.821	36.3005
691.254	37.3869
694.688	38.5652
698.121	39.9007
701.552	41.165
704.98	43.0784
708.409	44.5418
711.836	45.7806
715.26	47.7307
718.685	49.223
722.108	49.3472
725.528	49.3178
728.949	50.8796
732.367	53.2737
735.785	56.9617
739.2	60.4177
742.614	61.7975
746.028	64.9838
749.439	67.0905
752.849	70.5351
756.26	73.389
759.667	75.5932
763.073	77.5835
766.477	79.6752
769.883	81.7078
773.285	83.2492
776.686	85.9827
780.085	87.7181
783.484	89.5592
786.881	92.8122
790.276	93.8578
793.671	93.5615
797.064	94.4143
800.456	94.5846
803.846	94.8309
807.234	92.5218
810.622	92.0049
814.008	91.5868
817.394	91.0993
820.778	89.196
824.159	88.1755
827.541	86.4502
830.921	84.1113
834.298	80.8305
837.676	79.3159
841.051	76.1094
844.426	73.891
847.798	71.8511
851.171	69.9129
854.54	68.4866
857.911	66.3018
861.278	64.653
864.645	63.3255
868.01	61.7476
871.373	60.0712
874.735	59.7522
878.097	57.6921
881.457	58.9441
884.815	58.9396
888.172	57.8472
891.528	57.8672
894.882	58.0899
898.237	58.1178
901.589	57.3758
904.94	56.8955
908.289	55.3073
911.635	54.6067
914.982	54.0787
918.328	53.4955
921.672	53.0268
925.015	50.68
928.357	50.182
931.698	48.5826
935.035	48.1397
938.373	46.5742
941.71	46.0252
945.044	44.6009
948.378	42.614
951.709	41.4362
955.041	41.681
958.372	40.5286
961.699	38.6257
965.027	38.8257
968.352	39.3498
971.676	38.2782
975	38.2139
978.322	37.3942
981.642	35.8737
984.962	35.5079
988.28	34.1362
991.596	33.6598
994.911	33.7969
998.227	34.1704
1001.54	32.0313
1004.85	29.8278
1008.16	28.1003
1011.47	26.2851
1014.78	25.2979
1018.08	24.5825
1021.39	23.693
1024.69	22.5763
1028	22.4986
1031.3	23.538
1034.6	23.6519
1037.9	23.032
1041.19	20.9486
1044.49	21.4055
1047.78	21.8345
1051.08	19.6871
1054.37	17.8721
1057.66	16.5869
1060.95	16.9865
1064.24	15.4472
1067.53	15.123
1070.81	15.1077
1074.1	13.7092
1077.38	13.2678
1080.66	12.6097
1083.94	11.4214
1087.22	11.9763
1090.5	11.5348
1093.78	12.4397
1097.05	12.3556
1100.33	14.6067
1103.6	14.6648
1106.87	15.8698
1110.14	14.7485
1113.41	13.8644
1116.68	13.1191
1119.95	12.6882
1123.21	11.6793
1126.48	9.78364
1129.74	8.00457
1133	6.45275
1136.26	4.64185
1139.52	3.80261
1142.78	2.99489
1146.04	3.46012
1149.29	3.56779
1152.55	2.58478
1155.8	2.38563
1159.05	4.578
1162.3	5.53928
1165.55	7.36629
1168.8	8.67725
1172.05	9.24992
1175.29	9.62694
1178.54	10.5105
1181.78	11.2103
1185.02	12.0731
1188.26	13.0361
1191.5	13.9478
1194.74	14.898
1197.97	15.4921
1201.21	16.3192
1204.44	16.6443
1207.68	17.0638
1210.91	17.9619
1214.14	19.6156
1217.37	20.3144
1220.59	22.0784
1223.82	23.4084
1227.05	24.4187
1230.27	26.4184
1233.49	26.6971
1236.72	28.5441
1239.94	30.5584
1243.16	30.8834
1246.37	31.0987
1249.59	32.4943
1252.8	32.9713
1256.02	33.6588
1259.23	35.2183
1262.44	36.3075
1265.66	36.2993
1268.86	36.3398
1272.07	35.946
1275.28	36.9262
1278.48	38.1875
1281.69	39.4718
1284.89	39.0198
1288.09	39.9543
1291.29	40.764
1294.49	41.7394
1297.69	42.7388
1300.89	43.887
1304.08	43.6392
1307.28	44.8911
1310.47	44.5132
1313.66	45.3413
1316.85	46.7955
1320.04	46.5499
1323.23	47.0357
1326.42	47.9598
1329.61	48.4526
1332.79	50.0864
1335.97	49.1183
1339.16	48.1016
1342.34	46.8317
1345.52	46.0171
1348.7	45.1975
1351.87	45.5821
1355.05	45.3575
1358.22	44.1358
1361.4	42.928
1364.57	41.3217
1367.74	41.5588
1370.91	40.3911
1374.08	39.4436
1377.25	37.2642
1380.41	34.5221
1383.58	32.6258
1386.74	30.6468
1389.91	28.858
1393.07	27.0309
1396.23	26.3504
1399.39	25.0422
1402.55	23.8353
1405.7	23.2229
1408.86	22.3744
1412.01	21.2295
1415.17	20.4811
1418.32	22.3334
1421.47	24.0469
1424.62	27.5766
1427.77	29.6218
1430.91	32.0619
1434.06	36.0646
1437.2	39.509
1440.35	42.3497
1443.49	45.3389
1446.63	46.7729
1449.77	47.9461
1452.91	47.2974
1456.05	46.9897
1459.18	46.0972
1462.32	45.1324
1465.45	43.1611
1468.59	40.2697
1471.72	38.0789
1474.85	36.4639
1477.98	32.6189
1481.1	28.6459
1484.23	25.8934
1487.36	22.0993
1490.48	19.2198
1493.61	17.4344
1496.73	15.9249
1499.85	15.1381
1502.97	13.2622
1506.09	12.3036
1509.2	12.2363
1512.32	12.789
1515.43	12.6349
1518.55	12.9595
1521.66	14.2405
1524.77	14.2057
1527.88	13.8239
1530.99	15.4197
1534.1	17.2008
1537.21	18.8559
1540.31	20.9797
1543.42	22.9407
1546.52	25.1023
1549.62	28.4024
1552.72	29.6376
1555.82	30.376
1558.92	31.2485
1562.02	33.7231
1565.11	33.547
1568.21	36.0743
1571.3	37.4869
1574.39	39.2586
1577.49	40.0396
1580.57	41.6406
1583.66	43.3731
1586.75	44.4034
1589.84	45.5274
1592.92	45.0804
1596.01	44.0459
1599.09	42.8532
1602.17	42.6566
1605.25	42.1681
1608.33	41.4112
1611.41	40.742
1614.49	39.8081
1617.57	38.8732
1620.64	39.2294
1623.72	39.3691
1626.79	38.204
1629.86	38.1911
1632.93	38.2886
1636	39.2796
1639.07	39.1801
1642.13	40.8615
1645.2	42.046
1648.26	43.4821
1651.33	45.1688
1654.39	46.8065
1657.45	47.8597
1660.51	46.5278
1663.57	46.4065
1666.63	44.7219
1669.68	42.5859
1672.74	41.5446
1675.79	38.8449
1678.85	35.4073
1681.9	31.7274
1684.95	29.0395
1688	25.1919
1691.05	21.4749
1694.09	18.8548
1697.14	16.0083
1700.18	12.5559
1703.23	10.3397
1706.27	7.46178
1709.31	5.73054
1712.35	4.29649
1715.39	3.1538
1718.43	1.78318
1721.47	1.39378
1724.5	0.42081
1727.54	-0.482053
1730.57	0.544551
1733.61	0.331096
1736.64	-0.0525661
1739.67	1.19618
1742.7	2.00215
1745.72	1.50036
1748.75	1.89119
1751.77	2.29027
1754.8	3.61975
1757.82	3.86011
1760.84	2.92414
1763.87	3.27872
1766.89	3.1476
1769.91	3.90717
1772.92	3.92035
1775.94	4.03841
1778.95	4.67311
1781.97	5.08926
1784.98	5.42001
1787.99	4.24371
1791.01	3.61232
1794.01	2.95852
1797.02	2.5711
1800.03	2.49043
1803.04	2.74944
1806.04	3.21413
1809.05	2.403
1812.05	2.34909
1815.05	2.54426
1818.05	2.16988
1821.05	1.71322
1824.05	1.78362
1827.05	1.89629
1830.04	1.23963
1833.04	0.975601
1836.03	0.90339
1839.03	1.0333
1842.02	0.25623
1845.01	1.44291
1848	1.82567
1850.99	2.64071
1853.97	3.5993
1856.96	3.60326
1859.94	3.63629
1862.93	3.71235
1865.91	4.22583
1868.89	5.14436
1871.87	5.66458
1874.85	6.23039
1877.83	6.35596
1880.81	5.85259
1882.57	5.27093
1885.56	5.309
1888.55	6.18316
1891.54	5.81036
1894.52	6.42364
1897.51	5.87277
1900.49	5.5869
1903.47	5.30702
1906.45	4.92025
1909.43	5.2039
1912.41	5.71014
1915.39	5.93903
1918.37	6.15896
1921.34	6.68758
1924.32	7.06515
1927.29	7.24888
1930.26	6.04683
1933.23	5.27508
1936.2	5.67415
1939.17	6.15109
1942.14	6.63505
1945.11	5.68132
1948.07	4.95679
1951.04	5.19004
1954	5.48825
1956.96	5.20698
1959.93	6.37693
1962.89	5.85806
1965.85	5.66491
1968.8	5.98873
1971.76	5.07781
1974.72	5.56741
1977.67	6.09836
1980.63	6.74006
1983.58	6.59146
1986.53	6.12902
1989.48	6.13814
1992.43	6.93017
1995.38	7.17348
1998.32	6.52686
2001.27	6.82872
2004.22	6.72206
2007.16	7.86409
2010.1	7.65104
2013.04	7.04485
2015.98	6.1691
2018.92	6.07204
2021.86	5.99441
2024.8	6.17283
2027.74	6.02033
2030.67	6.07322
2033.61	5.06262
2036.54	5.21753
2039.47	4.924
2042.4	4.70392
2045.33	4.98198
2048.26	5.76969
2051.19	5.96647
2054.12	6.34308
2057.04	6.5287
2059.97	6.79818
2062.89	8.69335
2065.81	9.62231
2068.73	11.0049
2071.65	11.8157
2074.57	13.2142
2077.49	15.0562
2080.41	15.9991
2083.32	16.547
2086.24	17.0345
2089.15	16.6894
2092.07	17.4444
2094.98	17.0909
2097.89	17.5583
2100.8	18.4505
2103.71	19.44
2106.61	20.2365
2109.52	21.9142
2112.43	23.2068
2115.33	24.4196
2118.23	25.9806
2121.13	27.9434
2124.04	30.6097
2126.94	32.4684
2129.83	34.1894
2132.73	36.9884
2135.63	39.6948
2138.53	40.8856
2141.42	43.2271
2144.31	45.8004
2147.21	48.8037
2150.1	49.3314
2152.99	50.2432
2155.88	51.2776
2158.77	52.0804
2161.65	52.7676
2164.54	54.064
2167.43	55.5322
2170.31	56.9134
2173.19	57.8697
2176.07	57.576
2178.96	56.8201
2181.84	56.4833
2184.72	55.7183
2187.59	55.0326
2190.47	54.3404
2193.35	52.6303
2196.22	51.1995
2199.09	49.6999
2201.97	46.9288
2204.84	44.1347
2207.71	43.0631
2210.58	41.3045
2213.45	39.4755
2216.31	36.7293
2219.18	33.6863
2222.05	31.6596
2224.91	29.245
2227.78	27.3557
2230.64	25.4892
2233.5	23.288
2236.36	22.0304
2239.22	20.6243
2242.08	19.662
2244.93	18.1627
2247.79	17.1405
2250.64	16.0924
2253.5	14.6229
2256.35	13.0741
2259.2	12.3823
2262.05	11.3023
2264.9	10.3797
2267.75	10.9904
2270.6	11.2774
2273.45	10.6666
2276.29	11.1755
2279.14	11.3178
2281.98	10.9561
2284.82	10.5375
2287.66	11.1583
2290.5	9.86574
2293.34	8.57875
2296.18	8.44224
2299.02	8.76215
2301.86	8.74521
2304.69	9.32435
2307.53	9.86409
2310.36	10.4382
2313.19	10.6808
2316.02	10.316
2318.85	10.1093
2321.68	8.79608
2324.51	7.25296
2327.34	7.51394
2330.16	6.50013
2332.99	5.62817
2335.81	5.376
2338.64	4.69484
2341.46	2.87032
2344.28	2.38406
2347.1	2.78516
2349.92	2.39049
2352.74	2.12841
2355.55	1.63115
2358.37	1.0212
2361.19	0.484738
2364	1.63238
2366.81	2.44266
2369.62	1.05169
2372.44	1.39731
2375.24	1.63833
2378.05	1.6543
2380.86	1.37217
2383.67	1.9426
2386.47	1.42348
2389.28	0.58876
2392.08	0.692138
2394.89	0.460203
2397.69	0.469032
2400.49	0.466298
2403.29	0.642013
2406.09	1.41055
2408.88	2.16794
2411.68	3.14639
2414.48	4.68885
2417.27	5.84611
2420.06	6.34047
2422.86	7.0568
2425.65	7.2482
2428.44	7.53016
2431.23	8.46362
2434.02	8.0244
2436.81	7.22313
2439.59	6.95282
2442.38	6.81399
2445.16	5.81055
2447.95	6.08062
2450.73	5.47964
2453.51	4.31734
2456.29	4.23341
2459.07	4.05222
2461.85	3.36169
2464.63	2.62558
2467.4	3.34947
2470.18	3.25183
2472.95	3.32077
2475.73	3.33255
2478.5	3.72093
2481.27	3.44184
2484.04	2.98146
2486.81	2.54846
2489.58	2.19243
2492.35	2.78376
2495.12	2.39174
2497.88	2.94639
2500.65	2.64264
2503.41	1.79608
2506.17	2.3214
2508.94	1.84838
2511.7	1.81607
2514.46	1.74271
2517.22	2.21818
2519.97	1.74293
2522.73	1.85673
2525.49	1.93722
2528.24	1.95903
2530.99	1.37712
2533.75	1.80562
2536.5	2.33531
2539.25	2.86545
2542	3.31992
2544.75	3.32137
2547.5	3.2334
2550.24	3.20785
2552.99	3.88945
2555.74	4.15351
2558.48	4.246
2561.22	4.87745
2563.96	4.63548
2566.71	3.90085
2569.45	3.88895
2572.18	3.90358
2574.92	4.17576
2577.66	3.70888
2580.4	4.13707
2583.13	3.10231
2585.87	2.865
2588.6	2.26681
2591.33	1.58105
2594.06	0.551811
2596.79	0.949134
2599.52	0.90751
2602.25	0.234479
2604.98	0.996456
2607.71	1.33183
2610.43	1.6538
2613.16	2.08773
2615.88	2.41282
2618.6	2.99787
2621.32	3.23307
2624.04	2.70987
2626.76	3.29899
2629.48	2.47963
2632.2	2.33951
2634.92	2.33816
2637.63	3.08066
2640.35	2.91268
2643.06	3.00886
2645.77	3.14182
2648.49	2.72739
2651.2	2.33541
2653.91	1.93014
2656.62	1.68433
2659.33	1.6807
2662.03	2.01665
2664.74	3.04039
2667.44	2.46192
2670.15	3.55245
2672.85	4.69558
2675.55	5.30455
2678.26	5.67345
2680.96	5.90708
2683.66	6.05735
2686.35	5.93402
2689.05	5.98069
2691.75	6.35874
2694.44	6.45198
2697.14	7.0444
2699.83	7.28238
2702.52	8.01106
2705.22	8.1001
2707.91	7.86592
2710.6	8.27565
2713.29	7.66412
2715.97	7.81367
2718.66	7.94592
2721.35	7.46999
2724.03	6.77953
2726.72	6.31914
2729.4	5.98271
2732.08	6.1931
2734.76	6.40827
2737.44	6.06719
2740.12	5.29585
2742.8	5.35609
2745.48	4.31684
2748.16	4.1714
2750.83	3.55521
2753.51	3.3543
2756.18	3.86136
2758.85	3.24546
2761.53	3.33186
2764.2	2.73218
2766.87	2.45111
2769.54	2.26786
2772.2	2.13723
2774.87	1.63572
2777.54	0.770224
2780.2	-0.00140029
2782.87	0.207701
2785.53	0.341306
2788.19	0.706471
2790.85	0.372256
2793.51	0.461804
2796.17	0.313261
2798.83	0.134624
2801.49	0.347937
2804.15	0.432605
2806.8	1.0516
2809.46	1.26467
2812.11	1.61444
2814.76	0.703623
2817.42	1.02586
2820.07	1.91656
2822.72	2.55259
2825.37	3.2866
2828.02	3.82555
2830.66	4.79203
2833.31	6.10198
2835.96	7.61846
2838.6	9.81244
2841.24	11.9766
2843.89	14.8403
2846.53	18.8995
2849.17	23.7919
2851.81	27.3158
2854.45	31.7346
2857.09	35.8507
2859.72	39.9725
2862.36	43.5028
2865	47.9284
2867.63	52.3769
2870.26	55.7606
2872.9	58.3008
2875.53	60.3138
2878.16	62.5263
2880.79	64.9666
2883.42	66.8011
2886.05	69.3009
2888.67	72.4133
2891.3	74.0617
2893.92	75.9595
2896.55	78.2696
2899.17	81.1827
2901.79	84.8483
2904.42	89.0831
2907.04	94.2086
2909.66	99.5081
2912.27	105.847
2914.89	110.828
2917.51	117.188
2920.13	121.832
2922.74	125.662
2925.35	128.951
2927.97	131.504
2930.58	133.099
2933.19	132.568
2935.8	131.285
2938.41	130.424
2941.02	128.821
2943.63	126.258
2946.24	122.866
2948.84	118.842
2951.45	115.365
2954.05	109.78
2956.65	105.047
2959.26	99.7083
2961.86	94.6934
2964.46	89.1273
2967.06	83.6916
2969.66	79.6826
2972.25	74.5609
2974.85	70.4511
2977.45	66.2753
2980.04	61.5233
2982.64	55.9352
2985.23	50.7929
2987.82	45.6259
2990.41	40.9351
2993	36.0492
2995.59	30.9137
2998.18	26.6628
3000.77	22.8289
3003.36	19.7474
3005.94	16.5013
3008.53	13.8966
3011.11	11.1231
3013.69	9.65964
3016.28	7.89659
3018.86	6.93433
3021.44	5.54196
3024.02	4.80462
3026.6	4.3395
3029.18	4.34972
3031.75	4.53626
3034.33	5.16436
3036.9	5.36629
3039.48	5.39343
3042.05	6.05117
3044.62	6.42056
3047.19	7.04535
3049.77	7.65723
3052.34	7.93718
3054.9	8.33386
3057.47	7.68837
3060.04	7.00138
3062.61	6.67795
3065.17	5.65118
3067.74	5.13569
3070.3	4.75376
3072.86	3.62475
3075.42	2.72546
3077.99	2.19931
3080.54	0.940397
3083.1	0.359737
3085.66	0.439644
3088.22	0.588994
3090.78	0.633626
3093.33	0.527125
3095.89	0.211199
3098.44	0.613593
3100.99	1.10274
3103.54	2.47042
3106.1	3.12819
3108.65	4.29556
3111.2	4.64368
3113.74	5.12403
3116.29	4.96364
3118.84	5.92878
3121.38	6.57169
3123.93	7.48384
3126.47	7.87647
3129.01	8.59151
3131.56	9.21269
3134.1	9.76146
3136.64	9.99985
3139.18	11.103
3141.72	12.0162
3144.26	13.2194
3146.79	14.2625
3149.33	15.8412