File: data/Raman/poly_smoothed/Thy_10_08_37_1x_45s_532 nm_x100_100%_600 gr_mm_01.txt
#Acq. time (s)=	45
#Accumulations=	2
#Range (cm-¹)=	200...3150
#Windows=	2
#Auto scanning=	Off
#Autofocus=	Off
#Macrospot=	Off
#AutoExposure=	Off
#Spike filter=	Multiple accum.
#Delay time (s)=	0
#Binning=	1
#Readout mode=	Signal
#DeNoise=	Off
#ICS correction=	On
#Dark correction=	Off
#Inst. Process=	Off
#Detector Gain=	Best Dynamic Range
#Detector ADC=	20 kHz
#Detector temperature (°C)=	-69.85
#Instrument=	LabRAM HR Evol
#Detector=	Synapse
#Objective=	x100
#Grating=	600 gr/mm
#ND Filter=	100%
#Laser (nm)=	532
#Hole=	100.021
#Range=	Auto
#Laser Pol.=	No
#Raman. Pol.=	No
#Laser Pol. (°)=	-0.0007625
#Raman Pol. (°)=	89.9995
#Collection=	Microscope
#StageXY=	Marzhauser
#StageZ=	Marzhauser
#X (µm)=	-2372.5
#Y (µm)=	229
#Z (µm)=	521.4
#Full time(mm:ss)=	3:05
#Project=
#Sample=
#Site=
#Title=	Thy_10_08_37_2x_45s_532 nm_x100_100%_600 gr_mm
#Remark=
#Date=	06.07.2022 14:25
#Acquired=	06.07.2022 14:25:20
#Base:Fit=	10.08.2022 09:46:25
#Base:Sub=	10.08.2022 09:46:49
#Filter:Polynom=	16.08.2022 10:24:56
#AxisType[0]=Intens
#AxisUnit[0]=Cnt
#AxisType[1]=Spectr
#AxisUnit[1]=1/cm
200.398	5.19562
204.027	3.94018
207.657	3.45158
211.283	2.76331
214.909	2.50568
218.533	2.54197
222.157	2.52624
225.777	2.08646
229.396	3.11119
233.016	4.70502
236.632	3.98931
240.247	3.34002
243.86	2.24324
247.474	2.813
251.085	4.23426
254.694	5.30473
258.301	5.07193
261.908	5.41117
265.513	6.09208
269.116	8.08759
272.718	7.96597
276.319	8.65019
279.918	8.64583
283.516	9.42829
287.113	9.81228
290.708	11.0184
294.302	11.5155
297.894	11.6475
301.485	12.2177
305.073	13.6741
308.661	14.1556
312.247	14.7172
315.833	15.6353
319.415	16.7382
322.997	16.314
326.579	14.8454
330.156	15.3625
333.735	16.0061
337.31	17.4963
340.885	17.4494
344.458	17.3291
348.03	16.855
351.6	16.6064
355.17	15.0006
358.737	14.0612
362.304	12.3409
365.868	12.499
369.431	12.4154
372.994	11.9546
376.554	12.035
380.112	12.6959
383.669	11.9105
387.225	11.1359
390.781	11.6295
394.334	12.249
397.885	11.9254
401.436	11.3913
404.984	10.7305
408.532	9.82395
412.078	9.04718
415.623	9.53441
419.166	9.05112
422.708	8.3407
426.248	7.77677
429.788	8.52687
433.326	7.94718
436.86	6.66066
440.395	6.48754
443.929	5.89629
447.461	6.97539
450.99	7.84253
454.52	9.35879
458.048	9.81569
461.573	13.1212
465.099	13.8826
468.623	14.4493
472.144	14.7801
475.666	15.4081
479.184	16.8072
482.703	17.4598
486.218	17.7307
489.734	17.8086
493.247	18.0601
496.759	18.6542
500.271	19.7387
503.779	20.0415
507.287	19.4695
510.795	20.5243
514.299	20.7034
517.803	19.9703
521.305	18.608
524.805	18.7669
528.307	17.7839
531.805	18.4328
535.301	19.0032
538.797	17.376
542.291	16.6492
545.783	15.4473
549.275	14.712
552.765	13.4866
556.253	12.4207
559.738	10.2436
563.224	8.64111
566.709	8.36915
570.192	7.92644
573.674	6.72365
577.153	5.31613
580.632	4.62041
584.11	4.32801
587.587	3.5117
591.06	2.46806
594.534	2.23321
598.005	2.13284
601.476	2.0919
604.944	2.38789
608.413	3.63356
611.878	5.75021
615.344	6.2607
618.807	6.67111
622.27	6.46235
625.73	6.55849
629.189	7.84077
632.648	9.2964
636.105	10.2772
639.559	11.1653
643.013	11.9606
646.467	12.3074
649.918	13.5524
653.368	15.6872
656.816	16.1825
660.263	16.3718
663.708	17.2364
667.153	17.7574
670.596	18.6499
674.037	18.4858
677.478	19.171
680.917	21.298
684.355	22.38
687.791	22.3102
691.224	24.0359
694.658	25.4035
698.091	25.906
701.522	26.3905
704.95	28.4588
708.379	30.2565
711.806	32.2184
715.23	33.9084
718.655	36.6556
722.078	38.9796
725.498	41.3793
728.919	44.0097
732.337	45.9534
735.755	47.6585
739.17	50.1522
742.584	50.059
745.998	52.2834
749.409	54.4654
752.819	56.2057
756.23	56.704
759.637	59.1523
763.043	61.7301
766.448	63.4098
769.853	64.9146
773.255	64.949
776.656	67.0893
780.056	67.5877
783.454	68.1318
786.851	68.5933
790.247	71.0501
793.641	71.4587
797.034	73.7742
800.426	75.7418
803.817	77.5931
807.206	76.9778
810.592	76.6243
813.979	77.3771
817.364	77.2058
820.748	77.8871
824.129	77.6914
827.511	77.6679
830.891	77.9858
834.269	77.9622
837.646	76.2792
841.023	75.7436
844.396	75.2741
847.77	72.0063
851.141	71.2428
854.513	69.7892
857.881	67.1205
861.248	64.9293
864.616	62.6708
867.98	61.7927
871.343	60.6072
874.707	60.1831
878.068	59.1655
881.428	57.9534
884.786	56.8543
888.143	56.2723
891.498	55.0349
894.855	56.2142
898.208	54.4326
901.56	55.5098
904.91	55.78
908.26	54.9652
911.608	54.7819
914.955	54.3974
918.298	53.2533
921.643	52.2741
924.986	52.5475
928.328	52.2312
931.668	50.5784
935.006	50.0528
938.344	49.101
941.681	46.3152
945.014	43.7503
948.349	42.0895
951.682	40.2106
955.012	38.0167
958.343	35.3
961.67	32.8684
964.998	32.5947
968.323	32.0242
971.649	32.1095
974.971	32.076
978.293	33.1431
981.615	33.1073
984.933	32.9223
988.251	32.3616
991.567	33.0483
994.884	31.8588
998.198	31.4046
1001.51	30.167
1004.82	30.1503
1008.13	29.1424
1011.44	27.9245
1014.75	25.7969
1018.06	25.5474
1021.36	24.117
1024.66	21.4868
1027.97	21.2164
1031.27	19.4923
1034.57	18.6192
1037.87	15.6302
1041.16	14.8978
1044.46	15.4955
1047.76	14.5021
1051.05	12.9219
1054.34	12.8452
1057.63	12.6334
1060.92	11.6272
1064.21	10.817
1067.5	10.3111
1070.78	9.92706
1074.07	10.0595
1077.35	8.79827
1080.63	9.05901
1083.91	9.30161
1087.19	10.7709
1090.47	11.0848
1093.75	12.6099
1097.03	12.698
1100.3	13.161
1103.57	13.8156
1106.84	15.2308
1110.11	14.9726
1113.38	14.4345
1116.65	13.1344
1119.92	11.2914
1123.19	10.4241
1126.45	8.59535
1129.71	7.98287
1132.97	7.43292
1136.23	6.36296
1139.49	6.73548
1142.75	6.60512
1146.01	6.34756
1149.26	5.897
1152.52	5.1338
1155.77	4.67477
1159.02	4.26664
1162.27	4.03312
1165.52	4.01943
1168.77	3.51672
1172.02	4.5752
1175.26	4.86248
1178.51	4.06386
1181.75	4.95911
1184.99	4.72191
1188.23	6.24989
1191.47	5.56815
1194.71	5.46855
1197.94	6.88725
1201.18	8.82169
1204.41	11.431
1207.65	15.0639
1210.88	17.3303
1214.11	20.0543
1217.34	22.5429
1220.57	25.8088
1223.79	29.7159
1227.02	31.7243
1230.24	33.188
1233.47	34.9727
1236.69	36.7719
1239.91	37.4859
1243.13	38.3642
1246.34	38.4628
1249.56	39.0909
1252.78	40.5481
1255.99	39.2504
1259.2	38.6552
1262.42	39.3684
1265.63	39.9432
1268.84	39.971
1272.04	40.669
1275.25	42.3805
1278.46	43.2408
1281.66	45.0489
1284.86	46.7455
1288.07	47.2457
1291.27	49.6935
1294.47	51.6158
1297.66	52.4222
1300.86	55.4299
1304.06	55.3783
1307.25	55.5125
1310.44	56.6408
1313.64	58.624
1316.83	60.5082
1320.02	59.328
1323.2	59.1069
1326.39	58.6816
1329.58	57.2781
1332.76	56.0016
1335.95	54.7931
1339.13	54.0088
1342.31	53.7279
1345.49	52.8929
1348.67	52.2039
1351.85	50.1621
1355.02	48.2483
1358.2	46.0888
1361.37	45.3073
1364.54	42.4627
1367.71	41.0266
1370.88	38.6819
1374.05	34.6928
1377.22	32.9894
1380.39	31.6495
1383.55	29.8278
1386.72	29.0016
1389.88	29.2192
1393.04	27.0455
1396.2	25.4596
1399.36	24.6568
1402.52	24.6527
1405.68	24.7955
1408.83	26.2357
1411.98	29.3512
1415.14	32.7996
1418.29	35.9962
1421.44	39.2864
1424.59	42.8911
1427.74	47.5055
1430.89	51.6295
1434.03	55.1453
1437.18	59.5577
1440.32	61.5521
1443.46	62.3333
1446.6	62.8816
1449.74	63.0732
1452.88	62.442
1456.02	61.2565
1459.16	58.8617
1462.29	55.7407
1465.43	52.4659
1468.56	47.0915
1471.69	41.3516
1474.82	36.3136
1477.95	32.0337
1481.08	27.8884
1484.2	24.267
1487.33	20.0366
1490.46	16.3363
1493.58	14.2303
1496.7	11.9485
1499.82	9.61404
1502.94	9.21153
1506.06	9.10937
1509.18	9.30539
1512.29	9.26801
1515.41	9.57556
1518.52	9.77421
1521.63	11.1272
1524.75	13.6347
1527.85	14.2765
1530.96	15.8497
1534.07	18.2772
1537.18	19.9854
1540.28	21.6272
1543.39	24.0603
1546.49	26.8979
1549.59	28.2567
1552.69	31.9092
1555.79	35.3733
1558.89	38.2256
1561.99	39.0898
1565.08	41.5563
1568.18	43.2618
1571.27	45.4119
1574.37	45.5178
1577.46	48.053
1580.55	49.7504
1583.64	50.6347
1586.73	52.2325
1589.81	53.0817
1592.9	53.1972
1595.98	52.4963
1599.06	51.7074
1602.15	51.7176
1605.23	51.4379
1608.31	51.6502
1611.39	51.1972
1614.46	50.7763
1617.54	51.0599
1620.61	51.3062
1623.69	52.4159
1626.76	53.3245
1629.83	55.1109
1632.9	54.5222
1635.97	55.3032
1639.04	56.9923
1642.11	60.0096
1645.17	62.3757
1648.24	64.3726
1651.3	66.4651
1654.36	67.5608
1657.42	67.916
1660.48	67.7812
1663.54	67.0035
1666.6	64.8369
1669.66	61.9533
1672.71	58.2508
1675.77	56.1647
1678.82	52.6021
1681.87	48.0785
1684.92	43.9967
1687.97	39.3345
1691.02	34.175
1694.07	29.2446
1697.11	24.6048
1700.16	20.526
1703.2	16.6075
1706.25	13.6029
1709.29	10.8493
1712.33	9.41588
1715.37	8.95297
1718.41	8.93913
1721.44	8.59022
1724.48	7.89016
1727.51	7.18022
1730.55	6.82274
1733.58	6.55272
1736.61	7.01132
1739.64	6.9696
1742.67	6.38023
1745.7	6.18079
1748.72	6.03777
1751.75	6.69128
1754.77	6.88109
1757.8	6.80526
1760.82	6.92461
1763.84	6.54103
1766.86	5.05414
1769.88	5.15833
1772.9	4.18034
1775.91	3.48313
1778.93	3.50021
1781.94	2.77642
1784.96	2.37641
1787.97	1.8666
1790.98	1.58405
1793.99	1.33382
1797	0.981808
1800.01	0.625618
1803.01	0.875681
1806.02	1.27608
1809.02	0.872317
1812.02	1.08412
1815.02	0.651411
1818.03	0.342718
1821.02	0.469083
1824.02	0.861322
1827.02	1.20651
1830.02	0.988512
1833.01	1.06295
1836.01	0.79285
1839	0.806917
1841.99	0.440431
1844.98	-0.0345871
1847.97	0.0705989
1850.96	0.0806243
1853.95	0.00593193
1856.93	-0.016156
1859.92	-0.131774
1862.9	-0.157298
1865.88	0.425737
1868.87	1.33473
1871.85	1.93556
1874.83	3.14516
1877.81	3.62508
1880.78	3.806
1882.53	3.62848
1885.52	3.63903
1888.51	4.21607
1891.5	4.52011
1894.48	4.56538
1897.47	4.52681
1900.45	4.55207
1903.43	5.05395
1906.41	4.17652
1909.39	4.72591
1912.37	4.85444
1915.35	4.63119
1918.33	4.99006
1921.3	5.07811
1924.28	5.20478
1927.25	5.6602
1930.22	6.03742
1933.19	6.98729
1936.16	7.40608
1939.13	7.79356
1942.1	8.66697
1945.07	9.90008
1948.03	9.65736
1951	9.90286
1953.96	10.325
1956.92	11.0838
1959.88	11.7492
1962.84	13.1019
1965.8	12.7365
1968.76	12.9098
1971.72	12.601
1974.67	12.9735
1977.63	12.7403
1980.58	11.1254
1983.54	10.1554
1986.49	9.38556
1989.44	9.20672
1992.39	8.89547
1995.33	9.14325
1998.28	9.23371
2001.23	9.6908
2004.17	8.86615
2007.12	8.85211
2010.06	8.87314
2013	8.14328
2015.94	8.94622
2018.88	8.6416
2021.82	9.13312
2024.76	9.72643
2027.69	10.5768
2030.63	11.7314
2033.56	11.8689
2036.5	12.4114
2039.43	12.0809
2042.36	11.8199
2045.29	11.631
2048.22	11.9018
2051.15	12.0437
2054.07	12.6624
2057	13.6377
2059.92	15.2237
2062.85	16.2415
2065.77	16.4759
2068.69	17.3394
2071.61	17.8515
2074.53	18.3452
2077.45	19.1812
2080.37	19.1273
2083.28	19.4673
2086.2	19.5228
2089.11	20.2254
2092.02	20.8686
2094.94	20.3416
2097.85	20.4505
2100.76	21.4052
2103.66	21.2429
2106.57	20.6201
2109.48	21.1043
2112.38	21.047
2115.29	21.4854
2118.19	22.0386
2121.09	22.5486
2123.99	23.2305
2126.89	23.3954
2129.79	23.3871
2132.69	23.4312
2135.59	24.646
2138.48	24.7405
2141.38	25.6064
2144.27	26.8538
2147.17	27.2367
2150.06	28.6107
2152.95	29.7321
2155.84	30.413
2158.73	31.0341
2161.61	32.8676
2164.5	33.2981
2167.38	34.0077
2170.27	35.7662
2173.15	35.9768
2176.03	36.4197
2178.91	36.3525
2181.8	36.0432
2184.67	36.6199
2187.55	35.8177
2190.43	34.9583
2193.3	33.3022
2196.18	32.7568
2199.05	32.7127
2201.93	32.4837
2204.8	31.7689
2207.67	31.0662
2210.54	29.2923
2213.41	29.2238
2216.27	27.4746
2219.14	26.2793
2222.01	25.4726
2224.87	24.3212
2227.73	23.8512
2230.6	22.9252
2233.46	22.5684
2236.32	22.2118
2239.18	22.1029
2242.03	21.1106
2244.89	21.0798
2247.75	20.3697
2250.6	20.5783
2253.46	19.8224
2256.31	20.0435
2259.16	19.3143
2262.01	19.0642
2264.86	19.3137
2267.71	19.7609
2270.56	18.7482
2273.4	18.2115
2276.25	17.5337
2279.09	17.6655
2281.94	17.0737
2284.78	17.0243
2287.62	15.4185
2290.46	14.3061
2293.3	13.2529
2296.14	12.9854
2298.98	13.5879
2301.82	14.5343
2304.65	14.8339
2307.49	15.4509
2310.32	15.2958
2313.15	15.3804
2315.98	15.535
2318.81	16.3887
2321.64	16.7863
2324.47	15.4951
2327.3	15.3937
2330.12	15.0788
2332.95	15.5268
2335.77	14.732
2338.6	13.6583
2341.42	13.6497
2344.24	13.4341
2347.06	13.5993
2349.88	13.2989
2352.7	12.3156
2355.51	11.3835
2358.33	10.1345
2361.14	10.0512
2363.96	9.85088
2366.77	10.7859
2369.58	10.1122
2372.39	9.48137
2375.2	9.39807
2378.01	8.57139
2380.82	8.53555
2383.63	8.29202
2386.43	8.83892
2389.24	8.86846
2392.04	8.55726
2394.84	8.20884
2397.65	8.63286
2400.45	9.39597
2403.25	8.84787
2406.05	9.23616
2408.84	10.0101
2411.64	10.9523
2414.44	11.3215
2417.23	12.8956
2420.02	12.7789
2422.82	12.7105
2425.61	13.1301
2428.4	13.1895
2431.19	12.6781
2433.98	12.1345
2436.77	10.7619
2439.55	10.3682
2442.34	11.478
2445.12	11.3734
2447.91	10.7809
2450.69	10.1083
2453.47	9.1189
2456.25	7.68699
2459.03	7.18514
2461.81	7.14955
2464.59	6.34795
2467.36	6.59398
2470.14	6.06417
2472.92	5.60799
2475.69	5.44851
2478.46	4.83837
2481.23	4.91373
2484	4.16903
2486.77	4.22352
2489.54	4.62836
2492.31	5.10717
2495.08	4.61268
2497.84	4.66816
2500.61	3.77252
2503.37	3.11094
2506.13	3.06461
2508.9	3.8308
2511.66	4.11732
2514.42	3.5261
2517.18	2.55161
2519.93	2.97511
2522.69	2.68409
2525.45	2.84555
2528.2	3.17169
2530.95	2.97866
2533.71	2.13114
2536.46	2.68296
2539.21	1.91339
2541.96	2.173
2544.71	2.57652
2547.46	2.74801
2550.2	3.9221
2552.95	4.43044
2555.7	4.14312
2558.44	4.29383
2561.18	3.78503
2563.93	3.62388
2566.67	3.2559
2569.41	3.32272
2572.15	2.88757
2574.88	2.90417
2577.62	2.22591
2580.36	2.15577
2583.09	2.53543
2585.83	2.63741
2588.56	2.93417
2591.29	1.66905
2594.02	1.51409
2596.75	1.3869
2599.48	1.58398
2602.21	2.04721
2604.94	2.67332
2607.67	2.66468
2610.39	2.67234
2613.12	2.89838
2615.84	2.23653
2618.56	2.42922
2621.28	1.69417
2624.01	1.77968
2626.72	2.09138
2629.44	1.54134
2632.16	1.99738
2634.88	2.07259
2637.59	1.50035
2640.31	1.5468
2643.02	1.86165
2645.74	2.43415
2648.45	1.90773
2651.16	1.79288
2653.87	1.62614
2656.58	1.58249
2659.29	2.12132
2661.99	2.35065
2664.7	2.05947
2667.41	1.90263
2670.11	1.57919
2672.81	0.92745
2675.51	1.50483
2678.22	1.06089
2680.92	0.696155
2683.62	0.774023
2686.31	1.16426
2689.01	1.03262
2691.71	1.78477
2694.4	2.16941
2697.1	3.14348
2699.79	4.285
2702.49	5.02016
2705.18	6.38593
2707.87	7.7093
2710.56	7.74825
2713.25	8.80595
2715.94	9.03325
2718.62	9.68688
2721.31	9.22908
2723.99	8.67405
2726.68	7.99366
2729.36	7.3461
2732.04	6.75926
2734.73	6.33921
2737.41	6.16708
2740.08	5.45765
2742.76	4.42384
2745.44	3.62908
2748.12	2.57588
2750.79	2.44635
2753.47	1.43629
2756.14	0.811171
2758.81	0.903065
2761.49	0.641945
2764.16	1.13353
2766.83	0.782447
2769.5	1.31882
2772.16	2.18979
2774.83	1.37586
2777.5	1.13411
2780.16	1.63894
2782.83	1.30943
2785.49	0.371467
2788.15	-0.118197
2790.82	-0.440234
2793.48	0.0630189
2796.14	0.492166
2798.79	0.465425
2801.45	1.01348
2804.11	1.48686
2806.76	1.88597
2809.42	2.68574
2812.07	1.87809
2814.73	2.18151
2817.38	3.18642
2820.03	4.83565
2822.68	6.82928
2825.33	10.0952
2827.98	14.0431
2830.63	18.1578
2833.27	23.174
2835.92	28.4008
2838.56	34.0345
2841.21	40.7176
2843.85	47.7671
2846.49	56.1655
2849.13	65.0061
2851.77	74.1339
2854.41	83.4103
2857.05	92.6704
2859.69	100.652
2862.32	108.951
2864.96	116.449
2867.59	123.938
2870.23	129.567
2872.86	134.217
2875.49	138.501
2878.12	141.852
2880.75	145.329
2883.38	149.301
2886.01	152.299
2888.63	155.546
2891.26	158.995
2893.89	163.205
2896.51	167.903
2899.13	173.325
2901.76	179.569
2904.38	188.467
2907	198.484
2909.62	209.294
2912.24	220.361
2914.85	231.093
2917.47	241.045
2920.09	249.86
2922.7	256.51
2925.32	261.75
2927.93	265.7
2930.54	266.846
2933.15	265.619
2935.76	263.055
2938.37	258.875
2940.98	252.235
2943.59	244.471
2946.2	235.068
2948.8	224.764
2951.41	213.789
2954.01	203.638
2956.62	192.964
2959.22	183.536
2961.82	173.374
2964.42	164.993
2967.02	156.745
2969.62	149.367
2972.22	142.319
2974.81	135.761
2977.41	128.52
2980	121.82
2982.6	114.013
2985.19	106.929
2987.78	99.0658
2990.38	90.7029
2992.97	83.1354
2995.56	75.5706
2998.14	68.988
3000.73	63.1169
3003.32	56.1387
3005.91	50.1079
3008.49	44.8486
3011.07	40.066
3013.66	36.5512
3016.24	33.2629
3018.82	30.8318
3021.4	27.5792
3023.98	26.0538
3026.56	24.0723
3029.14	22.9638
3031.71	22.3285
3034.29	22.0934
3036.87	22.4436
3039.44	22.9655
3042.01	23.6764
3044.59	24.5006
3047.16	25.0917
3049.73	26.0173
3052.3	26.6396
3054.87	26.9458
3057.43	27.1028
3060	26.7543
3062.57	26.5626
3065.13	25.7466
3067.7	24.5759
3070.26	23.3007
3072.82	21.9574
3075.39	19.6616
3077.95	18.6016
3080.51	16.559
3083.07	14.096
3085.63	11.7348
3088.18	10.1464
3090.74	8.56897
3093.29	7.17134
3095.85	6.18706
3098.4	5.61143
3100.95	3.84414
3103.51	3.41617
3106.06	2.45006
3108.61	2.51911
3111.16	1.87037
3113.71	1.80058
3116.25	2.09931
3118.8	2.3345
3121.35	2.38134
3123.89	2.26145
3126.44	2.69884
3128.98	2.70649
3131.52	2.29844
3134.06	2.13397
3136.6	2.158
3139.14	2.64392
3141.68	2.99397
3144.22	2.8518
3146.76	2.40043
3149.29	0.495216