File: data/Raman/poly_smoothed/Thy_50_12_20_1x_45s_532 nm_x100_100%_600 gr_mm_01.txt
#Acq. time (s)=	45
#Accumulations=	2
#Range (cm-¹)=	200...3150
#Windows=	2
#Auto scanning=	Off
#Autofocus=	Off
#Macrospot=	Off
#AutoExposure=	Off
#Spike filter=	Multiple accum.
#Delay time (s)=	0
#Binning=	1
#Readout mode=	Signal
#DeNoise=	Off
#ICS correction=	On
#Dark correction=	Off
#Inst. Process=	Off
#Detector Gain=	Best Dynamic Range
#Detector ADC=	20 kHz
#Detector temperature (°C)=	-69.85
#Instrument=	LabRAM HR Evol
#Detector=	Synapse
#Objective=	x100
#Grating=	600 gr/mm
#ND Filter=	100%
#Laser (nm)=	532
#Hole=	100.021
#Range=	Auto
#Laser Pol.=	No
#Raman. Pol.=	No
#Laser Pol. (°)=	-0.0007625
#Raman Pol. (°)=	89.9995
#Collection=	Microscope
#StageXY=	Marzhauser
#StageZ=	Marzhauser
#X (µm)=	-5133.5
#Y (µm)=	1481.1
#Z (µm)=	63.25
#Full time(mm:ss)=	3:18
#Project=
#Sample=
#Site=
#Title=	Thy_50_12_20_2x_45s_532 nm_x100_100%_600 gr_mm
#Remark=
#Date=	07.07.2022 10:42
#Acquired=	07.07.2022 10:42:09
#Base:Fit=	10.08.2022 10:04:29
#Base:Sub=	10.08.2022 10:04:45
#Filter:Polynom=	16.08.2022 10:20:24
#AxisType[0]=Intens
#AxisUnit[0]=Cnt
#AxisType[1]=Spectr
#AxisUnit[1]=1/cm
200.43	67.6826
204.061	58.1981
207.688	51.1833
211.316	45.6998
214.941	40.034
218.566	35.1808
222.188	30.7869
225.809	27.237
229.43	21.2536
233.047	17.5996
236.663	13.8228
240.278	11.1324
243.894	9.30777
247.506	7.70669
251.116	5.92059
254.725	5.49063
258.333	7.09851
261.939	8.69045
265.546	7.38145
269.15	7.91667
272.752	8.23854
276.353	8.08466
279.952	8.26509
283.55	9.03054
287.146	11.815
290.739	14.9842
294.333	17.0425
297.925	17.7948
301.516	17.4876
305.106	19.5412
308.694	19.577
312.279	19.2542
315.864	16.6623
319.448	16.3902
323.029	16.7769
326.61	16.1352
330.19	15.2763
333.766	15.535
337.343	15.3864
340.917	13.7856
344.491	11.5798
348.062	10.7024
351.633	7.45484
355.201	6.22117
358.77	4.39333
362.335	4.12744
365.899	4.38292
369.464	3.99066
373.025	6.40175
376.585	7.27511
380.143	7.8832
383.702	7.77814
387.258	7.94638
390.812	8.83352
394.365	8.30618
397.916	7.71948
401.467	7.3326
405.015	8.49324
408.565	8.72897
412.111	8.91599
415.656	8.72312
419.197	9.06199
422.739	8.80318
426.279	7.37877
429.819	5.18922
433.356	4.61862
436.893	3.8402
440.428	3.38107
443.96	2.55293
447.492	3.12371
451.023	3.73323
454.553	4.01591
458.079	4.26184
461.606	8.26099
465.132	9.8729
468.654	11.2585
472.177	13.6762
475.696	15.7766
479.217	17.1929
482.733	19.6268
486.251	21.5317
489.765	24.8602
493.278	27.3726
496.791	29.6961
500.301	31.4657
503.81	32.8992
507.319	31.6842
510.825	30.418
514.33	30.2642
517.833	29.424
521.337	29.5763
524.838	27.3869
528.337	24.2857
531.835	21.8299
535.332	19.8797
538.827	17.3402
542.321	14.1426
545.814	13.9446
549.305	13.6814
552.795	12.9528
556.284	11.1372
559.771	9.59084
563.257	6.66962
566.742	5.78713
570.223	5.21356
573.705	5.26514
577.185	5.95152
580.665	5.31988
584.141	5.27646
587.617	3.59625
591.092	3.32035
594.564	2.13926
598.037	3.04929
601.506	6.03976
604.976	7.40648
608.443	8.01582
611.91	8.07349
615.374	8.15051
618.839	6.82996
622.3	7.51364
625.761	7.64267
629.221	8.99081
632.679	10.319
636.135	10.1741
639.592	8.77446
643.045	8.85349
646.497	8.79326
649.948	10.7522
653.398	12.3297
656.846	12.8227
660.293	12.7029
663.738	13.9045
667.185	14.6812
670.628	16.0071
674.067	16.1693
677.508	18.0758
680.947	22.4604
684.385	26.0028
687.821	28.9596
691.256	32.9721
694.69	34.6172
698.121	37.8279
701.552	38.769
704.982	40.4484
708.41	43.0101
711.836	44.9307
715.262	46.628
718.685	48.5658
722.108	50.0376
725.53	51.615
728.949	54.9062
732.369	57.4722
735.785	59.4261
739.2	58.954
742.616	59.8864
746.028	63.9378
749.441	65.7402
752.851	68.5684
756.26	70.5734
759.667	73.7529
763.075	76.6331
766.479	78.8955
769.883	80.6074
773.285	81.7746
776.686	81.6482
780.085	80.8487
783.484	80.363
786.881	79.5832
790.276	79.0028
793.671	79.5435
797.064	80.5146
800.456	81.2835
803.846	80.4773
807.236	80.5707
810.624	80.3268
814.01	81.3622
817.394	80.6447
820.778	80.544
824.161	80.7288
827.543	82.2045
830.921	80.9379
834.3	79.8511
837.676	79.8403
841.053	77.0286
844.426	74.3419
847.8	71.398
851.171	68.0665
854.542	65.9076
857.911	64.0794
861.279	62.4667
864.645	61.8294
868.01	60.1481
871.375	58.6848
874.737	58.7515
878.097	58.0683
881.457	57.509
884.817	54.0895
888.174	52.3088
891.53	51.2907
894.884	48.5856
898.237	48.062
901.589	46.6938
904.94	44.3481
908.289	41.9121
911.637	38.1899
914.984	35.2991
918.33	33.803
921.674	31.2357
925.015	28.9578
928.357	27.1338
931.698	25.7311
935.037	25.9563
938.373	26.9571
941.71	28.6188
945.046	29.2467
948.378	30.3838
951.711	35.9596
955.043	36.7549
958.372	37.7853
961.701	38.9879
965.027	40.9608
968.354	42.6428
971.678	44.9975
975	46.159
978.324	47.7677
981.644	49.5804
984.962	49.3222
988.282	48.8213
991.598	48.6076
994.913	47.5077
998.227	46.3088
1001.54	46.8757
1004.85	45.3603
1008.16	43.9662
1011.47	44.2745
1014.78	45.8772
1018.08	48.9662
1021.39	49.5498
1024.69	51.3318
1028	52.6969
1031.3	54.1991
1034.6	55.1768
1037.9	53.256
1041.19	52.8997
1044.49	54.2569
1047.79	51.5378
1051.08	50.0206
1054.37	48.6624
1057.66	44.8852
1060.95	42.1898
1064.24	39.2135
1067.53	34.9354
1070.81	31.8003
1074.1	30.3912
1077.38	28.1198
1080.66	26.6897
1083.94	24.8961
1087.22	23.3379
1090.5	22.6534
1093.78	25.0363
1097.05	26.3217
1100.33	25.7488
1103.6	27.254
1106.87	28.8651
1110.15	29.7768
1113.41	30.4538
1116.68	29.7676
1119.95	27.6282
1123.21	28.5303
1126.48	27.5873
1129.74	26.8611
1133	26.3026
1136.26	24.9206
1139.52	23.9658
1142.78	23.352
1146.04	21.1039
1149.29	18.9647
1152.55	16.3477
1155.8	14.5717
1159.05	12.2542
1162.3	9.61058
1165.55	6.97547
1168.8	6.22982
1172.05	6.63471
1175.29	7.66448
1178.54	8.74087
1181.78	7.96133
1185.02	7.57178
1188.26	8.15177
1191.5	9.64506
1194.74	8.28127
1197.97	10.1608
1201.21	14.8081
1204.44	18.4744
1207.68	21.8966
1210.91	24.4691
1214.14	28.0319
1217.37	32.6118
1220.6	37.302
1223.82	40.7983
1227.05	45.5656
1230.27	48.907
1233.49	55.106
1236.72	62.0039
1239.94	67.0418
1243.16	70.1624
1246.37	75.1062
1249.59	80.1951
1252.8	85.4469
1256.02	89.4615
1259.23	93.7062
1262.44	97.3736
1265.66	103.242
1268.87	108.083
1272.07	111.432
1275.28	115.018
1278.48	117.994
1281.69	120.037
1284.89	121.795
1288.09	121.541
1291.3	122.496
1294.49	122.377
1297.69	123.368
1300.89	124.294
1304.09	124.607
1307.28	123.697
1310.47	122.854
1313.66	123.365
1316.86	120.329
1320.05	117.122
1323.23	115.678
1326.42	113.188
1329.61	110.392
1332.79	106.671
1335.98	104.401
1339.16	101.536
1342.34	99.5837
1345.52	96.1571
1348.7	92.5509
1351.87	88.4794
1355.05	84.1587
1358.23	80.085
1361.4	77.6213
1364.57	73.4198
1367.74	70.2728
1370.91	67.6628
1374.08	65.944
1377.25	63.7178
1380.42	61.5864
1383.58	59.3026
1386.75	58.384
1389.91	58.4051
1393.07	56.8754
1396.23	56.1264
1399.39	56.0003
1402.55	57.4418
1405.7	56.7307
1408.86	58.9487
1412.01	60.6416
1415.17	65.7368
1418.32	72.6155
1421.47	79.6601
1424.62	85.9817
1427.77	92.9146
1430.92	100.299
1434.06	108.111
1437.2	115.35
1440.35	121.348
1443.49	124.106
1446.63	128.136
1449.77	128.558
1452.91	126.299
1456.05	124.624
1459.18	119.827
1462.32	115.868
1465.45	109.91
1468.59	102.947
1471.72	93.6734
1474.85	85.6364
1477.98	76.0277
1481.11	67.0642
1484.23	58.6272
1487.36	52.0608
1490.48	45.1328
1493.61	41.1399
1496.73	38.2406
1499.85	36.118
1502.97	33.7899
1506.09	34.9422
1509.2	36.665
1512.32	37.6859
1515.44	38.6457
1518.55	40.4606
1521.66	44.0318
1524.77	47.2066
1527.88	47.4654
1530.99	51.14
1534.1	55.4705
1537.21	60.4711
1540.31	66.6044
1543.42	73.8147
1546.52	78.8765
1549.62	85.8037
1552.72	91.063
1555.82	94.9283
1558.92	101.592
1562.02	106.001
1565.11	110.798
1568.21	117.319
1571.3	122.669
1574.39	126.797
1577.49	130.043
1580.58	133.587
1583.67	134.718
1586.75	134.363
1589.84	133.689
1592.93	130.364
1596.01	127.387
1599.09	122.755
1602.18	120.316
1605.26	116.965
1608.34	114.116
1611.41	112.316
1614.49	111.375
1617.57	111.449
1620.64	111.991
1623.72	113.615
1626.79	115.6
1629.86	117.416
1632.93	121.64
1636	126.399
1639.07	130.505
1642.14	133.957
1645.2	137.806
1648.27	139.805
1651.33	142.386
1654.39	142.71
1657.45	139.744
1660.51	136.718
1663.57	132.111
1666.63	126.597
1669.69	118.869
1672.74	111.004
1675.79	102.665
1678.85	94.4086
1681.9	85.1087
1684.95	75.7383
1688	67.3302
1691.05	59.5267
1694.1	51.4934
1697.14	45.8589
1700.19	39.3499
1703.23	34.6867
1706.27	29.6708
1709.32	28.0439
1712.35	23.9594
1715.39	22.0521
1718.43	20.2086
1721.47	19.8355
1724.5	19.6117
1727.54	19.1037
1730.57	17.8434
1733.61	18.0626
1736.64	17.3763
1739.67	16.7939
1742.7	15.8859
1745.72	13.3824
1748.75	12.1085
1751.78	12.5207
1754.8	11.5577
1757.82	10.5065
1760.85	9.27487
1763.87	8.1912
1766.89	6.1196
1769.91	5.19053
1772.92	4.19452
1775.94	1.78193
1778.96	0.860991
1781.97	0.446527
1784.98	0.358508
1788	1.31887
1791.01	1.99706
1794.01	2.46123
1797.02	2.09526
1800.03	1.98684
1803.04	1.71251
1806.04	2.81691
1809.05	3.25963
1812.05	3.139
1815.05	3.06556
1818.05	2.83565
1821.05	3.48386
1824.05	4.1247
1827.05	4.52716
1830.04	4.53338
1833.04	4.11488
1836.03	4.40909
1839.03	4.32253
1842.02	4.62473
1845.01	4.43388
1848	3.93228
1850.99	3.8736
1853.97	4.12618
1856.96	3.48597
1859.94	3.05818
1862.93	2.49924
1865.91	1.82878
1868.89	1.69785
1871.87	1.79133
1874.85	1.57058
1877.83	1.02094
1880.81	0.94043
1882.56	0.654682
1885.55	1.62755
1888.54	1.63405
1891.52	2.18927
1894.51	1.84508
1897.49	1.25896
1900.48	1.93244
1903.46	1.72304
1906.44	3.66832
1909.42	4.86117
1912.4	5.20655
1915.38	6.85777
1918.35	8.06496
1921.33	8.02059
1924.3	6.97712
1927.28	7.14373
1930.25	6.72392
1933.22	7.32078
1936.19	6.79084
1939.16	6.96152
1942.13	6.69316
1945.09	6.76882
1948.06	6.73997
1951.03	6.29151
1953.99	6.18489
1956.95	6.22004
1959.91	5.72738
1962.87	5.25783
1965.83	4.21285
1968.79	3.06848
1971.75	3.12761
1974.7	2.15953
1977.66	2.5837
1980.61	3.4943
1983.56	3.09605
1986.52	3.53913
1989.47	5.13952
1992.41	4.61359
1995.36	4.58632
1998.31	4.39119
2001.26	4.49878
2004.2	4.33424
2007.15	5.54109
2010.09	4.81071
2013.03	5.79449
2015.97	5.44092
2018.91	5.88458
2021.85	5.64667
2024.79	6.44688
2027.72	5.77469
2030.66	6.85762
2033.59	6.48066
2036.53	7.25042
2039.46	6.72384
2042.39	9.2297
2045.32	10.6502
2048.25	12.1875
2051.18	13.9985
2054.1	16.4713
2057.03	18.144
2059.95	21.8636
2062.88	23.9811
2065.8	26.5039
2068.72	28.2055
2071.64	30.5625
2074.56	32.1316
2077.48	35.2392
2080.39	36.784
2083.31	38.9961
2086.22	41.2472
2089.14	42.8758
2092.05	46.7979
2094.96	48.6107
2097.87	51.1034
2100.78	53.5409
2103.69	58.2403
2106.6	61.3482
2109.51	65.7151
2112.41	70.1017
2115.32	76.2179
2118.22	81.6296
2121.12	87.292
2124.02	93.5451
2126.92	101.537
2129.82	107.997
2132.72	114.954
2135.62	121.441
2138.51	127.925
2141.41	133.952
2144.3	138.935
2147.19	143.101
2150.09	147.871
2152.97	153.032
2155.86	157.038
2158.75	159.581
2161.64	162.255
2164.53	163.092
2167.41	163.145
2170.3	163.373
2173.18	161.533
2176.06	160.354
2178.94	157.14
2181.82	153.683
2184.7	149.842
2187.58	147.218
2190.46	144.164
2193.33	139.982
2196.21	134.306
2199.08	130.285
2201.95	124.347
2204.83	118.85
2207.7	113.423
2210.57	107.648
2213.43	103.027
2216.3	95.9088
2219.17	90.7329
2222.03	86.1487
2224.9	80.734
2227.76	75.4086
2230.62	69.7252
2233.49	65.308
2236.34	61.2591
2239.2	57.8676
2242.06	53.1213
2244.92	48.3813
2247.78	43.9927
2250.63	40.2649
2253.48	38.1377
2256.34	36.9565
2259.19	36.242
2262.04	35.5556
2264.89	33.7272
2267.74	32.7079
2270.59	31.9081
2273.43	29.9647
2276.28	28.8137
2279.12	28.6902
2281.97	27.8172
2284.81	26.4198
2287.65	25.087
2290.49	22.8833
2293.33	21.4025
2296.17	20.6259
2299.01	20.6319
2301.84	18.957
2304.68	17.4018
2307.51	15.597
2310.35	13.6229
2313.18	11.366
2316.01	9.49355
2318.84	9.47359
2321.67	9.791
2324.5	9.14464
2327.33	9.47043
2330.15	8.29494
2332.98	7.07629
2335.8	4.9185
2338.62	4.16536
2341.45	3.29249
2344.27	3.32824
2347.09	3.06727
2349.91	2.76659
2352.72	3.51455
2355.54	3.92816
2358.36	4.42759
2361.17	4.43781
2363.98	6.13847
2366.8	5.88122
2369.61	5.72601
2372.42	5.28021
2375.23	5.23514
2378.04	4.33385
2380.85	5.44011
2383.66	3.74799
2386.46	4.2472
2389.26	3.66315
2392.07	2.63422
2394.87	1.8441
2397.67	1.33379
2400.47	0.695333
2403.27	1.07187
2406.07	2.26036
2408.87	2.55188
2411.67	2.14816
2414.46	3.2673
2417.26	4.46354
2420.05	6.38518
2422.84	6.31008
2425.64	7.04487
2428.43	8.67221
2431.22	9.09408
2434.01	9.68775
2436.79	8.0091
2439.58	8.04623
2442.37	7.70494
2445.15	6.65458
2447.93	5.79198
2450.72	5.84716
2453.5	5.03185
2456.28	5.66923
2459.06	4.63048
2461.84	4.90139
2464.62	4.6696
2467.39	4.40173
2470.17	4.97285
2472.94	4.45822
2475.72	4.36187
2478.49	3.44779
2481.26	4.01033
2484.03	3.88379
2486.8	3.47848
2489.57	2.51922
2492.34	2.83325
2495.1	2.74604
2497.87	2.90603
2500.63	1.77183
2503.4	0.315375
2506.16	0.00145963
2508.92	-0.381616
2511.68	0.746987
2514.44	1.45763
2517.2	2.87495
2519.96	3.03989
2522.72	3.55514
2525.47	3.78797
2528.23	4.25529
2530.98	5.66949
2533.74	5.22353
2536.49	5.7303
2539.24	5.809
2541.99	5.68936
2544.74	6.36788
2547.49	6.29432
2550.23	7.10519
2552.98	6.47484
2555.72	6.5157
2558.47	6.21892
2561.21	6.57229
2563.95	6.81658
2566.69	6.54192
2569.43	6.91456
2572.17	6.81226
2574.91	6.63307
2577.65	6.83218
2580.39	7.35844
2583.12	7.29219
2585.85	7.35846
2588.59	6.6454
2591.32	6.62652
2594.05	7.14617
2596.78	6.47722
2599.51	5.29356
2602.24	3.67921
2604.97	2.44389
2607.69	1.79138
2610.42	1.85018
2613.14	2.01059
2615.87	2.18592
2618.59	2.15827
2621.31	1.83877
2624.03	2.41873
2626.75	2.93676
2629.47	2.76126
2632.19	2.74882
2634.91	3.67369
2637.62	4.22497
2640.34	4.67247
2643.05	5.22137
2645.76	6.65346
2648.48	7.41167
2651.19	8.76939
2653.9	8.68365
2656.6	8.01803
2659.31	7.63403
2662.02	7.27539
2664.73	6.89113
2667.43	6.6602
2670.14	7.20717
2672.84	7.33429
2675.54	8.13729
2678.24	8.29721
2680.94	7.87475
2683.64	6.95857
2686.34	6.58733
2689.04	5.47853
2691.74	6.10612
2694.43	4.75917
2697.13	5.59327
2699.82	6.04189
2702.51	7.23411
2705.21	8.28245
2707.9	8.46667
2710.58	10.0695
2713.27	11.5027
2715.96	11.4415
2718.65	13.2217
2721.33	13.2076
2724.02	13.8314
2726.71	14.3025
2729.39	15.5259
2732.07	15.5104
2734.75	15.9437
2737.43	16.0044
2740.11	15.301
2742.79	14.2848
2745.47	13.0584
2748.14	12.6054
2750.82	11.333
2753.49	10.247
2756.17	8.83923
2758.84	7.31825
2761.51	6.36691
2764.18	5.78767
2766.85	3.80332
2769.52	3.13201
2772.19	2.17778
2774.86	1.25821
2777.52	0.879267
2780.19	1.10959
2782.85	0.180963
2785.52	0.214391
2788.18	-0.00744813
2790.84	-0.658122
2793.5	-1.17885
2796.16	-0.602929
2798.82	-0.835933
2801.48	-0.17422
2804.13	-0.422853
2806.79	-0.914642
2809.45	-1.75149
2812.1	-1.38871
2814.75	-1.15775
2817.41	0.731742
2820.06	3.90817
2822.71	7.95926
2825.36	13.3653
2828	18.6448
2830.65	25.196
2833.3	32.2165
2835.94	40.4646
2838.59	49.5828
2841.23	58.1665
2843.87	68.358
2846.52	80.1181
2849.16	91.3533
2851.8	104.14
2854.44	117.461
2857.08	129.939
2859.71	142.915
2862.35	154.069
2864.98	163.284
2867.62	171.884
2870.25	179.967
2872.88	185.826
2875.52	191.859
2878.15	197.003
2880.78	202.98
2883.41	208.524
2886.03	215.091
2888.66	220.427
2891.29	225.268
2893.91	231.148
2896.54	238.541
2899.16	247.565
2901.78	256.884
2904.4	267.102
2907.02	280.607
2909.64	296.62
2912.26	311.624
2914.88	326.857
2917.5	340.79
2920.11	354.411
2922.73	365.12
2925.34	373.133
2927.96	377.2
2930.57	378.623
2933.18	378.173
2935.79	374.458
2938.4	369.15
2941.01	360.534
2943.62	351.232
2946.22	339.344
2948.83	325.613
2951.43	311.706
2954.04	295.844
2956.64	280.957
2959.24	266.002
2961.84	251.267
2964.45	237.625
2967.05	225.214
2969.64	213.141
2972.24	200.946
2974.84	188.036
2977.43	174.243
2980.03	160.563
2982.62	147.434
2985.22	134.647
2987.81	119.987
2990.4	105.994
2992.99	92.0865
2995.58	81.1557
2998.17	69.9062
3000.76	59.3375
3003.34	49.0353
3005.93	39.7372
3008.52	32.7875
3011.1	25.292
3013.68	20.0285
3016.27	15.9812
3018.85	11.5371
3021.43	8.79747
3024.01	5.73093
3026.59	4.51598
3029.16	5.01351
3031.74	4.73197
3034.32	4.91413
3036.89	6.05273
3039.47	8.32223
3042.04	9.23959
3044.61	9.54406
3047.18	11.6755
3049.75	11.3976
3052.32	11.5255
3054.89	12.0336
3057.46	13.5804
3060.03	11.8078
3062.59	11.231
3065.16	10.0649
3067.72	8.85505
3070.29	8.34286
3072.85	7.35774
3075.41	5.61038
3077.97	4.25688
3080.53	1.68534
3083.09	0.29358
3085.65	-1.51241
3088.21	-1.09427
3090.76	-0.28536
3093.32	-0.165665
3095.87	0.505477
3098.43	1.47497
3100.98	2.19453
3103.53	2.51303
3106.08	2.29872
3108.63	3.79756
3111.18	5.37238
3113.73	7.25717
3116.28	9.50099
3118.83	11.9256
3121.37	13.6975
3123.92	15.0679
3126.46	17.6591
3129	19.8404
3131.55	21.5017
3134.09	24.5811
3136.63	26.866
3139.17	29.3302
3141.71	31.8432
3144.24	34.5941
3146.78	37.807
3149.32	38.1863