File: data/Raman/poly_smoothed/Thy_10_08_27_1x_45s_532 nm_x100_100%_600 gr_mm_01.txt
#Acq. time (s)=	45
#Accumulations=	2
#Range (cm-¹)=	200...3150
#Windows=	2
#Auto scanning=	Off
#Autofocus=	Off
#Macrospot=	Off
#AutoExposure=	Off
#Spike filter=	Multiple accum.
#Delay time (s)=	0
#Binning=	1
#Readout mode=	Signal
#DeNoise=	Off
#ICS correction=	On
#Dark correction=	Off
#Inst. Process=	Off
#Detector Gain=	Best Dynamic Range
#Detector ADC=	20 kHz
#Detector temperature (°C)=	-69.85
#Instrument=	LabRAM HR Evol
#Detector=	Synapse
#Objective=	x100
#Grating=	600 gr/mm
#ND Filter=	100%
#Laser (nm)=	532
#Hole=	100.021
#Range=	Auto
#Laser Pol.=	No
#Raman. Pol.=	No
#Laser Pol. (°)=	-0.0007625
#Raman Pol. (°)=	89.9995
#Collection=	Microscope
#StageXY=	Marzhauser
#StageZ=	Marzhauser
#X (µm)=	2205.8
#Y (µm)=	1214.6
#Z (µm)=	442.15
#Full time(mm:ss)=	3:18
#Project=
#Sample=
#Site=
#Title=	Thy_10_08_27_2x_45s_532 nm_x100_100%_600 gr_mm
#Remark=
#Date=	05.07.2022 16:09
#Acquired=	05.07.2022 16:09:39
#Base:Fit=	10.08.2022 09:46:25
#Base:Sub=	10.08.2022 09:46:49
#Filter:Polynom=	16.08.2022 10:24:56
#AxisType[0]=Intens
#AxisUnit[0]=Cnt
#AxisType[1]=Spectr
#AxisUnit[1]=1/cm
200.43	2.7231
204.059	2.13297
207.688	2.54827
211.314	3.16242
214.941	3.45635
218.564	4.97066
222.186	6.52087
225.809	7.00062
229.428	8.13984
233.045	9.68958
236.663	9.17958
240.278	10.908
243.891	10.8419
247.503	11.5669
251.116	13.329
254.725	12.7895
258.333	14.9286
261.939	14.8825
265.544	15.4009
269.148	16.001
272.75	15.3429
276.351	15.9338
279.95	16.0088
283.548	15.1342
287.144	15.8692
290.739	17.1766
294.333	18.4475
297.925	20.6181
301.514	21.5048
305.104	23.7247
308.692	25.1981
312.279	26.1103
315.862	26.679
319.446	28.0899
323.029	26.5198
326.608	26.154
330.188	26.3922
333.766	26.9816
337.341	27.3475
340.917	28.346
344.489	27.3796
348.062	26.1163
351.631	23.2672
355.201	20.8283
358.768	19.194
362.333	16.2777
365.899	14.8389
369.462	13.1583
373.023	12.0345
376.585	11.9496
380.143	12.3561
383.7	12.7592
387.256	12.2807
390.812	11.2128
394.365	12.3544
397.916	12.5591
401.467	12.1211
405.015	10.8613
408.563	9.4928
412.109	9.23751
415.654	9.37545
419.197	10.5741
422.739	11.1423
426.279	11.537
429.819	12.2767
433.356	9.88371
436.891	9.21395
440.426	9.36332
443.96	8.5185
447.492	7.50439
451.021	7.98186
454.551	8.0925
458.079	10.6175
461.604	10.6303
465.13	11.5116
468.654	13.1742
472.175	13.4986
475.696	11.8356
479.215	14.0541
482.733	15.7429
486.249	15.7565
489.765	15.5807
493.278	15.5316
496.789	18.7968
500.301	19.6451
503.81	20.4406
507.317	21.5174
510.825	21.8767
514.33	21.4309
517.833	21.482
521.335	20.0418
524.836	20.5301
528.335	18.7799
531.835	16.6195
535.332	17.0621
538.827	16.8367
542.321	16.5672
545.814	15.1016
549.305	13.0825
552.795	11.406
556.282	9.34702
559.769	8.08708
563.255	7.81717
566.739	7.98746
570.223	7.66011
573.705	6.2026
577.183	5.76117
580.663	6.32903
584.141	6.6132
587.615	5.73121
591.09	6.52116
594.564	5.53661
598.035	4.45775
601.506	4.70789
604.974	4.27665
608.443	4.29709
611.908	4.96269
615.374	6.01221
618.837	7.40329
622.3	7.17252
625.761	7.47694
629.219	7.04927
632.677	7.83107
636.135	9.16774
639.59	10.4302
643.043	12.5456
646.495	13.5361
649.948	14.5477
653.398	14.4268
656.846	15.0944
660.293	15.2306
663.738	15.6611
667.183	16.768
670.626	17.9429
674.067	18.3878
677.508	19.397
680.947	19.2356
684.385	21.4069
687.821	22.575
691.254	22.9476
694.688	23.7704
698.121	25.4408
701.552	25.3026
704.98	26.1387
708.409	26.9546
711.836	28.5528
715.26	30.409
718.685	33.1741
722.108	35.8677
725.528	37.6193
728.949	39.2686
732.367	42.7028
735.785	44.1609
739.2	46.3724
742.614	49.1744
746.028	50.59
749.439	52.7712
752.849	55.1427
756.26	57.2984
759.667	59.9073
763.073	62.6133
766.477	64.9014
769.883	65.4847
773.285	66.6648
776.686	67.2946
780.085	68.0281
783.484	68.4309
786.881	68.7985
790.276	69.0609
793.671	69.1904
797.064	69.5368
800.456	71.4322
803.846	72.6763
807.234	73.1018
810.622	73.69
814.008	73.0768
817.394	74.5528
820.778	72.9313
824.159	72.3651
827.541	71.9652
830.921	69.3976
834.298	68.7164
837.676	67.3433
841.051	65.5739
844.426	64.7376
847.798	62.2094
851.171	58.2091
854.54	56.0815
857.911	54.1401
861.278	52.4475
864.645	49.7826
868.01	47.5429
871.373	46.9
874.735	47.7009
878.097	47.1307
881.457	46.8564
884.815	48.1908
888.172	47.7399
891.528	47.915
894.882	48.6284
898.237	48.9445
901.589	49.8511
904.94	49.5955
908.289	50.0742
911.635	49.2783
914.982	47.985
918.328	47.5749
921.672	45.7664
925.015	44.7052
928.357	43.0404
931.698	41.0039
935.035	39.5042
938.373	37.8701
941.71	34.2526
945.044	34.2223
948.378	32.7971
951.709	32.3983
955.041	31.4254
958.372	28.1747
961.699	24.3474
965.027	25.082
968.352	25.4408
971.676	26.1313
975	23.4475
978.322	25.5585
981.642	28.3956
984.962	29.8785
988.28	30.0258
991.596	29.0786
994.911	29.1213
998.227	28.7896
1001.54	28.9658
1004.85	28.1335
1008.16	29.3944
1011.47	28.4721
1014.78	26.4226
1018.08	25.7148
1021.39	24.0734
1024.69	23.1693
1028	22.0456
1031.3	18.8048
1034.6	15.9269
1037.9	12.6639
1041.19	9.6555
1044.49	7.64913
1047.78	6.96115
1051.08	4.82808
1054.37	4.23609
1057.66	3.29094
1060.95	3.77416
1064.24	2.798
1067.53	1.28656
1070.81	1.35598
1074.1	3.10098
1077.38	4.23103
1080.66	4.4836
1083.94	5.37303
1087.22	6.03829
1090.5	7.72891
1093.78	9.95032
1097.05	14.2059
1100.33	16.9354
1103.6	19.4562
1106.87	21.7543
1110.14	22.9358
1113.41	22.4991
1116.68	23.4305
1119.95	23.5671
1123.21	21.2339
1126.48	20.6897
1129.74	19.4017
1133	20.4514
1136.26	18.9021
1139.52	16.6515
1142.78	14.6286
1146.04	13.1318
1149.29	11.7587
1152.55	10.3771
1155.8	8.40228
1159.05	5.82836
1162.3	3.57617
1165.55	2.26188
1168.8	2.027
1172.05	3.49408
1175.29	6.03478
1178.54	6.68071
1181.78	7.33239
1185.02	7.37379
1188.26	7.98643
1191.5	9.71857
1194.74	10.6524
1197.97	12.8417
1201.21	15.6106
1204.44	20.2874
1207.68	25.5127
1210.91	29.6538
1214.14	33.4396
1217.37	37.5955
1220.59	41.9106
1223.82	45.0588
1227.05	48.432
1230.27	52.0023
1233.49	56.1714
1236.72	59.2704
1239.94	60.6926
1243.16	60.382
1246.37	60.757
1249.59	62.1252
1252.8	62.3286
1256.02	61.6989
1259.23	59.7048
1262.44	58.64
1265.66	58.711
1268.86	59.286
1272.07	57.7756
1275.28	58.3383
1278.48	61.1429
1281.69	63.6991
1284.89	66.1836
1288.09	67.2643
1291.29	70.1557
1294.49	73.6415
1297.69	76.2649
1300.89	79.3843
1304.08	83.6941
1307.28	85.2412
1310.47	88.4582
1313.66	89.8479
1316.85	90.6611
1320.04	90.0566
1323.23	89.9435
1326.42	89.8529
1329.61	89.7365
1332.79	88.0621
1335.97	84.9794
1339.16	83.4763
1342.34	82.351
1345.52	80.3506
1348.7	76.4913
1351.87	75.2343
1355.05	73.7552
1358.22	73.8108
1361.4	70.9227
1364.57	68.8366
1367.74	67.8384
1370.91	65.938
1374.08	64.8347
1377.25	62.7639
1380.41	61.7817
1383.58	60.3733
1386.74	59.11
1389.91	57.0248
1393.07	53.8771
1396.23	51.391
1399.39	50.017
1402.55	49.4316
1405.7	50.2201
1408.86	49.9929
1412.01	52.756
1415.17	55.3807
1418.32	59.6035
1421.47	63.9115
1424.62	68.722
1427.77	73.6517
1430.91	80.7972
1434.06	87.0017
1437.2	91.6026
1440.35	95.5791
1443.49	99.3884
1446.63	101.98
1449.77	103.098
1452.91	102.276
1456.05	101.266
1459.18	99.107
1462.32	94.8016
1465.45	87.7931
1468.59	80.1099
1471.72	73.4254
1474.85	67.917
1477.98	61.7913
1481.1	55.7377
1484.23	49.3777
1487.36	44.1887
1490.48	38.9741
1493.61	35.8503
1496.73	31.8718
1499.85	29.7736
1502.97	28.4917
1506.09	28.4731
1509.2	27.9903
1512.32	27.7883
1515.43	28.445
1518.55	29.0738
1521.66	31.2232
1524.77	33.1511
1527.88	35.2185
1530.99	39.5323
1534.1	43.9297
1537.21	47.6347
1540.31	51.3053
1543.42	54.7485
1546.52	59.3394
1549.62	64.5289
1552.72	68.9983
1555.82	73.4999
1558.92	78.9769
1562.02	82.1109
1565.11	86.9201
1568.21	91.1488
1571.3	94.6031
1574.39	97.1026
1577.49	100.08
1580.57	101.22
1583.66	102.349
1586.75	101.987
1589.84	103.298
1592.92	103.603
1596.01	102.385
1599.09	101.004
1602.17	98.8611
1605.25	95.6394
1608.33	93.9414
1611.41	91.6371
1614.49	90.7369
1617.57	88.6911
1620.64	87.486
1623.72	87.5057
1626.79	88.8295
1629.86	88.15
1632.93	89.3502
1636	89.3348
1639.07	90.4316
1642.13	92.5993
1645.2	93.5239
1648.26	95.3555
1651.33	97.4505
1654.39	97.7714
1657.45	97.6731
1660.51	97.8576
1663.57	96.2557
1666.63	93.8427
1669.68	89.7309
1672.74	85.6779
1675.79	81.7831
1678.85	76.982
1681.9	73.2601
1684.95	69.6273
1688	64.8985
1691.05	59.9817
1694.09	56.0456
1697.14	51.5735
1700.18	46.2541
1703.23	41.9312
1706.27	39.0758
1709.31	36.8894
1712.35	33.9563
1715.39	33.566
1718.43	32.0656
1721.47	31.8118
1724.5	30.5673
1727.54	30.0556
1730.57	29.1102
1733.61	28.509
1736.64	28.2413
1739.67	27.6541
1742.7	27.4678
1745.72	27.0567
1748.75	26.5228
1751.77	25.5303
1754.8	23.2844
1757.82	22.9566
1760.84	21.5706
1763.87	20.0769
1766.89	18.19
1769.91	16.2067
1772.92	14.561
1775.94	13.6174
1778.95	12.8361
1781.97	11.7104
1784.98	10.1748
1787.99	9.36105
1791.01	9.45758
1794.01	8.77753
1797.02	7.3174
1800.03	5.91922
1803.04	5.20542
1806.04	3.8815
1809.05	3.35557
1812.05	2.89813
1815.05	2.53086
1818.05	1.9734
1821.05	1.33303
1824.05	0.75202
1827.05	0.357225
1830.04	0.218869
1833.04	1.60621
1836.03	1.54158
1839.03	1.90406
1842.02	1.66297
1845.01	0.883376
1848	0.739885
1850.99	1.88669
1853.97	2.4956
1856.96	3.03622
1859.94	4.08336
1862.93	5.07993
1865.91	5.43648
1868.89	5.5247
1871.87	5.34449
1874.85	5.57864
1877.83	5.61672
1880.81	6.3191
1882.57	6.75324
1885.56	7.60773
1888.55	8.04697
1891.54	8.09303
1894.52	8.89746
1897.51	9.50843
1900.49	9.91619
1903.47	10.7
1906.45	10.4545
1909.43	8.63268
1912.41	7.90553
1915.39	6.51413
1918.37	6.07216
1921.34	6.56597
1924.32	5.80358
1927.29	5.2947
1930.26	4.65642
1933.23	4.90511
1936.2	4.95249
1939.17	4.25136
1942.14	3.59205
1945.11	3.42752
1948.07	4.66719
1951.04	5.49829
1954	5.65109
1956.96	5.42796
1959.93	5.01267
1962.89	5.90602
1965.85	6.38797
1968.8	5.98466
1971.76	6.94549
1974.72	6.78877
1977.67	6.38843
1980.63	6.29847
1983.58	6.28147
1986.53	5.81932
1989.48	7.13315
1992.43	7.93677
1995.38	7.69778
1998.32	9.23467
2001.27	9.39985
2004.22	10.149
2007.16	10.3654
2010.1	10.4944
2013.04	10.5815
2015.98	11.5992
2018.92	12.6952
2021.86	13.513
2024.8	14.5503
2027.74	13.8869
2030.67	15.3854
2033.61	15.7688
2036.54	15.0315
2039.47	13.8816
2042.4	14.1263
2045.33	13.7504
2048.26	12.9361
2051.19	12.258
2054.12	12.1772
2057.04	13.0722
2059.97	12.5818
2062.89	12.3085
2065.81	12.0814
2068.73	11.2505
2071.65	12.0852
2074.57	10.3753
2077.49	10.0183
2080.41	11.5743
2083.32	11.6576
2086.24	12.699
2089.15	13.2742
2092.07	14.3329
2094.98	15.7646
2097.89	16.8318
2100.8	16.9536
2103.71	17.3907
2106.61	17.7613
2109.52	18.5272
2112.43	18.8923
2115.33	19.5646
2118.23	20.4021
2121.13	21.6422
2124.04	23.3414
2126.94	25.1294
2129.83	25.6725
2132.73	25.8025
2135.63	26.5142
2138.53	27.9514
2141.42	28.2942
2144.31	29.4521
2147.21	29.0753
2150.1	30.2683
2152.99	31.3157
2155.88	31.0445
2158.77	32.0381
2161.65	32.0755
2164.54	31.7303
2167.43	31.9321
2170.31	32.7705
2173.19	32.875
2176.07	32.9877
2178.96	32.9004
2181.84	31.4711
2184.72	31.987
2187.59	32.6875
2190.47	32.2852
2193.35	32.9933
2196.22	32.6275
2199.09	32.3073
2201.97	32.1279
2204.84	30.5621
2207.71	30.8777
2210.58	29.0361
2213.45	27.1895
2216.31	26.5464
2219.18	25.1321
2222.05	24.0438
2224.91	23.9984
2227.78	23.0979
2230.64	22.5668
2233.5	21.8615
2236.36	21.6784
2239.22	21.9088
2242.08	22.0281
2244.93	21.6907
2247.79	22.2402
2250.64	21.9906
2253.5	22.1703
2256.35	22.9527
2259.2	23.3683
2262.05	22.9418
2264.9	22.6024
2267.75	22.4337
2270.6	21.5693
2273.45	21.4133
2276.29	21.4776
2279.14	19.7941
2281.98	18.5581
2284.82	18.8631
2287.66	18.0129
2290.5	16.905
2293.34	15.5109
2296.18	14.8666
2299.02	16.1464
2301.86	15.7036
2304.69	15.7907
2307.53	15.62
2310.36	16.0139
2313.19	16.5459
2316.02	15.7037
2318.85	15.268
2321.68	14.6765
2324.51	14.7995
2327.34	15.3622
2330.16	14.8513
2332.99	13.9067
2335.81	13.6944
2338.64	13.7182
2341.46	13.3103
2344.28	11.8702
2347.1	10.989
2349.92	10.5271
2352.74	10.0503
2355.55	10.5794
2358.37	9.11246
2361.19	9.02629
2364	9.9758
2366.81	10.8608
2369.62	11.153
2372.44	10.4532
2375.24	9.85857
2378.05	9.61816
2380.86	9.31137
2383.67	7.82166
2386.47	7.14702
2389.28	6.50744
2392.08	7.54514
2394.89	7.65921
2397.69	7.18985
2400.49	6.51704
2403.29	6.55207
2406.09	6.65828
2408.88	5.714
2411.68	5.18776
2414.48	5.83196
2417.27	6.91869
2420.06	6.74061
2422.86	8.02799
2425.65	8.134
2428.44	8.28891
2431.23	9.03202
2434.02	8.70609
2436.81	8.78325
2439.59	8.93667
2442.38	8.43028
2445.16	7.45272
2447.95	6.75651
2450.73	6.21246
2453.51	5.77528
2456.29	6.3918
2459.07	6.16701
2461.85	6.44295
2464.63	6.52401
2467.4	5.93151
2470.18	6.71284
2472.95	6.55557
2475.73	5.73198
2478.5	5.67469
2481.27	5.47766
2484.04	5.89441
2486.81	5.11709
2489.58	4.27591
2492.35	4.57748
2495.12	4.73708
2497.88	3.31603
2500.65	3.43698
2503.41	3.60512
2506.17	3.19762
2508.94	1.65526
2511.7	1.47722
2514.46	0.982921
2517.22	1.05079
2519.97	1.33022
2522.73	0.580304
2525.49	0.199351
2528.24	-0.34096
2530.99	-0.368683
2533.75	-0.557648
2536.5	0.376526
2539.25	0.112953
2542	-0.200055
2544.75	-0.818066
2547.5	-0.733677
2550.24	-0.325061
2552.99	0.0192094
2555.74	0.466278
2558.48	0.740777
2561.22	1.39681
2563.96	1.5522
2566.71	1.76088
2569.45	2.71075
2572.18	1.98758
2574.92	2.43912
2577.66	2.68851
2580.4	3.55038
2583.13	3.5953
2585.87	2.3886
2588.6	1.24999
2591.33	0.961468
2594.06	0.378414
2596.79	0.228553
2599.52	0.81458
2602.25	0.944521
2604.98	0.862266
2607.71	0.362919
2610.43	0.467948
2613.16	-0.138993
2615.88	0.140758
2618.6	-0.322087
2621.32	-0.223152
2624.04	0.154652
2626.76	0.756406
2629.48	1.56077
2632.2	2.61248
2634.92	2.70011
2637.63	3.65212
2640.35	3.52721
2643.06	4.15685
2645.77	4.30377
2648.49	5.37988
2651.2	4.44403
2653.91	3.80683
2656.62	4.82564
2659.33	5.10434
2662.03	5.43312
2664.74	5.56401
2667.44	5.36732
2670.15	4.7739
2672.85	4.09458
2675.55	3.5443
2678.26	2.47691
2680.96	2.7947
2683.66	3.26646
2686.35	3.35802
2689.05	3.55541
2691.75	4.7959
2694.44	5.71151
2697.14	7.0006
2699.83	8.52486
2702.52	8.37051
2705.22	9.17192
2707.91	9.46269
2710.6	9.79706
2713.29	10.1162
2715.97	9.37391
2718.66	10.7435
2721.35	10.7869
2724.03	10.9556
2726.72	10.7494
2729.4	11.1048
2732.08	10.2997
2734.76	10.6545
2737.44	9.84798
2740.12	9.59376
2742.8	9.78864
2745.48	10.0543
2748.16	9.38292
2750.83	7.8204
2753.51	7.44161
2756.18	7.70539
2758.85	7.25085
2761.53	7.95514
2764.2	8.51655
2766.87	8.60874
2769.54	7.97148
2772.2	6.77725
2774.87	5.79566
2777.54	5.7206
2780.2	5.03613
2782.87	5.25719
2785.53	5.05371
2788.19	4.95752
2790.85	4.73846
2793.51	4.74326
2796.17	5.48653
2798.83	5.21257
2801.49	5.84992
2804.15	5.03608
2806.8	5.81356
2809.46	5.66546
2812.11	4.70068
2814.76	5.33711
2817.42	6.71134
2820.07	9.59701
2822.72	12.6636
2825.37	15.6011
2828.02	19.8417
2830.66	22.9694
2833.31	27.474
2835.96	32.2529
2838.6	37.236
2841.24	42.1191
2843.89	49.4717
2846.53	56.3157
2849.17	64.5
2851.81	74.7763
2854.45	84.1573
2857.09	92.5551
2859.72	101.821
2862.36	109.912
2865	117.01
2867.63	123.72
2870.26	130.77
2872.9	136.606
2875.53	141.661
2878.16	146.852
2880.79	150.613
2883.42	154.442
2886.05	158.606
2888.67	162.163
2891.3	164.717
2893.92	168.514
2896.55	173.637
2899.17	180.779
2901.79	186.378
2904.42	192.507
2907.04	200.542
2909.66	210.996
2912.27	221.74
2914.89	233.337
2917.51	243.884
2920.13	253.233
2922.74	260.266
2925.35	265.971
2927.97	268.765
2930.58	270.449
2933.19	271.81
2935.8	270.221
2938.41	266.802
2941.02	262.108
2943.63	255.283
2946.24	247.439
2948.84	240.179
2951.45	231.359
2954.05	221.644
2956.65	212.289
2959.26	204.865
2961.86	195.351
2964.46	186.478
2967.06	176.496
2969.66	168.769
2972.25	160.847
2974.85	152.991
2977.45	145.669
2980.04	138.264
2982.64	130.086
2985.23	121.085
2987.82	112.59
2990.41	104.547
2993	95.4433
2995.59	88.1159
2998.18	80.5783
3000.77	72.8673
3003.36	66.6474
3005.94	59.2412
3008.53	53.8845
3011.11	50.0173
3013.69	45.9741
3016.28	41.6336
3018.86	38.7388
3021.44	36.0651
3024.02	33.3295
3026.6	30.3781
3029.18	28.7541
3031.75	26.7017
3034.33	26.0706
3036.9	25.1594
3039.48	25.2359
3042.05	26.3509
3044.62	27.325
3047.19	28.0241
3049.77	28.8877
3052.34	29.345
3054.9	29.4604
3057.47	28.692
3060.04	28.2652
3062.61	28.1152
3065.17	27.2757
3067.74	25.6057
3070.3	23.5974
3072.86	22.325
3075.42	21.1967
3077.99	18.7318
3080.54	16.7327
3083.1	13.8322
3085.66	11.205
3088.22	8.96058
3090.78	7.64541
3093.33	5.2847
3095.89	2.97595
3098.44	2.5357
3100.99	1.83502
3103.54	1.56477
3106.1	1.35036
3108.65	0.558924
3111.2	-0.354404
3113.74	-0.0827794
3116.29	-0.317421
3118.84	-0.316656
3121.38	-0.26232
3123.93	0.124807
3126.47	-0.166054
3129.01	-0.0692909
3131.56	-0.15071
3134.1	1.33628
3136.64	1.62708
3139.18	2.32182
3141.72	2.22903
3144.26	2.98069
3146.79	3.79124
3149.33	2.86611