File: data/Raman/poly_smoothed/Thy_50_12_12_1x_45s_532 nm_x100_100%_600 gr_mm_01.txt
#Acq. time (s)=	45
#Accumulations=	2
#Range (cm-¹)=	200...3150
#Windows=	2
#Auto scanning=	Off
#Autofocus=	Off
#Macrospot=	Off
#AutoExposure=	Off
#Spike filter=	Multiple accum.
#Delay time (s)=	0
#Binning=	1
#Readout mode=	Signal
#DeNoise=	Off
#ICS correction=	On
#Dark correction=	Off
#Inst. Process=	Off
#Detector Gain=	Best Dynamic Range
#Detector ADC=	20 kHz
#Detector temperature (°C)=	-69.85
#Instrument=	LabRAM HR Evol
#Detector=	Synapse
#Objective=	x100
#Grating=	600 gr/mm
#ND Filter=	100%
#Laser (nm)=	532
#Hole=	100.021
#Range=	Auto
#Laser Pol.=	No
#Raman. Pol.=	No
#Laser Pol. (°)=	-0.0007625
#Raman Pol. (°)=	89.9995
#Collection=	Microscope
#StageXY=	Marzhauser
#StageZ=	Marzhauser
#X (µm)=	-5112.1
#Y (µm)=	1511.6
#Z (µm)=	62.85
#Full time(mm:ss)=	3:18
#Project=
#Sample=
#Site=
#Title=	Thy_50_12_12_2x_45s_532 nm_x100_100%_600 gr_mm
#Remark=
#Date=	07.07.2022 10:06
#Acquired=	07.07.2022 10:06:19
#Base:Fit=	10.08.2022 10:04:29
#Base:Sub=	10.08.2022 10:04:45
#Filter:Polynom=	16.08.2022 10:20:24
#AxisType[0]=Intens
#AxisUnit[0]=Cnt
#AxisType[1]=Spectr
#AxisUnit[1]=1/cm
200.43	43.2017
204.061	38.9642
207.688	35.0544
211.316	31.9449
214.941	28.9526
218.566	27.4931
222.188	25.9449
225.809	24.7038
229.43	23.2665
233.047	20.5127
236.663	19.3411
240.278	16.5481
243.894	14.7661
247.506	14.5248
251.116	13.3707
254.725	11.4207
258.333	9.63498
261.939	9.42447
265.546	8.87016
269.15	8.06864
272.752	6.99852
276.353	6.55971
279.952	6.21081
283.55	5.31913
287.146	5.58397
290.739	4.93205
294.333	4.37583
297.925	4.94992
301.516	4.15795
305.106	3.86661
308.694	5.09281
312.279	3.58205
315.864	2.24244
319.448	1.45725
323.029	1.44735
326.61	3.07402
330.19	2.25487
333.766	3.83961
337.343	3.19399
340.917	1.7449
344.491	1.3358
348.062	3.57175
351.633	5.93535
355.201	7.26192
358.77	6.62281
362.335	7.13051
365.899	7.47541
369.464	7.30566
373.025	6.93127
376.585	6.62026
380.143	5.85338
383.702	5.64701
387.258	4.12102
390.812	2.57604
394.365	2.18064
397.916	1.51193
401.467	2.38415
405.015	2.88552
408.565	4.29037
412.111	4.2165
415.656	5.23564
419.197	5.4999
422.739	5.46777
426.279	5.88086
429.819	6.95225
433.356	8.67031
436.893	7.83643
440.428	7.34137
443.96	7.54123
447.492	7.60449
451.023	7.05011
454.553	8.5363
458.079	8.63606
461.606	8.74731
465.132	10.9616
468.654	11.3098
472.177	11.4084
475.696	12.5118
479.217	14.6279
482.733	15.6243
486.251	18.2433
489.765	20.041
493.278	20.9021
496.791	21.5692
500.301	24.4163
503.81	23.4727
507.319	22.9983
510.825	24.9077
514.33	25.6008
517.833	25.674
521.337	22.2662
524.838	21.3237
528.337	21.7417
531.835	20.3785
535.332	20.3337
538.827	19.033
542.321	18.8792
545.814	18.9326
549.305	19.916
552.795	18.92
556.284	17.1992
559.771	16.1197
563.257	15.8879
566.742	14.6065
570.223	12.7026
573.705	11.2414
577.185	10.1212
580.665	9.51268
584.141	8.12799
587.617	7.99582
591.092	6.21623
594.564	7.31759
598.037	7.20351
601.506	7.39769
604.976	6.05828
608.443	7.51861
611.91	7.44464
615.374	8.84489
618.839	10.9029
622.3	12.1937
625.761	13.3387
629.221	13.5269
632.679	15.0543
636.135	16.6864
639.592	16.8518
643.045	17.5269
646.497	19.1273
649.948	19.5445
653.398	20.694
656.846	22.3983
660.293	25.5093
663.738	28.0531
667.185	28.7966
670.628	31.5368
674.067	34.2491
677.508	35.244
680.947	36.3485
684.385	38.7384
687.821	40.2848
691.256	41.7215
694.69	42.3307
698.121	43.1001
701.552	44.6724
704.982	43.7382
708.41	43.6906
711.836	43.3773
715.262	43.2308
718.685	44.3154
722.108	42.6173
725.53	43.1222
728.949	46.2389
732.369	47.3316
735.785	48.9072
739.2	51.8549
742.616	53.8272
746.028	57.379
749.441	60.2401
752.851	63.0836
756.26	65.9807
759.667	68.6607
763.075	70.5209
766.479	72.549
769.883	77.2071
773.285	79.212
776.686	79.9621
780.085	81.3475
783.484	81.8433
786.881	83.6367
790.276	86.79
793.671	86.8303
797.064	86.6021
800.456	86.1733
803.846	85.2514
807.236	84.9573
810.624	86.6052
814.01	85.9446
817.394	85.1526
820.778	85.224
824.161	83.6936
827.543	84.7899
830.921	81.5455
834.3	78.4899
837.676	76.5466
841.053	73.8878
844.426	70.804
847.8	69.1681
851.171	67.6974
854.542	65.5977
857.911	63.3644
861.279	62.7348
864.645	62.4052
868.01	61.4566
871.375	60.7682
874.737	60.6149
878.097	57.1347
881.457	56.5668
884.817	55.1626
888.174	55.1699
891.53	55.1936
894.884	53.5354
898.237	53.7863
901.589	54.1152
904.94	52.3812
908.289	51.9316
911.637	49.6156
914.984	48.7968
918.33	48.0323
921.674	45.874
925.015	43.8755
928.357	42.9098
931.698	41.46
935.037	40.4512
938.373	40.5852
941.71	39.9423
945.046	38.0441
948.378	37.2284
951.711	37.3963
955.043	37.5664
958.372	36.1969
961.701	35.394
965.027	34.9482
968.354	35.0926
971.678	36.8708
975	36.8155
978.324	37.8232
981.644	38.1062
984.962	37.7819
988.282	38.4318
991.598	38.1405
994.913	37.7312
998.227	36.7079
1001.54	34.6496
1004.85	33.6457
1008.16	32.7558
1011.47	30.9793
1014.78	29.9301
1018.08	29.7982
1021.39	28.0358
1024.69	28.9564
1028	31.1823
1031.3	31.8947
1034.6	31.6087
1037.9	30.0756
1041.19	29.5762
1044.49	30.0678
1047.79	30.5355
1051.08	29.5136
1054.37	27.7718
1057.66	25.0392
1060.95	22.6926
1064.24	21.3267
1067.53	21.7575
1070.81	19.7402
1074.1	17.349
1077.38	16.136
1080.66	15.644
1083.94	14.1839
1087.22	13.8614
1090.5	12.1968
1093.78	12.126
1097.05	13.5193
1100.33	14.4572
1103.6	16.1964
1106.87	18.1434
1110.15	19.2727
1113.41	20.4296
1116.68	21.3494
1119.95	22.2847
1123.21	23.1572
1126.48	22.2773
1129.74	20.4573
1133	19.087
1136.26	17.7123
1139.52	13.9669
1142.78	14.5347
1146.04	13.0505
1149.29	11.674
1152.55	9.11452
1155.8	8.4279
1159.05	6.38205
1162.3	4.94359
1165.55	3.78763
1168.8	3.77202
1172.05	3.3509
1175.29	4.28244
1178.54	2.86244
1181.78	3.56259
1185.02	4.15602
1188.26	4.35073
1191.5	5.23407
1194.74	6.3707
1197.97	6.35345
1201.21	8.30333
1204.44	9.54412
1207.68	10.2729
1210.91	12.0681
1214.14	14.0883
1217.37	15.0612
1220.6	17.4927
1223.82	21.2162
1227.05	23.775
1230.27	25.7928
1233.49	28.8653
1236.72	33.3273
1239.94	35.9701
1243.16	41.0695
1246.37	43.7492
1249.59	45.769
1252.8	47.2875
1256.02	49.2218
1259.23	49.7879
1262.44	50.2952
1265.66	50.8023
1268.87	52.0958
1272.07	53.8348
1275.28	56.7576
1278.48	58.1172
1281.69	60.2844
1284.89	61.7831
1288.09	63.5534
1291.3	65.524
1294.49	66.0516
1297.69	65.8262
1300.89	67.4663
1304.09	67.7819
1307.28	70.2971
1310.47	69.9651
1313.66	72.3041
1316.86	71.8316
1320.05	71.2847
1323.23	70.3128
1326.42	67.7289
1329.61	66.0414
1332.79	63.7823
1335.98	61.5118
1339.16	57.7375
1342.34	55.6752
1345.52	54.0929
1348.7	54.5359
1351.87	52.7599
1355.05	52.109
1358.23	49.7903
1361.4	50.3915
1364.57	47.7899
1367.74	46.9944
1370.91	46.8945
1374.08	45.9948
1377.25	45.3651
1380.42	46.0244
1383.58	46.343
1386.75	46.2453
1389.91	45.948
1393.07	45.1405
1396.23	43.881
1399.39	42.9471
1402.55	42.1615
1405.7	43.1245
1408.86	44.2872
1412.01	45.1712
1415.17	47.1834
1418.32	51.7393
1421.47	54.8289
1424.62	60.362
1427.77	65.8217
1430.92	69.388
1434.06	73.1492
1437.2	77.8682
1440.35	81.1321
1443.49	83.0108
1446.63	86.1218
1449.77	86.5398
1452.91	86.8759
1456.05	85.0267
1459.18	82.5304
1462.32	79.3305
1465.45	74.6119
1468.59	67.883
1471.72	62.1251
1474.85	56.6436
1477.98	51.1522
1481.11	46.5265
1484.23	41.1437
1487.36	37.2176
1490.48	33.6093
1493.61	31.7576
1496.73	29.9754
1499.85	29.0253
1502.97	29.6135
1506.09	28.7031
1509.2	29.2518
1512.32	30.386
1515.44	31.6005
1518.55	31.8779
1521.66	32.3497
1524.77	32.3515
1527.88	33.1584
1530.99	33.6168
1534.1	33.0903
1537.21	33.9948
1540.31	36.7157
1543.42	38.4079
1546.52	41.0675
1549.62	43.8687
1552.72	45.9776
1555.82	49.1357
1558.92	52.8225
1562.02	54.4106
1565.11	58.3753
1568.21	60.6723
1571.3	65.9726
1574.39	67.4473
1577.49	71.1867
1580.58	74.0693
1583.67	76.338
1586.75	78.8314
1589.84	79.7763
1592.93	79.3452
1596.01	77.2836
1599.09	75.8329
1602.18	73.6353
1605.26	72.3457
1608.34	70.4119
1611.41	69.3017
1614.49	68.6892
1617.57	68.584
1620.64	67.4474
1623.72	68.4927
1626.79	68.8945
1629.86	70.1241
1632.93	72.4576
1636	73.3309
1639.07	73.7839
1642.14	75.7536
1645.2	77.5835
1648.27	78.8016
1651.33	79.9722
1654.39	80.3601
1657.45	79.9263
1660.51	79.929
1663.57	77.1325
1666.63	73.6008
1669.69	71.0848
1672.74	67.5681
1675.79	62.8849
1678.85	59.1227
1681.9	55.0669
1684.95	50.867
1688	45.7166
1691.05	40.8444
1694.1	37.1747
1697.14	34.3199
1700.19	30.8111
1703.23	27.8836
1706.27	25.903
1709.32	22.2479
1712.35	19.6764
1715.39	18.7349
1718.43	18.2417
1721.47	18.0348
1724.5	17.3874
1727.54	15.526
1730.57	13.7544
1733.61	13.0705
1736.64	13.2561
1739.67	12.54
1742.7	13.6095
1745.72	13.6906
1748.75	13.4285
1751.78	12.9643
1754.8	13.0949
1757.82	12.134
1760.85	11.511
1763.87	10.4102
1766.89	10.5905
1769.91	9.55483
1772.92	7.99904
1775.94	7.5045
1778.96	6.56429
1781.97	5.27025
1784.98	5.72809
1788	6.23225
1791.01	7.62401
1794.01	7.97218
1797.02	7.75372
1800.03	7.43467
1803.04	7.60306
1806.04	8.71691
1809.05	10.2812
1812.05	11.0129
1815.05	10.5857
1818.05	9.4291
1821.05	9.86187
1824.05	10.017
1827.05	9.51754
1830.04	9.44945
1833.04	9.31487
1836.03	8.80029
1839.03	7.96618
1842.02	7.4404
1845.01	7.08749
1848	7.10589
1850.99	6.43007
1853.97	6.6908
1856.96	5.78224
1859.94	5.9553
1862.93	5.44177
1865.91	5.45228
1868.89	5.07194
1871.87	4.08034
1874.85	3.09379
1877.83	2.69584
1880.81	2.75248
1882.56	2.63543
1885.55	0.364955
1888.54	0.435947
1891.52	-0.528058
1894.51	-0.00947633
1897.49	-0.0496746
1900.48	-0.491879
1903.46	-0.0183011
1906.44	0.862368
1909.42	0.776446
1912.4	0.80763
1915.38	2.45535
1918.35	4.2255
1921.33	4.12219
1924.3	5.2883
1927.28	5.49352
1930.25	5.26917
1933.22	6.64189
1936.19	7.15574
1939.16	7.04255
1942.13	6.85313
1945.09	5.90489
1948.06	5.56541
1951.03	5.81734
1953.99	6.43197
1956.95	6.83372
1959.91	5.42607
1962.87	5.64364
1965.83	5.05403
1968.79	5.30475
1971.75	5.63149
1974.7	6.87484
1977.66	6.54008
1980.61	5.54514
1983.56	5.15617
1986.52	5.5938
1989.47	6.32295
1992.41	6.03861
1995.36	6.09497
1998.31	6.05952
2001.26	5.73045
2004.2	5.71987
2007.15	5.43249
2010.09	4.26818
2013.03	4.38529
2015.97	4.19063
2018.91	3.74312
2021.85	4.24736
2024.79	4.50775
2027.72	4.84761
2030.66	3.77037
2033.59	2.7306
2036.53	3.25342
2039.46	4.3324
2042.39	5.50096
2045.32	6.11335
2048.25	6.13754
2051.18	6.37281
2054.1	7.27367
2057.03	8.53684
2059.95	9.94932
2062.88	10.9761
2065.8	13.3194
2068.72	12.792
2071.64	12.9694
2074.56	14.3198
2077.48	15.729
2080.39	15.6434
2083.31	15.8247
2086.22	16.9909
2089.14	17.3335
2092.05	18.7806
2094.96	19.2242
2097.87	20.1238
2100.78	21.2877
2103.69	22.7579
2106.6	25.3787
2109.51	27.6148
2112.41	30.1153
2115.32	31.5655
2118.22	34.9531
2121.12	37.2229
2124.02	40.6911
2126.92	44.7046
2129.82	48.3844
2132.72	51.7607
2135.62	55.2484
2138.51	58.0604
2141.41	60.3382
2144.3	63.6629
2147.19	67.0385
2150.09	69.2679
2152.97	71.7523
2155.86	73.6048
2158.75	75.5112
2161.64	78.1012
2164.53	79.8726
2167.41	81.4212
2170.3	83.4632
2173.18	82.9662
2176.06	82.4269
2178.94	81.2441
2181.82	79.1772
2184.7	76.4195
2187.58	74.0216
2190.46	72.5852
2193.33	69.6842
2196.21	67.6272
2199.08	65.3056
2201.95	62.7789
2204.83	60.136
2207.7	56.5875
2210.57	53.653
2213.43	50.548
2216.3	48.2002
2219.17	44.8373
2222.03	41.801
2224.9	39.0821
2227.76	37.6236
2230.62	36.2063
2233.49	33.829
2236.34	31.9207
2239.2	29.8791
2242.06	27.0656
2244.92	24.5822
2247.78	23.3029
2250.63	21.172
2253.48	19.4514
2256.34	17.4073
2259.19	17.5945
2262.04	16.2602
2264.89	15.7835
2267.74	15.0169
2270.59	15.1859
2273.43	14.7164
2276.28	13.7485
2279.12	11.5323
2281.97	10.2323
2284.81	9.80163
2287.65	9.23098
2290.49	7.54219
2293.33	6.75596
2296.17	7.11471
2299.01	7.04335
2301.84	6.92411
2304.68	7.17106
2307.51	7.47514
2310.35	7.66353
2313.18	7.87339
2316.01	7.25014
2318.84	6.98611
2321.67	7.41857
2324.5	7.28308
2327.33	7.80669
2330.15	8.06719
2332.98	6.8552
2335.8	7.49531
2338.62	6.34136
2341.45	5.05196
2344.27	4.16729
2347.09	2.72507
2349.91	1.30081
2352.72	-0.135947
2355.54	-0.1133
2358.36	-1.37395
2361.17	-2.51916
2363.98	-2.24082
2366.8	-1.32743
2369.61	-0.658422
2372.42	-0.0620955
2375.23	-0.0767202
2378.04	-0.0509072
2380.85	-0.142743
2383.66	0.767765
2386.46	0.794869
2389.26	2.59062
2392.07	4.00569
2394.87	3.84446
2397.67	4.31862
2400.47	3.23679
2403.27	3.88588
2406.07	4.01182
2408.87	3.74548
2411.67	5.03445
2414.46	5.78653
2417.26	5.72036
2420.05	6.7418
2422.84	6.53401
2425.64	7.90703
2428.43	7.21
2431.22	6.23301
2434.01	6.8796
2436.79	7.26031
2439.58	7.28677
2442.37	7.39184
2445.15	6.52549
2447.93	5.86218
2450.72	5.46705
2453.5	5.44392
2456.28	6.24682
2459.06	6.24186
2461.84	5.62121
2464.62	5.04019
2467.39	4.91094
2470.17	4.86931
2472.94	5.28249
2475.72	5.54045
2478.49	6.56782
2481.26	7.37124
2484.03	6.49894
2486.8	6.60584
2489.57	6.12931
2492.34	6.44093
2495.1	6.50451
2497.87	4.9657
2500.63	4.18676
2503.4	4.68652
2506.16	4.75449
2508.92	4.2961
2511.68	3.86869
2514.44	3.76583
2517.2	3.77761
2519.96	3.59177
2522.72	4.03059
2525.47	3.50014
2528.23	3.2627
2530.98	3.28263
2533.74	3.18862
2536.49	3.74735
2539.24	4.66699
2541.99	5.26505
2544.74	6.02648
2547.49	5.82325
2550.23	5.8229
2552.98	6.10373
2555.72	8.03085
2558.47	9.03417
2561.21	9.34636
2563.95	8.80532
2566.69	8.17836
2569.43	8.10433
2572.17	8.22729
2574.91	8.17813
2577.65	8.21002
2580.39	8.57665
2583.12	7.81852
2585.85	7.57147
2588.59	6.99963
2591.32	6.80914
2594.05	6.32599
2596.78	6.44956
2599.51	7.11201
2602.24	7.09036
2604.97	6.96312
2607.69	6.66433
2610.42	7.10313
2613.14	6.65574
2615.87	6.78154
2618.59	7.31767
2621.31	8.78825
2624.03	8.81893
2626.75	8.6196
2629.47	7.56196
2632.19	5.96244
2634.91	4.81321
2637.62	3.96418
2640.34	3.95555
2643.05	3.78032
2645.76	4.27983
2648.48	4.58514
2651.19	4.78874
2653.9	5.28096
2656.6	6.27135
2659.31	6.59242
2662.02	6.41145
2664.73	7.21725
2667.43	7.38344
2670.14	8.34354
2672.84	8.24078
2675.54	8.3035
2678.24	8.9114
2680.94	9.73197
2683.64	9.97271
2686.34	10.0172
2689.04	9.64229
2691.74	8.85409
2694.43	8.38349
2697.13	7.20703
2699.82	7.08453
2702.51	7.44541
2705.21	8.84692
2707.9	9.67461
2710.58	9.90172
2713.27	10.2622
2715.96	10.3129
2718.65	10.341
2721.33	10.4327
2724.02	9.96724
2726.71	8.45441
2729.39	7.38245
2732.07	7.15997
2734.75	6.87739
2737.43	7.201
2740.11	5.88421
2742.79	6.01995
2745.47	6.41937
2748.14	5.43241
2750.82	3.73533
2753.49	3.92927
2756.17	3.5583
2758.84	2.63595
2761.51	3.1724
2764.18	4.62885
2766.85	5.19758
2769.52	6.05813
2772.19	6.55834
2774.86	5.62424
2777.52	4.97891
2780.19	4.70049
2782.85	4.66558
2785.52	5.08209
2788.18	4.57752
2790.84	4.09134
2793.5	2.54266
2796.16	1.77151
2798.82	1.99013
2801.48	2.12838
2804.13	1.46086
2806.79	0.465508
2809.45	-0.744788
2812.1	-1.69335
2814.75	-2.53514
2817.41	-0.872582
2820.06	-0.0169501
2822.71	1.51876
2825.36	4.7434
2828	10.0176
2830.65	14.2116
2833.3	19.1598
2835.94	24.4818
2838.59	28.6955
2841.23	33.1332
2843.87	39.0011
2846.52	45.2372
2849.16	52.7473
2851.8	60.1658
2854.44	68.4519
2857.08	76.0218
2859.71	82.5981
2862.35	89.406
2864.98	95.9388
2867.62	100.439
2870.25	104.347
2872.88	108.385
2875.52	111.847
2878.15	115.276
2880.78	119.076
2883.41	123.202
2886.03	125.839
2888.66	129.389
2891.29	132.003
2893.91	134.83
2896.54	137.994
2899.16	141.497
2901.78	145.386
2904.4	149.915
2907.02	156.161
2909.64	163.969
2912.26	171.516
2914.88	179.615
2917.5	188.375
2920.11	194.635
2922.73	199.955
2925.34	204.394
2927.96	206.993
2930.57	208.24
2933.18	208.658
2935.79	208.718
2938.4	205.544
2941.01	202.375
2943.62	197.172
2946.22	190.875
2948.83	183.458
2951.43	175.885
2954.04	167.187
2956.64	159.031
2959.24	151.326
2961.84	142.867
2964.45	135.825
2967.05	127.935
2969.64	120.23
2972.24	113.305
2974.84	105.962
2977.43	99.4833
2980.03	92.314
2982.62	84.9497
2985.22	77.9625
2987.81	71.2079
2990.4	64.5476
2992.99	58.6767
2995.58	52.2733
2998.17	45.9916
3000.76	38.6906
3003.34	33.2622
3005.93	27.798
3008.52	23.2995
3011.1	20.0052
3013.68	15.5686
3016.27	12.6488
3018.85	9.62131
3021.43	6.59069
3024.01	3.56977
3026.59	2.38854
3029.16	1.49077
3031.74	0.823864
3034.32	0.279893
3036.89	0.879026
3039.47	2.06889
3042.04	3.04141
3044.61	4.10742
3047.18	5.30342
3049.75	6.62245
3052.32	7.753
3054.89	8.38237
3057.46	8.74745
3060.03	8.23134
3062.59	8.03675
3065.16	8.6326
3067.72	8.60672
3070.29	7.80786
3072.85	7.5008
3075.41	6.88194
3077.97	5.7524
3080.53	4.49565
3083.09	3.32711
3085.65	1.5087
3088.21	1.02764
3090.76	0.166973
3093.32	-0.712843
3095.87	-0.954524
3098.43	0.510443
3100.98	1.09315
3103.53	2.12914
3106.08	3.69644
3108.63	4.98317
3111.18	6.01029
3113.73	8.33437
3116.28	9.77954
3118.83	11.7075
3121.37	13.5814
3123.92	15.1372
3126.46	17.6373
3129	19.4349
3131.55	22.1264
3134.09	24.0563
3136.63	25.7723
3139.17	26.8198
3141.71	26.9227
3144.24	27.3335
3146.78	27.2543
3149.32	28.6382