File: data/Raman/poly_smoothed/Thy_40_11_24_1x_45s_532 nm_x100_100%_600 gr_mm_01.txt
#Acq. time (s)=	45
#Accumulations=	2
#Range (cm-¹)=	200...3150
#Windows=	2
#Auto scanning=	Off
#Autofocus=	Off
#Macrospot=	Off
#AutoExposure=	Off
#Spike filter=	Multiple accum.
#Delay time (s)=	0
#Binning=	1
#Readout mode=	Signal
#DeNoise=	Off
#ICS correction=	On
#Dark correction=	Off
#Inst. Process=	Off
#Detector Gain=	Best Dynamic Range
#Detector ADC=	20 kHz
#Detector temperature (°C)=	-69.85
#Instrument=	LabRAM HR Evol
#Detector=	Synapse
#Objective=	x100
#Grating=	600 gr/mm
#ND Filter=	100%
#Laser (nm)=	532
#Hole=	100.021
#Range=	Auto
#Laser Pol.=	No
#Raman. Pol.=	No
#Laser Pol. (°)=	-0.0007625
#Raman Pol. (°)=	89.9995
#Collection=	Microscope
#StageXY=	Marzhauser
#StageZ=	Marzhauser
#X (µm)=	1955.2
#Y (µm)=	-51.4
#Z (µm)=	425.15
#Full time(mm:ss)=	3:19
#Project=
#Sample=
#Site=
#Title=	Thy_40_11_24_2x_45s_532 nm_x100_100%_600 gr_mm
#Remark=
#Date=	05.07.2022 11:34
#Acquired=	05.07.2022 11:34:36
#Base:Fit=	10.08.2022 10:01:35
#Base:Sub=	10.08.2022 10:01:52
#Filter:Polynom=	16.08.2022 10:21:53
#AxisType[0]=Intens
#AxisUnit[0]=Cnt
#AxisType[1]=Spectr
#AxisUnit[1]=1/cm
200.43	22.9516
204.059	21.9498
207.688	22.579
211.314	22.3005
214.941	21.8988
218.564	19.1336
222.186	16.8173
225.809	15.3025
229.428	15.1779
233.045	12.714
236.663	12.1022
240.278	11.6759
243.891	9.95461
247.503	9.10928
251.116	10.5368
254.725	11.8359
258.333	11.8956
261.939	11.9626
265.544	12.2007
269.148	10.6626
272.75	11.645
276.351	10.8415
279.95	12.8462
283.548	14.0892
287.144	13.6152
290.739	12.6499
294.333	11.9749
297.925	10.9654
301.514	11.416
305.104	10.4416
308.692	9.70593
312.279	9.9036
315.862	10.6236
319.446	8.74528
323.029	8.33594
326.608	7.66889
330.188	8.66465
333.766	9.72837
337.341	10.7719
340.917	11.6336
344.489	10.9869
348.062	10.4033
351.631	8.6086
355.201	8.0166
358.768	8.28361
362.333	8.65916
365.899	9.22964
369.462	7.31391
373.023	5.75326
376.585	5.63051
380.143	4.86132
383.7	5.88411
387.256	6.14976
390.812	6.65668
394.365	5.85703
397.916	5.36269
401.467	5.17468
405.015	5.52837
408.563	4.81372
412.109	5.43183
415.654	6.80739
419.197	7.72412
422.739	9.24097
426.279	10.1281
429.819	10.1991
433.356	10.5358
436.891	10.8441
440.426	12.755
443.96	13.4016
447.492	13.4595
451.021	13.6679
454.551	12.9571
458.079	13.4873
461.604	14.7857
465.13	16.0549
468.654	14.9413
472.175	14.7928
475.696	14.8591
479.215	14.7557
482.733	14.2894
486.249	13.5232
489.765	15.1488
493.278	16.5595
496.789	18.1427
500.301	20.0335
503.81	20.8121
507.317	21.9836
510.825	22.7482
514.33	22.165
517.833	22.0648
521.335	22.1223
524.836	22.5877
528.335	22.4586
531.835	22.3575
535.332	22.2477
538.827	21.8547
542.321	20.114
545.814	19.2922
549.305	16.6656
552.795	15.7727
556.282	13.6397
559.769	13.5076
563.255	11.5296
566.739	8.98539
570.223	8.07984
573.705	7.84104
577.183	6.58075
580.663	6.70463
584.141	5.98295
587.615	5.24589
591.09	3.97732
594.564	3.93232
598.035	4.60827
601.506	5.83942
604.974	6.89713
608.443	9.47516
611.908	9.85457
615.374	10.7591
618.837	11.5761
622.3	11.3884
625.761	12.6169
629.219	14.9053
632.677	15.936
636.135	17.8933
639.59	20.8538
643.043	21.6362
646.495	21.2335
649.948	20.8854
653.398	22.1718
656.846	23.4848
660.293	24.3671
663.738	25.622
667.183	26.5768
670.626	26.4871
674.067	25.8257
677.508	27.1819
680.947	27.8408
684.385	30.4653
687.821	30.3157
691.254	31.0358
694.688	31.8889
698.121	31.5104
701.552	32.802
704.98	32.3178
708.409	33.7375
711.836	36.2694
715.26	37.9118
718.685	38.9231
722.108	39.9888
725.528	40.2331
728.949	40.9168
732.367	41.5072
735.785	45.2488
739.2	46.4926
742.614	48.3061
746.028	50.8192
749.439	52.7027
752.849	53.9418
756.26	55.0232
759.667	57.7402
763.073	59.7001
766.477	61.3775
769.883	62.3373
773.285	64.1431
776.686	65.9193
780.085	67.3755
783.484	69.2283
786.881	71.4087
790.276	72.8398
793.671	74.8839
797.064	76.386
800.456	78.1407
803.846	78.5915
807.234	78.8894
810.622	79.0032
814.008	79.2441
817.394	81.2438
820.778	83.1695
824.159	83.1714
827.541	83.9495
830.921	82.8261
834.298	82.5038
837.676	80.5952
841.051	77.8257
844.426	75.6766
847.798	73.2692
851.171	71.0946
854.54	68.4072
857.911	66.1006
861.278	65.0452
864.645	62.6831
868.01	61.0284
871.373	58.3419
874.735	57.0646
878.097	53.7888
881.457	53.4056
884.815	52.8468
888.172	51.6757
891.528	51.5813
894.882	51.5365
898.237	52.9703
901.589	52.6554
904.94	51.5162
908.289	50.641
911.635	51.5648
914.982	51.6317
918.328	48.7281
921.672	47.6924
925.015	47.4488
928.357	47.4094
931.698	46.3036
935.035	45.2104
938.373	44.3155
941.71	43.4415
945.044	40.7484
948.378	38.752
951.709	38.3521
955.041	38.3467
958.372	38.9599
961.699	38.6246
965.027	38.3504
968.352	39.6572
971.676	40.2273
975	39.707
978.322	39.1962
981.642	37.5405
984.962	37.2587
988.28	37.2503
991.596	37.2037
994.911	35.787
998.227	34.0005
1001.54	32.0431
1004.85	31.1656
1008.16	30.6056
1011.47	28.858
1014.78	27.293
1018.08	26.5617
1021.39	25.56
1024.69	24.1295
1028	23.6324
1031.3	23.3052
1034.6	22.4833
1037.9	22.3026
1041.19	22.059
1044.49	22.5958
1047.78	24.3311
1051.08	24.904
1054.37	24.2657
1057.66	23.4826
1060.95	23.2385
1064.24	24.94
1067.53	23.6491
1070.81	22.7066
1074.1	21.9169
1077.38	20.5294
1080.66	20.4577
1083.94	18.7628
1087.22	17.78
1090.5	17.6805
1093.78	17.4113
1097.05	16.5506
1100.33	15.9108
1103.6	15.5159
1106.87	14.3983
1110.14	14.1163
1113.41	14.3299
1116.68	15.3496
1119.95	15.4264
1123.21	15.4342
1126.48	14.6836
1129.74	15.5525
1133	14.0584
1136.26	13.3081
1139.52	13.7385
1142.78	12.7497
1146.04	12.7468
1149.29	10.6286
1152.55	11.2738
1155.8	9.90656
1159.05	9.0201
1162.3	9.46837
1165.55	7.86744
1168.8	7.49216
1172.05	8.12463
1175.29	8.39597
1178.54	7.61461
1181.78	8.63168
1185.02	8.51882
1188.26	10.6403
1191.5	11.8148
1194.74	12.9345
1197.97	12.2493
1201.21	13.5589
1204.44	14.8534
1207.68	16.7
1210.91	17.8613
1214.14	18.5045
1217.37	20.2608
1220.59	21.1063
1223.82	21.8059
1227.05	23.9374
1230.27	24.8699
1233.49	26.8038
1236.72	28.4197
1239.94	30.054
1243.16	32.8765
1246.37	33.5859
1249.59	35.2044
1252.8	37.1412
1256.02	37.0384
1259.23	39.0063
1262.44	40.5316
1265.66	42.5194
1268.86	43.8795
1272.07	45.1558
1275.28	47.7816
1278.48	49.1924
1281.69	52.0136
1284.89	52.1131
1288.09	53.2885
1291.29	53.1736
1294.49	54.8658
1297.69	55.7845
1300.89	55.6247
1304.08	56.3674
1307.28	55.855
1310.47	56.0779
1313.66	56.1424
1316.85	56.5575
1320.04	56.7834
1323.23	55.5246
1326.42	52.8738
1329.61	52.0649
1332.79	49.8925
1335.97	47.1276
1339.16	46.2967
1342.34	45.1235
1345.52	43.694
1348.7	42.8548
1351.87	42.5107
1355.05	41.0095
1358.22	40.9397
1361.4	38.7232
1364.57	37.5535
1367.74	35.8157
1370.91	36.1206
1374.08	35.9473
1377.25	34.7258
1380.41	33.9743
1383.58	33.4076
1386.74	33.5263
1389.91	32.3541
1393.07	31.3499
1396.23	29.6907
1399.39	27.3898
1402.55	26.693
1405.7	26.2854
1408.86	23.6698
1412.01	23.566
1415.17	25.4739
1418.32	27.7568
1421.47	30.5128
1424.62	34.0716
1427.77	37.3834
1430.91	40.953
1434.06	44.9046
1437.2	47.0956
1440.35	48.8503
1443.49	51.9059
1446.63	54.8107
1449.77	56.9577
1452.91	56.5237
1456.05	57.0828
1459.18	55.8229
1462.32	53.2321
1465.45	50.8049
1468.59	47.1432
1471.72	44.6892
1474.85	42.0495
1477.98	39.6968
1481.1	35.3903
1484.23	30.833
1487.36	27.9009
1490.48	25.3015
1493.61	24.1525
1496.73	22.6932
1499.85	21.3922
1502.97	21.0817
1506.09	19.6758
1509.2	19.2387
1512.32	17.8101
1515.43	15.9388
1518.55	16.0325
1521.66	16.1285
1524.77	15.9062
1527.88	16.1121
1530.99	16.4501
1534.1	16.0577
1537.21	17.4623
1540.31	19.3313
1543.42	19.5985
1546.52	22.4743
1549.62	24.3527
1552.72	26.4628
1555.82	27.2968
1558.92	27.8777
1562.02	28.1756
1565.11	28.5771
1568.21	29.1741
1571.3	31.6894
1574.39	33.8726
1577.49	35.2489
1580.57	36.8306
1583.66	36.7744
1586.75	37.4262
1589.84	37.1573
1592.92	38.8113
1596.01	41.3708
1599.09	41.2573
1602.17	41.569
1605.25	41.2689
1608.33	41.205
1611.41	41.7504
1614.49	41.1267
1617.57	40.6973
1620.64	42.1036
1623.72	44.5392
1626.79	45.8615
1629.86	46.8763
1632.93	46.2472
1636	48.0536
1639.07	48.5724
1642.13	49.3952
1645.2	50.6476
1648.26	52.7404
1651.33	52.8536
1654.39	52.6581
1657.45	52.3423
1660.51	51.7329
1663.57	50.8126
1666.63	50.1668
1669.68	48.4608
1672.74	45.6637
1675.79	41.2577
1678.85	38.7263
1681.9	35.4086
1684.95	32.7768
1688	28.7249
1691.05	25.6453
1694.09	23.018
1697.14	21.1126
1700.18	18.4538
1703.23	14.8395
1706.27	11.1259
1709.31	8.98428
1712.35	7.91406
1715.39	5.46632
1718.43	4.02736
1721.47	2.71294
1724.5	1.91132
1727.54	0.771362
1730.57	0.0318266
1733.61	-0.180966
1736.64	-0.0185765
1739.67	-0.172012
1742.7	-0.322825
1745.72	-0.355428
1748.75	-0.144001
1751.77	0.215787
1754.8	1.67737
1757.82	2.14642
1760.84	1.97611
1763.87	2.04647
1766.89	2.0097
1769.91	1.70503
1772.92	1.33057
1775.94	1.47828
1778.95	0.829562
1781.97	1.5963
1784.98	2.23329
1787.99	2.31798
1791.01	2.52834
1794.01	2.58916
1797.02	2.7189
1800.03	3.24579
1803.04	2.91278
1806.04	3.5612
1809.05	3.62778
1812.05	4.64688
1815.05	5.25019
1818.05	5.39479
1821.05	6.532
1824.05	7.41753
1827.05	7.47761
1830.04	6.65128
1833.04	6.29056
1836.03	5.91317
1839.03	5.83532
1842.02	5.08697
1845.01	5.44522
1848	5.29599
1850.99	6.03745
1853.97	6.11772
1856.96	6.35773
1859.94	6.00847
1862.93	6.16151
1865.91	5.87551
1868.89	6.22977
1871.87	5.4151
1874.85	5.30443
1877.83	4.29604
1880.81	4.60283
1882.57	4.91388
1885.56	5.37301
1888.55	5.0436
1891.54	5.40153
1894.52	4.79521
1897.51	3.97033
1900.49	3.81914
1903.47	3.74115
1906.45	3.34757
1909.43	3.67792
1912.41	3.17442
1915.39	2.86375
1918.37	3.04946
1921.34	2.62121
1924.32	2.37039
1927.29	2.69825
1930.26	2.65923
1933.23	2.79826
1936.2	3.02343
1939.17	3.41923
1942.14	4.39254
1945.11	3.34411
1948.07	2.58411
1951.04	3.49596
1954	4.14934
1956.96	4.7479
1959.93	4.31655
1962.89	4.18753
1965.85	4.4025
1968.8	4.03534
1971.76	4.50143
1974.72	4.53002
1977.67	3.7064
1980.63	3.82062
1983.58	3.26493
1986.53	3.08071
1989.48	2.77737
1992.43	1.69475
1995.38	2.11296
1998.32	1.87915
2001.27	1.68886
2004.22	0.566057
2007.16	0.834356
2010.1	1.34033
2013.04	0.975006
2015.98	0.561595
2018.92	1.71133
2021.86	1.8844
2024.8	1.72159
2027.74	2.23849
2030.67	1.69291
2033.61	1.17413
2036.54	1.14795
2039.47	0.859834
2042.4	0.550878
2045.33	0.9888
2048.26	1.52024
2051.19	2.64998
2054.12	3.10753
2057.04	3.76608
2059.97	4.61258
2062.89	4.85139
2065.81	5.1879
2068.73	6.80659
2071.65	6.37023
2074.57	6.54366
2077.49	7.12891
2080.41	8.64363
2083.32	9.60938
2086.24	10.9525
2089.15	13.1005
2092.07	14.5371
2094.98	15.0214
2097.89	15.6994
2100.8	16.3867
2103.71	16.8643
2106.61	17.1548
2109.52	17.9407
2112.43	20.4835
2115.33	22.8743
2118.23	25.4194
2121.13	28.0832
2124.04	30.1471
2126.94	32.4085
2129.83	34.6832
2132.73	36.8596
2135.63	40.0369
2138.53	42.4275
2141.42	44.4004
2144.31	46.3925
2147.21	49.3327
2150.1	51.528
2152.99	53.4939
2155.88	54.6944
2158.77	55.5318
2161.65	56.1735
2164.54	56.0559
2167.43	55.8591
2170.31	54.4805
2173.19	53.7512
2176.07	52.4895
2178.96	51.7532
2181.84	51.0669
2184.72	50.0445
2187.59	47.5186
2190.47	44.9764
2193.35	42.8051
2196.22	41.6609
2199.09	39.6855
2201.97	38.2989
2204.84	37.6005
2207.71	35.6817
2210.58	33.6675
2213.45	32.6619
2216.31	31.7659
2219.18	29.5452
2222.05	27.7728
2224.91	26.7473
2227.78	25.0168
2230.64	23.6527
2233.5	23.3759
2236.36	22.7787
2239.22	21.6273
2242.08	20.3409
2244.93	19.6333
2247.79	19.5598
2250.64	18.5063
2253.5	16.4824
2256.35	14.7467
2259.2	13.6456
2262.05	13.3912
2264.9	11.8863
2267.75	11.0976
2270.6	10.3968
2273.45	9.34585
2276.29	8.344
2279.14	8.44863
2281.98	8.40074
2284.82	7.56829
2287.66	7.03665
2290.5	5.84722
2293.34	4.141
2296.18	4.01343
2299.02	4.1855
2301.86	6.10518
2304.69	6.80104
2307.53	7.65333
2310.36	7.56831
2313.19	7.70291
2316.02	8.02665
2318.85	8.21951
2321.68	7.54997
2324.51	7.31243
2327.34	7.31461
2330.16	6.7432
2332.99	6.11269
2335.81	5.77441
2338.64	5.23668
2341.46	4.96316
2344.28	4.5766
2347.1	3.95669
2349.92	2.66895
2352.74	1.19453
2355.55	-0.0354763
2358.37	-0.827007
2361.19	-1.93111
2364	-1.18874
2366.81	-0.420893
2369.62	1.28713
2372.44	1.8342
2375.24	1.816
2378.05	1.59949
2380.86	0.962748
2383.67	0.683855
2386.47	1.84694
2389.28	3.50283
2392.08	3.82574
2394.89	4.09838
2397.69	4.07363
2400.49	4.49372
2403.29	4.67381
2406.09	5.25537
2408.88	4.98829
2411.68	4.49231
2414.48	4.49626
2417.27	4.63805
2420.06	4.97233
2422.86	5.18428
2425.65	5.46768
2428.44	4.82903
2431.23	5.57769
2434.02	6.2683
2436.81	6.50558
2439.59	6.3866
2442.38	5.90505
2445.16	5.65888
2447.95	5.76333
2450.73	6.62676
2453.51	7.44051
2456.29	8.25385
2459.07	8.25581
2461.85	8.36538
2464.63	7.69301
2467.4	7.42713
2470.18	7.5792
2472.95	7.76388
2475.73	7.3942
2478.5	6.53911
2481.27	6.4641
2484.04	6.27269
2486.81	6.24649
2489.58	5.7901
2492.35	5.75532
2495.12	6.17096
2497.88	6.53948
2500.65	6.48474
2503.41	6.17268
2506.17	5.32772
2508.94	5.04357
2511.7	4.9657
2514.46	4.69153
2517.22	4.4417
2519.97	3.55412
2522.73	3.30518
2525.49	2.66232
2528.24	2.27938
2530.99	2.28943
2533.75	2.97779
2536.5	2.99087
2539.25	3.90773
2542	3.99364
2544.75	4.14918
2547.5	4.7312
2550.24	4.84981
2552.99	5.34924
2555.74	5.84145
2558.48	7.02559
2561.22	7.18859
2563.96	7.69068
2566.71	7.2309
2569.45	7.45806
2572.18	6.8014
2574.92	5.86682
2577.66	5.29473
2580.4	4.70308
2583.13	5.1135
2585.87	5.73586
2588.6	5.73368
2591.33	6.41919
2594.06	6.73803
2596.79	7.25866
2599.52	7.30145
2602.25	7.16737
2604.98	7.37237
2607.71	7.18787
2610.43	5.80957
2613.16	5.92758
2615.88	6.68268
2618.6	6.63881
2621.32	6.76094
2624.04	7.20787
2626.76	7.00278
2629.48	6.91617
2632.2	6.46237
2634.92	7.40952
2637.63	6.76399
2640.35	6.99452
2643.06	8.12895
2645.77	9.40329
2648.49	9.72488
2651.2	10.5843
2653.91	10.6108
2656.62	10.2542
2659.33	10.5411
2662.03	10.1267
2664.74	9.04643
2667.44	9.42717
2670.15	8.87032
2672.85	7.43716
2675.55	6.74091
2678.26	6.55157
2680.96	7.652
2683.66	8.1727
2686.35	8.03427
2689.05	8.10361
2691.75	7.80793
2694.44	8.3119
2697.14	8.62424
2699.83	9.0964
2702.52	10.3053
2705.22	10.9011
2707.91	12.24
2710.6	13.6258
2713.29	13.6715
2715.97	14.149
2718.66	14.3307
2721.35	13.828
2724.03	15.2044
2726.72	14.4403
2729.4	13.8755
2732.08	13.3565
2734.76	11.8294
2737.44	10.4484
2740.12	9.8904
2742.8	10.2716
2745.48	9.95431
2748.16	10.1093
2750.83	8.64293
2753.51	7.9622
2756.18	6.96152
2758.85	5.74571
2761.53	4.54425
2764.2	4.24149
2766.87	4.59213
2769.54	4.87852
2772.2	4.00718
2774.87	4.1555
2777.54	4.17712
2780.2	3.63939
2782.87	3.26821
2785.53	3.08637
2788.19	1.89553
2790.85	1.4843
2793.51	1.11931
2796.17	0.863892
2798.83	1.06137
2801.49	0.696667
2804.15	0.0549754
2806.8	0.395406
2809.46	-0.377803
2812.11	0.173144
2814.76	0.732852
2817.42	0.607824
2820.07	1.23244
2822.72	1.18485
2825.37	2.29245
2828.02	4.39177
2830.66	7.22661
2833.31	9.02956
2835.96	10.6537
2838.6	12.5121
2841.24	16.3242
2843.89	18.4736
2846.53	21.8165
2849.17	25.2374
2851.81	29.1513
2854.45	33.4361
2857.09	38.0479
2859.72	42.6441
2862.36	46.1708
2865	50.8293
2867.63	53.6359
2870.26	56.1037
2872.9	58.9353
2875.53	61.668
2878.16	64.2515
2880.79	66.147
2883.42	68.0377
2886.05	70.1637
2888.67	72.7341
2891.3	75.9467
2893.92	79.4001
2896.55	81.5892
2899.17	84.639
2901.79	88.6443
2904.42	94.3277
2907.04	99.6865
2909.66	104.984
2912.27	111.826
2914.89	118.327
2917.51	124.028
2920.13	128.998
2922.74	133.822
2925.35	137.341
2927.97	139.793
2930.58	140.44
2933.19	139.363
2935.8	137.864
2938.41	135.859
2941.02	133.724
2943.63	130.728
2946.24	126.211
2948.84	121.972
2951.45	117.347
2954.05	111.628
2956.65	106.505
2959.26	101.284
2961.86	96.9563
2964.46	92.3957
2967.06	87.3795
2969.66	82.5739
2972.25	77.3863
2974.85	73.4635
2977.45	68.3342
2980.04	63.1567
2982.64	57.15
2985.23	51.5308
2987.82	45.6784
2990.41	39.9692
2993	34.3247
2995.59	29.2982
2998.18	25.2347
3000.77	20.3499
3003.36	15.5711
3005.94	13.1194
3008.53	10.1936
3011.11	7.43005
3013.69	5.63986
3016.28	3.39773
3018.86	2.38262
3021.44	2.30135
3024.02	1.35508
3026.6	0.765762
3029.18	0.920588
3031.75	1.59761
3034.33	2.18093
3036.9	3.52736
3039.48	4.13087
3042.05	5.44279
3044.62	6.35689
3047.19	7.7268
3049.77	9.26536
3052.34	10.68
3054.9	12.0108
3057.47	12.3906
3060.04	11.7649
3062.61	11.8067
3065.17	10.5414
3067.74	10.988
3070.3	11.6565
3072.86	11.123
3075.42	9.54553
3077.99	9.02921
3080.54	8.72869
3083.1	8.40036
3085.66	7.76416
3088.22	8.00859
3090.78	8.72546
3093.33	10.1334
3095.89	10.6481
3098.44	11.9812
3100.99	13.6998
3103.54	15.5107
3106.1	16.7225
3108.65	18.4273
3111.2	21.1811
3113.74	22.5048
3116.29	24.8316
3118.84	25.893
3121.38	27.1625
3123.93	28.4249
3126.47	30.8571
3129.01	32.6938
3131.56	35.3593
3134.1	35.7228
3136.64	36.8479
3139.18	39.1843
3141.72	41.8954
3144.26	44.4179
3146.79	47.4056
3149.33	51.0828