File: data/Raman/poly_smoothed/Thy_00_07_22_1x_45s_532 nm_x100_100%_600 gr_mm_01.txt
#Acq. time (s)=	45
#Accumulations=	2
#Range (cm-¹)=	200...3150
#Windows=	2
#Auto scanning=	Off
#Autofocus=	Off
#Macrospot=	Off
#AutoExposure=	Off
#Spike filter=	Multiple accum.
#Delay time (s)=	0
#Binning=	1
#Readout mode=	Signal
#DeNoise=	Off
#ICS correction=	On
#Dark correction=	Off
#Inst. Process=	Off
#Detector Gain=	Best Dynamic Range
#Detector ADC=	20 kHz
#Detector temperature (°C)=	-69.85
#Instrument=	LabRAM HR Evol
#Detector=	Synapse
#Objective=	x100
#Grating=	600 gr/mm
#ND Filter=	100%
#Laser (nm)=	532
#Hole=	100.021
#Range=	Auto
#Laser Pol.=	No
#Raman. Pol.=	No
#Laser Pol. (°)=	-0.0007625
#Raman Pol. (°)=	89.9995
#Collection=	Microscope
#StageXY=	Marzhauser
#StageZ=	Marzhauser
#X (µm)=	8996.9
#Y (µm)=	-3064.3
#Z (µm)=	-54.65
#Full time(mm:ss)=	3:19
#Project=
#Sample=
#Site=
#Title=	Thy_00_07_22_2x_45s_532 nm_x100_100%_600 gr_mm
#Remark=
#Date=	28.06.2022 11:45
#Acquired=	28.06.2022 11:45:52
#Base:Fit=	10.08.2022 10:07:56
#Base:Sub=	10.08.2022 10:08:40
#Filter:Polynom=	16.08.2022 10:26:06
#AxisType[0]=Intens
#AxisUnit[0]=Cnt
#AxisType[1]=Spectr
#AxisUnit[1]=1/cm
200.407	7.16332
204.035	6.67728
207.665	5.22743
211.291	4.4708
214.916	2.79084
218.541	0.796571
222.163	0.224878
225.785	0.0914247
229.404	0.952788
233.022	-0.685088
236.638	0.920507
240.255	3.03434
243.868	4.64492
247.48	4.97011
251.091	6.53792
254.702	6.30423
258.31	7.33306
261.916	7.66079
265.521	9.00914
269.125	9.4
272.727	10.5125
276.328	9.31658
279.927	10.1723
283.525	10.2659
287.121	10.0771
290.716	10.9249
294.31	10.3521
297.9	9.20016
301.491	8.2399
305.081	8.08557
308.669	9.45295
312.256	10.7243
315.839	11.5865
319.423	12.043
323.006	12.4238
326.585	15.604
330.165	17.482
333.741	18.0592
337.318	16.9476
340.894	17.4506
344.466	17.1669
348.039	16.2868
351.608	15.5226
355.176	15.5074
358.745	14.7473
362.31	14.0977
365.876	12.7584
369.439	13.2225
373	12.3701
376.56	11.3074
380.12	12.2524
383.677	11.771
387.233	13.2732
390.787	13.4962
394.34	13.4979
397.894	13.1535
401.444	13.9992
404.993	13.6536
408.54	14.9813
412.086	15.0652
415.631	18.4417
419.174	18.3741
422.716	17.6488
426.257	16.5486
429.794	16.3217
433.332	13.3671
436.868	12.541
440.403	13.3963
443.937	14.0664
447.468	15.6684
450.999	17.0298
454.528	16.8679
458.057	18.4892
461.582	19.3666
465.107	19.1155
468.629	21.7783
472.152	22.5938
475.672	22.795
479.192	24.0642
482.709	24.7358
486.226	26.7641
489.74	29.1934
493.255	29.9697
496.767	30.5245
500.277	30.1923
503.788	31.1661
507.295	29.6797
510.801	29.1929
514.308	26.9047
517.811	25.4733
521.313	25.2277
524.814	25.2354
528.313	26.0461
531.811	24.3286
535.308	22.5114
538.803	20.0404
542.297	19.3878
545.789	18.9175
549.281	17.0043
552.771	16.7297
556.259	16.0411
559.747	13.7827
563.233	12.8157
566.717	12.2469
570.2	10.5268
573.68	10.0692
577.161	9.34095
580.64	8.27782
584.118	8.01104
587.593	7.95392
591.068	8.39312
594.54	8.31234
598.013	8.1624
601.484	8.95742
604.952	9.52932
608.421	10.7428
611.886	12.2694
615.35	12.9602
618.815	14.038
622.276	16.5223
625.738	17.3479
629.197	18.7889
632.655	18.3347
636.113	17.6762
639.568	17.5803
643.021	16.7221
646.473	18.3568
649.924	17.6088
653.376	17.0797
656.824	16.3414
660.271	17.7516
663.716	18.3839
667.161	17.8303
670.604	17.9782
674.045	17.1186
677.486	19.3177
680.925	21.3522
684.361	22.7504
687.797	24.682
691.232	28.4781
694.666	30.8439
698.099	31.8136
701.528	32.7374
704.958	33.1946
708.387	33.0472
711.814	33.2274
715.238	34.9565
718.663	36.4601
722.084	36.3345
725.506	37.315
728.925	40.3717
732.345	42.4094
735.761	42.2608
739.178	45.0227
742.592	48.7753
746.006	52.1664
749.417	53.4501
752.827	56.6222
756.236	60.0088
759.645	64.1711
763.051	67.7534
766.456	70.0494
769.859	72.7266
773.261	76.673
776.664	77.8447
780.064	74.4771
783.462	76.0831
786.859	76.9736
790.255	77.864
793.649	80.0052
797.042	80.9358
800.434	81.0846
803.823	80.1561
807.212	79.443
810.6	80.9178
813.987	81.1772
817.372	81.4324
820.754	79.9273
824.137	79.7834
827.519	80.0787
830.897	80.7422
834.276	79.5583
837.654	77.735
841.029	76.9711
844.404	75.0129
847.776	72.2687
851.149	70.5268
854.519	67.7875
857.889	64.331
861.256	61.4365
864.622	58.9868
867.988	59.2102
871.351	57.0582
874.713	55.4104
878.074	52.142
881.435	50.0833
884.794	49.8865
888.15	47.6909
891.506	47.5077
894.861	46.3696
898.214	45.5503
901.566	46.2697
904.916	47.068
908.266	48.8298
911.614	50.4088
914.961	50.456
918.306	50.6544
921.651	49.8971
924.994	49.7563
928.336	48.9326
931.674	48.4937
935.014	47.1931
938.352	44.9199
941.687	43.541
945.022	41.5152
948.357	39.0884
951.688	38.7787
955.02	38.3585
958.348	36.2338
961.678	35.5024
965.004	37.3125
968.331	34.0213
971.655	33.7478
974.979	34.3332
978.3	35.8899
981.62	36.9139
984.941	37.8348
988.259	37.5779
991.575	37.6213
994.89	36.3527
998.204	36.5975
1001.52	36.756
1004.83	34.6884
1008.14	34.379
1011.45	33.1417
1014.76	31.777
1018.06	32.2303
1021.37	31.3966
1024.67	31.466
1027.97	30.0918
1031.27	29.9275
1034.57	29.9736
1037.87	27.5954
1041.17	26.4607
1044.47	26.1702
1047.76	26.4673
1051.06	27.4833
1054.35	28.6374
1057.64	29.1574
1060.93	28.4247
1064.22	27.8569
1067.5	28.202
1070.79	27.6487
1074.08	29.6258
1077.36	30.3435
1080.64	31.775
1083.92	32.1523
1087.2	33.5285
1090.48	34.0365
1093.76	35.8158
1097.03	39.3937
1100.31	40.9827
1103.58	41.2527
1106.85	42.1231
1110.12	40.9399
1113.39	40.229
1116.66	37.5114
1119.93	37.3165
1123.19	38.7542
1126.46	38.3523
1129.72	37.2489
1132.98	35.2657
1136.24	33.463
1139.5	32.1884
1142.76	30.0128
1146.01	28.6046
1149.27	26.508
1152.53	24.785
1155.78	22.1605
1159.03	19.0973
1162.28	15.7924
1165.53	12.5561
1168.78	10.9818
1172.02	10.2313
1175.27	10.303
1178.51	9.73291
1181.76	9.10298
1185	8.35835
1188.24	7.38212
1191.48	8.04456
1194.71	8.42625
1197.95	9.68384
1201.19	10.6087
1204.42	12.4756
1207.65	12.985
1210.88	15.9841
1214.12	19.7681
1217.35	23.3968
1220.57	25.5032
1223.8	28.0734
1227.03	30.8681
1230.25	33.2747
1233.47	34.3192
1236.69	35.6789
1239.92	37.2137
1243.13	37.9243
1246.35	39.5686
1249.57	42.386
1252.78	44.5926
1256	45.9088
1259.21	46.4809
1262.42	46.6092
1265.63	46.6803
1268.84	47.3195
1272.05	48.3453
1275.26	48.3516
1278.46	48.5563
1281.67	49.0148
1284.87	51.1492
1288.07	52.2354
1291.27	53.1837
1294.47	54.5985
1297.67	56.1058
1300.87	56.939
1304.06	58.0664
1307.26	60.0579
1310.45	62.4976
1313.64	63.9313
1316.83	65.8298
1320.02	67.6343
1323.21	69.1893
1326.4	71.0247
1329.59	71.8179
1332.77	70.8878
1335.95	71.6829
1339.14	72.3662
1342.32	70.5514
1345.5	69.3403
1348.67	68.0459
1351.85	66.5602
1355.03	64.1601
1358.2	63.1829
1361.38	61.6861
1364.55	59.8194
1367.72	57.6411
1370.89	57.8755
1374.06	55.7235
1377.23	52.7111
1380.39	51.9389
1383.56	49.7601
1386.72	48.6954
1389.89	47.8723
1393.05	46.2026
1396.21	43.3764
1399.37	42.6977
1402.52	41.9191
1405.68	41.4556
1408.84	41.7232
1411.99	41.1396
1415.15	41.7681
1418.3	42.6536
1421.45	43.9797
1424.6	47.2116
1427.75	50.2295
1430.89	54.2505
1434.04	59.4988
1437.18	64.5039
1440.33	66.4711
1443.47	70.2132
1446.61	72.8971
1449.75	73.2688
1452.89	74.1916
1456.03	75.0671
1459.16	73.1762
1462.3	70.0146
1465.43	66.1666
1468.56	62.5173
1471.7	56.592
1474.83	51.9985
1477.96	47.8833
1481.08	42.938
1484.21	37.1712
1487.34	33.1026
1490.46	27.7243
1493.58	24.8796
1496.71	22.8341
1499.83	19.5204
1502.95	17.8776
1506.07	15.8481
1509.18	14.3285
1512.3	12.6288
1515.41	10.6864
1518.53	9.08447
1521.64	9.02228
1524.75	11.1048
1527.86	13.9579
1530.97	15.541
1534.08	15.8745
1537.19	16.6247
1540.29	18.1933
1543.4	21.6858
1546.5	24.7353
1549.6	27.7319
1552.7	31.7326
1555.8	34.7272
1558.9	37.6617
1562	40.8719
1565.09	43.3985
1568.19	44.9477
1571.28	48.3006
1574.37	49.8983
1577.47	50.7446
1580.56	51.5277
1583.64	51.8059
1586.73	52.3868
1589.82	50.8956
1592.9	51.2674
1595.99	51.6289
1599.07	51.6032
1602.15	51.3111
1605.23	48.8555
1608.31	48.5084
1611.39	47.5462
1614.47	46.8511
1617.55	47.7292
1620.62	47.5905
1623.7	46.7302
1626.77	47.2386
1629.84	46.4039
1632.91	47.0583
1635.98	47.535
1639.05	47.9896
1642.11	45.9479
1645.18	44.9629
1648.24	46.6434
1651.31	49.4276
1654.37	51.938
1657.43	54.1464
1660.49	55.6309
1663.55	55.51
1666.61	54.5583
1669.66	55.6275
1672.72	53.8125
1675.77	51.0262
1678.83	49.5616
1681.88	47.5614
1684.93	46.1228
1687.98	44.361
1691.03	40.9855
1694.07	37.1405
1697.12	32.3709
1700.17	29.0463
1703.21	24.6488
1706.25	21.2167
1709.29	19.2404
1712.33	17.1462
1715.37	13.9157
1718.41	10.7624
1721.45	13.0465
1724.49	16.0486
1727.52	15.9897
1730.55	16.7452
1733.59	16.3064
1736.62	14.6898
1739.65	13.763
1742.68	13.3285
1745.7	13.4295
1748.73	12.7874
1751.76	12.5198
1754.78	12.5848
1757.8	11.7
1760.83	10.7538
1763.85	8.56907
1766.87	7.06302
1769.89	6.9887
1772.9	6.42039
1775.92	5.53354
1778.94	5.54864
1781.95	5.22627
1784.96	5.31092
1787.97	5.12234
1790.99	4.8248
1794	4.96574
1797	5.00962
1800.01	4.57738
1803.02	4.84515
1806.02	4.72713
1809.03	3.99983
1812.03	3.73561
1815.03	4.24407
1818.03	5.22241
1821.03	6.03812
1824.03	5.75387
1827.03	5.5259
1830.02	4.17554
1833.02	3.38472
1836.01	3.1009
1839.01	2.88925
1842	2.44765
1844.99	2.24737
1847.98	1.31135
1850.97	0.697024
1853.95	0.24565
1856.94	0.0391396
1859.93	0.432522
1862.91	1.65365
1865.89	2.71591
1868.87	2.84326
1871.85	2.61751
1874.83	2.78829
1877.81	3.25046
1880.79	4.06258
1882.52	4.82184
1885.51	5.12108
1888.5	6.01719
1891.49	6.54137
1894.47	7.10833
1897.46	6.80833
1900.44	6.80532
1903.42	6.18838
1906.4	6.15501
1909.38	6.9414
1912.36	6.58257
1915.34	6.91087
1918.32	7.19556
1921.29	7.60459
1924.27	7.75378
1927.24	8.72551
1930.21	8.99088
1933.18	9.77851
1936.15	9.44928
1939.12	9.73578
1942.09	8.31111
1945.06	8.32313
1948.02	8.77114
1950.99	9.22385
1953.95	8.89083
1956.91	7.50065
1959.88	6.66259
1962.84	5.94238
1965.8	5.28424
1968.75	4.82894
1971.71	3.03077
1974.67	2.60154
1977.62	2.29222
1980.58	3.11957
1983.53	2.96738
1986.48	2.7458
1989.43	2.6198
1992.38	3.765
1995.33	4.23646
1998.27	4.39658
2001.22	6.1847
2004.16	7.68791
2007.11	8.04369
2010.05	9.15708
2012.99	9.4656
2015.93	10.289
2018.87	11.1389
2021.81	13.0735
2024.75	13.067
2027.69	11.8182
2030.62	11.4681
2033.56	11.6849
2036.49	11.4542
2039.42	11.8194
2042.35	11.4304
2045.28	11.4567
2048.21	11.4522
2051.14	11.7069
2054.07	10.1418
2056.99	9.15611
2059.92	9.33199
2062.84	8.62314
2065.76	9.11502
2068.68	9.573
2071.6	9.67416
2074.52	9.74603
2077.44	8.60098
2080.36	7.49504
2083.27	6.53766
2086.19	7.23936
2089.1	7.81493
2092.02	8.25217
2094.93	7.18513
2097.84	7.33672
2100.75	7.85387
2103.66	8.55753
2106.56	7.69253
2109.47	7.79597
2112.38	7.19354
2115.28	6.63466
2118.18	6.96603
2121.09	6.5432
2123.99	6.53865
2126.89	7.08657
2129.79	7.14535
2132.68	6.8861
2135.58	6.85454
2138.48	6.63311
2141.37	7.23258
2144.27	6.85908
2147.16	6.63367
2150.05	7.20168
2152.94	7.49218
2155.83	8.98444
2158.72	10.7434
2161.6	11.8612
2164.49	12.0575
2167.38	12.453
2170.26	12.9167
2173.14	12.1449
2176.03	11.0202
2178.91	10.3468
2181.79	10.5482
2184.67	10.7186
2187.54	10.8012
2190.42	10.0741
2193.3	9.13223
2196.17	9.07433
2199.05	7.74228
2201.92	7.50811
2204.79	7.02058
2207.66	5.90858
2210.53	5.71535
2213.4	5.31614
2216.27	4.69985
2219.13	5.42178
2222	4.60744
2224.86	6.0717
2227.72	6.32415
2230.59	7.1816
2233.45	6.66762
2236.31	6.46708
2239.17	5.76696
2242.03	6.0864
2244.88	6.01066
2247.74	6.86738
2250.59	7.78999
2253.45	8.59161
2256.3	8.62012
2259.15	9.22889
2262	10.1567
2264.85	10.1271
2267.7	10.6481
2270.55	9.90698
2273.4	10.0853
2276.24	9.02155
2279.09	8.83332
2281.93	7.87343
2284.77	7.59023
2287.62	7.43694
2290.46	5.47447
2293.3	4.55919
2296.13	3.88435
2298.97	3.38166
2301.81	3.96868
2304.64	4.70987
2307.48	4.8783
2310.31	5.45614
2313.14	5.28852
2315.98	5.88169
2318.81	6.60179
2321.64	7.3587
2324.46	7.92555
2327.29	7.80365
2330.12	9.96632
2332.94	9.37001
2335.77	9.56327
2338.59	8.82392
2341.41	8.91011
2344.23	8.71518
2347.05	7.63796
2349.87	6.97117
2352.69	6.51668
2355.51	5.83821
2358.32	4.42555
2361.14	3.2902
2363.95	3.42525
2366.76	3.76302
2369.58	4.20072
2372.39	3.77898
2375.2	2.19692
2378	2.22982
2380.81	2.60547
2383.62	2.52317
2386.43	3.15257
2389.23	3.19186
2392.03	3.52309
2394.84	3.17208
2397.64	4.34056
2400.44	4.67681
2403.24	4.93746
2406.04	5.16937
2408.84	5.73106
2411.63	7.18225
2414.43	8.11162
2417.22	8.69328
2420.02	8.81089
2422.81	9.42033
2425.6	9.12165
2428.39	8.90436
2431.18	9.01203
2433.97	8.91377
2436.76	8.19395
2439.54	7.76688
2442.33	6.85183
2445.12	6.39599
2447.9	6.13811
2450.68	4.79631
2453.46	4.35208
2456.24	3.82402
2459.02	1.83181
2461.8	0.447512
2464.58	-0.265725
2467.36	-0.209957
2470.13	-0.9148
2472.91	-1.02437
2475.68	-1.83057
2478.45	-2.02579
2481.23	-2.51662
2484	-3.09775
2486.77	-2.95815
2489.54	-3.74726
2492.3	-3.05809
2495.07	-2.72512
2497.84	-2.08195
2500.6	-1.33349
2503.36	-1.04024
2506.13	0.175381
2508.89	0.772936
2511.65	1.50845
2514.41	2.17722
2517.17	3.66407
2519.93	3.20322
2522.68	4.1296
2525.44	4.20616
2528.19	4.36383
2530.95	5.3979
2533.7	5.76369
2536.45	5.68879
2539.2	5.29997
2541.95	5.04027
2544.7	4.95311
2547.45	4.37274
2550.2	4.21305
2552.94	4.23453
2555.69	4.07711
2558.43	3.4382
2561.18	3.82537
2563.92	3.75196
2566.66	3.75201
2569.4	3.95796
2572.14	3.48206
2574.88	3.40396
2577.61	4.59127
2580.35	4.82113
2583.09	4.68334
2585.82	3.83538
2588.55	3.8696
2591.29	4.56883
2594.02	4.98811
2596.75	5.68429
2599.48	5.50896
2602.21	5.46924
2604.93	5.84711
2607.66	5.59545
2610.39	5.74201
2613.11	6.65216
2615.83	6.37818
2618.56	7.0571
2621.28	7.29223
2624	6.37674
2626.72	5.427
2629.44	5.93471
2632.15	6.07908
2634.87	5.34721
2637.59	5.16713
2640.3	4.22966
2643.02	3.88216
2645.73	3.19972
2648.44	2.28858
2651.15	1.54494
2653.86	0.92761
2656.57	0.539192
2659.28	0.999616
2661.99	1.49737
2664.69	1.83242
2667.4	1.74846
2670.1	2.50095
2672.81	3.21668
2675.51	3.94992
2678.21	4.36292
2680.91	4.82405
2683.61	4.52816
2686.31	4.22837
2689	5.36402
2691.7	4.69748
2694.4	5.97977
2697.09	6.57713
2699.79	8.08648
2702.48	7.45784
2705.17	7.91468
2707.86	8.18649
2710.55	8.58812
2713.24	8.39936
2715.93	9.15011
2718.62	9.84124
2721.3	10.6836
2723.99	11.272
2726.67	11.8807
2729.35	12.1547
2732.04	12.0322
2734.72	11.6176
2737.4	10.7282
2740.08	10.498
2742.76	9.3874
2745.43	8.29
2748.11	7.06328
2750.79	6.16727
2753.46	6.1082
2756.14	5.59189
2758.81	4.78886
2761.48	4.80498
2764.15	4.98242
2766.82	4.3761
2769.49	3.78039
2772.16	3.59747
2774.82	3.96522
2777.49	3.49032
2780.16	3.22714
2782.82	3.09429
2785.48	2.56023
2788.15	2.2382
2790.81	1.79053
2793.47	1.53143
2796.13	0.575498
2798.79	0.00603624
2801.44	0.860505
2804.1	0.247973
2806.76	0.68251
2809.41	-0.247563
2812.07	0.071886
2814.72	-0.206062
2817.37	1.32515
2820.02	3.57351
2822.67	5.07538
2825.32	7.90294
2827.97	11.4412
2830.62	15.4218
2833.26	19.2244
2835.91	22.4229
2838.56	26.9094
2841.2	30.9735
2843.84	35.6033
2846.48	40.2492
2849.12	45.9603
2851.77	52.0579
2854.4	58.0415
2857.04	65.0083
2859.68	71.9309
2862.32	79.3942
2864.95	85.8854
2867.59	92.4888
2870.22	98.078
2872.85	103.219
2875.48	107.751
2878.11	113.48
2880.74	118.688
2883.37	124.459
2886	129.285
2888.63	134.361
2891.25	138.836
2893.88	143.251
2896.5	147.402
2899.13	150.114
2901.75	154.382
2904.37	159.33
2906.99	165.176
2909.61	171.395
2912.23	175.641
2914.85	181.26
2917.46	185.844
2920.08	190.115
2922.7	193.624
2925.31	194.73
2927.92	195.409
2930.54	194.037
2933.15	193.357
2935.76	190.293
2938.37	187.397
2940.98	183.048
2943.58	178.265
2946.19	172.717
2948.8	167.927
2951.4	161.428
2954.01	154.985
2956.61	147.798
2959.21	141.05
2961.81	134.539
2964.41	129.209
2967.01	123.043
2969.61	117.871
2972.21	112.698
2974.81	106.453
2977.4	100.581
2980	93.9254
2982.59	86.2659
2985.18	78.3619
2987.78	70.5312
2990.37	63.6711
2992.96	56.8585
2995.55	50.5465
2998.14	44.6841
3000.73	39.0479
3003.31	33.5294
3005.9	27.6205
3008.48	22.1833
3011.07	18.8556
3013.65	14.9616
3016.23	11.1452
3018.81	7.63376
3021.4	5.20666
3023.97	2.81332
3026.55	1.50238
3029.13	0.65091
3031.71	1.05894
3034.28	1.3963
3036.86	2.11502
3039.43	2.28395
3042.01	3.06607
3044.58	3.27478
3047.15	4.77421
3049.72	5.6701
3052.29	7.22682
3054.86	8.72106
3057.43	9.53792
3060	9.78805
3062.56	10.6631
3065.13	10.0672
3067.69	8.98684
3070.26	9.09703
3072.82	7.88172
3075.38	6.88351
3077.94	5.38266
3080.5	4.0284
3083.06	2.08004
3085.62	0.328366
3088.18	-0.212564
3090.73	0.247303
3093.29	0.300731
3095.84	0.15857
3098.4	-0.0756419
3100.95	0.559573
3103.5	0.97406
3106.05	2.86852
3108.6	3.25704
3111.15	4.08004
3113.7	5.28154
3116.25	6.07138
3118.79	6.38748
3121.34	7.46868
3123.88	8.81849
3126.43	9.72843
3128.97	10.3427
3131.51	11.7127
3134.06	12.4256
3136.6	12.9915
3139.14	14.3854
3141.67	15.1094
3144.21	16.3339
3146.75	19.1576
3149.29	22.4134