File: data/Raman/poly_smoothed/Thy_30_10_12_1x_45s_532 nm_x100_100%_600 gr_mm_01.txt
#Acq. time (s)=	45
#Accumulations=	2
#Range (cm-¹)=	200...3150
#Windows=	2
#Auto scanning=	Off
#Autofocus=	Off
#Macrospot=	Off
#AutoExposure=	Off
#Spike filter=	Multiple accum.
#Delay time (s)=	0
#Binning=	1
#Readout mode=	Signal
#DeNoise=	Off
#ICS correction=	On
#Dark correction=	Off
#Inst. Process=	Off
#Detector Gain=	Best Dynamic Range
#Detector ADC=	20 kHz
#Detector temperature (°C)=	-69.85
#Instrument=	LabRAM HR Evol
#Detector=	Synapse
#Objective=	x100
#Grating=	600 gr/mm
#ND Filter=	100%
#Laser (nm)=	532
#Hole=	100.021
#Range=	Auto
#Laser Pol.=	No
#Raman. Pol.=	No
#Laser Pol. (°)=	-0.0007625
#Raman Pol. (°)=	89.9995
#Collection=	Microscope
#StageXY=	Marzhauser
#StageZ=	Marzhauser
#X (µm)=	4738.2
#Y (µm)=	-7730.7
#Z (µm)=	584.45
#Full time(mm:ss)=	3:18
#Project=
#Sample=
#Site=
#Title=	Thy_30_10_12_2x_45s_532 nm_x100_100%_600 gr_mm
#Remark=
#Date=	30.06.2022 12:11
#Acquired=	30.06.2022 12:11:36
#Base:Fit=	10.08.2022 09:58:11
#Base:Sub=	10.08.2022 09:58:44
#Filter:Polynom=	16.08.2022 10:22:53
#AxisType[0]=Intens
#AxisUnit[0]=Cnt
#AxisType[1]=Spectr
#AxisUnit[1]=1/cm
200.533	8.21424
204.162	6.50038
207.792	6.42077
211.418	5.77776
215.044	5.60913
218.667	5.89204
222.289	6.26047
225.912	5.33874
229.531	5.07232
233.148	4.19911
236.766	2.96164
240.381	2.11307
243.994	3.0677
247.606	3.52309
251.217	4.29116
254.828	3.4931
258.436	5.24539
262.042	4.9785
265.647	6.07505
269.25	5.85983
272.852	6.31724
276.453	7.77843
280.052	9.15028
283.65	8.83713
287.247	9.65291
290.842	10.4758
294.436	10.6566
298.028	11.5759
301.617	12.9684
305.206	14.9316
308.794	15.9153
312.381	16.0776
315.964	17.5814
319.548	18.6215
323.131	19.4854
326.71	20.6941
330.29	23.4486
333.868	24.3373
337.443	23.2699
341.018	23.5176
344.591	23.0733
348.163	22.8487
351.733	20.6879
355.303	21.0769
358.869	18.6982
362.435	16.9578
366.001	16.6654
369.563	16.745
373.124	13.9923
376.686	14.1577
380.244	14.3497
383.801	14.5211
387.357	16.0253
390.911	17.5482
394.466	18.4746
398.018	20.831
401.568	23.3561
405.117	24.8975
408.664	27.0061
412.21	26.815
415.755	28.1622
419.298	28.1335
422.84	26.9046
426.38	26.0836
429.919	24.372
433.455	22.6191
436.992	21.2009
440.527	21.3329
444.06	18.0196
447.593	16.6055
451.122	16.7763
454.651	16.5232
458.18	16.4199
461.705	16.4416
465.23	16.9766
468.752	17.1229
472.275	16.886
475.797	18.4399
479.315	20.5735
482.834	20.8636
486.349	23.6357
489.863	24.0871
493.378	24.7574
496.889	26.7386
500.401	28.6619
503.91	29.9951
507.417	30.4698
510.923	30.0174
514.43	28.8326
517.933	28.4911
521.435	26.6953
524.936	26.3583
528.435	24.007
531.933	22.7482
535.43	21.3911
538.927	20.2536
542.421	18.4271
545.913	17.348
549.403	13.5629
552.893	10.9227
556.381	10.262
559.868	8.92753
563.354	10.1246
566.839	9.73082
570.322	9.27072
573.802	9.48291
577.283	7.74363
580.762	8.47959
584.24	8.69408
587.714	8.55651
591.19	6.15819
594.663	4.91392
598.134	4.52361
601.605	4.84441
605.073	4.27074
608.542	4.2034
612.007	4.09345
615.473	3.47048
618.936	3.25779
622.397	3.46435
625.859	5.11275
629.318	6.66546
632.775	7.51812
636.233	7.87603
639.688	9.26953
643.142	10.3211
646.594	11.7545
650.045	12.2262
653.496	14.1075
656.944	14.7018
660.391	15.5599
663.837	16.4827
667.281	17.4332
670.724	19.7352
674.166	20.7624
677.606	24.0746
681.045	27.6622
684.483	30.1619
687.917	32.5492
691.352	33.7967
694.786	36.2013
698.219	39.1152
701.65	40.7397
705.078	43.7323
708.506	45.4564
711.934	47.0299
715.358	48.2281
718.782	48.7306
722.204	48.5072
725.626	49.3484
729.045	49.9718
732.464	49.656
735.881	49.7393
739.297	50.3923
742.711	51.2041
746.125	52.9534
749.537	52.5952
752.946	55.841
756.357	57.3525
759.764	58.138
763.17	58.9987
766.575	60.413
769.978	60.9923
773.382	62.297
776.783	62.9126
780.182	65.4305
783.581	65.563
786.978	66.6487
790.373	66.4765
793.768	69.297
797.161	70.5019
800.552	72.69
803.941	72.7725
807.33	73.6308
810.718	74.2344
814.105	73.9809
817.49	75.1618
820.873	76.9041
824.256	77.0557
827.637	75.7785
831.016	74.3087
834.395	72.5264
837.772	69.9417
841.147	67.6848
844.522	65.0605
847.894	63.8536
851.267	60.9515
854.637	58.6793
858.007	57.6277
861.374	54.7606
864.739	52.6988
868.106	51.527
871.469	50.7238
874.831	49.2145
878.193	48.8214
881.553	47.4408
884.911	47.8332
888.268	46.3678
891.623	46.1498
894.978	45.5271
898.331	44.0422
901.683	44.6095
905.033	43.4313
908.383	40.2534
911.731	39.2084
915.078	37.6358
918.423	37.0914
921.768	37.2988
925.111	36.7577
928.452	36.4373
931.791	35.8043
935.13	35.8422
938.468	36.7596
941.803	35.7422
945.139	32.78
948.473	32.2696
951.804	32.2601
955.136	31.6387
958.465	30.48
961.794	29.1008
965.12	28.3803
968.447	28.7785
971.771	28.0298
975.095	28.8986
978.417	28.0352
981.737	27.24
985.057	26.5057
988.375	27.056
991.691	24.4581
995.006	23.664
998.32	25.8105
1001.63	26.1744
1004.95	27.1206
1008.26	26.7014
1011.56	27.5306
1014.87	27.4033
1018.18	27.0622
1021.48	26.8743
1024.79	24.5858
1028.09	24.2838
1031.39	23.137
1034.69	22.0881
1037.99	17.5974
1041.29	16.5955
1044.58	15.1235
1047.88	15.137
1051.17	14.0367
1054.46	10.3455
1057.75	10.3904
1061.04	8.40622
1064.33	5.82589
1067.62	5.34234
1070.9	5.86636
1074.19	4.61686
1077.47	6.16789
1080.76	8.58706
1084.04	9.06398
1087.32	9.07388
1090.59	9.41925
1093.87	10.7165
1097.15	9.58902
1100.42	10.0948
1103.69	11.3362
1106.97	9.50375
1110.24	7.74187
1113.51	6.30812
1116.77	7.24795
1120.04	6.79447
1123.31	6.32391
1126.57	5.3153
1129.83	5.73641
1133.1	4.81684
1136.36	3.69348
1139.62	5.00391
1142.87	4.57086
1146.13	4.74393
1149.38	4.93394
1152.64	5.91955
1155.89	5.65038
1159.14	5.98646
1162.39	4.62792
1165.64	4.09143
1168.89	3.01238
1172.14	3.14621
1175.38	3.18196
1178.63	2.26114
1181.87	1.29781
1185.11	2.16352
1188.35	0.648664
1191.59	2.63515
1194.83	4.61762
1198.07	5.35212
1201.3	7.59499
1204.53	10.4767
1207.77	12.7968
1211	17.0189
1214.23	18.9737
1217.46	24.2121
1220.69	28.8912
1223.91	32.4774
1227.14	36.9707
1230.36	40.6068
1233.59	44.414
1236.81	47.5106
1240.03	50.4622
1243.25	52.3902
1246.46	55.3887
1249.68	59.0127
1252.9	63.2762
1256.11	65.5691
1259.32	68.3425
1262.54	70.7411
1265.75	74.2847
1268.96	76.8736
1272.16	79.353
1275.37	81.274
1278.57	82.2869
1281.78	84.0422
1284.98	84.3021
1288.18	84.105
1291.38	85.9208
1294.58	83.7425
1297.78	84.2051
1300.98	85.2852
1304.17	84.995
1307.37	84.0859
1310.56	84.6
1313.76	83.1673
1316.95	81.4611
1320.14	78.7666
1323.32	79.4647
1326.51	80.1114
1329.7	79.051
1332.88	78.473
1336.07	79.2884
1339.25	77.9285
1342.43	77.5809
1345.61	74.6303
1348.79	72.9182
1351.96	70.8915
1355.14	68.8549
1358.31	65.4342
1361.49	62.3082
1364.66	59.0784
1367.83	58.0007
1371	55.633
1374.17	54.6107
1377.34	54.0278
1380.5	52.5594
1383.67	50.0981
1386.83	47.8263
1390	45.2498
1393.16	42.0072
1396.32	40.4068
1399.48	38.0381
1402.64	36.6443
1405.79	36.2952
1408.95	36.2426
1412.1	38.6271
1415.26	39.7719
1418.41	42.0198
1421.56	45.2507
1424.71	48.8721
1427.86	54.3614
1431	60.3776
1434.15	64.9096
1437.29	69.6893
1440.44	74.2871
1443.58	77.7679
1446.72	81.8716
1449.86	82.1209
1453	82.5371
1456.14	81.612
1459.27	77.0341
1462.41	74.2789
1465.54	69.3711
1468.67	62.6391
1471.81	57.5909
1474.94	52.5951
1478.07	45.1539
1481.19	41.0503
1484.32	36.3599
1487.45	31.0999
1490.57	27.5179
1493.69	23.4072
1496.82	20.5694
1499.94	19.2916
1503.06	20.1773
1506.17	20.1852
1509.29	20.2173
1512.41	21.7551
1515.52	21.3852
1518.64	22.7792
1521.75	25.5519
1524.86	28.1469
1527.97	30.8986
1531.08	33.9088
1534.19	35.8641
1537.29	39.2516
1540.4	42.1697
1543.5	45.9866
1546.61	51.8861
1549.71	56.8372
1552.81	61.9655
1555.91	66.447
1559.01	70.1483
1562.11	73.189
1565.2	77.4206
1568.29	80.8624
1571.39	84.2036
1574.48	88.9089
1577.57	92.3902
1580.66	94.6988
1583.75	95.7945
1586.84	95.3985
1589.93	95.5635
1593.01	95.1281
1596.1	94.9328
1599.18	94.7482
1602.26	93.2625
1605.34	90.8568
1608.42	90.4109
1611.5	88.755
1614.58	88.5238
1617.65	88.1347
1620.73	89.3851
1623.8	91.1778
1626.87	93.3266
1629.95	95.6611
1633.02	96.7678
1636.09	98.2372
1639.15	100.341
1642.22	103.18
1645.29	105.822
1648.35	108.021
1651.42	108.212
1654.48	108.263
1657.54	107.674
1660.6	105.674
1663.66	103.139
1666.72	100.68
1669.77	96.9471
1672.83	90.9399
1675.88	86.3078
1678.93	80.6281
1681.99	74.2576
1685.04	68.2137
1688.09	62.0806
1691.13	55.086
1694.18	49.2463
1697.23	44.2498
1700.27	38.4518
1703.32	33.2064
1706.36	29.6828
1709.4	25.0228
1712.44	21.7584
1715.48	19.4656
1718.52	18.8829
1721.56	17.7058
1724.59	16.0161
1727.63	14.2505
1730.66	14.2444
1733.69	14.1
1736.72	13.3642
1739.75	12.0383
1742.78	10.487
1745.81	9.22881
1748.84	8.55742
1751.86	7.61066
1754.89	6.84914
1757.91	5.03867
1760.93	3.39755
1763.95	2.91369
1766.97	2.36522
1769.99	2.67761
1773.01	1.89339
1776.03	1.94476
1779.04	2.69681
1782.06	2.35611
1785.07	2.25074
1788.08	1.97366
1791.09	3.1245
1794.1	3.29333
1797.11	1.92044
1800.12	1.0015
1803.12	1.0585
1806.13	1.94009
1809.13	0.826296
1812.14	1.16141
1815.14	1.04303
1818.14	0.742649
1821.14	1.50863
1824.14	0.256921
1827.13	-0.217924
1830.13	0.140845
1833.12	0.583803
1836.12	0.404632
1839.11	0.715626
1842.1	0.543044
1845.09	0.744963
1848.08	0.765097
1851.07	1.37971
1854.06	1.3761
1857.04	2.25507
1860.03	3.02301
1863.01	3.09046
1866	2.49341
1868.98	2.05213
1871.96	2.19752
1874.94	2.64585
1877.92	4.24855
1880.89	4.4023
1882.48	3.81065
1885.47	5.35923
1888.46	5.32378
1891.44	5.56337
1894.43	4.26665
1897.41	4.32828
1900.4	4.92197
1903.38	6.12761
1906.36	4.90448
1909.34	4.21192
1912.32	4.26702
1915.29	4.37613
1918.27	4.49727
1921.25	4.68056
1924.22	5.01675
1927.2	5.45534
1930.17	6.81531
1933.14	5.40804
1936.11	6.34605
1939.08	6.45416
1942.05	6.54467
1945.01	6.65873
1947.98	7.45975
1950.94	7.21952
1953.91	6.56092
1956.87	6.83546
1959.83	7.08106
1962.79	6.9879
1965.75	6.05099
1968.71	5.73462
1971.67	7.04595
1974.62	8.07755
1977.58	7.53032
1980.53	7.80294
1983.48	7.5733
1986.43	7.36369
1989.38	7.54889
1992.33	8.60101
1995.28	9.81192
1998.23	11.0168
2001.18	11.2413
2004.12	12.0996
2007.06	13.1286
2010.01	13.7451
2012.95	13.6634
2015.89	14.1272
2018.83	14.7303
2021.77	15.3899
2024.71	15.7364
2027.64	15.9145
2030.58	16.828
2033.51	16.4002
2036.45	15.3821
2039.38	15.7405
2042.31	16.1362
2045.24	15.7227
2048.17	15.0155
2051.1	15.6062
2054.02	15.4541
2056.95	16.1805
2059.87	16.5242
2062.8	18.2761
2065.72	19.4224
2068.64	20.4793
2071.56	21.1286
2074.48	22.3209
2077.4	23.5131
2080.31	24.4892
2083.23	25.7899
2086.14	27.1062
2089.06	29.0715
2091.97	30.8896
2094.88	33.0721
2097.79	35.0888
2100.7	36.3205
2103.61	38.2431
2106.52	38.85
2109.43	41.0412
2112.33	43.6385
2115.24	44.0002
2118.14	46.3482
2121.04	49.4026
2123.94	53.138
2126.84	56.344
2129.74	60.0089
2132.64	63.4079
2135.54	67.0303
2138.43	70.8934
2141.33	74.4277
2144.22	77.7046
2147.11	80.565
2150.01	84.3246
2152.9	86.8787
2155.79	89.9919
2158.67	91.8215
2161.56	94.01
2164.45	96.9681
2167.33	98.4843
2170.22	98.4944
2173.1	98.7835
2175.98	99.4864
2178.86	98.8672
2181.74	98.8427
2184.62	96.781
2187.5	95.7938
2190.38	94.3416
2193.25	91.594
2196.13	88.5513
2199	85.7093
2201.88	81.7294
2204.75	78.6268
2207.62	75.5591
2210.49	73.0667
2213.36	67.9481
2216.22	63.6661
2219.09	59.4201
2221.96	55.1699
2224.82	52.0258
2227.68	49.2367
2230.55	46.0947
2233.41	44.4707
2236.27	41.0602
2239.12	38.0196
2241.98	36.2345
2244.84	36.2298
2247.7	35.6639
2250.55	33.4914
2253.41	33.0701
2256.26	33.7249
2259.11	32.1383
2261.96	30.3125
2264.81	30.2384
2267.66	30.2691
2270.51	29.6636
2273.35	28.3998
2276.2	28.1107
2279.04	26.6645
2281.89	25.711
2284.73	24.3082
2287.57	23.2882
2290.41	22.0153
2293.25	22.108
2296.09	21.6265
2298.93	20.506
2301.76	20.5228
2304.6	20.986
2307.44	21.1006
2310.27	21.6094
2313.1	22.2053
2315.93	23.16
2318.76	22.6854
2321.59	24.849
2324.42	25.6522
2327.25	24.2314
2330.07	23.2087
2332.9	22.8978
2335.72	21.51
2338.55	18.4196
2341.37	16.5589
2344.19	14.3521
2347.01	13.6167
2349.83	13.0227
2352.65	11.278
2355.46	10.6101
2358.28	9.23575
2361.09	8.37788
2363.91	7.3054
2366.72	7.37642
2369.53	7.90796
2372.34	7.86674
2375.15	8.40172
2377.96	8.34064
2380.77	9.59819
2383.58	9.77097
2386.38	10.1035
2389.19	10.0071
2391.99	9.91128
2394.8	9.29478
2397.6	8.6493
2400.4	9.034
2403.2	8.81141
2406	8.83377
2408.79	8.46344
2411.59	9.69134
2414.39	11.0947
2417.18	11.7794
2419.98	12.3304
2422.77	13.2917
2425.56	14.9032
2428.35	15.2463
2431.14	15.2361
2433.93	15.4424
2436.72	15.0181
2439.5	15.8095
2442.29	15.2147
2445.07	15.1723
2447.86	15.1731
2450.64	14.2812
2453.42	14.1194
2456.2	14.2599
2458.98	13.3192
2461.76	12.475
2464.54	12.5153
2467.32	12.3756
2470.09	11.743
2472.87	11.3828
2475.64	11.078
2478.41	11.0529
2481.18	10.5939
2483.95	9.36515
2486.72	9.00391
2489.49	8.40048
2492.26	8.87283
2495.03	7.99093
2497.79	6.70151
2500.56	6.51354
2503.32	5.85952
2506.09	4.97239
2508.85	5.63277
2511.61	4.92558
2514.37	4.4226
2517.13	4.7468
2519.89	4.61551
2522.64	4.47776
2525.4	4.12768
2528.15	3.33765
2530.91	4.08911
2533.66	4.08408
2536.41	3.40108
2539.16	2.40738
2541.91	3.68092
2544.66	3.5088
2547.41	4.04189
2550.16	4.08424
2552.9	3.6021
2555.65	3.69666
2558.39	3.75566
2561.13	4.3876
2563.88	3.73724
2566.62	3.38252
2569.36	2.9746
2572.1	1.30839
2574.84	0.643803
2577.57	0.287233
2580.31	0.413733
2583.05	0.0916514
2585.78	0.487338
2588.51	0.681943
2591.24	1.25927
2593.98	0.67943
2596.71	0.623399
2599.44	1.13314
2602.16	0.955222
2604.89	1.3318
2607.62	1.12513
2610.34	1.61045
2613.07	2.10318
2615.79	2.6977
2618.52	1.32289
2621.24	1.14229
2623.96	1.86383
2626.68	1.07198
2629.4	0.449171
2632.11	0.610922
2634.83	-0.953098
2637.55	-1.84026
2640.26	-1.22227
2642.98	0.385424
2645.69	1.21868
2648.4	2.78047
2651.11	3.3172
2653.82	4.38027
2656.53	4.92211
2659.24	5.77862
2661.95	6.60579
2664.65	6.31802
2667.36	7.0988
2670.06	7.40613
2672.76	7.17961
2675.47	7.35788
2678.17	8.45291
2680.87	8.02383
2683.57	7.64594
2686.27	7.45821
2688.97	7.14383
2691.66	6.22529
2694.36	5.63511
2697.05	6.57172
2699.75	6.02074
2702.44	6.31681
2705.13	8.07189
2707.82	9.40483
2710.51	10.53
2713.2	11.2201
2715.89	11.9712
2718.57	12.8725
2721.26	13.0127
2723.95	13.5635
2726.63	13.154
2729.31	13.3732
2732	13.329
2734.68	13.6661
2737.36	13.4386
2740.04	14.1316
2742.72	14.1516
2745.39	14.1167
2748.07	13.4127
2750.75	12.3893
2753.42	11.0407
2756.09	10.4168
2758.77	10.343
2761.44	9.0652
2764.11	8.85522
2766.78	7.7558
2769.45	7.54329
2772.12	7.0661
2774.78	6.17638
2777.45	6.71184
2780.12	6.06552
2782.78	4.90983
2785.44	4.77441
2788.11	4.1946
2790.77	3.85866
2793.43	4.20835
2796.09	5.73206
2798.75	6.43583
2801.4	6.89213
2804.06	7.21153
2806.72	7.48921
2809.37	8.29778
2812.03	9.74698
2814.68	10.6233
2817.33	13.7542
2819.98	16.4757
2822.63	19.2456
2825.28	23.514
2827.93	28.3937
2830.58	34.1692
2833.23	40.1524
2835.87	45.5383
2838.52	50.8469
2841.16	57.2771
2843.8	64.7904
2846.44	72.1566
2849.08	81.2894
2851.73	92.2274
2854.36	102.882
2857	113.301
2859.64	123.896
2862.28	133.402
2864.91	143.112
2867.55	150.279
2870.18	157.512
2872.81	165.773
2875.44	172.397
2878.07	179.002
2880.7	183.528
2883.33	188.832
2885.96	192.451
2888.59	197.887
2891.21	202.252
2893.84	208.317
2896.46	213.167
2899.09	218.357
2901.71	225.225
2904.33	233.493
2906.95	245.053
2909.57	256.923
2912.19	271.181
2914.81	285.827
2917.43	299.953
2920.04	311.893
2922.66	322.582
2925.27	331.024
2927.88	336.736
2930.5	339.805
2933.11	339.457
2935.72	338.632
2938.33	335.275
2940.94	328.49
2943.54	321.387
2946.15	311.495
2948.76	300.303
2951.36	289.824
2953.97	278.671
2956.57	266.682
2959.17	254.756
2961.77	242.55
2964.37	230.977
2966.97	220.017
2969.57	210.15
2972.17	200.177
2974.77	190.808
2977.36	181.095
2979.96	171.076
2982.55	159.539
2985.15	148.707
2987.74	137.173
2990.33	125.653
2992.92	114.06
2995.51	103.276
2998.1	93.9254
3000.69	83.8649
3003.27	75.3909
3005.86	67.7485
3008.44	60.5538
3011.03	52.4323
3013.61	48.5547
3016.19	45.0017
3018.78	40.0516
3021.36	36.6529
3023.94	34.9451
3026.51	33.0241
3029.09	31.8553
3031.67	30.9399
3034.24	31.4321
3036.82	32.322
3039.39	33.6685
3041.97	34.7257
3044.54	35.546
3047.11	37.685
3049.68	39.5502
3052.25	40.8652
3054.82	41.3248
3057.39	42.0615
3059.96	42.1064
3062.52	40.275
3065.09	39.2064
3067.65	37.0547
3070.22	35.0481
3072.78	32.3355
3075.34	29.9043
3077.9	27.491
3080.46	23.5839
3083.02	20.5647
3085.58	17.9912
3088.14	14.2075
3090.69	11.4475
3093.25	8.87406
3095.8	7.49557
3098.36	6.26494
3100.91	5.30984
3103.46	3.49192
3106.01	3.68691
3108.56	3.16684
3111.11	2.75738
3113.66	2.16904
3116.21	2.34963
3118.76	2.34786
3121.3	1.53955
3123.85	1.37926
3126.39	1.05188
3128.93	1.19412
3131.48	1.78588
3134.02	1.62764
3136.56	1.36413
3139.1	0.603774
3141.64	0.0416962
3144.17	-0.840775
3146.71	-1.49463
3149.25	-0.290986