File: data/Raman/poly_smoothed/Thy_50_12_37_1x_45s_532 nm_x100_100%_600 gr_mm_01.txt
#Acq. time (s)=	45
#Accumulations=	2
#Range (cm-¹)=	200...3150
#Windows=	2
#Auto scanning=	Off
#Autofocus=	Off
#Macrospot=	Off
#AutoExposure=	Off
#Spike filter=	Multiple accum.
#Delay time (s)=	0
#Binning=	1
#Readout mode=	Signal
#DeNoise=	Off
#ICS correction=	On
#Dark correction=	Off
#Inst. Process=	Off
#Detector Gain=	Best Dynamic Range
#Detector ADC=	20 kHz
#Detector temperature (°C)=	-69.85
#Instrument=	LabRAM HR Evol
#Detector=	Synapse
#Objective=	x100
#Grating=	600 gr/mm
#ND Filter=	100%
#Laser (nm)=	532
#Hole=	100.021
#Range=	Auto
#Laser Pol.=	No
#Raman. Pol.=	No
#Laser Pol. (°)=	-0.0007625
#Raman Pol. (°)=	89.9995
#Collection=	Microscope
#StageXY=	Marzhauser
#StageZ=	Marzhauser
#X (µm)=	-5132.5
#Y (µm)=	1520
#Z (µm)=	63.4
#Full time(mm:ss)=	3:18
#Project=
#Sample=
#Site=
#Title=	Thy_50_12_37_2x_45s_532 nm_x100_100%_600 gr_mm
#Remark=
#Date=	07.07.2022 11:59
#Acquired=	07.07.2022 11:59:20
#Base:Fit=	10.08.2022 10:04:30
#Base:Sub=	10.08.2022 10:04:45
#Filter:Polynom=	16.08.2022 10:20:25
#AxisType[0]=Intens
#AxisUnit[0]=Cnt
#AxisType[1]=Spectr
#AxisUnit[1]=1/cm
200.43	17.1273
204.061	17.0217
207.688	16.8591
211.316	15.5709
214.941	13.9336
218.566	12.4636
222.188	10.4709
225.809	6.41384
229.43	6.10593
233.047	5.34139
236.663	5.40302
240.278	4.63597
243.894	3.9404
247.506	2.82685
251.116	1.34349
254.725	0.993221
258.333	0.800151
261.939	3.34622
265.546	3.20396
269.15	2.83974
272.752	2.47873
276.353	3.25615
279.952	3.85326
283.55	4.28579
287.146	4.37641
290.739	4.91943
294.333	4.11408
297.925	3.77786
301.516	4.46706
305.106	5.3617
308.694	4.89086
312.279	4.98286
315.864	4.8122
319.448	6.87244
323.029	8.17647
326.61	8.40175
330.19	8.93756
333.766	8.65729
337.343	9.7612
340.917	9.20174
344.491	9.37409
348.062	8.73386
351.633	8.96577
355.201	6.89996
358.77	5.99995
362.335	5.85096
365.899	7.03837
369.464	7.20345
373.025	5.49437
376.585	4.66305
380.143	4.07143
383.702	3.2579
387.258	4.05153
390.812	3.58653
394.365	2.15557
397.916	2.49911
401.467	2.80511
405.015	2.77351
408.565	4.42107
412.111	5.19563
415.656	4.80479
419.197	5.58547
422.739	6.38764
426.279	5.34221
429.819	4.24356
433.356	3.23307
436.893	4.22312
440.428	4.49416
443.96	4.84136
447.492	5.54316
451.023	6.38691
454.553	7.55196
458.079	8.23982
461.606	9.77873
465.132	12.0264
468.654	14.1881
472.177	16.3576
475.696	17.3238
479.217	17.8891
482.733	19.0226
486.251	19.9053
489.765	20.338
493.278	21.561
496.791	23.7342
500.301	23.3068
503.81	24.4807
507.319	24.8078
510.825	25.1644
514.33	24.6351
517.833	25.959
521.337	25.9391
524.838	27.6319
528.337	27.1919
531.835	27.8935
535.332	28.051
538.827	27.573
542.321	26.4119
545.814	25.7951
549.305	25.4516
552.795	24.5841
556.284	24.5877
559.771	22.7538
563.257	20.4353
566.742	16.8816
570.223	14.6705
573.705	11.9198
577.185	10.7425
580.665	10.0784
584.141	9.07881
587.617	7.06629
591.092	5.83228
594.564	6.45964
598.037	7.10631
601.506	8.29742
604.976	9.1704
608.443	11.3465
611.91	11.3923
615.374	13.3052
618.839	13.118
622.3	13.2067
625.761	15.3872
629.221	15.5169
632.679	16.7897
636.135	18.5011
639.592	19.0812
643.045	17.595
646.497	17.7297
649.948	18.2336
653.398	18.1866
656.846	17.5682
660.293	17.8676
663.738	21.5621
667.185	22.7395
670.628	24.4697
674.067	23.7465
677.508	25.6083
680.947	28.512
684.385	30.4953
687.821	32.5589
691.256	34.588
694.69	34.8116
698.121	37.0734
701.552	38.5647
704.982	39.0607
708.41	40.25
711.836	40.3615
715.262	40.2621
718.685	40.2152
722.108	40.8365
725.53	42.297
728.949	43.9855
732.369	45.5449
735.785	47.3102
739.2	49.1464
742.616	51.5862
746.028	56.6724
749.441	59.9643
752.851	62.7273
756.26	63.6502
759.667	66.9844
763.075	70.1367
766.479	72.6624
769.883	75.1351
773.285	77.1916
776.686	79.1204
780.085	80.2865
783.484	79.3809
786.881	79.3041
790.276	80.2749
793.671	81.3309
797.064	81.5506
800.456	80.2401
803.846	79.8116
807.236	79.0161
810.624	78.4172
814.01	77.2668
817.394	76.3775
820.778	76.0187
824.161	74.5119
827.543	74.181
830.921	71.8799
834.3	71.2371
837.676	69.0368
841.053	68.2585
844.426	66.3385
847.8	63.6919
851.171	62.8993
854.542	60.8762
857.911	61.1791
861.279	60.6352
864.645	59.8319
868.01	58.1283
871.375	58.6437
874.737	59.7676
878.097	58.4862
881.457	56.6581
884.817	55.9305
888.174	56.1411
891.53	54.7818
894.884	54.0868
898.237	52.4986
901.589	52.1335
904.94	51.0607
908.289	48.346
911.637	46.4719
914.984	45.7134
918.33	43.3189
921.674	39.9313
925.015	40.4123
928.357	39.0896
931.698	37.2932
935.037	34.2624
938.373	34.1125
941.71	34.1022
945.046	31.9367
948.378	30.7922
951.711	31.8076
955.043	31.1181
958.372	30
961.701	29.5888
965.027	32.068
968.354	33.77
971.678	33.3816
975	33.323
978.324	34.7027
981.644	36.1121
984.962	37.5621
988.282	38.0216
991.598	38.3903
994.913	39.2492
998.227	39.3742
1001.54	41.1682
1004.85	42.482
1008.16	43.1495
1011.47	42.4321
1014.78	40.5946
1018.08	40.5963
1021.39	40.9984
1024.69	39.4408
1028	40.7854
1031.3	41.4753
1034.6	39.6816
1037.9	37.7594
1041.19	36.0857
1044.49	36.8225
1047.79	35.2164
1051.08	32.4376
1054.37	30.116
1057.66	27.8746
1060.95	26.5549
1064.24	24.0711
1067.53	20.8286
1070.81	19.8057
1074.1	18.7734
1077.38	17.8675
1080.66	17.1264
1083.94	15.342
1087.22	14.9931
1090.5	15.401
1093.78	15.021
1097.05	16.178
1100.33	16.6292
1103.6	17.5679
1106.87	17.8177
1110.15	19.4879
1113.41	17.4802
1116.68	16.3854
1119.95	16.3304
1123.21	15.5522
1126.48	14.2056
1129.74	12.2397
1133	10.5695
1136.26	9.13681
1139.52	8.44328
1142.78	7.27437
1146.04	5.53392
1149.29	4.75292
1152.55	4.37654
1155.8	2.54382
1159.05	1.5556
1162.3	0.287277
1165.55	-0.320369
1168.8	-0.885479
1172.05	-0.920525
1175.29	1.21944
1178.54	0.248507
1181.78	-0.127846
1185.02	0.680767
1188.26	1.46128
1191.5	1.50217
1194.74	0.714616
1197.97	3.00553
1201.21	4.29206
1204.44	5.18399
1207.68	7.54422
1210.91	9.57538
1214.14	12.5208
1217.37	16.5017
1220.6	20.1457
1223.82	23.1473
1227.05	27.4848
1230.27	32.0373
1233.49	35.4241
1236.72	38.3002
1239.94	41.8483
1243.16	45.9447
1246.37	51.0555
1249.59	55.2537
1252.8	56.9128
1256.02	58.3854
1259.23	58.5808
1262.44	61.9123
1265.66	64.5544
1268.87	68.8572
1272.07	72.356
1275.28	74.6761
1278.48	77.9012
1281.69	79.2102
1284.89	80.6167
1288.09	82.1496
1291.3	84.1819
1294.49	86.7025
1297.69	88.1061
1300.89	87.8713
1304.09	88.5855
1307.28	89.2285
1310.47	88.7233
1313.66	87.7874
1316.86	85.3721
1320.05	84.1662
1323.23	82.1768
1326.42	78.9435
1329.61	73.2366
1332.79	70.4541
1335.98	67.4583
1339.16	64.9262
1342.34	64.7016
1345.52	63.2252
1348.7	61.6054
1351.87	58.8427
1355.05	56.2612
1358.23	54.0513
1361.4	51.9977
1364.57	49.2569
1367.74	47.3894
1370.91	45.008
1374.08	43.3961
1377.25	42.2076
1380.42	39.477
1383.58	41.6064
1386.75	40.2921
1389.91	39.5092
1393.07	37.2965
1396.23	36.1641
1399.39	36.9688
1402.55	38.3623
1405.7	38.94
1408.86	41.4999
1412.01	45.7094
1415.17	48.9741
1418.32	54.5468
1421.47	60.8489
1424.62	67.8888
1427.77	74.5724
1430.92	80.3168
1434.06	86.546
1437.2	92.486
1440.35	96.3524
1443.49	99.1776
1446.63	100.375
1449.77	102.483
1452.91	103.014
1456.05	101.903
1459.18	99.1277
1462.32	94.3385
1465.45	87.9933
1468.59	81.1004
1471.72	73.8681
1474.85	66.659
1477.98	59.2355
1481.11	52.274
1484.23	47.0572
1487.36	42.1698
1490.48	36.9179
1493.61	33.7719
1496.73	30.9016
1499.85	27.6041
1502.97	25.7665
1506.09	25.2544
1509.2	24.7146
1512.32	23.9764
1515.44	24.0868
1518.55	26.1087
1521.66	29.1855
1524.77	30.7959
1527.88	34.2124
1530.99	34.9678
1534.1	36.428
1537.21	38.1197
1540.31	41.1956
1543.42	45.2885
1546.52	48.8696
1549.62	53.2772
1552.72	56.6519
1555.82	60.021
1558.92	63.6383
1562.02	67.3717
1565.11	68.1484
1568.21	71.2019
1571.3	73.1567
1574.39	74.5435
1577.49	76.3698
1580.58	80.8291
1583.67	81.7558
1586.75	83.3638
1589.84	84.4853
1592.93	87.2882
1596.01	88.2125
1599.09	87.2015
1602.18	85.1804
1605.26	82.5828
1608.34	80.7839
1611.41	80.6429
1614.49	80.7126
1617.57	81.6641
1620.64	83.1498
1623.72	83.4094
1626.79	84.6558
1629.86	85.9436
1632.93	86.9875
1636	89.9438
1639.07	91.9371
1642.14	94.7633
1645.2	97.7029
1648.27	99.5303
1651.33	102.142
1654.39	104.866
1657.45	106.792
1660.51	106.809
1663.57	105.999
1666.63	103.241
1669.69	100.064
1672.74	94.215
1675.79	89.1694
1678.85	82.4506
1681.9	75.415
1684.95	69.145
1688	63.6413
1691.05	58.0125
1694.1	53.4143
1697.14	47.6103
1700.19	42.817
1703.23	36.6498
1706.27	31.5582
1709.32	28.0707
1712.35	25.8113
1715.39	22.6179
1718.43	21.189
1721.47	18.9333
1724.5	18.3974
1727.54	18.1785
1730.57	17.745
1733.61	18.5902
1736.64	17.2624
1739.67	16.8385
1742.7	15.559
1745.72	14.4494
1748.75	13.8671
1751.78	14.0014
1754.8	13.457
1757.82	13.6493
1760.85	13.4568
1763.87	13.1485
1766.89	12.5703
1769.91	12.2648
1772.92	10.437
1775.94	8.37699
1778.96	7.62085
1781.97	7.4839
1784.98	7.55726
1788	7.41472
1791.01	6.27553
1794.01	4.93035
1797.02	3.9515
1800.03	4.6392
1803.04	3.97061
1806.04	4.34762
1809.05	3.92691
1812.05	4.66171
1815.05	4.63081
1818.05	3.49418
1821.05	4.28732
1824.05	5.76956
1827.05	6.59608
1830.04	7.17733
1833.04	6.30392
1836.03	5.61702
1839.03	5.9391
1842.02	6.04958
1845.01	5.71826
1848	5.50646
1850.99	6.1625
1853.97	5.90127
1856.96	5.71284
1859.94	4.59186
1862.93	3.99717
1865.91	2.74687
1868.89	3.03503
1871.87	3.00961
1874.85	3.72395
1877.83	4.70337
1880.81	5.80035
1882.56	5.27982
1885.55	5.67161
1888.54	5.10469
1891.52	4.87255
1894.51	5.24921
1897.49	4.95875
1900.48	4.12909
1903.46	2.69789
1906.44	1.86208
1909.42	2.03384
1912.4	2.06065
1915.38	1.87143
1918.35	2.13242
1921.33	1.79096
1924.3	1.30756
1927.28	1.33233
1930.25	1.16561
1933.22	2.07096
1936.19	2.12703
1939.16	3.40717
1942.13	4.12087
1945.09	5.08503
1948.06	5.9178
1951.03	6.78288
1953.99	6.17939
1956.95	6.83017
1959.91	6.35051
1962.87	5.24024
1965.83	5.49121
1968.79	4.83518
1971.75	4.2911
1974.7	3.63458
1977.66	3.01809
1980.61	3.54333
1983.56	4.07386
1986.52	4.33571
1989.47	3.96886
1992.41	3.47507
1995.36	3.82646
1998.31	4.7944
2001.26	6.15924
2004.2	6.93763
2007.15	6.42397
2010.09	6.19313
2013.03	7.84073
2015.97	7.58912
2018.91	9.56896
2021.85	10.3319
2024.79	10.8776
2027.72	11.0047
2030.66	11.8937
2033.59	11.9111
2036.53	11.7741
2039.46	12.2142
2042.39	12.9478
2045.32	13.1286
2048.25	13.2726
2051.18	12.865
2054.1	14.1486
2057.03	14.3754
2059.95	14.1313
2062.88	14.9104
2065.8	15.7444
2068.72	17.1949
2071.64	18.4121
2074.56	19.6518
2077.48	21.4822
2080.39	23.2086
2083.31	25.6011
2086.22	28.0036
2089.14	31.0559
2092.05	33.5764
2094.96	36.2413
2097.87	38.8454
2100.78	41.6753
2103.69	45.3734
2106.6	48.1949
2109.51	51.2507
2112.41	54.4571
2115.32	58.0385
2118.22	62.1502
2121.12	65.5765
2124.02	69.9847
2126.92	76.2931
2129.82	80.7365
2132.72	85.9454
2135.62	91.6571
2138.51	95.9181
2141.41	100.007
2144.3	105.048
2147.19	109.359
2150.09	113.649
2152.97	117.161
2155.86	120.145
2158.75	123.571
2161.64	126.207
2164.53	128.567
2167.41	130.175
2170.3	130.976
2173.18	131.472
2176.06	131.837
2178.94	130.126
2181.82	128.142
2184.7	125.632
2187.58	122.489
2190.46	119.694
2193.33	115.983
2196.21	113.376
2199.08	108.917
2201.95	105.089
2204.83	101.499
2207.7	96.382
2210.57	90.5562
2213.43	86.201
2216.3	81.9258
2219.17	77.7352
2222.03	73.2357
2224.9	69.1845
2227.76	65.4847
2230.62	62.5997
2233.49	59.6411
2236.34	55.2899
2239.2	52.1172
2242.06	48.9636
2244.92	45.7458
2247.78	42.0248
2250.63	39.6493
2253.48	37.2097
2256.34	35.5481
2259.19	34.1503
2262.04	33.1077
2264.89	31.3625
2267.74	29.6616
2270.59	28.5273
2273.43	27.6529
2276.28	26.2712
2279.12	25.2503
2281.97	24.5938
2284.81	24.091
2287.65	23.1097
2290.49	21.0444
2293.33	18.8692
2296.17	18.3675
2299.01	17.4193
2301.84	16.7013
2304.68	15.5398
2307.51	16.1355
2310.35	15.4133
2313.18	14.5305
2316.01	14.0494
2318.84	13.731
2321.67	13.4363
2324.5	12.3021
2327.33	11.513
2330.15	10.067
2332.98	8.76111
2335.8	7.42835
2338.62	5.43033
2341.45	5.22652
2344.27	4.82434
2347.09	4.35978
2349.91	3.74688
2352.72	3.37317
2355.54	2.43866
2358.36	1.06278
2361.17	-0.0151081
2363.98	0.486627
2366.8	0.707045
2369.61	1.79738
2372.42	2.44474
2375.23	3.2247
2378.04	3.56958
2380.85	4.18184
2383.66	3.43159
2386.46	3.7228
2389.26	3.89076
2392.07	3.61009
2394.87	2.96415
2397.67	2.64416
2400.47	2.949
2403.27	2.51495
2406.07	2.63324
2408.87	3.36615
2411.67	3.02578
2414.46	4.33943
2417.26	5.37163
2420.05	5.60587
2422.84	6.3857
2425.64	5.96451
2428.43	6.85725
2431.22	7.84997
2434.01	6.94362
2436.79	7.58346
2439.58	8.66568
2442.37	8.89043
2445.15	7.94229
2447.93	8.01763
2450.72	7.59215
2453.5	6.98832
2456.28	6.89727
2459.06	6.13825
2461.84	5.8393
2464.62	4.91202
2467.39	5.51603
2470.17	5.3478
2472.94	4.97103
2475.72	5.16767
2478.49	4.95101
2481.26	5.69657
2484.03	5.79005
2486.8	5.66834
2489.57	5.40455
2492.34	5.05784
2495.1	4.37421
2497.87	4.36856
2500.63	3.05748
2503.4	2.03818
2506.16	2.32197
2508.92	1.2869
2511.68	0.285276
2514.44	0.359792
2517.2	0.459003
2519.96	0.434816
2522.72	0.588152
2525.47	1.21662
2528.23	1.04987
2530.98	1.30836
2533.74	1.83063
2536.49	2.80452
2539.24	3.08805
2541.99	3.95411
2544.74	5.18212
2547.49	6.38936
2550.23	6.92515
2552.98	7.40471
2555.72	7.64257
2558.47	7.41121
2561.21	7.76723
2563.95	8.00626
2566.69	8.53422
2569.43	7.70498
2572.17	7.59402
2574.91	6.5917
2577.65	6.1178
2580.39	5.46672
2583.12	4.89029
2585.85	4.17141
2588.59	2.92964
2591.32	3.49874
2594.05	2.87651
2596.78	2.37193
2599.51	2.61232
2602.24	1.87443
2604.97	2.19164
2607.69	2.24809
2610.42	2.3757
2613.14	2.39376
2615.87	4.01231
2618.59	5.2127
2621.31	6.16388
2624.03	5.76086
2626.75	5.84088
2629.47	6.52084
2632.19	6.31581
2634.91	5.75085
2637.62	5.11232
2640.34	5.64861
2643.05	5.28834
2645.76	5.28657
2648.48	5.05544
2651.19	4.69336
2653.9	5.42618
2656.6	5.34665
2659.31	5.23029
2662.02	5.7195
2664.73	5.95943
2667.43	5.47746
2670.14	5.45452
2672.84	5.83814
2675.54	5.31179
2678.24	6.01078
2680.94	6.88695
2683.64	7.29764
2686.34	6.72391
2689.04	6.3154
2691.74	6.49055
2694.43	7.15565
2697.13	7.4966
2699.82	7.68658
2702.51	7.39253
2705.21	9.01556
2707.9	9.79691
2710.58	9.40832
2713.27	9.91996
2715.96	10.7697
2718.65	11.6223
2721.33	11.3865
2724.02	12.2966
2726.71	13.5281
2729.39	13.9727
2732.07	13.4459
2734.75	13.345
2737.43	12.9695
2740.11	12.0214
2742.79	11.3164
2745.47	10.8911
2748.14	10.5218
2750.82	9.11755
2753.49	8.3145
2756.17	7.74878
2758.84	7.11793
2761.51	6.05918
2764.18	5.38719
2766.85	4.87299
2769.52	3.76685
2772.19	2.70634
2774.86	1.44122
2777.52	0.596982
2780.19	0.394219
2782.85	0.225842
2785.52	-0.697104
2788.18	-0.16255
2790.84	0.0703845
2793.5	0.102394
2796.16	0.154966
2798.82	0.584243
2801.48	0.188289
2804.13	-0.228763
2806.79	-0.655912
2809.45	-0.34157
2812.1	-0.643521
2814.75	-0.8709
2817.41	0.120708
2820.06	2.93455
2822.71	7.7742
2825.36	14.2775
2828	20.4266
2830.65	28.1372
2833.3	35.4124
2835.94	42.5757
2838.59	50.3173
2841.23	58.4695
2843.87	67.2492
2846.52	76.5733
2849.16	86.8753
2851.8	96.8263
2854.44	109.086
2857.08	120.986
2859.71	131.651
2862.35	142.039
2864.98	152.214
2867.62	159.739
2870.25	166.763
2872.88	171.526
2875.52	176.575
2878.15	180.76
2880.78	185.978
2883.41	191.075
2886.03	197.49
2888.66	203.426
2891.29	207.785
2893.91	211.762
2896.54	217.338
2899.16	222.076
2901.78	228.315
2904.4	236.475
2907.02	245.824
2909.64	256.47
2912.26	268.382
2914.88	279.596
2917.5	291.715
2920.11	302.997
2922.73	311.67
2925.34	318.379
2927.96	323.113
2930.57	325.609
2933.18	324.316
2935.79	320.917
2938.4	316.013
2941.01	309.305
2943.62	300.776
2946.22	290.786
2948.83	278.986
2951.43	267.179
2954.04	253.942
2956.64	239.991
2959.24	227.132
2961.84	213.622
2964.45	200.987
2967.05	190.445
2969.64	179.342
2972.24	168.739
2974.84	157.157
2977.43	146.417
2980.03	136.218
2982.62	125.382
2985.22	114.279
2987.81	103.406
2990.4	92.7289
2992.99	82.1115
2995.58	71.7454
2998.17	63.2524
3000.76	55.2166
3003.34	48.3874
3005.93	41.7507
3008.52	34.3256
3011.1	28.1142
3013.68	23.3111
3016.27	19.9771
3018.85	16.6248
3021.43	12.7144
3024.01	10.0697
3026.59	9.54235
3029.16	8.40726
3031.74	8.78325
3034.32	8.02803
3036.89	9.09967
3039.47	10.4793
3042.04	12.2886
3044.61	13.9502
3047.18	14.0745
3049.75	15.4468
3052.32	16.2019
3054.89	16.7898
3057.46	16.6838
3060.03	16.1602
3062.59	16.1025
3065.16	14.8658
3067.72	13.3159
3070.29	12.0087
3072.85	9.93148
3075.41	7.70807
3077.97	6.26379
3080.53	4.42798
3083.09	1.79053
3085.65	0.612992
3088.21	0.208097
3090.76	-0.155391
3093.32	-0.22305
3095.87	-0.202784
3098.43	0.0955684
3100.98	1.31983
3103.53	2.58103
3106.08	3.52429
3108.63	4.82918
3111.18	5.70493
3113.73	6.96031
3116.28	7.74765
3118.83	8.87395
3121.37	9.91196
3123.92	11.9657
3126.46	13.8189
3129	14.8352
3131.55	16.6095
3134.09	18.2212
3136.63	19.6204
3139.17	21.0309
3141.71	23.1973
3144.24	25.6227
3146.78	28.249
3149.32	29.5663