File: data/Raman/poly_smoothed/Thy_50_12_16_1x_45s_532 nm_x100_100%_600 gr_mm_01.txt
#Acq. time (s)=	45
#Accumulations=	2
#Range (cm-¹)=	200...3150
#Windows=	2
#Auto scanning=	Off
#Autofocus=	Off
#Macrospot=	Off
#AutoExposure=	Off
#Spike filter=	Multiple accum.
#Delay time (s)=	0
#Binning=	1
#Readout mode=	Signal
#DeNoise=	Off
#ICS correction=	On
#Dark correction=	Off
#Inst. Process=	Off
#Detector Gain=	Best Dynamic Range
#Detector ADC=	20 kHz
#Detector temperature (°C)=	-69.85
#Instrument=	LabRAM HR Evol
#Detector=	Synapse
#Objective=	x100
#Grating=	600 gr/mm
#ND Filter=	100%
#Laser (nm)=	532
#Hole=	100.021
#Range=	Auto
#Laser Pol.=	No
#Raman. Pol.=	No
#Laser Pol. (°)=	-0.0007625
#Raman Pol. (°)=	89.9995
#Collection=	Microscope
#StageXY=	Marzhauser
#StageZ=	Marzhauser
#X (µm)=	-5139.3
#Y (µm)=	1472.4
#Z (µm)=	62.85
#Full time(mm:ss)=	3:19
#Project=
#Sample=
#Site=
#Title=	Thy_50_12_16_2x_45s_532 nm_x100_100%_600 gr_mm
#Remark=
#Date=	07.07.2022 10:25
#Acquired=	07.07.2022 10:25:25
#Base:Fit=	10.08.2022 10:04:29
#Base:Sub=	10.08.2022 10:04:45
#Filter:Polynom=	16.08.2022 10:20:24
#AxisType[0]=Intens
#AxisUnit[0]=Cnt
#AxisType[1]=Spectr
#AxisUnit[1]=1/cm
200.43	7.77824
204.061	9.68327
207.688	9.72168
211.316	7.96039
214.941	6.81802
218.566	6.90667
222.188	6.49662
225.809	4.96777
229.43	4.8631
233.047	3.91563
236.663	3.77564
240.278	4.60529
243.894	5.33398
247.506	4.07257
251.116	3.39363
254.725	4.15493
258.333	6.72608
261.939	6.65321
265.546	6.17654
269.15	6.05008
272.752	7.19945
276.353	8.26206
279.952	8.32633
283.55	7.81838
287.146	7.5222
290.739	7.44987
294.333	7.20508
297.925	6.83596
301.516	6.67135
305.106	8.4276
308.694	6.89551
312.279	7.90394
315.864	7.36895
319.448	7.29484
323.029	7.64326
326.61	10.712
330.19	11.0268
333.766	10.3607
337.343	12.2817
340.917	14.4565
344.491	13.7466
348.062	14.0573
351.633	13.5864
355.201	13.622
358.77	13.8708
362.335	14.0074
365.899	12.722
369.464	12.5753
373.025	11.1609
376.585	11.2586
380.143	12.0998
383.702	10.9642
387.258	9.80171
390.812	9.59058
394.365	8.72906
397.916	7.87626
401.467	7.87747
405.015	8.99141
408.565	9.02526
412.111	10.0899
415.656	9.45963
419.197	7.61208
422.739	7.07827
426.279	7.18644
429.819	6.05512
433.356	6.291
436.893	7.42737
440.428	9.08191
443.96	8.85472
447.492	9.30687
451.023	9.40812
454.553	10.613
458.079	11.1853
461.606	11.2347
465.132	12.3541
468.654	13.1712
472.177	12.5747
475.696	12.7439
479.217	14.153
482.733	15.5349
486.251	16.6246
489.765	18.3051
493.278	18.6526
496.791	16.8825
500.301	17.1573
503.81	17.8322
507.319	16.7052
510.825	18.4852
514.33	19.297
517.833	21.2891
521.337	23.9545
524.838	23.9898
528.337	23.9903
531.835	24.6046
535.332	24.6627
538.827	24.4379
542.321	23.5661
545.814	21.8724
549.305	20.5456
552.795	18.8424
556.284	17.614
559.771	15.8789
563.257	15.1219
566.742	13.8666
570.223	11.6248
573.705	8.93735
577.185	7.1834
580.665	5.19364
584.141	4.27411
587.617	4.94566
591.092	3.89864
594.564	2.64389
598.037	4.4231
601.506	4.13501
604.976	6.33153
608.443	8.49376
611.91	9.01358
615.374	9.30344
618.839	10.2106
622.3	10.8633
625.761	11.1546
629.221	12.4745
632.679	13.4462
636.135	14.5522
639.592	15.0183
643.045	16.4812
646.497	17.0987
649.948	18.2643
653.398	19.9534
656.846	21.9745
660.293	21.7616
663.738	23.8067
667.185	26.3492
670.628	28.4931
674.067	30.249
677.508	32.1701
680.947	34.5104
684.385	36.2808
687.821	38.3143
691.256	38.6803
694.69	39.5719
698.121	39.2844
701.552	40.9285
704.982	42.0219
708.41	43.4697
711.836	44.5314
715.262	45.2203
718.685	44.9394
722.108	46.6034
725.53	47.1946
728.949	46.9495
732.369	49.5573
735.785	51.7657
739.2	55.4931
742.616	57.6641
746.028	60.0962
749.441	62.6047
752.851	65.2456
756.26	67.4342
759.667	70.4496
763.075	71.9783
766.479	73.5165
769.883	75.33
773.285	76.5712
776.686	78.1722
780.085	79.2801
783.484	81.1738
786.881	82.43
790.276	84.1652
793.671	85.3159
797.064	85.2271
800.456	85.6268
803.846	85.1038
807.236	84.8971
810.624	85.5342
814.01	87.0202
817.394	86.5327
820.778	87.2344
824.161	87.6304
827.543	85.4863
830.921	83.7004
834.3	81.6604
837.676	80.7805
841.053	78.5256
844.426	77.471
847.8	73.7361
851.171	71.3708
854.542	68.892
857.911	67.4445
861.279	66.9656
864.645	66.6562
868.01	65.6091
871.375	63.9881
874.737	64.1003
878.097	65.0741
881.457	63.93
884.817	63.8121
888.174	64.9939
891.53	64.8434
894.884	65.138
898.237	63.93
901.589	64.5125
904.94	62.7933
908.289	61.2653
911.637	58.6884
914.984	56.286
918.33	54.6477
921.674	52.7407
925.015	51.276
928.357	48.746
931.698	47.5459
935.037	46.423
938.373	45.7389
941.71	45.1108
945.046	45.1569
948.378	44.6426
951.711	45.8608
955.043	46.5411
958.372	46.2431
961.701	45.2802
965.027	45.8942
968.354	47.5921
971.678	47.5332
975	47.406
978.324	46.3056
981.644	45.3968
984.962	43.6454
988.282	41.4982
991.598	39.9959
994.913	38.4225
998.227	38.2973
1001.54	37.8169
1004.85	38.2075
1008.16	36.8695
1011.47	36.5752
1014.78	37.3352
1018.08	38.0944
1021.39	38.3937
1024.69	39.1403
1028	39.6105
1031.3	39.9316
1034.6	38.8096
1037.9	37.9211
1041.19	37.944
1044.49	38.6385
1047.79	38.1865
1051.08	37.2023
1054.37	34.4789
1057.66	31.9791
1060.95	29.6428
1064.24	28.8891
1067.53	28.0069
1070.81	27.3637
1074.1	27.0168
1077.38	25.3747
1080.66	23.646
1083.94	20.5337
1087.22	20.6492
1090.5	20.6632
1093.78	20.6589
1097.05	20.7728
1100.33	20.4812
1103.6	20.0328
1106.87	19.3013
1110.15	19.1286
1113.41	17.2528
1116.68	15.9818
1119.95	15.8392
1123.21	14.8079
1126.48	14.4271
1129.74	12.8134
1133	12.2497
1136.26	11.2496
1139.52	10.2824
1142.78	9.51177
1146.04	9.90566
1149.29	9.35106
1152.55	7.96236
1155.8	4.62031
1159.05	3.25125
1162.3	2.93589
1165.55	3.38777
1168.8	3.28684
1172.05	3.39052
1175.29	4.51721
1178.54	3.79967
1181.78	3.37689
1185.02	3.3531
1188.26	3.97746
1191.5	3.14918
1194.74	4.23099
1197.97	6.05609
1201.21	8.54034
1204.44	10.3997
1207.68	11.7657
1210.91	13.8221
1214.14	15.2393
1217.37	17.5497
1220.6	19.7856
1223.82	21.7834
1227.05	24.4739
1230.27	26.1731
1233.49	27.2238
1236.72	31.0183
1239.94	32.6386
1243.16	35.7055
1246.37	38.2534
1249.59	42.6025
1252.8	45.5236
1256.02	48.4085
1259.23	50.8202
1262.44	54.1972
1265.66	57.9455
1268.87	60.8748
1272.07	65.2233
1275.28	69.6368
1278.48	72.7847
1281.69	74.7931
1284.89	76.5558
1288.09	77.5784
1291.3	78.5811
1294.49	78.2333
1297.69	77.4702
1300.89	77.0134
1304.09	75.9549
1307.28	74.8204
1310.47	74.7786
1313.66	72.0287
1316.86	70.5957
1320.05	68.3633
1323.23	67.426
1326.42	65.1303
1329.61	63.397
1332.79	61.2037
1335.98	59.5525
1339.16	57.1026
1342.34	56.3238
1345.52	53.0685
1348.7	50.1184
1351.87	49.1356
1355.05	46.9672
1358.23	43.2778
1361.4	40.4457
1364.57	38.4744
1367.74	36.9916
1370.91	35.4057
1374.08	33.5325
1377.25	31.8304
1380.42	31.1064
1383.58	30.6877
1386.75	31.0243
1389.91	28.8149
1393.07	27.8806
1396.23	27.4817
1399.39	26.6708
1402.55	27.333
1405.7	27.7972
1408.86	29.7033
1412.01	30.7223
1415.17	32.042
1418.32	34.7773
1421.47	37.8606
1424.62	41.4217
1427.77	46.6934
1430.92	52.1594
1434.06	57.3654
1437.2	60.9675
1440.35	65.0307
1443.49	67.6196
1446.63	69.8843
1449.77	70.5502
1452.91	70.1376
1456.05	69.6177
1459.18	68.0623
1462.32	63.6544
1465.45	59.102
1468.59	53.8184
1471.72	48.5527
1474.85	42.9666
1477.98	36.8087
1481.11	31.258
1484.23	25.7472
1487.36	21.3656
1490.48	18.8075
1493.61	16.6792
1496.73	16.0567
1499.85	15.0926
1502.97	15.7739
1506.09	17.2168
1509.2	18.3697
1512.32	18.9262
1515.44	19.5742
1518.55	21.5238
1521.66	24.8284
1524.77	26.8011
1527.88	28.8557
1530.99	30.267
1534.1	33.463
1537.21	34.662
1540.31	36.9465
1543.42	38.1945
1546.52	41.5676
1549.62	43.1648
1552.72	45.7263
1555.82	48.4672
1558.92	51.8083
1562.02	54.5128
1565.11	58.239
1568.21	59.6052
1571.3	61.0728
1574.39	63.0104
1577.49	64.8216
1580.58	66.3289
1583.67	66.7425
1586.75	66.02
1589.84	65.8187
1592.93	65.0562
1596.01	63.3461
1599.09	61.8888
1602.18	60.1719
1605.26	59.3473
1608.34	58.5014
1611.41	57.759
1614.49	56.5935
1617.57	56.3208
1620.64	57.3168
1623.72	58.7775
1626.79	60.7693
1629.86	62.4067
1632.93	65.3982
1636	68.4883
1639.07	70.4873
1642.14	74.2479
1645.2	76.5785
1648.27	79.1597
1651.33	81.3914
1654.39	82.4569
1657.45	82.3353
1660.51	81.0771
1663.57	79.2593
1666.63	77.1569
1669.69	72.7378
1672.74	69.4941
1675.79	65.4569
1678.85	60.812
1681.9	54.624
1684.95	50.0937
1688	44.4366
1691.05	39.0449
1694.1	34.4127
1697.14	29.6531
1700.19	24.663
1703.23	21.5478
1706.27	18.4405
1709.32	15.5315
1712.35	13.1809
1715.39	11.0589
1718.43	10.5636
1721.47	9.9456
1724.5	9.73255
1727.54	9.64043
1730.57	8.35751
1733.61	7.13999
1736.64	6.53155
1739.67	6.74617
1742.7	6.22779
1745.72	5.22883
1748.75	5.76643
1751.78	4.66744
1754.8	4.4147
1757.82	4.17933
1760.85	3.60694
1763.87	3.1849
1766.89	2.39122
1769.91	2.91558
1772.92	2.44016
1775.94	3.04543
1778.96	3.55582
1781.97	3.65439
1784.98	4.11635
1788	4.58347
1791.01	4.73873
1794.01	5.36084
1797.02	5.58307
1800.03	5.79915
1803.04	5.0631
1806.04	4.26249
1809.05	3.85818
1812.05	3.55699
1815.05	3.47709
1818.05	3.15793
1821.05	2.70429
1824.05	1.77118
1827.05	1.11328
1830.04	1.0024
1833.04	0.803544
1836.03	0.734544
1839.03	1.22668
1842.02	0.465028
1845.01	0.882466
1848	1.133
1850.99	0.810732
1853.97	1.12542
1856.96	1.39244
1859.94	1.58364
1862.93	2.62667
1865.91	3.34114
1868.89	2.52313
1871.87	1.42235
1874.85	1.5819
1877.83	0.199771
1880.81	0.80746
1882.56	1.30322
1885.55	1.37043
1888.54	1.71768
1891.52	2.22977
1894.51	2.83271
1897.49	2.64941
1900.48	3.14826
1903.46	4.25191
1906.44	5.78767
1909.42	6.13613
1912.4	7.22659
1915.38	7.30852
1918.35	7.73826
1921.33	8.02466
1924.3	7.70438
1927.28	8.85099
1930.25	8.94512
1933.22	9.356
1936.19	8.53545
1939.16	6.96428
1942.13	6.14923
1945.09	6.70263
1948.06	5.73153
1951.03	5.67889
1953.99	5.05915
1956.95	3.1361
1959.91	2.2554
1962.87	1.2092
1965.83	1.08507
1968.79	1.13491
1971.75	1.39017
1974.7	1.94234
1977.66	4.00532
1980.61	4.17898
1983.56	4.40211
1986.52	4.96165
1989.47	5.85663
1992.41	6.92341
1995.36	7.1696
1998.31	7.63462
2001.26	9.01106
2004.2	9.01682
2007.15	9.46491
2010.09	10.0408
2013.03	10.7214
2015.97	11.4855
2018.91	10.3452
2021.85	10.2048
2024.79	10.2952
2027.72	9.98281
2030.66	10.2366
2033.59	10.5021
2036.53	12.0218
2039.46	12.3098
2042.39	12.7284
2045.32	14.0367
2048.25	15.3034
2051.18	16.3563
2054.1	17.6427
2057.03	18.8154
2059.95	19.7904
2062.88	21.0764
2065.8	21.7971
2068.72	22.2328
2071.64	23.076
2074.56	24.6374
2077.48	26.3828
2080.39	27.1148
2083.31	28.2361
2086.22	30.2999
2089.14	31.5237
2092.05	32.81
2094.96	35.9678
2097.87	37.4809
2100.78	39.3259
2103.69	41.7413
2106.6	44.6616
2109.51	47.3867
2112.41	50.5101
2115.32	54.476
2118.22	59.1637
2121.12	63.3906
2124.02	68.4175
2126.92	72.3993
2129.82	76.0611
2132.72	80.6712
2135.62	84.9485
2138.51	88.5755
2141.41	92.4955
2144.3	96.3602
2147.19	100.521
2150.09	102.976
2152.97	105.603
2155.86	108.568
2158.75	110.938
2161.64	112.782
2164.53	115.04
2167.41	114.857
2170.3	115.303
2173.18	114.882
2176.06	115.231
2178.94	113.32
2181.82	111.433
2184.7	109.596
2187.58	107.724
2190.46	104.926
2193.33	102.094
2196.21	98.0469
2199.08	94.3968
2201.95	90.3853
2204.83	86.4345
2207.7	81.8776
2210.57	79.2701
2213.43	74.2281
2216.3	70.0573
2219.17	65.5593
2222.03	61.9487
2224.9	58.3467
2227.76	54.8072
2230.62	52.4965
2233.49	49.937
2236.34	47.5411
2239.2	43.8484
2242.06	41.0652
2244.92	39.5963
2247.78	36.9974
2250.63	34.5605
2253.48	33.3789
2256.34	31.6968
2259.19	29.8888
2262.04	28.6087
2264.89	27.7725
2267.74	26.728
2270.59	26.0636
2273.43	25.4821
2276.28	23.9713
2279.12	23.4798
2281.97	21.7828
2284.81	20.0031
2287.65	18.1781
2290.49	16.6389
2293.33	14.7851
2296.17	14.3546
2299.01	14.3412
2301.84	14.791
2304.68	14.5618
2307.51	13.7985
2310.35	12.7279
2313.18	12.7101
2316.01	11.2153
2318.84	9.94676
2321.67	9.54069
2324.5	8.48191
2327.33	8.29497
2330.15	7.93129
2332.98	8.18364
2335.8	8.56055
2338.62	7.8144
2341.45	7.4144
2344.27	6.40207
2347.09	6.09628
2349.91	5.17879
2352.72	4.75923
2355.54	3.83333
2358.36	3.51757
2361.17	3.35136
2363.98	3.25958
2366.8	4.68993
2369.61	4.96155
2372.42	5.42026
2375.23	5.36369
2378.04	5.07125
2380.85	3.99128
2383.66	3.88281
2386.46	3.56384
2389.26	4.54131
2392.07	4.48124
2394.87	5.11455
2397.67	5.69307
2400.47	6.91071
2403.27	7.09478
2406.07	7.33155
2408.87	7.36853
2411.67	7.88078
2414.46	8.57492
2417.26	8.48294
2420.05	8.686
2422.84	8.99498
2425.64	9.26113
2428.43	10.0779
2431.22	9.18471
2434.01	9.55305
2436.79	9.36886
2439.58	8.92474
2442.37	8.84433
2445.15	7.1113
2447.93	6.40236
2450.72	6.1652
2453.5	6.11147
2456.28	5.78099
2459.06	5.24103
2461.84	4.24845
2464.62	4.43729
2467.39	4.84637
2470.17	4.44982
2472.94	3.74738
2475.72	3.04013
2478.49	2.91018
2481.26	3.2095
2484.03	3.95332
2486.8	3.89006
2489.57	5.02611
2492.34	5.83812
2495.1	6.03838
2497.87	4.6105
2500.63	4.17846
2503.4	4.19821
2506.16	3.73853
2508.92	4.33194
2511.68	3.68543
2514.44	2.73127
2517.2	2.64093
2519.96	1.80923
2522.72	1.37504
2525.47	0.647872
2528.23	-0.0828461
2530.98	-0.215662
2533.74	0.42684
2536.49	-0.117742
2539.24	-0.551181
2541.99	-0.980228
2544.74	0.0725086
2547.49	0.59407
2550.23	0.961085
2552.98	1.96143
2555.72	2.23497
2558.47	3.69693
2561.21	4.147
2563.95	3.44477
2566.69	4.07276
2569.43	5.19217
2572.17	5.73034
2574.91	6.04827
2577.65	5.84641
2580.39	4.98214
2583.12	4.10016
2585.85	4.02171
2588.59	3.2617
2591.32	3.76944
2594.05	2.80192
2596.78	2.17882
2599.51	1.93088
2602.24	2.00828
2604.97	0.859241
2607.69	0.751221
2610.42	1.28946
2613.14	0.732157
2615.87	-0.145077
2618.59	0.11779
2621.31	1.09624
2624.03	1.48487
2626.75	2.01813
2629.47	1.21193
2632.19	0.538565
2634.91	1.25077
2637.62	1.37514
2640.34	1.32148
2643.05	1.40451
2645.76	1.78262
2648.48	1.75347
2651.19	2.28115
2653.9	2.58393
2656.6	2.82558
2659.31	2.88123
2662.02	2.34371
2664.73	2.39689
2667.43	2.97914
2670.14	3.20976
2672.84	3.10792
2675.54	2.79415
2678.24	2.3436
2680.94	1.83584
2683.64	2.78678
2686.34	2.91764
2689.04	2.96644
2691.74	3.05542
2694.43	2.8382
2697.13	3.33376
2699.82	4.20883
2702.51	5.509
2705.21	6.35836
2707.9	7.00389
2710.58	8.6746
2713.27	9.62459
2715.96	10.0941
2718.65	11.1815
2721.33	10.9801
2724.02	11.1828
2726.71	11.5729
2729.39	11.9189
2732.07	11.4554
2734.75	10.7053
2737.43	10.3741
2740.11	8.82856
2742.79	8.01979
2745.47	7.42677
2748.14	6.71594
2750.82	5.91201
2753.49	4.62392
2756.17	4.14411
2758.84	3.43468
2761.51	2.32791
2764.18	1.52301
2766.85	0.774278
2769.52	0.523454
2772.19	0.326448
2774.86	0.0049929
2777.52	-0.451849
2780.19	-0.391032
2782.85	0.0336809
2785.52	0.0846948
2788.18	0.600348
2790.84	0.689668
2793.5	0.465127
2796.16	0.466556
2798.82	0.731096
2801.48	1.2782
2804.13	2.57942
2806.79	2.98091
2809.45	3.82083
2812.1	4.11411
2814.75	4.76216
2817.41	6.12614
2820.06	8.61318
2822.71	12.2821
2825.36	17.0232
2828	20.5311
2830.65	25.2579
2833.3	30.7146
2835.94	36.136
2838.59	41.6627
2841.23	46.979
2843.87	53.2901
2846.52	60.3492
2849.16	67.8854
2851.8	75.5583
2854.44	83.3777
2857.08	91.5176
2859.71	99.8862
2862.35	107.68
2864.98	114.86
2867.62	120.781
2870.25	126.412
2872.88	130.377
2875.52	134.165
2878.15	138.284
2880.78	142.651
2883.41	147.76
2886.03	152.006
2888.66	155.911
2891.29	159.641
2893.91	163.714
2896.54	168.513
2899.16	173.845
2901.78	179.668
2904.4	185.424
2907.02	194.58
2909.64	204.233
2912.26	214.886
2914.88	225.346
2917.5	234.896
2920.11	245.078
2922.73	252.448
2925.34	258.02
2927.96	260.954
2930.57	262.822
2933.18	262.957
2935.79	260.708
2938.4	256.84
2941.01	252.48
2943.62	245.555
2946.22	237.9
2948.83	229.131
2951.43	219.743
2954.04	210.448
2956.64	200.495
2959.24	190.665
2961.84	181.745
2964.45	172.343
2967.05	162.986
2969.64	155.091
2972.24	147.305
2974.84	138.977
2977.43	130.387
2980.03	121.866
2982.62	113.393
2985.22	105.476
2987.81	96.4678
2990.4	88.4017
2992.99	79.422
2995.58	70.8394
2998.17	62.8095
3000.76	55.0408
3003.34	47.4345
3005.93	40.7453
3008.52	35.263
3011.1	31.0439
3013.68	26.8483
3016.27	23.3479
3018.85	20.1287
3021.43	18.1854
3024.01	16.6606
3026.59	14.9135
3029.16	13.8552
3031.74	13.9846
3034.32	14.3101
3036.89	15.3618
3039.47	16.5384
3042.04	17.9812
3044.61	19.1619
3047.18	20.3361
3049.75	21.2001
3052.32	22.257
3054.89	21.6126
3057.46	22.121
3060.03	20.8532
3062.59	20.4625
3065.16	19.484
3067.72	18.812
3070.29	17.9683
3072.85	16.3247
3075.41	14.7804
3077.97	12.838
3080.53	10.4808
3083.09	9.15161
3085.65	7.71008
3088.21	5.56612
3090.76	4.56554
3093.32	4.18796
3095.87	3.3798
3098.43	2.76555
3100.98	1.95255
3103.53	1.65188
3106.08	0.893947
3108.63	0.349604
3111.18	-0.177395
3113.73	-0.11482
3116.28	-0.719864
3118.83	-0.273574
3121.37	-0.0291989
3123.92	0.104496
3126.46	1.12817
3129	1.40372
3131.55	1.64754
3134.09	1.16545
3136.63	1.41482
3139.17	2.2928
3141.71	2.82351
3144.24	3.22582
3146.78	3.72638
3149.32	4.82293