File: data/Raman/poly_smoothed/Thy_20_09_36_1x_45s_532 nm_x100_100%_600 gr_mm_01.txt
#Acq. time (s)=	45
#Accumulations=	2
#Range (cm-¹)=	200...3150
#Windows=	2
#Auto scanning=	Off
#Autofocus=	Off
#Macrospot=	Off
#AutoExposure=	Off
#Spike filter=	Multiple accum.
#Delay time (s)=	0
#Binning=	1
#Readout mode=	Signal
#DeNoise=	Off
#ICS correction=	On
#Dark correction=	Off
#Inst. Process=	Off
#Detector Gain=	Best Dynamic Range
#Detector ADC=	20 kHz
#Detector temperature (°C)=	-69.85
#Instrument=	LabRAM HR Evol
#Detector=	Synapse
#Objective=	x100
#Grating=	600 gr/mm
#ND Filter=	100%
#Laser (nm)=	532
#Hole=	100.021
#Range=	Auto
#Laser Pol.=	No
#Raman. Pol.=	No
#Laser Pol. (°)=	-0.0007625
#Raman Pol. (°)=	89.9995
#Collection=	Microscope
#StageXY=	Marzhauser
#StageZ=	Marzhauser
#X (µm)=	-5921
#Y (µm)=	2869.7
#Z (µm)=	-223.35
#Full time(mm:ss)=	3:19
#Project=
#Sample=
#Site=
#Title=	Thy_20_09_36_2x_45s_532 nm_x100_100%_600 gr_mm
#Remark=
#Date=	29.06.2022 13:11
#Acquired=	29.06.2022 13:11:08
#Base:Fit=	10.08.2022 09:52:02
#Base:Fit=	10.08.2022 09:52:12
#Base:Sub=	10.08.2022 09:54:21
#Filter:Polynom=	16.08.2022 10:24:04
#AxisType[0]=Intens
#AxisUnit[0]=Cnt
#AxisType[1]=Spectr
#AxisUnit[1]=1/cm
200.523	32.4858
204.154	33.2523
207.781	31.5591
211.409	28.4191
215.034	25.7862
218.659	24.4633
222.281	21.9277
225.903	21.1686
229.522	18.5494
233.14	17.1488
236.756	15.672
240.373	13.5161
243.986	11.5759
247.598	9.89095
251.208	8.20614
254.818	5.76835
258.427	5.89484
262.034	4.00261
265.638	3.25381
269.242	1.81775
272.844	2.6499
276.445	2.17292
280.044	1.89816
283.642	2.55249
287.238	2.88645
290.833	3.7869
294.425	3.99802
298.017	4.75991
301.608	7.17918
305.198	10.1353
308.786	12.2644
312.371	13.6041
315.956	15.0123
319.54	16.1485
323.122	16.0429
326.701	16.3395
330.281	15.5341
333.857	16.1759
337.434	16.4705
341.008	15.2351
344.582	16.4486
348.153	16.3626
351.724	15.7217
355.292	14.5618
358.861	14.5682
362.426	14.7039
365.99	14.0598
369.555	14.0801
373.116	14.2378
376.676	13.2906
380.236	14.1757
383.793	13.6779
387.349	13.9724
390.903	15.555
394.456	13.7794
398.007	13.4944
401.56	11.8664
405.108	10.6096
408.656	8.07904
412.202	7.32553
415.746	7.22121
419.29	7.56018
422.831	8.43211
426.37	6.40531
429.909	7.18115
433.447	6.82841
436.983	6.23833
440.519	7.92561
444.052	9.13481
447.583	8.03535
451.114	8.19939
454.643	9.09819
458.169	10.1988
461.696	9.90849
465.222	12.2713
468.744	13.414
472.267	13.2348
475.787	14.3191
479.307	14.0584
482.823	15.0531
486.341	17.3809
489.855	17.6998
493.37	20.4655
496.881	23.5462
500.391	25.9562
503.902	27.81
507.409	27.8093
510.915	28.3541
514.42	29.5848
517.925	31.2384
521.427	31.8354
524.928	33.246
528.427	32.4573
531.925	31.3502
535.422	31.8588
538.917	32.1381
542.411	30.8686
545.903	29.8353
549.395	27.829
552.884	25.7026
556.373	22.7749
559.86	20.9927
563.346	19.4122
566.831	16.8701
570.314	15.6604
573.794	12.9409
577.274	10.9984
580.754	10.2521
584.23	7.37459
587.706	6.69231
591.181	4.81497
594.653	2.26343
598.126	2.22535
601.595	2.4435
605.065	3.25419
608.532	3.3592
611.999	3.26469
615.463	4.27432
618.928	6.556
622.389	6.75964
625.851	5.67078
629.31	7.42706
632.767	8.62369
636.223	9.23435
639.68	11.3963
643.134	14.6306
646.586	15.9828
650.037	17.6263
653.486	17.8207
656.936	17.6976
660.383	18.2639
663.829	20.6452
667.273	22.6453
670.716	23.1187
674.158	23.9358
677.598	23.8998
681.035	24.3691
684.473	26.5014
687.909	29.0728
691.344	29.2813
694.778	29.6021
698.211	32.2626
701.64	33.5368
705.07	34.0166
708.498	33.269
711.924	36.238
715.35	39.0407
718.774	41.6494
722.196	45.0797
725.618	46.8322
729.037	48.142
732.456	50.8239
735.873	51.5814
739.289	52.6264
742.703	54.2114
746.116	55.8639
749.529	58.7809
752.938	61.7865
756.347	64.1412
759.756	67.3922
763.162	68.8986
766.567	71.0891
769.97	73.9981
773.372	74.0571
776.773	75.2956
780.174	75.0075
783.573	74.8705
786.97	73.8214
790.365	73.5674
793.76	74.8714
797.153	76.9083
800.543	77.9725
803.933	79.0582
807.322	79.8171
810.71	80.2696
814.097	81.7955
817.483	81.8209
820.865	81.4101
824.248	81.0418
827.629	83.2225
831.008	82.3303
834.387	81.9564
837.765	80.8268
841.139	79.1485
844.514	75.7128
847.886	75.1126
851.259	72.9986
854.629	68.4868
857.997	66.326
861.366	62.9487
864.732	60.0775
868.098	58.4504
871.461	58.1533
874.823	56.1409
878.184	55.9003
881.545	56.7016
884.903	56.1327
888.26	55.793
891.616	54.3007
894.97	53.9247
898.323	53.7082
901.675	52.7424
905.026	52.4652
908.375	50.1326
911.723	48.525
915.07	45.0107
918.415	43.4045
921.76	42.5476
925.103	42.4446
928.443	43.1179
931.783	42.1438
935.123	41.0446
938.461	40.456
941.796	39.4057
945.131	38.5668
948.465	37.6847
951.797	38.309
955.128	39.6929
958.457	38.0794
961.786	38.0696
965.113	38.3007
968.44	40.7403
971.763	43.5888
975.086	45.8545
978.409	48.2017
981.729	49.3906
985.048	50.6117
988.367	50.305
991.683	49.1485
994.998	49.9292
998.312	50.48
1001.62	51.1078
1004.94	51.6627
1008.25	51.2798
1011.56	50.9738
1014.86	48.9743
1018.17	46.5723
1021.48	45.3098
1024.78	42.6295
1028.08	39.5417
1031.38	39.3777
1034.68	37.1521
1037.98	31.6716
1041.28	29.0772
1044.57	28.5583
1047.87	29.1871
1051.16	28.3409
1054.45	26.0242
1057.75	24.2865
1061.04	23.9697
1064.32	24.2248
1067.61	24.2099
1070.9	23.6477
1074.18	24.0778
1077.47	25.4165
1080.75	25.3126
1084.03	25.3861
1087.31	27.0084
1090.59	27.7266
1093.86	27.6784
1097.14	27.5362
1100.41	28.7375
1103.69	29.1176
1106.96	29.181
1110.23	28.0503
1113.5	26.461
1116.77	23.569
1120.03	20.158
1123.3	19.0916
1126.56	17.6791
1129.83	15.2701
1133.09	13.7284
1136.35	11.2384
1139.61	12.2831
1142.86	10.0271
1146.12	8.98557
1149.38	7.88779
1152.63	6.21115
1155.88	3.77095
1159.14	1.76061
1162.39	-0.31594
1165.63	-0.13636
1168.88	1.23961
1172.13	2.21214
1175.38	4.89729
1178.62	8.77807
1181.86	11.783
1185.1	13.3154
1188.34	15.2406
1191.58	17.5157
1194.82	20.173
1198.06	24.733
1201.29	29.2516
1204.53	34.6954
1207.76	39.4252
1210.99	43.0211
1214.22	47.3031
1217.45	52.0789
1220.68	56.233
1223.91	60.7393
1227.13	66.3802
1230.36	70.1706
1233.58	71.239
1236.8	73.9511
1240.02	77.558
1243.24	79.801
1246.46	83.8527
1249.67	87.2611
1252.89	90.961
1256.1	94.0569
1259.32	95.9982
1262.53	95.0764
1265.74	96.4515
1268.95	99.1151
1272.15	100.723
1275.36	103.232
1278.57	103.898
1281.77	106.789
1284.97	109.154
1288.18	110.142
1291.38	110.858
1294.58	113.555
1297.78	117.106
1300.97	117.443
1304.17	119.481
1307.36	119.836
1310.55	119.996
1313.75	120.14
1316.94	122.031
1320.13	122.717
1323.32	123.753
1326.5	124.896
1329.69	124.932
1332.87	122.738
1336.06	121.973
1339.24	120.651
1342.42	119.537
1345.6	118.943
1348.78	116.774
1351.96	114.14
1355.13	111.085
1358.31	106.29
1361.48	103.75
1364.65	100.043
1367.82	95.5833
1370.99	91.2213
1374.16	86.7071
1377.33	80.2967
1380.5	76.036
1383.66	72.9973
1386.83	70.0623
1389.99	68.068
1393.15	64.5887
1396.31	62.2041
1399.47	60.5109
1402.63	59.0122
1405.78	59.5833
1408.94	59.8239
1412.1	61.3167
1415.25	66.4586
1418.4	72.3903
1421.55	79.3209
1424.7	86.5721
1427.85	93.9335
1431	101.684
1434.14	109.687
1437.29	114.165
1440.43	120.546
1443.57	124.928
1446.71	127.427
1449.85	128.628
1452.99	127.471
1456.13	125.723
1459.26	121.657
1462.4	116.773
1465.54	109.972
1468.67	101.039
1471.8	90.8765
1474.93	82.1549
1478.06	72.8374
1481.19	63.6506
1484.31	56.8497
1487.44	49.1703
1490.56	45.0288
1493.69	42.0177
1496.81	38.2313
1499.93	36.3467
1503.05	33.9727
1506.17	31.9376
1509.28	31.8781
1512.4	31.0447
1515.52	31.9217
1518.63	32.8461
1521.74	34.9653
1524.85	35.7728
1527.96	37.3678
1531.07	38.9576
1534.18	40.7659
1537.29	43.5019
1540.39	46.6845
1543.5	50.5014
1546.6	55.8803
1549.7	62.2413
1552.8	69.2733
1555.9	77.2747
1559	84.1
1562.1	90.2813
1565.19	94.9172
1568.29	100.442
1571.38	105.851
1574.47	110.94
1577.56	115.176
1580.66	118.564
1583.74	121.877
1586.83	124.766
1589.92	125.314
1593.01	124.496
1596.09	123.647
1599.17	122.377
1602.25	119.446
1605.34	115.921
1608.41	111.985
1611.49	110.528
1614.57	108.577
1617.65	108.394
1620.72	108.253
1623.79	109.004
1626.87	109.916
1629.94	111.496
1633.01	113.041
1636.08	115.558
1639.15	119.385
1642.21	125.973
1645.28	130.15
1648.34	134.333
1651.41	136.706
1654.47	139.013
1657.53	141.688
1660.59	142.366
1663.65	140.202
1666.71	137.929
1669.76	135.288
1672.82	130.107
1675.87	122.88
1678.93	115.443
1681.98	106.659
1685.03	98.7311
1688.08	90.2945
1691.13	80.1257
1694.17	71.1597
1697.22	62.6089
1700.27	53.7033
1703.31	47.4232
1706.35	41.076
1709.39	37.0237
1712.43	33.3614
1715.47	29.1667
1718.51	25.1283
1721.55	23.2216
1724.58	21.9132
1727.62	21.024
1730.65	19.2628
1733.68	19.0518
1736.72	17.6034
1739.74	16.1157
1742.77	15.9119
1745.8	14.5915
1748.83	12.4122
1751.85	11.2573
1754.88	10.3293
1757.9	9.4824
1760.92	7.70042
1763.95	5.51263
1766.96	4.09518
1769.98	3.58019
1773	2.41049
1776.02	1.22592
1779.03	0.950626
1782.05	0.987324
1785.06	2.01208
1788.07	1.24527
1791.08	2.04729
1794.09	2.35326
1797.1	3.40784
1800.11	3.34174
1803.12	3.41463
1806.12	4.00096
1809.12	4.90235
1812.13	4.3833
1815.13	3.88303
1818.13	4.08421
1821.13	4.22611
1824.13	4.25719
1827.13	4.93089
1830.12	4.8956
1833.12	4.76223
1836.11	4.50195
1839.1	4.32874
1842.09	3.78753
1845.09	3.21341
1848.08	2.74161
1851.06	3.1034
1854.05	2.96345
1857.04	2.91286
1860.02	1.45341
1863.01	1.4219
1865.99	1.73445
1868.97	0.774439
1871.95	1.52286
1874.93	1.06453
1877.91	0.881379
1880.89	0.430683
1882.46	-0.0657718
1885.45	0.0900406
1888.43	0.548546
1891.42	0.564154
1894.41	-0.587003
1897.39	-0.742086
1900.37	0.0514481
1903.36	0.37172
1906.34	0.266588
1909.32	0.802441
1912.29	1.77939
1915.27	1.90324
1918.25	2.75109
1921.23	3.81494
1924.2	3.52213
1927.17	3.93066
1930.15	4.13948
1933.12	3.57837
1936.09	4.64488
1939.06	3.99763
1942.02	3.8095
1944.99	3.57634
1947.96	2.39206
1950.92	2.7893
1953.88	2.36363
1956.85	2.94664
1959.81	3.36218
1962.77	3.45076
1965.73	2.42663
1968.69	2.79782
1971.64	3.05434
1974.6	3.30287
1977.55	4.13631
1980.51	5.57314
1983.46	6.13421
1986.41	5.59535
1989.36	5.81831
1992.31	6.01524
1995.26	6.06057
1998.21	4.64821
2001.15	4.49027
2004.1	4.20065
2007.04	4.25739
2009.99	4.93169
2012.93	4.71458
2015.87	4.69969
2018.81	5.8236
2021.75	6.82572
2024.68	7.73758
2027.62	9.01817
2030.56	9.07856
2033.49	10.3097
2036.42	10.5895
2039.36	11.3218
2042.29	11.4417
2045.22	12.1748
2048.14	13.299
2051.07	14.2573
2054	13.7189
2056.93	13.3172
2059.85	13.4388
2062.77	13.3474
2065.7	12.6801
2068.62	12.6301
2071.54	12.2542
2074.46	12.0927
2077.38	11.898
2080.29	12.484
2083.21	12.3616
2086.12	13.127
2089.04	13.4136
2091.95	14.1415
2094.86	15.2891
2097.77	15.2275
2100.68	14.74
2103.59	15.8918
2106.5	17.9508
2109.41	19.1328
2112.31	21.515
2115.21	23.6714
2118.12	26.5208
2121.02	30.5628
2123.92	34.0997
2126.82	37.5464
2129.72	40.5745
2132.62	44.1715
2135.51	47.4985
2138.41	50.5742
2141.31	53.8114
2144.2	57.7687
2147.09	61.9406
2149.98	65.2775
2152.87	68.4211
2155.76	72.3392
2158.65	75.3679
2161.54	77.8719
2164.43	79.0819
2167.31	81.0633
2170.2	82.6878
2173.08	84.1188
2175.96	84.8945
2178.84	84.7391
2181.72	85.1176
2184.6	84.3952
2187.48	83.0782
2190.36	80.9107
2193.23	78.3443
2196.11	75.6602
2198.98	71.2339
2201.85	68.1313
2204.72	63.7547
2207.59	59.4365
2210.46	55.7308
2213.33	52.4831
2216.2	47.19
2219.07	43.2658
2221.93	39.3079
2224.8	36.061
2227.66	33.3992
2230.52	30.9271
2233.39	29.4388
2236.25	27.1202
2239.1	26.174
2241.96	23.4545
2244.82	22.1936
2247.68	22.3007
2250.53	20.732
2253.38	19.8684
2256.24	18.7368
2259.09	17.8377
2261.94	17.4651
2264.79	18.094
2267.64	18.2958
2270.49	17.7741
2273.33	17.6377
2276.18	16.8638
2279.02	16.0247
2281.87	15.2154
2284.71	14.3392
2287.55	13.8249
2290.39	13.9536
2293.23	12.7843
2296.07	12.282
2298.91	12.2286
2301.74	12.7078
2304.58	11.9958
2307.41	11.245
2310.25	10.3032
2313.08	10.3494
2315.91	9.62344
2318.74	8.68915
2321.57	8.02528
2324.4	9.09803
2327.23	9.73542
2330.05	10.1278
2332.88	10.5251
2335.7	11.3136
2338.52	10.0105
2341.35	9.43713
2344.17	8.23513
2346.99	6.86942
2349.81	5.85721
2352.62	5.15332
2355.44	5.19342
2358.26	3.7932
2361.07	2.61934
2363.89	1.85715
2366.7	2.02323
2369.51	2.08586
2372.32	1.99048
2375.13	0.995492
2377.94	1.25125
2380.75	0.962278
2383.56	0.887046
2386.36	1.15995
2389.17	2.75075
2391.97	3.39921
2394.77	3.26113
2397.58	2.80178
2400.38	3.22212
2403.18	3.15867
2405.97	2.97426
2408.77	1.73064
2411.57	2.0762
2414.37	2.32691
2417.16	2.87034
2419.95	3.2017
2422.75	3.34001
2425.54	2.988
2428.33	3.4339
2431.12	3.15879
2433.91	3.22117
2436.7	3.58487
2439.48	4.25837
2442.27	4.31585
2445.05	4.90316
2447.84	5.18034
2450.62	5.05869
2453.4	5.3093
2456.18	5.34229
2458.96	5.20888
2461.74	4.09943
2464.52	3.56792
2467.29	3.73379
2470.07	3.44812
2472.85	3.4224
2475.62	3.80036
2478.39	3.47561
2481.16	3.74996
2483.93	3.25635
2486.7	4.02469
2489.47	2.82054
2492.24	2.21491
2495.01	1.82381
2497.77	0.758207
2500.54	0.310081
2503.3	-0.0209877
2506.06	0.577657
2508.83	1.22595
2511.59	1.77043
2514.35	2.11675
2517.11	2.56067
2519.86	2.78555
2522.62	3.301
2525.38	4.18223
2528.13	3.67073
2530.89	3.96404
2533.64	3.58599
2536.39	4.30071
2539.14	4.94645
2541.89	4.8948
2544.64	4.39786
2547.39	4.09277
2550.14	3.86564
2552.88	4.7647
2555.63	4.3688
2558.37	4.05533
2561.11	3.9713
2563.86	4.33248
2566.6	4.72137
2569.34	5.28884
2572.08	5.19715
2574.82	5.30602
2577.55	6.10169
2580.29	6.09879
2583.02	6.14158
2585.76	6.34279
2588.49	6.78376
2591.22	6.79104
2593.96	6.01897
2596.69	5.27424
2599.42	3.65149
2602.14	3.88101
2604.87	2.86039
2607.6	2.16885
2610.32	0.383903
2613.05	1.0904
2615.77	0.189469
2618.49	0.286945
2621.22	-0.344783
2623.94	-1.07104
2626.66	-1.64285
2629.37	-1.37067
2632.09	-0.587876
2634.81	0.225458
2637.53	-0.034624
2640.24	0.580232
2642.96	1.4344
2645.67	2.76512
2648.38	3.3114
2651.09	4.09248
2653.8	5.12398
2656.51	6.03861
2659.22	6.79797
2661.93	6.76473
2664.63	6.91315
2667.34	7.00914
2670.04	7.85179
2672.75	7.66846
2675.45	7.45271
2678.15	8.15268
2680.85	7.92765
2683.55	7.36875
2686.25	7.78102
2688.94	7.34602
2691.64	7.72777
2694.34	9.03394
2697.03	9.61679
2699.73	10.3743
2702.42	10.7849
2705.11	12.1694
2707.8	13.5048
2710.49	13.6875
2713.18	14.9396
2715.87	13.9157
2718.55	15.3657
2721.24	16.8054
2723.93	16.8624
2726.61	18.0217
2729.29	17.6294
2731.98	17.6352
2734.66	17.5785
2737.34	17.4511
2740.02	17.5078
2742.7	17.9885
2745.37	17.5176
2748.05	17.2645
2750.72	15.928
2753.4	15.2218
2756.07	13.5465
2758.75	12.8804
2761.42	10.7381
2764.09	9.29166
2766.76	8.9465
2769.43	7.19484
2772.1	5.6096
2774.76	4.38244
2777.43	3.20738
2780.1	2.41604
2782.76	2.8477
2785.42	3.29041
2788.09	2.57326
2790.75	1.89146
2793.41	2.48536
2796.07	2.44036
2798.73	2.42232
2801.39	2.54524
2804.04	2.96156
2806.7	3.00706
2809.35	3.65627
2812.01	3.50222
2814.66	3.34635
2817.31	3.82728
2819.96	6.69088
2822.61	9.98285
2825.26	15.0982
2827.91	21.0593
2830.56	28.0573
2833.21	35.1131
2835.85	42.0354
2838.5	50.2976
2841.14	60.7528
2843.78	72.2181
2846.42	85.0348
2849.06	99.7211
2851.71	116.479
2854.34	133.565
2856.98	150.194
2859.62	166.478
2862.26	180.453
2864.89	194.088
2867.53	206.594
2870.16	218.411
2872.79	228.085
2875.42	237.024
2878.05	244.841
2880.68	252.602
2883.31	261.174
2885.94	267.694
2888.57	275.776
2891.19	282.659
2893.82	288.883
2896.44	296.011
2899.07	304.452
2901.69	314.998
2904.31	329.394
2906.93	345.511
2909.55	364.611
2912.17	385.251
2914.79	407.38
2917.41	426.184
2920.02	441.33
2922.64	455.644
2925.25	466.141
2927.86	473.454
2930.48	477.218
2933.09	477.543
2935.7	475.737
2938.31	469.847
2940.92	461.319
2943.53	449.947
2946.13	435.555
2948.74	418.819
2951.34	400.898
2953.95	381.677
2956.55	363.706
2959.15	345.551
2961.75	327.891
2964.35	310.453
2966.95	294.736
2969.55	279.76
2972.15	265.344
2974.75	252.298
2977.34	237.88
2979.94	222.196
2982.53	205.992
2985.13	190.461
2987.72	174.94
2990.31	158.604
2992.9	143.466
2995.49	128.56
2998.08	115.644
3000.67	102.439
3003.25	89.3164
3005.84	78.1793
3008.42	66.7477
3011.01	57.0761
3013.59	48.3239
3016.17	42.6164
3018.76	37.3363
3021.34	32.6807
3023.92	28.0901
3026.49	24.4278
3029.07	22.9055
3031.65	23.4305
3034.23	24.4756
3036.8	25.9246
3039.38	27.535
3041.95	30.0312
3044.52	32.0017
3047.09	35.3459
3049.66	36.9667
3052.23	39.2047
3054.8	40.2608
3057.37	40.7762
3059.94	40.4408
3062.5	39.6449
3065.07	37.2323
3067.63	35.4072
3070.2	32.4872
3072.76	28.9114
3075.32	24.9667
3077.88	20.9937
3080.44	16.4483
3083	12.1858
3085.56	8.18517
3088.12	5.14735
3090.67	2.78164
3093.23	2.96576
3095.78	1.9475
3098.34	1.61318
3100.89	1.8636
3103.44	2.32957
3105.99	3.77585
3108.54	4.41762
3111.09	5.66235
3113.64	7.12152
3116.19	7.09922
3118.74	8.41396
3121.28	9.21364
3123.83	10.3172
3126.37	10.8422
3128.91	11.8001
3131.46	11.9055
3134	12.5992
3136.54	13.1235
3139.08	13.9048
3141.62	15.4534
3144.16	17.6008
3146.69	19.8809
3149.23	22.9546