File: data/Raman/poly_smoothed/Thy_20_09_01_1x_45s_532 nm_x100_100%_600 gr_mm_01.txt
#Acq. time (s)=	45
#Accumulations=	2
#Range (cm-¹)=	200...3150
#Windows=	2
#Auto scanning=	Off
#Autofocus=	Off
#Macrospot=	Off
#AutoExposure=	Off
#Spike filter=	Multiple accum.
#Delay time (s)=	0
#Binning=	1
#Readout mode=	Signal
#DeNoise=	Off
#ICS correction=	On
#Dark correction=	Off
#Inst. Process=	Off
#Detector Gain=	Best Dynamic Range
#Detector ADC=	20 kHz
#Detector temperature (°C)=	-69.85
#Instrument=	LabRAM HR Evol
#Detector=	Synapse
#Objective=	x100
#Grating=	600 gr/mm
#ND Filter=	100%
#Laser (nm)=	532
#Hole=	100.021
#Range=	Auto
#Laser Pol.=	No
#Raman. Pol.=	No
#Laser Pol. (°)=	-0.0007625
#Raman Pol. (°)=	89.9995
#Collection=	Microscope
#StageXY=	Marzhauser
#StageZ=	Marzhauser
#X (µm)=	-5929.2
#Y (µm)=	2832.7
#Z (µm)=	-223.85
#Full time(mm:ss)=	3:18
#Project=
#Sample=
#Site=
#Title=	Thy_20_09_01_2x_45s_532 nm_x100_100%_600 gr_mm
#Remark=
#Date=	29.06.2022 10:38
#Acquired=	29.06.2022 10:38:44
#Base:Fit=	10.08.2022 09:49:32
#Base:Fit=	10.08.2022 09:49:42
#Base:Fit=	10.08.2022 09:49:53
#Base:Fit=	10.08.2022 09:50:12
#Base:Fit=	10.08.2022 09:50:26
#Base:Fit=	10.08.2022 09:50:30
#Base:Fit=	10.08.2022 09:50:43
#Base:Fit=	10.08.2022 09:52:02
#Base:Fit=	10.08.2022 09:52:12
#Base:Sub=	10.08.2022 09:54:21
#Filter:Polynom=	16.08.2022 10:24:04
#AxisType[0]=Intens
#AxisUnit[0]=Cnt
#AxisType[1]=Spectr
#AxisUnit[1]=1/cm
200.523	52.8735
204.154	48.156
207.781	40.7023
211.409	34.106
215.034	28.1991
218.659	25.1728
222.281	22.5639
225.903	21.7233
229.522	19.6611
233.14	17.5345
236.756	14.135
240.373	13.5648
243.986	12.6078
247.598	11.3369
251.208	10.2395
254.818	8.58547
258.427	7.22234
262.034	6.1364
265.638	6.56578
269.242	7.30818
272.844	9.33739
276.445	10.879
280.044	12.344
283.642	11.1512
287.238	10.2965
290.833	10.3978
294.425	12.8338
298.017	15.4757
301.608	17.4187
305.198	21.0633
308.786	22.614
312.371	24.3517
315.956	25.3226
319.54	25.4339
323.122	25.4523
326.701	25.6015
330.281	25.3747
333.857	24.0409
337.434	21.7021
341.008	19.8173
344.582	18.5209
348.153	18.7266
351.724	17.7092
355.292	17.3048
358.861	18.4217
362.426	17.0801
365.99	15.1818
369.555	14.0268
373.116	12.8417
376.676	12.6076
380.236	12.6578
383.793	12.6544
387.349	13.0854
390.903	12.9525
394.456	10.7952
398.007	9.62319
401.56	8.3605
405.108	7.1761
408.656	6.44063
412.202	4.72344
415.746	4.94982
419.29	6.36441
422.831	7.21312
426.37	6.59402
429.909	6.03014
433.447	6.55878
436.983	6.12489
440.519	6.07844
444.052	7.07299
447.583	6.45683
451.114	7.85292
454.643	10.3546
458.169	11.6938
461.696	12.422
465.222	14.1012
468.744	16.4942
472.267	17.9418
475.787	18.477
479.307	18.7143
482.823	18.5544
486.341	19.45
489.855	21.9579
493.37	22.5039
496.881	24.9168
500.391	26.3394
503.902	27.3061
507.409	26.1272
510.915	25.5718
514.42	23.7841
517.925	24.2981
521.427	23.7942
524.928	23.8611
528.427	22.5764
531.925	22.9961
535.422	22.482
538.917	22.2924
542.411	20.2619
545.903	17.7889
549.395	16.7508
552.884	15.4848
556.373	14.8075
559.86	12.4811
563.346	9.66663
566.831	9.35762
570.314	9.52326
573.794	8.44443
577.274	7.29671
580.754	7.1719
584.23	6.31523
587.706	6.25914
591.181	5.46858
594.653	4.81924
598.126	4.45636
601.595	4.2681
605.065	4.7207
608.532	3.53838
611.999	4.69269
615.463	3.25455
618.928	6.39335
622.389	7.23415
625.851	8.17081
629.31	9.08254
632.767	10.1802
636.223	12.4074
639.68	12.7782
643.134	14.9088
646.586	13.6476
650.037	14.7043
653.486	15.5013
656.936	15.5575
660.383	17.0183
663.829	19.2953
667.273	18.2771
670.716	17.3557
674.158	16.9383
677.598	16.2838
681.035	16.2876
684.473	15.8261
687.909	18.416
691.344	21.4534
694.778	21.5663
698.211	23.8539
701.64	25.9843
705.07	27.883
708.498	30.8723
711.924	31.8565
715.35	34.5494
718.774	37.062
722.196	38.2633
725.618	39.7188
729.037	41.3817
732.456	43.6275
735.873	43.8732
739.289	44.4733
742.703	46.6869
746.116	48.4056
749.529	49.069
752.938	48.3745
756.347	52.3927
759.756	54.9947
763.162	57.8506
766.567	59.3498
769.97	63.436
773.372	65.5324
776.773	68.0336
780.174	66.9045
783.573	68.1513
786.97	69.458
790.365	70.9234
793.76	72.4393
797.153	72.2694
800.543	75.8329
803.933	76.4119
807.322	75.8646
810.71	76.9694
814.097	77.4924
817.483	77.7289
820.865	75.478
824.248	75.5965
827.629	76.0335
831.008	75.5931
834.387	74.8936
837.765	75.0103
841.139	75.0677
844.514	74.6253
847.886	71.3594
851.259	69.1005
854.629	67.2382
857.997	62.5726
861.366	61.0882
864.732	56.0287
868.098	54.5842
871.461	52.7362
874.823	50.335
878.184	47.2718
881.545	46.9601
884.903	46.2128
888.26	43.6074
891.616	42.4003
894.97	41.1177
898.323	40.5898
901.675	39.0892
905.026	38.3933
908.375	38.0373
911.723	37.7231
915.07	38.7648
918.415	37.9087
921.76	36.6183
925.103	36.0063
928.443	35.166
931.783	33.2763
935.123	32.7331
938.461	31.6075
941.796	30.261
945.131	28.1756
948.465	26.4322
951.797	26.435
955.128	23.9638
958.457	21.3675
961.786	19.0164
965.113	19.8589
968.44	21.7147
971.763	23.1797
975.086	23.1313
978.409	26.1487
981.729	25.8538
985.048	25.3912
988.367	25.5946
991.683	26.2565
994.998	26.7999
998.312	27.1185
1001.62	25.6378
1004.94	26.6213
1008.25	26.3686
1011.56	26.9277
1014.86	24.7381
1018.17	22.9164
1021.48	19.5044
1024.78	17.3218
1028.08	16.5372
1031.38	14.837
1034.68	13.5008
1037.98	10.1716
1041.28	10.316
1044.57	10.1467
1047.87	11.7201
1051.16	12.7908
1054.45	12.029
1057.75	9.36557
1061.04	7.30066
1064.32	7.41371
1067.61	8.15594
1070.9	10.4685
1074.18	10.4554
1077.47	11.0345
1080.75	8.99442
1084.03	11.6761
1087.31	11.9324
1090.59	13.1897
1093.86	13.8517
1097.14	13.8072
1100.41	14.63
1103.69	15.269
1106.96	16.4282
1110.23	14.4664
1113.5	14.8121
1116.77	12.4687
1120.03	12.2793
1123.3	10.3396
1126.56	7.40259
1129.83	6.49214
1133.09	6.38683
1136.35	4.49062
1139.61	4.69051
1142.86	5.29316
1146.12	6.62448
1149.38	5.18449
1152.63	5.24213
1155.88	3.08006
1159.14	2.82444
1162.39	3.2528
1165.63	3.38434
1168.88	4.14561
1172.13	5.95457
1175.38	5.51858
1178.62	5.9619
1181.86	4.88487
1185.1	4.83829
1188.34	5.49211
1191.58	3.88373
1194.82	4.68695
1198.06	4.97184
1201.29	6.75768
1204.53	10.3499
1207.76	15.7904
1210.99	20.6176
1214.22	24.0211
1217.45	28.3474
1220.68	31.7949
1223.91	36.5705
1227.13	40.3796
1230.36	45.1844
1233.58	49.7197
1236.8	51.9163
1240.02	53.5698
1243.24	56.0692
1246.46	58.661
1249.67	60.3999
1252.89	60.5564
1256.1	60.1149
1259.32	60.153
1262.53	59.7005
1265.74	60.3523
1268.95	61.5102
1272.15	62.2273
1275.36	64.3882
1278.57	64.5746
1281.77	68.7529
1284.97	72.3099
1288.18	74.2461
1291.38	75.5243
1294.58	79.2268
1297.78	81.9541
1300.97	87.0563
1304.17	91.7931
1307.36	95.5025
1310.55	99.222
1313.75	100.823
1316.94	102.211
1320.13	103.923
1323.32	106.181
1326.5	106.397
1329.69	105.479
1332.87	104.462
1336.06	103.094
1339.24	102.83
1342.42	100.243
1345.6	97.6215
1348.78	94.8786
1351.96	88.6696
1355.13	84.1957
1358.31	80.337
1361.48	77.2596
1364.65	73.3155
1367.82	68.8082
1370.99	65.2388
1374.16	63.9854
1377.33	62.5497
1380.5	62.0651
1383.66	58.2035
1386.83	55.9063
1389.99	54.968
1393.15	52.6968
1396.31	52.5654
1399.47	53.6769
1402.63	53.3561
1405.78	51.9169
1408.94	53.6748
1412.1	54.6924
1415.25	57.9604
1418.4	61.1115
1421.55	64.3273
1424.7	67.1542
1427.85	70.7877
1431	75.5879
1434.14	81.9867
1437.29	88.3818
1440.43	91.1274
1443.57	92.3025
1446.71	94.4454
1449.85	95.0154
1452.99	94.9386
1456.13	93.7446
1459.26	91.2023
1462.4	87.2219
1465.54	81.9573
1468.67	75.1687
1471.8	70.911
1474.93	65.4035
1478.06	58.0836
1481.19	50.7121
1484.31	45.3586
1487.44	40.1504
1490.56	34.062
1493.69	30.0545
1496.81	28.2597
1499.93	27.0442
1503.05	26.1017
1506.17	26.5629
1509.28	26.7238
1512.4	27.1806
1515.52	26.7649
1518.63	25.7271
1521.74	27.9602
1524.85	28.1826
1527.96	30.9999
1531.07	32.3691
1534.18	33.488
1537.29	36.6141
1540.39	37.2983
1543.5	40.7053
1546.6	44.0951
1549.7	49.2012
1552.8	52.4994
1555.9	56.1043
1559	61.0343
1562.1	66.5245
1565.19	71.577
1568.29	75.8162
1571.38	82.4003
1574.47	88.3267
1577.56	93.0546
1580.66	97.1436
1583.74	100.42
1586.83	104.307
1589.92	107.323
1593.01	107.619
1596.09	107.03
1599.17	105.061
1602.25	100.759
1605.34	99.5035
1608.41	94.7642
1611.49	92.5431
1614.57	89.5778
1617.65	87.613
1620.72	85.1074
1623.79	81.5049
1626.87	80.8054
1629.94	80.2603
1633.01	80.2643
1636.08	82.4604
1639.15	85.0443
1642.21	87.1495
1645.28	90.028
1648.34	92.1423
1651.41	93.0198
1654.47	93.9672
1657.53	94.0671
1660.59	93.827
1663.65	93.5953
1666.71	90.0686
1669.76	84.0596
1672.82	80.5373
1675.87	74.7944
1678.93	68.9668
1681.98	63.7048
1685.03	57.2302
1688.08	52.1687
1691.13	45.1187
1694.17	38.9197
1697.22	32.906
1700.27	27.0376
1703.31	23.9513
1706.35	19.2777
1709.39	17.118
1712.43	14.7593
1715.47	12.4123
1718.51	9.29933
1721.55	8.52359
1724.58	6.22883
1727.62	5.82466
1730.65	3.67731
1733.68	4.08496
1736.72	3.28575
1739.74	2.5242
1742.77	2.5259
1745.8	3.92314
1748.83	2.37677
1751.85	0.829855
1754.88	2.04635
1757.9	2.41016
1760.92	2.6209
1763.95	2.96522
1766.96	1.56491
1769.98	1.70533
1773	0.983857
1776.02	2.21397
1779.03	2.8853
1782.05	3.28541
1785.06	4.18038
1788.07	4.86779
1791.08	7.01298
1794.09	8.66504
1797.1	9.54513
1800.11	9.22104
1803.12	9.54657
1806.12	9.80685
1809.12	10.0674
1812.13	10.3392
1815.13	10.2009
1818.13	10.3225
1821.13	8.73335
1824.13	7.14131
1827.13	7.16209
1830.12	7.72094
1833.12	7.11163
1836.11	6.98427
1839.1	5.94769
1842.09	5.41508
1845.09	5.51685
1848.08	5.95135
1851.06	5.97634
1854.05	5.52927
1857.04	5.17288
1860.02	6.04837
1863.01	6.3318
1865.99	6.93353
1868.97	6.5554
1871.95	6.12219
1874.93	5.50622
1877.91	4.90594
1880.89	3.58632
1882.46	3.49806
1885.45	2.58775
1888.43	2.12562
1891.42	1.52115
1894.41	0.582815
1897.39	1.31466
1900.37	1.64669
1903.36	1.11003
1906.34	0.980751
1909.32	0.603964
1912.29	1.43981
1915.27	2.59351
1918.25	3.45097
1921.23	2.41385
1924.2	1.86628
1927.17	1.94672
1930.15	2.00815
1933.12	3.14189
1936.09	3.71898
1939.06	3.96856
1942.02	3.9774
1944.99	3.85512
1947.96	4.48746
1950.92	4.66689
1953.88	4.15614
1956.85	5.18464
1959.81	5.27451
1962.77	6.24346
1965.73	7.02513
1968.69	6.59897
1971.64	6.11643
1974.6	6.07862
1977.55	5.99723
1980.51	5.71457
1983.46	6.98874
1986.41	7.88456
1989.36	7.75046
1992.31	8.27185
1995.26	8.30191
1998.21	8.99602
2001.15	8.29587
2004.1	7.98904
2007.04	9.85867
2009.99	8.97788
2012.93	9.22985
2015.87	9.70791
2018.81	8.64447
2021.75	8.48892
2024.68	9.42681
2027.62	9.3736
2030.56	8.26537
2033.49	7.86358
2036.42	6.5656
2039.36	6.06492
2042.29	6.59581
2045.22	6.3604
2048.14	5.61787
2051.07	5.58115
2054	5.94136
2056.93	6.58161
2059.85	6.99393
2062.77	7.34939
2065.7	7.22296
2068.62	6.81811
2071.54	7.5237
2074.46	7.77913
2077.38	9.12676
2080.29	10.1537
2083.21	10.0609
2086.12	10.6876
2089.04	9.80941
2091.95	10.6496
2094.86	13.4345
2097.77	15.088
2100.68	15.3899
2103.59	15.8188
2106.5	16.8225
2109.41	18.8261
2112.31	18.9654
2115.21	19.6947
2118.12	19.709
2121.02	21.154
2123.92	22.8161
2126.82	24.709
2129.72	26.9467
2132.62	28.7472
2135.51	30.6906
2138.41	32.4857
2141.31	35.938
2144.2	38.4949
2147.09	40.1891
2149.98	41.4819
2152.87	44.5638
2155.76	45.6327
2158.65	46.9558
2161.54	48.428
2164.43	49.2981
2167.31	50.9751
2170.2	53.1314
2173.08	53.0547
2175.96	52.8901
2178.84	51.934
2181.72	50.2839
2184.6	49.2292
2187.48	49.1597
2190.36	48.3025
2193.23	47.7308
2196.11	46.5822
2198.98	44.9885
2201.85	43.5435
2204.72	41.1462
2207.59	39.4808
2210.46	37.0244
2213.33	34.7469
2216.2	31.944
2219.07	31.443
2221.93	30.517
2224.8	28.7836
2227.66	26.2843
2230.52	23.5946
2233.39	21.4773
2236.25	21.7009
2239.1	21.2731
2241.96	20.3167
2244.82	20.3063
2247.68	20.6286
2250.53	21.4756
2253.38	22.1229
2256.24	22.1571
2259.09	20.477
2261.94	19.6866
2264.79	18.8288
2267.64	17.5931
2270.49	15.0588
2273.33	14.4622
2276.18	13.5662
2279.02	14.0127
2281.87	13.2593
2284.71	12.3576
2287.55	11.3545
2290.39	9.61692
2293.23	7.86048
2296.07	8.35129
2298.91	8.54666
2301.74	8.34045
2304.58	8.46231
2307.41	8.28949
2310.25	9.15642
2313.08	10.5871
2315.91	13.172
2318.74	13.7665
2321.57	12.5707
2324.4	12.8763
2327.23	10.6315
2330.05	10.1129
2332.88	10.1384
2335.7	9.64646
2338.52	9.50763
2341.35	10.4334
2344.17	9.07987
2346.99	8.07852
2349.81	5.80367
2352.62	5.42726
2355.44	5.23916
2358.26	4.78831
2361.07	3.57149
2363.89	4.83626
2366.7	5.6923
2369.51	5.82702
2372.32	6.56495
2375.13	5.51224
2377.94	6.85505
2380.75	6.93985
2383.56	5.97614
2386.36	4.85096
2389.17	3.25097
2391.97	3.49912
2394.77	4.69628
2397.58	4.59181
2400.38	4.49344
2403.18	5.13167
2405.97	5.12186
2408.77	5.22493
2411.57	6.25329
2414.37	6.35058
2417.16	7.01788
2419.95	6.87194
2422.75	9.13588
2425.54	8.43416
2428.33	7.14492
2431.12	9.57289
2433.91	10.3883
2436.7	10.789
2439.48	11.3737
2442.27	9.30825
2445.05	9.65861
2447.84	9.21079
2450.62	7.63485
2453.4	7.39869
2456.18	7.58392
2458.96	7.59686
2461.74	8.12594
2464.52	6.93868
2467.29	6.34652
2470.07	6.12344
2472.85	5.50004
2475.62	5.83871
2478.39	6.04323
2481.16	5.32257
2483.93	3.82807
2486.7	3.61461
2489.47	2.18746
2492.24	1.90781
2495.01	-0.139264
2497.77	0.978373
2500.54	0.874975
2503.3	-1.37945
2506.06	-2.19625
2508.83	-2.06583
2511.59	-1.82713
2514.35	-0.727584
2517.11	-0.519956
2519.86	0.220015
2522.62	1.05257
2525.38	2.28599
2528.13	4.01047
2530.89	5.50344
2533.64	6.1471
2536.39	7.02863
2539.14	6.74267
2541.89	7.74587
2544.64	8.05886
2547.39	7.77279
2550.14	8.9434
2552.88	9.59257
2555.63	9.12155
2558.37	9.98111
2561.11	9.44068
2563.86	9.1598
2566.6	8.10383
2569.34	7.3861
2572.08	7.49327
2574.82	7.64678
2577.55	7.43941
2580.29	7.08776
2583.02	6.5227
2585.76	5.12025
2588.49	6.04463
2591.22	5.38525
2593.96	5.60418
2596.69	5.65746
2599.42	4.36358
2602.14	4.40791
2604.87	3.81198
2607.6	3.38197
2610.32	4.48876
2613.05	4.89174
2615.77	4.40188
2618.49	5.96082
2621.22	7.80312
2623.94	8.61114
2626.66	10.8345
2629.37	11.3371
2632.09	11.3109
2634.81	12.5587
2637.53	13.5256
2640.24	13.7549
2642.96	13.9282
2645.67	14.9468
2648.38	14.4531
2651.09	14.7913
2653.8	15.2178
2656.51	14.2789
2659.22	13.4138
2661.93	12.5445
2664.63	12.6876
2667.34	12.5143
2670.04	13.3263
2672.75	12.7065
2675.45	12.6817
2678.15	12.8072
2680.85	12.8535
2683.55	13.0618
2686.25	14.2961
2688.94	14.3072
2691.64	12.997
2694.34	12.5331
2697.03	10.6628
2699.73	11.3055
2702.42	11.1884
2705.11	11.8025
2707.8	11.2309
2710.49	12.0417
2713.18	11.5576
2715.87	9.91706
2718.55	11.1604
2721.24	10.1844
2723.93	9.1739
2726.61	10.0503
2729.29	12.2289
2731.98	12.191
2734.66	12.8396
2737.34	13.4223
2740.02	14.2498
2742.7	13.7776
2745.37	13.5735
2748.05	12.2419
2750.72	11.3177
2753.4	9.99643
2756.07	9.55109
2758.75	9.06475
2761.42	8.35494
2764.09	7.48795
2766.76	6.47292
2769.43	6.2607
2772.1	5.44458
2774.76	5.39672
2777.43	5.61459
2780.1	4.83012
2782.76	6.17027
2785.42	6.26016
2788.09	5.65835
2790.75	6.12177
2793.41	6.50883
2796.07	5.72358
2798.73	5.1216
2801.39	5.29218
2804.04	5.12659
2806.7	4.00057
2809.35	1.81886
2812.01	-0.672672
2814.66	-0.66222
2817.31	-0.461278
2819.96	1.82966
2822.61	3.48621
2825.26	6.99743
2827.91	10.1802
2830.56	13.9901
2833.21	18.6916
2835.85	24.8832
2838.5	30.9223
2841.14	37.6771
2843.78	45.9518
2846.42	54.3215
2849.06	63.0068
2851.71	72.485
2854.34	83.4614
2856.98	92.8832
2859.62	102.267
2862.26	110.085
2864.89	118.058
2867.53	125.217
2870.16	129.707
2872.79	132.987
2875.42	136.484
2878.05	140.856
2880.68	145.61
2883.31	150.042
2885.94	155.095
2888.57	159.359
2891.19	162.784
2893.82	168.052
2896.44	172.842
2899.07	177.444
2901.69	183.683
2904.31	190.782
2906.93	201.329
2909.55	212.893
2912.17	223.499
2914.79	235.951
2917.41	247.004
2920.02	255.022
2922.64	263.355
2925.25	268.231
2927.86	271.359
2930.48	271.884
2933.09	271.705
2935.7	270.435
2938.31	265.8
2940.92	260.784
2943.53	257.097
2946.13	250.858
2948.74	243.273
2951.34	233.814
2953.95	225.097
2956.55	217.327
2959.15	207.385
2961.75	196.719
2964.35	189.874
2966.95	181.247
2969.55	173.338
2972.15	165.743
2974.75	156.542
2977.34	148.097
2979.94	137.074
2982.53	127.646
2985.13	119.362
2987.72	109.098
2990.31	98.342
2992.9	89.4808
2995.49	79.9812
2998.08	71.1865
3000.67	60.4947
3003.25	54.0851
3005.84	47.8926
3008.42	41.1831
3011.01	33.0461
3013.59	27.9233
3016.17	23.5066
3018.76	20.7289
3021.34	15.9696
3023.92	12.9249
3026.49	10.6193
3029.07	9.29468
3031.65	7.87067
3034.23	8.65839
3036.8	8.39723
3039.38	9.49007
3041.95	11.1718
3044.52	13.2782
3047.09	15.8086
3049.66	17.3544
3052.23	17.0783
3054.8	17.803
3057.37	17.9232
3059.94	17.2396
3062.5	15.8755
3065.07	15.18
3067.63	14.6428
3070.2	11.2983
3072.76	9.37815
3075.32	8.84266
3077.88	6.9546
3080.44	4.62094
3083	1.84658
3085.56	-0.685355
3088.12	-1.03354
3090.67	-0.884178
3093.23	-1.62791
3095.78	-0.149634
3098.34	0.6105
3100.89	1.99983
3103.44	4.28641
3105.99	5.32649
3108.54	6.75377
3111.09	9.13876
3113.64	10.6187
3116.19	11.7251
3118.74	12.4487
3121.28	14.0716
3123.83	15.4619
3126.37	15.6067
3128.91	18.2403
3131.46	19.0435
3134	20.452
3136.54	21.6753
3139.08	22.3539
3141.62	21.5231
3144.16	21.4815
3146.69	22.1947
3149.23	23.2607