File: data/Raman/poly_smoothed/Thy_00_07_4_1x_45s_532 nm_x100_100%_600 gr_mm_01.txt
#Acq. time (s)=	45
#Accumulations=	2
#Range (cm-¹)=	200...3150
#Windows=	2
#Auto scanning=	Off
#Autofocus=	Off
#Macrospot=	Off
#AutoExposure=	Off
#Spike filter=	Multiple accum.
#Delay time (s)=	0
#Binning=	1
#Readout mode=	Signal
#DeNoise=	Off
#ICS correction=	On
#Dark correction=	Off
#Inst. Process=	Off
#Detector Gain=	Best Dynamic Range
#Detector ADC=	20 kHz
#Detector temperature (°C)=	-69.85
#Instrument=	LabRAM HR Evol
#Detector=	Synapse
#Objective=	x100
#Grating=	600 gr/mm
#ND Filter=	100%
#Laser (nm)=	532
#Hole=	100.021
#Range=	Auto
#Laser Pol.=	No
#Raman. Pol.=	No
#Laser Pol. (°)=	-0.0007625
#Raman Pol. (°)=	89.9995
#Collection=	Microscope
#StageXY=	Marzhauser
#StageZ=	Marzhauser
#X (µm)=	9000.9
#Y (µm)=	-3094.9
#Z (µm)=	-54.85
#Full time(mm:ss)=	3:18
#Project=
#Sample=
#Site=
#Title=	Thy_00_07_4_2x_45s_532 nm_x100_100%_600 gr_mm
#Remark=
#Date=	28.06.2022 10:11
#Acquired=	28.06.2022 10:11:40
#Base:Fit=	10.08.2022 10:07:56
#Base:Sub=	10.08.2022 10:08:40
#Filter:Polynom=	16.08.2022 10:26:06
#AxisType[0]=Intens
#AxisUnit[0]=Cnt
#AxisType[1]=Spectr
#AxisUnit[1]=1/cm
200.407	-0.577128
204.035	0.473632
207.665	1.89743
211.291	1.7111
214.916	1.71687
218.541	2.88469
222.163	2.36135
225.785	2.66164
229.404	3.70834
233.022	4.82068
236.638	6.67264
240.255	8.32192
243.868	9.01696
247.48	9.93657
251.091	10.1279
254.702	9.78237
258.31	9.05532
261.916	9.21567
265.521	8.31809
269.125	8.28029
272.727	7.90486
276.328	8.09456
279.927	7.75557
283.525	9.22415
287.121	9.9868
290.716	11.5955
294.31	11.8904
297.9	12.0472
301.491	13.5027
305.081	16.684
308.669	17.4379
312.256	19.4547
315.839	21.8571
319.423	23.076
323.006	26.6335
326.585	27.4748
330.165	26.8454
333.741	25.064
337.318	23.6394
340.894	23.268
344.466	19.9599
348.039	20.4191
351.608	18.659
355.176	19.2327
358.745	21.4706
362.31	25.4743
365.876	27.091
369.439	27.6261
373	28.2967
376.56	29.3122
380.12	29.7681
383.677	28.8083
387.233	30.1556
390.787	30.3317
394.34	27.8214
397.894	26.9345
401.444	26.0656
404.993	24.8622
408.54	22.8727
412.086	21.9678
415.631	19.4082
419.174	16.9084
422.716	15.2128
426.257	12.9453
429.794	10.5289
433.332	7.37631
436.868	6.17766
440.403	7.13017
443.937	8.53318
447.468	11.134
450.999	13.8859
454.528	12.7344
458.057	12.5411
461.582	12.7585
465.107	12.9405
468.629	14.4497
472.152	16.1652
475.672	18.8414
479.192	19.4865
482.709	22.5288
486.226	25.7304
489.74	28.2618
493.255	32.3809
496.767	35.2178
500.277	36.7294
503.788	38.2084
507.295	39.8577
510.801	39.4176
514.308	38.0146
517.811	35.0344
521.313	33.1358
524.814	33.6873
528.313	33.6453
531.811	32.5107
535.308	30.49
538.803	27.4355
542.297	24.6811
545.789	21.037
549.281	17.3386
552.771	16.3075
556.259	14.7819
559.747	14.1399
563.233	14.0015
566.717	12.9949
570.2	11.8344
573.68	11.0353
577.161	10.7628
580.64	9.71153
584.118	10.5722
587.593	10.5505
591.068	10.4474
594.54	9.37409
598.013	8.15657
601.484	6.40467
604.952	5.57475
608.421	6.29746
611.886	6.28335
615.35	5.58715
618.815	5.24438
622.276	5.57601
625.738	5.68843
629.197	6.42783
632.655	7.67083
636.113	9.47011
639.568	9.68477
643.021	10.6024
646.473	12.1193
649.924	13.4169
653.376	13.3738
656.824	13.4176
660.271	14.36
663.716	15.2922
667.161	17.5772
670.604	17.9958
674.045	18.4966
677.486	18.1527
680.925	18.7924
684.361	19.6651
687.797	20.3297
691.232	21.8592
694.666	23.1933
698.099	24.3614
701.528	25.1839
704.958	25.9242
708.387	26.9492
711.814	29.0729
715.238	31.2428
718.663	32.1451
722.084	33.8254
725.506	34.8054
728.925	36.9052
732.345	39.5921
735.761	42.3158
739.178	46.6831
742.592	51.6643
746.006	57.8567
749.417	65.681
752.827	72.1741
756.236	78.2827
759.645	81.0669
763.051	84.6473
766.456	87.7913
769.859	89.6497
773.261	90.6106
776.664	90.2812
780.064	89.7507
783.462	87.3623
786.859	86.6601
790.255	85.817
793.649	84.319
797.042	81.3125
800.434	77.6928
803.823	74.8079
807.212	70.4556
810.6	66.4424
813.987	64.4405
817.372	64.3016
820.754	64.4528
824.137	65.6888
827.519	68.2865
830.897	68.716
834.276	68.4954
837.654	66.3622
841.029	61.7598
844.404	58.2266
847.776	54.8684
851.149	51.5285
854.519	46.5547
857.889	43.4451
861.256	40.4104
864.622	37.9095
867.988	36.72
871.351	34.2005
874.713	32.5273
878.074	29.4267
881.435	28.0868
884.794	27.2297
888.15	25.3748
891.506	25.0573
894.861	25.5242
898.214	26.6652
901.566	28.7868
904.916	30.0785
908.266	32.0371
911.614	34.1707
914.961	34.925
918.306	35.1956
921.651	33.4612
924.994	32.854
928.336	33.5696
931.674	34.0466
935.014	33.1853
938.352	33.0043
941.687	34.7323
945.022	33.4392
948.357	33.1763
951.688	32.7101
955.02	32.3322
958.348	30.5623
961.678	29.2624
965.004	27.9652
968.331	28.0965
971.655	27.6973
974.979	28.0983
978.3	28.3592
981.62	28.4571
984.941	28.3593
988.259	26.566
991.575	25.411
994.89	25.8435
998.204	26.8867
1001.52	28.8709
1004.83	31.49
1008.14	33.298
1011.45	37.3936
1014.76	38.8426
1018.06	40.2183
1021.37	42.4587
1024.67	42.1542
1027.97	42.4481
1031.27	42.3394
1034.57	40.0003
1037.87	36.1763
1041.17	32.922
1044.47	30.7638
1047.76	28.9273
1051.06	27.5943
1054.35	27.1515
1057.64	25.4966
1060.93	25.7223
1064.22	22.3166
1067.5	21.0506
1070.79	19.5888
1074.08	22.409
1077.36	26.7864
1080.64	28.0663
1083.92	27.7289
1087.2	28.2681
1090.48	28.889
1093.76	30.4041
1097.03	29.8918
1100.31	29.5887
1103.58	29.4759
1106.85	28.2973
1110.12	26.9409
1113.39	22.9379
1116.66	19.1443
1119.93	16.9266
1123.19	14.6568
1126.46	12.2249
1129.72	11.7523
1132.98	10.944
1136.24	11.8519
1139.5	11.804
1142.76	11.4975
1146.01	12.003
1149.27	12.6086
1152.53	13.2619
1155.78	13.159
1159.03	12.1154
1162.28	8.93372
1165.53	6.96374
1168.78	7.06229
1172.02	7.03061
1175.27	8.69826
1178.51	10.5794
1181.76	10.8809
1185	10.6971
1188.24	9.89007
1191.48	9.68972
1194.71	10.7084
1197.95	13.7411
1201.19	14.8969
1204.42	15.7212
1207.65	17.2171
1210.88	18.6111
1214.12	21.7568
1217.35	24.9286
1220.57	27.3803
1223.8	30.5538
1227.03	31.705
1230.25	33.7004
1233.47	33.8829
1236.69	34.758
1239.92	34.851
1243.13	32.2187
1246.35	32.564
1249.57	33.7606
1252.78	33.5549
1256	33.1076
1259.21	31.6133
1262.42	27.9485
1265.63	28.3895
1268.84	28.574
1272.05	28.0528
1275.26	28.2432
1278.46	31.0377
1281.67	32.877
1284.87	35.8084
1288.07	38.2932
1291.27	41.5532
1294.47	46.0473
1297.67	49.8293
1300.87	52.9372
1304.06	54.6446
1307.26	58.2084
1310.45	61.2271
1313.64	64.007
1316.83	66.3444
1320.02	67.7356
1323.21	68.7296
1326.4	69.6824
1329.59	69.1157
1332.77	68.0881
1335.95	65.776
1339.14	65.0181
1342.32	63.001
1345.5	62.342
1348.67	61.8143
1351.85	60.602
1355.03	59.65
1358.2	59.5087
1361.38	56.5581
1364.55	55.6753
1367.72	53.1435
1370.89	53.758
1374.06	52.81
1377.23	51.6442
1380.39	48.262
1383.56	47.8133
1386.72	47.0981
1389.89	44.4697
1393.05	42.8258
1396.21	42.1364
1399.37	39.3445
1402.52	38.4863
1405.68	38.1231
1408.84	40.0447
1411.99	42.0712
1415.15	43.6886
1418.3	47.3487
1421.45	50.5132
1424.6	53.9904
1427.75	58.7678
1430.89	62.756
1434.04	68.623
1437.18	73.4799
1440.33	77.7194
1443.47	80.2995
1446.61	83.6428
1449.75	86.0786
1452.89	80.4017
1456.03	78.6968
1459.16	78.8406
1462.3	77.3658
1465.43	76.0308
1468.56	72.8314
1471.7	69.2293
1474.83	64.8124
1477.96	60.5223
1481.08	57.8863
1484.21	52.8106
1487.34	47.8295
1490.46	43.7619
1493.58	41.0911
1496.71	36.0721
1499.83	34.1361
1502.95	31.8949
1506.07	31.8539
1509.18	29.5654
1512.3	26.101
1515.41	21.6949
1518.53	20.8343
1521.64	19.2403
1524.75	17.3613
1527.86	15.4964
1530.97	14.566
1534.08	23.3228
1537.19	26.0003
1540.29	28.2753
1543.4	31.6537
1546.5	33.7285
1549.6	35.3369
1552.7	39.9803
1555.8	44.0773
1558.9	46.8629
1562	49.3445
1565.09	52.0778
1568.19	55.5942
1571.28	58.8692
1574.37	61.724
1577.47	65.9115
1580.56	66.4417
1583.64	67.9019
1586.73	67.9705
1589.82	68.0471
1592.9	68.9599
1595.99	69.575
1599.07	67.9955
1602.15	65.8602
1605.23	64.5322
1608.31	64.5742
1611.39	64.6456
1614.47	63.7055
1617.55	62.1119
1620.62	61.2096
1623.7	59.9393
1626.77	59.7769
1629.84	60.3364
1632.91	59.2761
1635.98	58.0019
1639.05	59.5139
1642.11	59.1916
1645.18	60.1576
1648.24	61.1601
1651.31	62.3884
1654.37	62.6511
1657.43	62.5417
1660.49	62.3488
1663.55	59.7856
1666.61	58.0449
1669.66	54.8891
1672.72	50.2342
1675.77	45.293
1678.83	41.8495
1681.88	38.3773
1684.93	35.5769
1687.98	29.8957
1691.03	25.4849
1694.07	21.3448
1697.12	16.9262
1700.17	12.7374
1703.21	9.91293
1706.25	7.66435
1709.29	5.28294
1712.33	3.06674
1715.37	2.50165
1718.41	0.780056
1721.45	0.711349
1724.49	2.27754
1727.52	3.14794
1730.55	3.14937
1733.59	4.17401
1736.62	5.15728
1739.65	5.21459
1742.68	3.8748
1745.7	2.58556
1748.73	1.42991
1751.76	1.78534
1754.78	2.98639
1757.8	2.36547
1760.83	3.0494
1763.85	3.71208
1766.87	3.84076
1769.89	2.90931
1772.9	2.59774
1775.92	2.93282
1778.94	3.76063
1781.95	3.49534
1784.96	2.61017
1787.97	2.38607
1790.99	2.70605
1794	2.65018
1797	3.86625
1800.01	4.33546
1803.02	5.20823
1806.02	5.66239
1809.03	6.3671
1812.03	5.43119
1815.03	3.65656
1818.03	3.59515
1821.03	3.68582
1824.03	4.25123
1827.03	4.16252
1830.02	4.65601
1833.02	4.70829
1836.01	4.3645
1839.01	4.28627
1842	4.23028
1844.99	5.30979
1847.98	6.44314
1850.97	7.10683
1853.95	6.25923
1856.94	5.86625
1859.93	5.8581
1862.91	5.3855
1865.89	5.14231
1868.87	6.53812
1871.85	5.59067
1874.83	6.21918
1877.81	5.43996
1880.79	4.73061
1882.52	4.18143
1885.51	3.87779
1888.5	4.76995
1891.49	5.48248
1894.47	5.57346
1897.46	5.40435
1900.44	5.76731
1903.42	6.8502
1906.4	8.24797
1909.38	8.75491
1912.36	10.0179
1915.34	12.7073
1918.32	13.2484
1921.29	12.7983
1924.27	12.5943
1927.24	12.0229
1930.21	11.8121
1933.18	11.391
1936.15	11.5603
1939.12	11.3508
1942.09	11.2695
1945.06	10.5585
1948.02	9.74356
1950.99	10.5196
1953.95	11.4269
1956.91	12.0037
1959.88	12.0437
1962.84	12.2292
1965.8	13.1559
1968.75	12.4068
1971.71	12.4075
1974.67	12.1497
1977.62	11.1944
1980.58	10.1886
1983.53	9.61301
1986.48	8.28818
1989.43	8.2327
1992.38	6.49049
1995.33	5.54963
1998.27	4.76992
2001.22	4.82613
2004.16	3.88779
2007.11	2.97479
2010.05	2.21525
2012.99	2.54686
2015.93	4.22266
2018.87	4.68243
2021.81	6.47989
2024.75	7.17752
2027.69	6.74214
2030.62	7.15349
2033.56	8.68463
2036.49	9.37657
2039.42	11.9172
2042.35	11.9872
2045.28	12.2839
2048.21	12.882
2051.14	13.1424
2054.07	15.4425
2056.99	16.105
2059.92	17.0682
2062.84	16.289
2065.76	16.7612
2068.68	16.3327
2071.6	15.7636
2074.52	14.0323
2077.44	13.0056
2080.36	12.1273
2083.27	11.0067
2086.19	11.3514
2089.1	9.96246
2092.02	8.72912
2094.93	7.37475
2097.84	6.68784
2100.75	5.98585
2103.66	6.32358
2106.56	7.6507
2109.47	8.28917
2112.38	8.67951
2115.28	10.1173
2118.18	10.645
2121.09	12.0544
2123.99	12.5979
2126.89	13.4007
2129.79	13.0578
2132.68	12.5444
2135.58	12.1015
2138.48	12.125
2141.37	11.308
2144.27	11.0977
2147.16	10.6563
2150.05	10.5942
2152.94	11.0845
2155.83	10.8609
2158.72	10.3145
2161.6	8.93582
2164.49	7.95824
2167.38	7.32547
2170.26	7.65649
2173.14	7.94565
2176.03	8.96176
2178.91	9.05466
2181.79	9.32686
2184.67	9.85027
2187.54	11.2499
2190.42	12.4997
2193.3	12.2498
2196.17	12.4993
2199.05	12.9794
2201.92	13.5613
2204.79	14.8738
2207.66	15.2567
2210.53	16.2914
2213.4	17.4771
2216.27	17.8895
2219.13	18.1502
2222	18.567
2224.86	18.4483
2227.72	17.186
2230.59	16.3549
2233.45	15.5475
2236.31	15.4453
2239.17	15.7808
2242.03	16.533
2244.88	16.6
2247.74	16.4449
2250.59	17.5557
2253.45	16.8835
2256.3	18.1932
2259.15	18.4763
2262	17.8344
2264.85	18.4222
2267.7	18.8769
2270.55	18.4386
2273.4	19.4635
2276.24	18.5073
2279.09	18.1993
2281.93	18.1765
2284.77	16.4603
2287.62	17.0989
2290.46	15.4387
2293.3	14.4351
2296.13	14.3812
2298.97	14.4365
2301.81	13.9876
2304.64	13.0438
2307.48	13.7449
2310.31	13.3925
2313.14	12.8045
2315.98	12.2117
2318.81	13.0858
2321.64	12.8142
2324.46	11.7819
2327.29	11.2348
2330.12	10.5953
2332.94	11.2544
2335.77	10.9393
2338.59	9.87696
2341.41	9.57764
2344.23	9.39985
2347.05	8.24053
2349.87	7.67412
2352.69	6.78084
2355.51	4.78683
2358.32	4.45432
2361.14	3.49358
2363.95	1.98252
2366.76	2.23635
2369.58	1.38974
2372.39	1.17638
2375.2	0.722402
2378	0.752794
2380.81	0.802244
2383.62	1.03903
2386.43	0.923224
2389.23	0.166829
2392.03	0.427861
2394.84	0.820043
2397.64	2.67168
2400.44	4.72134
2403.24	5.60696
2406.04	5.29078
2408.84	6.88135
2411.63	7.76042
2414.43	8.35735
2417.22	8.3131
2420.02	9.13714
2422.81	8.8755
2425.6	8.96682
2428.39	8.69017
2431.18	8.2555
2433.97	7.74159
2436.76	8.0386
2439.54	8.05221
2442.33	8.44817
2445.12	8.42925
2447.9	8.49707
2450.68	7.89297
2453.46	6.75028
2456.24	6.82637
2459.02	7.30549
2461.8	8.30392
2464.58	8.56607
2467.36	9.02068
2470.13	7.21519
2472.91	6.01724
2475.68	5.88368
2478.45	5.49406
2481.23	4.81358
2484	4.82128
2486.77	4.31355
2489.54	4.09418
2492.3	3.22061
2495.07	3.00442
2497.84	1.51889
2500.6	1.75782
2503.36	1.45692
2506.13	2.13659
2508.89	2.42642
2511.65	2.69305
2514.41	2.64429
2517.17	2.52268
2519.93	2.1853
2522.68	2.06339
2525.44	2.64871
2528.19	2.63082
2530.95	2.15933
2533.7	2.24958
2536.45	2.73128
2539.2	2.34571
2541.95	1.65072
2544.7	2.7934
2547.45	4.67567
2550.2	4.87802
2552.94	4.20127
2555.69	3.9735
2558.43	4.49391
2561.18	4.79987
2563.92	5.17954
2566.66	6.09968
2569.4	6.85188
2572.14	6.46909
2574.88	5.81344
2577.61	6.46993
2580.35	5.64829
2583.09	4.62606
2585.82	3.36741
2588.55	2.32146
2591.29	2.09386
2594.02	2.15922
2596.75	1.97707
2599.48	1.56028
2602.21	1.49791
2604.93	1.72088
2607.66	1.39009
2610.39	2.18508
2613.11	2.16759
2615.83	1.98399
2618.56	1.47384
2621.28	1.66714
2624	2.13591
2626.72	2.81172
2629.44	1.95343
2632.15	2.58107
2634.87	2.78703
2637.59	2.42891
2640.3	2.20871
2643.02	3.00122
2645.73	3.02545
2648.44	2.92299
2651.15	3.25894
2653.86	2.47425
2656.57	3.31718
2659.28	4.20486
2661.99	5.36437
2664.69	5.79577
2667.4	6.94397
2670.1	6.79596
2672.81	7.85368
2675.51	8.02729
2678.21	7.17871
2680.91	8.14889
2683.61	7.83375
2686.31	7.90549
2689	8.15266
2691.7	7.6545
2694.4	8.4072
2697.09	7.99451
2699.79	9.77381
2702.48	10.0046
2705.17	11.4255
2707.86	12.5077
2710.55	11.8816
2713.24	10.9773
2715.93	11.6869
2718.62	10.8871
2721.3	10.1999
2723.99	10.5705
2726.67	10.7197
2729.35	9.37684
2732.04	9.4627
2734.72	8.30008
2737.4	8.05602
2740.08	7.87608
2742.76	6.68725
2745.43	6.42419
2748.11	5.45404
2750.79	3.96547
2753.46	4.59305
2756.14	3.79196
2758.81	3.51167
2761.48	3.89113
2764.15	3.76901
2766.82	3.61913
2769.49	3.29488
2772.16	2.86848
2774.82	2.02918
2777.49	0.911313
2780.16	0.839869
2782.82	1.9983
2785.48	2.42092
2788.15	2.6931
2790.81	2.64517
2793.47	4.24329
2796.13	5.83798
2798.79	6.8558
2801.44	7.62549
2804.1	8.67245
2806.76	9.63051
2809.41	8.94121
2812.07	10.1576
2814.72	9.84058
2817.37	10.9603
2820.02	13.0831
2822.67	14.6603
2825.32	16.0138
2827.97	17.5738
2830.62	19.557
2833.26	23.1316
2835.91	26.3875
2838.56	29.5925
2841.2	34.486
2843.84	40.3802
2846.48	45.5079
2849.12	52.1506
2851.77	58.7173
2854.4	65.4191
2857.04	73.0349
2859.68	80.333
2862.32	87.2942
2864.95	92.1828
2867.59	98.128
2870.22	103.624
2872.85	108.825
2875.48	114.322
2878.11	118.594
2880.74	122.531
2883.37	126.712
2886	129.56
2888.63	133.22
2891.25	136.631
2893.88	140.104
2896.5	143.668
2899.13	148.346
2901.75	152.765
2904.37	158.076
2906.99	166.1
2909.61	173.083
2912.23	182.253
2914.85	189.104
2917.46	197.41
2920.08	204.437
2922.7	210.71
2925.31	214.301
2927.92	216.287
2930.54	217.268
2933.15	217.924
2935.76	216.471
2938.37	212.486
2940.98	207.031
2943.58	200.963
2946.19	193.849
2948.8	187.211
2951.4	179.111
2954.01	171.097
2956.61	162.37
2959.21	154.244
2961.81	147.077
2964.41	138.906
2967.01	133.217
2969.61	127.151
2972.21	122.566
2974.81	117.1
2977.4	111.059
2980	105.344
2982.59	99.4624
2985.18	93.1315
2987.78	86.1886
2990.37	78.4981
2992.96	71.96
2995.55	65.6216
2998.14	58.8484
3000.73	52.1446
3003.31	45.8447
3005.9	40.758
3008.48	36.5135
3011.07	32.0807
3013.65	27.3707
3016.23	24.023
3018.81	20.6975
3021.4	18.1745
3023.97	15.6811
3026.55	13.6227
3029.13	12.3429
3031.71	12.0804
3034.28	11.4374
3036.86	12.0086
3039.43	11.9386
3042.01	11.8953
3044.58	12.4412
3047.15	13.8865
3049.72	14.5016
3052.29	14.9974
3054.86	14.7603
3057.43	14.57
3060	14.9029
3062.56	13.9111
3065.13	13.2163
3067.69	12.3702
3070.26	11.1454
3072.82	10.0143
3075.38	7.61932
3077.94	6.15377
3080.5	5.74095
3083.06	4.61351
3085.62	2.84823
3088.18	1.85922
3090.73	1.3382
3093.29	0.798777
3095.84	1.01616
3098.4	1.99847
3100.95	2.61714
3103.5	3.03613
3106.05	3.82485
3108.6	5.28157
3111.15	6.51555
3113.7	6.94597
3116.25	6.64948
3118.79	6.30749
3121.34	7.02673
3123.88	7.6439
3126.43	7.40362
3128.97	7.12209
3131.51	7.53072
3134.06	7.75727
3136.6	7.55174
3139.14	8.15785
3141.67	9.18804
3144.21	9.38844
3146.75	10.2953
3149.29	11.9677