File: data/Raman/poly_smoothed/Thy_30_10_27_1x_45s_532 nm_x100_100%_600 gr_mm_01.txt
#Acq. time (s)=	45
#Accumulations=	2
#Range (cm-¹)=	200...3150
#Windows=	2
#Auto scanning=	Off
#Autofocus=	Off
#Macrospot=	Off
#AutoExposure=	Off
#Spike filter=	Multiple accum.
#Delay time (s)=	0
#Binning=	1
#Readout mode=	Signal
#DeNoise=	Off
#ICS correction=	On
#Dark correction=	Off
#Inst. Process=	Off
#Detector Gain=	Best Dynamic Range
#Detector ADC=	20 kHz
#Detector temperature (°C)=	-69.85
#Instrument=	LabRAM HR Evol
#Detector=	Synapse
#Objective=	x100
#Grating=	600 gr/mm
#ND Filter=	100%
#Laser (nm)=	532
#Hole=	100.021
#Range=	Auto
#Laser Pol.=	No
#Raman. Pol.=	No
#Laser Pol. (°)=	-0.0007625
#Raman Pol. (°)=	89.9995
#Collection=	Microscope
#StageXY=	Marzhauser
#StageZ=	Marzhauser
#X (µm)=	4769
#Y (µm)=	-7711.4
#Z (µm)=	584.45
#Full time(mm:ss)=	3:18
#Project=
#Sample=
#Site=
#Title=	Thy_30_10_27_2x_45s_532 nm_x100_100%_600 gr_mm
#Remark=
#Date=	30.06.2022 13:25
#Acquired=	30.06.2022 13:25:17
#Base:Fit=	10.08.2022 09:58:11
#Base:Sub=	10.08.2022 09:58:44
#Filter:Polynom=	16.08.2022 10:22:53
#AxisType[0]=Intens
#AxisUnit[0]=Cnt
#AxisType[1]=Spectr
#AxisUnit[1]=1/cm
200.533	-4.16022
204.162	7.13841
207.792	10.9175
211.418	13.5102
215.044	15.9464
218.667	17.1248
222.289	14.5066
225.912	14.8302
229.531	15.4008
233.148	16.2543
236.766	15.4978
240.381	13.9611
243.994	14.6486
247.606	14.4962
251.217	13.6229
254.828	12.6455
258.436	11.4811
262.042	11.0565
265.647	10.1889
269.25	10.6565
272.852	9.43624
276.453	10.3321
280.052	10.8061
283.65	12.2305
287.247	12.2906
290.842	12.7364
294.436	12.8758
298.028	15.2214
301.617	15.4686
305.206	16.2394
308.794	16.0751
312.381	18.7966
315.964	21.9793
319.548	21.9094
323.131	21.299
326.71	20.5889
330.29	20.8005
333.868	20.4408
337.443	18.8085
341.018	16.2155
344.591	13.9538
348.163	12.549
351.733	10.6003
355.303	10.7522
358.869	11.3291
362.435	9.37051
366.001	8.94929
369.563	9.50208
373.124	10.493
376.686	11.4261
380.244	12.7606
383.801	14.2094
387.357	14.9371
390.911	16.5167
394.466	17.7293
398.018	17.8812
401.568	17.9629
405.117	15.5054
408.664	13.4222
412.21	11.0896
415.755	10.38
419.298	9.09927
422.84	7.14968
426.38	5.58709
429.919	3.94459
433.455	5.64228
436.992	5.65768
440.527	5.6252
444.06	5.99999
447.593	4.44088
451.122	5.1465
454.651	6.25421
458.18	7.58648
461.705	10.377
465.23	12.327
468.752	12.715
472.275	14.2249
475.797	14.5837
479.315	15.7429
482.834	15.6019
486.349	16.0552
489.863	18.0314
493.378	20.385
496.889	20.4522
500.401	22.5414
503.91	25.7577
507.417	27.2077
510.923	29.0551
514.43	30.3853
517.933	30.8043
521.435	31.5332
524.936	31.7803
528.435	29.759
531.933	27.0163
535.43	24.1661
538.927	21.8041
542.421	20.842
545.913	20.8864
549.403	18.5154
552.893	17.2989
556.381	15.2659
559.868	13.2887
563.354	13.3908
566.839	12.2696
570.322	11.4309
573.802	10.6409
577.283	9.16658
580.762	7.36191
584.24	7.62593
587.714	6.68091
591.19	7.60975
594.663	6.73696
598.134	6.54959
601.605	5.55159
605.073	6.58442
608.542	7.74426
612.007	8.63786
615.473	6.78624
618.936	6.83523
622.397	7.38042
625.859	8.192
629.318	9.32014
632.775	11.8371
636.233	11.8289
639.688	13.6065
643.142	11.9899
646.594	12.4235
650.045	15.1015
653.496	15.3755
656.944	16.1664
660.391	16.8463
663.837	13.1632
667.281	13.8316
670.724	13.358
674.166	15.807
677.606	15.0489
681.045	15.5165
684.483	17.7019
687.917	19.5737
691.352	21.4969
694.786	22.4263
698.219	22.0626
701.65	22.9495
705.078	23.7287
708.506	23.6974
711.934	26.6971
715.358	29.5802
718.782	34.124
722.204	33.3843
725.626	36.9571
729.045	39.2512
732.464	43.0547
735.881	47.4251
739.297	49.6033
742.711	52.6724
746.125	55.0892
749.537	59.7584
752.946	66.263
756.357	70.9326
759.764	75.6545
763.17	79.0987
766.575	81.7285
769.978	84.6889
773.382	84.0917
776.783	86.6194
780.182	86.7498
783.581	86.3661
786.978	86.5419
790.373	87.5928
793.768	90.0936
797.161	91.279
800.552	90.8797
803.941	89.7073
807.33	85.5235
810.718	84.8869
814.105	83.4826
817.49	83.1266
820.873	83.0147
824.256	82.6791
827.637	83.3961
831.016	82.5241
834.395	82.5527
837.772	81.234
841.147	81.0119
844.522	77.7136
847.894	73.7642
851.267	70.6151
854.637	66.9801
858.007	63.986
861.374	62.1394
864.739	60.1143
868.106	57.7222
871.469	56.5669
874.831	55.6946
878.193	55.4591
881.553	53.8025
884.911	51.1212
888.268	49.1097
891.623	47.7411
894.978	48.0877
898.331	47.0758
901.683	46.7942
905.033	45.1093
908.383	46.6884
911.731	45.373
915.078	46.9138
918.423	47.1906
921.768	46.2826
925.111	43.3985
928.452	42.5704
931.791	40.1794
935.13	38.6131
938.468	37.5403
941.803	35.2964
945.139	32.6944
948.473	32.3662
951.804	32.9145
955.136	36.8664
958.465	36.7386
961.794	38.6124
965.12	37.8359
968.447	39.8449
971.771	42.201
975.095	44.5571
978.417	46.68
981.737	47.9857
985.057	49.7601
988.375	51.342
991.691	52.3288
995.006	51.8963
998.32	53.0175
1001.63	52.8762
1004.95	52.0727
1008.26	53.631
1011.56	53.7416
1014.87	54.3622
1018.18	54.6461
1021.48	53.4433
1024.79	55.7487
1028.09	56.4656
1031.39	59.0897
1034.69	59.5034
1037.99	58.2604
1041.29	55.5001
1044.58	53.5988
1047.88	49.5175
1051.17	46.4523
1054.46	41.4219
1057.75	39.7492
1061.04	34.6169
1064.33	30.5854
1067.62	26.2715
1070.9	24.4715
1074.19	22.0533
1077.47	20.8135
1080.76	20.5201
1084.04	19.4314
1087.32	20.3941
1090.59	19.8252
1093.87	20.0897
1097.15	21.6112
1100.42	21.8853
1103.69	23.8577
1106.97	24.8081
1110.24	24.2311
1113.51	23.7937
1116.77	23.2621
1120.04	22.5815
1123.31	19.5202
1126.57	17.0306
1129.83	15.5674
1133.1	13.1102
1136.36	12.5977
1139.62	11.8176
1142.87	10.7817
1146.13	9.9403
1149.38	9.26913
1152.64	7.97235
1155.89	6.30274
1159.14	5.14742
1162.39	4.52155
1165.64	1.98676
1168.89	0.776487
1172.14	0.821766
1175.38	-0.558409
1178.63	0.742895
1181.87	0.889638
1185.11	0.41624
1188.35	0.531359
1191.59	1.82292
1194.83	4.36064
1198.07	6.46298
1201.3	9.19835
1204.53	11.1448
1207.77	14.845
1211	17.8726
1214.23	23.4835
1217.46	30.4925
1220.69	34.8545
1223.91	39.357
1227.14	44.108
1230.36	49.9551
1233.59	53.9249
1236.81	57.5384
1240.03	61.8494
1243.25	63.452
1246.46	66.2964
1249.68	69.602
1252.9	71.8109
1256.11	74.2689
1259.32	77.4522
1262.54	80.9921
1265.75	83.6949
1268.96	85.9664
1272.16	86.0638
1275.37	86.98
1278.57	90.353
1281.78	91.3138
1284.98	92.9381
1288.18	95.3391
1291.38	99.6185
1294.58	101.337
1297.78	100.85
1300.98	100.666
1304.17	101.938
1307.37	102.807
1310.56	103.609
1313.76	104.296
1316.95	104.374
1320.14	103.502
1323.32	102.295
1326.51	104.538
1329.7	104.225
1332.88	103.557
1336.07	105.047
1339.25	103.932
1342.43	100.277
1345.61	98.2961
1348.79	93.2797
1351.96	89.546
1355.14	85.0729
1358.31	82.6924
1361.49	78.8456
1364.66	75.8071
1367.83	72.3998
1371	67.899
1374.17	64.6261
1377.34	62.7635
1380.5	62.1315
1383.67	60.1829
1386.83	58.5607
1390	58.1236
1393.16	55.4858
1396.32	52.8057
1399.48	51.1702
1402.64	52.0943
1405.79	53.3972
1408.95	54.805
1412.1	59.1827
1415.26	61.0482
1418.41	65.3904
1421.56	69.6196
1424.71	76.6223
1427.86	83.4274
1431	90.5813
1434.15	98.5903
1437.29	105.721
1440.44	111.487
1443.58	116.411
1446.72	118.854
1449.86	119.487
1453	118.602
1456.14	116.522
1459.27	111.58
1462.41	104
1465.54	95.2217
1468.67	84.9492
1471.81	75.5629
1474.94	65.206
1478.07	54.6406
1481.19	46.3311
1484.32	38.4083
1487.45	31.1915
1490.57	24.0934
1493.69	19.0826
1496.82	16.1504
1499.94	13.7954
1503.06	13.2494
1506.17	12.9217
1509.29	14.9297
1512.41	16.0905
1515.52	19.0085
1518.64	21.373
1521.75	22.9746
1524.86	24.4495
1527.97	28.5108
1531.08	31.3418
1534.19	35.9969
1537.29	40.2295
1540.4	43.2883
1543.5	47.9689
1546.61	52.6535
1549.71	60.2438
1552.81	66.3538
1555.91	73.6008
1559.01	80.4522
1562.11	86.8613
1565.2	91.3475
1568.29	97.7212
1571.39	101.165
1574.48	104.456
1577.57	107.869
1580.66	112.18
1583.75	115.475
1586.84	116.26
1589.93	117.06
1593.01	118.786
1596.1	114.523
1599.18	112.657
1602.26	109.359
1605.34	105.791
1608.42	103.136
1611.5	99.7001
1614.58	96.7099
1617.65	94.218
1620.73	93.7934
1623.8	93.3881
1626.87	95.2365
1629.95	96.1297
1633.02	98.7717
1636.09	101.344
1639.15	106.235
1642.22	110.363
1645.29	115.208
1648.35	117.084
1651.42	120.526
1654.48	124.6
1657.54	126.59
1660.6	125.763
1663.66	125.476
1666.72	122.552
1669.77	118.796
1672.83	112.018
1675.88	104.768
1678.93	98.1392
1681.99	89.6024
1685.04	82.3649
1688.09	73.1136
1691.13	63.7272
1694.18	55.5468
1697.23	46.2329
1700.27	39.8737
1703.32	33.9064
1706.36	28.5081
1709.4	24.883
1712.44	21.3464
1715.48	19.242
1718.52	16.9657
1721.56	14.1985
1724.59	12.5249
1727.63	10.9754
1730.66	8.39317
1733.69	7.65273
1736.72	6.93201
1739.75	6.15224
1742.78	5.05472
1745.81	4.824
1748.84	4.02714
1751.86	4.02402
1754.89	3.05495
1757.91	2.44773
1760.93	0.784323
1763.95	-0.394598
1766.97	-1.69989
1769.99	-2.54543
1773.01	-0.975917
1776.03	-0.0486356
1779.04	-0.401533
1782.06	0.513416
1785.07	1.09411
1788.08	2.16832
1791.09	2.59121
1794.1	2.38479
1797.11	2.50895
1800.12	1.64071
1803.12	2.7877
1806.13	3.51553
1809.13	4.86302
1812.14	5.26967
1815.14	6.21644
1818.14	7.09012
1821.14	7.79002
1824.14	7.651
1827.13	8.08182
1830.13	7.87087
1833.12	7.41202
1836.12	7.86027
1839.11	8.3845
1842.1	9.45132
1845.09	9.07595
1848.08	9.54095
1851.07	9.8659
1854.06	8.32082
1857.04	7.90216
1860.03	8.20648
1863.01	9.28323
1866	8.81292
1868.98	8.79449
1871.96	9.0485
1874.94	9.93056
1877.92	10.9749
1880.89	11.0708
1882.48	10.4515
1885.47	11.8905
1888.46	12.664
1891.44	12.8586
1894.43	12.2587
1897.41	12.9013
1900.4	13.117
1903.38	13.7885
1906.36	14.8652
1909.34	14.1642
1912.32	13.1389
1915.29	11.5421
1918.27	10.5758
1921.25	10.9287
1924.22	9.90692
1927.2	9.28247
1930.17	9.14919
1933.14	10.0939
1936.11	9.68273
1939.08	10.3497
1942.05	11.6386
1945.01	12.7554
1947.98	12.6217
1950.94	13.5072
1953.91	13.956
1956.87	14.9967
1959.83	14.6042
1962.79	13.5857
1965.75	13.2944
1968.71	14.1786
1971.67	14.9812
1974.62	14.8684
1977.58	12.7303
1980.53	12.7285
1983.48	10.3103
1986.43	9.77296
1989.38	10.2556
1992.33	9.76223
1995.28	10.1003
1998.23	9.5592
2001.18	9.94581
2004.12	10.4298
2007.06	11.4027
2010.01	11.4484
2012.95	13.7317
2015.89	13.4867
2018.83	13.761
2021.77	15.6549
2024.71	17.0308
2027.64	18.0919
2030.58	19.5663
2033.51	19.0473
2036.45	20.148
2039.38	20.4419
2042.31	22.1665
2045.24	22.2028
2048.17	22.4661
2051.1	23.2591
2054.02	24.3134
2056.95	23.8483
2059.87	26.3708
2062.8	26.8326
2065.72	26.6472
2068.64	28.6682
2071.56	29.9102
2074.48	30.1236
2077.4	31.3349
2080.31	32.2641
2083.23	33.3768
2086.14	35.5003
2089.06	36.6956
2091.97	38.7301
2094.88	42.1741
2097.79	43.6351
2100.7	44.5105
2103.61	46.4817
2106.52	46.8337
2109.43	49.7257
2112.33	52.8878
2115.24	56.2736
2118.14	59.2056
2121.04	64.4074
2123.94	68.148
2126.84	71.3105
2129.74	78.7318
2132.64	83.5098
2135.54	87.9634
2138.43	93.8543
2141.33	101.022
2144.22	104.893
2147.11	109.194
2150.01	114.787
2152.9	117.936
2155.79	120.905
2158.67	123.971
2161.56	125.993
2164.45	129.006
2167.33	129.749
2170.22	129.116
2173.1	127.967
2175.98	126.061
2178.86	124.473
2181.74	123.515
2184.62	120.704
2187.5	118.015
2190.38	114.738
2193.25	109.28
2196.13	105.251
2199	100.552
2201.88	96.5058
2204.75	90.4904
2207.62	86.5414
2210.49	82.1509
2213.36	78.3079
2216.22	73.3731
2219.09	70.3108
2221.96	66.8249
2224.82	62.6028
2227.68	60.038
2230.55	57.6811
2233.41	55.6816
2236.27	53.4594
2239.12	51.166
2241.98	48.469
2244.84	46.7222
2247.7	45.3728
2250.55	45.3709
2253.41	43.9408
2256.26	42.8717
2259.11	41.1549
2261.96	39.0757
2264.81	38.6796
2267.66	37.4655
2270.51	36.4329
2273.35	36.1032
2276.2	36.4691
2279.04	36.2343
2281.89	34.4375
2284.73	34.7551
2287.57	35.0026
2290.41	33.8526
2293.25	32.6236
2296.09	31.519
2298.93	30.4528
2301.76	30.8477
2304.6	29.4019
2307.44	28.2739
2310.27	27.7402
2313.1	26.4817
2315.93	24.0548
2318.76	22.2135
2321.59	20.8383
2324.42	19.7161
2327.25	17.6304
2330.07	16.17
2332.9	15.8429
2335.72	14.801
2338.55	13.6883
2341.37	13.457
2344.19	12.5002
2347.01	11.9129
2349.83	9.70954
2352.65	9.445
2355.46	9.33617
2358.28	7.95329
2361.09	7.15436
2363.91	6.94097
2366.72	7.06045
2369.53	6.42052
2372.34	5.3013
2375.15	5.16291
2377.96	5.52488
2380.77	4.27481
2383.58	4.21262
2386.38	4.25816
2389.19	4.86072
2391.99	4.88346
2394.8	4.46399
2397.6	5.01252
2400.4	6.79264
2403.2	6.63801
2406	6.20665
2408.79	6.31851
2411.59	6.4971
2414.39	8.71107
2417.18	9.61265
2419.98	9.35029
2422.77	10.2903
2425.56	11.7006
2428.35	11.4357
2431.14	11.1281
2433.93	11.6032
2436.72	10.7557
2439.5	9.85079
2442.29	10.4895
2445.07	10.878
2447.86	10.9387
2450.64	10.6299
2453.42	9.38523
2456.2	8.81715
2458.98	8.2509
2461.76	7.14606
2464.54	6.25522
2467.32	5.03644
2470.09	3.54875
2472.87	2.73051
2475.64	2.76659
2478.41	2.05659
2481.18	2.42464
2483.95	2.06361
2486.72	0.264633
2489.49	-0.371639
2492.26	-0.655738
2495.03	-1.07865
2497.79	-2.06733
2500.56	-2.05292
2503.32	-3.33806
2506.09	-3.03662
2508.85	-2.59329
2511.61	-3.15941
2514.37	-3.06016
2517.13	-2.33687
2519.89	-3.18216
2522.64	-2.72027
2525.4	-1.28483
2528.15	-0.592359
2530.91	0.398279
2533.66	1.20558
2536.41	2.71392
2539.16	4.82651
2541.91	5.77523
2544.66	5.83384
2547.41	6.31476
2550.16	5.31056
2552.9	5.31004
2555.65	4.41043
2558.39	5.50521
2561.13	6.51041
2563.88	7.03248
2566.62	5.69977
2569.36	5.01456
2572.1	5.4188
2574.84	5.37183
2577.57	4.71805
2580.31	5.44661
2583.05	5.52155
2585.78	5.24564
2588.51	4.86243
2591.24	3.81007
2593.98	3.85844
2596.71	3.52815
2599.44	3.32552
2602.16	2.79347
2604.89	2.30165
2607.62	2.32615
2610.34	1.63171
2613.07	-0.113292
2615.79	0.632938
2618.52	0.630019
2621.24	1.2377
2623.96	2.50523
2626.68	3.87276
2629.4	5.43096
2632.11	5.13196
2634.83	5.36882
2637.55	6.91186
2640.26	8.27942
2642.98	8.1875
2645.69	8.3662
2648.4	8.18295
2651.11	7.3996
2653.82	6.19307
2656.53	6.10893
2659.24	5.63384
2661.95	5.71211
2664.65	5.06571
2667.36	4.4903
2670.06	3.8261
2672.76	3.77313
2675.47	4.32365
2678.17	3.67461
2680.87	5.56127
2683.57	7.03946
2686.27	8.11936
2688.97	9.79285
2691.66	12.5547
2694.36	15.3812
2697.05	16.1803
2699.75	17.0521
2702.44	18.2817
2705.13	18.591
2707.82	20.2869
2710.51	21.1696
2713.2	22.5322
2715.89	23.0326
2718.57	24.6496
2721.26	26.1745
2723.95	27.3922
2726.63	27.935
2729.31	29.1168
2732	29.448
2734.68	28.8356
2737.36	28.9985
2740.04	27.3417
2742.72	26.3265
2745.39	26.3546
2748.07	26.9166
2750.75	25.9626
2753.42	25.6468
2756.09	24.8927
2758.77	24.4129
2761.44	24.245
2764.11	21.8078
2766.78	21.3035
2769.45	20.5492
2772.12	21.4245
2774.78	21.7576
2777.45	21.8158
2780.12	21.344
2782.78	22.9549
2785.44	22.8194
2788.11	22.0064
2790.77	22.5748
2793.43	23.3947
2796.09	23.2808
2798.75	23.0562
2801.4	22.4242
2804.06	21.7278
2806.72	22.1309
2809.37	22.3963
2812.03	23.2338
2814.68	23.7517
2817.33	24.0392
2819.98	27.3127
2822.63	30.7666
2825.28	35.3215
2827.93	39.426
2830.58	46.8821
2833.23	52.1294
2835.87	60.0745
2838.52	69.4754
2841.16	78.3531
2843.8	89.2923
2846.44	100.964
2849.08	113.366
2851.73	126.92
2854.36	143.162
2857	158.089
2859.64	172.553
2862.28	185.616
2864.91	199.207
2867.55	210.348
2870.18	221.405
2872.81	230.244
2875.44	238.726
2878.07	246.593
2880.7	253.565
2883.33	261.419
2885.96	267.252
2888.59	273.446
2891.21	279.807
2893.84	287.023
2896.46	294.879
2899.09	305.265
2901.71	317.266
2904.33	330.957
2906.95	346.775
2909.57	364.678
2912.19	384.078
2914.81	403.407
2917.43	422.64
2920.04	438.483
2922.66	451.131
2925.27	461.941
2927.88	468.583
2930.5	472.255
2933.11	473.344
2935.72	471.073
2938.33	465.865
2940.94	457.622
2943.54	446.645
2946.15	433.114
2948.76	417.583
2951.36	401.535
2953.97	384.058
2956.57	368.377
2959.17	351.243
2961.77	336.553
2964.37	322.134
2966.97	308.288
2969.57	295.524
2972.17	282.701
2974.77	268.54
2977.36	254.817
2979.96	241.693
2982.55	226.831
2985.15	210.883
2987.74	196.262
2990.33	180.815
2992.92	165.69
2995.51	152.392
2998.1	139.23
3000.69	126.192
3003.27	114.725
3005.86	103.312
3008.44	93.1718
3011.03	85.3395
3013.61	77.6692
3016.19	71.5475
3018.78	66.934
3021.36	62.9652
3023.94	59.9856
3026.51	58.6734
3029.09	57.7036
3031.67	55.4872
3034.24	54.7327
3036.82	55.7336
3039.39	55.2167
3041.97	56.5983
3044.54	57.8481
3047.11	57.4451
3049.68	57.9777
3052.25	59.0954
3054.82	58.9573
3057.39	57.5365
3059.96	56.618
3062.52	55.7258
3065.09	53.644
3067.65	50.589
3070.22	46.98
3072.78	44.8424
3075.34	41.3289
3077.9	37.85
3080.46	34.6904
3083.02	32.0965
3085.58	28.9688
3088.14	25.733
3090.69	23.6896
3093.25	21.2845
3095.8	19.4583
3098.36	19.1781
3100.91	18.6931
3103.46	19.0899
3106.01	19.493
3108.56	19.0114
3111.11	19.6601
3113.66	20.7785
3116.21	20.4235
3118.76	19.6166
3121.3	18.7541
3123.85	18.3584
3126.39	16.2877
3128.93	14.8286
3131.48	13.8213
3134.02	13.4007
3136.56	10.5278
3139.1	7.62466
3141.64	4.89118
3144.17	1.45733
3146.71	-2.05811
3149.25	-4.84793