File: data/Raman/poly_smoothed/Thy_30_10_13_1x_45s_532 nm_x100_100%_600 gr_mm_01.txt
#Acq. time (s)=	45
#Accumulations=	2
#Range (cm-¹)=	200...3150
#Windows=	2
#Auto scanning=	Off
#Autofocus=	Off
#Macrospot=	Off
#AutoExposure=	Off
#Spike filter=	Multiple accum.
#Delay time (s)=	0
#Binning=	1
#Readout mode=	Signal
#DeNoise=	Off
#ICS correction=	On
#Dark correction=	Off
#Inst. Process=	Off
#Detector Gain=	Best Dynamic Range
#Detector ADC=	20 kHz
#Detector temperature (°C)=	-69.85
#Instrument=	LabRAM HR Evol
#Detector=	Synapse
#Objective=	x100
#Grating=	600 gr/mm
#ND Filter=	100%
#Laser (nm)=	532
#Hole=	100.021
#Range=	Auto
#Laser Pol.=	No
#Raman. Pol.=	No
#Laser Pol. (°)=	-0.0007625
#Raman Pol. (°)=	89.9995
#Collection=	Microscope
#StageXY=	Marzhauser
#StageZ=	Marzhauser
#X (µm)=	4750.3
#Y (µm)=	-7729.3
#Z (µm)=	584.45
#Full time(mm:ss)=	3:18
#Project=
#Sample=
#Site=
#Title=	Thy_30_10_13_2x_45s_532 nm_x100_100%_600 gr_mm
#Remark=
#Date=	30.06.2022 12:15
#Acquired=	30.06.2022 12:15:35
#Base:Fit=	10.08.2022 09:58:11
#Base:Sub=	10.08.2022 09:58:44
#Filter:Polynom=	16.08.2022 10:22:53
#AxisType[0]=Intens
#AxisUnit[0]=Cnt
#AxisType[1]=Spectr
#AxisUnit[1]=1/cm
200.533	1.29039
204.162	8.41828
207.792	13.1498
211.418	16.4929
215.044	18.704
218.667	20.1718
222.289	21.7713
225.912	23.6695
229.531	25.0848
233.148	26.4472
236.766	28.9938
240.381	30.6531
243.994	31.5104
247.606	29.8151
251.217	27.2205
254.828	26.7814
258.436	26.1063
262.042	26.9713
265.647	27.5154
269.25	28.5728
272.852	27.9701
276.453	27.8862
280.052	27.619
283.65	25.732
287.247	26.4333
290.842	26.2929
294.436	25.853
298.028	24.6231
301.617	24.5281
305.206	22.1325
308.794	22.5657
312.381	23.5784
315.964	22.4326
319.548	22.6559
323.131	24.0266
326.71	23.5095
330.29	22.4148
333.868	20.512
337.443	18.3342
341.018	17.2628
344.591	15.7139
348.163	15.8528
351.733	14.8447
355.303	14.5023
358.869	13.5146
362.435	13.262
366.001	12.7557
369.563	12.8463
373.124	13.1336
376.686	13.7186
380.244	14.0639
383.801	13.0382
387.357	12.0812
390.911	11.9767
394.466	12.0927
398.018	12.8882
401.568	12.6749
405.117	11.8229
408.664	11.7328
412.21	12.3689
415.755	13.0527
419.298	13.0647
422.84	11.7251
426.38	11.1156
429.919	9.7878
433.455	9.25041
436.992	8.63557
440.527	8.99318
444.06	8.50746
447.593	8.4957
451.122	9.22614
454.651	9.56361
458.18	10.2094
461.705	11.3055
465.23	11.6915
468.752	12.551
472.275	12.2062
475.797	12.8154
479.315	14.0712
482.834	14.6848
486.349	15.6515
489.863	15.2959
493.378	16.853
496.889	17.8503
500.401	18.7156
503.91	18.4416
507.417	18.2645
510.923	17.3811
514.43	16.4737
517.933	15.509
521.435	16.1296
524.936	16.4821
528.435	16.6208
531.933	14.8659
535.43	14.8733
538.927	13.3875
542.421	11.6481
545.913	9.7779
549.403	7.64718
552.893	7.24971
556.381	7.193
559.868	7.61213
563.354	7.02262
566.839	5.42612
570.322	5.29712
573.802	4.64004
577.283	5.85698
580.762	5.89618
584.24	6.25083
587.714	6.57217
591.19	6.96911
594.663	7.83721
598.134	8.57275
601.605	10.7283
605.073	11.4069
608.542	13.1639
612.007	14.478
615.473	15.8664
618.936	17.123
622.397	17.0531
625.859	17.1228
629.318	16.7801
632.775	16.5402
636.233	17.9507
639.688	20.8224
643.142	21.3328
646.594	22.3867
650.045	22.86
653.496	23.0214
656.944	24.7409
660.391	25.5877
663.837	26.2003
667.281	27.0596
670.724	25.6759
674.166	25.9263
677.606	27.0956
681.045	29.0338
684.483	30.6462
687.917	32.5926
691.352	33.7321
694.786	35.937
698.219	37.6524
701.65	39.1281
705.078	38.9961
708.506	38.5641
711.934	39.3745
715.358	39.1255
718.782	40.8296
722.204	42.6327
725.626	43.4397
729.045	42.9937
732.464	43.0977
735.881	43.5887
739.297	43.1155
742.711	44.2859
746.125	44.8848
749.537	44.7346
752.946	46.4486
756.357	49.1894
759.764	51.2384
763.17	55.5974
766.575	57.6759
769.978	59.8587
773.382	63.9626
776.783	68.3261
780.182	72.1649
783.581	74.21
786.978	77.4008
790.373	80.4488
793.768	83.1641
797.161	84.5466
800.552	86.3995
803.941	87.2139
807.33	87.5143
810.718	87.3537
814.105	87.4977
817.49	87.7624
820.873	85.5969
824.256	83.8469
827.637	82.1257
831.016	79.7917
834.395	78.8687
837.772	76.9688
841.147	75.0726
844.522	72.4144
847.894	70.9827
851.267	69.06
854.637	67.8962
858.007	67.6314
861.374	66.524
864.739	65.6487
868.106	64.9966
871.469	63.6296
874.831	62.2747
878.193	60.0355
881.553	58.803
884.911	57.602
888.268	55.4897
891.623	54.8664
894.978	54.2202
898.331	53.9702
901.683	52.6748
905.033	50.4846
908.383	48.6276
911.731	49.9304
915.078	49.8446
918.423	48.54
921.768	47.2604
925.111	46.2253
928.452	44.2685
931.791	44.7637
935.13	42.9252
938.468	42.2085
941.803	42.3522
945.139	41.2447
948.473	38.6695
951.804	37.191
955.136	34.7478
958.465	33.1319
961.794	30.6798
965.12	30.9217
968.447	29.9078
971.771	28.6603
975.095	30.1221
978.417	29.1031
981.737	29.4928
985.057	28.5683
988.375	27.9556
991.691	28.703
995.006	28.0336
998.32	27.2301
1001.63	27.177
1004.95	25.6712
1008.26	24.8069
1011.56	24.8823
1014.87	24.4275
1018.18	24.145
1021.48	22.4375
1024.79	20.3381
1028.09	19.0905
1031.39	16.7611
1034.69	15.8034
1037.99	14.6892
1041.29	13.8962
1044.58	12.6179
1047.88	13.1025
1051.17	13.8513
1054.46	12.9668
1057.75	12.0027
1061.04	9.8231
1064.33	11.1182
1067.62	9.96373
1070.9	9.19002
1074.19	10.4267
1077.47	10.0845
1080.76	9.20571
1084.04	9.12232
1087.32	9.79572
1090.59	9.17773
1093.87	7.81626
1097.15	7.748
1100.42	7.84815
1103.69	6.21738
1106.97	7.1092
1110.24	7.60518
1113.51	7.2741
1116.77	6.13236
1120.04	5.45788
1123.31	5.42071
1126.57	4.75513
1129.83	4.64802
1133.1	4.29634
1136.36	3.54755
1139.62	3.68036
1142.87	4.65196
1146.13	3.44283
1149.38	3.94659
1152.64	3.75243
1155.89	3.22402
1159.14	2.64859
1162.39	3.00129
1165.64	3.32498
1168.89	4.0968
1172.14	4.0751
1175.38	4.98522
1178.63	5.06813
1181.87	4.71598
1185.11	4.51823
1188.35	5.6169
1191.59	5.58853
1194.83	4.26183
1198.07	4.9906
1201.3	7.19931
1204.53	9.39069
1207.77	9.22434
1211	11.0716
1214.23	14.65
1217.46	16.739
1220.69	19.4205
1223.91	21.4824
1227.14	23.8426
1230.36	26.3441
1233.59	27.929
1236.81	28.8453
1240.03	29.7207
1243.25	30.7011
1246.46	32.2472
1249.68	33.2745
1252.9	32.7877
1256.11	33.4314
1259.32	32.2406
1262.54	31.5095
1265.75	30.7102
1268.96	30.6995
1272.16	31.4038
1275.37	32.6378
1278.57	34.7034
1281.78	36.2494
1284.98	37.3027
1288.18	37.7259
1291.38	40.0348
1294.58	41.2316
1297.78	43.8938
1300.98	44.9136
1304.17	45.5578
1307.37	46.0266
1310.56	46.7674
1313.76	46.6961
1316.95	46.9038
1320.14	47.0315
1323.32	45.8717
1326.51	44.9674
1329.7	44.6258
1332.88	43.2024
1336.07	41.1201
1339.25	40.7966
1342.43	40.738
1345.61	39.8389
1348.79	41.6209
1351.96	42.3521
1355.14	41.5963
1358.31	40.2012
1361.49	40.4715
1364.66	39.7756
1367.83	39.8191
1371	39.4312
1374.17	38.9295
1377.34	37.6534
1380.5	37.2734
1383.67	35.4216
1386.83	33.8872
1390	31.5675
1393.16	29.6887
1396.32	27.4525
1399.48	25.1975
1402.64	23.6234
1405.79	21.8331
1408.95	22.729
1412.1	22.0029
1415.26	23.1844
1418.41	24.1563
1421.56	26.5956
1424.71	29.6936
1427.86	32.6975
1431	34.5819
1434.15	36.3774
1437.29	38.505
1440.44	41.1832
1443.58	43.1494
1446.72	44.931
1449.86	44.8404
1453	44.8792
1456.14	43.4436
1459.27	40.2084
1462.41	37.4247
1465.54	34.0787
1468.67	29.9155
1471.81	26.3936
1474.94	21.7017
1478.07	18.4298
1481.19	14.141
1484.32	10.552
1487.45	7.93739
1490.57	4.86913
1493.69	3.82672
1496.82	2.05701
1499.94	1.08091
1503.06	1.96661
1506.17	1.61377
1509.29	1.8673
1512.41	1.69103
1515.52	3.39201
1518.64	5.63433
1521.75	6.55177
1524.86	8.07929
1527.97	10.5036
1531.08	12.6256
1534.19	13.4771
1537.29	15.0588
1540.4	16.3895
1543.5	18.7457
1546.61	21.372
1549.71	23.6892
1552.81	25.4016
1555.91	28.1789
1559.01	30.0836
1562.11	31.8471
1565.2	35.5711
1568.29	38.3708
1571.39	41.7694
1574.48	44.4762
1577.57	47.8851
1580.66	49.1228
1583.75	50.3861
1586.84	50.7453
1589.93	51.2338
1593.01	51.5934
1596.1	50.3109
1599.18	49.4535
1602.26	48.1756
1605.34	44.9866
1608.42	41.4625
1611.5	39.8829
1614.58	37.3197
1617.65	36.1317
1620.73	34.2487
1623.8	33.4566
1626.87	32.6305
1629.95	31.9191
1633.02	32.4455
1636.09	32.6377
1639.15	35.402
1642.22	35.9997
1645.29	38.1765
1648.35	39.1181
1651.42	39.8875
1654.48	40.9813
1657.54	41.9572
1660.6	42.689
1663.66	42.876
1666.72	42.8225
1669.77	40.7547
1672.83	37.8535
1675.88	34.6603
1678.93	31.8394
1681.99	29.4546
1685.04	26.4361
1688.09	22.9455
1691.13	19.295
1694.18	16.6308
1697.23	14.279
1700.27	11.5983
1703.32	8.23198
1706.36	6.26432
1709.4	3.45844
1712.44	2.22355
1715.48	1.06244
1718.52	0.0803921
1721.56	-0.506257
1724.59	-0.926972
1727.63	-0.375681
1730.66	0.247651
1733.69	0.574393
1736.72	0.52414
1739.75	0.582981
1742.78	0.850311
1745.81	0.522679
1748.84	0.430821
1751.86	1.07554
1754.89	1.16582
1757.91	1.39942
1760.93	0.626044
1763.95	0.656795
1766.97	0.733411
1769.99	0.485872
1773.01	-0.233284
1776.03	-0.749264
1779.04	-0.24982
1782.06	0.0452063
1785.07	1.42829
1788.08	2.40084
1791.09	2.94363
1794.1	3.38813
1797.11	3.6897
1800.12	5.12709
1803.12	5.72859
1806.13	5.68299
1809.13	5.54133
1812.14	5.75703
1815.14	6.41909
1818.14	6.57121
1821.14	6.06511
1824.14	6.45629
1827.13	7.11527
1830.13	6.05301
1833.12	5.34315
1836.12	5.22816
1839.11	4.86363
1842.1	4.73113
1845.09	4.53183
1848.08	4.15946
1851.07	4.03368
1854.06	3.69679
1857.04	3.63973
1860.03	4.04081
1863.01	3.61636
1866	3.84037
1868.98	4.0836
1871.96	4.76691
1874.94	5.55774
1877.92	6.32958
1880.89	6.68854
1882.48	7.45388
1885.47	9.06412
1888.46	9.71086
1891.44	10.8686
1894.43	12.1239
1897.41	13.5848
1900.4	14.3648
1903.38	14.6622
1906.36	15.7729
1909.34	15.6053
1912.32	16.3372
1915.29	16.3404
1918.27	14.7959
1921.25	14.5149
1924.22	12.5724
1927.2	12.0656
1930.17	11.7526
1933.14	10.9677
1936.11	10.262
1939.08	10.0995
1942.05	8.91569
1945.01	8.2008
1947.98	8.48019
1950.94	8.70217
1953.91	8.57759
1956.87	8.85707
1959.83	8.67871
1962.79	9.27927
1965.75	9.05482
1968.71	10.1834
1971.67	10.1719
1974.62	9.31212
1977.58	10.2189
1980.53	11.0749
1983.48	11.8841
1986.43	12.195
1989.38	11.863
1992.33	11.438
1995.28	11.3602
1998.23	11.7435
2001.18	12.5961
2004.12	11.5115
2007.06	10.3605
2010.01	10.3563
2012.95	9.22809
2015.89	9.00908
2018.83	8.81525
2021.77	7.87949
2024.71	7.45017
2027.64	7.67517
2030.58	8.47134
2033.51	8.78066
2036.45	8.65565
2039.38	8.88334
2042.31	10.0123
2045.24	9.77346
2048.17	11.2427
2051.1	12.0173
2054.02	13.2891
2056.95	13.7795
2059.87	13.2877
2062.8	14.0049
2065.72	14.2673
2068.64	15.8593
2071.56	15.8633
2074.48	15.802
2077.4	15.5315
2080.31	14.9632
2083.23	15.1221
2086.14	14.8468
2089.06	14.5673
2091.97	15.2873
2094.88	16.5491
2097.79	17.3173
2100.7	17.7502
2103.61	18.7882
2106.52	19.2734
2109.43	19.51
2112.33	20.5924
2115.24	22.3385
2118.14	24.4676
2121.04	26.0758
2123.94	27.378
2126.84	28.6508
2129.74	29.9956
2132.64	31.1971
2135.54	33.5475
2138.43	34.7158
2141.33	36.327
2144.22	38.0809
2147.11	39.2623
2150.01	41.2955
2152.9	41.923
2155.79	43.7381
2158.67	44.4884
2161.56	46.5373
2164.45	47.5023
2167.33	48.2945
2170.22	47.9669
2173.1	48.6537
2175.98	49.0821
2178.86	48.5592
2181.74	48.3597
2184.62	49.154
2187.5	48.9664
2190.38	47.4199
2193.25	45.8271
2196.13	43.5124
2199	42.3163
2201.88	39.6595
2204.75	38.2046
2207.62	36.527
2210.49	34.465
2213.36	32.6541
2216.22	31.2947
2219.09	30.0391
2221.96	28.2224
2224.82	26.9858
2227.68	25.5483
2230.55	24.1771
2233.41	22.8615
2236.27	22.232
2239.12	20.4975
2241.98	20.131
2244.84	19.784
2247.7	18.9326
2250.55	18.7816
2253.41	18.7354
2256.26	18.489
2259.11	18.6974
2261.96	18.7424
2264.81	17.8994
2267.66	18.6108
2270.51	19.101
2273.35	18.5671
2276.2	17.9538
2279.04	17.9695
2281.89	18.2371
2284.73	18.2196
2287.57	17.7808
2290.41	17.6621
2293.25	15.747
2296.09	14.8783
2298.93	14.5355
2301.76	14.3843
2304.6	14.8017
2307.44	14.5069
2310.27	13.9309
2313.1	14.2451
2315.93	13.728
2318.76	14.5681
2321.59	14.812
2324.42	15.1216
2327.25	13.8683
2330.07	12.9614
2332.9	11.8846
2335.72	10.696
2338.55	10.8113
2341.37	9.67535
2344.19	8.87645
2347.01	8.30092
2349.83	7.57462
2352.65	5.69402
2355.46	5.3864
2358.28	4.26388
2361.09	3.39554
2363.91	3.86924
2366.72	4.5116
2369.53	5.31326
2372.34	6.15151
2375.15	7.0576
2377.96	7.96217
2380.77	8.69935
2383.58	9.16999
2386.38	9.85311
2389.19	10.3057
2391.99	9.88992
2394.8	9.15659
2397.6	8.29582
2400.4	9.4989
2403.2	10.4284
2406	10.4019
2408.79	10.55
2411.59	11.2955
2414.39	10.369
2417.18	9.54636
2419.98	8.50767
2422.77	8.49478
2425.56	9.27202
2428.35	9.23736
2431.14	9.07995
2433.93	9.07501
2436.72	8.12007
2439.5	8.90029
2442.29	8.79976
2445.07	8.78566
2447.86	8.30359
2450.64	7.47311
2453.42	7.41451
2456.2	7.4857
2458.98	6.69566
2461.76	7.24247
2464.54	7.76988
2467.32	7.74951
2470.09	7.65432
2472.87	6.90534
2475.64	6.72654
2478.41	6.24734
2481.18	4.88312
2483.95	3.92375
2486.72	3.95013
2489.49	3.62577
2492.26	3.50133
2495.03	3.31544
2497.79	3.36788
2500.56	2.25748
2503.32	2.47113
2506.09	2.85617
2508.85	2.76109
2511.61	2.82149
2514.37	2.72815
2517.13	1.92383
2519.89	1.76355
2522.64	1.64738
2525.4	2.26347
2528.15	1.8385
2530.91	2.3671
2533.66	1.90251
2536.41	1.12337
2539.16	1.16978
2541.91	1.60205
2544.66	1.87697
2547.41	0.842054
2550.16	2.24588
2552.9	2.30463
2555.65	2.88216
2558.39	2.75842
2561.13	2.594
2563.88	3.15127
2566.62	3.25622
2569.36	3.04381
2572.1	3.50908
2574.84	2.58451
2577.57	2.3848
2580.31	2.16393
2583.05	1.60313
2585.78	0.720544
2588.51	0.769535
2591.24	1.54057
2593.98	1.23651
2596.71	1.26266
2599.44	1.74827
2602.16	1.53449
2604.89	1.57844
2607.62	2.12981
2610.34	2.83361
2613.07	2.28775
2615.79	2.58145
2618.52	3.1435
2621.24	2.61319
2623.96	3.39227
2626.68	3.58864
2629.4	3.59019
2632.11	3.19514
2634.83	3.69641
2637.55	3.68787
2640.26	3.48569
2642.98	3.19325
2645.69	3.52631
2648.4	3.27661
2651.11	2.05361
2653.82	2.25694
2656.53	2.32934
2659.24	2.30151
2661.95	2.06348
2664.65	1.21633
2667.36	0.434617
2670.06	-0.46127
2672.76	-1.22431
2675.47	-1.09275
2678.17	-1.20511
2680.87	-0.177434
2683.57	0.414331
2686.27	0.803616
2688.97	1.23211
2691.66	1.12843
2694.36	2.20157
2697.05	2.27365
2699.75	4.05529
2702.44	4.81976
2705.13	5.16836
2707.82	6.51091
2710.51	5.95583
2713.2	6.73906
2715.89	6.48038
2718.57	6.47854
2721.26	7.33913
2723.95	7.47265
2726.63	7.3223
2729.31	6.31207
2732	5.65813
2734.68	5.52121
2737.36	5.56135
2740.04	5.60114
2742.72	5.53701
2745.39	4.70607
2748.07	3.94516
2750.75	3.73131
2753.42	3.41253
2756.09	2.73572
2758.77	2.82566
2761.44	3.32043
2764.11	2.92198
2766.78	2.94879
2769.45	3.03789
2772.12	2.73983
2774.78	1.78237
2777.45	1.75681
2780.12	1.71915
2782.78	2.03348
2785.44	2.89211
2788.11	3.1519
2790.77	4.07131
2793.43	3.05098
2796.09	3.37882
2798.75	3.08718
2801.4	3.11277
2804.06	3.35972
2806.72	2.57464
2809.37	1.61385
2812.03	1.36111
2814.68	1.35034
2817.33	1.94789
2819.98	1.94045
2822.63	2.42333
2825.28	3.76708
2827.93	4.68982
2830.58	6.4663
2833.23	7.46841
2835.87	9.64568
2838.52	11.043
2841.16	13.5274
2843.8	15.7576
2846.44	20.1012
2849.08	24.3004
2851.73	28.8306
2854.36	33.2501
2857	37.246
2859.64	41.2406
2862.28	45.5781
2864.91	49.3653
2867.55	53.6832
2870.18	56.1844
2872.81	58.1558
2875.44	60.5449
2878.07	62.3126
2880.7	64.4057
2883.33	66.7042
2885.96	69.0701
2888.59	71.8497
2891.21	73.0871
2893.84	75.5737
2896.46	77.3631
2899.09	80.0208
2901.71	83.6497
2904.33	87.3358
2906.95	91.7158
2909.57	97.4549
2912.19	103.674
2914.81	109.206
2917.43	114.631
2920.04	119.689
2922.66	124.324
2925.27	127.681
2927.88	129.475
2930.5	131.615
2933.11	132.467
2935.72	132.658
2938.33	132.056
2940.94	130.238
2943.54	127.184
2946.15	124.307
2948.76	120.072
2951.36	115.85
2953.97	111.446
2956.57	107.069
2959.17	103.586
2961.77	99.2432
2964.37	95.0525
2966.97	89.7632
2969.57	85.1622
2972.17	80.94
2974.77	76.4037
2977.36	71.968
2979.96	68.8245
2982.55	64.5243
2985.15	59.5014
2987.74	54.1405
2990.33	48.8529
2992.92	44.5142
2995.51	40.9995
2998.1	36.6702
3000.69	32.3297
3003.27	28.0215
3005.86	24.466
3008.44	20.8076
3011.03	18.8988
3013.61	16.951
3016.19	15.9276
3018.78	14.7468
3021.36	14.0371
3023.94	13.359
3026.51	12.2418
3029.09	12.2194
3031.67	11.4397
3034.24	11.7008
3036.82	12.6886
3039.39	14.2229
3041.97	14.9147
3044.54	15.2281
3047.11	14.6828
3049.68	15.8575
3052.25	15.3887
3054.82	15.5412
3057.39	15.0193
3059.96	14.6566
3062.52	13.3652
3065.09	12.7712
3067.65	12.3836
3070.22	12.053
3072.78	11.9291
3075.34	11.2802
3077.9	10.812
3080.46	10.1181
3083.02	9.17106
3085.58	8.63097
3088.14	7.83858
3090.69	6.22872
3093.25	4.91596
3095.8	4.02997
3098.36	3.92516
3100.91	3.65887
3103.46	3.5579
3106.01	3.27027
3108.56	2.8242
3111.11	2.46332
3113.66	2.65025
3116.21	1.62709
3118.76	0.935862
3121.3	0.313475
3123.85	0.240664
3126.39	0.517994
3128.93	0.768742
3131.48	1.05679
3134.02	1.82688
3136.56	2.60662
3139.1	3.10879
3141.64	3.36936
3144.17	3.31041
3146.71	2.87586
3149.25	2.77988