File: data/Raman/poly_smoothed/Thy_00_07_27_1x_45s_532 nm_x100_100%_600 gr_mm_01.txt
#Acq. time (s)=	45
#Accumulations=	2
#Range (cm-¹)=	200...3150
#Windows=	2
#Auto scanning=	Off
#Autofocus=	Off
#Macrospot=	Off
#AutoExposure=	Off
#Spike filter=	Multiple accum.
#Delay time (s)=	0
#Binning=	1
#Readout mode=	Signal
#DeNoise=	Off
#ICS correction=	On
#Dark correction=	Off
#Inst. Process=	Off
#Detector Gain=	Best Dynamic Range
#Detector ADC=	20 kHz
#Detector temperature (°C)=	-69.85
#Instrument=	LabRAM HR Evol
#Detector=	Synapse
#Objective=	x100
#Grating=	600 gr/mm
#ND Filter=	100%
#Laser (nm)=	532
#Hole=	100.021
#Range=	Auto
#Laser Pol.=	No
#Raman. Pol.=	No
#Laser Pol. (°)=	-0.0007625
#Raman Pol. (°)=	89.9995
#Collection=	Microscope
#StageXY=	Marzhauser
#StageZ=	Marzhauser
#X (µm)=	8989.2
#Y (µm)=	-3069.7
#Z (µm)=	-55.15
#Full time(mm:ss)=	3:18
#Project=
#Sample=
#Site=
#Title=	Thy_00_07_27_2x_45s_532 nm_x100_100%_600 gr_mm
#Remark=
#Date=	28.06.2022 12:05
#Acquired=	28.06.2022 12:05:44
#Base:Fit=	10.08.2022 10:07:56
#Base:Sub=	10.08.2022 10:08:40
#Filter:Polynom=	16.08.2022 10:26:06
#AxisType[0]=Intens
#AxisUnit[0]=Cnt
#AxisType[1]=Spectr
#AxisUnit[1]=1/cm
200.407	28.9773
204.035	28.1924
207.665	28.6821
211.291	28.8196
214.916	28.0914
218.541	25.0314
222.163	22.8198
225.785	20.973
229.404	18.895
233.022	16.1514
236.638	13.3932
240.255	11.9408
243.868	10.9015
247.48	9.74233
251.091	7.66699
254.702	6.48484
258.31	5.9757
261.916	5.7072
265.521	6.47858
269.125	4.4667
272.727	4.80583
276.328	4.36738
279.927	5.11996
283.525	6.24403
287.121	7.07643
290.716	7.8121
294.31	9.78448
297.9	10.5086
301.491	11.3534
305.081	11.4788
308.669	10.6179
312.256	11.6957
315.839	11.4502
319.423	12.0847
323.006	12.5656
326.585	12.8497
330.165	14.7115
333.741	14.5868
337.318	14.8052
340.894	14.1991
344.466	15.5621
348.039	16.4865
351.608	15.6671
355.176	15.3219
358.745	15.9499
362.31	17.5278
365.876	17.3617
369.439	15.5833
373	14.6158
376.56	15.3194
380.12	16.1044
383.677	16.4034
387.233	16.8366
390.787	16.937
394.34	16.1539
397.894	16.2216
401.444	15.6682
404.993	15.7018
408.54	17.092
412.086	17.9774
415.631	17.5071
419.174	18.3725
422.716	16.9298
426.257	14.7507
429.794	13.0036
433.332	11.8181
436.868	9.46557
440.403	9.1455
443.937	10.6348
447.468	13.3207
450.999	13.9943
454.528	16.1503
458.057	18.9883
461.582	24.7514
465.107	29.0301
468.629	33.1512
472.152	36.9289
475.672	39.679
479.192	42.9886
482.709	45.8792
486.226	49.3289
489.74	51.9356
493.255	54.1872
496.767	55.8586
500.277	55.4374
503.788	53.4432
507.295	50.211
510.801	44.8284
514.308	39.2016
517.811	32.6568
521.313	28.3234
524.814	25.0578
528.313	22.2327
531.811	20.2075
535.308	16.9585
538.803	15.3649
542.297	13.5224
545.789	13.2637
549.281	11.6217
552.771	11.4345
556.259	10.9668
559.747	12.4847
563.233	12.9953
566.717	13.7525
570.2	15.2179
573.68	16.3624
577.161	16.6667
580.64	16.7212
584.118	16.5325
587.593	15.4348
591.068	14.6531
594.54	11.6873
598.013	10.2377
601.484	7.81848
604.952	5.08028
608.421	4.45801
611.886	2.89066
615.35	2.48384
618.815	0.695859
622.276	-0.802128
625.738	0.513523
629.197	0.195173
632.655	1.68599
636.113	2.59902
639.568	4.49285
643.021	5.93645
646.473	7.28202
649.924	7.18753
653.376	8.67511
656.824	8.52103
660.271	8.14958
663.716	7.95835
667.161	7.11708
670.604	8.25462
674.045	8.27784
677.486	9.92424
680.925	10.2097
684.361	11.4758
687.797	11.1038
691.232	13.0514
694.666	14.1183
698.099	14.0054
701.528	14.284
704.958	13.5353
708.387	15.0244
711.814	17.1367
715.238	19.1405
718.663	20.3828
722.084	22.2794
725.506	24.4254
728.925	25.9234
732.345	26.6228
735.761	28.2312
739.178	30.6787
742.592	34.271
746.006	36.4427
749.417	41.0148
752.827	45.2571
756.236	49.0142
759.645	52.5022
763.051	56.1567
766.456	58.2092
769.859	60.3519
773.261	61.1319
776.664	62.1336
780.064	62.0946
783.462	61.9578
786.859	62.1567
790.255	61.4083
793.649	62.1143
797.042	60.9016
800.434	61.533
803.823	59.7616
807.212	58.7929
810.6	58.1987
813.987	57.7883
817.372	60.2219
820.754	63.4077
824.137	67.1997
827.519	69.9357
830.897	73.5331
834.276	77.0304
837.654	78.5752
841.029	80.306
844.404	80.2444
847.776	78.2048
851.149	75.289
854.519	73.3389
857.889	71.7266
861.256	68.4148
864.622	64.4262
867.988	59.95
871.351	55.6863
874.713	52.9603
878.074	49.1337
881.435	45.6326
884.794	42.3547
888.15	39.3627
891.506	37.8607
894.861	39.8761
898.214	41.7658
901.566	44.739
904.916	47.7192
908.266	50.1067
911.614	53.6776
914.961	57.275
918.306	58.6654
921.651	59.1451
924.994	58.1258
928.336	55.3896
931.674	53.6805
935.014	51.8947
938.352	50.6975
941.687	47.6601
945.022	43.8104
948.357	39.8947
951.688	38.1175
955.02	34.7899
958.348	30.8553
961.678	26.2293
965.004	24.885
968.331	25.3813
971.655	25.671
974.979	27.0292
978.3	30.2719
981.62	30.2916
984.941	32.682
988.259	33.8179
991.575	34.1484
994.89	34.7059
998.204	37.3195
1001.52	37.0774
1004.83	38.2007
1008.14	39.4114
1011.45	40.501
1014.76	43.8754
1018.06	44.382
1021.37	42.7831
1024.67	42.2163
1027.97	40.5291
1031.27	39.2158
1034.57	36.5872
1037.87	33.5989
1041.17	32.6571
1044.47	34.2727
1047.76	34.8261
1051.06	35.7235
1054.35	34.9624
1057.64	36.9679
1060.93	34.673
1064.22	34.2356
1067.5	34.0989
1070.79	34.1743
1074.08	36.6893
1077.36	38.2328
1080.64	40.4571
1083.92	41.5408
1087.2	42.6881
1090.48	44.4447
1093.76	46.2414
1097.03	47.6737
1100.31	47.211
1103.58	48.1783
1106.85	48.7003
1110.12	48.099
1113.39	47.8667
1116.66	46.7707
1119.93	46.6097
1123.19	45.1375
1126.46	44.0756
1129.72	42.6303
1132.98	40.9805
1136.24	39.0744
1139.5	35.1705
1142.76	32.6528
1146.01	30.5935
1149.27	27.3816
1152.53	23.0562
1155.78	20.1155
1159.03	15.8269
1162.28	12.3519
1165.53	8.39753
1168.78	7.49027
1172.02	7.89146
1175.27	7.5727
1178.51	6.71519
1181.76	6.72103
1185	6.76108
1188.24	8.4654
1191.48	8.67244
1194.71	9.67692
1197.95	10.617
1201.19	12.9079
1204.42	15.0851
1207.65	20.1591
1210.88	23.8037
1214.12	28.1558
1217.35	31.5592
1220.57	35.7238
1223.8	39.9421
1227.03	41.2251
1230.25	43.7943
1233.47	44.6971
1236.69	47.4397
1239.92	50.0716
1243.13	51.6762
1246.35	54.3669
1249.57	56.5131
1252.78	57.6367
1256	57.5414
1259.21	56.2487
1262.42	56.5322
1265.63	55.8658
1268.84	54.848
1272.05	53.5777
1275.26	53.9042
1278.46	53.4124
1281.67	54.3771
1284.87	57.5864
1288.07	59.4035
1291.27	59.7871
1294.47	61.1678
1297.67	64.4926
1300.87	66.1557
1304.06	68.5497
1307.26	72.824
1310.45	78.8188
1313.64	84.6545
1316.83	91.2053
1320.02	95.3053
1323.21	100.333
1326.4	102.491
1329.59	105.135
1332.77	106.594
1335.95	106.759
1339.14	105.82
1342.32	104.592
1345.5	103.188
1348.67	101.035
1351.85	99.9246
1355.03	95.0078
1358.2	91.5589
1361.38	88.6026
1364.55	86.8792
1367.72	83.1685
1370.89	80.0766
1374.06	78.2793
1377.23	75.6718
1380.39	73.3692
1383.56	74.0449
1386.72	74.3457
1389.89	73.2683
1393.05	71.574
1396.21	69.0844
1399.37	67.588
1402.52	65.7656
1405.68	64.1192
1408.84	63.1997
1411.99	64.5546
1415.15	65.2409
1418.3	68.2399
1421.45	71.7769
1424.6	77.122
1427.75	81.6489
1430.89	86.3123
1434.04	92.7423
1437.18	100.144
1440.33	105.556
1443.47	109.692
1446.61	113.861
1449.75	115.055
1452.89	114.78
1456.03	112.552
1459.16	109.1
1462.3	103.295
1465.43	97.7861
1468.56	89.7141
1471.7	82.4759
1474.83	73.9977
1477.96	66.059
1481.08	57.0899
1484.21	50.6711
1487.34	44.7389
1490.46	38.2254
1493.58	33.2488
1496.71	27.9799
1499.83	24.3179
1502.95	22.2695
1506.07	20.3076
1509.18	20.6318
1512.3	20.1118
1515.41	18.4004
1518.53	19.2812
1521.64	20.6374
1524.75	21.284
1527.86	21.4922
1530.97	21.2524
1534.08	21.9584
1537.19	25.1578
1540.29	28.8818
1543.4	31.5445
1546.5	34.8356
1549.6	38.048
1552.7	41.2966
1555.8	44.93
1558.9	49.3517
1562	53.4246
1565.09	57.609
1568.19	62.2073
1571.28	65.7128
1574.37	70.2412
1577.47	72.9807
1580.56	76.6442
1583.64	79.0972
1586.73	81.275
1589.82	81.8036
1592.9	83.2781
1595.99	85.3658
1599.07	86.4051
1602.15	85.3481
1605.23	83.4007
1608.31	82.8842
1611.39	82.9414
1614.47	82.359
1617.55	79.2971
1620.62	78.2847
1623.7	77.8041
1626.77	77.4762
1629.84	78.0373
1632.91	79.8101
1635.98	79.3447
1639.05	81.5687
1642.11	84.561
1645.18	87.9165
1648.24	88.78
1651.31	89.8788
1654.37	90.1321
1657.43	90.4415
1660.49	89.5571
1663.55	88.1383
1666.61	86.3317
1669.66	83.8726
1672.72	81.0969
1675.77	76.3729
1678.83	72.1181
1681.88	67.7722
1684.93	63.2166
1687.98	58.2179
1691.03	53.202
1694.07	49.2701
1697.12	45.4927
1700.17	41.3133
1703.21	37.4179
1706.25	34.9179
1709.29	30.3624
1712.33	28.9445
1715.37	27.7136
1718.41	25.4605
1721.45	23.5472
1724.49	21.3983
1727.52	19.4238
1730.55	18.7279
1733.59	16.7123
1736.62	16.6765
1739.65	15.3704
1742.68	14.5012
1745.7	13.2996
1748.73	11.7669
1751.76	11.1146
1754.78	10.6572
1757.8	9.45246
1760.83	8.61551
1763.85	8.62163
1766.87	9.18414
1769.89	7.98466
1772.9	8.40589
1775.92	8.33127
1778.94	8.72017
1781.95	8.50279
1784.96	8.55594
1787.97	8.92818
1790.99	8.55214
1794	8.27149
1797	7.5172
1800.01	6.91417
1803.02	6.05469
1806.02	4.89807
1809.03	4.51826
1812.03	4.96431
1815.03	4.91926
1818.03	4.56301
1821.03	4.14257
1824.03	3.63627
1827.03	3.44515
1830.02	3.0069
1833.02	3.53623
1836.01	3.63476
1839.01	5.17818
1842	5.74753
1844.99	6.84617
1847.98	8.27265
1850.97	7.87109
1853.95	8.43081
1856.94	7.98533
1859.93	7.57548
1862.91	7.25884
1865.89	6.40255
1868.87	7.15551
1871.85	5.79137
1874.83	5.04505
1877.81	4.02321
1880.79	3.1329
1882.52	3.26895
1885.51	2.72294
1888.5	3.03222
1891.49	2.86069
1894.47	3.49639
1897.46	3.78114
1900.44	4.28743
1903.42	4.81675
1906.4	5.46619
1909.38	5.19686
1912.36	6.73348
1915.34	6.61515
1918.32	6.85506
1921.29	6.96073
1924.27	5.91662
1927.24	5.75596
1930.21	6.0056
1933.18	6.45962
1936.15	7.30228
1939.12	7.62371
1942.09	7.30339
1945.06	5.88892
1948.02	6.08368
1950.99	4.77576
1953.95	4.32968
1956.91	4.11147
1959.88	4.16566
1962.84	4.84382
1965.8	3.9654
1968.75	3.40594
1971.71	2.94423
1974.67	3.13454
1977.62	2.29883
1980.58	2.13195
1983.53	2.44121
1986.48	2.98309
1989.43	3.80278
1992.38	4.27788
1995.33	5.48686
1998.27	6.11109
2001.22	6.77266
2004.16	8.02063
2007.11	9.02598
2010.05	8.70729
2012.99	9.85834
2015.93	9.88911
2018.87	9.84348
2021.81	9.66999
2024.75	9.09479
2027.69	10.0004
2030.62	8.85574
2033.56	9.08398
2036.49	7.98902
2039.42	6.62304
2042.35	6.63398
2045.28	6.45111
2048.21	6.33786
2051.14	6.01933
2054.07	6.63292
2056.99	7.14114
2059.92	6.84908
2062.84	6.53631
2065.76	5.73961
2068.68	4.53423
2071.6	4.81676
2074.52	4.65369
2077.44	4.80087
2080.36	4.69228
2083.27	4.16961
2086.19	4.19836
2089.1	5.06037
2092.02	5.14007
2094.93	5.39465
2097.84	6.39002
2100.75	6.70997
2103.66	5.62877
2106.56	5.99807
2109.47	6.76619
2112.38	7.16751
2115.28	8.18428
2118.18	7.29059
2121.09	5.9836
2123.99	5.51727
2126.89	6.13715
2129.79	5.57036
2132.68	3.91512
2135.58	3.9369
2138.48	3.54605
2141.37	3.67584
2144.27	3.53186
2147.16	3.92554
2150.05	3.38288
2152.94	3.30913
2155.83	3.09205
2158.72	4.3068
2161.6	4.29941
2164.49	5.38501
2167.38	5.89586
2170.26	5.81793
2173.14	6.12036
2176.03	6.56089
2178.91	6.95988
2181.79	6.95634
2184.67	5.74545
2187.54	4.72004
2190.42	4.12384
2193.3	4.44562
2196.17	5.48673
2199.05	5.9045
2201.92	4.39198
2204.79	4.604
2207.66	3.80504
2210.53	3.28744
2213.4	3.31523
2216.27	2.9779
2219.13	3.18094
2222	3.35289
2224.86	3.07297
2227.72	4.06073
2230.59	4.17961
2233.45	4.02232
2236.31	4.28476
2239.17	5.09247
2242.03	5.54769
2244.88	6.2402
2247.74	8.26589
2250.59	7.77676
2253.45	7.90181
2256.3	8.95881
2259.15	8.66302
2262	8.67033
2264.85	8.50961
2267.7	6.95813
2270.55	6.24364
2273.4	5.02937
2276.24	4.03617
2279.09	3.98431
2281.93	3.31725
2284.77	2.70055
2287.62	2.39585
2290.46	2.63862
2293.3	1.04319
2296.13	0.818807
2298.97	0.598925
2301.81	0.412059
2304.64	1.95986
2307.48	3.91755
2310.31	5.44897
2313.14	5.09945
2315.98	6.12221
2318.81	7.05061
2321.64	6.61981
2324.46	7.56678
2327.29	8.00315
2330.12	6.64271
2332.94	6.28938
2335.77	6.50702
2338.59	6.9901
2341.41	6.44357
2344.23	6.13469
2347.05	5.81887
2349.87	5.05875
2352.69	3.2443
2355.51	3.04426
2358.32	1.47593
2361.14	1.42852
2363.95	1.20476
2366.76	1.01243
2369.58	0.536994
2372.39	1.25625
2375.2	1.52843
2378	1.77358
2380.81	1.19226
2383.62	1.34797
2386.43	1.66543
2389.23	2.43928
2392.03	2.229
2394.84	4.14109
2397.64	4.46858
2400.44	6.23189
2403.24	6.66108
2406.04	7.86896
2408.84	8.49704
2411.63	8.95685
2414.43	9.4522
2417.22	10.3025
2420.02	11.031
2422.81	11.7206
2425.6	13.0234
2428.39	13.2547
2431.18	12.8861
2433.97	11.4081
2436.76	11.2696
2439.54	11.1318
2442.33	10.5003
2445.12	9.43715
2447.9	8.63175
2450.68	7.33177
2453.46	6.02076
2456.24	4.55142
2459.02	4.19051
2461.8	3.41428
2464.58	2.79407
2467.36	1.61396
2470.13	0.615963
2472.91	0.654683
2475.68	0.366556
2478.45	0.358053
2481.23	1.01489
2484	1.94692
2486.77	2.58101
2489.54	3.41332
2492.3	3.87158
2495.07	4.39546
2497.84	3.40111
2500.6	4.0434
2503.36	3.30309
2506.13	4.96344
2508.89	5.15976
2511.65	5.66735
2514.41	6.57562
2517.17	6.26045
2519.93	5.76022
2522.68	5.95302
2525.44	6.09124
2528.19	5.78767
2530.95	4.60932
2533.7	4.40254
2536.45	3.91604
2539.2	4.42092
2541.95	5.45676
2544.7	6.35799
2547.45	6.19558
2550.2	6.19546
2552.94	5.21869
2555.69	5.04848
2558.43	4.4442
2561.18	4.4035
2563.92	3.57018
2566.66	2.86828
2569.4	2.51637
2572.14	2.04455
2574.88	3.00369
2577.61	3.27295
2580.35	3.39872
2583.09	3.84828
2585.82	4.2495
2588.55	4.54334
2591.29	4.46171
2594.02	3.62788
2596.75	3.72159
2599.48	4.31768
2602.21	5.34314
2604.93	6.10321
2607.66	6.9137
2610.39	6.91445
2613.11	7.28556
2615.83	7.59373
2618.56	8.39144
2621.28	9.01667
2624	9.40916
2626.72	8.96114
2629.44	8.70493
2632.15	7.52218
2634.87	7.26572
2637.59	7.39645
2640.3	8.00599
2643.02	9.54384
2645.73	9.98709
2648.44	9.80364
2651.15	10.0116
2653.86	10.1845
2656.57	9.69056
2659.28	8.60681
2661.99	8.32542
2664.69	9.03103
2667.4	9.16574
2670.1	8.52082
2672.81	8.34526
2675.51	8.31656
2678.21	9.27546
2680.91	9.92464
2683.61	10.2729
2686.31	10.6857
2689	10.2954
2691.7	10.6308
2694.4	10.367
2697.09	10.4908
2699.79	11.3883
2702.48	12.669
2705.17	14.2971
2707.86	14.5357
2710.55	15.5249
2713.24	15.5807
2715.93	16.7169
2718.62	17.1196
2721.3	17.5471
2723.99	16.904
2726.67	15.8645
2729.35	16.1192
2732.04	15.9974
2734.72	15.4735
2737.4	15.0337
2740.08	15.1882
2742.76	15.2115
2745.43	14.5912
2748.11	13.6269
2750.79	13.0758
2753.46	13.0272
2756.14	11.8125
2758.81	11.0172
2761.48	9.86582
2764.15	9.5478
2766.82	9.3251
2769.49	8.10612
2772.16	6.90053
2774.82	5.56766
2777.49	4.7651
2780.16	3.86686
2782.82	2.23521
2785.48	1.03409
2788.15	0.395262
2790.81	-0.513998
2793.47	-0.904872
2796.13	-0.772043
2798.79	-0.558171
2801.44	0.2932
2804.1	0.0462563
2806.76	0.703127
2809.41	0.32259
2812.07	0.516156
2814.72	1.33625
2817.37	3.69769
2820.02	6.84872
2822.67	11.0664
2825.32	16.1863
2827.97	22.4575
2830.62	29.4174
2833.26	35.7926
2835.91	41.9885
2838.56	49.9942
2841.2	59.453
2843.84	69.1569
2846.48	80.1947
2849.12	92.7942
2851.77	106.995
2854.4	123.417
2857.04	138.759
2859.68	154.627
2862.32	171.724
2864.95	188.933
2867.59	202.75
2870.22	217.501
2872.85	232
2875.48	245.146
2878.11	258.726
2880.74	271.053
2883.37	284.481
2886	296.408
2888.63	307.149
2891.25	318.458
2893.88	328.413
2896.5	336.774
2899.13	344.179
2901.75	353.621
2904.37	363.872
2906.99	375.761
2909.61	388.257
2912.23	402.05
2914.85	415.51
2917.46	429.581
2920.08	441.162
2922.7	450.139
2925.31	456.534
2927.92	460.334
2930.54	460.521
2933.15	455.56
2935.76	451.177
2938.37	443.796
2940.98	431.766
2943.58	419.299
2946.19	405.751
2948.8	391.759
2951.4	376.664
2954.01	358.757
2956.61	341.663
2959.21	322.416
2961.81	305.053
2964.41	289.146
2967.01	273.273
2969.61	260.128
2972.21	246.705
2974.81	233.631
2977.4	220.709
2980	205.854
2982.59	192.118
2985.18	176.899
2987.78	161.317
2990.37	144.778
2992.96	128.525
2995.55	111.97
2998.14	96.9072
3000.73	83.9376
3003.31	70.527
3005.9	58.9232
3008.48	47.9722
3011.07	39.0679
3013.65	31.2126
3016.23	22.8746
3018.81	15.8628
3021.4	11.4073
3023.97	6.70698
3026.55	3.65297
3029.13	1.32577
3031.71	-0.530645
3034.28	-0.959638
3036.86	-0.00319407
3039.43	0.251721
3042.01	2.28483
3044.58	3.90565
3047.15	6.70416
3049.72	8.54468
3052.29	10.1662
3054.86	11.9487
3057.43	14.0343
3060	15.6346
3062.56	16.935
3065.13	16.3608
3067.69	16.0734
3070.26	15.9294
3072.82	14.6273
3075.38	13.7954
3077.94	13.1391
3080.5	10.6126
3083.06	8.88525
3085.62	6.67939
3088.18	5.14801
3090.73	4.70611
3093.29	3.27811
3095.84	3.55415
3098.4	4.26022
3100.95	5.5437
3103.5	6.40747
3106.05	7.98026
3108.6	9.54879
3111.15	12.1832
3113.7	14.2411
3116.25	17.6466
3118.79	20.1549
3121.34	22.9769
3123.88	25.6
3126.43	27.128
3128.97	29.3473
3131.51	32.0487
3134.06	35.3725
3136.6	37.7356
3139.14	40.4368
3141.67	42.5397
3144.21	45.0533
3146.75	47.7631
3149.29	49.9085