File: data/Raman/poly_smoothed/Thy_20_09_49_1x_45s_532 nm_x100_100%_600 gr_mm_01.txt
#Acq. time (s)=	45
#Accumulations=	2
#Range (cm-¹)=	200...3150
#Windows=	2
#Auto scanning=	Off
#Autofocus=	Off
#Macrospot=	Off
#AutoExposure=	Off
#Spike filter=	Multiple accum.
#Delay time (s)=	0
#Binning=	1
#Readout mode=	Signal
#DeNoise=	Off
#ICS correction=	On
#Dark correction=	Off
#Inst. Process=	Off
#Detector Gain=	Best Dynamic Range
#Detector ADC=	20 kHz
#Detector temperature (°C)=	-69.85
#Instrument=	LabRAM HR Evol
#Detector=	Synapse
#Objective=	x100
#Grating=	600 gr/mm
#ND Filter=	100%
#Laser (nm)=	532
#Hole=	100.021
#Range=	Auto
#Laser Pol.=	No
#Raman. Pol.=	No
#Laser Pol. (°)=	-0.0007625
#Raman Pol. (°)=	89.9995
#Collection=	Microscope
#StageXY=	Marzhauser
#StageZ=	Marzhauser
#X (µm)=	-5936.9
#Y (µm)=	2867.1
#Z (µm)=	-223.35
#Full time(mm:ss)=	3:18
#Project=
#Sample=
#Site=
#Title=	Thy_20_09_49_2x_45s_532 nm_x100_100%_600 gr_mm
#Remark=
#Date=	29.06.2022 14:04
#Acquired=	29.06.2022 14:04:13
#Base:Fit=	10.08.2022 09:52:02
#Base:Fit=	10.08.2022 09:52:12
#Base:Sub=	10.08.2022 09:54:21
#Filter:Polynom=	16.08.2022 10:24:04
#AxisType[0]=Intens
#AxisUnit[0]=Cnt
#AxisType[1]=Spectr
#AxisUnit[1]=1/cm
200.523	21.2872
204.154	17.6536
207.781	14.7794
211.409	12.6917
215.034	10.8914
218.659	9.07279
222.281	7.4004
225.903	5.03319
229.522	5.95129
233.14	5.52792
236.756	5.75799
240.373	6.15206
243.986	7.1467
247.598	8.17387
251.208	9.49055
254.818	10.8338
258.427	9.82373
262.034	11.4477
265.638	13.4158
269.242	14.9695
272.844	15.2052
276.445	15.784
280.044	16.2118
283.642	16.3635
287.238	17.6787
290.833	17.8653
294.425	20.1408
298.017	20.2472
301.608	20.1837
305.198	20.0005
308.786	19.6155
312.371	21.1762
315.956	20.7312
319.54	22.0514
323.122	21.6179
326.701	22.6976
330.281	21.4877
333.857	20.6631
337.434	20.8982
341.008	19.5313
344.582	19.1734
348.153	17.663
351.724	16.9238
355.292	16.0747
358.861	15.1272
362.426	13.2097
365.99	12.2898
369.555	10.5089
373.116	10.1085
376.676	10.5484
380.236	10.4004
383.793	10.1437
387.349	11.4979
390.903	10.7873
394.456	11.6029
398.007	12.6493
401.56	11.3775
405.108	11.2875
408.656	11.9569
412.202	12.6214
415.746	12.5366
419.29	11.1541
422.831	11.7289
426.37	10.5633
429.909	9.71105
433.447	9.10674
436.983	8.41689
440.519	7.30279
444.052	6.17955
447.583	5.77437
451.114	4.85922
454.643	3.40771
458.169	3.0523
461.696	1.81608
465.222	1.20357
468.744	1.41292
472.267	2.34713
475.787	1.49538
479.307	0.79557
482.823	2.86502
486.341	3.69725
489.855	3.7833
493.37	6.54273
496.881	7.15531
500.391	7.95939
503.902	9.05402
507.409	10.1185
510.915	10.8938
514.42	12.2421
517.925	12.7481
521.427	13.6989
524.928	14.0972
528.427	14.283
531.925	14.6036
535.422	14.2854
538.917	12.0705
542.411	11.2752
545.903	9.96219
549.395	8.3795
552.884	8.25107
556.373	6.74331
559.86	5.46827
563.346	4.44208
566.831	4.90522
570.314	4.77056
573.794	4.07092
577.274	2.05512
580.754	2.83785
584.23	2.64928
587.706	2.59153
591.181	2.12633
594.653	2.4768
598.126	2.39697
601.595	3.47327
605.065	2.71681
608.532	1.98232
611.999	1.45539
615.463	1.08759
618.928	1.03526
622.389	0.425445
625.851	-0.0463593
629.31	1.33523
632.767	0.151647
636.223	2.51381
639.68	3.41268
643.134	3.46036
646.586	5.01572
650.037	6.81196
653.486	8.61026
656.936	9.81321
660.383	12.7073
663.829	14.4204
667.273	17.3704
670.716	17.7526
674.158	19.2007
677.598	21.7376
681.035	23.6468
684.473	24.8964
687.909	25.7271
691.344	26.1998
694.778	26.69
698.211	26.5348
701.64	26.8633
705.07	28.2847
708.498	28.7543
711.924	31.0721
715.35	30.9128
718.774	33.2433
722.196	35.2028
725.618	36.6332
729.037	37.9649
732.456	38.0951
735.873	38.005
739.289	39.2236
742.703	40.6801
746.116	40.9126
749.529	42.3814
752.938	43.3763
756.347	43.8064
759.756	46.8498
763.162	47.8561
766.567	49.8682
769.97	51.0066
773.372	52.2914
776.773	53.2426
780.174	53.7184
783.573	55.1819
786.97	57.3625
790.365	58.8604
793.76	60.8973
797.153	61.9748
800.543	63.1791
803.933	64.9851
807.322	64.6691
810.71	64.6731
814.097	63.8822
817.483	64.1663
820.865	64.6144
824.248	63.7632
827.629	62.3431
831.008	61.5036
834.387	61.5369
837.765	59.1397
841.139	57.4508
844.514	56.7056
847.886	54.739
851.259	53.6983
854.629	51.8662
857.997	49.4233
861.366	47.4355
864.732	45.0972
868.098	42.3921
871.461	42.3827
874.823	40.9068
878.184	40.0165
881.545	38.739
884.903	39.4767
888.26	39.7189
891.616	39.415
894.97	39.5416
898.323	39.0404
901.675	40.1464
905.026	40.4203
908.375	38.8614
911.723	39.1623
915.07	39.0157
918.415	38.7239
921.76	38.1605
925.103	38.1293
928.443	37.9941
931.783	37.86
935.123	37.6964
938.461	35.2798
941.796	33.6545
945.131	32.577
948.465	31.5445
951.797	30.2131
955.128	29.9333
958.457	28.7842
961.786	28.7983
965.113	27.6125
968.44	28.0133
971.763	27.2705
975.086	26.3016
978.409	24.4234
981.729	23.9275
985.048	24.3784
988.367	23.1956
991.683	20.8564
994.998	20.6268
998.312	20.5049
1001.62	19.6947
1004.94	19.0483
1008.25	19.3107
1011.56	19.1791
1014.86	16.8052
1018.17	16.5238
1021.48	15.8879
1024.78	15.7681
1028.08	15.0709
1031.38	13.7811
1034.68	12.4579
1037.98	12.5513
1041.28	11.7753
1044.57	13.8384
1047.87	13.3823
1051.16	12.3059
1054.45	12.705
1057.75	12.035
1061.04	12.1993
1064.32	12.8841
1067.61	12.274
1070.9	10.6594
1074.18	10.3758
1077.47	10.5134
1080.75	10.2524
1084.03	7.95413
1087.31	9.72322
1090.59	10.0528
1093.86	10.2606
1097.14	10.728
1100.41	12.6004
1103.69	13.6408
1106.96	13.589
1110.23	13.3328
1113.5	13.6187
1116.77	13.5725
1120.03	13.2042
1123.3	12.9921
1126.56	12.0674
1129.83	11.3418
1133.09	11.6137
1136.35	10.9401
1139.61	9.54217
1142.86	8.2516
1146.12	6.95307
1149.38	5.72496
1152.63	5.2342
1155.88	4.29459
1159.14	3.34088
1162.39	3.57962
1165.63	4.89643
1168.88	6.43533
1172.13	7.16833
1175.38	8.21382
1178.62	8.8023
1181.86	9.70001
1185.1	9.30884
1188.34	10.2935
1191.58	10.318
1194.82	10.3455
1198.06	10.7715
1201.29	11.3747
1204.53	13.1306
1207.76	13.7139
1210.99	14.4549
1214.22	16.114
1217.45	18.3508
1220.68	19.7328
1223.91	21.8718
1227.13	25.0174
1230.36	26.2184
1233.58	27.4213
1236.8	28.4209
1240.02	29.9351
1243.24	32.6986
1246.46	33.9029
1249.67	34.6054
1252.89	35.475
1256.1	35.9633
1259.32	37.0504
1262.53	37.9119
1265.74	39.726
1268.95	40.2784
1272.15	41.1269
1275.36	43.0193
1278.57	44.056
1281.77	44.9929
1284.97	46.7293
1288.18	47.9188
1291.38	49.6155
1294.58	51.4717
1297.78	51.3834
1300.97	53.017
1304.17	54.2155
1307.36	54.3687
1310.55	53.7074
1313.75	53.5163
1316.94	53.6166
1320.13	54.0618
1323.32	54.7145
1326.5	52.601
1329.69	51.2835
1332.87	50.562
1336.06	49.8994
1339.24	48.2695
1342.42	47.3342
1345.6	46.1553
1348.78	44.8029
1351.96	42.6745
1355.13	41.2695
1358.31	40.4761
1361.48	39.073
1364.65	37.0327
1367.82	35.4996
1370.99	34.0826
1374.16	34.3402
1377.33	33.7366
1380.5	33.6999
1383.66	33.2769
1386.83	33.4696
1389.99	33.2142
1393.15	33.6475
1396.31	34.5206
1399.47	35.0045
1402.63	32.9165
1405.78	32.5358
1408.94	32.9573
1412.1	34.4854
1415.25	36.3038
1418.4	38.63
1421.55	40.0973
1424.7	42.85
1427.85	46.2553
1431	49.6126
1434.14	52.392
1437.29	54.9983
1440.43	56.2023
1443.57	59.0364
1446.71	59.7413
1449.85	61.0117
1452.99	61.1619
1456.13	59.2066
1459.26	56.8485
1462.4	55.8649
1465.54	53.372
1468.67	50.6711
1471.8	48.0294
1474.93	43.4678
1478.06	39.1214
1481.19	34.0913
1484.31	30.8247
1487.44	28.6013
1490.56	27.09
1493.69	23.9509
1496.81	22.6974
1499.93	22.1784
1503.05	23.0562
1506.17	23.5844
1509.28	24.0444
1512.4	24.0818
1515.52	24.002
1518.63	24.0463
1521.74	25.142
1524.85	25.3158
1527.96	25.6646
1531.07	26.5753
1534.18	27.7156
1537.29	30.4055
1540.39	34.4642
1543.5	35.9442
1546.6	38.3443
1549.7	40.1903
1552.8	41.6181
1555.9	42.8088
1559	45.2871
1562.1	47.7754
1565.19	50.0972
1568.29	49.8666
1571.38	51.7703
1574.47	54.6782
1577.56	57.2174
1580.66	58.1888
1583.74	59.1421
1586.83	58.9591
1589.92	59.1762
1593.01	58.4775
1596.09	58.8153
1599.17	57.0278
1602.25	57.3104
1605.34	55.8351
1608.41	54.528
1611.49	53.4256
1614.57	52.5444
1617.65	51.0133
1620.72	50.7656
1623.79	50.2114
1626.87	49.6371
1629.94	48.583
1633.01	49.0192
1636.08	48.7153
1639.15	48.7197
1642.21	48.5787
1645.28	50.7894
1648.34	51.8429
1651.41	51.3346
1654.47	52.3051
1657.53	51.6325
1660.59	50.3537
1663.65	49.6912
1666.71	47.8893
1669.76	45.9256
1672.82	43.7079
1675.87	40.6703
1678.93	37.4645
1681.98	33.9353
1685.03	31.6295
1688.08	28.3067
1691.13	24.5344
1694.17	20.9807
1697.22	18.7399
1700.27	15.3429
1703.31	12.9011
1706.35	10.3346
1709.39	8.35135
1712.43	7.64673
1715.47	7.33775
1718.51	6.00247
1721.55	5.88292
1724.58	5.18037
1727.62	6.38247
1730.65	6.44448
1733.68	6.95391
1736.72	6.85868
1739.74	7.43267
1742.77	6.76235
1745.8	6.25172
1748.83	6.28816
1751.85	6.52864
1754.88	6.68779
1757.9	6.83923
1760.92	6.77578
1763.95	4.86995
1766.96	4.15333
1769.98	3.24406
1773	4.13938
1776.02	4.06542
1779.03	3.77316
1782.05	4.23027
1785.06	5.2041
1788.07	6.18988
1791.08	6.15941
1794.09	6.6212
1797.1	7.20897
1800.11	6.97699
1803.12	7.30565
1806.12	8.03673
1809.12	7.82177
1812.13	7.72697
1815.13	6.90306
1818.13	7.04726
1821.13	6.60112
1824.13	7.16735
1827.13	6.82917
1830.12	6.1468
1833.12	5.6647
1836.11	4.55417
1839.1	4.2236
1842.09	3.63418
1845.09	3.3697
1848.08	3.72125
1851.06	3.3639
1854.05	3.1217
1857.04	2.78177
1860.02	2.6132
1863.01	2.14622
1865.99	2.3609
1868.97	2.23648
1871.95	2.78745
1874.93	2.08649
1877.91	2.81467
1880.89	3.12525
1882.46	4.30233
1885.45	4.45192
1888.43	5.30294
1891.42	6.64903
1894.41	6.76932
1897.39	6.18283
1900.37	6.57422
1903.36	6.24017
1906.34	7.31845
1909.32	6.97833
1912.29	6.33859
1915.27	6.59149
1918.25	6.05533
1921.23	6.15411
1924.2	5.4959
1927.17	4.38259
1930.15	3.3836
1933.12	3.41618
1936.09	2.8803
1939.06	2.44973
1942.02	2.62684
1944.99	1.82315
1947.96	0.750457
1950.92	1.89202
1953.88	2.28206
1956.85	3.48634
1959.81	3.55923
1962.77	2.57496
1965.73	2.1185
1968.69	1.79832
1971.64	1.50023
1974.6	2.09829
1977.55	2.42023
1980.51	2.90037
1983.46	2.18244
1986.41	2.83847
1989.36	3.7195
1992.31	3.38295
1995.26	3.82786
1998.21	4.24499
2001.15	5.11111
2004.1	6.0855
2007.04	6.44694
2009.99	5.89392
2012.93	6.46743
2015.87	6.43781
2018.81	6.38129
2021.75	7.23639
2024.68	8.41153
2027.62	9.1638
2030.56	9.03619
2033.49	8.5199
2036.42	8.54091
2039.36	9.19363
2042.29	9.27982
2045.22	8.82337
2048.14	9.57182
2051.07	9.9687
2054	10.2652
2056.93	11.1214
2059.85	11.4185
2062.77	11.684
2065.7	11.2615
2068.62	11.4093
2071.54	11.6321
2074.46	10.7777
2077.38	9.48337
2080.29	8.271
2083.21	7.18916
2086.12	6.64988
2089.04	7.00548
2091.95	6.47147
2094.86	6.29417
2097.77	6.09389
2100.68	5.98715
2103.59	6.40398
2106.5	6.22867
2109.41	6.35802
2112.31	7.37334
2115.21	7.07675
2118.12	8.14374
2121.02	9.22414
2123.92	10.0033
2126.82	11.2263
2129.72	12.1074
2132.62	12.9614
2135.51	14.539
2138.41	15.7424
2141.31	18.0006
2144.2	19.244
2147.09	20.7724
2149.98	21.9142
2152.87	22.7697
2155.76	23.2196
2158.65	23.7776
2161.54	24.6613
2164.43	25.9088
2167.31	26.5764
2170.2	26.2766
2173.08	26.0413
2175.96	26.9333
2178.84	26.0268
2181.72	25.2792
2184.6	24.2118
2187.48	23.7486
2190.36	22.9203
2193.23	21.5448
2196.11	20.3022
2198.98	19.7212
2201.85	18.9349
2204.72	18.0391
2207.59	17.5362
2210.46	16.8508
2213.33	16.2968
2216.2	15.3138
2219.07	14.6379
2221.93	13.8769
2224.8	13.3183
2227.66	12.958
2230.52	12.7556
2233.39	12.6772
2236.25	11.4706
2239.1	10.2915
2241.96	9.53036
2244.82	10.3204
2247.68	10.1009
2250.53	9.58108
2253.38	10.1991
2256.24	10.2324
2259.09	9.90564
2261.94	9.50706
2264.79	9.02102
2267.64	9.14814
2270.49	9.18773
2273.33	8.64029
2276.18	8.92594
2279.02	9.40807
2281.87	9.71822
2284.71	9.55394
2287.55	8.85637
2290.39	7.04111
2293.23	5.71233
2296.07	5.95861
2298.91	6.06372
2301.74	6.07856
2304.58	6.00478
2307.41	5.25054
2310.25	5.23335
2313.08	5.11661
2315.91	5.13097
2318.74	4.32528
2321.57	4.73585
2324.4	4.49906
2327.23	3.86118
2330.05	3.20788
2332.88	3.42787
2335.7	3.13081
2338.52	3.21693
2341.35	3.36586
2344.17	2.61432
2346.99	2.48605
2349.81	1.62739
2352.62	0.54474
2355.44	0.258734
2358.26	-1.10446
2361.07	-1.05736
2363.89	-0.568403
2366.7	1.44177
2369.51	0.877373
2372.32	0.592394
2375.13	0.944789
2377.94	0.987288
2380.75	1.34952
2383.56	1.89645
2386.36	2.04019
2389.17	1.95632
2391.97	2.16685
2394.77	2.13667
2397.58	2.11937
2400.38	2.92702
2403.18	3.58675
2405.97	4.39068
2408.77	5.05826
2411.57	4.52205
2414.37	4.40526
2417.16	5.05284
2419.95	4.89593
2422.75	5.80247
2425.54	6.21676
2428.33	5.96764
2431.12	5.25466
2433.91	4.56523
2436.7	5.25533
2439.48	4.88551
2442.27	4.84514
2445.05	4.28596
2447.84	4.94476
2450.62	4.89523
2453.4	4.07288
2456.18	3.79995
2458.96	3.05833
2461.74	2.95623
2464.52	2.96982
2467.29	3.18349
2470.07	3.62389
2472.85	3.16626
2475.62	2.03705
2478.39	1.43551
2481.16	1.11152
2483.93	2.14379
2486.7	2.78401
2489.47	2.49795
2492.24	2.48905
2495.01	2.6826
2497.77	2.78896
2500.54	2.51038
2503.3	3.45187
2506.06	3.84523
2508.83	4.27901
2511.59	4.22353
2514.35	5.02734
2517.11	5.51452
2519.86	5.62855
2522.62	5.81754
2525.38	6.37958
2528.13	6.64087
2530.89	7.06982
2533.64	6.26761
2536.39	6.71057
2539.14	5.69348
2541.89	5.83929
2544.64	5.96336
2547.39	5.15784
2550.14	5.3306
2552.88	5.24112
2555.63	3.8897
2558.37	3.67986
2561.11	3.04851
2563.86	2.92982
2566.6	1.6897
2569.34	1.59713
2572.08	0.590253
2574.82	0.955501
2577.55	0.95093
2580.29	0.51686
2583.02	0.536806
2585.76	0.248754
2588.49	0.1995
2591.22	0.714241
2593.96	1.24794
2596.69	1.13528
2599.42	1.43294
2602.14	1.20289
2604.87	1.68164
2607.6	2.04467
2610.32	2.57674
2613.05	1.55198
2615.77	1.49727
2618.49	1.22105
2621.22	0.984611
2623.94	0.786047
2626.66	0.478794
2629.37	1.28209
2632.09	1.58809
2634.81	2.3458
2637.53	2.93285
2640.24	3.41926
2642.96	3.96328
2645.67	3.75465
2648.38	3.81771
2651.09	3.51149
2653.8	3.27262
2656.51	3.32904
2659.22	3.60791
2661.93	3.57596
2664.63	3.76329
2667.34	4.14431
2670.04	3.92426
2672.75	3.64768
2675.45	4.44869
2678.15	3.8422
2680.85	3.40502
2683.55	3.39549
2686.25	3.51271
2688.94	3.92505
2691.64	4.51519
2694.34	5.34919
2697.03	5.41859
2699.73	5.45713
2702.42	5.81438
2705.11	5.2956
2707.8	5.2981
2710.49	4.45897
2713.18	4.22453
2715.87	3.92158
2718.55	3.90297
2721.24	4.31649
2723.93	4.19223
2726.61	4.59176
2729.29	5.29978
2731.98	5.38103
2734.66	5.4341
2737.34	5.03665
2740.02	5.48127
2742.7	5.20808
2745.37	5.06684
2748.05	5.0281
2750.72	5.13658
2753.4	4.55028
2756.07	4.77352
2758.75	4.00331
2761.42	3.72211
2764.09	2.69573
2766.76	1.91498
2769.43	1.19207
2772.1	1.02577
2774.76	2.09379
2777.43	2.09424
2780.1	2.64359
2782.76	2.4793
2785.42	2.96562
2788.09	3.28474
2790.75	3.18327
2793.41	2.76022
2796.07	1.58724
2798.73	2.63546
2801.39	1.86755
2804.04	1.50315
2806.7	1.07296
2809.35	0.578579
2812.01	0.786138
2814.66	0.837661
2817.31	1.68415
2819.96	1.9794
2822.61	3.32169
2825.26	3.96922
2827.91	5.41686
2830.56	6.28709
2833.21	9.15721
2835.85	11.5067
2838.5	13.389
2841.14	15.6992
2843.78	18.7017
2846.42	22.627
2849.06	26.2662
2851.71	30.1796
2854.34	33.9248
2856.98	37.4431
2859.62	41.2313
2862.26	44.8823
2864.89	49.048
2867.53	51.3355
2870.16	53.9208
2872.79	56.486
2875.42	59.6431
2878.05	62.3475
2880.68	64.9778
2883.31	67.0659
2885.94	68.591
2888.57	70.642
2891.19	73.1566
2893.82	74.2898
2896.44	76.5727
2899.07	79.5898
2901.69	81.702
2904.31	84.9997
2906.93	89.4758
2909.55	94.5411
2912.17	98.5151
2914.79	103.037
2917.41	107.185
2920.02	110.875
2922.64	113.193
2925.25	115.824
2927.86	117.712
2930.48	118.283
2933.09	118.242
2935.7	117.449
2938.31	116.362
2940.92	114.265
2943.53	111.784
2946.13	109.478
2948.74	105.686
2951.34	102.815
2953.95	99
2956.55	95.2622
2959.15	91.2004
2961.75	87.6077
2964.35	84.2053
2966.95	80.5249
2969.55	77.0208
2972.15	73.4628
2974.75	69.7383
2977.34	66.1856
2979.94	62.6735
2982.53	58.0592
2985.13	52.9478
2987.72	48.4958
2990.31	43.8369
2992.9	39.106
2995.49	34.7798
2998.08	30.8352
3000.67	26.6869
3003.25	23.0241
3005.84	20.5645
3008.42	18.4237
3011.01	15.702
3013.59	13.9108
3016.17	12.3639
3018.76	10.9143
3021.34	10.9066
3023.92	9.70342
3026.49	9.74267
3029.07	9.26326
3031.65	9.12271
3034.23	9.51968
3036.8	10.9522
3039.38	11.1782
3041.95	11.9074
3044.52	11.8441
3047.09	12.181
3049.66	12.4544
3052.23	11.7356
3054.8	11.7644
3057.37	11.9088
3059.94	11.9792
3062.5	10.8063
3065.07	9.57253
3067.63	8.418
3070.2	7.91303
3072.76	6.50028
3075.32	5.97221
3077.88	4.58526
3080.44	3.39786
3083	2.47821
3085.56	0.756115
3088.12	0.146007
3090.67	-0.0579017
3093.23	-0.310067
3095.78	0.403743
3098.34	0.159673
3100.89	0.342556
3103.44	0.863407
3105.99	1.62829
3108.54	2.02728
3111.09	2.90191
3113.64	2.87531
3116.19	3.92832
3118.74	4.1335
3121.28	4.69234
3123.83	5.12807
3126.37	5.78484
3128.91	6.09112
3131.46	7.32314
3134	7.82893
3136.54	8.66065
3139.08	9.33396
3141.62	10.0789
3144.16	11.4378
3146.69	12.9873
3149.23	15.1009