File: data/Raman/poly_smoothed/Thy_00_07_8_1x_45s_532 nm_x100_100%_600 gr_mm_01.txt
#Acq. time (s)=	45
#Accumulations=	2
#Range (cm-¹)=	200...3150
#Windows=	2
#Auto scanning=	Off
#Autofocus=	Off
#Macrospot=	Off
#AutoExposure=	Off
#Spike filter=	Multiple accum.
#Delay time (s)=	0
#Binning=	1
#Readout mode=	Signal
#DeNoise=	Off
#ICS correction=	On
#Dark correction=	Off
#Inst. Process=	Off
#Detector Gain=	Best Dynamic Range
#Detector ADC=	20 kHz
#Detector temperature (°C)=	-69.85
#Instrument=	LabRAM HR Evol
#Detector=	Synapse
#Objective=	x100
#Grating=	600 gr/mm
#ND Filter=	100%
#Laser (nm)=	532
#Hole=	100.021
#Range=	Auto
#Laser Pol.=	No
#Raman. Pol.=	No
#Laser Pol. (°)=	-0.0007625
#Raman Pol. (°)=	89.9995
#Collection=	Microscope
#StageXY=	Marzhauser
#StageZ=	Marzhauser
#X (µm)=	8993.5
#Y (µm)=	-3097.1
#Z (µm)=	-54.9
#Full time(mm:ss)=	3:05
#Project=
#Sample=
#Site=
#Title=	Thy_00_07_8_2x_45s_532 nm_x100_100%_600 gr_mm
#Remark=
#Date=	28.06.2022 10:35
#Acquired=	28.06.2022 10:35:23
#Base:Fit=	10.08.2022 10:07:56
#Base:Sub=	10.08.2022 10:08:40
#Filter:Polynom=	16.08.2022 10:26:06
#AxisType[0]=Intens
#AxisUnit[0]=Cnt
#AxisType[1]=Spectr
#AxisUnit[1]=1/cm
200.407	-2.31107
204.035	2.8489
207.665	7.04607
211.291	10.1745
214.916	11.4916
218.541	11.9388
222.163	14.6895
225.785	14.8131
229.404	14.7363
233.022	12.8902
236.638	11.768
240.255	11.2892
243.868	10.5259
247.48	10.6674
251.091	9.25897
254.702	8.87638
258.31	7.07046
261.916	5.87247
265.521	3.58284
269.125	1.79854
272.727	1.49002
276.328	2.15158
279.927	2.72205
283.525	4.38681
287.121	5.64929
290.716	7.87425
294.31	9.73149
297.9	12.0473
301.491	15.7197
305.081	17.5192
308.669	21.1489
312.256	24.8848
315.839	25.6513
319.423	26.9678
323.006	27.7636
326.585	30.2519
330.165	30.4556
333.741	29.1975
337.318	27.8272
340.894	27.5799
344.466	25.1912
348.039	23.5825
351.608	24.7365
355.176	25.5972
358.745	28.8753
362.31	30.1074
365.876	31.1278
369.439	32.9928
373	36.4024
376.56	38.0728
380.12	41.6247
383.677	43.9454
387.233	45.9322
390.787	44.5615
394.34	43.3735
397.894	43.3504
401.444	41.5433
404.993	37.8829
408.54	35.8067
412.086	34.1832
415.631	28.1775
419.174	22.8679
422.716	18.9694
426.257	16.505
429.794	13.6391
433.332	10.1451
436.868	9.03836
440.403	8.03814
443.937	9.14846
447.468	11.0759
450.999	14.7466
454.528	18.3601
458.057	21.3517
461.582	24.9012
465.107	29.5084
468.629	31.7552
472.152	32.0123
475.672	33.5239
479.192	35.4531
482.709	37.6351
486.226	39.9486
489.74	42.335
493.255	44.1913
496.767	47.745
500.277	49.003
503.788	48.4366
507.295	48.8575
510.801	47.7069
514.308	46.0556
517.811	43.3742
521.313	40.8979
524.814	39.647
528.313	38.8054
531.811	39.2967
535.308	36.2356
538.803	34.3419
542.297	33.0098
545.789	29.4922
549.281	26.6629
552.771	23.624
556.259	19.1813
559.747	17.0351
563.233	14.3762
566.717	12.3695
570.2	10.9585
573.68	9.81439
577.161	9.81869
580.64	9.69531
584.118	9.72257
587.593	9.8426
591.068	8.66149
594.54	9.29967
598.013	9.05777
601.484	8.53735
604.952	10.4137
608.421	9.49136
611.886	9.81882
615.35	10.4488
618.815	10.1858
622.276	8.2931
625.738	8.43553
629.197	9.62949
632.655	8.46513
636.113	9.15532
639.568	9.2139
643.021	7.49191
646.473	9.38434
649.924	8.39275
653.376	7.80761
656.824	8.47583
660.271	8.07231
663.716	8.88819
667.161	8.84395
670.604	9.19207
674.045	10.7216
677.486	11.7163
680.925	13.3242
684.361	14.3576
687.797	15.9166
691.232	18.6878
694.666	18.1433
698.099	17.3388
701.528	16.1748
704.958	16.1611
708.387	15.5251
711.814	17.101
715.238	18.3045
718.663	18.7999
722.084	21.1118
725.506	21.0167
728.925	22.7768
732.345	26.5421
735.761	29.5679
739.178	36.1511
742.592	43.0075
746.006	51.7609
749.417	58.9346
752.827	66.1761
756.236	73.4497
759.645	79.2641
763.051	84.8733
766.456	89.6353
769.859	91.3566
773.261	93.3274
776.664	94.3372
780.064	91.4288
783.462	88.4021
786.859	85.5296
790.255	81.9709
793.649	77.1309
797.042	72.5947
800.434	68.5155
803.823	63.9685
807.212	59.1273
810.6	55.6971
813.987	54.8802
817.372	54.9101
820.754	56.2835
824.137	58.4163
827.519	60.2882
830.897	61.018
834.276	60.6821
837.654	61.1795
841.029	60.4722
844.404	60.6508
847.776	59.2873
851.149	57.3256
854.519	55.2851
857.889	54.0816
861.256	50.4621
864.622	47.0898
867.988	44.9083
871.351	41.8638
874.713	37.0468
878.074	33.8356
881.435	31.2202
884.794	29.3265
888.15	26.9993
891.506	25.0627
894.861	25.4296
898.214	26.8492
901.566	28.1306
904.916	30.1884
908.266	31.6043
911.614	34.719
914.961	38.0068
918.306	38.7579
921.651	40.6469
924.994	40.8243
928.336	41.1877
931.674	40.6439
935.014	39.3185
938.352	38.3395
941.687	36.0678
945.022	35.5012
948.357	32.4485
951.688	29.6516
955.02	26.4355
958.348	20.8481
961.678	15.2836
965.004	14.0409
968.331	14.2947
971.655	11.9957
974.979	11.9763
978.3	12.7233
981.62	12.4553
984.941	11.0036
988.259	9.90573
991.575	11.0459
994.89	13.2927
998.204	16.2279
1001.52	20.159
1004.83	24.5397
1008.14	29.604
1011.45	34.4321
1014.76	39.5736
1018.06	43.819
1021.37	46.3301
1024.67	47.0773
1027.97	48.0782
1031.27	47.8462
1034.57	45.1958
1037.87	40.5855
1041.17	36.5403
1044.47	35.542
1047.76	35.7318
1051.06	33.5321
1054.35	29.941
1057.64	27.1586
1060.93	25.1722
1064.22	23.9076
1067.5	21.5171
1070.79	22.6918
1074.08	26.3852
1077.36	29.109
1080.64	33.6744
1083.92	35.3155
1087.2	36.7143
1090.48	38.641
1093.76	39.5277
1097.03	39.5577
1100.31	38.5846
1103.58	38.2862
1106.85	37.7772
1110.12	34.6193
1113.39	29.9453
1116.66	26.1779
1119.93	21.9714
1123.19	20.0927
1126.46	18.1202
1129.72	17.721
1132.98	15.39
1136.24	15.1529
1139.5	14.4987
1142.76	14.2183
1146.01	12.6088
1149.27	11.0159
1152.53	10.048
1155.78	8.5739
1159.03	6.53216
1162.28	3.72908
1165.53	1.19954
1168.78	0.352098
1172.02	0.731565
1175.27	0.654244
1178.51	0.937727
1181.76	2.9052
1185	2.81116
1188.24	4.61057
1191.48	4.74867
1194.71	6.80266
1197.95	9.25926
1201.19	11.8442
1204.42	15.507
1207.65	19.2344
1210.88	22.9465
1214.12	25.8813
1217.35	28.6506
1220.57	32.1464
1223.8	34.9555
1227.03	38.6385
1230.25	40.7193
1233.47	41.4102
1236.69	41.991
1239.92	43.015
1243.13	44.3161
1246.35	43.336
1249.57	43.0361
1252.78	42.3022
1256	40.4048
1259.21	39.7173
1262.42	39.3828
1265.63	38.2518
1268.84	37.7974
1272.05	37.111
1275.26	37.464
1278.46	39.4594
1281.67	40.8766
1284.87	43.5656
1288.07	47.1379
1291.27	47.3526
1294.47	51.5201
1297.67	54.3967
1300.87	56.8451
1304.06	60.7369
1307.26	63.6616
1310.45	66.5999
1313.64	69.8613
1316.83	72.6024
1320.02	75.1956
1323.21	76.1268
1326.4	76.2365
1329.59	76.5329
1332.77	75.658
1335.95	74.976
1339.14	74.6902
1342.32	73.0378
1345.5	70.1321
1348.67	68.2138
1351.85	65.8128
1355.03	64.0592
1358.2	63.5177
1361.38	61.2557
1364.55	60.548
1367.72	57.8906
1370.89	55.7054
1374.06	53.3486
1377.23	51.8066
1380.39	51.8804
1383.56	50.5726
1386.72	48.5463
1389.89	48.6942
1393.05	48.6738
1396.21	49.3457
1399.37	49.5805
1402.52	48.8258
1405.68	47.9581
1408.84	47.7842
1411.99	49.8169
1415.15	52.7757
1418.3	55.5158
1421.45	59.857
1424.6	65.0906
1427.75	72.1721
1430.89	78.1993
1434.04	83.8543
1437.18	89.7308
1440.33	93.1749
1443.47	96.0174
1446.61	98.635
1449.75	99.9247
1452.89	98.5966
1456.03	97.7088
1459.16	95.0545
1462.3	90.2481
1465.43	85.0677
1468.56	80.2481
1471.7	72.6386
1474.83	64.7592
1477.96	57.0022
1481.08	48.9813
1484.21	40.1931
1487.34	35.0508
1490.46	28.9551
1493.58	24.3956
1496.71	22.0242
1499.83	19.7706
1502.95	18.8212
1506.07	16.668
1509.18	14.1524
1512.3	14.1177
1515.41	12.8235
1518.53	13.4557
1521.64	14.8697
1524.75	16.6858
1527.86	18.3788
1530.97	21.2248
1534.08	24.0042
1537.19	25.4698
1540.29	27.4596
1543.4	29.5966
1546.5	32.4956
1549.6	35.1608
1552.7	38.8464
1555.8	43.4255
1558.9	46.4073
1562	49.5815
1565.09	53.0401
1568.19	55.8556
1571.28	58.8855
1574.37	61.1009
1577.47	64.2666
1580.56	67.4327
1583.64	69.6554
1586.73	71.9073
1589.82	73.6307
1592.9	74.8827
1595.99	76.2648
1599.07	76.7761
1602.15	76.4831
1605.23	76.6008
1608.31	73.5941
1611.39	71.1907
1614.47	67.6705
1617.55	66.7801
1620.62	64.2584
1623.7	62.4215
1626.77	61.7477
1629.84	62.2279
1632.91	61.2334
1635.98	60.6974
1639.05	61.8023
1642.11	62.2682
1645.18	63.4905
1648.24	65.1984
1651.31	67.1187
1654.37	68.724
1657.43	69.483
1660.49	67.9851
1663.55	68.3337
1666.61	67.5901
1669.66	65.9943
1672.72	63.9273
1675.77	60.7371
1678.83	55.7254
1681.88	50.9527
1684.93	46.3263
1687.98	41.077
1691.03	36.2355
1694.07	32.2083
1697.12	26.9601
1700.17	22.9525
1703.21	20.283
1706.25	18.529
1709.29	16.0663
1712.33	14.3617
1715.37	11.6201
1718.41	10.3165
1721.45	9.91774
1724.49	8.66591
1727.52	8.51256
1730.55	7.82862
1733.59	7.47566
1736.62	7.32304
1739.65	7.72589
1742.68	8.46134
1745.7	7.71806
1748.73	5.84627
1751.76	4.46696
1754.78	4.93544
1757.8	5.49595
1760.83	4.64775
1763.85	3.37544
1766.87	2.72807
1769.89	2.71905
1772.9	2.20095
1775.92	2.62747
1778.94	2.75402
1781.95	2.44397
1784.96	1.8854
1787.97	2.17286
1790.99	2.01468
1794	3.39676
1797	2.90538
1800.01	2.59409
1803.02	1.38729
1806.02	1.53601
1809.03	1.59665
1812.03	1.47183
1815.03	2.24763
1818.03	2.96461
1821.03	3.54444
1824.03	3.42218
1827.03	3.63401
1830.02	3.48294
1833.02	2.8954
1836.01	2.30696
1839.01	3.61805
1842	4.2212
1844.99	3.71701
1847.98	3.94102
1850.97	3.1281
1853.95	3.74726
1856.94	5.05462
1859.93	6.21305
1862.91	6.21653
1865.89	5.47389
1868.87	5.26374
1871.85	5.27273
1874.83	5.58184
1877.81	5.72733
1880.79	4.87522
1882.52	4.347
1885.51	5.17562
1888.5	5.64572
1891.49	5.19361
1894.47	4.07513
1897.46	3.5207
1900.44	2.89652
1903.42	2.47725
1906.4	2.31641
1909.38	3.4509
1912.36	4.54179
1915.34	4.35723
1918.32	4.82497
1921.29	5.15463
1924.27	6.09496
1927.24	6.64233
1930.21	6.39643
1933.18	6.70543
1936.15	6.55535
1939.12	6.45765
1942.09	6.64103
1945.06	6.98941
1948.02	7.15915
1950.99	6.19754
1953.95	5.06326
1956.91	5.02557
1959.88	4.64896
1962.84	4.41197
1965.8	4.25554
1968.75	4.31633
1971.71	4.60253
1974.67	4.61204
1977.62	4.54049
1980.58	4.35121
1983.53	5.56661
1986.48	6.71053
1989.43	7.02845
1992.38	7.18355
1995.33	8.03807
1998.27	8.28782
2001.22	9.02185
2004.16	8.34189
2007.11	9.28961
2010.05	8.67724
2012.99	8.14062
2015.93	8.01766
2018.87	7.54078
2021.81	6.40769
2024.75	4.77
2027.69	4.51114
2030.62	3.63183
2033.56	3.06125
2036.49	2.39256
2039.42	1.61298
2042.35	1.91671
2045.28	0.374528
2048.21	-0.224093
2051.14	-1.25683
2054.07	-1.25491
2056.99	-0.376788
2059.92	0.499577
2062.84	1.43514
2065.76	3.07223
2068.68	3.68161
2071.6	5.19
2074.52	5.02544
2077.44	4.98091
2080.36	6.32965
2083.27	6.44612
2086.19	6.77837
2089.1	6.76535
2092.02	6.10881
2094.93	5.52295
2097.84	4.63033
2100.75	4.99415
2103.66	4.1502
2106.56	3.75427
2109.47	3.8734
2112.38	2.3963
2115.28	1.0547
2118.18	0.367682
2121.09	0.300589
2123.99	-0.310962
2126.89	0.722657
2129.79	0.242599
2132.68	1.33108
2135.58	2.99607
2138.48	3.52479
2141.37	3.30612
2144.27	3.30949
2147.16	4.23796
2150.05	4.43469
2152.94	4.37121
2155.83	4.3693
2158.72	4.77414
2161.6	3.83743
2164.49	3.81023
2167.38	4.48579
2170.26	5.03489
2173.14	5.92556
2176.03	5.54177
2178.91	5.66448
2181.79	4.04139
2184.67	3.75205
2187.54	4.22158
2190.42	3.37268
2193.3	3.46376
2196.17	3.35952
2199.05	3.72578
2201.92	4.17908
2204.79	4.27369
2207.66	3.76367
2210.53	3.90385
2213.4	3.44622
2216.27	2.89177
2219.13	2.91265
2222	3.19985
2224.86	3.00388
2227.72	4.58731
2230.59	4.88849
2233.45	5.54748
2236.31	5.69012
2239.17	6.11927
2242.03	5.98712
2244.88	6.03714
2247.74	6.77405
2250.59	6.67563
2253.45	6.98947
2256.3	7.89345
2259.15	8.10367
2262	8.87554
2264.85	8.32599
2267.7	7.04846
2270.55	7.32719
2273.4	8.33292
2276.24	7.10904
2279.09	6.93467
2281.93	6.28048
2284.77	5.47901
2287.62	5.27341
2290.46	5.36628
2293.3	4.71803
2296.13	4.66835
2298.97	5.94013
2301.81	4.89757
2304.64	4.83295
2307.48	5.50103
2310.31	5.54199
2313.14	6.51424
2315.98	7.69113
2318.81	8.07675
2321.64	8.31967
2324.46	8.77955
2327.29	8.78513
2330.12	8.35246
2332.94	6.88288
2335.77	6.14559
2338.59	7.20133
2341.41	7.17643
2344.23	6.1446
2347.05	6.40405
2349.87	5.35121
2352.69	5.88997
2355.51	5.26596
2358.32	4.52176
2361.14	4.43014
2363.95	4.58119
2366.76	5.1408
2369.58	4.75317
2372.39	4.68577
2375.2	4.83818
2378	4.73924
2380.81	4.94733
2383.62	4.93968
2386.43	5.46559
2389.23	5.26094
2392.03	4.94135
2394.84	5.12386
2397.64	4.1227
2400.44	4.44192
2403.24	4.46409
2406.04	4.07861
2408.84	4.7037
2411.63	4.47362
2414.43	5.23238
2417.22	5.49366
2420.02	5.26337
2422.81	5.03893
2425.6	4.00013
2428.39	4.17973
2431.18	4.84999
2433.97	5.71334
2436.76	6.19375
2439.54	6.41135
2442.33	6.71902
2445.12	5.68866
2447.9	6.61581
2450.68	7.2183
2453.46	7.28676
2456.24	7.48039
2459.02	7.01955
2461.8	7.33499
2464.58	6.67436
2467.36	5.94021
2470.13	6.3429
2472.91	4.97628
2475.68	5.569
2478.45	5.28693
2481.23	5.46794
2484	5.35947
2486.77	5.0811
2489.54	4.89957
2492.3	5.68463
2495.07	5.83126
2497.84	6.41809
2500.6	8.07973
2503.36	7.7767
2506.13	7.34594
2508.89	6.32991
2511.65	4.86686
2514.41	5.04257
2517.17	4.58279
2519.93	5.18299
2522.68	4.93267
2525.44	4.54416
2528.19	4.57031
2530.95	4.58054
2533.7	4.54351
2536.45	4.9571
2539.2	3.851
2541.95	3.84655
2544.7	3.77331
2547.45	3.5147
2550.2	4.86094
2552.94	4.77105
2555.69	4.99386
2558.43	4.48412
2561.18	3.99847
2563.92	3.78063
2566.66	4.80209
2569.4	4.56572
2572.14	3.26801
2574.88	3.21386
2577.61	3.32692
2580.35	4.11455
2583.09	4.22379
2585.82	4.92876
2588.55	4.86615
2591.29	4.5551
2594.02	3.37757
2596.75	3.67092
2599.48	2.77778
2602.21	2.98854
2604.93	3.01215
2607.66	2.42291
2610.39	2.94306
2613.11	3.89353
2615.83	4.39989
2618.56	5.31446
2621.28	6.25381
2624	4.48211
2626.72	5.15811
2629.44	5.58592
2632.15	6.88762
2634.87	7.36597
2637.59	8.13585
2640.3	7.91424
2643.02	8.64858
2645.73	9.06799
2648.44	9.13219
2651.15	9.70335
2653.86	9.09893
2656.57	8.96668
2659.28	8.14376
2661.99	8.77247
2664.69	9.76483
2667.4	9.11529
2670.1	9.73372
2672.81	10.2554
2675.51	11.0761
2678.21	12.2963
2680.91	13.3553
2683.61	13.1138
2686.31	13.0469
2689	11.8386
2691.7	12.0844
2694.4	12.7289
2697.09	12.8312
2699.79	12.5779
2702.48	12.5913
2705.17	13.2522
2707.86	13.334
2710.55	12.8748
2713.24	12.6517
2715.93	13.7467
2718.62	14.1908
2721.3	15.0587
2723.99	14.9533
2726.67	14.5883
2729.35	15.3627
2732.04	16.2149
2734.72	14.7765
2737.4	14.4377
2740.08	15.255
2742.76	14.4785
2745.43	13.3961
2748.11	11.6856
2750.79	11.3227
2753.46	10.4337
2756.14	9.96765
2758.81	9.05035
2761.48	7.53547
2764.15	6.86462
2766.82	5.83324
2769.49	5.379
2772.16	4.73239
2774.82	4.74196
2777.49	4.65448
2780.16	4.25995
2782.82	3.5939
2785.48	3.77567
2788.15	3.59537
2790.81	2.79078
2793.47	2.92831
2796.13	3.01584
2798.79	1.83138
2801.44	1.52614
2804.1	1.66136
2806.76	1.34908
2809.41	1.84292
2812.07	2.42296
2814.72	2.77868
2817.37	3.5592
2820.02	6.14864
2822.67	9.19644
2825.32	12.2676
2827.97	16.7992
2830.62	21.9697
2833.26	27.9522
2835.91	33.2544
2838.56	40.6013
2841.2	48.7941
2843.84	57.198
2846.48	64.6315
2849.12	75.2306
2851.77	85.1085
2854.4	95.559
2857.04	105.65
2859.68	114.885
2862.32	124.823
2864.95	133.695
2867.59	143.516
2870.22	153.198
2872.85	160.997
2875.48	169.15
2878.11	174.388
2880.74	179.958
2883.37	186.764
2886	193.444
2888.63	199.572
2891.25	206.105
2893.88	210.922
2896.5	216.548
2899.13	223.379
2901.75	230.112
2904.37	239.32
2906.99	246.679
2909.61	256.371
2912.23	265.335
2914.85	275.697
2917.46	284.285
2920.08	291.878
2922.7	298.433
2925.31	303.021
2927.92	306.696
2930.54	307.182
2933.15	307.732
2935.76	304.822
2938.37	298.825
2940.98	292.122
2943.58	283.207
2946.19	274.177
2948.8	265.03
2951.4	253.872
2954.01	242.849
2956.61	231.891
2959.21	221.199
2961.81	211.087
2964.41	200.708
2967.01	190.853
2969.61	182.637
2972.21	175.075
2974.81	165.966
2977.4	155.913
2980	147.684
2982.59	138.561
2985.18	128.821
2987.78	118.871
2990.37	108.216
2992.96	98.0784
2995.55	88.4517
2998.14	78.7855
3000.73	69.8444
3003.31	61.0492
3005.9	52.3208
3008.48	43.4575
3011.07	36.88
3013.65	30.2568
3016.23	24.3332
3018.81	18.7919
3021.4	15.2799
3023.97	12.0462
3026.55	9.0501
3029.13	6.78306
3031.71	5.48574
3034.28	4.6411
3036.86	3.69964
3039.43	2.94533
3042.01	3.46613
3044.58	4.53641
3047.15	5.42694
3049.72	6.4815
3052.29	7.33743
3054.86	7.92825
3057.43	8.44629
3060	8.58482
3062.56	9.15134
3065.13	9.54663
3067.69	10.0466
3070.26	9.86774
3072.82	9.3181
3075.38	7.68529
3077.94	6.02014
3080.5	4.83045
3083.06	4.48646
3085.62	4.37861
3088.18	2.65494
3090.73	2.25596
3093.29	2.00094
3095.84	2.36446
3098.4	2.41225
3100.95	3.35787
3103.5	3.67311
3106.05	4.29306
3108.6	5.1907
3111.15	6.57838
3113.7	7.77679
3116.25	9.15713
3118.79	10.5113
3121.34	12.0538
3123.88	13.9673
3126.43	16.1059
3128.97	18.0451
3131.51	20.2122
3134.06	21.5127
3136.6	22.6046
3139.14	24.6124
3141.67	26.7535
3144.21	28.1458
3146.75	29.6996
3149.29	31.5884