File: data/Raman/poly_smoothed/Thy_10_08_25_1x_45s_532 nm_x100_100%_600 gr_mm_01.txt
#Acq. time (s)=	45
#Accumulations=	2
#Range (cm-¹)=	200...3150
#Windows=	2
#Auto scanning=	Off
#Autofocus=	Off
#Macrospot=	Off
#AutoExposure=	Off
#Spike filter=	Multiple accum.
#Delay time (s)=	0
#Binning=	1
#Readout mode=	Signal
#DeNoise=	Off
#ICS correction=	On
#Dark correction=	Off
#Inst. Process=	Off
#Detector Gain=	Best Dynamic Range
#Detector ADC=	20 kHz
#Detector temperature (°C)=	-69.85
#Instrument=	LabRAM HR Evol
#Detector=	Synapse
#Objective=	x100
#Grating=	600 gr/mm
#ND Filter=	100%
#Laser (nm)=	532
#Hole=	100.021
#Range=	Auto
#Laser Pol.=	No
#Raman. Pol.=	No
#Laser Pol. (°)=	-0.0007625
#Raman Pol. (°)=	89.9995
#Collection=	Microscope
#StageXY=	Marzhauser
#StageZ=	Marzhauser
#X (µm)=	2206.8
#Y (µm)=	1220.4
#Z (µm)=	443.5
#Full time(mm:ss)=	3:18
#Project=
#Sample=
#Site=
#Title=	Thy_10_08_25_2x_45s_532 nm_x100_100%_600 gr_mm
#Remark=
#Date=	05.07.2022 15:59
#Acquired=	05.07.2022 15:59:02
#Base:Fit=	10.08.2022 09:46:25
#Base:Sub=	10.08.2022 09:46:49
#Filter:Polynom=	16.08.2022 10:24:56
#AxisType[0]=Intens
#AxisUnit[0]=Cnt
#AxisType[1]=Spectr
#AxisUnit[1]=1/cm
200.43	36.6426
204.059	25.5831
207.688	18.12
211.314	12.8066
214.941	8.59353
218.564	5.39938
222.186	3.11903
225.809	2.4666
229.428	1.37057
233.045	0.852634
236.663	0.0595835
240.278	-1.01082
243.891	-1.09788
247.503	0.157444
251.116	1.6796
254.725	1.70917
258.333	1.89409
261.939	2.30626
265.544	2.77181
269.148	3.26264
272.75	2.37983
276.351	2.89541
279.95	4.03953
283.548	4.84414
287.144	6.26476
290.739	6.81006
294.333	7.39068
297.925	8.46014
301.514	8.68373
305.104	11.373
308.692	13.4434
312.279	14.7609
315.862	16.5075
319.446	17.4164
323.029	17.2468
326.608	17.121
330.188	17.8216
333.766	19.3154
337.341	19.4383
340.917	17.0736
344.489	15.637
348.062	15.9215
351.631	16.1507
355.201	15.3815
358.768	15.0958
362.333	13.8143
365.899	15.2208
369.462	14.2342
373.023	13.6196
376.585	12.677
380.143	11.0801
383.7	10.6789
387.256	11.5005
390.812	11.6816
394.365	12.0061
397.916	10.1994
401.467	9.8636
405.015	9.21194
408.563	8.30627
412.109	7.37191
415.654	7.77915
419.197	7.06164
422.739	7.95336
426.279	5.74316
429.819	5.12283
433.356	4.19799
436.891	5.80215
440.426	6.66165
443.96	7.19689
447.492	6.83921
451.021	7.47824
454.551	6.7901
458.079	8.24317
461.604	9.41297
465.13	10.096
468.654	12.2259
472.175	14.1057
475.696	15.9078
479.215	16.4125
482.733	17.1121
486.249	18.6181
489.765	19.5836
493.278	20.927
496.789	22.0662
500.301	21.8864
503.81	22.5676
507.317	22.1624
510.825	22.2591
514.33	21.1944
517.833	20.3622
521.335	20.0216
524.836	19.9537
528.335	17.0751
531.835	14.6434
535.332	12.4596
538.827	12.0974
542.321	8.83082
545.814	7.53502
549.305	6.29899
552.795	5.31265
556.282	4.9659
559.769	3.37542
563.255	3.4268
566.739	3.42652
570.223	2.69512
573.705	2.60421
577.183	1.66777
580.663	1.85255
584.141	1.93586
587.615	2.46502
591.09	4.19021
594.564	5.2144
598.035	5.66865
601.506	6.01738
604.974	6.33264
608.443	6.33914
611.908	5.49044
615.374	6.76286
618.837	7.78753
622.3	7.60482
625.761	7.87032
629.219	8.27162
632.677	10.5064
636.135	10.7185
639.59	12.2188
643.043	13.5015
646.495	15.4472
649.948	17.644
653.398	18.3125
656.846	18.6314
660.293	20.1291
663.738	21.1416
667.183	23.3777
670.626	24.1807
674.067	24.7648
677.508	25.455
680.947	25.2105
684.385	25.0523
687.821	26.0112
691.254	26.9145
694.688	26.4754
698.121	27.824
701.552	27.9041
704.98	28.6497
708.409	29.7044
711.836	30.2546
715.26	31.7402
718.685	32.6532
722.108	32.8521
725.528	34.9483
728.949	36.2182
732.367	37.2107
735.785	38.293
739.2	39.7103
742.614	42.4756
746.028	44.1263
749.439	46.6936
752.849	48.3034
756.26	50.7508
759.667	53.4426
763.073	57.0516
766.477	59.8943
769.883	63.1336
773.285	66.3079
776.686	68.4456
780.085	70.5735
783.484	72.0266
786.881	74.9405
790.276	77.4432
793.671	78.9044
797.064	80.1997
800.456	80.4493
803.846	81.195
807.234	81.1513
810.622	81.1914
814.008	80.6381
817.394	80.7204
820.778	80.9188
824.159	79.8509
827.541	79.1928
830.921	79.1773
834.298	78.4706
837.676	77.6592
841.051	77.6794
844.426	75.8445
847.798	75.0933
851.171	73.7845
854.54	71.2917
857.911	68.728
861.278	65.7811
864.645	64.4302
868.01	62.6463
871.373	61.0367
874.735	59.9839
878.097	59.3352
881.457	57.0397
884.815	55.9906
888.172	54.9784
891.528	53.6264
894.882	54.2025
898.237	56.293
901.589	55.8154
904.94	55.2936
908.289	56.3541
911.635	56.6834
914.982	57.1847
918.328	56.2981
921.672	56.0746
925.015	55.8794
928.357	55.1744
931.698	54.5673
935.035	52.2211
938.373	51.2334
941.71	50.1128
945.044	48.1079
948.378	45.4821
951.709	44.628
955.041	42.4396
958.372	39.9757
961.699	38.5226
965.027	37.687
968.352	36.3461
971.676	36.0189
975	36.9941
978.322	37.4763
981.642	37.0829
984.962	35.3058
988.28	34.6318
991.596	35.0014
994.911	34.0603
998.227	34.4889
1001.54	32.7304
1004.85	31.4392
1008.16	30.8757
1011.47	29.6299
1014.78	28.6476
1018.08	27.6371
1021.39	26.7741
1024.69	24.4241
1028	21.8506
1031.3	20.7488
1034.6	19.7654
1037.9	17.9847
1041.19	16.9024
1044.49	17.8774
1047.78	18.2651
1051.08	17.5624
1054.37	17.9158
1057.66	18.3318
1060.95	17.672
1064.24	17.9975
1067.53	17.3318
1070.81	17.622
1074.1	18.1509
1077.38	16.1358
1080.66	15.1289
1083.94	14.1865
1087.22	14.8441
1090.5	13.9321
1093.78	14.3796
1097.05	14.6359
1100.33	14.4102
1103.6	13.0422
1106.87	12.5445
1110.14	12.2587
1113.41	11.7151
1116.68	11.3095
1119.95	11.1665
1123.21	10.8479
1126.48	10.0872
1129.74	10.0133
1133	8.69852
1136.26	8.34048
1139.52	8.47268
1142.78	8.3576
1146.04	8.15781
1149.29	6.77093
1152.55	6.17984
1155.8	6.9398
1159.05	5.61062
1162.3	5.54005
1165.55	4.89468
1168.8	4.13798
1172.05	4.16598
1175.29	5.12694
1178.54	4.96827
1181.78	5.34895
1185.02	6.38955
1188.26	6.33509
1191.5	6.30085
1194.74	7.2535
1197.97	7.98507
1201.21	8.00096
1204.44	8.29163
1207.68	9.4553
1210.91	9.76171
1214.14	11.6499
1217.37	14.3842
1220.59	17.8013
1223.82	19.3432
1227.05	21.1095
1230.27	23.0856
1233.49	25.5334
1236.72	26.426
1239.94	27.1928
1243.16	27.7553
1246.37	29.3712
1249.59	31.7809
1252.8	33.4222
1256.02	34.9437
1259.23	34.893
1262.44	35.2043
1265.66	33.9458
1268.86	34.044
1272.07	33.7971
1275.28	33.2988
1278.48	32.6244
1281.69	32.9243
1284.89	33.8894
1288.09	33.8813
1291.29	34.9435
1294.49	36.655
1297.69	37.7511
1300.89	37.4317
1304.08	38.5435
1307.28	41.0736
1310.47	42.2269
1313.66	44.0108
1316.85	44.0808
1320.04	44.9381
1323.23	45.7807
1326.42	46.6721
1329.61	46.9457
1332.79	46.9233
1335.97	45.0591
1339.16	43.928
1342.34	42.1923
1345.52	40.3633
1348.7	39.0759
1351.87	38.6437
1355.05	37.4317
1358.22	35.7265
1361.4	35.1369
1364.57	32.1298
1367.74	30.0584
1370.91	27.9183
1374.08	24.8271
1377.25	24.2085
1380.41	23.444
1383.58	22.5646
1386.74	21.9099
1389.91	21.4223
1393.07	20.077
1396.23	19.0794
1399.39	19.4182
1402.55	18.8967
1405.7	19.1071
1408.86	20.719
1412.01	22.3444
1415.17	24.3809
1418.32	26.9957
1421.47	29.8886
1424.62	32.2469
1427.77	37.1211
1430.91	40.3437
1434.06	43.1589
1437.2	45.3692
1440.35	46.4636
1443.49	47.5171
1446.63	48.4915
1449.77	48.2335
1452.91	46.9006
1456.05	45.3683
1459.18	42.9257
1462.32	40.8085
1465.45	38.3774
1468.59	33.9951
1471.72	29.904
1474.85	25.5307
1477.98	21.4897
1481.1	17.5648
1484.23	15.0019
1487.36	12.9618
1490.48	9.94436
1493.61	8.96629
1496.73	7.40783
1499.85	7.79808
1502.97	7.83212
1506.09	8.3695
1509.2	8.49602
1512.32	8.42825
1515.43	9.05906
1518.55	10.1379
1521.66	10.9455
1524.77	11.8414
1527.88	12.2808
1530.99	13.7182
1534.1	15.0849
1537.21	16.0558
1540.31	17.28
1543.42	18.6217
1546.52	18.519
1549.62	19.4136
1552.72	20.7242
1555.82	22.356
1558.92	23.9841
1562.02	25.7559
1565.11	28.8443
1568.21	29.5625
1571.3	32.0629
1574.39	34.5745
1577.49	36.7175
1580.57	37.5868
1583.66	39.3167
1586.75	40.8824
1589.84	41.6995
1592.92	42.1486
1596.01	41.299
1599.09	41.4016
1602.17	42.2983
1605.25	41.2102
1608.33	40.4806
1611.41	39.243
1614.49	38.3405
1617.57	37.3296
1620.64	36.4562
1623.72	35.2704
1626.79	34.8493
1629.86	35.0061
1632.93	34.9628
1636	35.3077
1639.07	36.4032
1642.13	37.553
1645.2	39.7063
1648.26	41.714
1651.33	43.9997
1654.39	44.1875
1657.45	45.0401
1660.51	44.0535
1663.57	42.7091
1666.63	41.7868
1669.68	39.9768
1672.74	38.1101
1675.79	35.9264
1678.85	32.9229
1681.9	30.87
1684.95	27.6266
1688	24.5329
1691.05	20.9161
1694.09	18.0515
1697.14	16.3412
1700.18	13.4398
1703.23	11.8304
1706.27	10.075
1709.31	8.89035
1712.35	7.62151
1715.39	7.53429
1718.43	8.42675
1721.47	7.83905
1724.5	7.9494
1727.54	6.39468
1730.57	5.175
1733.61	4.61358
1736.64	3.30948
1739.67	2.40361
1742.7	2.69082
1745.72	2.01104
1748.75	1.097
1751.77	0.43425
1754.8	0.13059
1757.82	-0.609645
1760.84	-0.66232
1763.87	-0.202077
1766.89	0.0810895
1769.91	1.02147
1772.92	1.45273
1775.94	1.45647
1778.95	1.6745
1781.97	1.80919
1784.98	1.8177
1787.99	1.74094
1791.01	2.42845
1794.01	2.22558
1797.02	2.53705
1800.03	2.73491
1803.04	2.33095
1806.04	2.00252
1809.05	2.16115
1812.05	2.53888
1815.05	3.40594
1818.05	3.88115
1821.05	3.74286
1824.05	3.40284
1827.05	3.33878
1830.04	4.59781
1833.04	5.17517
1836.03	6.03209
1839.03	6.62981
1842.02	7.08356
1845.01	6.59193
1848	6.3044
1850.99	6.41592
1853.97	6.86719
1856.96	6.57006
1859.94	6.32886
1862.93	7.46487
1865.91	8.22161
1868.89	8.64914
1871.87	9.17627
1874.85	9.91258
1877.83	11.9959
1880.81	12.6631
1882.57	13.569
1885.56	14.1312
1888.55	14.3392
1891.54	14.2946
1894.52	14.4882
1897.51	14.4667
1900.49	15.45
1903.47	15.5266
1906.45	14.5504
1909.43	13.6684
1912.41	12.1443
1915.39	11.0799
1918.37	10.6989
1921.34	10.6447
1924.32	10.1952
1927.29	9.8303
1930.26	9.48504
1933.23	9.56012
1936.2	9.40426
1939.17	9.25236
1942.14	9.60864
1945.11	10.5859
1948.07	12.2668
1951.04	12.7721
1954	12.995
1956.96	13.3687
1959.93	13.317
1962.89	12.4843
1965.85	12.2128
1968.8	12.4823
1971.76	12.6019
1974.72	12.4343
1977.67	11.8969
1980.63	11.6624
1983.58	11.5292
1986.53	11.6748
1989.48	12.5031
1992.43	13.1367
1995.38	12.641
1998.32	12.7162
2001.27	12.6017
2004.22	12.8586
2007.16	12.0885
2010.1	12.4657
2013.04	12.7733
2015.98	12.8643
2018.92	13.5737
2021.86	13.294
2024.8	12.3008
2027.74	12.7021
2030.67	12.0665
2033.61	11.1557
2036.54	11.043
2039.47	11.5396
2042.4	11.8565
2045.33	11.6897
2048.26	11.9037
2051.19	12.2436
2054.12	12.7
2057.04	12.4957
2059.97	13.2934
2062.89	14.0833
2065.81	15.1762
2068.73	16.0446
2071.65	16.9587
2074.57	16.8515
2077.49	16.2972
2080.41	16.6807
2083.32	16.9111
2086.24	17.1097
2089.15	17.259
2092.07	17.3522
2094.98	17.9088
2097.89	19.1343
2100.8	19.2807
2103.71	19.3341
2106.61	19.4395
2109.52	19.2455
2112.43	19.8042
2115.33	20.1958
2118.23	19.8354
2121.13	20.3536
2124.04	20.6651
2126.94	20.5138
2129.83	20.9464
2132.73	21.5561
2135.63	22.1456
2138.53	22.5617
2141.42	23.2994
2144.31	23.1196
2147.21	23.4802
2150.1	23.4888
2152.99	23.6956
2155.88	24.5368
2158.77	24.9111
2161.65	25.365
2164.54	25.3857
2167.43	26.144
2170.31	25.6239
2173.19	24.8868
2176.07	24.8867
2178.96	24.9478
2181.84	25.167
2184.72	25.3084
2187.59	24.5464
2190.47	24.3834
2193.35	23.3796
2196.22	22.1333
2199.09	21.9706
2201.97	21.4702
2204.84	21.3393
2207.71	20.8453
2210.58	21.463
2213.45	21.1513
2216.31	20.6294
2219.18	20.2367
2222.05	19.4298
2224.91	20.4523
2227.78	19.3851
2230.64	18.6132
2233.5	18.1188
2236.36	18.0325
2239.22	17.6584
2242.08	16.9163
2244.93	16.5471
2247.79	16.5236
2250.64	15.5238
2253.5	15.2449
2256.35	15.2218
2259.2	14.8038
2262.05	15.154
2264.9	15.3923
2267.75	16.485
2270.6	17.8156
2273.45	18.5549
2276.29	18.6248
2279.14	18.5962
2281.98	18.4448
2284.82	17.3711
2287.66	16.8408
2290.5	16.1861
2293.34	14.3584
2296.18	12.7327
2299.02	12.4921
2301.86	12.8026
2304.69	12.5415
2307.53	12.6599
2310.36	11.6744
2313.19	10.8398
2316.02	10.046
2318.85	9.66956
2321.68	9.02536
2324.51	9.621
2327.34	8.77166
2330.16	9.74225
2332.99	10.1677
2335.81	9.79534
2338.64	10.186
2341.46	10.2014
2344.28	10.2209
2347.1	9.89196
2349.92	8.65212
2352.74	7.93353
2355.55	6.50198
2358.37	6.25654
2361.19	5.30805
2364	4.61779
2366.81	5.68161
2369.62	5.45618
2372.44	4.61763
2375.24	4.30344
2378.05	4.0132
2380.86	3.80099
2383.67	3.79438
2386.47	4.08709
2389.28	3.50264
2392.08	4.50057
2394.89	4.65776
2397.69	3.91549
2400.49	5.18968
2403.29	5.299
2406.09	6.0034
2408.88	7.28927
2411.68	8.04311
2414.48	8.74285
2417.27	9.10239
2420.06	9.4355
2422.86	10.1936
2425.65	10.757
2428.44	10.0807
2431.23	8.84872
2434.02	8.16717
2436.81	7.89527
2439.59	7.51695
2442.38	6.57054
2445.16	5.67106
2447.95	5.6024
2450.73	4.83741
2453.51	4.77254
2456.29	3.96223
2459.07	4.15412
2461.85	3.52623
2464.63	2.9011
2467.4	2.44184
2470.18	2.76438
2472.95	3.09422
2475.73	3.22598
2478.5	4.17696
2481.27	4.24765
2484.04	4.24835
2486.81	4.86661
2489.58	5.16429
2492.35	5.70292
2495.12	5.57463
2497.88	5.25266
2500.65	6.28014
2503.41	6.55314
2506.17	6.63807
2508.94	5.67128
2511.7	4.99383
2514.46	5.13713
2517.22	4.29524
2519.97	4.22114
2522.73	3.79652
2525.49	3.99043
2528.24	3.63601
2530.99	3.36707
2533.75	2.66686
2536.5	2.65295
2539.25	2.30186
2542	2.06954
2544.75	1.84568
2547.5	1.38364
2550.24	1.40442
2552.99	1.41515
2555.74	1.26113
2558.48	1.36333
2561.22	1.52209
2563.96	1.25862
2566.71	1.85406
2569.45	1.15015
2572.18	1.0947
2574.92	0.949925
2577.66	0.321006
2580.4	0.419944
2583.13	0.303872
2585.87	0.67108
2588.6	1.34321
2591.33	1.57414
2594.06	1.53242
2596.79	1.39293
2599.52	1.6394
2602.25	1.68673
2604.98	1.55132
2607.71	1.05957
2610.43	0.766764
2613.16	1.12508
2615.88	0.333581
2618.6	0.203493
2621.32	0.0656909
2624.04	0.280699
2626.76	0.151133
2629.48	0.737762
2632.2	0.78244
2634.92	1.22213
2637.63	1.06806
2640.35	1.21778
2643.06	1.10721
2645.77	1.13073
2648.49	1.50825
2651.2	2.43915
2653.91	2.08013
2656.62	2.5046
2659.33	2.65722
2662.03	1.72352
2664.74	1.54986
2667.44	2.12411
2670.15	1.98576
2672.85	1.87705
2675.55	1.51035
2678.26	1.89341
2680.96	2.93518
2683.66	2.79476
2686.35	3.82962
2689.05	3.88626
2691.75	3.62715
2694.44	3.28442
2697.14	3.29823
2699.83	3.86187
2702.52	3.86527
2705.22	3.81159
2707.91	3.61084
2710.6	3.36172
2713.29	4.09586
2715.97	4.73471
2718.66	4.96809
2721.35	5.06366
2724.03	4.60693
2726.72	4.14709
2729.4	3.89571
2732.08	4.19034
2734.76	4.32305
2737.44	4.3671
2740.12	4.82458
2742.8	4.8585
2745.48	5.18887
2748.16	4.85769
2750.83	4.4152
2753.51	3.97681
2756.18	2.92979
2758.85	2.85138
2761.53	2.82574
2764.2	3.50573
2766.87	4.21038
2769.54	4.3664
2772.2	4.21271
2774.87	4.20601
2777.54	4.38974
2780.2	5.359
2782.87	5.12545
2785.53	4.60991
2788.19	3.97579
2790.85	3.69966
2793.51	3.25833
2796.17	3.556
2798.83	3.64233
2801.49	3.31625
2804.15	3.56151
2806.8	2.71655
2809.46	2.59073
2812.11	2.7206
2814.76	2.44468
2817.42	2.94053
2820.07	3.32288
2822.72	5.04985
2825.37	7.17208
2828.02	9.5806
2830.66	11.6
2833.31	15.2223
2835.96	17.5382
2838.6	20.4194
2841.24	24.9465
2843.89	30.229
2846.53	35.1974
2849.17	40.3508
2851.81	45.6704
2854.45	51.7863
2857.09	57.7635
2859.72	63.2795
2862.36	69.1009
2865	73.0542
2867.63	77.9622
2870.26	81.7384
2872.9	85.2047
2875.53	88.4147
2878.16	91.3573
2880.79	93.7809
2883.42	96.4681
2886.05	99.3801
2888.67	102.598
2891.3	105.006
2893.92	107.969
2896.55	110.764
2899.17	114.551
2901.79	118.78
2904.42	123.704
2907.04	130.253
2909.66	136.805
2912.27	143.105
2914.89	150.267
2917.51	156.055
2920.13	161.454
2922.74	165.541
2925.35	167.801
2927.97	169.899
2930.58	171.314
2933.19	170.516
2935.8	168.57
2938.41	165.783
2941.02	161.434
2943.63	156.939
2946.24	151.512
2948.84	146.583
2951.45	141.162
2954.05	135.367
2956.65	129.611
2959.26	123.885
2961.86	118.206
2964.46	112.804
2967.06	107.338
2969.66	102.482
2972.25	97.6746
2974.85	92.8212
2977.45	88.4803
2980.04	83.6251
2982.64	77.8884
2985.23	71.8897
2987.82	65.3582
2990.41	60.0945
2993	54.8811
2995.59	48.7093
2998.18	43.4174
3000.77	39.0067
3003.36	34.3685
3005.94	31.1492
3008.53	27.995
3011.11	25.2189
3013.69	23.0902
3016.28	21.7829
3018.86	20.3127
3021.44	18.5614
3024.02	17.2774
3026.6	16.4661
3029.18	15.6688
3031.75	14.9592
3034.33	14.9581
3036.9	16.008
3039.48	16.8432
3042.05	16.8581
3044.62	16.7735
3047.19	17.3066
3049.77	18.0304
3052.34	18.0697
3054.9	18.1976
3057.47	17.8099
3060.04	17.6155
3062.61	17.6665
3065.17	17.12
3067.74	16.2548
3070.3	14.9627
3072.86	12.7306
3075.42	11.966
3077.99	10.3005
3080.54	8.97322
3083.1	7.82109
3085.66	6.54544
3088.22	6.08377
3090.78	5.14015
3093.33	4.41018
3095.89	4.43067
3098.44	4.11703
3100.99	3.83993
3103.54	3.61596
3106.1	4.00838
3108.65	3.90588
3111.2	3.60226
3113.74	3.35615
3116.29	3.0363
3118.84	2.72953
3121.38	2.74462
3123.93	2.43995
3126.47	2.45997
3129.01	1.56172
3131.56	-0.282415
3134.1	-0.52855
3136.64	-0.427844
3139.18	-0.91896
3141.72	-0.92912
3144.26	-0.781056
3146.79	-0.957873
3149.33	-1.33261