File: data/Raman/poly_smoothed/Thy_00_07_21_1x_45s_532 nm_x100_100%_600 gr_mm_01.txt
#Acq. time (s)=	45
#Accumulations=	2
#Range (cm-¹)=	200...3150
#Windows=	2
#Auto scanning=	Off
#Autofocus=	Off
#Macrospot=	Off
#AutoExposure=	Off
#Spike filter=	Multiple accum.
#Delay time (s)=	0
#Binning=	1
#Readout mode=	Signal
#DeNoise=	Off
#ICS correction=	On
#Dark correction=	Off
#Inst. Process=	Off
#Detector Gain=	Best Dynamic Range
#Detector ADC=	20 kHz
#Detector temperature (°C)=	-69.85
#Instrument=	LabRAM HR Evol
#Detector=	Synapse
#Objective=	x100
#Grating=	600 gr/mm
#ND Filter=	100%
#Laser (nm)=	532
#Hole=	100.021
#Range=	Auto
#Laser Pol.=	No
#Raman. Pol.=	No
#Laser Pol. (°)=	-0.0007625
#Raman Pol. (°)=	89.9995
#Collection=	Microscope
#StageXY=	Marzhauser
#StageZ=	Marzhauser
#X (µm)=	8994.2
#Y (µm)=	-3064.3
#Z (µm)=	-54.9
#Full time(mm:ss)=	3:19
#Project=
#Sample=
#Site=
#Title=	Thy_00_07_21_2x_45s_532 nm_x100_100%_600 gr_mm
#Remark=
#Date=	28.06.2022 11:41
#Acquired=	28.06.2022 11:41:30
#Base:Fit=	10.08.2022 10:07:56
#Base:Sub=	10.08.2022 10:08:40
#Filter:Polynom=	16.08.2022 10:26:06
#AxisType[0]=Intens
#AxisUnit[0]=Cnt
#AxisType[1]=Spectr
#AxisUnit[1]=1/cm
200.407	6.78962
204.035	13.764
207.665	16.1761
211.291	17.4541
214.916	18.2329
218.541	16.6391
222.163	15.7167
225.785	13.8056
229.404	12.5343
233.022	10.0179
236.638	9.29346
240.255	7.91989
243.868	6.92211
247.48	5.97732
251.091	4.11102
254.702	3.31774
258.31	2.20455
261.916	2.04452
265.521	1.67499
269.125	2.50584
272.727	3.06253
276.328	2.56347
279.927	2.60404
283.525	2.96206
287.121	4.21483
290.716	4.62817
294.31	5.17968
297.9	8.05972
301.491	9.44829
305.081	9.2221
308.669	10.4054
312.256	11.9384
315.839	12.3534
319.423	13.0296
323.006	14.811
326.585	14.7148
330.165	14.2181
333.741	14.2284
337.318	13.4609
340.894	12.9254
344.466	12.6836
348.039	12.0986
351.608	12.2019
355.176	11.3663
358.745	9.84242
362.31	7.85568
365.876	7.62034
369.439	7.17311
373	4.96141
376.56	6.95514
380.12	7.29858
383.677	6.62103
387.233	5.60591
390.787	4.78543
394.34	4.5049
397.894	5.61305
401.444	6.01508
404.993	7.12982
408.54	6.5696
412.086	5.53885
415.631	4.04307
419.174	4.17326
422.716	4.84848
426.257	4.70378
429.794	5.35134
433.332	5.30396
436.868	3.84631
440.403	3.68675
443.937	5.53992
447.468	8.35452
450.999	12.2474
454.528	14.6848
458.057	16.0563
461.582	20.5138
465.107	22.5787
468.629	24.7854
472.152	26.8198
475.672	28.649
479.192	30.5453
482.709	31.4229
486.226	34.4672
489.74	34.9984
493.255	35.3825
496.767	35.3274
500.277	33.9162
503.788	34.4313
507.295	34.0286
510.801	29.9905
514.308	27.0978
517.811	24.2559
521.313	21.3547
524.814	19.9848
528.313	19.058
531.811	16.8075
535.308	14.8635
538.803	12.5838
542.297	12.091
545.789	11.0319
549.281	10.1051
552.771	9.15298
556.259	8.40409
559.747	6.40941
563.233	6.78345
566.717	6.03449
570.2	7.10363
573.68	7.19781
577.161	6.67204
580.64	7.07161
584.118	8.59061
587.593	7.95807
591.068	6.69319
594.54	4.52327
598.013	3.51556
601.484	4.02926
604.952	3.11936
608.421	3.9698
611.886	3.0843
615.35	2.59275
618.815	3.27849
622.276	3.62785
625.738	5.73613
629.197	7.15751
632.655	8.0543
636.113	9.90583
639.568	12.0797
643.021	12.8151
646.473	13.5332
649.924	13.6674
653.376	16.001
656.824	16.9832
660.271	18.3297
663.716	19.6974
667.161	20.7735
670.604	21.0832
674.045	20.0816
677.486	20.3896
680.925	22.8345
684.361	23.8034
687.797	24.9503
691.232	25.6882
694.666	27.371
698.099	27.2076
701.528	26.5066
704.958	27.4717
708.387	28.8943
711.814	28.9954
715.238	28.7816
718.663	30.2178
722.084	32.2865
725.506	32.8302
728.925	32.699
732.345	34.1008
735.761	37.9782
739.178	40.7905
742.592	43.694
746.006	47.6292
749.417	52.191
752.827	55.9756
756.236	60.4812
759.645	64.8451
763.051	67.7899
766.456	69.4271
769.859	72.5599
773.261	74.2808
776.664	75.0506
780.064	75.5627
783.462	75.4858
786.859	74.7905
790.255	73.4658
793.649	72.9265
797.042	72.66
800.434	72.0124
803.823	70.6558
807.212	70.5685
810.6	69.3764
813.987	70.1115
817.372	70.9642
820.754	74.0441
824.137	75.0379
827.519	77.2064
830.897	80.0746
834.276	81.5568
837.654	83.3861
841.029	84.1549
844.404	84.6051
847.776	82.9799
851.149	81.5855
854.519	79.7925
857.889	75.1704
861.256	70.9068
864.622	67.0988
867.988	63.7201
871.351	58.9659
874.713	55.4135
878.074	53.0742
881.435	50.2452
884.794	46.8476
888.15	44.3999
891.506	44.8009
894.861	43.8336
898.214	44.4366
901.566	46.8427
904.916	50.062
908.266	52.0137
911.614	54.6459
914.961	57.9509
918.306	60.1877
921.651	61.6376
924.994	62.0196
928.336	61.2219
931.674	60.404
935.014	57.9162
938.352	55.6061
941.687	52.6924
945.022	50.0962
948.357	48.2992
951.688	45.5671
955.02	43.2423
958.348	39.5825
961.678	36.8791
965.004	32.8383
968.331	31.3612
971.655	30.189
974.979	28.8033
978.3	27.8272
981.62	28.5035
984.941	28.787
988.259	29.0999
991.575	29.1165
994.89	30.9786
998.204	32.7365
1001.52	35.0278
1004.83	36.0581
1008.14	39.1929
1011.45	40.1498
1014.76	41.0669
1018.06	42.3315
1021.37	43.7113
1024.67	44.9698
1027.97	45.8877
1031.27	45.8178
1034.57	44.1144
1037.87	42.8411
1041.17	40.1071
1044.47	39.7068
1047.76	38.0521
1051.06	36.9025
1054.35	36.2479
1057.64	35.1396
1060.93	34.2691
1064.22	31.5495
1067.5	31.782
1070.79	32.1524
1074.08	33.0006
1077.36	35.0087
1080.64	36.6491
1083.92	38.2701
1087.2	39.8529
1090.48	41.8928
1093.76	43.5086
1097.03	47.6977
1100.31	51.1151
1103.58	52.7762
1106.85	54.7192
1110.12	56.1895
1113.39	57.8864
1116.66	57.8698
1119.93	57.8384
1123.19	56.0589
1126.46	54.9609
1129.72	53.0082
1132.98	51.1993
1136.24	50.2753
1139.5	47.7469
1142.76	45.4551
1146.01	42.019
1149.27	38.3902
1152.53	34.1056
1155.78	29.8546
1159.03	25.5755
1162.28	21.9755
1165.53	17.1738
1168.78	15.0801
1172.02	12.9832
1175.27	11.314
1178.51	10.5024
1181.76	8.30296
1185	6.9035
1188.24	4.74066
1191.48	5.07774
1194.71	4.94874
1197.95	3.79054
1201.19	4.68214
1204.42	6.33108
1207.65	7.61934
1210.88	10.5893
1214.12	14.8492
1217.35	19.2578
1220.57	22.3757
1223.8	25.4164
1227.03	28.1101
1230.25	32.3022
1233.47	35.154
1236.69	37.0408
1239.92	39.7973
1243.13	41.1404
1246.35	42.4661
1249.57	45.2425
1252.78	45.1196
1256	45.2044
1259.21	43.9201
1262.42	42.7731
1265.63	41.0274
1268.84	41.9466
1272.05	42.2453
1275.26	41.3027
1278.46	41.4564
1281.67	40.1066
1284.87	41.9778
1288.07	43.5013
1291.27	43.9773
1294.47	45.5607
1297.67	48.1695
1300.87	52.9593
1304.06	58.8814
1307.26	63.5082
1310.45	68.8338
1313.64	73.384
1316.83	79.0621
1320.02	82.7017
1323.21	87.4123
1326.4	89.9066
1329.59	93.6638
1332.77	94.4977
1335.95	94.3937
1339.14	94.5682
1342.32	91.2844
1345.5	90.7145
1348.67	88.2151
1351.85	84.2993
1355.03	82.5173
1358.2	79.1685
1361.38	76.8774
1364.55	73.704
1367.72	71.2857
1370.89	68.7801
1374.06	68.7424
1377.23	67.7343
1380.39	68.9128
1383.56	67.8432
1386.72	66.9259
1389.89	66.3634
1393.05	66.0787
1396.21	65.8057
1399.37	63.38
1402.52	61.4246
1405.68	59.1015
1408.84	58.919
1411.99	57.8744
1415.15	58.7188
1418.3	58.2532
1421.45	58.6022
1424.6	60.3628
1427.75	64.0496
1430.89	69.3504
1434.04	74.3604
1437.18	78.7559
1440.33	80.817
1443.47	85.4873
1446.61	88.4673
1449.75	90.8199
1452.89	89.4636
1456.03	88.7008
1459.16	85.5861
1462.3	81.9613
1465.43	77.2416
1468.56	72.0588
1471.7	65.1356
1474.83	56.2925
1477.96	47.8825
1481.08	40.3464
1484.21	32.2497
1487.34	27.2335
1490.46	22.5098
1493.58	16.7875
1496.71	11.7219
1499.83	9.23666
1502.95	10.4499
1506.07	11.6581
1509.18	12.4309
1512.3	12.7425
1515.41	12.8172
1518.53	15.5919
1521.64	18.566
1524.75	19.38
1527.86	19.169
1530.97	20.4723
1534.08	22.993
1537.19	24.6578
1540.29	26.0855
1543.4	27.944
1546.5	27.7646
1549.6	26.9254
1552.7	30.116
1555.8	31.6205
1558.9	33.2684
1562	35.1829
1565.09	38.8697
1568.19	40.0456
1571.28	42.1508
1574.37	44.8277
1577.47	47.3902
1580.56	50.2578
1583.64	51.8998
1586.73	53.7208
1589.82	56.282
1592.9	59.122
1595.99	60.1886
1599.07	59.8916
1602.15	58.4735
1605.23	58.7049
1608.31	58.6227
1611.39	57.1688
1614.47	57.108
1617.55	55.2865
1620.62	54.1228
1623.7	53.6965
1626.77	54.8081
1629.84	55.2942
1632.91	53.232
1635.98	53.9643
1639.05	53.8963
1642.11	53.0591
1645.18	53.8574
1648.24	52.9519
1651.31	54.5742
1654.37	55.055
1657.43	56.2373
1660.49	56.2899
1663.55	56.4346
1666.61	56.6751
1669.66	55.454
1672.72	51.9852
1675.77	49.1983
1678.83	45.9568
1681.88	44.1279
1684.93	41.3004
1687.98	38.2889
1691.03	35.1795
1694.07	31.3922
1697.12	28.7007
1700.17	26.7926
1703.21	24.8323
1706.25	22.2776
1709.29	20.804
1712.33	19.1507
1715.37	17.4208
1718.41	15.7103
1721.45	13.9633
1724.49	13.5072
1727.52	12.3617
1730.55	11.0035
1733.59	11.1047
1736.62	10.8335
1739.65	10.4955
1742.68	9.66462
1745.7	8.72755
1748.73	7.02832
1751.76	6.01293
1754.78	6.06134
1757.8	6.96035
1760.83	5.94879
1763.85	5.16321
1766.87	5.76314
1769.89	6.42498
1772.9	6.97331
1775.92	8.46571
1778.94	8.21435
1781.95	8.04239
1784.96	8.33316
1787.97	7.61273
1790.99	6.8321
1794	7.22586
1797	7.73854
1800.01	7.74785
1803.02	8.06443
1806.02	8.92423
1809.03	8.73665
1812.03	8.84668
1815.03	9.01943
1818.03	9.21369
1821.03	8.25743
1824.03	8.03292
1827.03	8.73507
1830.02	8.63667
1833.02	8.37886
1836.01	8.43262
1839.01	8.85275
1842	9.36146
1844.99	10.1015
1847.98	10.4951
1850.97	10.2506
1853.95	9.64056
1856.94	10.4486
1859.93	11.0128
1862.91	12.0803
1865.89	13.221
1868.87	12.6203
1871.85	12.339
1874.83	12.7966
1877.81	12.5264
1880.79	11.8021
1882.52	11.1326
1885.51	10.8337
1888.5	9.94706
1891.49	9.20235
1894.47	9.09897
1897.46	8.62514
1900.44	9.2012
1903.42	8.91755
1906.4	8.72038
1909.38	8.7235
1912.36	7.19972
1915.34	7.02759
1918.32	7.50519
1921.29	6.30651
1924.27	5.77966
1927.24	5.83671
1930.21	5.68664
1933.18	4.76896
1936.15	4.30686
1939.12	4.46173
1942.09	2.76513
1945.06	2.15113
1948.02	2.25119
1950.99	0.985392
1953.95	0.285096
1956.91	0.420409
1959.88	0.0895817
1962.84	0.8428
1965.8	0.580929
1968.75	2.07386
1971.71	3.58201
1974.67	3.76285
1977.62	4.00974
1980.58	4.01743
1983.53	4.98296
1986.48	4.88398
1989.43	4.6208
1992.38	6.04395
1995.33	4.85161
1998.27	5.23599
2001.22	5.71366
2004.16	6.26339
2007.11	7.78488
2010.05	8.82161
2012.99	8.77518
2015.93	8.36053
2018.87	8.73934
2021.81	8.12034
2024.75	8.82637
2027.69	8.95917
2030.62	8.48436
2033.56	7.69763
2036.49	6.97974
2039.42	7.71541
2042.35	9.14995
2045.28	7.59716
2048.21	6.64753
2051.14	6.51854
2054.07	5.74843
2056.99	4.85922
2059.92	4.6696
2062.84	4.66701
2065.76	5.16274
2068.68	4.83568
2071.6	5.37185
2074.52	6.48536
2077.44	7.27526
2080.36	7.8829
2083.27	8.32988
2086.19	7.81211
2089.1	8.16807
2092.02	8.43584
2094.93	9.96826
2097.84	10.5376
2100.75	9.69747
2103.66	9.68507
2106.56	9.20128
2109.47	9.37149
2112.38	8.65648
2115.28	8.3015
2118.18	7.89552
2121.09	8.65459
2123.99	8.95321
2126.89	8.73195
2129.79	9.31172
2132.68	9.40395
2135.58	8.92829
2138.48	9.03879
2141.37	8.97188
2144.27	9.27485
2147.16	9.39638
2150.05	9.02345
2152.94	8.34373
2155.83	8.42047
2158.72	8.18754
2161.6	8.89784
2164.49	9.19203
2167.38	8.67993
2170.26	8.04939
2173.14	7.60822
2176.03	6.83134
2178.91	6.52548
2181.79	6.08744
2184.67	7.29466
2187.54	7.56233
2190.42	7.78736
2193.3	7.31241
2196.17	8.16131
2199.05	8.26589
2201.92	8.45083
2204.79	7.80928
2207.66	7.87045
2210.53	7.14683
2213.4	6.99689
2216.27	7.05479
2219.13	6.61229
2222	7.34228
2224.86	7.43515
2227.72	6.88465
2230.59	7.5985
2233.45	6.27304
2236.31	7.21845
2239.17	6.76205
2242.03	7.38298
2244.88	7.44716
2247.74	8.55457
2250.59	8.68427
2253.45	10.298
2256.3	10.6587
2259.15	10.3564
2262	9.94044
2264.85	9.82046
2267.7	9.37278
2270.55	8.4183
2273.4	7.13782
2276.24	5.99442
2279.09	5.82692
2281.93	5.93829
2284.77	6.87746
2287.62	6.59477
2290.46	6.17528
2293.3	4.46208
2296.13	4.62257
2298.97	5.43889
2301.81	5.50556
2304.64	7.14286
2307.48	8.27481
2310.31	8.61696
2313.14	10.1391
2315.98	9.80449
2318.81	9.64864
2321.64	10.4346
2324.46	10.2967
2327.29	8.48766
2330.12	8.23019
2332.94	7.00102
2335.77	5.77139
2338.59	4.54636
2341.41	4.15439
2344.23	4.09137
2347.05	4.42737
2349.87	4.82001
2352.69	4.37828
2355.51	3.26092
2358.32	3.24304
2361.14	2.17923
2363.95	3.48687
2366.76	5.68455
2369.58	6.69935
2372.39	6.86138
2375.2	7.29753
2378	7.5336
2380.81	6.50835
2383.62	5.31054
2386.43	5.47629
2389.23	4.56672
2392.03	5.39972
2394.84	3.73287
2397.64	1.99651
2400.44	1.85176
2403.24	1.75835
2406.04	1.58852
2408.84	2.07012
2411.63	3.11785
2414.43	3.40789
2417.22	4.76552
2420.02	5.23022
2422.81	5.29949
2425.6	6.12758
2428.39	6.5475
2431.18	6.55034
2433.97	7.48045
2436.76	7.80351
2439.54	7.22248
2442.33	6.78854
2445.12	5.75899
2447.9	5.93679
2450.68	4.76927
2453.46	4.52779
2456.24	4.16027
2459.02	2.95194
2461.8	1.88044
2464.58	0.468125
2467.36	1.33739
2470.13	1.22946
2472.91	1.27909
2475.68	1.87309
2478.45	2.02706
2481.23	2.16643
2484	2.70126
2486.77	2.92692
2489.54	2.14319
2492.3	1.62131
2495.07	1.1836
2497.84	0.85054
2500.6	0.502769
2503.36	1.0313
2506.13	1.78931
2508.89	0.997107
2511.65	1.39874
2514.41	1.23119
2517.17	0.625018
2519.93	0.87886
2522.68	0.58115
2525.44	0.0879706
2528.19	-0.0505217
2530.95	1.11626
2533.7	1.97153
2536.45	1.49828
2539.2	1.78542
2541.95	2.42721
2544.7	2.49292
2547.45	2.87117
2550.2	3.67066
2552.94	3.082
2555.69	2.92973
2558.43	2.92155
2561.18	2.41907
2563.92	1.88509
2566.66	1.5332
2569.4	2.51412
2572.14	2.50303
2574.88	2.52095
2577.61	2.27278
2580.35	2.42401
2583.09	2.26671
2585.82	1.64696
2588.55	1.26142
2591.29	1.32458
2594.02	1.81283
2596.75	2.15564
2599.48	2.18734
2602.21	1.66523
2604.93	2.01482
2607.66	3.01595
2610.39	3.02708
2613.11	3.86507
2615.83	3.13027
2618.56	3.91415
2621.28	3.74683
2624	3.99917
2626.72	2.87146
2629.44	2.84445
2632.15	1.97001
2634.87	2.94543
2637.59	3.47728
2640.3	3.15938
2643.02	3.59913
2645.73	3.04273
2648.44	2.87962
2651.15	2.89148
2653.86	2.67862
2656.57	2.66147
2659.28	3.02941
2661.99	3.24986
2664.69	3.5014
2667.4	4.31408
2670.1	5.46545
2672.81	6.51051
2675.51	6.28118
2678.21	6.73187
2680.91	6.89751
2683.61	6.98164
2686.31	8.00273
2689	8.19365
2691.7	8.67395
2694.4	9.12233
2697.09	9.93698
2699.79	10.068
2702.48	12.322
2705.17	12.3774
2707.86	13.2372
2710.55	12.8614
2713.24	13.0841
2715.93	13.2469
2718.62	13.0568
2721.3	12.5591
2723.99	12.7606
2726.67	13.6009
2729.35	13.1534
2732.04	13.1015
2734.72	12.513
2737.4	11.9343
2740.08	10.1959
2742.76	9.77697
2745.43	9.29729
2748.11	8.50529
2750.79	7.58457
2753.46	7.61068
2756.14	6.98949
2758.81	7.30423
2761.48	7.3322
2764.15	6.31725
2766.82	6.04041
2769.49	4.96772
2772.16	3.73605
2774.82	4.23249
2777.49	3.10379
2780.16	2.73711
2782.82	2.59793
2785.48	2.30398
2788.15	1.94277
2790.81	2.25838
2793.47	2.27651
2796.13	1.98436
2798.79	1.67694
2801.44	1.55438
2804.1	1.10104
2806.76	1.52276
2809.41	1.29149
2812.07	1.63666
2814.72	2.74383
2817.37	3.77058
2820.02	6.00457
2822.67	8.60487
2825.32	11.208
2827.97	13.6868
2830.62	17.0613
2833.26	20.0477
2835.91	24.6549
2838.56	30.4381
2841.2	35.9234
2843.84	41.286
2846.48	48.4264
2849.12	54.9427
2851.77	63.6428
2854.4	74.2962
2857.04	84.0435
2859.68	94.292
2862.32	103.746
2864.95	114.979
2867.59	126.11
2870.22	136.633
2872.85	147.123
2875.48	157.451
2878.11	168.429
2880.74	178.353
2883.37	187.992
2886	197.742
2888.63	205.652
2891.25	214.867
2893.88	222.529
2896.5	229.441
2899.13	236.326
2901.75	243.042
2904.37	249.381
2906.99	255.215
2909.61	262.579
2912.23	269.319
2914.85	277.509
2917.46	284.01
2920.08	289.555
2922.7	293.792
2925.31	296.45
2927.92	297.685
2930.54	297.423
2933.15	295.431
2935.76	291.054
2938.37	286.101
2940.98	279.611
2943.58	272.064
2946.19	264.279
2948.8	255.452
2951.4	246.167
2954.01	236.561
2956.61	227.197
2959.21	216.952
2961.81	206.503
2964.41	196.269
2967.01	186.528
2969.61	176.856
2972.21	167.682
2974.81	159.011
2977.4	148.933
2980	139.743
2982.59	129.854
2985.18	119.565
2987.78	108.776
2990.37	98.4085
2992.96	87.8651
2995.55	77.0731
2998.14	66.7502
3000.73	56.1179
3003.31	47.5955
3005.9	39.1481
3008.48	31.2434
3011.07	25.3267
3013.65	19.4056
3016.23	14.4814
3018.81	10.3182
3021.4	7.35425
3023.97	4.80719
3026.55	3.0451
3029.13	1.46322
3031.71	0.674178
3034.28	0.943624
3036.86	0.689518
3039.43	1.65837
3042.01	3.16231
3044.58	4.35452
3047.15	6.44468
3049.72	7.94425
3052.29	8.99592
3054.86	10.3674
3057.43	11.0008
3060	11.321
3062.56	11.193
3065.13	11.2668
3067.69	11.4221
3070.26	10.7438
3072.82	9.96576
3075.38	8.7166
3077.94	6.23621
3080.5	5.16751
3083.06	4.48281
3085.62	3.5185
3088.18	3.02644
3090.73	2.11777
3093.29	2.32369
3095.84	2.22598
3098.4	2.92495
3100.95	2.98331
3103.5	3.26547
3106.05	3.52405
3108.6	4.30453
3111.15	5.76901
3113.7	8.25596
3116.25	9.48773
3118.79	10.9123
3121.34	12.8766
3123.88	14.1808
3126.43	15.4104
3128.97	18.3288
3131.51	19.884
3134.06	21.4567
3136.6	24.2478
3139.14	26.6265
3141.67	29.4454
3144.21	32.7501
3146.75	35.3285
3149.29	37.8388