File: data/Raman/poly_smoothed/Thy_20_09_38_1x_45s_532 nm_x100_100%_600 gr_mm_01.txt
#Acq. time (s)=	45
#Accumulations=	2
#Range (cm-¹)=	200...3150
#Windows=	2
#Auto scanning=	Off
#Autofocus=	Off
#Macrospot=	Off
#AutoExposure=	Off
#Spike filter=	Multiple accum.
#Delay time (s)=	0
#Binning=	1
#Readout mode=	Signal
#DeNoise=	Off
#ICS correction=	On
#Dark correction=	Off
#Inst. Process=	Off
#Detector Gain=	Best Dynamic Range
#Detector ADC=	20 kHz
#Detector temperature (°C)=	-69.85
#Instrument=	LabRAM HR Evol
#Detector=	Synapse
#Objective=	x100
#Grating=	600 gr/mm
#ND Filter=	100%
#Laser (nm)=	532
#Hole=	100.021
#Range=	Auto
#Laser Pol.=	No
#Raman. Pol.=	No
#Laser Pol. (°)=	-0.0007625
#Raman Pol. (°)=	89.9995
#Collection=	Microscope
#StageXY=	Marzhauser
#StageZ=	Marzhauser
#X (µm)=	-5912.3
#Y (µm)=	2863.7
#Z (µm)=	-223.6
#Full time(mm:ss)=	3:19
#Project=
#Sample=
#Site=
#Title=	Thy_20_09_38_2x_45s_532 nm_x100_100%_600 gr_mm
#Remark=
#Date=	29.06.2022 13:20
#Acquired=	29.06.2022 13:20:02
#Base:Fit=	10.08.2022 09:52:02
#Base:Fit=	10.08.2022 09:52:12
#Base:Sub=	10.08.2022 09:54:21
#Filter:Polynom=	16.08.2022 10:24:04
#AxisType[0]=Intens
#AxisUnit[0]=Cnt
#AxisType[1]=Spectr
#AxisUnit[1]=1/cm
200.523	5.03945
204.154	3.58414
207.781	4.51486
211.409	5.53998
215.034	7.03231
218.659	8.04093
222.281	8.14527
225.903	7.64057
229.522	7.34629
233.14	8.91295
236.756	10.0048
240.373	10.4382
243.986	10.3187
247.598	8.95872
251.208	8.84487
254.818	9.712
258.427	10.434
262.034	11.0425
265.638	10.1175
269.242	10.6321
272.844	8.41946
276.445	8.03239
280.044	9.23572
283.642	8.53527
287.238	9.86366
290.833	10.6318
294.425	11.5162
298.017	13.1503
301.608	14.3438
305.198	15.1877
308.786	15.6996
312.371	17.2522
315.956	17.5473
319.54	18.7663
323.122	20.0773
326.701	19.7459
330.281	19.4201
333.857	18.8622
337.434	19.3123
341.008	19.1101
344.582	19.0277
348.153	17.1127
351.724	16.0544
355.292	15.3687
358.861	14.5668
362.426	13.7422
365.99	12.6827
369.555	12.464
373.116	11.4571
376.676	11.1158
380.236	11.0015
383.793	10.4905
387.349	11.0088
390.903	11.3571
394.456	10.54
398.007	9.10425
401.56	7.79207
405.108	5.74571
408.656	5.52857
412.202	5.46809
415.746	5.57962
419.29	4.95149
422.831	5.59355
426.37	5.66738
429.909	6.38977
433.447	6.33867
436.983	6.74865
440.519	6.23515
444.052	7.36773
447.583	8.42957
451.114	9.95263
454.643	11.0405
458.169	12.0408
461.696	12.4032
465.222	13.8194
468.744	14.0393
472.267	15.2208
475.787	16.4169
479.307	16.0561
482.823	15.0906
486.341	16.1432
489.855	17.0627
493.37	16.4577
496.881	17.1479
500.391	19.3509
503.902	20.1597
507.409	18.6277
510.915	18.3076
514.42	17.8307
517.925	16.8242
521.427	15.5537
524.928	14.9125
528.427	13.4681
531.925	14.1073
535.422	13.542
538.917	13.1529
542.411	12.2758
545.903	12.1899
549.395	11.726
552.884	11.9622
556.373	11.6853
559.86	11.0553
563.346	10.3018
566.831	8.96246
570.314	8.72811
573.794	8.8464
577.274	8.25426
580.754	7.74935
584.23	8.20178
587.706	7.1117
591.181	5.36229
594.653	3.06325
598.126	2.80388
601.595	2.9972
605.065	2.07028
608.532	3.20612
611.999	4.46532
615.463	5.52507
618.928	6.23479
622.389	6.58427
625.851	7.75643
629.31	9.1679
632.767	9.99905
636.223	10.8526
639.68	12.5706
643.134	13.8945
646.586	14.3112
650.037	14.9755
653.486	15.4536
656.936	15.9762
660.383	16.3679
663.829	16.649
667.273	16.3769
670.716	16.0194
674.158	15.4959
677.598	17.009
681.035	18.0917
684.473	19.9898
687.909	20.6383
691.344	23.0351
694.778	25.1979
698.211	28.0886
701.64	28.8796
705.07	29.6212
708.498	31.1654
711.924	34.0704
715.35	35.5756
718.774	36.6505
722.196	38.4585
725.618	40.1557
729.037	41.9698
732.456	42.5355
735.873	43.4096
739.289	44.3602
742.703	46.5251
746.116	47.0064
749.529	49.7861
752.938	50.5931
756.347	51.5781
759.756	54.7097
763.162	56.7742
766.567	58.609
769.97	59.4227
773.372	60.0426
776.773	61.9535
780.174	62.1815
783.573	62.9533
786.97	62.6872
790.365	63.1902
793.76	64.7375
797.153	65.6176
800.543	65.417
803.933	65.2671
807.322	66.5466
810.71	69.0442
814.097	70.3962
817.483	71.6322
820.865	72.6722
824.248	72.8926
827.629	72.0501
831.008	71.9906
834.387	70.3011
837.765	69.2471
841.139	66.4708
844.514	64.5051
847.886	61.1774
851.259	57.2054
854.629	54.3814
857.997	51.5257
861.366	47.9468
864.732	45.0246
868.098	43.3211
871.461	41.8788
874.823	41.0428
878.184	40.0908
881.545	39.5004
884.903	37.2745
888.26	38.2205
891.616	39.9145
894.97	39.3566
898.323	38.4563
901.675	38.7545
905.026	36.4588
908.375	34.9429
911.723	34.3539
915.07	34.8486
918.415	33.8458
921.76	33.108
925.103	32.823
928.443	32.8828
931.783	30.8173
935.123	30.5496
938.461	29.5393
941.796	27.3047
945.131	27.5604
948.465	27.7731
951.797	27.2601
955.128	26.4159
958.457	25.3438
961.786	23.1859
965.113	22.5304
968.44	23.7707
971.763	23.9409
975.086	22.973
978.409	23.0423
981.729	21.9381
985.048	22.3878
988.367	21.7712
991.683	21.3334
994.998	20.5602
998.312	20.1804
1001.62	19.5579
1004.94	18.1718
1008.25	17.4406
1011.56	16.0077
1014.86	15.2129
1018.17	13.6484
1021.48	12.6459
1024.78	10.8375
1028.08	10.1444
1031.38	8.41384
1034.68	7.71963
1037.98	5.04044
1041.28	3.01608
1044.57	4.3291
1047.87	5.38201
1051.16	6.36046
1054.45	6.86441
1057.75	6.81365
1061.04	7.28535
1064.32	7.51492
1067.61	8.18629
1070.9	6.99788
1074.18	7.73017
1077.47	7.75105
1080.75	9.42812
1084.03	9.39473
1087.31	9.90424
1090.59	10.692
1093.86	11.8345
1097.14	11.153
1100.41	9.75283
1103.69	9.41338
1106.96	7.75481
1110.23	8.23088
1113.5	7.30455
1116.77	5.68299
1120.03	5.3257
1123.3	5.10219
1126.56	5.17861
1129.83	3.39475
1133.09	3.1204
1136.35	2.42864
1139.61	1.34451
1142.86	3.40927
1146.12	4.02591
1149.38	3.10639
1152.63	4.57007
1155.88	4.47562
1159.14	5.63138
1162.39	6.05419
1165.63	5.03442
1168.88	4.72313
1172.13	4.63932
1175.38	4.8951
1178.62	4.32547
1181.86	5.30301
1185.1	6.23913
1188.34	6.03846
1191.58	7.37324
1194.82	8.21742
1198.06	10.8814
1201.29	12.3214
1204.53	13.0053
1207.76	14.7373
1210.99	16.4174
1214.22	19.9835
1217.45	22.549
1220.68	25.0152
1223.91	28.3939
1227.13	30.4585
1230.36	34.1517
1233.58	38.4216
1236.8	40.9546
1240.02	42.5443
1243.24	43.9067
1246.46	45.3851
1249.67	47.2128
1252.89	48.8232
1256.1	50.1766
1259.32	51.3693
1262.53	54.3434
1265.74	54.7705
1268.95	55.7528
1272.15	58.0842
1275.36	58.3049
1278.57	58.8433
1281.77	58.3786
1284.97	58.083
1288.18	59.1095
1291.38	59.8736
1294.58	61.2365
1297.78	61.1396
1300.97	62.7555
1304.17	63.3807
1307.36	65.6275
1310.55	66.9561
1313.75	67.261
1316.94	67.0894
1320.13	67.8188
1323.32	68.4736
1326.5	68.4918
1329.69	67.4787
1332.87	67.9773
1336.06	67.8804
1339.24	67.2177
1342.42	67.0379
1345.6	65.0611
1348.78	64.3908
1351.96	63.1404
1355.13	62.802
1358.31	60.9783
1361.48	60.4041
1364.65	59.6768
1367.82	58.7488
1370.99	56.051
1374.16	54.6189
1377.33	52.7598
1380.5	51.6461
1383.66	50.8107
1386.83	49.3634
1389.99	47.1565
1393.15	44.765
1396.31	43.753
1399.47	42.7683
1402.63	41.2611
1405.78	40.3429
1408.94	41.3793
1412.1	42.2547
1415.25	43.8395
1418.4	47.3959
1421.55	51.4238
1424.7	55.2283
1427.85	59.193
1431	63.3345
1434.14	66.6143
1437.29	69.2132
1440.43	73.0138
1443.57	75.0576
1446.71	76.1927
1449.85	77.0826
1452.99	77.7209
1456.13	78.5222
1459.26	76.3484
1462.4	72.4235
1465.54	68.2064
1468.67	63.8408
1471.8	59.4027
1474.93	53.5855
1478.06	47.5828
1481.19	41.4114
1484.31	35.7651
1487.44	33.0958
1490.56	28.7153
1493.69	26.132
1496.81	23.8267
1499.93	22.5936
1503.05	21.374
1506.17	20.5665
1509.28	21.0834
1512.4	21.2032
1515.52	23.6377
1518.63	25.9101
1521.74	28.4443
1524.85	31.177
1527.96	33.7568
1531.07	35.1016
1534.18	36.533
1537.29	39.3751
1540.39	42.687
1543.5	45.8694
1546.6	48.7565
1549.7	51.0496
1552.8	54.4782
1555.9	57.9782
1559	60.8802
1562.1	64.2856
1565.19	67.6512
1568.29	70.3781
1571.38	73.8968
1574.47	76.1041
1577.56	79.56
1580.66	82.6421
1583.74	84.0825
1586.83	86.2701
1589.92	86.7297
1593.01	87.1126
1596.09	85.9363
1599.17	82.807
1602.25	79.1371
1605.34	75.6968
1608.41	73.5034
1611.49	71.7803
1614.57	69.0685
1617.65	66.8684
1620.72	65.1663
1623.79	64.7815
1626.87	65.111
1629.94	65.8543
1633.01	64.9932
1636.08	65.8135
1639.15	65.6607
1642.21	67.7462
1645.28	69.6238
1648.34	71.8124
1651.41	73.8248
1654.47	75.1409
1657.53	76.1301
1660.59	74.5523
1663.65	73.6268
1666.71	71.2329
1669.76	67.4312
1672.82	61.8819
1675.87	56.6112
1678.93	52.1706
1681.98	47.3783
1685.03	43.0549
1688.08	37.4165
1691.13	32.1809
1694.17	28.5877
1697.22	24.7921
1700.27	22
1703.31	17.8358
1706.35	13.8968
1709.39	11.1571
1712.43	10.5397
1715.47	7.68313
1718.51	8.72902
1721.55	8.12105
1724.58	6.93109
1727.62	7.64796
1730.65	8.58851
1733.68	7.80568
1736.72	7.35731
1739.74	8.0015
1742.77	7.0897
1745.8	7.33328
1748.83	6.80256
1751.85	6.53571
1754.88	5.90619
1757.9	6.28557
1760.92	5.50438
1763.95	4.61452
1766.96	5.22653
1769.98	3.64284
1773	3.09533
1776.02	1.48838
1779.03	0.329718
1782.05	0.357859
1785.06	0.584781
1788.07	1.48931
1791.08	1.4287
1794.09	2.26825
1797.1	1.86239
1800.11	3.34775
1803.12	4.01849
1806.12	4.78477
1809.12	5.30401
1812.13	6.35594
1815.13	7.23064
1818.13	7.93727
1821.13	8.02465
1824.13	7.94072
1827.13	8.2881
1830.12	8.3919
1833.12	8.46063
1836.11	8.67478
1839.1	8.8945
1842.09	7.46995
1845.09	6.14588
1848.08	5.36359
1851.06	5.43732
1854.05	5.2888
1857.04	4.72798
1860.02	5.35257
1863.01	4.2414
1865.99	4.14066
1868.97	3.51405
1871.95	3.40017
1874.93	3.4583
1877.91	3.68385
1880.89	2.74184
1882.46	3.10879
1885.45	4.42719
1888.43	5.3211
1891.42	5.08736
1894.41	5.88923
1897.39	6.65111
1900.37	7.59768
1903.36	7.57777
1906.34	7.55243
1909.32	7.67487
1912.29	6.49323
1915.27	6.01745
1918.25	5.55407
1921.23	5.99523
1924.2	6.04156
1927.17	6.34792
1930.15	5.99199
1933.12	7.4714
1936.09	8.48905
1939.06	9.22388
1942.02	9.02547
1944.99	9.68168
1947.96	9.08212
1950.92	9.30426
1953.88	9.66829
1956.85	10.8112
1959.81	11.4779
1962.77	10.2611
1965.73	10.9517
1968.69	11.5667
1971.64	11.3337
1974.6	10.7939
1977.55	9.49934
1980.51	8.85119
1983.46	7.27595
1986.41	5.53521
1989.36	4.6229
1992.31	4.25381
1995.26	3.87127
1998.21	4.85618
2001.15	4.60519
2004.1	5.51286
2007.04	6.21712
2009.99	6.5049
2012.93	6.39549
2015.87	6.37157
2018.81	7.28676
2021.75	7.93696
2024.68	9.1533
2027.62	10.0919
2030.56	10.0727
2033.49	10.8061
2036.42	11.2273
2039.36	11.8026
2042.29	12.5036
2045.22	11.4831
2048.14	11.4251
2051.07	11.7578
2054	11.5132
2056.93	10.3765
2059.85	10.8438
2062.77	11.3834
2065.7	11.4199
2068.62	11.4775
2071.54	11.7208
2074.46	11.8327
2077.38	13.1838
2080.29	13.1975
2083.21	14.0959
2086.12	14.3122
2089.04	14.6425
2091.95	14.8655
2094.86	14.0563
2097.77	13.5601
2100.68	13.4542
2103.59	13.3837
2106.5	13.4345
2109.41	13.9728
2112.31	14.3757
2115.21	15.9535
2118.12	16.8183
2121.02	18.1764
2123.92	18.6356
2126.82	20.1016
2129.72	21.3049
2132.62	23.0143
2135.51	25.0329
2138.41	27.4585
2141.31	29.2964
2144.2	32.1184
2147.09	34.4978
2149.98	36.275
2152.87	37.1139
2155.76	37.4568
2158.65	38.2673
2161.54	38.9853
2164.43	40.5216
2167.31	40.8344
2170.2	41.1792
2173.08	41.6137
2175.96	41.2834
2178.84	41.9649
2181.72	41.6412
2184.6	41.1574
2187.48	40.877
2190.36	40.2954
2193.23	38.7857
2196.11	37.4916
2198.98	36.1164
2201.85	35.0101
2204.72	33.9259
2207.59	32.1346
2210.46	30.7254
2213.33	29.4781
2216.2	28.1173
2219.07	27.056
2221.93	25.2231
2224.8	22.7139
2227.66	20.7768
2230.52	20.4531
2233.39	19.417
2236.25	19.1912
2239.1	17.9972
2241.96	17.4161
2244.82	17.2968
2247.68	17.1999
2250.53	17.1335
2253.38	17.3034
2256.24	18.3231
2259.09	17.9917
2261.94	16.8146
2264.79	15.9439
2267.64	15.0163
2270.49	14.843
2273.33	14.5519
2276.18	13.2065
2279.02	13.7295
2281.87	13.5629
2284.71	13.0564
2287.55	12.3822
2290.39	11.0541
2293.23	8.61417
2296.07	7.50149
2298.91	8.46355
2301.74	8.01079
2304.58	8.3433
2307.41	9.22344
2310.25	9.73134
2313.08	9.55437
2315.91	9.76954
2318.74	10.1367
2321.57	10.3881
2324.4	9.96504
2327.23	9.37897
2330.05	8.11325
2332.88	7.91053
2335.7	6.64963
2338.52	6.55888
2341.35	5.32059
2344.17	4.17643
2346.99	3.32223
2349.81	3.24142
2352.62	2.07632
2355.44	1.55757
2358.26	1.00828
2361.07	1.20401
2363.89	1.88382
2366.7	2.34534
2369.51	2.65684
2372.32	3.61009
2375.13	4.48907
2377.94	4.79697
2380.75	5.47953
2383.56	4.73704
2386.36	5.17054
2389.17	5.25846
2391.97	5.35351
2394.77	5.13595
2397.58	5.28727
2400.38	5.18825
2403.18	5.01919
2405.97	5.1559
2408.77	4.84363
2411.57	5.49806
2414.37	5.76384
2417.16	6.61858
2419.95	7.2032
2422.75	6.94332
2425.54	7.50484
2428.33	7.57176
2431.12	7.03034
2433.91	6.3827
2436.7	5.65575
2439.48	5.54281
2442.27	4.75906
2445.05	4.43883
2447.84	3.42228
2450.62	2.5803
2453.4	1.67623
2456.18	1.78724
2458.96	1.82921
2461.74	1.90872
2464.52	1.90628
2467.29	1.8213
2470.07	1.70571
2472.85	2.33448
2475.62	1.88238
2478.39	2.01168
2481.16	1.1128
2483.93	1.56109
2486.7	1.95831
2489.47	1.76252
2492.24	2.09988
2495.01	2.01092
2497.77	0.945461
2500.54	0.147355
2503.3	0.170583
2506.06	0.462133
2508.83	-0.11394
2511.59	-0.0842456
2514.35	0.340484
2517.11	0.282785
2519.86	1.55622
2522.62	2.33625
2525.38	3.2377
2528.13	3.87161
2530.89	3.93104
2533.64	4.0828
2536.39	4.02282
2539.14	3.88797
2541.89	4.11327
2544.64	3.44506
2547.39	3.09628
2550.14	2.84271
2552.88	3.40504
2555.63	3.03831
2558.37	3.34114
2561.11	2.32927
2563.86	1.95195
2566.6	1.77721
2569.34	1.69688
2572.08	1.0285
2574.82	1.12611
2577.55	1.40468
2580.29	2.05426
2583.02	2.04216
2585.76	2.86853
2588.49	3.29842
2591.22	3.10061
2593.96	3.40506
2596.69	3.84103
2599.42	3.66005
2602.14	4.39726
2604.87	3.70982
2607.6	3.22891
2610.32	3.39118
2613.05	3.35299
2615.77	3.6473
2618.49	3.80585
2621.22	4.79781
2623.94	4.18819
2626.66	3.91489
2629.37	3.96288
2632.09	4.03047
2634.81	3.89787
2637.53	3.37341
2640.24	3.70858
2642.96	4.39599
2645.67	4.18533
2648.38	3.74896
2651.09	4.50728
2653.8	4.6235
2656.51	5.01555
2659.22	5.05641
2661.93	4.39143
2664.63	5.4036
2667.34	5.19347
2670.04	5.4671
2672.75	5.40253
2675.45	5.46243
2678.15	6.3224
2680.85	6.70954
2683.55	7.79521
2686.25	7.77332
2688.94	7.21908
2691.64	6.79694
2694.34	7.12606
2697.03	7.10119
2699.73	6.37222
2702.42	6.46998
2705.11	6.55817
2707.8	7.32781
2710.49	7.5078
2713.18	7.33955
2715.87	7.98198
2718.55	8.13128
2721.24	7.53606
2723.93	7.36195
2726.61	6.75431
2729.29	6.72505
2731.98	6.23197
2734.66	5.87104
2737.34	4.39104
2740.02	4.50114
2742.7	3.99328
2745.37	3.63639
2748.05	2.91845
2750.72	2.46068
2753.4	2.12823
2756.07	2.06965
2758.75	1.7683
2761.42	1.34251
2764.09	0.910263
2766.76	1.18127
2769.43	1.14151
2772.1	1.23773
2774.76	1.94935
2777.43	1.99078
2780.1	1.98398
2782.76	1.9121
2785.42	1.69894
2788.09	1.82181
2790.75	1.56852
2793.41	0.898795
2796.07	0.665774
2798.73	0.140283
2801.39	-0.371585
2804.04	-0.882586
2806.7	-0.171411
2809.35	0.605024
2812.01	0.900121
2814.66	1.53273
2817.31	2.58605
2819.96	3.29814
2822.61	4.67168
2825.26	5.882
2827.91	7.7377
2830.56	9.58958
2833.21	11.6908
2835.85	14.6214
2838.5	18.4733
2841.14	22.2402
2843.78	26.8494
2846.42	32.2104
2849.06	37.5704
2851.71	44.7779
2854.34	50.5402
2856.98	57.008
2859.62	63.2312
2862.26	69.3232
2864.89	74.6469
2867.53	79.8954
2870.16	85.6047
2872.79	90.5397
2875.42	93.9379
2878.05	96.3896
2880.68	99.466
2883.31	101.556
2885.94	103.965
2888.57	106.24
2891.19	108.491
2893.82	111.907
2896.44	114.765
2899.07	120.021
2901.69	125.209
2904.31	131.416
2906.93	138.854
2909.55	147.922
2912.17	156.499
2914.79	165.737
2917.41	173.414
2920.02	180.675
2922.64	186.555
2925.25	191.325
2927.86	195.112
2930.48	197.278
2933.09	198.341
2935.7	196.604
2938.31	194.545
2940.92	191.384
2943.53	186.852
2946.13	181.458
2948.74	175.273
2951.34	168.593
2953.95	162.917
2956.55	156.595
2959.15	150.416
2961.75	144.616
2964.35	138.78
2966.95	132.845
2969.55	126.946
2972.15	120.572
2974.75	115.22
2977.34	108.767
2979.94	102.057
2982.53	94.4629
2985.13	87.1563
2987.72	79.5087
2990.31	71.399
2992.9	63.1849
2995.49	54.9814
2998.08	48.0546
3000.67	41.8535
3003.25	35.9073
3005.84	30.3609
3008.42	25.1388
3011.01	20.6026
3013.59	18.2156
3016.17	15.7354
3018.76	14.0015
3021.34	11.8907
3023.92	11.1059
3026.49	10.2284
3029.07	8.78701
3031.65	8.93283
3034.23	9.25033
3036.8	10.6313
3039.38	11.6233
3041.95	13.1325
3044.52	14.2305
3047.09	14.7877
3049.66	15.6699
3052.23	15.9214
3054.8	15.94
3057.37	15.6463
3059.94	15.6153
3062.5	15.5386
3065.07	15.1437
3067.63	13.5912
3070.2	12.2841
3072.76	10.3496
3075.32	9.17141
3077.88	7.58163
3080.44	5.46188
3083	3.80193
3085.56	2.29138
3088.12	0.81234
3090.67	-0.0425198
3093.23	-0.341644
3095.78	-0.208942
3098.34	-0.340817
3100.89	0.0429696
3103.44	0.175685
3105.99	0.456026
3108.54	0.317278
3111.09	0.515631
3113.64	0.863478
3116.19	1.05136
3118.74	1.15457
3121.28	2.37544
3123.83	3.18271
3126.37	3.53633
3128.91	4.02151
3131.46	4.57557
3134	5.28242
3136.54	6.43713
3139.08	8.17659
3141.62	10.2384
3144.16	12.7821
3146.69	15.7931
3149.23	18.7571