File: data/Raman/poly_smoothed/Thy_00_07_18_1x_45s_532 nm_x100_100%_600 gr_mm_01.txt
#Acq. time (s)=	45
#Accumulations=	2
#Range (cm-¹)=	200...3150
#Windows=	2
#Auto scanning=	Off
#Autofocus=	Off
#Macrospot=	Off
#AutoExposure=	Off
#Spike filter=	Multiple accum.
#Delay time (s)=	0
#Binning=	1
#Readout mode=	Signal
#DeNoise=	Off
#ICS correction=	On
#Dark correction=	Off
#Inst. Process=	Off
#Detector Gain=	Best Dynamic Range
#Detector ADC=	20 kHz
#Detector temperature (°C)=	-69.85
#Instrument=	LabRAM HR Evol
#Detector=	Synapse
#Objective=	x100
#Grating=	600 gr/mm
#ND Filter=	100%
#Laser (nm)=	532
#Hole=	100.021
#Range=	Auto
#Laser Pol.=	No
#Raman. Pol.=	No
#Laser Pol. (°)=	-0.0007625
#Raman Pol. (°)=	89.9995
#Collection=	Microscope
#StageXY=	Marzhauser
#StageZ=	Marzhauser
#X (µm)=	9020.2
#Y (µm)=	-3078.4
#Z (µm)=	-54.75
#Full time(mm:ss)=	3:19
#Project=
#Sample=
#Site=
#Title=	Thy_00_07_18_2x_45s_532 nm_x100_100%_600 gr_mm
#Remark=
#Date=	28.06.2022 11:22
#Acquired=	28.06.2022 11:22:50
#Base:Fit=	10.08.2022 10:07:56
#Base:Sub=	10.08.2022 10:08:40
#Filter:Polynom=	16.08.2022 10:26:06
#AxisType[0]=Intens
#AxisUnit[0]=Cnt
#AxisType[1]=Spectr
#AxisUnit[1]=1/cm
200.407	8.49677
204.035	8.19154
207.665	7.90213
211.291	7.86863
214.916	8.63513
218.541	10.0998
222.163	9.98802
225.785	8.80829
229.404	9.56067
233.022	9.40888
236.638	10.9881
240.255	10.425
243.868	9.90255
247.48	8.98267
251.091	8.41616
254.702	7.89061
258.31	7.60332
261.916	7.63678
265.521	7.74921
269.125	6.89646
272.727	7.2347
276.328	6.70461
279.927	4.16017
283.525	2.68412
287.121	1.98451
290.716	0.011719
294.31	0.109422
297.9	-0.576635
301.491	1.27323
305.081	3.23072
308.669	3.71922
312.256	4.54688
315.839	6.3784
319.423	8.30273
323.006	9.86623
326.585	10.868
330.165	11.1565
333.741	11.0254
337.318	14.2405
340.894	15.1908
344.466	13.9485
348.039	13.3018
351.608	14.1131
355.176	14.7444
358.745	15.0693
362.31	15.6617
365.876	16.5771
369.439	16.391
373	16.1356
376.56	14.84
380.12	14.8285
383.677	15.1731
387.233	16.0838
390.787	15.6386
394.34	15.137
397.894	14.5731
401.444	13.686
404.993	12.4832
408.54	11.4089
412.086	10.6063
415.631	9.53434
419.174	8.79088
422.716	7.25825
426.257	5.86185
429.794	3.90406
433.332	1.97158
436.868	2.30954
440.403	2.81306
443.937	2.58413
447.468	3.85792
450.999	5.85375
454.528	7.24082
458.057	9.04298
461.582	10.6627
465.107	12.9779
468.629	13.2306
472.152	14.9229
475.672	16.219
479.192	16.82
482.709	17.8906
486.226	18.8663
489.74	19.4928
493.255	19.8877
496.767	20.5736
500.277	20.7003
503.788	19.4833
507.295	18.8263
510.801	17.8198
514.308	17.9824
517.811	15.5722
521.313	13.5975
524.814	11.3685
528.313	10.7726
531.811	9.89291
535.308	10.0822
538.803	9.94786
542.297	9.48359
545.789	9.24337
549.281	8.06817
552.771	6.24257
556.259	5.12816
559.747	4.21463
563.233	3.30909
566.717	2.58051
570.2	2.95969
573.68	0.954795
577.161	0.245555
580.64	0.182164
584.118	-0.341543
587.593	0.0451882
591.068	0.698406
594.54	1.00018
598.013	1.89961
601.484	1.93102
604.952	2.57761
608.421	3.1054
611.886	4.56378
615.35	5.37243
618.815	6.28089
622.276	6.86475
625.738	7.97119
629.197	8.46298
632.655	8.36948
636.113	8.49028
639.568	8.524
643.021	7.48785
646.473	6.36534
649.924	6.90226
653.376	6.47196
656.824	6.4002
660.271	7.07906
663.716	7.10375
667.161	7.35046
670.604	8.34442
674.045	10.4328
677.486	12.8464
680.925	13.7174
684.361	16.4479
687.797	18.0437
691.232	21.609
694.666	23.9915
698.099	26.2536
701.528	28.4579
704.958	30.8396
708.387	31.6055
711.814	33.3902
715.238	34.6068
718.663	36.798
722.084	39.4141
725.506	39.768
728.925	41.2183
732.345	44.0915
735.761	46.8249
739.178	49.4156
742.592	52.2935
746.006	54.3045
749.417	57.9694
752.827	60.3842
756.236	63.8432
759.645	68.3499
763.051	70.8862
766.456	73.6283
769.859	75.2388
773.261	77.079
776.664	77.0073
780.064	77.885
783.462	76.3657
786.859	76.2815
790.255	74.4872
793.649	74.7243
797.042	76.2801
800.434	76.1807
803.823	75.5542
807.212	72.3914
810.6	71.3074
813.987	70.8209
817.372	71.1791
820.754	70.2326
824.137	69.7485
827.519	69.4234
830.897	70.3603
834.276	68.0114
837.654	66.9753
841.029	65.9832
844.404	62.3135
847.776	59.5226
851.149	57.7437
854.519	55.0932
857.889	51.5088
861.256	48.9441
864.622	46.0325
867.988	43.1255
871.351	42.3957
874.713	40.3395
878.074	40.6272
881.435	39.7897
884.794	38.8922
888.15	37.009
891.506	36.4086
894.861	37.4164
898.214	37.819
901.566	37.447
904.916	38.4156
908.266	39.2668
911.614	40.1805
914.961	39.471
918.306	38.4802
921.651	37.6798
924.994	37.6874
928.336	37.3425
931.674	37.8168
935.014	37.512
938.352	37.5284
941.687	35.501
945.022	33.547
948.357	32.7195
951.688	31.4651
955.02	32.8229
958.348	32.1161
961.678	30.486
965.004	29.8972
968.331	30.9045
971.655	31.5869
974.979	30.7634
978.3	31.5181
981.62	29.3143
984.941	27.834
988.259	27.9117
991.575	27.5931
994.89	27.4454
998.204	27.6116
1001.52	27.0866
1004.83	27.3695
1008.14	27.8849
1011.45	29.2059
1014.76	30.9052
1018.06	31.022
1021.37	30.3545
1024.67	28.8385
1027.97	28.5733
1031.27	28.9289
1034.57	29.1621
1037.87	28.6071
1041.17	26.8713
1044.47	26.5327
1047.76	27.3129
1051.06	26.7804
1054.35	25.2265
1057.64	23.9024
1060.93	20.8964
1064.22	20.0414
1067.5	20.2698
1070.79	20.2148
1074.08	20.2708
1077.36	20.9689
1080.64	20.614
1083.92	20.164
1087.2	19.4107
1090.48	22.1016
1093.76	23.5966
1097.03	22.5878
1100.31	22.4608
1103.58	22.0967
1106.85	21.552
1110.12	22.0128
1113.39	22.0273
1116.66	20.0826
1119.93	18.9252
1123.19	16.2949
1126.46	14.933
1129.72	12.742
1132.98	11.5645
1136.24	10.2007
1139.5	9.64305
1142.76	9.66335
1146.01	9.25172
1149.27	8.77621
1152.53	9.18276
1155.78	9.65574
1159.03	7.9242
1162.28	7.23268
1165.53	6.97369
1168.78	8.22789
1172.02	9.2179
1175.27	8.46461
1178.51	9.33692
1181.76	10.3029
1185	11.082
1188.24	12.6556
1191.48	13.7739
1194.71	14.6778
1197.95	16.0983
1201.19	17.3834
1204.42	18.8496
1207.65	20.6735
1210.88	22.0114
1214.12	25.3124
1217.35	27.6681
1220.57	30.4684
1223.8	34.1237
1227.03	38.4562
1230.25	41.5737
1233.47	44.2548
1236.69	45.8839
1239.92	47.827
1243.13	49.1783
1246.35	48.7352
1249.57	47.0716
1252.78	45.8466
1256	45.8843
1259.21	45.4582
1262.42	44.3879
1265.63	43.4253
1268.84	40.929
1272.05	40.9425
1275.26	40.8099
1278.46	40.7018
1281.67	40.1319
1284.87	41.261
1288.07	43.0784
1291.27	46.0145
1294.47	48.5543
1297.67	51.0236
1300.87	55.7051
1304.06	59.2813
1307.26	62.7905
1310.45	66.3434
1313.64	70.0955
1316.83	71.7377
1320.02	73.2967
1323.21	71.5536
1326.4	71.5987
1329.59	70.9209
1332.77	69.5009
1335.95	68.4491
1339.14	66.6942
1342.32	63.4606
1345.5	61.0819
1348.67	59.0914
1351.85	58.5163
1355.03	56.4736
1358.2	55.9239
1361.38	54.25
1364.55	53.8335
1367.72	54.956
1370.89	55.005
1374.06	54.4001
1377.23	54.6945
1380.39	54.6393
1383.56	55.3619
1386.72	54.978
1389.89	54.035
1393.05	52.3318
1396.21	49.5961
1399.37	48.0249
1402.52	46.5382
1405.68	46.1339
1408.84	45.4432
1411.99	44.8651
1415.15	46.3606
1418.3	47.5134
1421.45	50.193
1424.6	52.8439
1427.75	56.5645
1430.89	60.4264
1434.04	63.0118
1437.18	65.5538
1440.33	69.0328
1443.47	71.8208
1446.61	74.9769
1449.75	76.1913
1452.89	77.3262
1456.03	77.0947
1459.16	75.432
1462.3	73.3956
1465.43	69.3878
1468.56	66.2762
1471.7	61.614
1474.83	56.0681
1477.96	52.5929
1481.08	49.1166
1484.21	43.1372
1487.34	39.883
1490.46	36.9225
1493.58	32.5734
1496.71	31.1883
1499.83	28.8919
1502.95	26.036
1506.07	23.0168
1509.18	22.2417
1512.3	19.4636
1515.41	19.543
1518.53	18.9705
1521.64	18.79
1524.75	19.1133
1527.86	20.3843
1530.97	23.1381
1534.08	24.9176
1537.19	27.3181
1540.29	29.9727
1543.4	33.0522
1546.5	35.846
1549.6	39.4336
1552.7	43.0564
1555.8	48.9413
1558.9	50.5701
1562	54.8679
1565.09	57.3454
1568.19	59.3
1571.28	61.2492
1574.37	63.4485
1577.47	63.7614
1580.56	65.8416
1583.64	66.3568
1586.73	66.6638
1589.82	66.3482
1592.9	66.3666
1595.99	65.0176
1599.07	63.0023
1602.15	60.9156
1605.23	59.9639
1608.31	58.4506
1611.39	56.5215
1614.47	54.893
1617.55	55.3986
1620.62	54.4958
1623.7	56.0051
1626.77	56.5498
1629.84	57.2619
1632.91	57.6124
1635.98	59.6282
1639.05	59.5147
1642.11	61.9882
1645.18	64.1815
1648.24	65.6134
1651.31	66.3201
1654.37	66.762
1657.43	67.6204
1660.49	67.3489
1663.55	66.2054
1666.61	64.3542
1669.66	62.3768
1672.72	59.2741
1675.77	55.9954
1678.83	53.7127
1681.88	51.6939
1684.93	50.0569
1687.98	47.2325
1691.03	44.3746
1694.07	41.4644
1697.12	38.375
1700.17	34.1315
1703.21	30.3483
1706.25	28.7185
1709.29	26.8444
1712.33	24.6642
1715.37	22.9225
1718.41	21.4081
1721.45	17.8127
1724.49	16.3421
1727.52	14.3011
1730.55	12.6965
1733.59	11.2543
1736.62	10.9226
1739.65	9.84346
1742.68	8.81398
1745.7	9.57157
1748.73	9.02032
1751.76	10.109
1754.78	11.3232
1757.8	12.343
1760.83	12.9299
1763.85	12.1267
1766.87	12.2296
1769.89	12.366
1772.9	11.1771
1775.92	10.9604
1778.94	11.8082
1781.95	12.5033
1784.96	12.5259
1787.97	11.6898
1790.99	11.2829
1794	9.89982
1797	8.93264
1800.01	8.36801
1803.02	7.20167
1806.02	7.66418
1809.03	7.15226
1812.03	6.53499
1815.03	6.25874
1818.03	6.49936
1821.03	6.57795
1824.03	8.38999
1827.03	8.32329
1830.02	8.75767
1833.02	8.63032
1836.01	8.82466
1839.01	8.81636
1842	9.65882
1844.99	9.15843
1847.98	8.87663
1850.97	9.24357
1853.95	9.10777
1856.94	7.92616
1859.93	6.94045
1862.91	5.72727
1865.89	4.52531
1868.87	4.29076
1871.85	4.62751
1874.83	4.87232
1877.81	5.97058
1880.79	5.76631
1882.52	6.61056
1885.51	7.26048
1888.5	8.51272
1891.49	8.74121
1894.47	8.614
1897.46	8.1624
1900.44	8.51136
1903.42	8.97047
1906.4	8.37774
1909.38	8.92087
1912.36	8.84148
1915.34	8.60071
1918.32	9.13796
1921.29	8.57233
1924.27	6.86804
1927.24	4.67023
1930.21	3.84467
1933.18	4.33113
1936.15	4.10923
1939.12	3.50129
1942.09	3.69053
1945.06	3.54469
1948.02	3.30685
1950.99	2.48759
1953.95	1.36085
1956.91	0.9051
1959.88	0.854682
1962.84	0.143934
1965.8	-0.117109
1968.75	0.358733
1971.71	0.743794
1974.67	1.11565
1977.62	1.92219
1980.58	2.22651
1983.53	3.57309
1986.48	3.74023
1989.43	5.24696
1992.38	6.16785
1995.33	5.71776
1998.27	5.50853
2001.22	6.37337
2004.16	6.65156
2007.11	7.1466
2010.05	6.99978
2012.99	7.27887
2015.93	7.53124
2018.87	7.35019
2021.81	7.49992
2024.75	6.69385
2027.69	7.68197
2030.62	8.04039
2033.56	8.02611
2036.49	7.92985
2039.42	8.22786
2042.35	7.75873
2045.28	7.01412
2048.21	6.37711
2051.14	6.07673
2054.07	5.7424
2056.99	5.60029
2059.92	4.92213
2062.84	5.12447
2065.76	5.41004
2068.68	4.76462
2071.6	5.00551
2074.52	4.61351
2077.44	4.05314
2080.36	4.60809
2083.27	5.46318
2086.19	5.73981
2089.1	6.34469
2092.02	5.90782
2094.93	5.61998
2097.84	6.09144
2100.75	6.45754
2103.66	5.88487
2106.56	5.64465
2109.47	6.11079
2112.38	5.12301
2115.28	4.71262
2118.18	4.44493
2121.09	4.24465
2123.99	3.99844
2126.89	2.83525
2129.79	2.98789
2132.68	3.01229
2135.58	2.13198
2138.48	3.15289
2141.37	2.87817
2144.27	2.70417
2147.16	2.46393
2150.05	2.89838
2152.94	4.98673
2155.83	5.25141
2158.72	4.76639
2161.6	4.48621
2164.49	4.47013
2167.38	4.84254
2170.26	5.19963
2173.14	5.10038
2176.03	4.79421
2178.91	4.58326
2181.79	4.41181
2184.67	3.73043
2187.54	3.49082
2190.42	3.21564
2193.3	2.97926
2196.17	3.91735
2199.05	4.23701
2201.92	3.70594
2204.79	3.80314
2207.66	4.62962
2210.53	5.5749
2213.4	5.92267
2216.27	6.68564
2219.13	8.12051
2222	8.37745
2224.86	8.56373
2227.72	7.42279
2230.59	6.76812
2233.45	6.45458
2236.31	6.58072
2239.17	5.69405
2242.03	5.9223
2244.88	4.64586
2247.74	4.20853
2250.59	4.0294
2253.45	3.87448
2256.3	4.10077
2259.15	4.373
2262	5.03237
2264.85	4.74324
2267.7	3.9257
2270.55	3.18638
2273.4	3.13936
2276.24	5.05657
2279.09	5.10935
2281.93	5.61448
2284.77	5.25741
2287.62	5.39636
2290.46	4.46708
2293.3	3.3317
2296.13	3.59081
2298.97	4.03199
2301.81	6.03107
2304.64	6.73211
2307.48	7.73308
2310.31	8.22263
2313.14	7.80124
2315.98	8.08032
2318.81	9.14491
2321.64	9.63883
2324.46	9.7277
2327.29	9.32577
2330.12	8.48433
2332.94	6.89086
2335.77	6.09779
2338.59	5.23645
2341.41	4.96681
2344.23	4.59865
2347.05	3.87294
2349.87	3.13812
2352.69	2.3949
2355.51	1.51473
2358.32	0.513477
2361.14	0.318173
2363.95	0.913523
2366.76	1.53149
2369.58	2.47884
2372.39	1.918
2375.2	2.08729
2378	2.18579
2380.81	1.78177
2383.62	1.37914
2386.43	2.25229
2389.23	2.64251
2392.03	3.03964
2394.84	3.3616
2397.64	3.89642
2400.44	4.09325
2403.24	5.27996
2406.04	6.34853
2408.84	7.27564
2411.63	9.38403
2414.43	10.0418
2417.22	10.8125
2420.02	10.9429
2422.81	12.3844
2425.6	13.2187
2428.39	12.8847
2431.18	12.2274
2433.97	12.6463
2436.76	12.6034
2439.54	12.789
2442.33	11.827
2445.12	11.531
2447.9	11.5604
2450.68	10.3149
2453.46	9.88793
2456.24	10.4808
2459.02	10.0062
2461.8	9.65448
2464.58	9.68887
2467.36	8.53486
2470.13	8.5972
2472.91	8.54609
2475.68	8.00816
2478.45	7.11608
2481.23	6.06533
2484	4.62077
2486.77	3.98383
2489.54	3.28124
2492.3	2.21716
2495.07	1.53976
2497.84	1.80052
2500.6	1.50124
2503.36	1.72878
2506.13	1.58886
2508.89	1.8128
2511.65	2.56984
2514.41	3.11917
2517.17	3.51945
2519.93	4.71591
2522.68	6.18442
2525.44	8.09256
2528.19	7.43417
2530.95	7.58524
2533.7	7.70279
2536.45	7.48154
2539.2	7.05285
2541.95	7.62105
2544.7	7.02836
2547.45	7.03642
2550.2	7.25134
2552.94	6.81907
2555.69	8.15099
2558.43	8.26301
2561.18	8.40238
2563.92	8.86132
2566.66	8.45468
2569.4	7.76699
2572.14	7.59888
2574.88	6.96939
2577.61	6.00252
2580.35	5.29893
2583.09	5.32607
2585.82	6.57583
2588.55	6.38544
2591.29	5.88765
2594.02	5.16115
2596.75	4.89285
2599.48	4.94012
2602.21	4.45538
2604.93	5.06525
2607.66	5.64336
2610.39	4.98798
2613.11	3.91953
2615.83	4.37758
2618.56	5.50935
2621.28	5.97064
2624	6.73191
2626.72	6.45517
2629.44	6.66886
2632.15	6.10508
2634.87	6.08439
2637.59	5.55066
2640.3	5.36555
2643.02	4.73645
2645.73	4.82114
2648.44	6.1598
2651.15	6.12328
2653.86	6.22783
2656.57	5.93137
2659.28	6.11174
2661.99	6.99676
2664.69	6.38807
2667.4	6.31498
2670.1	6.6548
2672.81	5.8576
2675.51	4.48317
2678.21	3.96338
2680.91	4.84718
2683.61	5.2506
2686.31	5.33117
2689	5.59138
2691.7	5.59036
2694.4	6.64444
2697.09	7.62875
2699.79	7.8934
2702.48	8.9205
2705.17	9.99287
2707.86	10.2117
2710.55	11.5724
2713.24	10.9115
2715.93	11.3409
2718.62	10.5006
2721.3	10.2685
2723.99	9.86882
2726.67	9.88213
2729.35	9.00468
2732.04	8.82794
2734.72	8.1353
2737.4	7.59618
2740.08	6.43795
2742.76	4.90471
2745.43	5.14768
2748.11	5.59595
2750.79	5.04051
2753.46	4.79928
2756.14	4.95761
2758.81	5.27545
2761.48	5.31597
2764.15	5.00772
2766.82	5.27014
2769.49	5.20024
2772.16	5.03664
2774.82	4.61031
2777.49	3.77741
2780.16	3.83762
2782.82	3.22052
2785.48	3.36075
2788.15	2.98221
2790.81	2.12556
2793.47	1.82513
2796.13	1.58394
2798.79	1.92036
2801.44	0.51979
2804.1	0.0701604
2806.76	0.00855739
2809.41	0.0969891
2812.07	0.531148
2814.72	0.657554
2817.37	1.01379
2820.02	1.99197
2822.67	3.20954
2825.32	4.00089
2827.97	5.34646
2830.62	7.97938
2833.26	11.3026
2835.91	14.2946
2838.56	17.4579
2841.2	21.789
2843.84	25.9992
2846.48	31.0414
2849.12	35.1165
2851.77	41.7751
2854.4	47.6044
2857.04	53.499
2859.68	60.0717
2862.32	66.5366
2864.95	71.4976
2867.59	76.9892
2870.22	82.2614
2872.85	87.0555
2875.48	90.6712
2878.11	95.274
2880.74	99.1284
2883.37	102.098
2886	104.985
2888.63	107.016
2891.25	109.974
2893.88	113.468
2896.5	117.224
2899.13	121.538
2901.75	125.81
2904.37	131.081
2906.99	136.781
2909.61	142.42
2912.23	148.918
2914.85	156.133
2917.46	162.635
2920.08	168.868
2922.7	173.725
2925.31	177.304
2927.92	179.859
2930.54	180.191
2933.15	180.058
2935.76	179.647
2938.37	176.783
2940.98	173.432
2943.58	168.512
2946.19	162.985
2948.8	157.369
2951.4	150.966
2954.01	144.75
2956.61	138.476
2959.21	131.772
2961.81	125.908
2964.41	120.296
2967.01	114.301
2969.61	109.323
2972.21	103.265
2974.81	97.3275
2977.4	93.0105
2980	87.4638
2982.59	81.7518
2985.18	74.9924
2987.78	67.9744
2990.37	61.2728
2992.96	54.9032
2995.55	49.8224
2998.14	44.5971
3000.73	39.4504
3003.31	33.4211
3005.9	28.4358
3008.48	24.1234
3011.07	20.3255
3013.65	17.4103
3016.23	13.4585
3018.81	11.4222
3021.4	9.15399
3023.97	6.34206
3026.55	4.11988
3029.13	3.46088
3031.71	2.77726
3034.28	2.13253
3036.86	2.19401
3039.43	2.23825
3042.01	3.00625
3044.58	3.74621
3047.15	4.17861
3049.72	5.18493
3052.29	6.14185
3054.86	7.35886
3057.43	8.09995
3060	8.88105
3062.56	8.37117
3065.13	8.2361
3067.69	7.32784
3070.26	7.59533
3072.82	6.29018
3075.38	6.08533
3077.94	5.76439
3080.5	4.24567
3083.06	2.65327
3085.62	2.07428
3088.18	0.729875
3090.73	0.350811
3093.29	0.686428
3095.84	1.2951
3098.4	1.48128
3100.95	3.31099
3103.5	4.22843
3106.05	6.13338
3108.6	7.79875
3111.15	9.17418
3113.7	11.0074
3116.25	12.4994
3118.79	13.7359
3121.34	14.9905
3123.88	17.3899
3126.43	19.2097
3128.97	20.6428
3131.51	23.2511
3134.06	25.4441
3136.6	26.9312
3139.14	29.6678
3141.67	31.3033
3144.21	33.6098
3146.75	36.6862
3149.29	40.3729