File: data/Raman/poly_smoothed/Thy_20_09_16_1x_45s_532 nm_x100_100%_600 gr_mm_01.txt
#Acq. time (s)=	45
#Accumulations=	2
#Range (cm-¹)=	200...3150
#Windows=	2
#Auto scanning=	Off
#Autofocus=	Off
#Macrospot=	Off
#AutoExposure=	Off
#Spike filter=	Multiple accum.
#Delay time (s)=	0
#Binning=	1
#Readout mode=	Signal
#DeNoise=	Off
#ICS correction=	On
#Dark correction=	Off
#Inst. Process=	Off
#Detector Gain=	Best Dynamic Range
#Detector ADC=	20 kHz
#Detector temperature (°C)=	-69.85
#Instrument=	LabRAM HR Evol
#Detector=	Synapse
#Objective=	x100
#Grating=	600 gr/mm
#ND Filter=	100%
#Laser (nm)=	532
#Hole=	100.021
#Range=	Auto
#Laser Pol.=	No
#Raman. Pol.=	No
#Laser Pol. (°)=	-0.0007625
#Raman Pol. (°)=	89.9995
#Collection=	Microscope
#StageXY=	Marzhauser
#StageZ=	Marzhauser
#X (µm)=	-5891.9
#Y (µm)=	2875.9
#Z (µm)=	-223.1
#Full time(mm:ss)=	3:18
#Project=
#Sample=
#Site=
#Title=	Thy_20_09_16_2x_45s_532 nm_x100_100%_600 gr_mm
#Remark=
#Date=	29.06.2022 11:49
#Acquired=	29.06.2022 11:49:32
#Base:Fit=	10.08.2022 09:52:02
#Base:Fit=	10.08.2022 09:52:12
#Base:Sub=	10.08.2022 09:54:21
#Filter:Polynom=	16.08.2022 10:24:04
#AxisType[0]=Intens
#AxisUnit[0]=Cnt
#AxisType[1]=Spectr
#AxisUnit[1]=1/cm
200.523	9.51147
204.154	14.039
207.781	16.3598
211.409	16.8269
215.034	15.5647
218.659	14.3668
222.281	11.6348
225.903	10.1038
229.522	10.2291
233.14	9.58147
236.756	9.06661
240.373	9.34896
243.986	8.85586
247.598	8.12262
251.208	6.52019
254.818	5.79246
258.427	6.19881
262.034	6.25291
265.638	6.62682
269.242	5.97383
272.844	5.19903
276.445	5.96975
280.044	7.42947
283.642	8.56649
287.238	9.41319
290.833	9.41142
294.425	9.89481
298.017	9.46398
301.608	8.57454
305.198	9.07365
308.786	9.07895
312.371	10.2846
315.956	12.3766
319.54	13.6942
323.122	14.6959
326.701	15.4107
330.281	16.4694
333.857	15.9703
337.434	15.9025
341.008	15.6268
344.582	14.4792
348.153	14.0562
351.724	13.4543
355.292	11.9468
358.861	10.9625
362.426	11.0712
365.99	10.2545
369.555	9.30344
373.116	8.25407
376.676	6.62416
380.236	6.33235
383.793	7.25773
387.349	6.56843
390.903	7.12726
394.456	7.31815
398.007	8.89259
401.56	9.90523
405.108	10.2621
408.656	9.68233
412.202	9.5707
415.746	9.49039
419.29	8.38861
422.831	8.27426
426.37	7.20504
429.909	6.83705
433.447	6.68707
436.983	5.9788
440.519	5.3053
444.052	5.95056
447.583	6.63348
451.114	6.75522
454.643	7.03044
458.169	6.69047
461.696	8.07054
465.222	9.72593
468.744	11.0841
472.267	13.115
475.787	13.5034
479.307	14.2843
482.823	15.6503
486.341	16.0118
489.855	15.9111
493.37	15.809
496.881	15.6426
500.391	14.9885
503.902	15.2323
507.409	14.7513
510.915	12.7041
514.42	12.5897
517.925	14.1155
521.427	12.4217
524.928	13.7538
528.427	15.2441
531.925	14.8636
535.422	15.5724
538.917	15.4395
542.411	14.9374
545.903	14.7809
549.395	14.0936
552.884	13.1554
556.373	12.5118
559.86	9.89135
563.346	7.20078
566.831	8.16126
570.314	10.8012
573.794	13.2049
577.274	13.8064
580.754	14.6359
584.23	15.3198
587.706	16.7105
591.181	16.9755
594.653	15.9094
598.126	16.927
601.595	18.401
605.065	17.3628
608.532	16.4052
611.999	16.5033
615.463	15.9709
618.928	15.2539
622.389	14.8283
625.851	13.5445
629.31	12.8221
632.767	9.69381
636.223	10.2796
639.68	9.62583
643.134	8.31746
646.586	11.9456
650.037	14.2574
653.486	19.2075
656.936	21.1672
660.383	21.6147
663.829	23.1604
667.273	25.0785
670.716	29.0451
674.158	30.4755
677.598	30.0448
681.035	31.0509
684.473	30.5855
687.909	31.0361
691.344	30.2328
694.778	30.9184
698.211	31.0801
701.64	30.7389
705.07	31.5176
708.498	33.1157
711.924	33.4262
715.35	33.4488
718.774	36.1155
722.196	36.9306
725.618	38.5695
729.037	39.9727
732.456	39.3932
735.873	40.0458
739.289	40.6366
742.703	41.4105
746.116	42.4527
749.529	44.9379
752.938	47.6858
756.347	50.1249
759.756	50.1207
763.162	51.057
766.567	51.7952
769.97	53.1614
773.372	56.0557
776.773	58.2102
780.174	59.7218
783.573	63.1951
786.97	65.667
790.365	67.5242
793.76	69.0033
797.153	70.2325
800.543	71.6657
803.933	71.4498
807.322	71.6701
810.71	73.2465
814.097	72.2036
817.483	72.5445
820.865	71.6318
824.248	70.695
827.629	70.3981
831.008	70.0182
834.387	69.4877
837.765	69.0633
841.139	66.7152
844.514	64.4965
847.886	63.1631
851.259	61.4767
854.629	59.7847
857.997	60.2638
861.366	58.348
864.732	56.9667
868.098	55.8553
871.461	53.8938
874.823	51.1922
878.184	49.2394
881.545	48.8266
884.903	46.6054
888.26	45.5113
891.616	43.7784
894.97	42.7084
898.323	42.2319
901.675	41.5199
905.026	40.0473
908.375	39.8776
911.723	40.4584
915.07	38.2131
918.415	37.9393
921.76	36.7368
925.103	36.0172
928.443	36.5704
931.783	36.724
935.123	37.0036
938.461	38.7599
941.796	38.9691
945.131	38.1679
948.465	37.4091
951.797	37.0379
955.128	36.0793
958.457	34.1076
961.786	31.9109
965.113	31.4008
968.44	31.0061
971.763	31.6561
975.086	30.3615
978.409	31.8596
981.729	31.5355
985.048	30.9619
988.367	30.7716
991.683	29.2861
994.998	28.4332
998.312	26.3032
1001.62	25.5323
1004.94	25.6513
1008.25	25.4924
1011.56	24.3581
1014.86	23.5114
1018.17	23.3836
1021.48	21.105
1024.78	18.9869
1028.08	18.2255
1031.38	16.6456
1034.68	14.398
1037.98	11.8933
1041.28	11.7847
1044.57	12.4874
1047.87	14.9938
1051.16	14.8414
1054.45	14.4713
1057.75	14.2496
1061.04	14.3187
1064.32	14.9694
1067.61	14.3006
1070.9	12.4752
1074.18	10.8657
1077.47	10.7417
1080.75	11.2178
1084.03	12.5095
1087.31	10.869
1090.59	10.7248
1093.86	10.9216
1097.14	11.3464
1100.41	11.7628
1103.69	10.7236
1106.96	12.1828
1110.23	12.3012
1113.5	11.979
1116.77	11.7346
1120.03	11.6722
1123.3	11.4512
1126.56	12.1707
1129.83	10.2197
1133.09	9.11611
1136.35	8.26151
1139.61	7.22689
1142.86	6.16608
1146.12	3.38984
1149.38	3.11466
1152.63	1.32294
1155.88	1.83018
1159.14	1.39261
1162.39	-0.0552882
1165.63	-1.20456
1168.88	-0.859578
1172.13	-0.836157
1175.38	0.256619
1178.62	0.327839
1181.86	1.24044
1185.1	3.81332
1188.34	5.76562
1191.58	6.4137
1194.82	7.44332
1198.06	9.36025
1201.29	11.1689
1204.53	14.5815
1207.76	18.562
1210.99	20.9012
1214.22	24.1719
1217.45	26.9233
1220.68	29.8794
1223.91	31.5815
1227.13	33.2192
1230.36	35.6035
1233.58	36.562
1236.8	38.7254
1240.02	39.7558
1243.24	39.4723
1246.46	40.9626
1249.67	42.9544
1252.89	42.915
1256.1	43.5155
1259.32	45.3641
1262.53	47.0459
1265.74	48.4268
1268.95	47.944
1272.15	48.1572
1275.36	48.5672
1278.57	49.8924
1281.77	51.2675
1284.97	52.3489
1288.18	53.8844
1291.38	55.2896
1294.58	55.738
1297.78	57.1066
1300.97	57.9368
1304.17	59.6971
1307.36	59.6668
1310.55	61.4422
1313.75	62.9009
1316.94	64.1093
1320.13	64.2574
1323.32	64.2096
1326.5	65.571
1329.69	63.5985
1332.87	62.1669
1336.06	62.7101
1339.24	61.5861
1342.42	61.8668
1345.6	59.766
1348.78	57.3049
1351.96	56.7044
1355.13	55.0268
1358.31	53.4298
1361.48	52.0422
1364.65	50.9546
1367.82	49.9394
1370.99	48.1844
1374.16	47.1317
1377.33	46.7093
1380.5	45.725
1383.66	44.113
1386.83	42.227
1389.99	41.7686
1393.15	39.3229
1396.31	37.8675
1399.47	36.3602
1402.63	34.9754
1405.78	33.7687
1408.94	34.3283
1412.1	36.5754
1415.25	40.2877
1418.4	42.5106
1421.55	44.7096
1424.7	49.252
1427.85	53.8161
1431	59.0556
1434.14	61.931
1437.29	65.2292
1440.43	68.5582
1443.57	69.8884
1446.71	70.9462
1449.85	72.267
1452.99	71.7192
1456.13	70.4788
1459.26	68.5869
1462.4	63.7178
1465.54	59.0757
1468.67	53.197
1471.8	48.2965
1474.93	45.1991
1478.06	41.0147
1481.19	37.4392
1484.31	35.2221
1487.44	35.2222
1490.56	32.7249
1493.69	30.3771
1496.81	29.7844
1499.93	29.6833
1503.05	30.6677
1506.17	31.2744
1509.28	30.4791
1512.4	30.2409
1515.52	30.204
1518.63	31.3947
1521.74	30.7879
1524.85	33.6009
1527.96	34.1409
1531.07	34.9939
1534.18	35.8982
1537.29	36.5095
1540.39	36.9777
1543.5	38.777
1546.6	41.3569
1549.7	43.6775
1552.8	46.8049
1555.9	48.8233
1559	51.3713
1562.1	53.3526
1565.19	55.2867
1568.29	57.2816
1571.38	59.8112
1574.47	62.6189
1577.56	65.8499
1580.66	67.0015
1583.74	69.3031
1586.83	71.2623
1589.92	72.8015
1593.01	73.0439
1596.09	73.734
1599.17	72.8728
1602.25	71.9384
1605.34	70.4747
1608.41	67.1586
1611.49	66.1141
1614.57	64.0545
1617.65	61.4519
1620.72	59.5484
1623.79	57.8533
1626.87	57.5353
1629.94	56.1055
1633.01	55.54
1636.08	54.739
1639.15	55.6468
1642.21	56.3976
1645.28	57.713
1648.34	59.9891
1651.41	61.4879
1654.47	61.3491
1657.53	61.4967
1660.59	61.9244
1663.65	61.8087
1666.71	60.3845
1669.76	57.5508
1672.82	53.1978
1675.87	49.479
1678.93	46.1196
1681.98	41.9961
1685.03	37.1533
1688.08	35.2422
1691.13	30.9631
1694.17	27.0329
1697.22	24.2924
1700.27	22.4671
1703.31	19.7089
1706.35	16.1939
1709.39	14.3288
1712.43	12.5359
1715.47	11.5909
1718.51	11.7494
1721.55	10.6543
1724.58	9.10849
1727.62	8.64262
1730.65	7.7985
1733.68	8.10298
1736.72	8.00864
1739.74	7.09006
1742.77	6.33546
1745.8	5.45655
1748.83	6.64732
1751.85	6.47156
1754.88	6.40545
1757.9	6.24927
1760.92	6.67868
1763.95	7.13755
1766.96	6.81524
1769.98	6.54789
1773	6.79877
1776.02	5.66422
1779.03	5.34336
1782.05	5.08944
1785.06	4.49487
1788.07	4.37777
1791.08	3.83285
1794.09	3.09079
1797.1	3.31925
1800.11	2.50191
1803.12	2.41951
1806.12	2.40944
1809.12	1.9667
1812.13	1.80234
1815.13	2.26746
1818.13	2.21217
1821.13	2.43305
1824.13	1.9173
1827.13	1.76579
1830.12	2.02805
1833.12	2.73419
1836.11	3.75331
1839.1	4.89671
1842.09	5.30307
1845.09	5.86834
1848.08	6.27526
1851.06	6.48219
1854.05	7.36747
1857.04	7.0805
1860.02	7.43302
1863.01	8.1976
1865.99	8.20728
1868.97	9.08564
1871.95	9.95451
1874.93	10.1565
1877.91	9.88947
1880.89	9.13059
1882.46	9.8459
1885.45	9.9225
1888.43	9.33161
1891.42	8.64415
1894.41	7.65994
1897.39	7.21852
1900.37	6.75959
1903.36	7.08855
1906.34	7.29876
1909.32	6.265
1912.29	5.82034
1915.27	5.78887
1918.25	5.61582
1921.23	5.18535
1924.2	4.89914
1927.17	4.61039
1930.15	5.45172
1933.12	6.18679
1936.09	6.19064
1939.06	5.58808
1942.02	5.36346
1944.99	5.12402
1947.96	4.41209
1950.92	4.80327
1953.88	5.14529
1956.85	5.06505
1959.81	3.91869
1962.77	3.04174
1965.73	3.05354
1968.69	2.81561
1971.64	2.05217
1974.6	1.43395
1977.55	1.45728
1980.51	0.723529
1983.46	0.206055
1986.41	0.840342
1989.36	1.24842
1992.31	1.19744
1995.26	1.41186
1998.21	2.00283
2001.15	2.80711
2004.1	3.20466
2007.04	2.40619
2009.99	1.56429
2012.93	1.828
2015.87	2.48034
2018.81	3.08365
2021.75	3.34542
2024.68	4.02961
2027.62	4.40883
2030.56	4.36768
2033.49	4.85745
2036.42	5.54565
2039.36	5.51459
2042.29	5.18265
2045.22	5.7337
2048.14	5.91774
2051.07	5.98928
2054	6.59095
2056.93	6.99
2059.85	7.38928
2062.77	6.70057
2065.7	7.22636
2068.62	7.99189
2071.54	7.20602
2074.46	7.3667
2077.38	7.44254
2080.29	7.58205
2083.21	7.73673
2086.12	8.34029
2089.04	9.56093
2091.95	9.59815
2094.86	10.0111
2097.77	10.6124
2100.68	10.6883
2103.59	10.6544
2106.5	11.2856
2109.41	12.294
2112.31	12.471
2115.21	13.0925
2118.12	13.3193
2121.02	14.1243
2123.92	14.8819
2126.82	16.2643
2129.72	17.434
2132.62	18.0145
2135.51	19.0814
2138.41	20.9438
2141.31	21.8214
2144.2	22.9018
2147.09	24.9203
2149.98	25.5176
2152.87	27.3534
2155.76	28.9789
2158.65	30.2757
2161.54	30.8732
2164.43	30.9511
2167.31	32.0548
2170.2	32.7856
2173.08	31.993
2175.96	32.8409
2178.84	32.9397
2181.72	32.2332
2184.6	31.1651
2187.48	31.0342
2190.36	30.5421
2193.23	29.4835
2196.11	28.7282
2198.98	26.4964
2201.85	24.9543
2204.72	23.0929
2207.59	22.0437
2210.46	20.8226
2213.33	19.3884
2216.2	17.6095
2219.07	14.867
2221.93	13.6277
2224.8	12.3696
2227.66	11.2602
2230.52	9.6488
2233.39	9.17255
2236.25	8.36442
2239.1	7.90418
2241.96	6.67478
2244.82	6.47844
2247.68	7.62916
2250.53	7.923
2253.38	8.44909
2256.24	9.04829
2259.09	9.18716
2261.94	9.9175
2264.79	9.55085
2267.64	9.61315
2270.49	10.9599
2273.33	11.4856
2276.18	11.8369
2279.02	12.0637
2281.87	11.8039
2284.71	10.3513
2287.55	9.87847
2290.39	8.91268
2293.23	8.14581
2296.07	7.98288
2298.91	8.64813
2301.74	7.90688
2304.58	8.17816
2307.41	7.42543
2310.25	7.89703
2313.08	8.29291
2315.91	8.47097
2318.74	9.10149
2321.57	8.14938
2324.4	7.22954
2327.23	6.84235
2330.05	6.60601
2332.88	6.1465
2335.7	5.55773
2338.52	5.57334
2341.35	4.98133
2344.17	4.52897
2346.99	4.5333
2349.81	3.60049
2352.62	4.58669
2355.44	5.14647
2358.26	5.25056
2361.07	3.43092
2363.89	4.16054
2366.7	5.03482
2369.51	5.45197
2372.32	6.0077
2375.13	6.23945
2377.94	6.37083
2380.75	6.54854
2383.56	6.90921
2386.36	6.17144
2389.17	6.07955
2391.97	4.86677
2394.77	4.37926
2397.58	4.43607
2400.38	4.21157
2403.18	4.23012
2405.97	4.40372
2408.77	4.12497
2411.57	4.81188
2414.37	5.71054
2417.16	6.57099
2419.95	9.03562
2422.75	10.1664
2425.54	10.3184
2428.33	9.25187
2431.12	9.84563
2433.91	10.2393
2436.7	10.7089
2439.48	10.8741
2442.27	10.6688
2445.05	9.92332
2447.84	9.30326
2450.62	9.12697
2453.4	8.28147
2456.18	7.79657
2458.96	6.69748
2461.74	5.36807
2464.52	4.9964
2467.29	4.04126
2470.07	3.93351
2472.85	3.46143
2475.62	2.42263
2478.39	2.17347
2481.16	2.27436
2483.93	2.45603
2486.7	3.03852
2489.47	2.70043
2492.24	2.70068
2495.01	2.84239
2497.77	2.96999
2500.54	1.90058
2503.3	2.19827
2506.06	1.78937
2508.83	1.88272
2511.59	0.977491
2514.35	1.0308
2517.11	1.85897
2519.86	2.24554
2522.62	2.15739
2525.38	1.46257
2528.13	1.52435
2530.89	1.63419
2533.64	2.05129
2536.39	3.31263
2539.14	4.29869
2541.89	4.64702
2544.64	4.11918
2547.39	4.00174
2550.14	4.81445
2552.88	4.32462
2555.63	4.16675
2558.37	4.55721
2561.11	5.54719
2563.86	5.17797
2566.6	4.84865
2569.34	4.657
2572.08	4.59237
2574.82	4.7224
2577.55	4.38111
2580.29	3.41582
2583.02	4.31417
2585.76	4.47431
2588.49	4.10586
2591.22	3.39212
2593.96	3.63307
2596.69	2.72765
2599.42	3.10781
2602.14	3.82309
2604.87	3.97261
2607.6	2.45729
2610.32	1.73709
2613.05	1.21988
2615.77	0.413703
2618.49	0.422373
2621.22	-0.235938
2623.94	-0.734586
2626.66	-0.705723
2629.37	-0.578186
2632.09	-1.00024
2634.81	-0.591228
2637.53	-1.47497
2640.24	-1.72971
2642.96	-1.37812
2645.67	-0.00206293
2648.38	2.24997
2651.09	4.37111
2653.8	4.97291
2656.51	5.33952
2659.22	6.15396
2661.93	6.95145
2664.63	8.2028
2667.34	9.52579
2670.04	10.1248
2672.75	10.1387
2675.45	10.5744
2678.15	9.79159
2680.85	9.9407
2683.55	9.35737
2686.25	9.15616
2688.94	8.10129
2691.64	6.64122
2694.34	5.61668
2697.03	4.51453
2699.73	3.37732
2702.42	1.21214
2705.11	0.925282
2707.8	1.44502
2710.49	2.35148
2713.18	3.45196
2715.87	3.25396
2718.55	2.81743
2721.24	3.24893
2723.93	3.72579
2726.61	5.25125
2729.29	5.92334
2731.98	6.62256
2734.66	7.31432
2737.34	7.66729
2740.02	7.22227
2742.7	7.2089
2745.37	7.41304
2748.05	6.57069
2750.72	6.66435
2753.4	6.16707
2756.07	5.2417
2758.75	4.40717
2761.42	4.04429
2764.09	3.76961
2766.76	3.37323
2769.43	2.74983
2772.1	1.78792
2774.76	2.21561
2777.43	2.25656
2780.1	1.23308
2782.76	2.11176
2785.42	1.85343
2788.09	2.61482
2790.75	2.80938
2793.41	2.14425
2796.07	2.57565
2798.73	2.59198
2801.39	3.13843
2804.04	2.86611
2806.7	2.71309
2809.35	2.81475
2812.01	2.68241
2814.66	2.86722
2817.31	3.6011
2819.96	4.97294
2822.61	6.62147
2825.26	8.37312
2827.91	10.2291
2830.56	12.6151
2833.21	14.4341
2835.85	16.4625
2838.5	19.4764
2841.14	23.2399
2843.78	26.919
2846.42	31.875
2849.06	37.0451
2851.71	40.8585
2854.34	45.9731
2856.98	50.9099
2859.62	55.837
2862.26	61.2072
2864.89	65.3405
2867.53	69.5318
2870.16	71.7906
2872.79	74.3803
2875.42	78.0646
2878.05	80.3157
2880.68	82.5611
2883.31	85.3767
2885.94	87.4093
2888.57	89.1704
2891.19	91.6946
2893.82	92.8441
2896.44	95.034
2899.07	97.4298
2901.69	100.94
2904.31	106.351
2906.93	112.743
2909.55	118.059
2912.17	123.391
2914.79	129.843
2917.41	136.075
2920.02	141.166
2922.64	145.209
2925.25	148.952
2927.86	150.878
2930.48	151.044
2933.09	151.534
2935.7	151.006
2938.31	150.308
2940.92	147.392
2943.53	143.395
2946.13	139.036
2948.74	133.796
2951.34	128.813
2953.95	122.511
2956.55	116.41
2959.15	109.912
2961.75	104.932
2964.35	99.949
2966.95	95.9609
2969.55	91.2731
2972.15	86.1163
2974.75	81.1117
2977.34	76.3019
2979.94	71.8084
2982.53	66.4389
2985.13	61.0534
2987.72	55.5972
2990.31	50.1447
2992.9	44.3385
2995.49	40.2222
2998.08	36.1531
3000.67	31.4138
3003.25	27.7805
3005.84	23.5025
3008.42	20.0682
3011.01	17.0027
3013.59	14.6085
3016.17	12.1763
3018.76	11.2685
3021.34	9.38132
3023.92	7.85145
3026.49	6.98599
3029.07	6.67357
3031.65	6.44378
3034.23	6.39677
3036.8	6.62093
3039.38	7.34002
3041.95	8.27957
3044.52	9.03269
3047.09	9.44793
3049.66	9.45836
3052.23	9.90445
3054.8	10.2398
3057.37	9.67177
3059.94	9.71512
3062.5	9.85153
3065.07	8.73787
3067.63	7.57514
3070.2	6.60313
3072.76	5.96347
3075.32	4.00912
3077.88	3.15431
3080.44	2.35713
3083	0.91147
3085.56	-0.0833711
3088.12	-0.235439
3090.67	-0.0840706
3093.23	0.138779
3095.78	0.268738
3098.34	-0.108038
3100.89	1.02561
3103.44	1.06009
3105.99	1.22136
3108.54	0.586567
3111.09	0.479039
3113.64	1.15312
3116.19	1.82013
3118.74	1.96748
3121.28	2.24933
3123.83	2.94739
3126.37	2.59405
3128.91	2.84477
3131.46	3.61377
3134	3.39015
3136.54	3.59306
3139.08	5.42642
3141.62	6.49969
3144.16	7.3919
3146.69	8.17238
3149.23	8.46952