File: data/Raman/poly_smoothed/Thy_40_11_35_1x_45s_532 nm_x100_100%_600 gr_mm_01.txt
#Acq. time (s)=	45
#Accumulations=	2
#Range (cm-¹)=	200...3150
#Windows=	2
#Auto scanning=	Off
#Autofocus=	Off
#Macrospot=	Off
#AutoExposure=	Off
#Spike filter=	Multiple accum.
#Delay time (s)=	0
#Binning=	1
#Readout mode=	Signal
#DeNoise=	Off
#ICS correction=	On
#Dark correction=	Off
#Inst. Process=	Off
#Detector Gain=	Best Dynamic Range
#Detector ADC=	20 kHz
#Detector temperature (°C)=	-69.85
#Instrument=	LabRAM HR Evol
#Detector=	Synapse
#Objective=	x100
#Grating=	600 gr/mm
#ND Filter=	100%
#Laser (nm)=	532
#Hole=	100.021
#Range=	Auto
#Laser Pol.=	No
#Raman. Pol.=	No
#Laser Pol. (°)=	-0.0007625
#Raman Pol. (°)=	89.9995
#Collection=	Microscope
#StageXY=	Marzhauser
#StageZ=	Marzhauser
#X (µm)=	237.6
#Y (µm)=	1668.5
#Z (µm)=	427.35
#Full time(mm:ss)=	3:18
#Project=
#Sample=
#Site=
#Title=	Thy_40_11_35_2x_45s_532 nm_x100_100%_600 gr_mm
#Remark=
#Date=	05.07.2022 12:30
#Acquired=	05.07.2022 12:30:15
#Base:Fit=	10.08.2022 10:01:35
#Base:Sub=	10.08.2022 10:01:52
#Filter:Polynom=	16.08.2022 10:21:53
#AxisType[0]=Intens
#AxisUnit[0]=Cnt
#AxisType[1]=Spectr
#AxisUnit[1]=1/cm
200.43	1.208
204.059	5.98941
207.688	9.23491
211.314	11.3588
214.941	11.8717
218.564	11.8768
222.186	13.0109
225.809	12.13
229.428	12.7117
233.045	13.0211
236.663	13.3311
240.278	14.6637
243.891	16.2053
247.503	17.4554
251.116	17.3599
254.725	16.3398
258.333	17.1907
261.939	18.5827
265.544	19.9927
269.148	20.6323
272.75	21.5445
276.351	22.4599
279.95	23.4961
283.548	24.1651
287.144	23.7207
290.739	22.8867
294.333	23.5406
297.925	23.7194
301.514	23.8221
305.104	23.5797
308.692	25.1131
312.279	24.8245
315.862	25.1974
319.446	26.305
323.029	26.8287
326.608	27.6269
330.188	28.558
333.766	28.3308
337.341	26.8135
340.917	26.7581
344.489	26.3582
348.062	26.7852
351.631	25.3879
355.201	25.5519
358.768	25.2797
362.333	24.0515
365.899	22.5596
369.462	20.7366
373.023	18.6652
376.585	16.9694
380.143	14.5921
383.7	15.2976
387.256	13.1734
390.812	12.1739
394.365	12.953
397.916	11.1219
401.467	11.0824
405.015	10.3367
408.563	10.7488
412.109	9.70454
415.654	10.3547
419.197	10.4697
422.739	10.8798
426.279	12.5177
429.819	14.6788
433.356	15.4223
436.891	15.9136
440.426	17.235
443.96	19.1619
447.492	18.2103
451.021	17.9899
454.551	19.08
458.079	18.1727
461.604	18.8761
465.13	18.7762
468.654	18.7471
472.175	19.0584
475.696	17.7684
479.215	18.7734
482.733	19.1666
486.249	17.6749
489.765	18.5692
493.278	19.1581
496.789	19.4076
500.301	18.7702
503.81	18.2124
507.317	19.3247
510.825	20.0102
514.33	21.3446
517.833	22.3565
521.335	21.2631
524.836	22.2881
528.335	22.1738
531.835	22.0764
535.332	20.4787
538.827	20.4138
542.321	18.9251
545.814	16.6866
549.305	15.3467
552.795	13.8319
556.282	12.2375
559.769	10.754
563.255	10.2092
566.739	8.44735
570.223	6.26887
573.705	4.60705
577.183	3.71482
580.663	2.53939
584.141	2.37891
587.615	0.655074
591.09	-0.0611822
594.564	1.72409
598.035	2.69034
601.506	5.30368
604.974	5.66208
608.443	6.60184
611.908	7.88866
615.374	7.61004
618.837	6.46138
622.3	7.10286
625.761	6.56421
629.219	7.57323
632.677	8.72623
636.135	8.63957
639.59	10.1075
643.043	11.0668
646.495	12.7238
649.948	13.5301
653.398	13.3136
656.846	14.3225
660.293	14.7976
663.738	16.292
667.183	16.1576
670.626	16.811
674.067	17.5501
677.508	19.7536
680.947	21.2003
684.385	21.3866
687.821	22.7547
691.254	22.8614
694.688	24.1144
698.121	25.6409
701.552	25.8596
704.98	27.5566
708.409	29.6079
711.836	31.4628
715.26	33.6885
718.685	34.8053
722.108	34.9008
725.528	37.1894
728.949	38.2978
732.367	40.2962
735.785	41.456
739.2	43.4243
742.614	44.5984
746.028	45.9679
749.439	48.3244
752.849	49.4958
756.26	51.6786
759.667	53.0648
763.073	55.606
766.477	57.2389
769.883	58.8341
773.285	60.9833
776.686	63.6916
780.085	65.5624
783.484	66.6996
786.881	67.7871
790.276	70.1326
793.671	71.463
797.064	71.0009
800.456	72.2834
803.846	72.2365
807.234	72.7358
810.622	74.0604
814.008	74.2131
817.394	74.8289
820.778	76.3483
824.159	77.1428
827.541	76.3702
830.921	76.5122
834.298	76.4377
837.676	75.1949
841.051	73.6337
844.426	71.7898
847.798	69.4793
851.171	66.9063
854.54	63.2882
857.911	62.1633
861.278	60.0589
864.645	58.6637
868.01	57.5785
871.373	55.8205
874.735	53.1384
878.097	50.5451
881.457	49.64
884.815	47.082
888.172	45.8254
891.528	45.0806
894.882	45.4509
898.237	44.3263
901.589	45.3181
904.94	44.4852
908.289	43.0044
911.635	43.4764
914.982	41.4988
918.328	40.6447
921.672	38.4911
925.015	36.8071
928.357	36.7079
931.698	36.0444
935.035	36.0064
938.373	36.2701
941.71	35.5893
945.044	33.2915
948.378	32.4546
951.709	32.7275
955.041	31.9837
958.372	30.9277
961.699	30.375
965.027	30.1274
968.352	29.2102
971.676	29.0491
975	29.2612
978.322	29.4225
981.642	29.3879
984.962	29.3453
988.28	28.5666
991.596	26.9559
994.911	25.8349
998.227	24.3827
1001.54	23.4802
1004.85	22.9863
1008.16	21.9235
1011.47	20.465
1014.78	20.9239
1018.08	20.7603
1021.39	18.3393
1024.69	18.8809
1028	19.5916
1031.3	22.288
1034.6	23.5334
1037.9	24.0114
1041.19	24.0593
1044.49	22.9442
1047.78	24.4908
1051.08	24.6958
1054.37	24.828
1057.66	23.5018
1060.95	22.1196
1064.24	21.6408
1067.53	20.3155
1070.81	18.603
1074.1	19.2158
1077.38	18.56
1080.66	16.968
1083.94	15.811
1087.22	14.3678
1090.5	13.6166
1093.78	13.7468
1097.05	14.528
1100.33	13.0582
1103.6	11.906
1106.87	12.4792
1110.14	12.9808
1113.41	12.165
1116.68	11.0372
1119.95	9.66965
1123.21	7.82989
1126.48	7.33627
1129.74	6.93497
1133	4.78188
1136.26	3.87252
1139.52	2.46531
1142.78	2.62864
1146.04	2.188
1149.29	3.69511
1152.55	3.565
1155.8	3.40832
1159.05	1.90232
1162.3	3.11211
1165.55	4.24238
1168.8	5.40989
1172.05	6.12481
1175.29	6.81814
1178.54	5.91997
1181.78	5.71819
1185.02	6.49966
1188.26	7.56103
1191.5	7.81542
1194.74	7.12119
1197.97	8.03145
1201.21	6.46493
1204.44	7.51295
1207.68	9.79424
1210.91	10.1955
1214.14	11.1877
1217.37	12.4214
1220.59	13.9679
1223.82	17.0559
1227.05	18.4082
1230.27	20.8964
1233.49	23.1258
1236.72	25.8296
1239.94	29.1471
1243.16	32.8221
1246.37	34.8507
1249.59	36.5319
1252.8	37.257
1256.02	38.0235
1259.23	39.5983
1262.44	42.0547
1265.66	43.4475
1268.86	43.8405
1272.07	43.9423
1275.28	45.1589
1278.48	45.3325
1281.69	45.9062
1284.89	47.6711
1288.09	48.0289
1291.29	47.855
1294.49	48.0457
1297.69	47.4832
1300.89	49.0005
1304.08	48.2289
1307.28	48.7191
1310.47	49.4161
1313.66	49.617
1316.85	50.1588
1320.04	49.4804
1323.23	48.3124
1326.42	47.088
1329.61	46.4659
1332.79	45.9417
1335.97	46.0119
1339.16	45.4552
1342.34	44.0606
1345.52	42.0497
1348.7	40.6618
1351.87	39.4258
1355.05	38.1066
1358.22	35.9384
1361.4	33.7147
1364.57	31.6603
1367.74	31.9483
1370.91	30.0722
1374.08	28.3183
1377.25	29.0103
1380.41	28.4948
1383.58	28.4089
1386.74	28.4338
1389.91	27.5437
1393.07	27.0194
1396.23	25.9276
1399.39	25.4396
1402.55	25.2087
1405.7	25.9114
1408.86	27.1239
1412.01	27.7183
1415.17	28.0675
1418.32	28.2299
1421.47	29.5822
1424.62	30.795
1427.77	34.1627
1430.91	36.2337
1434.06	39.3164
1437.2	41.6223
1440.35	44.1909
1443.49	46.4055
1446.63	47.8229
1449.77	47.8595
1452.91	47.8152
1456.05	46.7129
1459.18	44.4543
1462.32	42.4917
1465.45	40.5861
1468.59	36.2508
1471.72	31.6273
1474.85	27.5925
1477.98	22.7302
1481.1	18.7574
1484.23	15.7678
1487.36	12.1237
1490.48	8.94522
1493.61	5.80521
1496.73	4.09132
1499.85	4.92558
1502.97	5.74912
1506.09	5.55119
1509.2	6.13078
1512.32	6.9955
1515.43	8.30829
1518.55	8.51586
1521.66	9.64687
1524.77	10.2851
1527.88	11.8057
1530.99	11.8409
1534.1	13.7025
1537.21	15.8136
1540.31	17.5947
1543.42	18.7214
1546.52	19.2582
1549.62	20.5184
1552.72	21.814
1555.82	23.6996
1558.92	24.4558
1562.02	26.5079
1565.11	27.8154
1568.21	30.2211
1571.3	31.8563
1574.39	34.3996
1577.49	36.4967
1580.57	39.0107
1583.66	40.2604
1586.75	41.7423
1589.84	43.3314
1592.92	44.3641
1596.01	44.6459
1599.09	44.847
1602.17	45.5175
1605.25	45.6727
1608.33	46.2577
1611.41	46.5561
1614.49	46.3339
1617.57	45.9954
1620.64	44.8339
1623.72	44.8685
1626.79	44.7735
1629.86	44.0689
1632.93	44.4663
1636	46.3751
1639.07	49.0461
1642.13	49.5741
1645.2	51.2782
1648.26	52.3193
1651.33	53.9215
1654.39	54.4571
1657.45	54.6773
1660.51	53.7308
1663.57	53.3017
1666.63	51.8335
1669.68	50.3797
1672.74	47.2725
1675.79	44.388
1678.85	40.4167
1681.9	36.5671
1684.95	32.9835
1688	29.4475
1691.05	24.9346
1694.09	20.9921
1697.14	17.7496
1700.18	15.0245
1703.23	11.8817
1706.27	9.96158
1709.31	9.40702
1712.35	7.78181
1715.39	6.38866
1718.43	4.05422
1721.47	3.27385
1724.5	2.7374
1727.54	1.77823
1730.57	0.619508
1733.61	0.367523
1736.64	1.61632
1739.67	1.15429
1742.7	0.438008
1745.72	0.466402
1748.75	-0.154761
1751.77	0.363772
1754.8	1.28059
1757.82	2.82692
1760.84	3.02447
1763.87	3.93455
1766.89	4.53518
1769.91	5.29405
1772.92	5.13645
1775.94	5.49524
1778.95	4.63286
1781.97	4.73573
1784.98	3.87052
1787.99	4.09606
1791.01	3.88519
1794.01	3.54013
1797.02	2.97156
1800.03	2.20357
1803.04	1.65953
1806.04	2.01439
1809.05	2.98092
1812.05	2.63312
1815.05	2.92023
1818.05	3.01987
1821.05	2.89618
1824.05	3.41773
1827.05	2.8562
1830.04	3.69364
1833.04	4.68695
1836.03	5.58546
1839.03	5.83221
1842.02	5.9384
1845.01	6.02978
1848	6.06307
1850.99	6.11393
1853.97	6.40974
1856.96	6.61193
1859.94	7.6525
1862.93	8.05159
1865.91	8.10331
1868.89	8.06807
1871.87	7.93772
1874.85	8.26335
1877.83	9.96519
1880.81	10.1946
1882.57	9.07797
1885.56	9.52808
1888.55	9.75461
1891.54	9.49329
1894.52	9.57425
1897.51	8.28551
1900.49	8.25265
1903.47	9.16443
1906.45	10.6011
1909.43	10.5556
1912.41	10.8294
1915.39	10.945
1918.37	11.6727
1921.34	11.9096
1924.32	12.136
1927.29	12.4966
1930.26	12.2337
1933.23	13.0728
1936.2	12.3642
1939.17	12.0808
1942.14	12.4009
1945.11	12.6325
1948.07	13.1264
1951.04	11.8227
1954	11.4934
1956.96	11.0776
1959.93	9.94966
1962.89	8.97132
1965.85	8.02534
1968.8	6.22344
1971.76	6.13246
1974.72	6.44107
1977.67	7.05645
1980.63	7.14068
1983.58	6.90936
1986.53	6.38359
1989.48	6.12075
1992.43	5.70086
1995.38	5.20087
1998.32	5.42687
2001.27	4.59085
2004.22	4.41362
2007.16	4.42916
2010.1	3.89773
2013.04	4.154
2015.98	4.28181
2018.92	4.47941
2021.86	4.35076
2024.8	5.11711
2027.74	5.66729
2030.67	5.50737
2033.61	5.41722
2036.54	4.88769
2039.47	5.88702
2042.4	6.23859
2045.33	7.62023
2048.26	8.39915
2051.19	9.55988
2054.12	9.6517
2057.04	9.63676
2059.97	10.0151
2062.89	10.8104
2065.81	11.0877
2068.73	12.4045
2071.65	12.4039
2074.57	13.2535
2077.49	14.4595
2080.41	14.9934
2083.32	15.7535
2086.24	17.3457
2089.15	17.9657
2092.07	19.5153
2094.98	21.2141
2097.89	22.4136
2100.8	23.7697
2103.71	23.5642
2106.61	24.4217
2109.52	26.0294
2112.43	27.9625
2115.33	28.9367
2118.23	30.9974
2121.13	33.1044
2124.04	33.93
2126.94	34.9691
2129.83	36.9973
2132.73	39.1422
2135.63	41.0836
2138.53	42.521
2141.42	44.4975
2144.31	47.5501
2147.21	50.7639
2150.1	52.5145
2152.99	53.3221
2155.88	56.18
2158.77	58.3523
2161.65	59.5573
2164.54	62.1491
2167.43	62.7787
2170.31	62.7818
2173.19	63.0977
2176.07	64.1506
2178.96	64.5573
2181.84	63.2082
2184.72	62.5089
2187.59	61.0663
2190.47	59.6234
2193.35	57.0822
2196.22	54.3423
2199.09	52.2249
2201.97	50.6269
2204.84	47.483
2207.71	44.909
2210.58	42.72
2213.45	40.8256
2216.31	38.8238
2219.18	35.5018
2222.05	32.7355
2224.91	30.7952
2227.78	29.4008
2230.64	27.2495
2233.5	25.5213
2236.36	24.5962
2239.22	21.9282
2242.08	20.7959
2244.93	20.2881
2247.79	19.5087
2250.64	17.8463
2253.5	16.6774
2256.35	15.6723
2259.2	14.9177
2262.05	13.5301
2264.9	12.8053
2267.75	13.1806
2270.6	12.9765
2273.45	12.3533
2276.29	11.7799
2279.14	11.8242
2281.98	11.0892
2284.82	9.69566
2287.66	8.21079
2290.5	7.3822
2293.34	5.67577
2296.18	5.29612
2299.02	5.46353
2301.86	6.39946
2304.69	6.4286
2307.53	6.14876
2310.36	6.41509
2313.19	7.36183
2316.02	7.8967
2318.85	7.4573
2321.68	7.66602
2324.51	6.71829
2327.34	7.07562
2330.16	7.19791
2332.99	7.02104
2335.81	7.47112
2338.64	7.85931
2341.46	6.30889
2344.28	6.2855
2347.1	6.46526
2349.92	4.87103
2352.74	3.94094
2355.55	3.85822
2358.37	3.25349
2361.19	2.23744
2364	1.71273
2366.81	2.62624
2369.62	2.97674
2372.44	1.69294
2375.24	0.990414
2378.05	0.900626
2380.86	1.00188
2383.67	0.745712
2386.47	0.283691
2389.28	-1.19867
2392.08	-0.938879
2394.89	-0.834493
2397.69	-0.184641
2400.49	-0.19862
2403.29	0.942663
2406.09	0.862148
2408.88	2.04543
2411.68	3.22599
2414.48	4.42579
2417.27	5.64048
2420.06	6.86981
2422.86	8.87511
2425.65	8.87951
2428.44	8.68615
2431.23	9.03846
2434.02	9.45135
2436.81	9.19408
2439.59	8.60349
2442.38	7.21954
2445.16	6.76664
2447.95	6.27633
2450.73	5.92142
2453.51	5.08505
2456.29	4.39347
2459.07	3.69732
2461.85	3.56917
2464.63	3.96448
2467.4	3.28774
2470.18	4.338
2472.95	4.16941
2475.73	3.93035
2478.5	4.2006
2481.27	4.39477
2484.04	5.35683
2486.81	5.54748
2489.58	6.16856
2492.35	5.30736
2495.12	5.23862
2497.88	5.80509
2500.65	6.00719
2503.41	5.04747
2506.17	5.48308
2508.94	4.70735
2511.7	4.72959
2514.46	4.45882
2517.22	4.56076
2519.97	3.80446
2522.73	2.89231
2525.49	2.22647
2528.24	1.90847
2530.99	1.7699
2533.75	1.36262
2536.5	0.895294
2539.25	0.64679
2542	0.0069146
2544.75	-0.57616
2547.5	-0.52529
2550.24	0.135367
2552.99	0.570735
2555.74	0.743718
2558.48	0.871251
2561.22	1.73685
2563.96	2.40734
2566.71	2.87206
2569.45	3.06317
2572.18	2.95448
2574.92	3.25412
2577.66	2.97649
2580.4	3.20293
2583.13	2.98489
2585.87	2.55373
2588.6	2.16357
2591.33	2.43768
2594.06	2.53052
2596.79	3.01786
2599.52	3.73456
2602.25	2.99247
2604.98	3.66735
2607.71	3.8596
2610.43	3.48666
2613.16	3.53729
2615.88	4.28794
2618.6	5.25583
2621.32	5.31105
2624.04	6.66863
2626.76	6.1887
2629.48	5.48053
2632.2	4.84797
2634.92	4.20613
2637.63	3.99826
2640.35	3.27725
2643.06	3.71656
2645.77	2.56125
2648.49	2.68232
2651.2	2.61119
2653.91	2.0616
2656.62	2.74625
2659.33	2.83563
2662.03	2.96178
2664.74	3.03276
2667.44	2.00398
2670.15	2.14317
2672.85	3.14668
2675.55	2.78336
2678.26	3.22473
2680.96	4.00989
2683.66	4.3879
2686.35	5.09056
2689.05	4.56844
2691.75	4.16997
2694.44	4.22362
2697.14	3.55437
2699.83	3.69094
2702.52	4.0762
2705.22	4.81992
2707.91	4.76834
2710.6	4.72474
2713.29	3.72801
2715.97	3.89666
2718.66	3.61322
2721.35	4.51156
2724.03	4.68084
2726.72	4.65145
2729.4	4.36524
2732.08	3.92204
2734.76	4.20885
2737.44	4.42628
2740.12	4.06754
2742.8	4.88097
2745.48	5.1784
2748.16	4.88607
2750.83	4.28945
2753.51	4.32501
2756.18	3.07802
2758.85	3.37239
2761.53	3.52849
2764.2	2.69605
2766.87	2.36957
2769.54	2.78874
2772.2	1.32226
2774.87	0.58041
2777.54	-0.446385
2780.2	-0.552774
2782.87	-1.2205
2785.53	-0.686786
2788.19	-0.710323
2790.85	-0.334521
2793.51	-0.229282
2796.17	0.32398
2798.83	0.399952
2801.49	1.36711
2804.15	1.02189
2806.8	1.76564
2809.46	1.95098
2812.11	1.50616
2814.76	1.6444
2817.42	2.27686
2820.07	3.53072
2822.72	4.70136
2825.37	6.00796
2828.02	6.93504
2830.66	8.87771
2833.31	10.6105
2835.96	12.5605
2838.6	14.8054
2841.24	17.4841
2843.89	20.9636
2846.53	23.6822
2849.17	27.8927
2851.81	32.6934
2854.45	37.5967
2857.09	42.3377
2859.72	46.1073
2862.36	50.6256
2865	54.0155
2867.63	57.737
2870.26	60.6343
2872.9	63.6954
2875.53	65.9332
2878.16	68.4733
2880.79	71.2826
2883.42	73.8287
2886.05	76.5051
2888.67	78.6987
2891.3	81.1362
2893.92	83.4467
2896.55	85.9363
2899.17	88.9314
2901.79	93.0133
2904.42	97.4039
2907.04	102.161
2909.66	107.484
2912.27	112.483
2914.89	118.658
2917.51	124.275
2920.13	128.695
2922.74	132.767
2925.35	135.612
2927.97	139.059
2930.58	139.699
2933.19	140.621
2935.8	140.616
2938.41	139.581
2941.02	137.343
2943.63	134.313
2946.24	131.469
2948.84	126.644
2951.45	122.022
2954.05	116.973
2956.65	111
2959.26	105.523
2961.86	100.489
2964.46	96.0261
2967.06	91.3127
2969.66	85.8666
2972.25	81.5943
2974.85	76.3908
2977.45	71.7897
2980.04	67.1923
2982.64	61.9257
2985.23	57.0215
2987.82	52.6906
2990.41	48.3273
2993	43.5328
2995.59	38.1731
2998.18	33.7929
3000.77	29.2671
3003.36	24.1924
3005.94	20.5572
3008.53	16.7123
3011.11	13.3962
3013.69	10.466
3016.28	8.29372
3018.86	6.26206
3021.44	5.38648
3024.02	4.16364
3026.6	3.02617
3029.18	2.60064
3031.75	2.33195
3034.33	2.69187
3036.9	3.2714
3039.48	3.91041
3042.05	4.86458
3044.62	5.44369
3047.19	6.92091
3049.77	7.58493
3052.34	7.9754
3054.9	7.83504
3057.47	7.11068
3060.04	6.39779
3062.61	5.29556
3065.17	4.8852
3067.74	4.09571
3070.3	4.39558
3072.86	3.17845
3075.42	3.10861
3077.99	2.5812
3080.54	2.34277
3083.1	1.23354
3085.66	0.460433
3088.22	0.289075
3090.78	-0.0398088
3093.33	0.219766
3095.89	0.472347
3098.44	0.916766
3100.99	1.35599
3103.54	2.22431
3106.1	2.17199
3108.65	2.1658
3111.2	2.06042
3113.74	1.82255
3116.29	1.77056
3118.84	1.61628
3121.38	2.24137
3123.93	2.65566
3126.47	3.43276
3129.01	4.71643
3131.56	4.99994
3134.1	6.33922
3136.64	6.40734
3139.18	8.05506
3141.72	9.47139
3144.26	11.1538
3146.79	13.965
3149.33	16.581