File: data/Raman/poly_smoothed/Thy_50_12_38_1x_45s_532 nm_x100_100%_600 gr_mm_01.txt
#Acq. time (s)=	45
#Accumulations=	2
#Range (cm-¹)=	200...3150
#Windows=	2
#Auto scanning=	Off
#Autofocus=	Off
#Macrospot=	Off
#AutoExposure=	Off
#Spike filter=	Multiple accum.
#Delay time (s)=	0
#Binning=	1
#Readout mode=	Signal
#DeNoise=	Off
#ICS correction=	On
#Dark correction=	Off
#Inst. Process=	Off
#Detector Gain=	Best Dynamic Range
#Detector ADC=	20 kHz
#Detector temperature (°C)=	-69.85
#Instrument=	LabRAM HR Evol
#Detector=	Synapse
#Objective=	x100
#Grating=	600 gr/mm
#ND Filter=	100%
#Laser (nm)=	532
#Hole=	100.021
#Range=	Auto
#Laser Pol.=	No
#Raman. Pol.=	No
#Laser Pol. (°)=	-0.0007625
#Raman Pol. (°)=	89.9995
#Collection=	Microscope
#StageXY=	Marzhauser
#StageZ=	Marzhauser
#X (µm)=	-5131.1
#Y (µm)=	1523.7
#Z (µm)=	63.4
#Full time(mm:ss)=	3:18
#Project=
#Sample=
#Site=
#Title=	Thy_50_12_38_2x_45s_532 nm_x100_100%_600 gr_mm
#Remark=
#Date=	07.07.2022 12:03
#Acquired=	07.07.2022 12:03:13
#Base:Fit=	10.08.2022 10:04:30
#Base:Sub=	10.08.2022 10:04:45
#Filter:Polynom=	16.08.2022 10:20:25
#AxisType[0]=Intens
#AxisUnit[0]=Cnt
#AxisType[1]=Spectr
#AxisUnit[1]=1/cm
200.43	36.4682
204.061	31.3395
207.688	29.2539
211.316	27.0703
214.941	24.5772
218.566	21.9687
222.188	17.6712
225.809	15.5635
229.43	13.2453
233.047	11.8566
236.663	10.4248
240.278	9.10723
243.894	7.55912
247.506	7.47852
251.116	6.89183
254.725	5.36277
258.333	4.84259
261.939	5.17222
265.546	6.591
269.15	5.70147
272.752	5.69473
276.353	6.61573
279.952	5.90426
283.55	8.78845
287.146	8.61463
290.739	11.0445
294.333	11.6272
297.925	13.4181
301.516	15.1023
305.106	14.5628
308.694	15.0094
312.279	15.7012
315.864	17.0426
319.448	17.6739
323.029	18.74
326.61	17.1405
330.19	16.786
333.766	14.9027
337.343	15.3334
340.917	13.6383
344.491	13.0925
348.062	13.2741
351.633	11.0267
355.201	8.84745
358.77	7.1402
362.335	6.39396
365.899	4.46185
369.464	4.63189
373.025	4.47197
376.585	4.31072
380.143	4.92836
383.702	4.68194
387.258	4.71031
390.812	3.91828
394.365	4.00357
397.916	5.39501
401.467	6.48146
405.015	8.98381
408.565	10.2024
412.111	9.69831
415.656	8.82186
419.197	8.93157
422.739	9.69777
426.279	10.8253
429.819	10.7081
433.356	10.8532
436.893	11.4289
440.428	11.405
443.96	12.1997
447.492	12.144
451.023	13.0211
454.553	11.0276
458.079	11.9459
461.606	12.4596
465.132	12.8506
468.654	13.1056
472.177	14.1585
475.696	16.1603
479.217	18.2734
482.733	20.7865
486.251	24.3133
489.765	24.4779
493.278	25.5451
496.791	24.8638
500.301	22.9138
503.81	21.7433
507.319	22.6337
510.825	22.3319
514.33	21.1019
517.833	21.4448
521.337	20.1705
524.838	20.2658
528.337	18.5146
531.835	17.5061
535.332	16.0091
538.827	15.5221
542.321	15.3371
545.814	14.0604
549.305	13.4837
552.795	14.1592
556.284	13.8748
559.771	13.8731
563.257	13.2848
566.742	11.7028
570.223	10.8123
573.705	9.50969
577.185	8.70036
580.665	6.77524
584.141	5.07154
587.617	3.26672
591.092	3.43203
594.564	3.70264
598.037	2.44628
601.506	1.93136
604.976	1.06625
608.443	0.373533
611.91	2.24958
615.374	3.91134
618.839	5.31357
622.3	7.50587
625.761	7.23507
629.221	8.36321
632.679	8.67726
636.135	10.663
639.592	11.377
643.045	12.6282
646.497	10.4829
649.948	10.5572
653.398	11.1094
656.846	12.5108
660.293	13.1424
663.738	12.0503
667.185	11.5805
670.628	12.6966
674.067	14.894
677.508	14.7841
680.947	13.8042
684.385	13.8601
687.821	14.0658
691.256	16.2631
694.69	16.5701
698.121	18.7185
701.552	20.9113
704.982	23.161
708.41	24.446
711.836	25.6648
715.262	27.6646
718.685	29.7418
722.108	30.8253
725.53	32.6081
728.949	32.882
732.369	36.4272
735.785	39.3274
739.2	41.0941
742.616	43.8043
746.028	45.6539
749.441	49.6413
752.851	54.2113
756.26	57.2255
759.667	59.3055
763.075	60.3751
766.479	63.9327
769.883	66.4471
773.285	68.4044
776.686	70.0969
780.085	71.7829
783.484	75.2839
786.881	75.5219
790.276	75.4724
793.671	75.6784
797.064	77.0708
800.456	79.04
803.846	78.8039
807.236	80.5441
810.624	80.2721
814.01	79.2601
817.394	79.5486
820.778	78.0644
824.161	77.6955
827.543	77.5358
830.921	76.427
834.3	75.5458
837.676	73.5012
841.053	69.3378
844.426	66.9956
847.8	64.8891
851.171	63.0252
854.542	59.9476
857.911	56.0911
861.279	53.6442
864.645	51.6176
868.01	49.8727
871.375	47.0172
874.737	47.0249
878.097	48.1495
881.457	49.6841
884.817	48.1625
888.174	47.6444
891.53	47.2128
894.884	47.0433
898.237	47.5076
901.589	48.008
904.94	46.8851
908.289	46.5644
911.637	45.9542
914.984	45.4778
918.33	44.6064
921.674	41.3215
925.015	40.0067
928.357	40.1575
931.698	39.3172
935.037	38.1881
938.373	35.636
941.71	34.8225
945.046	33.8691
948.378	33.8605
951.711	35.4332
955.043	35.9911
958.372	36.0011
961.701	35.2811
965.027	35.4153
968.354	35.1921
971.678	35.5686
975	34.5323
978.324	33.5912
981.644	33.2766
984.962	32.5586
988.282	29.1512
991.598	29.0369
994.913	27.6185
998.227	25.8596
1001.54	23.8253
1004.85	23.1787
1008.16	23.448
1011.47	23.6378
1014.78	23.6203
1018.08	25.303
1021.39	26.0234
1024.69	26.29
1028	28.027
1031.3	31.229
1034.6	32.6037
1037.9	33.0406
1041.19	33.8811
1044.49	34.9843
1047.79	36.1101
1051.08	36.5189
1054.37	37.5933
1057.66	35.8798
1060.95	34.5843
1064.24	32.0432
1067.53	30.9403
1070.81	30.4141
1074.1	28.4216
1077.38	25.9411
1080.66	23.4218
1083.94	22.1782
1087.22	19.6995
1090.5	18.0276
1093.78	17.7417
1097.05	17.4066
1100.33	16.9992
1103.6	16.3016
1106.87	16.3547
1110.15	17.1309
1113.41	16.9878
1116.68	16.5478
1119.95	16.7514
1123.21	16.3034
1126.48	15.8452
1129.74	16.056
1133	15.0081
1136.26	13.4399
1139.52	12.5211
1142.78	11.288
1146.04	11.2762
1149.29	11.0699
1152.55	9.18627
1155.8	7.14837
1159.05	6.48254
1162.3	5.93736
1165.55	4.27837
1168.8	4.04373
1172.05	3.52999
1175.29	3.94855
1178.54	4.48172
1181.78	4.14752
1185.02	4.02473
1188.26	3.72176
1191.5	2.01869
1194.74	0.64807
1197.97	0.963103
1201.21	1.56975
1204.44	3.11502
1207.68	3.80069
1210.91	4.87059
1214.14	6.62084
1217.37	7.98968
1220.6	10.5566
1223.82	13.336
1227.05	17.5504
1230.27	21.5773
1233.49	24.5313
1236.72	27.9586
1239.94	30.2852
1243.16	34.5217
1246.37	36.0877
1249.59	38.7842
1252.8	41.0466
1256.02	43.4241
1259.23	45.606
1262.44	47.2555
1265.66	49.5583
1268.87	51.2647
1272.07	51.7234
1275.28	53.8718
1278.48	57.3325
1281.69	58.7435
1284.89	60.165
1288.09	61.0149
1291.3	62.1538
1294.49	62.5756
1297.69	63.2861
1300.89	65.3641
1304.09	65.7013
1307.28	66.9012
1310.47	66.2666
1313.66	64.9523
1316.86	63.7879
1320.05	64.1077
1323.23	63.2234
1326.42	61.9648
1329.61	59.8054
1332.79	57.1174
1335.98	56.2167
1339.16	55.7269
1342.34	53.9449
1345.52	53.2139
1348.7	52.1943
1351.87	50.726
1355.05	51.0132
1358.23	48.6639
1361.4	45.8611
1364.57	44.4499
1367.74	40.9756
1370.91	40.6551
1374.08	39.7163
1377.25	39.8364
1380.42	39.5701
1383.58	39.2874
1386.75	38.6412
1389.91	37.6369
1393.07	37.8247
1396.23	37.1268
1399.39	38.412
1402.55	39.5967
1405.7	39.7435
1408.86	39.9111
1412.01	40.3759
1415.17	42.6446
1418.32	45.2178
1421.47	47.2757
1424.62	51.6647
1427.77	54.9549
1430.92	59.66
1434.06	62.2516
1437.2	64.9502
1440.35	66.9719
1443.49	68.3698
1446.63	70.6603
1449.77	71.9429
1452.91	70.6969
1456.05	68.6706
1459.18	67.2502
1462.32	62.8646
1465.45	59.1018
1468.59	54.0095
1471.72	49.2948
1474.85	44.2235
1477.98	39.5966
1481.11	34.9564
1484.23	28.7919
1487.36	24.4256
1490.48	20.9128
1493.61	19.4343
1496.73	16.6927
1499.85	14.7589
1502.97	14.7169
1506.09	15.2405
1509.2	16.1212
1512.32	16.93
1515.44	18.0717
1518.55	20.0657
1521.66	21.6766
1524.77	22.5602
1527.88	23.5948
1530.99	24.5393
1534.1	27.1982
1537.21	27.3831
1540.31	28.7853
1543.42	31.1239
1546.52	33.6795
1549.62	37.2923
1552.72	40.283
1555.82	44.0128
1558.92	47.4052
1562.02	50.6509
1565.11	52.2845
1568.21	54.4527
1571.3	56.2794
1574.39	58.0045
1577.49	59.6422
1580.58	61.9018
1583.67	64.777
1586.75	65.0645
1589.84	65.9425
1592.93	66.2281
1596.01	65.1002
1599.09	64.615
1602.18	61.0486
1605.26	60.0724
1608.34	59.3012
1611.41	57.9601
1614.49	57.1225
1617.57	56.3052
1620.64	57.6498
1623.72	57.0976
1626.79	58.5429
1629.86	60.1822
1632.93	62.3626
1636	63.7624
1639.07	64.8803
1642.14	66.8633
1645.2	67.9488
1648.27	69.3717
1651.33	69.8191
1654.39	70.3496
1657.45	70.8219
1660.51	69.2836
1663.57	66.036
1666.63	63.9682
1669.69	60.4129
1672.74	58.0071
1675.79	54.0621
1678.85	50.718
1681.9	47.76
1684.95	42.0631
1688	38.3752
1691.05	34.0236
1694.1	29.5917
1697.14	26.3494
1700.19	23.9305
1703.23	21.8128
1706.27	19.3307
1709.32	16.6784
1712.35	14.7762
1715.39	13.1328
1718.43	11.3394
1721.47	10.7848
1724.5	8.6086
1727.54	7.03114
1730.57	5.75338
1733.61	4.96326
1736.64	3.31522
1739.67	3.04645
1742.7	2.64476
1745.72	2.83001
1748.75	3.27046
1751.78	1.90475
1754.8	2.38788
1757.82	1.94535
1760.85	2.26159
1763.87	1.82896
1766.89	1.23712
1769.91	2.03755
1772.92	1.66237
1775.94	1.98178
1778.96	2.19995
1781.97	2.23871
1784.98	3.03555
1788	2.76759
1791.01	3.42509
1794.01	3.91746
1797.02	4.38796
1800.03	4.03121
1803.04	4.14721
1806.04	3.05421
1809.05	2.68344
1812.05	2.66304
1815.05	2.31278
1818.05	1.90361
1821.05	2.23648
1824.05	2.25472
1827.05	2.53096
1830.04	3.50871
1833.04	3.55352
1836.03	3.61557
1839.03	2.93879
1842.02	3.54697
1845.01	4.09952
1848	3.81629
1850.99	4.1735
1853.97	3.79917
1856.96	3.9827
1859.94	3.57023
1862.93	4.14239
1865.91	3.91063
1868.89	4.11974
1871.87	2.45893
1874.85	0.91797
1877.83	0.557585
1880.81	0.115366
1882.56	0.048273
1885.55	-0.769457
1888.54	-0.999087
1891.52	-1.03452
1894.51	-0.255007
1897.49	0.411301
1900.48	1.74195
1903.46	1.93223
1906.44	2.30165
1909.42	3.07115
1912.4	3.21332
1915.38	2.80876
1918.35	3.80985
1921.33	3.52055
1924.3	4.46439
1927.28	5.23565
1930.25	4.86905
1933.22	5.29294
1936.19	5.57435
1939.16	5.69364
1942.13	5.12778
1945.09	4.49035
1948.06	5.18398
1951.03	4.17937
1953.99	4.75839
1956.95	3.75471
1959.91	3.64675
1962.87	3.80372
1965.83	4.26927
1968.79	4.63192
1971.75	4.28607
1974.7	3.42951
1977.66	3.43497
1980.61	3.44492
1983.56	2.12158
1986.52	1.74252
1989.47	1.53271
1992.41	1.76613
1995.36	2.43713
1998.31	3.60951
2001.26	3.41296
2004.2	3.74809
2007.15	4.18652
2010.09	4.6671
2013.03	4.77084
2015.97	6.16241
2018.91	6.84888
2021.85	6.91596
2024.79	6.80403
2027.72	6.83557
2030.66	6.37279
2033.59	7.09859
2036.53	7.45904
2039.46	7.02816
2042.39	5.89021
2045.32	6.56
2048.25	7.02113
2051.18	7.31079
2054.1	7.81816
2057.03	8.17168
2059.95	9.66942
2062.88	9.34979
2065.8	10.8713
2068.72	13.2092
2071.64	14.0918
2074.56	14.8243
2077.48	16.8297
2080.39	18.7341
2083.31	20.3393
2086.22	23.0571
2089.14	24.7129
2092.05	26.8341
2094.96	26.9156
2097.87	29.0919
2100.78	30.303
2103.69	32.2421
2106.6	34.4297
2109.51	35.99
2112.41	37.9078
2115.32	39.7287
2118.22	43.2999
2121.12	45.8251
2124.02	48.2397
2126.92	50.7724
2129.82	54.8459
2132.72	57.8677
2135.62	61.2368
2138.51	64.28
2141.41	68.5266
2144.3	72.3627
2147.19	76.0644
2150.09	79.999
2152.97	82.5333
2155.86	86.2756
2158.75	88.1257
2161.64	89.7195
2164.53	91.2781
2167.41	91.7117
2170.3	91.8951
2173.18	90.4601
2176.06	89.8417
2178.94	88.0531
2181.82	86.5991
2184.7	84.3407
2187.58	82.9442
2190.46	80.2855
2193.33	77.5257
2196.21	75.139
2199.08	71.9303
2201.95	68.7257
2204.83	65.4806
2207.7	63.0413
2210.57	60.4334
2213.43	58.7548
2216.3	55.784
2219.17	53.2066
2222.03	50.2208
2224.9	46.5761
2227.76	44.4859
2230.62	40.8942
2233.49	37.5527
2236.34	35.6558
2239.2	33.298
2242.06	30.3427
2244.92	29.6845
2247.78	28.1089
2250.63	27.3875
2253.48	27.0989
2256.34	26.2252
2259.19	25.2211
2262.04	24.7836
2264.89	23.1054
2267.74	22.4584
2270.59	21.1245
2273.43	20.1683
2276.28	19.5451
2279.12	18.5319
2281.97	17.6119
2284.81	16.733
2287.65	15.3284
2290.49	13.9893
2293.33	11.554
2296.17	11.401
2299.01	11.4363
2301.84	10.7691
2304.68	11.7529
2307.51	11.6298
2310.35	10.7034
2313.18	10.8389
2316.01	11.5881
2318.84	11.3645
2321.67	11.2443
2324.5	11.1662
2327.33	10.5615
2330.15	10.3914
2332.98	10.7631
2335.8	8.89479
2338.62	9.21956
2341.45	7.94268
2344.27	7.7702
2347.09	7.63023
2349.91	8.21629
2352.72	7.88217
2355.54	8.68867
2358.36	7.98692
2361.17	7.47494
2363.98	7.44809
2366.8	7.87211
2369.61	6.83241
2372.42	7.1603
2375.23	5.59121
2378.04	5.13073
2380.85	4.46799
2383.66	4.00213
2386.46	2.39259
2389.26	2.1308
2392.07	1.84126
2394.87	2.2364
2397.67	2.37888
2400.47	3.05319
2403.27	2.6656
2406.07	2.9958
2408.87	3.15102
2411.67	4.07562
2414.46	6.07001
2417.26	7.093
2420.05	7.59168
2422.84	8.03848
2425.64	8.92932
2428.43	8.45998
2431.22	8.4058
2434.01	8.88622
2436.79	8.01233
2439.58	8.77196
2442.37	8.35935
2445.15	8.35784
2447.93	7.92779
2450.72	8.47293
2453.5	7.38147
2456.28	7.24679
2459.06	8.61173
2461.84	9.05585
2464.62	9.21932
2467.39	9.97852
2470.17	10.4452
2472.94	11.1302
2475.72	11.4499
2478.49	10.878
2481.26	11.9304
2484.03	11.3977
2486.8	10.6922
2489.57	10.2654
2492.34	9.54184
2495.1	9.10106
2497.87	8.49823
2500.63	8.18478
2503.4	8.12626
2506.16	7.97132
2508.92	7.14872
2511.68	6.61468
2514.44	6.11684
2517.2	6.40649
2519.96	6.3601
2522.72	6.11238
2525.47	6.57341
2528.23	7.46467
2530.98	7.63152
2533.74	8.2661
2536.49	9.36553
2539.24	9.70933
2541.99	9.1836
2544.74	9.22327
2547.49	9.26859
2550.23	9.2223
2552.98	9.09718
2555.72	8.60332
2558.47	9.18882
2561.21	9.38053
2563.95	9.73079
2566.69	10.163
2569.43	10.3033
2572.17	10.106
2574.91	9.59783
2577.65	9.35225
2580.39	8.5456
2583.12	8.6157
2585.85	9.23085
2588.59	9.3855
2591.32	8.74792
2594.05	7.92262
2596.78	7.79164
2599.51	7.76147
2602.24	7.60133
2604.97	6.97747
2607.69	5.58695
2610.42	4.99475
2613.14	4.07554
2615.87	4.30847
2618.59	4.30948
2621.31	3.62941
2624.03	3.2652
2626.75	2.91029
2629.47	3.11315
2632.19	3.38637
2634.91	3.5918
2637.62	3.42143
2640.34	4.77819
2643.05	5.07297
2645.76	5.01595
2648.48	5.16691
2651.19	5.40097
2653.9	4.79228
2656.6	4.73475
2659.31	4.48729
2662.02	4.2826
2664.73	4.15903
2667.43	4.10126
2670.14	3.46224
2672.84	3.1204
2675.54	2.59742
2678.24	2.13343
2680.94	2.24353
2683.64	2.56635
2686.34	2.40032
2689.04	2.79493
2691.74	3.42922
2694.43	3.94338
2697.13	4.88625
2699.82	6.07262
2702.51	6.00962
2705.21	6.88722
2707.9	7.32788
2710.58	7.51535
2713.27	8.36329
2715.96	7.80773
2718.65	8.36994
2721.33	8.7511
2724.02	9.50182
2726.71	8.97819
2729.39	8.85874
2732.07	9.03744
2734.75	9.07223
2737.43	8.84278
2740.11	8.79963
2742.79	7.27482
2745.47	6.8386
2748.14	5.69606
2750.82	5.02922
2753.49	4.57732
2756.17	4.46627
2758.84	3.05793
2761.51	2.19235
2764.18	2.10738
2766.85	1.66713
2769.52	1.16777
2772.19	1.00753
2774.86	0.876653
2777.52	1.53003
2780.19	0.659755
2782.85	0.386581
2785.52	1.00143
2788.18	1.09391
2790.84	1.38703
2793.5	1.86703
2796.16	2.34807
2798.82	2.7421
2801.48	2.5857
2804.13	2.51149
2806.79	1.29476
2809.45	-0.112425
2812.1	-0.199606
2814.75	-0.668642
2817.41	-0.343893
2820.06	0.558081
2822.71	1.73933
2825.36	4.03652
2828	6.26269
2830.65	9.25225
2833.3	13.4082
2835.94	17.3154
2838.59	21.168
2841.23	25.9967
2843.87	30.1085
2846.52	35.2616
2849.16	42.0414
2851.8	48.9961
2854.44	55.8613
2857.08	63.1663
2859.71	70.2476
2862.35	76.2167
2864.98	82.0861
2867.62	87.8417
2870.25	92.2526
2872.88	96.2225
2875.52	100.731
2878.15	104.35
2880.78	108.842
2883.41	112.717
2886.03	116.573
2888.66	121.025
2891.29	125.771
2893.91	129.905
2896.54	134.106
2899.16	140.047
2901.78	144.479
2904.4	150.47
2907.02	157.113
2909.64	163.964
2912.26	171.243
2914.88	178.228
2917.5	186.233
2920.11	193.254
2922.73	198.844
2925.34	202.929
2927.96	204.77
2930.57	207.453
2933.18	207.497
2935.79	205.64
2938.4	203.165
2941.01	198.077
2943.62	193.113
2946.22	186.956
2948.83	179.608
2951.43	171.289
2954.04	163.64
2956.64	155.468
2959.24	147.288
2961.84	139.138
2964.45	131.852
2967.05	123.683
2969.64	116.208
2972.24	109.921
2974.84	102.277
2977.43	94.7516
2980.03	88.5334
2982.62	81.79
2985.22	74.395
2987.81	67.3357
2990.4	59.6777
2992.99	53.0891
2995.58	47.5305
2998.17	40.7791
3000.76	34.2403
3003.34	28.7921
3005.93	23.6876
3008.52	19.5997
3011.1	14.5844
3013.68	10.9186
3016.27	7.82878
3018.85	5.1463
3021.43	2.97989
3024.01	1.26708
3026.59	0.446568
3029.16	0.982029
3031.74	1.91727
3034.32	2.60169
3036.89	2.13698
3039.47	2.76238
3042.04	3.71742
3044.61	5.33817
3047.18	5.5324
3049.75	5.7128
3052.32	6.46329
3054.89	7.07436
3057.46	7.65786
3060.03	7.68997
3062.59	6.99814
3065.16	6.06406
3067.72	5.57484
3070.29	4.35324
3072.85	3.07489
3075.41	2.32472
3077.97	1.57291
3080.53	0.433541
3083.09	-0.946115
3085.65	-0.455671
3088.21	0.411201
3090.76	0.0556989
3093.32	0.372175
3095.87	0.471651
3098.43	0.994637
3100.98	1.6834
3103.53	3.52174
3106.08	4.60814
3108.63	5.78627
3111.18	6.6325
3113.73	8.2534
3116.28	9.04615
3118.83	10.461
3121.37	12.1195
3123.92	13.4678
3126.46	14.8127
3129	16.556
3131.55	18.6121
3134.09	20.5651
3136.63	22.5529
3139.17	25.3992
3141.71	27.3277
3144.24	30.2984
3146.78	33.7522
3149.32	36.2258