File: data/Raman/poly_smoothed/Thy_10_08_20_1x_45s_532 nm_x100_100%_600 gr_mm_01.txt
#Acq. time (s)=	45
#Accumulations=	2
#Range (cm-¹)=	200...3150
#Windows=	2
#Auto scanning=	Off
#Autofocus=	Off
#Macrospot=	Off
#AutoExposure=	Off
#Spike filter=	Multiple accum.
#Delay time (s)=	0
#Binning=	1
#Readout mode=	Signal
#DeNoise=	Off
#ICS correction=	On
#Dark correction=	Off
#Inst. Process=	Off
#Detector Gain=	Best Dynamic Range
#Detector ADC=	20 kHz
#Detector temperature (°C)=	-69.85
#Instrument=	LabRAM HR Evol
#Detector=	Synapse
#Objective=	x100
#Grating=	600 gr/mm
#ND Filter=	100%
#Laser (nm)=	532
#Hole=	100.021
#Range=	Auto
#Laser Pol.=	No
#Raman. Pol.=	No
#Laser Pol. (°)=	-0.0007625
#Raman Pol. (°)=	89.9995
#Collection=	Microscope
#StageXY=	Marzhauser
#StageZ=	Marzhauser
#X (µm)=	2204.1
#Y (µm)=	1241.1
#Z (µm)=	442.45
#Full time(mm:ss)=	3:18
#Project=
#Sample=
#Site=
#Title=	Thy_10_08_20_2x_45s_532 nm_x100_100%_600 gr_mm
#Remark=
#Date=	05.07.2022 15:36
#Acquired=	05.07.2022 15:36:22
#Base:Fit=	10.08.2022 09:46:25
#Base:Sub=	10.08.2022 09:46:49
#Filter:Polynom=	16.08.2022 10:24:56
#AxisType[0]=Intens
#AxisUnit[0]=Cnt
#AxisType[1]=Spectr
#AxisUnit[1]=1/cm
200.43	-11.3004
204.059	2.80761
207.688	11.5087
211.314	17.5628
214.941	18.8694
218.564	20.5439
222.186	20.1427
225.809	21.2137
229.428	21.3438
233.045	21.6631
236.663	21.1809
240.278	19.362
243.891	18.6722
247.503	15.406
251.116	13.0757
254.725	11.2169
258.333	10.5294
261.939	8.54779
265.544	8.61007
269.148	9.12127
272.75	10.6196
276.351	11.3182
279.95	9.45862
283.548	10.0008
287.144	11.5874
290.739	11.6652
294.333	11.6196
297.925	12.6029
301.514	12.3492
305.104	11.7173
308.692	13.4998
312.279	14.1902
315.862	14.7867
319.446	16.0348
323.029	15.0532
326.608	14.649
330.188	14.1026
333.766	13.0854
337.341	13.2734
340.917	13.7754
344.489	13.5475
348.062	12.3302
351.631	11.506
355.201	11.3034
358.768	10.5986
362.333	8.59474
365.899	6.71681
369.462	5.54872
373.023	4.49258
376.585	5.07029
380.143	5.19073
383.7	4.47585
387.256	3.86316
390.812	5.11536
394.365	4.32378
397.916	5.29256
401.467	4.86073
405.015	6.08238
408.563	7.30887
412.109	8.72077
415.654	8.83432
419.197	8.71288
422.739	9.01608
426.279	8.14865
429.819	8.39761
433.356	7.09723
436.891	7.21867
440.426	7.64102
443.96	7.72594
447.492	7.54646
451.021	6.28558
454.551	5.71953
458.079	6.47481
461.604	8.07897
465.13	9.70119
468.654	11.0492
472.175	12.2333
475.696	13.1437
479.215	15.485
482.733	16.2234
486.249	18.2448
489.765	19.0939
493.278	22.838
496.789	24.3876
500.301	24.1476
503.81	24.2398
507.317	24.5173
510.825	24.5028
514.33	25.3643
517.833	24.7287
521.335	24.3694
524.836	23.8969
528.335	23.3921
531.835	21.2047
535.332	17.8577
538.827	17.5971
542.321	14.8956
545.814	14.1447
549.305	13.2695
552.795	13.2812
556.282	9.99449
559.769	8.16377
563.255	7.37146
566.739	6.80407
570.223	6.55116
573.705	6.5974
577.183	5.2121
580.663	3.60982
584.141	1.95183
587.615	1.7941
591.09	1.06028
594.564	2.92363
598.035	2.80673
601.506	2.55414
604.974	3.71021
608.443	4.4351
611.908	5.19237
615.374	5.99199
618.837	5.6317
622.3	7.11455
625.761	8.27772
629.219	9.09572
632.677	10.4529
636.135	11.7763
639.59	13.6487
643.043	14.609
646.495	17.4868
649.948	18.5567
653.398	20.0083
656.846	19.8495
660.293	19.6172
663.738	19.9038
667.183	21.1713
670.626	22.2913
674.067	22.332
677.508	23.547
680.947	24.917
684.385	23.4677
687.821	23.7601
691.254	24.5699
694.688	25.5036
698.121	27.1522
701.552	30.1929
704.98	29.6191
708.409	30.051
711.836	30.8444
715.26	29.8076
718.685	30.8754
722.108	33.9487
725.528	35.7637
728.949	37.1245
732.367	40.466
735.785	41.202
739.2	42.8162
742.614	46.4774
746.028	49.6752
749.439	52.8982
752.849	55.4131
756.26	56.4091
759.667	58.648
763.073	61.1729
766.477	63.3731
769.883	65.1432
773.285	67.2637
776.686	70.6026
780.085	74.4485
783.484	77.4329
786.881	78.1636
790.276	78.8738
793.671	80.7326
797.064	82.0527
800.456	83.1363
803.846	86.2944
807.234	87.6623
810.622	87.0371
814.008	88.466
817.394	88.3866
820.778	89.5543
824.159	88.8398
827.541	88.543
830.921	86.1709
834.298	83.4101
837.676	80.9164
841.051	79.4047
844.426	77.4964
847.798	75.5269
851.171	73.5401
854.54	70.0298
857.911	68.2104
861.278	67.0992
864.645	65.1696
868.01	64.1011
871.373	62.4562
874.735	61.8617
878.097	59.4407
881.457	57.4185
884.815	56.7139
888.172	54.5904
891.528	53.4505
894.882	52.1852
898.237	51.9166
901.589	52.2235
904.94	52.0656
908.289	51.8236
911.635	50.9604
914.982	50.3363
918.328	51.2695
921.672	52.7535
925.015	52.598
928.357	52.4928
931.698	53.4957
935.035	52.0947
938.373	50.2948
941.71	51.2866
945.044	50.2959
948.378	49.8078
951.709	48.6705
955.041	47.0862
958.372	43.8368
961.699	39.6094
965.027	39.7771
968.352	41.3285
971.676	42.6957
975	42.3979
978.322	44.9796
981.642	47.08
984.962	47.5288
988.28	47.9235
991.596	48.2214
994.911	49.0598
998.227	49.3847
1001.54	49.6695
1004.85	49.2624
1008.16	48.3984
1011.47	47.1906
1014.78	44.3978
1018.08	43.5459
1021.39	41.0596
1024.69	38.0427
1028	34.332
1031.3	31.6086
1034.6	27.4888
1037.9	22.8765
1041.19	18.9275
1044.49	18.4156
1047.78	20.8362
1051.08	21.1666
1054.37	20.8731
1057.66	19.8644
1060.95	19.5961
1064.24	18.6059
1067.53	20.1831
1070.81	20.6718
1074.1	20.9823
1077.38	21.9253
1080.66	21.8445
1083.94	22.9274
1087.22	23.555
1090.5	24.0213
1093.78	24.7738
1097.05	24.4627
1100.33	23.527
1103.6	21.9618
1106.87	20.516
1110.14	18.0215
1113.41	16.045
1116.68	13.9575
1119.95	13.0027
1123.21	10.8004
1126.48	10.5668
1129.74	8.11893
1133	7.05534
1136.26	4.84541
1139.52	6.42841
1142.78	6.51626
1146.04	6.43244
1149.29	6.05594
1152.55	5.33148
1155.8	3.07815
1159.05	2.20643
1162.3	2.47215
1165.55	3.04972
1168.8	5.7947
1172.05	5.97285
1175.29	7.32318
1178.54	8.34491
1181.78	9.88361
1185.02	11.7313
1188.26	11.8005
1191.5	13.1487
1194.74	14.7964
1197.97	16.2757
1201.21	18.4232
1204.44	20.0427
1207.68	23.5783
1210.91	27.5302
1214.14	31.4277
1217.37	35.7772
1220.59	38.9234
1223.82	41.0303
1227.05	43.3712
1230.27	44.5132
1233.49	45.8749
1236.72	46.9461
1239.94	49.4093
1243.16	50.7785
1246.37	54.5915
1249.59	56.4336
1252.8	58.1132
1256.02	59.6563
1259.23	59.9419
1262.44	59.7218
1265.66	58.511
1268.86	58.1965
1272.07	59.6817
1275.28	60.2614
1278.48	62.5371
1281.69	64.7109
1284.89	65.1639
1288.09	66.74
1291.29	69.29
1294.49	71.5419
1297.69	72.912
1300.89	75.3218
1304.08	76.99
1307.28	79.6884
1310.47	81.8293
1313.66	84.4976
1316.85	85.1745
1320.04	86.0251
1323.23	86.3982
1326.42	86.2617
1329.61	84.2001
1332.79	83.1742
1335.97	80.9223
1339.16	78.1687
1342.34	73.8854
1345.52	71.7639
1348.7	68.8298
1351.87	66.4565
1355.05	62.6279
1358.22	60.5103
1361.4	57.9007
1364.57	56.3241
1367.74	55.6593
1370.91	53.3891
1374.08	51.9996
1377.25	50.6681
1380.41	50.7155
1383.58	49.3397
1386.74	48.2289
1389.91	44.9334
1393.07	41.7594
1396.23	39.0115
1399.39	37.4186
1402.55	36.4156
1405.7	33.8982
1408.86	34.2811
1412.01	35.1212
1415.17	36.0658
1418.32	37.9251
1421.47	42.1807
1424.62	47.0444
1427.77	53.6422
1430.91	59.7306
1434.06	65.1424
1437.2	71.9321
1440.35	77.3861
1443.49	81.7194
1446.63	84.9782
1449.77	85.0115
1452.91	86.7424
1456.05	86.7074
1459.18	85.0242
1462.32	81.3736
1465.45	76.2797
1468.59	69.845
1471.72	64.01
1474.85	58.661
1477.98	51.1005
1481.1	44.5326
1484.23	36.8782
1487.36	31.3791
1490.48	27.763
1493.61	23.371
1496.73	19.6235
1499.85	17.2797
1502.97	14.8216
1506.09	13.2296
1509.2	11.708
1512.32	10.7192
1515.43	10.6515
1518.55	10.8663
1521.66	11.7484
1524.77	13.182
1527.88	14.3763
1530.99	17.9959
1534.1	18.8048
1537.21	20.6886
1540.31	22.413
1543.42	24.6843
1546.52	27.0135
1549.62	30.3812
1552.72	33.1163
1555.82	36.471
1558.92	39.2371
1562.02	41.7363
1565.11	45.8523
1568.21	47.5954
1571.3	51.0041
1574.39	53.6716
1577.49	56.473
1580.57	58.5969
1583.66	61.7622
1586.75	63.6386
1589.84	64.8279
1592.92	66.4197
1596.01	67.6744
1599.09	68.7541
1602.17	69.061
1605.25	67.7822
1608.33	67.2355
1611.41	63.778
1614.49	63.8557
1617.57	63.9964
1620.64	64.0754
1623.72	64.5279
1626.79	67.0176
1629.86	68.5785
1632.93	68.9206
1636	71.8975
1639.07	74.5245
1642.13	78.3869
1645.2	82.7249
1648.26	87.1247
1651.33	90.895
1654.39	93.328
1657.45	97.1609
1660.51	97.0868
1663.57	96.3661
1666.63	95.5092
1669.68	92.9114
1672.74	90.409
1675.79	85.9542
1678.85	79.9849
1681.9	73.5573
1684.95	66.0387
1688	58.8711
1691.05	52.4759
1694.09	44.4762
1697.14	39.0233
1700.18	33.1827
1703.23	26.9515
1706.27	19.9642
1709.31	15.0566
1712.35	11.8874
1715.39	10.3336
1718.43	7.81531
1721.47	7.20644
1724.5	5.95632
1727.54	4.75012
1730.57	4.15382
1733.61	3.92126
1736.64	3.37798
1739.67	3.74056
1742.7	4.30366
1745.72	4.32868
1748.75	5.5578
1751.77	5.93237
1754.8	4.95728
1757.82	5.25596
1760.84	4.54207
1763.87	4.01395
1766.89	3.45875
1769.91	4.07205
1772.92	3.86267
1775.94	2.04832
1778.95	1.13307
1781.97	0.745182
1784.98	0.85679
1787.99	1.0272
1791.01	-0.384895
1794.01	-0.46869
1797.02	-1.2236
1800.03	-0.628634
1803.04	-0.808823
1806.04	-0.848246
1809.05	-0.593607
1812.05	0.429311
1815.05	0.77626
1818.05	1.29012
1821.05	0.99563
1824.05	2.48781
1827.05	1.77395
1830.04	2.23474
1833.04	2.95122
1836.03	4.25775
1839.03	4.58551
1842.02	5.68064
1845.01	6.20751
1848	7.27639
1850.99	8.11831
1853.97	9.0497
1856.96	9.68446
1859.94	11.264
1862.93	11.652
1865.91	13.0802
1868.89	14.1089
1871.87	15.5099
1874.85	15.9782
1877.83	17.3564
1880.81	17.4561
1882.57	18.2819
1885.56	18.5941
1888.55	19.1592
1891.54	19.5685
1894.52	19.2287
1897.51	18.8726
1900.49	18.0211
1903.47	17.7282
1906.45	18.7936
1909.43	18.8357
1912.41	18.0326
1915.39	17.7421
1918.37	18.3936
1921.34	18.7711
1924.32	17.8464
1927.29	18.3938
1930.26	17.1745
1933.23	16.8651
1936.2	17.7223
1939.17	18.6578
1942.14	18.8937
1945.11	18.6899
1948.07	19.9567
1951.04	20.7979
1954	21.5223
1956.96	22.6765
1959.93	22.0661
1962.89	21.7038
1965.85	22.0932
1968.8	21.8767
1971.76	21.9763
1974.72	21.8347
1977.67	22.1366
1980.63	22.741
1983.58	22.0149
1986.53	21.3492
1989.48	21.5892
1992.43	22.1978
1995.38	22.6348
1998.32	21.8692
2001.27	21.9245
2004.22	21.9321
2007.16	22.3536
2010.1	22.5357
2013.04	22.768
2015.98	22.5243
2018.92	23.233
2021.86	23.4215
2024.8	24.7362
2027.74	24.8584
2030.67	24.3651
2033.61	26.3753
2036.54	26.5908
2039.47	27.8742
2042.4	27.4452
2045.33	28.0467
2048.26	28.6934
2051.19	29.6072
2054.12	29.3857
2057.04	29.8011
2059.97	31.5647
2062.89	31.7185
2065.81	31.8073
2068.73	32.0367
2071.65	31.3095
2074.57	31.344
2077.49	30.7375
2080.41	30.2365
2083.32	29.9096
2086.24	29.0967
2089.15	28.4249
2092.07	28.4361
2094.98	28.7082
2097.89	29.0692
2100.8	28.8542
2103.71	29.4796
2106.61	29.549
2109.52	29.0899
2112.43	29.9958
2115.33	29.7671
2118.23	30.647
2121.13	31.7823
2124.04	33.2462
2126.94	34.5118
2129.83	36.5955
2132.73	38.0401
2135.63	39.4309
2138.53	40.6462
2141.42	42.2206
2144.31	43.3139
2147.21	45.2945
2150.1	45.9808
2152.99	47.4084
2155.88	48.9242
2158.77	49.864
2161.65	53.388
2164.54	54.3186
2167.43	56.1256
2170.31	56.2224
2173.19	57.1864
2176.07	58.1091
2178.96	57.8269
2181.84	58.1075
2184.72	57.0979
2187.59	56.6467
2190.47	56.5927
2193.35	55.7217
2196.22	55.1178
2199.09	53.4444
2201.97	51.0428
2204.84	48.3006
2207.71	45.7575
2210.58	42.3834
2213.45	40.2031
2216.31	38.8678
2219.18	36.8615
2222.05	36.2393
2224.91	34.9811
2227.78	35.1579
2230.64	35.1715
2233.5	34.4335
2236.36	34.2654
2239.22	34.5883
2242.08	33.7674
2244.93	33.7528
2247.79	33.6074
2250.64	33.0113
2253.5	33.4407
2256.35	33.2496
2259.2	33.8359
2262.05	33.7218
2264.9	33.8527
2267.75	33.2022
2270.6	31.6635
2273.45	30.4605
2276.29	30.41
2279.14	29.6528
2281.98	29.5197
2284.82	29.6844
2287.66	28.9555
2290.5	28.025
2293.34	27.0262
2296.18	26.9801
2299.02	28.0303
2301.86	29.2804
2304.69	29.8757
2307.53	29.5385
2310.36	29.1154
2313.19	27.8565
2316.02	27.8874
2318.85	27.5875
2321.68	27.2808
2324.51	27.6055
2327.34	26.9984
2330.16	26.7492
2332.99	26.0056
2335.81	24.2454
2338.64	22.8702
2341.46	21.5604
2344.28	20.885
2347.1	19.7704
2349.92	18.4271
2352.74	16.9133
2355.55	15.4259
2358.37	12.9718
2361.19	12.4191
2364	12.5261
2366.81	13.3369
2369.62	13.4307
2372.44	12.1603
2375.24	11.1988
2378.05	9.79239
2380.86	9.22385
2383.67	8.1992
2386.47	9.01573
2389.28	9.63601
2392.08	11.3022
2394.89	12.0285
2397.69	12.9434
2400.49	13.5119
2403.29	14.2848
2406.09	15.1477
2408.88	17.1247
2411.68	17.874
2414.48	19.8202
2417.27	20.8347
2420.06	20.8103
2422.86	21.0249
2425.65	20.3752
2428.44	20.7684
2431.23	20.4727
2434.02	19.6437
2436.81	18.907
2439.59	17.3131
2442.38	16.2948
2445.16	15.4349
2447.95	13.9608
2450.73	13.4607
2453.51	12.5175
2456.29	11.839
2459.07	10.4739
2461.85	10.3521
2464.63	10.7969
2467.4	10.9217
2470.18	10.4927
2472.95	11.3209
2475.73	11.6293
2478.5	12.2516
2481.27	11.3684
2484.04	11.9688
2486.81	12.3475
2489.58	11.6912
2492.35	11.511
2495.12	11.0059
2497.88	10.7704
2500.65	11.1583
2503.41	10.7406
2506.17	10.0538
2508.94	9.93307
2511.7	9.16562
2514.46	8.20176
2517.22	6.72305
2519.97	6.1137
2522.73	4.67942
2525.49	4.08566
2528.24	3.90493
2530.99	3.39109
2533.75	3.59136
2536.5	3.1354
2539.25	3.2424
2542	3.87545
2544.75	3.20316
2547.5	3.19114
2550.24	2.38634
2552.99	3.38409
2555.74	3.75439
2558.48	2.29976
2561.22	2.27245
2563.96	2.15284
2566.71	2.44986
2569.45	2.17211
2572.18	2.90616
2574.92	2.33283
2577.66	1.34402
2580.4	1.22024
2583.13	1.54851
2585.87	1.71828
2588.6	1.99083
2591.33	1.62325
2594.06	1.74428
2596.79	1.05033
2599.52	1.3208
2602.25	1.73945
2604.98	1.92478
2607.71	2.20912
2610.43	2.32948
2613.16	2.39267
2615.88	0.724466
2618.6	1.00696
2621.32	0.252991
2624.04	-0.38398
2626.76	-0.832134
2629.48	-1.23729
2632.2	-1.24273
2634.92	-1.38939
2637.63	-1.09897
2640.35	-1.17969
2643.06	-1.30037
2645.77	-0.0236681
2648.49	0.798619
2651.2	1.67526
2653.91	2.30132
2656.62	2.08574
2659.33	1.99742
2662.03	2.74434
2664.74	2.68191
2667.44	2.88647
2670.15	2.9787
2672.85	3.04293
2675.55	2.31514
2678.26	2.44683
2680.96	1.89855
2683.66	1.88602
2686.35	1.48178
2689.05	1.71159
2691.75	2.64375
2694.44	2.61235
2697.14	2.72313
2699.83	3.01354
2702.52	3.68197
2705.22	3.96539
2707.91	4.11065
2710.6	4.67412
2713.29	4.26323
2715.97	5.12717
2718.66	5.95276
2721.35	6.41062
2724.03	6.5966
2726.72	6.9075
2729.4	6.02338
2732.08	5.49202
2734.76	5.0822
2737.44	5.11836
2740.12	4.6392
2742.8	4.83082
2745.48	4.3749
2748.16	3.56054
2750.83	3.93408
2753.51	3.44826
2756.18	3.60641
2758.85	2.8658
2761.53	2.41186
2764.2	1.92207
2766.87	1.49915
2769.54	1.12722
2772.2	0.835897
2774.87	1.27984
2777.54	0.435909
2780.2	0.338574
2782.87	0.628372
2785.53	1.11577
2788.19	0.803183
2790.85	0.737567
2793.51	0.358045
2796.17	-0.587325
2798.83	-0.155794
2801.49	-0.737608
2804.15	-0.924209
2806.8	-1.72407
2809.46	-1.44233
2812.11	-2.23177
2814.76	-1.85589
2817.42	-0.946077
2820.07	-0.428506
2822.72	2.33128
2825.37	6.22367
2828.02	10.418
2830.66	15.4682
2833.31	20.7315
2835.96	26.6934
2838.6	33.9015
2841.24	41.2759
2843.89	50.4226
2846.53	60.5697
2849.17	73.21
2851.81	86.3808
2854.45	98.566
2857.09	111.121
2859.72	124.546
2862.36	136.571
2865	148.095
2867.63	158.482
2870.26	168.307
2872.9	176.538
2875.53	183.162
2878.16	189.476
2880.79	195.121
2883.42	199.832
2886.05	203.324
2888.67	208.7
2891.3	213.899
2893.92	219.976
2896.55	225.537
2899.17	231.61
2901.79	239.89
2904.42	250.75
2907.04	263.331
2909.66	277.777
2912.27	292.393
2914.89	307.783
2917.51	321.796
2920.13	334.549
2922.74	345.386
2925.35	354.113
2927.97	360.02
2930.58	362.326
2933.19	363.12
2935.8	360.428
2938.41	354.558
2941.02	346.363
2943.63	336.606
2946.24	324.611
2948.84	311.568
2951.45	298.476
2954.05	286.119
2956.65	272.366
2959.26	259.146
2961.86	245.282
2964.46	233.702
2967.06	223.056
2969.66	213.264
2972.25	203.532
2974.85	194.243
2977.45	184.288
2980.04	173.795
2982.64	163.024
2985.23	151.992
2987.82	140.626
2990.41	128.878
2993	117.559
2995.59	106.709
2998.18	96.0771
3000.77	85.1807
3003.36	75.2074
3005.94	66.2452
3008.53	58.2837
3011.11	51.0438
3013.69	45.6009
3016.28	40.3832
3018.86	34.7181
3021.44	30.0108
3024.02	27.9259
3026.6	26.6268
3029.18	25.035
3031.75	24.4737
3034.33	23.5696
3036.9	23.4689
3039.48	24.961
3042.05	25.924
3044.62	26.6973
3047.19	28.4157
3049.77	29.5738
3052.34	30.3782
3054.9	31.6653
3057.47	32.0462
3060.04	32.5403
3062.61	31.787
3065.17	31.2996
3067.74	30.0585
3070.3	27.7473
3072.86	25.8172
3075.42	23.9725
3077.99	20.8604
3080.54	18.3058
3083.1	15.1078
3085.66	12.8014
3088.22	10.9518
3090.78	8.78647
3093.33	6.89407
3095.89	4.81522
3098.44	3.80916
3100.99	3.56176
3103.54	3.44972
3106.1	2.42312
3108.65	1.94459
3111.2	1.89236
3113.74	0.983676
3116.29	1.42875
3118.84	1.11204
3121.38	1.07995
3123.93	0.970814
3126.47	0.694236
3129.01	0.995837
3131.56	-0.317392
3134.1	-0.264319
3136.64	-0.129103
3139.18	0.230941
3141.72	0.847334
3144.26	1.83635
3146.79	3.36978
3149.33	5.70721