File: data/Raman/poly_smoothed/Thy_20_09_08_1x_45s_532 nm_x100_100%_600 gr_mm_01.txt
#Acq. time (s)=	45
#Accumulations=	2
#Range (cm-¹)=	200...3150
#Windows=	2
#Auto scanning=	Off
#Autofocus=	Off
#Macrospot=	Off
#AutoExposure=	Off
#Spike filter=	Multiple accum.
#Delay time (s)=	0
#Binning=	1
#Readout mode=	Signal
#DeNoise=	Off
#ICS correction=	On
#Dark correction=	Off
#Inst. Process=	Off
#Detector Gain=	Best Dynamic Range
#Detector ADC=	20 kHz
#Detector temperature (°C)=	-69.85
#Instrument=	LabRAM HR Evol
#Detector=	Synapse
#Objective=	x100
#Grating=	600 gr/mm
#ND Filter=	100%
#Laser (nm)=	532
#Hole=	100.021
#Range=	Auto
#Laser Pol.=	No
#Raman. Pol.=	No
#Laser Pol. (°)=	-0.0007625
#Raman Pol. (°)=	89.9995
#Collection=	Microscope
#StageXY=	Marzhauser
#StageZ=	Marzhauser
#X (µm)=	-5904.6
#Y (µm)=	2839.4
#Z (µm)=	-223.25
#Full time(mm:ss)=	3:18
#Project=
#Sample=
#Site=
#Title=	Thy_20_09_08_2x_45s_532 nm_x100_100%_600 gr_mm
#Remark=
#Date=	29.06.2022 11:18
#Acquired=	29.06.2022 11:18:20
#Base:Fit=	10.08.2022 09:49:32
#Base:Fit=	10.08.2022 09:49:42
#Base:Fit=	10.08.2022 09:49:53
#Base:Fit=	10.08.2022 09:50:12
#Base:Fit=	10.08.2022 09:50:26
#Base:Fit=	10.08.2022 09:50:30
#Base:Fit=	10.08.2022 09:50:43
#Base:Fit=	10.08.2022 09:52:02
#Base:Fit=	10.08.2022 09:52:12
#Base:Sub=	10.08.2022 09:54:21
#Filter:Polynom=	16.08.2022 10:24:04
#AxisType[0]=Intens
#AxisUnit[0]=Cnt
#AxisType[1]=Spectr
#AxisUnit[1]=1/cm
200.523	23.0473
204.154	16.5643
207.781	13.6796
211.409	12.325
215.034	10.6699
218.659	10.5693
222.281	11.3571
225.903	10.1149
229.522	10.5239
233.14	9.2871
236.756	9.0834
240.373	8.47277
243.986	7.86728
247.598	7.16707
251.208	7.75948
254.818	7.24985
258.427	5.99714
262.034	4.2559
265.638	2.80721
269.242	0.620548
272.844	0.953564
276.445	0.524354
280.044	0.115219
283.642	1.79642
287.238	2.01222
290.833	5.59643
294.425	7.10621
298.017	8.01521
301.608	8.24574
305.198	8.41422
308.786	11.319
312.371	13.4679
315.956	13.8491
319.54	15.4197
323.122	16.5719
326.701	17.544
330.281	17.0742
333.857	17.2037
337.434	16.3959
341.008	14.5824
344.582	13.2186
348.153	11.2193
351.724	9.72832
355.292	9.29833
358.861	7.88382
362.426	7.18542
365.99	6.87574
369.555	5.80675
373.116	5.01575
376.676	4.09353
380.236	4.76701
383.793	2.17873
387.349	2.56723
390.903	2.79905
394.456	4.05003
398.007	7.19513
401.56	7.29811
405.108	7.02572
408.656	7.49711
412.202	8.74379
415.746	9.50328
419.29	10.1269
422.831	10.878
426.37	10.0664
429.909	11.1633
433.447	11.758
436.983	9.97458
440.519	9.98032
444.052	8.31233
447.583	6.49422
451.114	6.64827
454.643	6.90546
458.169	4.09761
461.696	3.86336
465.222	3.17794
468.744	2.97039
472.267	5.26102
475.787	6.92831
479.307	7.93142
482.823	8.60296
486.341	10.3444
489.855	9.71217
493.37	11.0134
496.881	12.1544
500.391	14.5712
503.902	16.5476
507.409	17.2404
510.915	18.2173
514.42	17.2271
517.925	18.9735
521.427	18.5414
524.928	18.7198
528.427	18.2699
531.925	17.7054
535.422	17.724
538.917	16.2977
542.411	13.9674
545.903	11.7644
549.395	11.6677
552.884	10.5783
556.373	11.7866
559.86	11.9195
563.346	11.1798
566.831	11.0374
570.314	10.8503
573.794	10.2247
577.274	9.43919
580.754	8.11187
584.23	7.28845
587.706	7.41496
591.181	5.70689
594.653	4.86636
598.126	3.81483
601.595	4.20091
605.065	5.44254
608.532	6.31351
611.999	6.85784
615.463	7.58367
618.928	7.70388
622.389	7.24926
625.851	8.02834
629.31	9.46517
632.767	8.87197
636.223	11.3873
639.68	14.0938
643.134	16.2237
646.586	18.2471
650.037	19.7331
653.486	20.4877
656.936	20.5299
660.383	21.8332
663.829	22.1091
667.273	22.4945
670.716	22.6359
674.158	23.0591
677.598	24.3394
681.035	24.5673
684.473	25.2631
687.909	27.0833
691.344	28.7721
694.778	28.6548
698.211	28.1613
701.64	29.2072
705.07	30.3402
708.498	31.5729
711.924	34.1968
715.35	35.8879
718.774	39.0862
722.196	41.7128
725.618	43.7798
729.037	45.4994
732.456	47.5133
735.873	49.5612
739.289	51.5251
742.703	53.7009
746.116	56.7774
749.529	59.2687
752.938	61.5301
756.347	64.4609
759.756	65.4921
763.162	67.0462
766.567	69.136
769.97	70.3385
773.372	71.9174
776.773	71.9981
780.174	73.1135
783.573	73.7932
786.97	74.1469
790.365	75.3228
793.76	76.6313
797.153	77.9154
800.543	78.4675
803.933	79.4706
807.322	80.0733
810.71	80.7945
814.097	80.7788
817.483	81.7635
820.865	81.8791
824.248	81.3385
827.629	80.7323
831.008	79.8506
834.387	79.0177
837.765	76.7237
841.139	74.7828
844.514	71.3922
847.886	69.4772
851.259	66.1809
854.629	63.2318
857.997	60.5144
861.366	59.0176
864.732	55.5146
868.098	53.2704
871.461	51.7092
874.823	51.4165
878.184	51.5614
881.545	51.4853
884.903	50.8712
888.26	50.5357
891.616	51.8146
894.97	50.8863
898.323	51.221
901.675	51.7733
905.026	51.6723
908.375	50.4051
911.723	49.0851
915.07	46.3998
918.415	44.5004
921.76	43.4108
925.103	42.5418
928.443	41.7287
931.783	41.1866
935.123	39.7262
938.461	38.3791
941.796	37.8619
945.131	36.5122
948.465	34.8861
951.797	33.0394
955.128	31.3687
958.457	28.587
961.786	27.4292
965.113	29.1609
968.44	30.3446
971.763	31.5568
975.086	34.0256
978.409	36.2812
981.729	38.0247
985.048	38.6711
988.367	40.7402
991.683	41.6635
994.998	42.5476
998.312	44.0376
1001.62	44.6184
1004.94	46.7934
1008.25	46.9044
1011.56	46.7652
1014.86	44.1966
1018.17	43.4551
1021.48	40.6999
1024.78	37.3768
1028.08	34.585
1031.38	31.641
1034.68	27.5206
1037.98	24.4231
1041.28	23.4305
1044.57	23.8394
1047.87	24.7325
1051.16	23.0844
1054.45	21.9571
1057.75	23.0762
1061.04	23.032
1064.32	23.7248
1067.61	24.4851
1070.9	25.3558
1074.18	23.4739
1077.47	23.891
1080.75	23.2943
1084.03	22.3597
1087.31	23.601
1090.59	23.3421
1093.86	23.5778
1097.14	23.475
1100.41	23.4214
1103.69	23.5027
1106.96	24.4053
1110.23	24.2126
1113.5	22.8123
1116.77	21.1032
1120.03	20.478
1123.3	18.9587
1126.56	18.493
1129.83	16.4166
1133.09	14.306
1136.35	13.397
1139.61	12.3254
1142.86	9.76283
1146.12	8.1888
1149.38	6.30431
1152.63	3.94757
1155.88	2.53805
1159.14	2.651
1162.39	2.40363
1165.63	3.08463
1168.88	3.48725
1172.13	5.20705
1175.38	6.63051
1178.62	7.86641
1181.86	10.637
1185.1	12.4599
1188.34	13.6851
1191.58	14.5485
1194.82	16.5737
1198.06	18.2101
1201.29	20.451
1204.53	23.6135
1207.76	26.1399
1210.99	29.8086
1214.22	34.1531
1217.45	38.2139
1220.68	42.2718
1223.91	46.2278
1227.13	50.3521
1230.36	54.9998
1233.58	58.7122
1236.8	62.8315
1240.02	66.7367
1243.24	69.3165
1246.46	70.5807
1249.67	71.8534
1252.89	74.159
1256.1	74.795
1259.32	74.6754
1262.53	75.6996
1265.74	74.7631
1268.95	74.8404
1272.15	75.5363
1275.36	76.0447
1278.57	77.4996
1281.77	79.0842
1284.97	80.3906
1288.18	81.6882
1291.38	83.6034
1294.58	85.5728
1297.78	86.5002
1300.97	89.0539
1304.17	90.7247
1307.36	93.9255
1310.55	96.3311
1313.75	97.0726
1316.94	97.6377
1320.13	97.6099
1323.32	97.734
1326.5	95.1684
1329.69	93.715
1332.87	90.927
1336.06	88.0147
1339.24	88.1291
1342.42	85.5633
1345.6	83.1539
1348.78	79.6324
1351.96	76.5417
1355.13	73.652
1358.31	72.0481
1361.48	68.8755
1364.65	66.8236
1367.82	64.3309
1370.99	63.7988
1374.16	61.5047
1377.33	60.2212
1380.5	57.9498
1383.66	58.5052
1386.83	57.1467
1389.99	55.1446
1393.15	54.2871
1396.31	52.6294
1399.47	49.5744
1402.63	48.4893
1405.78	47.2168
1408.94	48.5705
1412.1	49.1476
1415.25	52.2128
1418.4	55.29
1421.55	58.2393
1424.7	63.0952
1427.85	68.4079
1431	74.5683
1434.14	80.7095
1437.29	87.0207
1440.43	90.6371
1443.57	93.8577
1446.71	94.838
1449.85	95.7781
1452.99	94.8367
1456.13	93.8242
1459.26	91.7953
1462.4	88.8961
1465.54	83.2167
1468.67	77.2375
1471.8	71.5398
1474.93	64.4948
1478.06	59.0221
1481.19	52.5046
1484.31	46.1251
1487.44	41.4106
1490.56	38.3643
1493.69	35.2187
1496.81	33.4518
1499.93	31.4706
1503.05	30.3625
1506.17	30.0033
1509.28	30.1557
1512.4	30.0536
1515.52	28.549
1518.63	28.2347
1521.74	29.577
1524.85	30.8811
1527.96	32.831
1531.07	35.046
1534.18	38.4949
1537.29	39.8517
1540.39	42.9134
1543.5	45.7957
1546.6	49.157
1549.7	53.2028
1552.8	57.8171
1555.9	61.3114
1559	64.0921
1562.1	68.7755
1565.19	72.9069
1568.29	75.7314
1571.38	78.2263
1574.47	81.181
1577.56	83.6121
1580.66	86.368
1583.74	89.2363
1586.83	89.997
1589.92	90.0807
1593.01	89.2936
1596.09	87.0596
1599.17	86.2965
1602.25	84.4108
1605.34	82.5485
1608.41	80.634
1611.49	78.3733
1614.57	76.5978
1617.65	74.6688
1620.72	74.7446
1623.79	74.9461
1626.87	76.1774
1629.94	77.6196
1633.01	79.3173
1636.08	82.169
1639.15	85.7551
1642.21	90.8184
1645.28	94.3655
1648.34	97.9972
1651.41	102.629
1654.47	106.679
1657.53	109.504
1660.59	110.007
1663.65	108.959
1666.71	106.94
1669.76	103.85
1672.82	99.937
1675.87	96.4139
1678.93	91.6283
1681.98	84.9953
1685.03	76.5461
1688.08	69.4345
1691.13	63.2285
1694.17	56.1762
1697.22	49.4735
1700.27	43.2181
1703.31	37.1902
1706.35	31.7897
1709.39	27.8961
1712.43	24.3519
1715.47	22.2447
1718.51	19.3305
1721.55	16.9587
1724.58	15.181
1727.62	14.193
1730.65	13.1385
1733.68	12.1778
1736.72	10.2323
1739.74	9.12471
1742.77	7.47939
1745.8	6.96736
1748.83	7.67197
1751.85	7.59353
1754.88	6.59431
1757.9	5.76804
1760.92	4.89943
1763.95	5.47174
1766.96	4.6599
1769.98	4.08381
1773	3.10486
1776.02	2.64807
1779.03	3.64637
1782.05	3.67166
1785.06	4.51605
1788.07	3.75471
1791.08	3.9407
1794.09	3.89601
1797.1	4.24595
1800.11	4.73482
1803.12	3.41271
1806.12	2.51664
1809.12	3.17304
1812.13	2.11488
1815.13	1.65131
1818.13	1.87336
1821.13	2.10968
1824.13	1.77642
1827.13	1.81596
1830.12	0.892719
1833.12	0.864845
1836.11	0.218622
1839.1	0.348968
1842.09	0.527164
1845.09	1.02653
1848.08	1.13439
1851.06	2.12279
1854.05	2.38941
1857.04	2.07151
1860.02	1.6644
1863.01	1.7439
1865.99	2.7051
1868.97	3.11886
1871.95	3.09416
1874.93	2.70256
1877.91	2.00416
1880.89	1.9775
1882.46	1.89282
1885.45	1.59403
1888.43	1.22497
1891.42	1.36584
1894.41	1.28154
1897.39	2.24116
1900.37	1.97054
1903.36	2.48729
1906.34	2.68375
1909.32	3.60165
1912.29	4.28861
1915.27	4.89579
1918.25	5.56106
1921.23	6.15955
1924.2	6.06653
1927.17	5.49836
1930.15	5.1347
1933.12	5.5472
1936.09	6.56297
1939.06	6.70889
1942.02	7.01024
1944.99	6.87273
1947.96	7.52592
1950.92	6.87623
1953.88	6.16227
1956.85	5.91623
1959.81	5.43929
1962.77	6.47708
1965.73	7.55062
1968.69	7.65963
1971.64	7.49169
1974.6	7.86306
1977.55	8.28866
1980.51	8.04458
1983.46	7.61786
1986.41	6.87482
1989.36	7.11545
1992.31	7.31712
1995.26	6.83136
1998.21	7.07529
2001.15	6.91822
2004.1	6.53956
2007.04	6.16111
2009.99	5.18884
2012.93	5.47374
2015.87	5.66959
2018.81	5.72835
2021.75	5.26513
2024.68	5.16523
2027.62	6.29065
2030.56	7.38518
2033.49	8.28308
2036.42	8.68894
2039.36	8.98423
2042.29	8.51854
2045.22	8.77969
2048.14	9.26229
2051.07	9.15549
2054	9.23412
2056.93	8.90972
2059.85	10.1885
2062.77	10.6974
2065.7	11.1757
2068.62	11.9936
2071.54	12.5866
2074.46	12.3317
2077.38	12.3186
2080.29	13.332
2083.21	13.8093
2086.12	14.5624
2089.04	15.9339
2091.95	16.6433
2094.86	16.6459
2097.77	17.6439
2100.68	18.6738
2103.59	19.1764
2106.5	19.6108
2109.41	20.9741
2112.31	22.3306
2115.21	23.9422
2118.12	26.0477
2121.02	27.8937
2123.92	28.7236
2126.82	30.8358
2129.72	33.3366
2132.62	36.3618
2135.51	39.2129
2138.41	41.4024
2141.31	44.0534
2144.2	46.7417
2147.09	49.5826
2149.98	53.8364
2152.87	56.4
2155.76	58.6555
2158.65	61.1992
2161.54	63.5267
2164.43	64.881
2167.31	67.0751
2170.2	68.0897
2173.08	68.4461
2175.96	67.8082
2178.84	67.7039
2181.72	67.4983
2184.6	65.6692
2187.48	64.4486
2190.36	61.8462
2193.23	58.2181
2196.11	56.0113
2198.98	53.4813
2201.85	50.9722
2204.72	47.781
2207.59	44.2666
2210.46	41.5165
2213.33	39.2297
2216.2	38.213
2219.07	35.9842
2221.93	32.8279
2224.8	30.2987
2227.66	29.9846
2230.52	28.105
2233.39	26.622
2236.25	25.257
2239.1	23.6005
2241.96	22.2205
2244.82	21.8022
2247.68	20.5531
2250.53	19.9402
2253.38	19.0337
2256.24	18.3571
2259.09	18.0716
2261.94	16.6945
2264.79	17.2947
2267.64	16.5716
2270.49	16.9045
2273.33	16.5022
2276.18	15.5253
2279.02	15.6273
2281.87	16.1076
2284.71	16.256
2287.55	16.0421
2290.39	14.4682
2293.23	13.8627
2296.07	14.8437
2298.91	14.3746
2301.74	14.7418
2304.58	14.6594
2307.41	13.4367
2310.25	13.2004
2313.08	12.875
2315.91	11.4494
2318.74	9.99541
2321.57	8.93317
2324.4	8.12817
2327.23	6.16539
2330.05	6.30843
2332.88	6.46579
2335.7	4.9761
2338.52	2.71036
2341.35	2.76886
2344.17	2.10429
2346.99	2.10804
2349.81	2.22075
2352.62	1.55929
2355.44	1.64171
2358.26	1.26041
2361.07	1.29315
2363.89	2.35414
2366.7	4.1041
2369.51	4.57648
2372.32	5.63871
2375.13	4.65176
2377.94	4.54605
2380.75	5.73723
2383.56	4.82317
2386.36	4.19255
2389.17	4.34092
2391.97	4.53022
2394.77	4.29717
2397.58	4.42453
2400.38	3.94732
2403.18	3.393
2405.97	2.55913
2408.77	3.51246
2411.57	4.52398
2414.37	5.08843
2417.16	5.23451
2419.95	6.26446
2422.75	6.07354
2425.54	5.65828
2428.33	6.16957
2431.12	7.04723
2433.91	7.30438
2436.7	7.53103
2439.48	7.67586
2442.27	7.3612
2445.05	7.01855
2447.84	6.3414
2450.62	7.01097
2453.4	6.90509
2456.18	7.09209
2458.96	6.63168
2461.74	5.75526
2464.52	4.78357
2467.29	5.8653
2470.07	6.3351
2472.85	6.13572
2475.62	7.23428
2478.39	7.74374
2481.16	7.16613
2483.93	6.81837
2486.7	5.64818
2489.47	4.8827
2492.24	3.55999
2495.01	2.96789
2497.77	2.30397
2500.54	2.66579
2503.3	1.85139
2506.06	1.78063
2508.83	1.03858
2511.59	1.22254
2514.35	1.05062
2517.11	1.8791
2519.86	2.98931
2522.62	3.68924
2525.38	3.70429
2528.13	3.48162
2530.89	4.50515
2533.64	4.80175
2536.39	6.58294
2539.14	6.19735
2541.89	6.00013
2544.64	5.9887
2547.39	5.24901
2550.14	4.21128
2552.88	3.7742
2555.63	3.5684
2558.37	2.73128
2561.11	3.03607
2563.86	3.66949
2566.6	3.30348
2569.34	4.02829
2572.08	4.15687
2574.82	3.71514
2577.55	3.61842
2580.29	3.55195
2583.02	3.58404
2585.76	4.79292
2588.49	4.73364
2591.22	4.65262
2593.96	4.51302
2596.69	4.64522
2599.42	4.27154
2602.14	4.98385
2604.87	5.36569
2607.6	4.59699
2610.32	5.38923
2613.05	5.08216
2615.77	4.38177
2618.49	4.77399
2621.22	5.23507
2623.94	5.45639
2626.66	5.61954
2629.37	5.97517
2632.09	5.37949
2634.81	5.65348
2637.53	5.31133
2640.24	4.1804
2642.96	3.44067
2645.67	2.77471
2648.38	2.4293
2651.09	1.60732
2653.8	1.20597
2656.51	0.658459
2659.22	0.425268
2661.93	0.48226
2664.63	0.104713
2667.34	0.478616
2670.04	0.318129
2672.75	0.464369
2675.45	0.402593
2678.15	0.715577
2680.85	0.528059
2683.55	0.461694
2686.25	0.79403
2688.94	1.28491
2691.64	2.30729
2694.34	3.9301
2697.03	4.40012
2699.73	4.92235
2702.42	5.7912
2705.11	6.97119
2707.8	7.20129
2710.49	8.85396
2713.18	8.75232
2715.87	9.0163
2718.55	9.24449
2721.24	10.5583
2723.93	11.3536
2726.61	11.5394
2729.29	11.5182
2731.98	11.3424
2734.66	10.1967
2737.34	9.6635
2740.02	8.97235
2742.7	8.33231
2745.37	7.76153
2748.05	6.55389
2750.72	6.35916
2753.4	6.4513
2756.07	5.9422
2758.75	5.57861
2761.42	4.22145
2764.09	3.82816
2766.76	2.85723
2769.43	3.15024
2772.1	2.53845
2774.76	1.07298
2777.43	0.64513
2780.1	1.16117
2782.76	1.00712
2785.42	0.687713
2788.09	0.783982
2790.75	1.02369
2793.41	-0.0478146
2796.07	-0.832104
2798.73	-0.841995
2801.39	-1.54262
2804.04	-1.63955
2806.7	-1.18428
2809.35	-1.91221
2812.01	-3.06469
2814.66	-3.07664
2817.31	-2.35457
2819.96	-0.944377
2822.61	1.32362
2825.26	5.16725
2827.91	9.34759
2830.56	14.5042
2833.21	19.1839
2835.85	24.4906
2838.5	31.1449
2841.14	39.4891
2843.78	49.6176
2846.42	59.8793
2849.06	71.7204
2851.71	84.8158
2854.34	97.1624
2856.98	109.792
2859.62	120.938
2862.26	131.876
2864.89	141.951
2867.53	150.967
2870.16	158.564
2872.79	165.53
2875.42	170.806
2878.05	175.734
2880.68	180.613
2883.31	185.4
2885.94	190.597
2888.57	194.432
2891.19	199.537
2893.82	204.132
2896.44	209.274
2899.07	216.046
2901.69	225.953
2904.31	237.422
2906.93	250.432
2909.55	264.948
2912.17	280.77
2914.79	296.487
2917.41	311.284
2920.02	323.266
2922.64	334.878
2925.25	343.022
2927.86	348.767
2930.48	350.74
2933.09	350.63
2935.7	346.746
2938.31	341.945
2940.92	334.06
2943.53	324.447
2946.13	312.595
2948.74	299.374
2951.34	285.867
2953.95	271.639
2956.55	258.081
2959.15	245.146
2961.75	232.263
2964.35	220.477
2966.95	208.773
2969.55	197.68
2972.15	187.759
2974.75	177.816
2977.34	168.282
2979.94	158.123
2982.53	146.33
2985.13	134.698
2987.72	123.276
2990.31	110.931
2992.9	97.9449
2995.49	86.1984
2998.08	75.5261
3000.67	64.9394
3003.25	56.2753
3005.84	46.9657
3008.42	39.9122
3011.01	32.3581
3013.59	26.849
3016.17	23.3984
3018.76	19.5347
3021.34	17.5121
3023.92	17.1235
3026.49	14.7778
3029.07	14.4202
3031.65	15.0174
3034.23	15.7586
3036.8	17.3519
3039.38	19.0716
3041.95	19.8486
3044.52	21.1277
3047.09	22.3603
3049.66	24.0561
3052.23	24.8903
3054.8	25.0133
3057.37	24.9801
3059.94	25.6385
3062.5	25.1398
3065.07	24.9032
3067.63	24.1462
3070.2	23.3424
3072.76	21.424
3075.32	18.9088
3077.88	17.0206
3080.44	14.4597
3083	11.7719
3085.56	9.98631
3088.12	7.87051
3090.67	5.96491
3093.23	5.5592
3095.78	5.2057
3098.34	5.22395
3100.89	5.64963
3103.44	5.33386
3105.99	5.7988
3108.54	7.11537
3111.09	7.78195
3113.64	7.80424
3116.19	9.37057
3118.74	10.5137
3121.28	12.3401
3123.83	14.3775
3126.37	15.5084
3128.91	17.1943
3131.46	18.8246
3134	19.82
3136.54	20.7095
3139.08	21.4847
3141.62	23.1829
3144.16	25.396
3146.69	28.8198
3149.23	33.5166