File: data/Raman/poly_smoothed/Thy_10_08_14_1x_45s_532 nm_x100_100%_600 gr_mm_01.txt
#Acq. time (s)=	45
#Accumulations=	2
#Range (cm-¹)=	200...3150
#Windows=	2
#Auto scanning=	Off
#Autofocus=	Off
#Macrospot=	Off
#AutoExposure=	Off
#Spike filter=	Multiple accum.
#Delay time (s)=	0
#Binning=	1
#Readout mode=	Signal
#DeNoise=	Off
#ICS correction=	On
#Dark correction=	Off
#Inst. Process=	Off
#Detector Gain=	Best Dynamic Range
#Detector ADC=	20 kHz
#Detector temperature (°C)=	-69.85
#Instrument=	LabRAM HR Evol
#Detector=	Synapse
#Objective=	x100
#Grating=	600 gr/mm
#ND Filter=	100%
#Laser (nm)=	532
#Hole=	100.021
#Range=	Auto
#Laser Pol.=	No
#Raman. Pol.=	No
#Laser Pol. (°)=	-0.0007625
#Raman Pol. (°)=	89.9995
#Collection=	Microscope
#StageXY=	Marzhauser
#StageZ=	Marzhauser
#X (µm)=	2173.3
#Y (µm)=	1260.7
#Z (µm)=	442.15
#Full time(mm:ss)=	3:19
#Project=
#Sample=
#Site=
#Title=	Thy_10_08_14_2x_45s_532 nm_x100_100%_600 gr_mm
#Remark=
#Date=	05.07.2022 15:11
#Acquired=	05.07.2022 15:11:16
#Base:Fit=	10.08.2022 09:46:25
#Base:Sub=	10.08.2022 09:46:49
#Filter:Polynom=	16.08.2022 10:24:56
#AxisType[0]=Intens
#AxisUnit[0]=Cnt
#AxisType[1]=Spectr
#AxisUnit[1]=1/cm
200.43	19.6928
204.059	18.048
207.688	17.5847
211.314	16.512
214.941	14.6292
218.564	12.6487
222.186	10.8498
225.809	7.47289
229.428	6.95696
233.045	6.52599
236.663	5.37107
240.278	6.11299
243.891	5.8516
247.503	5.74203
251.116	5.97819
254.725	4.91907
258.333	3.53634
261.939	3.74095
265.544	3.62255
269.148	2.76517
272.75	3.6118
276.351	3.6747
279.95	2.9978
283.548	3.84861
287.144	3.28738
290.739	3.89499
294.333	4.35006
297.925	6.72382
301.514	7.53867
305.104	9.11387
308.692	9.79592
312.279	10.1278
315.862	11.247
319.446	12.7908
323.029	15.3092
326.608	15.3115
330.188	16.3685
333.766	15.7615
337.341	15.8251
340.917	16.9112
344.489	16.5595
348.062	15.8666
351.631	15.9498
355.201	14.4315
358.768	13.1912
362.333	11.9035
365.899	9.98374
369.462	9.36108
373.023	7.81516
376.585	8.03197
380.143	8.86007
383.7	9.97504
387.256	11.7597
390.812	10.2182
394.365	8.56107
397.916	7.64135
401.467	7.09113
405.015	8.5013
408.563	8.06436
412.109	7.57119
415.654	7.49546
419.197	7.13492
422.739	6.28575
426.279	6.22787
429.819	5.76234
433.356	4.53864
436.891	3.90928
440.426	3.6269
443.96	3.2545
447.492	4.22558
451.021	4.51384
454.551	6.00667
458.079	7.58785
461.604	9.48257
465.13	10.6918
468.654	13.4277
472.175	15.6679
475.696	17.6679
479.215	19.6932
482.733	21.4683
486.249	22.9184
489.765	24.4693
493.278	26.607
496.789	26.9479
500.301	28.1033
503.81	29.3454
507.317	29.9434
510.825	29.4666
514.33	28.7665
517.833	26.9569
521.335	26.9131
524.836	27.2333
528.335	26.2892
531.835	24.4557
535.332	22.7096
538.827	21.9557
542.321	19.7367
545.814	17.8477
549.305	15.6741
552.795	14.6515
556.282	13.872
559.769	12.2968
563.255	10.6075
566.739	8.02044
570.223	4.85724
573.705	4.06473
577.183	3.01309
580.663	1.64225
584.141	1.49133
587.615	1.87376
591.09	1.47963
594.564	1.45681
598.035	0.025503
601.506	-0.0494599
604.974	0.73096
608.443	1.1933
611.908	1.51482
615.374	2.40957
618.837	1.55237
622.3	3.62556
625.761	4.64114
629.219	7.04965
632.677	9.35598
636.135	11.1218
639.59	12.4255
643.043	13.8784
646.495	15.6224
649.948	15.8427
653.398	17.147
656.846	17.9834
660.293	18.2152
663.738	18.2668
667.183	18.3373
670.626	19.7581
674.067	19.9772
677.508	19.5393
680.947	20.0819
684.385	21.4701
687.821	23.2268
691.254	23.9562
694.688	23.5592
698.121	25.7984
701.552	28.3773
704.98	30.9716
708.409	33.9831
711.836	36.223
715.26	38.8221
718.685	38.5654
722.108	39.8973
725.528	41.2642
728.949	43.3253
732.367	44.5024
735.785	46.0123
739.2	46.8282
742.614	47.5331
746.028	51.3958
749.439	53.2223
752.849	56.359
756.26	59.1989
759.667	60.4048
763.073	62.9416
766.477	66.7036
769.883	68.7875
773.285	70.6065
776.686	72.5436
780.085	73.4337
783.484	76.2295
786.881	77.0847
790.276	78.1201
793.671	79.3086
797.064	80.6341
800.456	80.6877
803.846	82.2931
807.234	83.7564
810.622	83.109
814.008	84.1965
817.394	84.8356
820.778	86.13
824.159	87.2357
827.541	89.2068
830.921	90.0839
834.298	89.337
837.676	86.9296
841.051	85.3308
844.426	84.463
847.798	81.6002
851.171	78.7655
854.54	76.4537
857.911	72.2583
861.278	67.8613
864.645	65.533
868.01	64.3472
871.373	62.0124
874.735	60.3514
878.097	60.4761
881.457	59.2073
884.815	59.5103
888.172	58.0714
891.528	58.0321
894.882	57.6569
898.237	58.3554
901.589	58.1595
904.94	57.3963
908.289	57.8404
911.635	56.8428
914.982	56.8688
918.328	55.4469
921.672	55.757
925.015	56.8439
928.357	54.5475
931.698	53.7903
935.035	52.4812
938.373	51.6596
941.71	50.8348
945.044	49.322
948.378	48.8912
951.709	47.0263
955.041	45.9043
958.372	43.8938
961.699	40.5703
965.027	42.975
968.352	45.2277
971.676	48.1852
975	50.7059
978.322	51.7321
981.642	53.2027
984.962	54.7303
988.28	55.1507
991.596	56.4104
994.911	57.2051
998.227	57.5206
1001.54	56.8909
1004.85	56.5057
1008.16	56.2329
1011.47	56.0061
1014.78	55.068
1018.08	52.5951
1021.39	50.4362
1024.69	47.7604
1028	44.7224
1031.3	41.2391
1034.6	37.6001
1037.9	33.2245
1041.19	30.8102
1044.49	30.6519
1047.78	31.5048
1051.08	28.7065
1054.37	27.2398
1057.66	25.803
1060.95	22.3544
1064.24	21.6738
1067.53	19.4784
1070.81	17.8281
1074.1	16.1199
1077.38	14.0679
1080.66	13.1457
1083.94	13.3305
1087.22	13.536
1090.5	14.3124
1093.78	13.7808
1097.05	12.716
1100.33	14.8411
1103.6	15.7853
1106.87	16.4008
1110.14	14.733
1113.41	13.5275
1116.68	14.52
1119.95	14.7293
1123.21	14.4481
1126.48	12.5219
1129.74	11.2955
1133	10.0553
1136.26	11.0278
1139.52	10.2684
1142.78	9.51674
1146.04	9.37587
1149.29	9.44354
1152.55	8.38866
1155.8	6.90518
1159.05	5.51973
1162.3	4.46888
1165.55	4.07246
1168.8	4.39629
1172.05	4.48706
1175.29	6.41466
1178.54	9.41781
1181.78	11.6123
1185.02	12.4267
1188.26	13.1635
1191.5	14.4398
1194.74	18.0869
1197.97	21.8908
1201.21	24.3606
1204.44	27.7506
1207.68	32.994
1210.91	39.5898
1214.14	44.9166
1217.37	50.4102
1220.59	55.4846
1223.82	58.939
1227.05	62.1538
1230.27	63.1643
1233.49	64.1386
1236.72	67.3722
1239.94	69.5908
1243.16	72.4562
1246.37	75.2732
1249.59	78.0172
1252.8	81.5178
1256.02	81.852
1259.23	82.6063
1262.44	82.9377
1265.66	84.1915
1268.86	83.2066
1272.07	82.1304
1275.28	83.048
1278.48	85.5741
1281.69	85.9844
1284.89	89.2437
1288.09	90.0859
1291.29	92.3158
1294.49	92.5431
1297.69	92.4926
1300.89	92.1559
1304.08	90.5008
1307.28	92.2581
1310.47	93.0687
1313.66	95.9081
1316.85	97.5657
1320.04	97.3194
1323.23	97.8469
1326.42	97.1686
1329.61	97.2173
1332.79	97.173
1335.97	94.2358
1339.16	93.5233
1342.34	90.9521
1345.52	87.4098
1348.7	83.6308
1351.87	79.7297
1355.05	76.8651
1358.22	74.0946
1361.4	70.4637
1364.57	65.7588
1367.74	62.3896
1370.91	59.2559
1374.08	54.9851
1377.25	52.3666
1380.41	50.4271
1383.58	48.4128
1386.74	47.1165
1389.91	44.1907
1393.07	42.1638
1396.23	40.4414
1399.39	40.6265
1402.55	41.1317
1405.7	42.8802
1408.86	45.3167
1412.01	49.3443
1415.17	52.1486
1418.32	56.9243
1421.47	63.8629
1424.62	70.4765
1427.77	79.9672
1430.91	89.5078
1434.06	97.8557
1437.2	103.407
1440.35	109.483
1443.49	113.385
1446.63	115.656
1449.77	115.887
1452.91	115.652
1456.05	112.968
1459.18	108.225
1462.32	102.012
1465.45	94.3175
1468.59	83.4056
1471.72	74.5256
1474.85	64.4138
1477.98	56.2316
1481.1	45.4233
1484.23	35.5515
1487.36	27.1374
1490.48	21.2311
1493.61	15.9999
1496.73	12.6967
1499.85	10.5985
1502.97	8.97116
1506.09	8.71179
1509.2	7.01968
1512.32	6.70019
1515.43	5.31055
1518.55	6.84177
1521.66	8.77836
1524.77	9.20031
1527.88	10.9461
1530.99	14.41
1534.1	15.6452
1537.21	18.4388
1540.31	21.0123
1543.42	23.5217
1546.52	27.4693
1549.62	30.4311
1552.72	35.4476
1555.82	39.3549
1558.92	43.9893
1562.02	48.4467
1565.11	53.1617
1568.21	57.5812
1571.3	61.3574
1574.39	65.8896
1577.49	70.0506
1580.57	73.862
1583.66	77.6892
1586.75	79.9602
1589.84	83.6355
1592.92	85.9973
1596.01	87.759
1599.09	87.4837
1602.17	86.0766
1605.25	85.4422
1608.33	85.1864
1611.41	84.0818
1614.49	83.5986
1617.57	83.7864
1620.64	85.0922
1623.72	87.0717
1626.79	90.4455
1629.86	93.9517
1632.93	97.7346
1636	101.275
1639.07	104.385
1642.13	109.108
1645.2	114.806
1648.26	119.644
1651.33	123.967
1654.39	128.492
1657.45	131.738
1660.51	133.321
1663.57	132.496
1666.63	130.632
1669.68	126.777
1672.74	120.963
1675.79	113.646
1678.85	106.281
1681.9	99.0172
1684.95	89.466
1688	80.0467
1691.05	70.4966
1694.09	62.3928
1697.14	53.7926
1700.18	45.9358
1703.23	38.1724
1706.27	31.2606
1709.31	24.9772
1712.35	19.7401
1715.39	15.3669
1718.43	14.129
1721.47	12.2653
1724.5	10.0914
1727.54	10.0673
1730.57	9.6151
1733.61	9.32052
1736.64	7.26276
1739.67	6.55736
1742.7	6.25133
1745.72	5.84035
1748.75	5.39749
1751.77	4.90772
1754.8	3.78196
1757.82	2.84732
1760.84	1.87999
1763.87	1.63611
1766.89	1.29461
1769.91	0.873004
1772.92	-0.621891
1775.94	-0.469683
1778.95	-0.866126
1781.97	-1.0832
1784.98	-1.52292
1787.99	-1.62579
1791.01	-0.421301
1794.01	0.238812
1797.02	1.20688
1800.03	1.90639
1803.04	1.8043
1806.04	0.999041
1809.05	1.63965
1812.05	1.899
1815.05	1.99516
1818.05	2.17471
1821.05	2.48071
1824.05	1.97973
1827.05	1.50556
1830.04	1.43871
1833.04	1.12036
1836.03	1.22234
1839.03	1.58969
1842.02	1.68165
1845.01	2.02297
1848	3.10649
1850.99	3.65858
1853.97	4.32833
1856.96	4.8552
1859.94	5.31844
1862.93	5.92567
1865.91	6.4502
1868.89	7.49708
1871.87	8.49458
1874.85	8.54522
1877.83	8.42877
1880.81	8.99637
1882.57	10.1146
1885.56	10.2235
1888.55	10.0897
1891.54	10.1569
1894.52	9.38301
1897.51	9.51436
1900.49	8.97185
1903.47	9.13149
1906.45	9.76408
1909.43	10.1258
1912.41	9.78239
1915.39	10.7193
1918.37	11.5391
1921.34	10.896
1924.32	10.6294
1927.29	11.203
1930.26	10.9435
1933.23	11.1158
1936.2	12.2214
1939.17	12.2211
1942.14	12.684
1945.11	11.5525
1948.07	12.335
1951.04	13.0915
1954	14.0709
1956.96	14.515
1959.93	14.9958
1962.89	15.0838
1965.85	16.2538
1968.8	16.2503
1971.76	17.0237
1974.72	18.4631
1977.67	18.917
1980.63	18.9904
1983.58	18.9623
1986.53	19.7544
1989.48	20.5413
1992.43	20.7417
1995.38	20.6022
1998.32	20.7081
2001.27	21.3939
2004.22	21.7439
2007.16	21.5903
2010.1	21.4203
2013.04	20.994
2015.98	20.1167
2018.92	20.3973
2021.86	21.7015
2024.8	21.9759
2027.74	21.8227
2030.67	21.9015
2033.61	21.2486
2036.54	21.4768
2039.47	21.2492
2042.4	21.1973
2045.33	22.0775
2048.26	21.7072
2051.19	21.2878
2054.12	21.2976
2057.04	21.4093
2059.97	22.0438
2062.89	21.5813
2065.81	21.0143
2068.73	22.2065
2071.65	21.8949
2074.57	23.673
2077.49	24.6056
2080.41	24.185
2083.32	24.5798
2086.24	26.0511
2089.15	26.7536
2092.07	28.346
2094.98	29.7847
2097.89	30.2138
2100.8	30.8651
2103.71	30.7133
2106.61	32.2162
2109.52	33.1372
2112.43	33.2206
2115.33	33.8204
2118.23	34.9381
2121.13	35.6926
2124.04	37.5976
2126.94	38.0426
2129.83	37.8471
2132.73	38.8219
2135.63	40.6312
2138.53	43.0711
2141.42	45.7499
2144.31	47.4392
2147.21	49.6521
2150.1	50.5779
2152.99	52.2579
2155.88	54.3633
2158.77	56.6486
2161.65	58.3012
2164.54	60.2275
2167.43	61.7866
2170.31	62.678
2173.19	63.5652
2176.07	64.0607
2178.96	64.5256
2181.84	65.1955
2184.72	66.1159
2187.59	66.7335
2190.47	67.3682
2193.35	66.6283
2196.22	64.8772
2199.09	62.989
2201.97	61.3755
2204.84	59.2956
2207.71	58.5563
2210.58	56.1167
2213.45	54.1303
2216.31	51.8383
2219.18	48.8061
2222.05	46.5806
2224.91	44.9278
2227.78	43.3006
2230.64	41.645
2233.5	38.9041
2236.36	35.9133
2239.22	34.2173
2242.08	32.3332
2244.93	30.9678
2247.79	29.9464
2250.64	29.4447
2253.5	29.2656
2256.35	29.0512
2259.2	27.8557
2262.05	26.7532
2264.9	26.1599
2267.75	25.1152
2270.6	24.7375
2273.45	23.7821
2276.29	23.8386
2279.14	23.5414
2281.98	24.7748
2284.82	24.3151
2287.66	23.915
2290.5	24.2051
2293.34	23.3637
2296.18	23.6028
2299.02	23.5348
2301.86	24.2272
2304.69	25.373
2307.53	25.3588
2310.36	26.1193
2313.19	25.4124
2316.02	25.5547
2318.85	24.5099
2321.68	24.6659
2324.51	24.2247
2327.34	24.3247
2330.16	24.092
2332.99	22.836
2335.81	21.783
2338.64	20.5724
2341.46	19.0169
2344.28	18.4514
2347.1	17.1998
2349.92	16.1743
2352.74	14.4754
2355.55	12.4008
2358.37	11.5757
2361.19	10.1559
2364	10.2023
2366.81	11.5486
2369.62	11.613
2372.44	11.8899
2375.24	11.6733
2378.05	11.304
2380.86	10.5662
2383.67	10.745
2386.47	10.4558
2389.28	10.8152
2392.08	11.3584
2394.89	11.3999
2397.69	11.4816
2400.49	11.1259
2403.29	10.9694
2406.09	10.3287
2408.88	10.7445
2411.68	10.8814
2414.48	11.737
2417.27	11.8963
2420.06	11.6233
2422.86	12.2791
2425.65	12.4477
2428.44	12.7378
2431.23	12.8433
2434.02	13.4201
2436.81	12.5766
2439.59	12.4413
2442.38	12.8195
2445.16	12.0083
2447.95	10.9857
2450.73	10.3073
2453.51	10.099
2456.29	9.73386
2459.07	9.52633
2461.85	9.4837
2464.63	8.90193
2467.4	9.15877
2470.18	8.60161
2472.95	7.70896
2475.73	6.55267
2478.5	6.7391
2481.27	5.94511
2484.04	4.02233
2486.81	3.53037
2489.58	3.44937
2492.35	2.555
2495.12	2.43452
2497.88	2.07037
2500.65	1.30903
2503.41	0.749008
2506.17	0.604854
2508.94	0.901644
2511.7	0.0965478
2514.46	0.808133
2517.22	0.778571
2519.97	1.55722
2522.73	2.44332
2525.49	2.87682
2528.24	3.55161
2530.99	4.23619
2533.75	4.06646
2536.5	3.33424
2539.25	2.89467
2542	3.83047
2544.75	3.8019
2547.5	3.21942
2550.24	2.60593
2552.99	2.48836
2555.74	3.54022
2558.48	3.05994
2561.22	3.2104
2563.96	2.22444
2566.71	2.22967
2569.45	2.41789
2572.18	3.54413
2574.92	3.4969
2577.66	3.27513
2580.4	3.2391
2583.13	3.24303
2585.87	3.02525
2588.6	3.26832
2591.33	3.43104
2594.06	2.70761
2596.79	1.6012
2599.52	1.8503
2602.25	1.72457
2604.98	1.53793
2607.71	1.64146
2610.43	1.76752
2613.16	2.06459
2615.88	2.33861
2618.6	1.77225
2621.32	2.32713
2624.04	1.95836
2626.76	1.98325
2629.48	1.99315
2632.2	2.32306
2634.92	3.68463
2637.63	3.93834
2640.35	3.45479
2643.06	2.6933
2645.77	2.42269
2648.49	2.084
2651.2	2.12604
2653.91	1.66677
2656.62	0.81741
2659.33	-0.157624
2662.03	-0.723847
2664.74	-0.281248
2667.44	-0.102056
2670.15	0.196211
2672.85	-0.351122
2675.55	0.28648
2678.26	0.0406333
2680.96	1.40934
2683.66	0.590129
2686.35	1.17325
2689.05	2.37679
2691.75	3.06925
2694.44	4.10418
2697.14	5.3108
2699.83	5.93042
2702.52	7.30905
2705.22	8.49415
2707.91	10.2316
2710.6	10.1144
2713.29	11.1968
2715.97	12.6744
2718.66	13.8687
2721.35	15.7388
2724.03	16.1026
2726.72	17.2213
2729.4	17.2984
2732.08	18.1585
2734.76	17.7704
2737.44	17.3179
2740.12	16.6104
2742.8	15.3969
2745.48	15.1211
2748.16	13.2881
2750.83	12.2984
2753.51	12.2225
2756.18	11.2747
2758.85	10.6592
2761.53	10.1933
2764.2	9.76893
2766.87	8.92058
2769.54	8.98438
2772.2	7.86848
2774.87	7.15564
2777.54	6.97717
2780.2	6.50636
2782.87	5.75181
2785.53	4.98578
2788.19	4.16223
2790.85	3.52042
2793.51	2.95393
2796.17	2.43738
2798.83	0.931674
2801.49	1.13033
2804.15	1.83769
2806.8	1.02513
2809.46	0.333901
2812.11	1.45613
2814.76	1.41183
2817.42	3.54509
2820.07	7.07554
2822.72	10.2759
2825.37	15.2538
2828.02	19.4322
2830.66	24.9616
2833.31	31.5663
2835.96	38.5009
2838.6	48.0707
2841.24	57.671
2843.89	70.3474
2846.53	84.9424
2849.17	100.954
2851.81	118.75
2854.45	137.326
2857.09	155.743
2859.72	172.824
2862.36	189.372
2865	205.681
2867.63	220.776
2870.26	233.551
2872.9	244.342
2875.53	255.834
2878.16	264.85
2880.79	274.002
2883.42	281.026
2886.05	286.728
2888.67	292.824
2891.3	298.902
2893.92	305.983
2896.55	313.419
2899.17	324.304
2901.79	335.671
2904.42	350.307
2907.04	367.979
2909.66	388.743
2912.27	410.55
2914.89	431.819
2917.51	453.214
2920.13	472.249
2922.74	487.41
2925.35	500.518
2927.97	508.095
2930.58	512.986
2933.19	513.451
2935.8	510.787
2938.41	504.916
2941.02	494.498
2943.63	482.305
2946.24	466.511
2948.84	449.042
2951.45	430.756
2954.05	412.362
2956.65	393.586
2959.26	375.176
2961.86	356.389
2964.46	339.096
2967.06	321.454
2969.66	307.807
2972.25	294.012
2974.85	280.734
2977.45	267.466
2980.04	251.928
2982.64	237.759
2985.23	222.2
2987.82	206.232
2990.41	189.557
2993	173.066
2995.59	157.691
2998.18	143.205
3000.77	129.575
3003.36	115.566
3005.94	102.952
3008.53	91.6399
3011.11	80.8643
3013.69	72.1375
3016.28	65.6186
3018.86	60.3064
3021.44	55.2779
3024.02	50.9011
3026.6	47.8498
3029.18	46.1572
3031.75	45.5533
3034.33	46.2346
3036.9	46.5478
3039.48	48.2907
3042.05	49.9806
3044.62	51.6121
3047.19	54.5849
3049.77	55.8652
3052.34	56.55
3054.9	57.1311
3057.47	57.4326
3060.04	56.5876
3062.61	56.1889
3065.17	53.5032
3067.74	50.0149
3070.3	47.429
3072.86	43.441
3075.42	38.7923
3077.99	35.1873
3080.54	31.7295
3083.1	27.2393
3085.66	23.0211
3088.22	18.6159
3090.78	14.7812
3093.33	11.6775
3095.89	9.72655
3098.44	8.04769
3100.99	7.37739
3103.54	6.31137
3106.1	6.84656
3108.65	5.53603
3111.2	6.01866
3113.74	5.37754
3116.29	5.00709
3118.84	5.05227
3121.38	4.89634
3123.93	4.54045
3126.47	5.2902
3129.01	4.34368
3131.56	4.25533
3134.1	4.32964
3136.64	3.38238
3139.18	3.21592
3141.72	2.72635
3144.26	1.43985
3146.79	-0.0407049
3149.33	-0.341794