File: data/Raman/poly_smoothed/Thy_20_09_19_1x_45s_532 nm_x100_100%_600 gr_mm_01.txt
#Acq. time (s)=	45
#Accumulations=	2
#Range (cm-¹)=	200...3150
#Windows=	2
#Auto scanning=	Off
#Autofocus=	Off
#Macrospot=	Off
#AutoExposure=	Off
#Spike filter=	Multiple accum.
#Delay time (s)=	0
#Binning=	1
#Readout mode=	Signal
#DeNoise=	Off
#ICS correction=	On
#Dark correction=	Off
#Inst. Process=	Off
#Detector Gain=	Best Dynamic Range
#Detector ADC=	20 kHz
#Detector temperature (°C)=	-69.85
#Instrument=	LabRAM HR Evol
#Detector=	Synapse
#Objective=	x100
#Grating=	600 gr/mm
#ND Filter=	100%
#Laser (nm)=	532
#Hole=	100.021
#Range=	Auto
#Laser Pol.=	No
#Raman. Pol.=	No
#Laser Pol. (°)=	-0.0007625
#Raman Pol. (°)=	89.9995
#Collection=	Microscope
#StageXY=	Marzhauser
#StageZ=	Marzhauser
#X (µm)=	-5892.8
#Y (µm)=	2886.5
#Z (µm)=	-223.35
#Full time(mm:ss)=	3:18
#Project=
#Sample=
#Site=
#Title=	Thy_20_09_19_2x_45s_532 nm_x100_100%_600 gr_mm
#Remark=
#Date=	29.06.2022 12:01
#Acquired=	29.06.2022 12:01:07
#Base:Fit=	10.08.2022 09:52:02
#Base:Fit=	10.08.2022 09:52:12
#Base:Sub=	10.08.2022 09:54:21
#Filter:Polynom=	16.08.2022 10:24:04
#AxisType[0]=Intens
#AxisUnit[0]=Cnt
#AxisType[1]=Spectr
#AxisUnit[1]=1/cm
200.523	4.88542
204.154	6.45726
207.781	9.0173
211.409	10.465
215.034	11.7158
218.659	12.5359
222.281	12.4379
225.903	14.0595
229.522	13.7114
233.14	13.4629
236.756	13.0413
240.373	12.4948
243.986	12.7174
247.598	12.7155
251.208	12.7693
254.818	11.2637
258.427	10.9651
262.034	10.024
265.638	9.96437
269.242	9.58521
272.844	7.58294
276.445	6.19701
280.044	5.35808
283.642	5.63164
287.238	6.32698
290.833	6.26041
294.425	6.88677
298.017	7.52804
301.608	8.79752
305.198	10.789
308.786	11.8784
312.371	13.5271
315.956	14.8348
319.54	16.1133
323.122	17.5789
326.701	19.8878
330.281	22.137
333.857	23.3342
337.434	24.3156
341.008	25.0506
344.582	25.0878
348.153	24.2684
351.724	23.1623
355.292	21.6136
358.861	21.4598
362.426	20.9526
365.99	20.2111
369.555	18.6758
373.116	19.0099
376.676	18.9384
380.236	16.4
383.793	17.385
387.349	15.5052
390.903	15.2283
394.456	14.3611
398.007	13.0856
401.56	12.2562
405.108	12.0906
408.656	12.2674
412.202	12.4754
415.746	13.0439
419.29	13.5949
422.831	13.9758
426.37	14.24
429.909	13.0422
433.447	12.4586
436.983	11.8262
440.519	11.876
444.052	12.0648
447.583	11.8054
451.114	11.3143
454.643	10.2842
458.169	10.7432
461.696	11.2215
465.222	10.4539
468.744	9.40977
472.267	9.42031
475.787	9.57685
479.307	9.30463
482.823	8.38055
486.341	9.6375
489.855	11.0432
493.37	11.9802
496.881	13.4327
500.391	14.904
503.902	14.6274
507.409	15.5631
510.915	14.8252
514.42	14.9247
517.925	15.2457
521.427	15.7364
524.928	16.7632
528.427	16.8347
531.925	15.7269
535.422	15.9254
538.917	13.5441
542.411	14.578
545.903	13.6472
549.395	12.5463
552.884	10.081
556.373	9.55262
559.86	10.3956
563.346	9.39248
566.831	9.04603
570.314	7.94351
573.794	8.9968
577.274	8.29397
580.754	7.31219
584.23	6.28837
587.706	4.97439
591.181	3.44936
594.653	3.37579
598.126	2.36574
601.595	2.71761
605.065	3.37777
608.532	4.5497
611.999	5.53675
615.463	4.89999
618.928	5.13044
622.389	5.04259
625.851	5.62209
629.31	7.26854
632.767	7.97507
636.223	9.24363
639.68	10.5112
643.134	12.7779
646.586	15.1458
650.037	16.4599
653.486	18.2921
656.936	19.1717
660.383	21.1129
663.829	21.412
667.273	21.8351
670.716	21.9181
674.158	21.9103
677.598	23.0606
681.035	24.0036
684.473	23.7012
687.909	25.004
691.344	26.8543
694.778	28.5235
698.211	29.8317
701.64	31.2041
705.07	32.6798
708.498	35.1274
711.924	36.7343
715.35	37.1709
718.774	38.8272
722.196	39.2085
725.618	40.9164
729.037	41.5412
732.456	42.6215
735.873	44.1285
739.289	44.8846
742.703	45.602
746.116	46.8642
749.529	47.0651
752.938	48.2032
756.347	48.792
759.756	49.8375
763.162	51.0858
766.567	52.7021
769.97	53.7553
773.372	55.7832
776.773	58.2555
780.174	56.4823
783.573	58.3068
786.97	62.2373
790.365	66.8529
793.76	70.8251
797.153	73.5584
800.543	76.4855
803.933	78.8449
807.322	79.858
810.71	79.8275
814.097	80.8399
817.483	81.2891
820.865	80.389
824.248	78.2542
827.629	77.4529
831.008	76.5368
834.387	74.8175
837.765	72.5066
841.139	70.0079
844.514	67.4509
847.886	63.6342
851.259	59.5547
854.629	54.8534
857.997	49.7797
861.366	45.3317
864.732	43.2582
868.098	43.3041
871.461	42.6355
874.823	41.7032
878.184	40.2614
881.545	39.488
884.903	38.485
888.26	37.7036
891.616	35.5446
894.97	35.0244
898.323	35.9944
901.675	35.8216
905.026	35.916
908.375	36.0117
911.723	37.8987
915.07	40.0094
918.415	39.8887
921.76	40.7271
925.103	39.6045
928.443	38.229
931.783	36.6034
935.123	36.9689
938.461	35.2294
941.796	32.7469
945.131	31.6059
948.465	29.7369
951.797	28.1612
955.128	26.9567
958.457	25.5868
961.786	24.0723
965.113	26.4635
968.44	27.4628
971.763	26.8843
975.086	27.3946
978.409	27.4156
981.729	27.4507
985.048	28.2781
988.367	28.3897
991.683	28.8195
994.998	29.6839
998.312	30.4107
1001.62	29.903
1004.94	28.2657
1008.25	27.244
1011.56	27.6149
1014.86	26.5832
1018.17	24.7383
1021.48	21.8676
1024.78	20.7562
1028.08	19.2277
1031.38	18.0375
1034.68	16.1281
1037.98	14.0103
1041.28	12.5123
1044.57	13.2372
1047.87	12.9841
1051.16	12.0312
1054.45	10.9114
1057.75	9.71199
1061.04	8.95912
1064.32	8.63605
1067.61	7.984
1070.9	8.55862
1074.18	7.91466
1077.47	8.13306
1080.75	8.78912
1084.03	7.037
1087.31	6.82574
1090.59	8.00408
1093.86	8.71295
1097.14	9.81601
1100.41	11.2584
1103.69	12.4272
1106.96	13.2177
1110.23	14.5733
1113.5	14.4434
1116.77	11.6511
1120.03	10.8067
1123.3	9.96121
1126.56	10.8544
1129.83	12.1122
1133.09	11.7488
1136.35	10.6492
1139.61	9.46436
1142.86	8.61146
1146.12	8.28166
1149.38	6.64155
1152.63	5.53141
1155.88	4.93988
1159.14	5.62505
1162.39	4.17506
1165.63	3.70647
1168.88	3.98363
1172.13	3.63634
1175.38	4.9755
1178.62	7.2829
1181.86	7.50797
1185.1	7.56727
1188.34	6.76842
1191.58	7.8624
1194.82	9.51669
1198.06	9.81452
1201.29	12.1537
1204.53	15.5928
1207.76	19.582
1210.99	22.849
1214.22	24.4764
1217.45	27.3278
1220.68	29.6287
1223.91	32.4508
1227.13	34.8005
1230.36	37.2505
1233.58	39.1348
1236.8	40.8398
1240.02	40.4698
1243.24	40.443
1246.46	41.9634
1249.67	42.8358
1252.89	44.8687
1256.1	46.4925
1259.32	47.3634
1262.53	47.6439
1265.74	48.2434
1268.95	50.5756
1272.15	52.8674
1275.36	52.8848
1278.57	53.6337
1281.77	56.7295
1284.97	58.0012
1288.18	58.3948
1291.38	59.2532
1294.58	60.4564
1297.78	61.0528
1300.97	62.3028
1304.17	64.2887
1307.36	64.9788
1310.55	64.7933
1313.75	63.6826
1316.94	64.8992
1320.13	65.2525
1323.32	65.4896
1326.5	65.1277
1329.69	65.9073
1332.87	65.1175
1336.06	64.6083
1339.24	62.8161
1342.42	60.9772
1345.6	59.6532
1348.78	58.1606
1351.96	54.9581
1355.13	52.7697
1358.31	50.4459
1361.48	48.0999
1364.65	47.287
1367.82	46.1502
1370.99	44.1221
1374.16	43.8111
1377.33	42.9085
1380.5	41.6137
1383.66	40.744
1386.83	39.7915
1389.99	39.3782
1393.15	39.1425
1396.31	38.2293
1399.47	36.6461
1402.63	37.2299
1405.78	38.4109
1408.94	39.8197
1412.1	40.2266
1415.25	41.7772
1418.4	43.5814
1421.55	46.6749
1424.7	50.3544
1427.85	54.7919
1431	58.6417
1434.14	62.1501
1437.29	66.29
1440.43	69.4688
1443.57	71.4978
1446.71	72.6137
1449.85	72.5224
1452.99	72.6058
1456.13	71.5506
1459.26	68.6651
1462.4	64.0392
1465.54	59.9429
1468.67	55.2633
1471.8	49.4027
1474.93	43.8553
1478.06	40.1185
1481.19	35.6756
1484.31	32.0762
1487.44	28.9103
1490.56	24.8729
1493.69	23.5052
1496.81	21.5776
1499.93	23.3968
1503.05	23.7286
1506.17	24.4643
1509.28	24.681
1512.4	25.5338
1515.52	27.4141
1518.63	29.4749
1521.74	32.4692
1524.85	33.9616
1527.96	34.3279
1531.07	35.3941
1534.18	35.5202
1537.29	34.8841
1540.39	36.962
1543.5	39.4004
1546.6	42.398
1549.7	44.6015
1552.8	47.3259
1555.9	49.9888
1559	52.3088
1562.1	55.5264
1565.19	57.9455
1568.29	61.0569
1571.38	63.7367
1574.47	65.8841
1577.56	68.7584
1580.66	70.2553
1583.74	71.5634
1586.83	73.5186
1589.92	74.6421
1593.01	74.5611
1596.09	74.1183
1599.17	70.6581
1602.25	67.5043
1605.34	67.3897
1608.41	63.7724
1611.49	62.9021
1614.57	62.0522
1617.65	62.0419
1620.72	62.0757
1623.79	62.107
1626.87	62.2884
1629.94	60.8933
1633.01	60.5476
1636.08	61.8477
1639.15	62.4233
1642.21	64.1571
1645.28	66.5698
1648.34	68.0405
1651.41	68.8223
1654.47	69.5855
1657.53	68.6311
1660.59	67.9807
1663.65	66.619
1666.71	65.0315
1669.76	62.8658
1672.82	60.0338
1675.87	56.3143
1678.93	52.1911
1681.98	48.0686
1685.03	42.8375
1688.08	38.8348
1691.13	34.9308
1694.17	31.8208
1697.22	27.3326
1700.27	23.0871
1703.31	19.1902
1706.35	16.6153
1709.39	15.7644
1712.43	14.6829
1715.47	14.3499
1718.51	13.5457
1721.55	13.4727
1724.58	11.6468
1727.62	11.0961
1730.65	11.3532
1733.68	10.8525
1736.72	11.9349
1739.74	11.9029
1742.77	10.6582
1745.8	9.35348
1748.83	7.20105
1751.85	6.59617
1754.88	6.04154
1757.9	5.35544
1760.92	4.08794
1763.95	4.3356
1766.96	4.13687
1769.98	3.2007
1773	2.87274
1776.02	2.85632
1779.03	2.76594
1782.05	3.52511
1785.06	2.67277
1788.07	2.50597
1791.08	2.73363
1794.09	3.02737
1797.1	3.62703
1800.11	4.37456
1803.12	4.7443
1806.12	5.07071
1809.12	4.72927
1812.13	4.6385
1815.13	4.54776
1818.13	4.18061
1821.13	4.36235
1824.13	4.93454
1827.13	4.68456
1830.12	3.83926
1833.12	3.26871
1836.11	2.46123
1839.1	2.8751
1842.09	2.64575
1845.09	2.05206
1848.08	1.65387
1851.06	1.69645
1854.05	2.0002
1857.04	1.39289
1860.02	1.49336
1863.01	0.805615
1865.99	0.527243
1868.97	0.880913
1871.95	1.39627
1874.93	0.773977
1877.91	0.831444
1880.89	1.27372
1882.46	1.24928
1885.45	2.28954
1888.43	2.73214
1891.42	3.03156
1894.41	3.30611
1897.39	4.11348
1900.37	3.60806
1903.36	3.21822
1906.34	3.21354
1909.32	3.82339
1912.29	3.60522
1915.27	3.86385
1918.25	3.62697
1921.23	4.09309
1924.2	4.2584
1927.17	4.32259
1930.15	3.78403
1933.12	2.88427
1936.09	2.56141
1939.06	2.31966
1942.02	2.32995
1944.99	2.35165
1947.96	2.28742
1950.92	2.17518
1953.88	1.92584
1956.85	2.33299
1959.81	2.90707
1962.77	2.91019
1965.73	3.21637
1968.69	3.08205
1971.64	2.40823
1974.6	1.60937
1977.55	1.95749
1980.51	1.96339
1983.46	1.39522
1986.41	1.1771
1989.36	1.40554
1992.31	0.790801
1995.26	0.889383
1998.21	0.821702
2001.15	0.74693
2004.1	1.11682
2007.04	1.0951
2009.99	1.45287
2012.93	1.54824
2015.87	1.92975
2018.81	1.69389
2021.75	2.59709
2024.68	2.77397
2027.62	3.06857
2030.56	4.18497
2033.49	5.86364
2036.42	5.98465
2039.36	5.40267
2042.29	5.83896
2045.22	5.90626
2048.14	6.59212
2051.07	6.58917
2054	5.71928
2056.93	6.04758
2059.85	6.33896
2062.77	6.04396
2065.7	4.90536
2068.62	4.58276
2071.54	4.12466
2074.46	3.52366
2077.38	3.00385
2080.29	2.73864
2083.21	2.58003
2086.12	2.77976
2089.04	4.43151
2091.95	4.96726
2094.86	5.39785
2097.77	6.11995
2100.68	6.8682
2103.59	7.34165
2106.5	8.23693
2109.41	8.96624
2112.31	10.2535
2115.21	10.8808
2118.12	12.0411
2121.02	12.191
2123.92	14.8735
2126.82	16.1061
2129.72	17.7665
2132.62	18.9361
2135.51	19.9783
2138.41	21.5007
2141.31	22.5361
2144.2	23.3885
2147.09	24.69
2149.98	26.2436
2152.87	28.8642
2155.76	31.3046
2158.65	33.0457
2161.54	34.595
2164.43	35.6379
2167.31	36.114
2170.2	36.0546
2173.08	35.717
2175.96	35.1781
2178.84	35.9704
2181.72	34.4158
2184.6	33.0406
2187.48	32.0921
2190.36	31.2023
2193.23	29.8022
2196.11	28.3131
2198.98	26.4515
2201.85	24.3133
2204.72	22.8924
2207.59	20.9075
2210.46	19.0007
2213.33	16.9499
2216.2	15.4396
2219.07	14.0716
2221.93	14.0831
2224.8	14.0739
2227.66	12.7515
2230.52	12.1612
2233.39	11.9178
2236.25	11.2492
2239.1	9.87873
2241.96	10.0487
2244.82	9.91016
2247.68	10.5318
2250.53	9.2292
2253.38	9.10678
2256.24	9.24673
2259.09	8.78528
2261.94	8.74051
2264.79	9.04294
2267.64	10.3829
2270.49	11.1062
2273.33	10.4017
2276.18	10.1025
2279.02	9.38932
2281.87	8.24618
2284.71	7.49328
2287.55	6.72432
2290.39	6.1385
2293.23	5.60565
2296.07	5.38935
2298.91	5.3422
2301.74	6.38193
2304.58	8.12435
2307.41	7.63757
2310.25	8.06077
2313.08	8.11827
2315.91	8.5815
2318.74	8.67603
2321.57	8.8044
2324.4	9.0256
2327.23	9.2017
2330.05	9.60337
2332.88	10.0718
2335.7	9.99838
2338.52	8.92616
2341.35	7.21516
2344.17	6.18655
2346.99	5.02903
2349.81	3.77046
2352.62	2.67759
2355.44	2.13422
2358.26	2.10834
2361.07	2.02078
2363.89	1.67733
2366.7	2.23858
2369.51	2.65534
2372.32	2.24574
2375.13	0.843575
2377.94	1.43828
2380.75	1.47628
2383.56	1.75745
2386.36	1.93881
2389.17	2.86475
2391.97	2.81282
2394.77	3.61267
2397.58	4.03382
2400.38	5.09109
2403.18	5.15292
2405.97	4.68562
2408.77	5.14105
2411.57	6.11499
2414.37	7.01287
2417.16	7.61959
2419.95	8.8639
2422.75	9.95223
2425.54	9.9865
2428.33	10.1777
2431.12	9.37343
2433.91	9.57167
2436.7	9.09507
2439.48	7.62057
2442.27	6.39675
2445.05	6.09704
2447.84	6.39776
2450.62	5.12133
2453.4	5.22986
2456.18	5.57369
2458.96	5.57516
2461.74	4.95977
2464.52	5.05037
2467.29	5.10203
2470.07	3.95525
2472.85	3.95577
2475.62	4.49219
2478.39	4.76109
2481.16	4.71142
2483.93	4.47525
2486.7	3.63221
2489.47	4.77846
2492.24	4.11736
2495.01	3.45872
2497.77	3.47181
2500.54	3.62656
2503.3	2.76642
2506.06	1.77342
2508.83	1.85139
2511.59	2.01753
2514.35	2.51029
2517.11	2.96611
2519.86	3.16529
2522.62	3.78992
2525.38	3.35659
2528.13	3.36191
2530.89	3.5459
2533.64	3.67253
2536.39	3.53761
2539.14	4.02596
2541.89	4.29886
2544.64	2.82878
2547.39	2.74796
2550.14	1.53312
2552.88	1.96414
2555.63	2.12239
2558.37	1.91476
2561.11	1.36825
2563.86	1.81662
2566.6	2.36022
2569.34	2.23142
2572.08	2.21138
2574.82	3.37561
2577.55	3.6159
2580.29	4.70484
2583.02	5.04476
2585.76	5.46973
2588.49	5.55388
2591.22	5.94743
2593.96	6.76219
2596.69	7.32654
2599.42	6.66004
2602.14	6.63297
2604.87	6.76012
2607.6	6.41388
2610.32	5.96059
2613.05	6.57452
2615.77	7.24871
2618.49	6.28102
2621.22	6.35314
2623.94	6.34224
2626.66	7.11695
2629.37	6.62942
2632.09	7.40046
2634.81	7.27557
2637.53	7.88549
2640.24	7.98107
2642.96	8.41949
2645.67	8.63348
2648.38	9.63295
2651.09	9.65279
2653.8	9.08074
2656.51	8.75301
2659.22	8.29768
2661.93	7.63966
2664.63	6.84989
2667.34	6.99043
2670.04	6.92375
2672.75	6.79816
2675.45	7.08998
2678.15	7.05194
2680.85	7.00607
2683.55	6.97357
2686.25	6.56496
2688.94	7.21146
2691.64	7.27746
2694.34	7.55973
2697.03	7.90195
2699.73	7.9337
2702.42	8.20097
2705.11	7.8957
2707.8	7.94436
2710.49	8.48086
2713.18	8.34368
2715.87	9.07832
2718.55	8.5251
2721.24	7.95003
2723.93	6.62549
2726.61	7.36496
2729.29	6.60941
2731.98	7.26152
2734.66	7.24848
2737.34	7.43004
2740.02	8.25112
2742.7	8.19764
2745.37	7.76869
2748.05	7.87527
2750.72	6.71678
2753.4	5.75864
2756.07	5.86678
2758.75	6.10117
2761.42	5.79066
2764.09	4.8677
2766.76	4.19771
2769.43	4.22522
2772.1	3.05671
2774.76	2.95584
2777.43	3.0696
2780.1	2.55415
2782.76	1.96794
2785.42	0.409263
2788.09	-0.0402254
2790.75	-0.36504
2793.41	-0.726266
2796.07	-0.394666
2798.73	0.899595
2801.39	0.840077
2804.04	0.957617
2806.7	1.32899
2809.35	1.3452
2812.01	1.46005
2814.66	1.30145
2817.31	1.29196
2819.96	2.19883
2822.61	3.68738
2825.26	4.9517
2827.91	5.54568
2830.56	7.36852
2833.21	9.91179
2835.85	11.9738
2838.5	14.769
2841.14	18.5829
2843.78	22.1341
2846.42	26.3959
2849.06	31.9469
2851.71	37.7614
2854.34	43.861
2856.98	49.7845
2859.62	55.141
2862.26	61.405
2864.89	65.6948
2867.53	70.3933
2870.16	74.6764
2872.79	78.8397
2875.42	81.4585
2878.05	83.9645
2880.68	86.7888
2883.31	88.7227
2885.94	91.6842
2888.57	94.8318
2891.19	97.4935
2893.82	99.8636
2896.44	102.456
2899.07	107.845
2901.69	112.344
2904.31	118.375
2906.93	125.293
2909.55	132.455
2912.17	140.326
2914.79	148.368
2917.41	154.842
2920.02	160.941
2922.64	165.917
2925.25	169.097
2927.86	171.388
2930.48	171.482
2933.09	171.103
2935.7	168.227
2938.31	164.364
2940.92	160.415
2943.53	156.147
2946.13	151.371
2948.74	144.956
2951.34	139.542
2953.95	132.244
2956.55	125.152
2959.15	118.608
2961.75	112.906
2964.35	106.695
2966.95	101.479
2969.55	96.3971
2972.15	91.2103
2974.75	87.1107
2977.34	83.1669
2979.94	77.7917
2982.53	72.5878
2985.13	66.0381
2987.72	61.1035
2990.31	54.9255
2992.9	48.5153
2995.49	42.0321
2998.08	36.3833
3000.67	31.2032
3003.25	26.5358
3005.84	22.7536
3008.42	19.2834
3011.01	16.1171
3013.59	12.9328
3016.17	10.37
3018.76	7.53752
3021.34	6.15367
3023.92	4.12851
3026.49	2.92607
3029.07	3.35459
3031.65	2.78487
3034.23	4.09564
3036.8	5.09772
3039.38	6.12971
3041.95	7.03957
3044.52	8.1183
3047.09	9.54501
3049.66	11.7025
3052.23	12.2249
3054.8	12.7672
3057.37	12.5321
3059.94	12.0356
3062.5	11.5525
3065.07	10.8471
3067.63	9.96084
3070.2	8.97855
3072.76	8.00686
3075.32	6.9632
3077.88	5.61598
3080.44	4.42598
3083	3.67356
3085.56	2.96049
3088.12	2.07449
3090.67	2.12451
3093.23	2.05079
3095.78	2.34665
3098.34	2.77251
3100.89	3.42782
3103.44	4.23993
3105.99	5.51698
3108.54	6.61495
3111.09	7.24064
3113.64	8.54963
3116.19	9.58015
3118.74	10.1859
3121.28	10.7867
3123.83	11.8421
3126.37	13.0193
3128.91	13.0637
3131.46	14.9564
3134	15.6966
3136.54	17.0083
3139.08	18.7925
3141.62	20.241
3144.16	21.4326
3146.69	22.394
3149.23	23.2185