File: data/Raman/poly_smoothed/Thy_40_11_31_1x_45s_532 nm_x100_100%_600 gr_mm_01.txt
#Acq. time (s)=	45
#Accumulations=	2
#Range (cm-¹)=	200...3150
#Windows=	2
#Auto scanning=	Off
#Autofocus=	Off
#Macrospot=	Off
#AutoExposure=	Off
#Spike filter=	Multiple accum.
#Delay time (s)=	0
#Binning=	1
#Readout mode=	Signal
#DeNoise=	Off
#ICS correction=	On
#Dark correction=	Off
#Inst. Process=	Off
#Detector Gain=	Best Dynamic Range
#Detector ADC=	20 kHz
#Detector temperature (°C)=	-69.85
#Instrument=	LabRAM HR Evol
#Detector=	Synapse
#Objective=	x100
#Grating=	600 gr/mm
#ND Filter=	100%
#Laser (nm)=	532
#Hole=	100.021
#Range=	Auto
#Laser Pol.=	No
#Raman. Pol.=	No
#Laser Pol. (°)=	-0.0007625
#Raman Pol. (°)=	89.9995
#Collection=	Microscope
#StageXY=	Marzhauser
#StageZ=	Marzhauser
#X (µm)=	250.1
#Y (µm)=	1675.8
#Z (µm)=	426.7
#Full time(mm:ss)=	3:14
#Project=
#Sample=
#Site=
#Title=	Thy_40_11_31_2x_45s_532 nm_x100_100%_600 gr_mm
#Remark=
#Date=	05.07.2022 12:14
#Acquired=	05.07.2022 12:14:07
#Base:Fit=	10.08.2022 10:01:35
#Base:Sub=	10.08.2022 10:01:52
#Filter:Polynom=	16.08.2022 10:21:53
#AxisType[0]=Intens
#AxisUnit[0]=Cnt
#AxisType[1]=Spectr
#AxisUnit[1]=1/cm
200.43	7.85089
204.059	13.2884
207.688	15.9155
211.314	16.9854
214.941	16.8628
218.564	15.6909
222.186	15.6143
225.809	16.1556
229.428	15.8921
233.045	15.0057
236.663	15.2655
240.278	15.5035
243.891	14.8379
247.503	14.2448
251.116	12.2882
254.725	9.49372
258.333	9.54996
261.939	9.7767
265.544	9.61389
269.148	8.74206
272.75	8.2281
276.351	7.86033
279.95	7.57107
283.548	9.58841
287.144	9.65605
290.739	9.22582
294.333	8.09735
297.925	9.99125
301.514	10.6596
305.104	11.7761
308.692	13.7326
312.279	15.2061
315.862	16.3815
319.446	16.5455
323.029	16.9424
326.608	17.4474
330.188	18.0394
333.766	16.4702
337.341	16.2311
340.917	13.4583
344.489	12.8339
348.062	14.3619
351.631	13.1999
355.201	12.3347
358.768	12.7431
362.333	13.083
365.899	12.8575
369.462	12.1431
373.023	12.5925
376.585	12.4038
380.143	11.7082
383.7	13.843
387.256	13.5825
390.812	12.9946
394.365	13.7096
397.916	14.3074
401.467	12.8537
405.015	11.7017
408.563	10.3565
412.109	9.39159
415.654	9.04674
419.197	7.319
422.739	7.47438
426.279	6.61902
429.819	5.16909
433.356	4.34932
436.891	3.84792
440.426	3.86614
443.96	4.98051
447.492	5.98744
451.021	6.70118
454.551	7.32548
458.079	9.03719
461.604	9.12681
465.13	10.2215
468.654	12.3219
472.175	13.4225
475.696	13.895
479.215	14.9951
482.733	17.0314
486.249	16.8553
489.765	16.7133
493.278	17.2265
496.789	18.4251
500.301	19.2194
503.81	19.8329
507.317	19.3523
510.825	19.4245
514.33	18.8034
517.833	17.8246
521.335	17.4393
524.836	19.3103
528.335	18.7908
531.835	19.0412
535.332	20.4117
538.827	19.5409
542.321	18.4108
545.814	16.5947
549.305	15.6022
552.795	15.1675
556.282	13.0361
559.769	11.4392
563.255	10.2191
566.739	8.79203
570.223	8.08466
573.705	6.15125
577.183	3.90878
580.663	3.1042
584.141	1.93594
587.615	1.01274
591.09	1.48288
594.564	1.67666
598.035	0.942231
601.506	2.42321
604.974	2.87537
608.443	3.0728
611.908	4.64273
615.374	6.06489
618.837	5.3158
622.3	6.07398
625.761	5.93237
629.219	5.08228
632.677	6.80399
636.135	6.78851
639.59	8.18704
643.043	8.49903
646.495	9.02027
649.948	9.73344
653.398	9.62662
656.846	11.2353
660.293	10.8659
663.738	11.4516
667.183	14.6283
670.626	16.071
674.067	17.7165
677.508	19.7777
680.947	20.2057
684.385	21.5312
687.821	24.171
691.254	25.6886
694.688	26.7946
698.121	29.3231
701.552	29.4458
704.98	29.7433
708.409	32.3672
711.836	34.0976
715.26	34.5576
718.685	36.9028
722.108	40.1031
725.528	42.1771
728.949	43.6212
732.367	44.5945
735.785	46.1125
739.2	48.0558
742.614	50.3532
746.028	52.5014
749.439	55.7837
752.849	56.6966
756.26	58.819
759.667	59.8393
763.073	62.0784
766.477	64.1568
769.883	65.4249
773.285	66.5651
776.686	67.8131
780.085	68.4873
783.484	69.6381
786.881	69.8303
790.276	73.0237
793.671	75.0772
797.064	77.6513
800.456	79.9803
803.846	82.7842
807.234	82.5996
810.622	82.337
814.008	83.7063
817.394	83.6261
820.778	84.4405
824.159	85.2943
827.541	83.9502
830.921	83.3023
834.298	82.1799
837.676	80.1068
841.051	78.7925
844.426	77.3091
847.798	73.7751
851.171	70.4018
854.54	67.1729
857.911	63.4083
861.278	61.6345
864.645	58.4879
868.01	56.5431
871.373	55.6951
874.735	55.4398
878.097	55.3759
881.457	53.8059
884.815	52.8188
888.172	50.9561
891.528	50.0972
894.882	48.3973
898.237	47.7961
901.589	48.6674
904.94	48.3018
908.289	46.453
911.635	46.0333
914.982	44.9228
918.328	43.9646
921.672	43.0805
925.015	42.371
928.357	40.5364
931.698	36.8046
935.035	36.3287
938.373	34.5676
941.71	32.9134
945.044	33.2707
948.378	32.3463
951.709	33.772
955.041	35.9064
958.372	35.311
961.699	34.7833
965.027	36.9688
968.352	37.8972
971.676	38.1622
975	39.6359
978.322	41.1012
981.642	42.6182
984.962	43.0048
988.28	42.0362
991.596	44.3405
994.911	43.958
998.227	43.5191
1001.54	43.8875
1004.85	42.4761
1008.16	42.6484
1011.47	42.2642
1014.78	41.0874
1018.08	40.9749
1021.39	41.963
1024.69	42.6248
1028	40.7693
1031.3	42.2245
1034.6	41.3947
1037.9	39.1343
1041.19	37.9688
1044.49	38.199
1047.78	37.2909
1051.08	35.2737
1054.37	33.4764
1057.66	33.058
1060.95	30.7259
1064.24	28.8342
1067.53	28.5364
1070.81	27.953
1074.1	27.7954
1077.38	25.3508
1080.66	25.2913
1083.94	24.331
1087.22	24.931
1090.5	25.5833
1093.78	25.1741
1097.05	25.342
1100.33	25.448
1103.6	26.212
1106.87	24.7804
1110.14	23.7876
1113.41	23.1727
1116.68	21.8155
1119.95	19.7969
1123.21	17.4132
1126.48	15.4035
1129.74	13.6421
1133	13.2285
1136.26	11.7273
1139.52	10.5675
1142.78	10.3956
1146.04	8.78071
1149.29	6.18804
1152.55	5.39947
1155.8	5.28138
1159.05	5.35773
1162.3	3.52474
1165.55	3.84487
1168.8	2.47034
1172.05	2.2824
1175.29	2.85741
1178.54	4.1143
1181.78	3.18968
1185.02	3.12803
1188.26	3.1464
1191.5	3.72956
1194.74	5.66326
1197.97	7.65453
1201.21	9.46814
1204.44	11.4668
1207.68	15.7304
1210.91	20.2514
1214.14	25.3736
1217.37	28.955
1220.59	34.7336
1223.82	38.7921
1227.05	42.0019
1230.27	47.4549
1233.49	53.5302
1236.72	58.0086
1239.94	61.1657
1243.16	64.9475
1246.37	67.1399
1249.59	70.6423
1252.8	72.6968
1256.02	73.9898
1259.23	76.5697
1262.44	78.3199
1265.66	78.5241
1268.86	82.7157
1272.07	83.3899
1275.28	85.1602
1278.48	85.6627
1281.69	86.2453
1284.89	86.6709
1288.09	88.465
1291.29	89.649
1294.49	90.8378
1297.69	90.8739
1300.89	92.6975
1304.08	92.0524
1307.28	93.2317
1310.47	93.6959
1313.66	93.2091
1316.85	94.0773
1320.04	94.0925
1323.23	93.6532
1326.42	90.96
1329.61	91.4868
1332.79	88.4932
1335.97	88.2834
1339.16	86.023
1342.34	82.0241
1345.52	79.0273
1348.7	75.3962
1351.87	71.0463
1355.05	68.4528
1358.22	63.3377
1361.4	58.9973
1364.57	56.3503
1367.74	53.113
1370.91	50.2962
1374.08	46.8728
1377.25	44.7635
1380.41	42.8367
1383.58	39.7314
1386.74	38.8495
1389.91	37.6919
1393.07	37.0416
1396.23	36.9531
1399.39	36.2262
1402.55	34.1966
1405.7	34.414
1408.86	35.8827
1412.01	38.0524
1415.17	39.7422
1418.32	40.973
1421.47	45.7641
1424.62	51.0917
1427.77	57.2392
1430.91	63.6231
1434.06	68.2552
1437.2	74.0531
1440.35	78.7308
1443.49	82.9348
1446.63	85.4283
1449.77	85.7905
1452.91	87.0496
1456.05	86.4591
1459.18	84.5649
1462.32	81.1031
1465.45	77.8158
1468.59	72.6693
1471.72	67.1615
1474.85	61.8732
1477.98	55.1397
1481.1	50.4401
1484.23	44.9315
1487.36	40.628
1490.48	34.9054
1493.61	30.7529
1496.73	27.4907
1499.85	26.1664
1502.97	25.1373
1506.09	23.5032
1509.2	24.2384
1512.32	24.3778
1515.43	23.8835
1518.55	24.0823
1521.66	25.0871
1524.77	26.5173
1527.88	27.8994
1530.99	30.226
1534.1	31.1066
1537.21	33.5005
1540.31	35.6914
1543.42	40.3971
1546.52	45.667
1549.62	50.482
1552.72	55.8863
1555.82	59.8166
1558.92	63.7992
1562.02	65.9598
1565.11	69.6396
1568.21	71.3338
1571.3	73.5991
1574.39	75.7806
1577.49	77.7799
1580.57	79.9324
1583.66	82.8887
1586.75	84.5571
1589.84	85.4099
1592.92	85.2522
1596.01	84.0078
1599.09	83.2795
1602.17	81.5171
1605.25	80.3272
1608.33	78.5585
1611.41	77.2825
1614.49	77.2597
1617.57	77.7252
1620.64	80.1892
1623.72	82.6112
1626.79	85.354
1629.86	88.8785
1632.93	92.9623
1636	96.3646
1639.07	100.553
1642.13	103.287
1645.2	106.754
1648.26	109.172
1651.33	110.845
1654.39	113.566
1657.45	115.09
1660.51	114.944
1663.57	113.432
1666.63	110.457
1669.68	106.009
1672.74	100.684
1675.79	95.3587
1678.85	87.2059
1681.9	78.7652
1684.95	70.4949
1688	62.7418
1691.05	53.9523
1694.09	47.0437
1697.14	41.9284
1700.18	35.6514
1703.23	32.1427
1706.27	27.0759
1709.31	23.5662
1712.35	20.6471
1715.39	17.6829
1718.43	14.8718
1721.47	13.8436
1724.5	12.6666
1727.54	12.5785
1730.57	12.6183
1733.61	12.6593
1736.64	12.8493
1739.67	13.6179
1742.7	12.8326
1745.72	12.1197
1748.75	10.8528
1751.77	9.10817
1754.8	7.02561
1757.82	5.73754
1760.84	3.97917
1763.87	2.76934
1766.89	2.07481
1769.91	1.52346
1772.92	0.0962264
1775.94	0.465728
1778.95	0.35589
1781.97	1.17487
1784.98	1.20088
1787.99	0.870591
1791.01	0.993157
1794.01	1.84716
1797.02	1.39445
1800.03	2.85414
1803.04	2.94957
1806.04	2.8413
1809.05	3.05107
1812.05	4.0461
1815.05	3.98786
1818.05	3.96469
1821.05	4.68724
1824.05	4.87086
1827.05	4.30763
1830.04	3.7571
1833.04	3.76566
1836.03	3.09444
1839.03	3.69195
1842.02	4.17373
1845.01	4.06434
1848	5.22773
1850.99	5.31339
1853.97	4.86574
1856.96	5.86309
1859.94	5.45312
1862.93	5.81468
1865.91	5.50185
1868.89	5.01819
1871.87	4.98605
1874.85	4.61377
1877.83	4.05832
1880.81	3.65192
1882.57	3.50717
1885.56	3.02348
1888.55	3.98171
1891.54	3.79386
1894.52	3.29187
1897.51	2.55315
1900.49	2.37776
1903.47	1.9396
1906.45	0.264704
1909.43	0.880801
1912.41	1.81853
1915.39	2.33333
1918.37	3.60593
1921.34	4.22054
1924.32	4.8907
1927.29	5.60314
1930.26	6.71415
1933.23	6.32835
1936.2	6.51201
1939.17	5.51345
1942.14	5.64151
1945.11	5.02481
1948.07	5.31384
1951.04	4.6085
1954	5.29578
1956.96	3.91931
1959.93	3.79818
1962.89	3.35671
1965.85	2.02903
1968.8	1.77588
1971.76	1.67843
1974.72	1.54978
1977.67	1.33891
1980.63	1.94284
1983.58	1.91061
1986.53	2.21298
1989.48	3.14406
1992.43	4.53367
1995.38	4.80507
1998.32	5.32317
2001.27	4.92596
2004.22	5.29837
2007.16	5.47565
2010.1	5.95281
2013.04	6.40914
2015.98	7.3412
2018.92	7.37095
2021.86	7.55661
2024.8	8.10038
2027.74	7.83436
2030.67	8.81199
2033.61	9.56609
2036.54	10.3163
2039.47	11.8744
2042.4	13.3253
2045.33	13.5983
2048.26	13.855
2051.19	13.4512
2054.12	13.9399
2057.04	14.4887
2059.97	16.9254
2062.89	17.4441
2065.81	18.2636
2068.73	19.1895
2071.65	20.052
2074.57	20.5899
2077.49	21.1546
2080.41	22.3893
2083.32	23.7643
2086.24	24.9837
2089.15	26.1286
2092.07	26.286
2094.98	27.9816
2097.89	29.8299
2100.8	32.1609
2103.71	34.4478
2106.61	36.8587
2109.52	38.6745
2112.43	42.1201
2115.33	45.6321
2118.23	48.7912
2121.13	52.2852
2124.04	57.3865
2126.94	61.9229
2129.83	66.4205
2132.73	70.5067
2135.63	74.6084
2138.53	79.231
2141.42	83.166
2144.31	87.2707
2147.21	92.2675
2150.1	97.0981
2152.99	100.852
2155.88	104.668
2158.77	107.971
2161.65	110.999
2164.54	112.781
2167.43	115.252
2170.31	117.143
2173.19	117.864
2176.07	119.774
2178.96	118.526
2181.84	117.747
2184.72	116.43
2187.59	114.269
2190.47	111.313
2193.35	108.258
2196.22	104.415
2199.09	99.0854
2201.97	94.0363
2204.84	89.2441
2207.71	83.215
2210.58	77.9048
2213.45	72.9002
2216.31	69.545
2219.18	65.5437
2222.05	61.5708
2224.91	58.1309
2227.78	54.423
2230.64	50.6879
2233.5	47.5105
2236.36	45.5839
2239.22	43.297
2242.08	41.3841
2244.93	39.1637
2247.79	36.7998
2250.64	34.8811
2253.5	33.3233
2256.35	32.0734
2259.2	30.3027
2262.05	28.8058
2264.9	25.9369
2267.75	24.2641
2270.6	23.0945
2273.45	21.6307
2276.29	19.9353
2279.14	19.2996
2281.98	17.9371
2284.82	16.9188
2287.66	16.3474
2290.5	14.8951
2293.34	13.5185
2296.18	13.2997
2299.02	12.2191
2301.86	12.6017
2304.69	13.4816
2307.53	13.0415
2310.36	13.0622
2313.19	13.5154
2316.02	13.1945
2318.85	13.1947
2321.68	12.8721
2324.51	12.488
2327.34	11.579
2330.16	11.2049
2332.99	10.4129
2335.81	9.7681
2338.64	9.25951
2341.46	8.9501
2344.28	8.70191
2347.1	6.89961
2349.92	5.0286
2352.74	3.61861
2355.55	2.24352
2358.37	0.621361
2361.19	-0.834848
2364	-0.123727
2366.81	0.730576
2369.62	0.451089
2372.44	0.335343
2375.24	0.371605
2378.05	0.494496
2380.86	1.06676
2383.67	0.893917
2386.47	1.4963
2389.28	2.54565
2392.08	3.97161
2394.89	4.34056
2397.69	5.62773
2400.49	6.1964
2403.29	7.00534
2406.09	7.66999
2408.88	8.63169
2411.68	8.7002
2414.48	9.22121
2417.27	8.55435
2420.06	8.55768
2422.86	9.2134
2425.65	9.33618
2428.44	9.03674
2431.23	8.29368
2434.02	8.41851
2436.81	7.7108
2439.59	7.21455
2442.38	6.75032
2445.16	6.49254
2447.95	6.39711
2450.73	6.56912
2453.51	6.09685
2456.29	6.83938
2459.07	6.30417
2461.85	5.65018
2464.63	5.34058
2467.4	6.0457
2470.18	6.18012
2472.95	5.46037
2475.73	4.75903
2478.5	4.45885
2481.27	4.44869
2484.04	3.80412
2486.81	2.95277
2489.58	3.00595
2492.35	2.16485
2495.12	1.94862
2497.88	0.784884
2500.65	0.426863
2503.41	-0.307527
2506.17	-1.18367
2508.94	-0.53292
2511.7	0.297757
2514.46	0.482895
2517.22	0.973445
2519.97	0.831942
2522.73	1.91242
2525.49	2.78055
2528.24	2.6694
2530.99	4.00641
2533.75	4.22339
2536.5	4.66804
2539.25	4.96486
2542	5.03236
2544.75	5.34789
2547.5	5.62672
2550.24	5.79478
2552.99	5.77265
2555.74	6.24166
2558.48	6.64994
2561.22	6.09865
2563.96	5.77372
2566.71	5.36292
2569.45	4.62527
2572.18	4.24898
2574.92	5.57987
2577.66	6.4392
2580.4	6.62508
2583.13	6.5225
2585.87	6.22532
2588.6	6.31884
2591.33	6.15721
2594.06	5.54015
2596.79	5.36586
2599.52	4.2705
2602.25	4.17353
2604.98	4.47113
2607.71	3.99997
2610.43	3.57284
2613.16	4.32283
2615.88	4.24054
2618.6	4.25041
2621.32	3.55658
2624.04	3.24031
2626.76	3.03292
2629.48	2.98518
2632.2	2.81559
2634.92	3.2149
2637.63	4.33811
2640.35	4.83218
2643.06	6.16647
2645.77	6.43562
2648.49	7.13973
2651.2	6.34697
2653.91	6.40477
2656.62	7.32621
2659.33	7.54902
2662.03	7.94165
2664.74	7.16519
2667.44	6.60487
2670.15	6.95043
2672.85	5.479
2675.55	4.88
2678.26	4.54984
2680.96	4.15888
2683.66	2.34809
2686.35	1.38586
2689.05	1.18625
2691.75	0.991232
2694.44	1.7748
2697.14	2.5395
2699.83	3.62272
2702.52	4.30954
2705.22	4.90221
2707.91	6.15167
2710.6	7.23995
2713.29	8.56083
2715.97	8.71926
2718.66	10.0767
2721.35	11.1295
2724.03	11.4907
2726.72	11.4566
2729.4	10.9622
2732.08	10.4043
2734.76	10.623
2737.44	9.62235
2740.12	10.1514
2742.8	10.5451
2745.48	9.93797
2748.16	9.09336
2750.83	8.68925
2753.51	8.06695
2756.18	8.40203
2758.85	7.89416
2761.53	7.49764
2764.2	6.96961
2766.87	6.53979
2769.54	5.71067
2772.2	4.91015
2774.87	4.80112
2777.54	4.28112
2780.2	3.23043
2782.87	1.92781
2785.53	1.21055
2788.19	0.399619
2790.85	0.0409417
2793.51	-0.146994
2796.17	-0.257158
2798.83	-0.660649
2801.49	-0.768435
2804.15	-1.11943
2806.8	-1.1614
2809.46	-1.68666
2812.11	-1.63577
2814.76	-1.35208
2817.42	-1.45439
2820.07	-0.0525045
2822.72	2.69994
2825.37	5.35457
2828.02	8.96647
2830.66	13.5796
2833.31	17.994
2835.96	21.7822
2838.6	27.5382
2841.24	32.9588
2843.89	39.8193
2846.53	47.5253
2849.17	56.1376
2851.81	67.3759
2854.45	77.5621
2857.09	89.0171
2859.72	99.5496
2862.36	108.325
2865	117.174
2867.63	124.99
2870.26	132.607
2872.9	139.508
2875.53	146.175
2878.16	151.56
2880.79	156.756
2883.42	162.137
2886.05	168.629
2888.67	173.906
2891.3	179.818
2893.92	185.092
2896.55	191.287
2899.17	198.623
2901.79	206.991
2904.42	217.238
2907.04	229.123
2909.66	242.196
2912.27	256.935
2914.89	272.128
2917.51	286.007
2920.13	298.936
2922.74	309.792
2925.35	318.304
2927.97	325.127
2930.58	328.742
2933.19	331.117
2935.8	331.025
2938.41	327.133
2941.02	321.925
2943.63	313.615
2946.24	304.756
2948.84	294.68
2951.45	283.467
2954.05	270.174
2956.65	256.65
2959.26	243.697
2961.86	230.437
2964.46	218.849
2967.06	206.914
2969.66	195.432
2972.25	184.282
2974.85	173.91
2977.45	163.147
2980.04	152.167
2982.64	142.436
2985.23	131.308
2987.82	120.269
2990.41	109.534
2993	98.2958
2995.59	88.5407
2998.18	79.2493
3000.77	69.6089
3003.36	61.3618
3005.94	53.5077
3008.53	46.1661
3011.11	40.4058
3013.69	34.8732
3016.28	29.9801
3018.86	26.0561
3021.44	22.7465
3024.02	20.9861
3026.6	19.7043
3029.18	19.7226
3031.75	20.0568
3034.33	20.1405
3036.9	20.2253
3039.48	21.0069
3042.05	21.8205
3044.62	23.6757
3047.19	24.1916
3049.77	24.3424
3052.34	25.3354
3054.9	24.8903
3057.47	24.8215
3060.04	24.3354
3062.61	23.3912
3065.17	22.5629
3067.74	20.1944
3070.3	18.5863
3072.86	16.7072
3075.42	14.4202
3077.99	12.2905
3080.54	10.2005
3083.1	8.22968
3085.66	6.09154
3088.22	4.43131
3090.78	2.55074
3093.33	1.63793
3095.89	0.96498
3098.44	-0.628078
3100.99	0.202027
3103.54	0.943337
3106.1	1.45492
3108.65	1.81117
3111.2	2.44292
3113.74	3.56173
3116.29	4.08094
3118.84	5.32624
3121.38	6.71372
3123.93	7.71996
3126.47	8.51135
3129.01	9.60043
3131.56	10.3364
3134.1	11.6191
3136.64	12.6433
3139.18	13.5111
3141.72	13.9488
3144.26	14.6964
3146.79	15.6817
3149.33	17.5546