File: data/Raman/poly_smoothed/Thy_30_10_39_1x_45s_532 nm_x100_100%_600 gr_mm_01.txt
#Acq. time (s)=	45
#Accumulations=	2
#Range (cm-¹)=	200...3150
#Windows=	2
#Auto scanning=	Off
#Autofocus=	Off
#Macrospot=	Off
#AutoExposure=	Off
#Spike filter=	Multiple accum.
#Delay time (s)=	0
#Binning=	1
#Readout mode=	Signal
#DeNoise=	Off
#ICS correction=	On
#Dark correction=	Off
#Inst. Process=	Off
#Detector Gain=	Best Dynamic Range
#Detector ADC=	20 kHz
#Detector temperature (°C)=	-69.85
#Instrument=	LabRAM HR Evol
#Detector=	Synapse
#Objective=	x100
#Grating=	600 gr/mm
#ND Filter=	100%
#Laser (nm)=	532
#Hole=	100.021
#Range=	Auto
#Laser Pol.=	No
#Raman. Pol.=	No
#Laser Pol. (°)=	-0.0007625
#Raman Pol. (°)=	89.9995
#Collection=	Microscope
#StageXY=	Marzhauser
#StageZ=	Marzhauser
#X (µm)=	4722.6
#Y (µm)=	-7715.6
#Z (µm)=	584.4
#Full time(mm:ss)=	3:19
#Project=
#Sample=
#Site=
#Title=	Thy_30_10_39_2x_45s_532 nm_x100_100%_600 gr_mm
#Remark=
#Date=	30.06.2022 14:14
#Acquired=	30.06.2022 14:14:27
#Base:Fit=	10.08.2022 09:58:11
#Base:Sub=	10.08.2022 09:58:44
#Filter:Polynom=	16.08.2022 10:22:53
#AxisType[0]=Intens
#AxisUnit[0]=Cnt
#AxisType[1]=Spectr
#AxisUnit[1]=1/cm
200.533	19.0556
204.162	15.8776
207.792	14.5621
211.418	13.0473
215.044	10.5691
218.667	8.13509
222.289	6.46105
225.912	5.23178
229.531	5.6875
233.148	4.98709
236.766	5.59435
240.381	5.24139
243.994	4.24602
247.606	4.49119
251.217	4.68901
254.828	5.13232
258.436	5.13324
262.042	5.91692
265.647	6.60378
269.25	7.17505
272.852	9.07857
276.453	8.24787
280.052	8.57159
283.65	7.92132
287.247	7.64221
290.842	7.9681
294.436	9.65717
298.028	9.9146
301.617	9.27211
305.206	10.2773
308.794	10.9356
312.381	10.7635
315.964	11.1332
319.548	11.3596
323.131	12.8359
326.71	13.3148
330.29	13.4399
333.868	13.2248
337.443	12.9426
341.018	12.5011
344.591	11.0765
348.163	10.0871
351.733	9.70072
355.303	7.76257
358.869	7.87034
362.435	8.42438
366.001	8.37589
369.563	8.08197
373.124	7.30068
376.686	7.51944
380.244	10.5933
383.801	10.2377
387.357	10.9526
390.911	12.1713
394.466	10.5684
398.018	10.1485
401.568	9.32481
405.117	10.2561
408.664	10.1411
412.21	10.6881
415.755	9.62332
419.298	7.6206
422.84	7.44448
426.38	6.77864
429.919	5.18009
433.455	3.09507
436.992	2.38995
440.527	2.3276
444.06	1.6235
447.593	3.55176
451.122	2.82066
454.651	3.15575
458.18	4.94383
461.705	7.22789
465.23	10.0667
468.752	11.0873
472.275	12.6259
475.797	15.1309
479.315	16.8708
482.834	17.9143
486.349	19.496
489.863	21.3651
493.378	22.423
496.889	23.6348
500.401	24.6353
503.91	25.318
507.417	26.1768
510.923	26.2305
514.43	23.8357
517.933	22.5889
521.435	21.8788
524.936	20.9651
528.435	21.3591
531.933	20.1337
535.43	20.1811
538.927	18.4937
542.421	18.1178
545.913	17.5284
549.403	16.9117
552.893	15.3988
556.381	14.1241
559.868	12.5361
563.354	11.3226
566.839	9.58526
570.322	7.64983
573.802	6.76513
577.283	4.99327
580.762	3.72278
584.24	3.15046
587.714	2.60832
591.19	3.07864
594.663	3.56374
598.134	3.55222
601.605	5.2521
605.073	5.89016
608.542	7.03471
612.007	10.3771
615.473	11.0285
618.936	11.5259
622.397	11.4949
625.859	13.0579
629.318	13.4027
632.775	14.9904
636.233	15.0291
639.688	14.8333
643.142	15.5913
646.594	17.1394
650.045	19.0518
653.496	20.0514
656.944	20.3458
660.391	20.3731
663.837	20.6336
667.281	22.3415
670.724	23.688
674.166	25.691
677.606	27.583
681.045	28.7
684.483	30.1991
687.917	30.5479
691.352	32.6715
694.786	33.5481
698.219	34.6994
701.65	34.8507
705.078	36.5644
708.506	38.7225
711.934	39.2385
715.358	40.8214
718.782	43.3389
722.204	44.4147
725.626	46.6562
729.045	48.9445
732.464	51.5284
735.881	51.7816
739.297	52.7127
742.711	52.2462
746.125	53.9011
749.537	55.9558
752.946	57.148
756.357	58.2643
759.764	60.4971
763.17	60.2481
766.575	60.6811
769.978	62.5295
773.382	62.8564
776.783	63.7763
780.182	65.3901
783.581	66.8452
786.978	69.4575
790.373	72.4532
793.768	72.478
797.161	74.8238
800.552	77.6402
803.941	78.9788
807.33	80.9674
810.718	83.7158
814.105	84.9916
817.49	86.1476
820.873	85.2134
824.256	85.9085
827.637	85.3027
831.016	83.6395
834.395	81.9923
837.772	80.5751
841.147	80.2664
844.522	77.6026
847.894	73.8768
851.267	72.6235
854.637	71.438
858.007	68.8483
861.374	68.0816
864.739	68.3411
868.106	66.1385
871.469	64.651
874.831	62.1466
878.193	61.6523
881.553	62.6793
884.911	63.5967
888.268	63.2664
891.623	64.5506
894.978	64.9508
898.331	64.6121
901.683	62.8968
905.033	62.8938
908.383	61.7686
911.731	59.75
915.078	58.6894
918.423	59.1486
921.768	58.2052
925.111	56.2709
928.452	52.6949
931.791	50.9431
935.13	50.4947
938.468	48.9402
941.803	48.029
945.139	45.732
948.473	42.8888
951.804	42.7185
955.136	42.4551
958.465	41.266
961.794	41.1966
965.12	41.8373
968.447	44.5182
971.771	47.0845
975.095	50.3967
978.417	51.5843
981.737	53.3315
985.057	55.8962
988.375	56.8154
991.691	58.2433
995.006	57.6462
998.32	59.6149
1001.63	60.402
1004.95	59.5723
1008.26	58.4743
1011.56	58.7115
1014.87	59.3205
1018.18	58.9005
1021.48	58.4759
1024.79	57.4434
1028.09	57.2107
1031.39	57.2436
1034.69	55.7995
1037.99	53.3565
1041.29	51.262
1044.58	50.2289
1047.88	50.5127
1051.17	49.3562
1054.46	47.6253
1057.75	46.7729
1061.04	43.5432
1064.33	41.3347
1067.62	39.2488
1070.9	37.2017
1074.19	35.2122
1077.47	34.0098
1080.76	33.624
1084.04	34.1671
1087.32	33.5635
1090.59	33.9467
1093.87	34.0479
1097.15	34.5178
1100.42	34.1343
1103.69	35.3885
1106.97	35.4961
1110.24	36.4681
1113.51	35.8495
1116.77	34.1408
1120.04	32.6814
1123.31	30.3087
1126.57	27.6764
1129.83	25.9295
1133.1	23.4885
1136.36	21.0472
1139.62	18.2563
1142.87	15.5157
1146.13	13.0325
1149.38	11.9697
1152.64	9.26973
1155.89	7.82796
1159.14	6.93508
1162.39	6.70368
1165.64	4.88588
1168.89	4.35736
1172.14	4.97487
1175.38	5.8804
1178.63	7.46726
1181.87	10.9512
1185.11	11.854
1188.35	13.7597
1191.59	16.7892
1194.83	17.5717
1198.07	18.0871
1201.3	21.0534
1204.53	23.4521
1207.77	26.7466
1211	31.5712
1214.23	34.256
1217.46	38.8784
1220.69	42.8138
1223.91	48.1363
1227.14	51.8134
1230.36	54.069
1233.59	57.9736
1236.81	61.5718
1240.03	65.3569
1243.25	68.8536
1246.46	72.8317
1249.68	75.9718
1252.9	79.034
1256.11	80.9364
1259.32	82.3898
1262.54	84.437
1265.75	84.4566
1268.96	86.5364
1272.16	87.266
1275.37	87.3183
1278.57	88.2235
1281.78	88.8123
1284.98	89.5745
1288.18	89.8521
1291.38	89.9152
1294.58	89.204
1297.78	89.7159
1300.98	89.8544
1304.17	90.5841
1307.37	89.4222
1310.56	88.7475
1313.76	88.9108
1316.95	89.9241
1320.14	89.8287
1323.32	91.1712
1326.51	89.6862
1329.7	87.6947
1332.88	84.6739
1336.07	82.488
1339.25	80.7408
1342.43	79.9143
1345.61	76.4947
1348.79	75.1373
1351.96	70.4487
1355.14	67.5227
1358.31	64.1689
1361.49	61.09
1364.66	56.9077
1367.83	54.1564
1371	51.2555
1374.17	46.427
1377.34	43.5271
1380.5	41.9954
1383.67	40.5374
1386.83	38.6683
1390	37.9181
1393.16	36.754
1396.32	36.4954
1399.48	35.5303
1402.64	34.4534
1405.79	34.5156
1408.95	35.0455
1412.1	36.5841
1415.26	39.6383
1418.41	42.5539
1421.56	47.3509
1424.71	53.6746
1427.86	60.7251
1431	67.2046
1434.15	75.622
1437.29	79.8147
1440.44	83.3706
1443.58	86.208
1446.72	87.5385
1449.86	88.1898
1453	88.2408
1456.14	86.483
1459.27	83.9905
1462.41	79.8233
1465.54	72.6211
1468.67	65.8083
1471.81	58.4729
1474.94	51.9793
1478.07	45.7696
1481.19	37.8285
1484.32	30.4529
1487.45	24.9869
1490.57	19.8503
1493.69	17.0222
1496.82	14.5046
1499.94	13.8035
1503.06	12.544
1506.17	11.3559
1509.29	11.6335
1512.41	9.64651
1515.52	6.36609
1518.64	6.28337
1521.75	6.95624
1524.86	8.53724
1527.97	9.19858
1531.08	10.0474
1534.19	11.6661
1537.29	13.8773
1540.4	16.2379
1543.5	19.7791
1546.61	25.7505
1549.71	29.3701
1552.81	34.0493
1555.91	39.1608
1559.01	42.4042
1562.11	48.5505
1565.2	53.6592
1568.29	57.7616
1571.39	61.1402
1574.48	65.4136
1577.57	67.9913
1580.66	72.648
1583.75	75.602
1586.84	75.3774
1589.93	76.5333
1593.01	78.9037
1596.1	79.4244
1599.18	78.0774
1602.26	77.1284
1605.34	74.3419
1608.42	73.0499
1611.5	71.3658
1614.58	70.9503
1617.65	71.1626
1620.73	72.3326
1623.8	73.4305
1626.87	75.4579
1629.95	79.8583
1633.02	84.3625
1636.09	89.6488
1639.15	95.2106
1642.22	100.459
1645.29	104.456
1648.35	109.719
1651.42	113.037
1654.48	116.354
1657.54	118.395
1660.6	118.666
1663.66	119.119
1666.72	117.403
1669.77	113.168
1672.83	106.112
1675.88	98.7373
1678.93	89.4383
1681.99	80.9853
1685.04	73.1073
1688.09	65.1033
1691.13	56.8355
1694.18	48.9723
1697.23	41.0785
1700.27	33.7542
1703.32	28.3054
1706.36	23.1427
1709.4	18.857
1712.44	15.0516
1715.48	11.6664
1718.52	7.78679
1721.56	6.1546
1724.59	4.3594
1727.63	3.50135
1730.66	2.53522
1733.69	1.9292
1736.72	1.7706
1739.75	1.91775
1742.78	0.91269
1745.81	0.341681
1748.84	0.495089
1751.86	-0.0446361
1754.89	0.457781
1757.91	1.05462
1760.93	1.08203
1763.95	1.13763
1766.97	1.06207
1769.99	0.471355
1773.01	0.275281
1776.03	0.257826
1779.04	0.716646
1782.06	0.617475
1785.07	0.970197
1788.08	1.33223
1791.09	1.50314
1794.1	0.504873
1797.11	0.240645
1800.12	0.595635
1803.12	-0.151797
1806.13	-0.157259
1809.13	-0.0101541
1812.14	0.577585
1815.14	0.749353
1818.14	1.78626
1821.14	2.29105
1824.14	3.39727
1827.13	4.10634
1830.13	5.47704
1833.12	7.29918
1836.12	8.69455
1839.11	10.4353
1842.1	10.82
1845.09	11.1078
1848.08	11.8368
1851.07	12.4294
1854.06	13.3837
1857.04	13.7497
1860.03	14.8873
1863.01	15.0689
1866	14.9756
1868.98	14.9905
1871.96	14.2473
1874.94	14.1251
1877.92	14.3712
1880.89	14.1898
1882.48	13.7753
1885.47	14.2456
1888.46	14.4385
1891.44	14.6383
1894.43	15.0597
1897.41	16.5113
1900.4	17.0496
1903.38	18.4576
1906.36	18.8362
1909.34	19.7751
1912.32	20.3678
1915.29	19.7223
1918.27	20.1779
1921.25	20.4248
1924.22	21.736
1927.2	20.8687
1930.17	21.3058
1933.14	22.0074
1936.11	20.8852
1939.08	20.6806
1942.05	20.7681
1945.01	21.0795
1947.98	20.8128
1950.94	19.9487
1953.91	19.3992
1956.87	19.4148
1959.83	18.6266
1962.79	18.6636
1965.75	17.9576
1968.71	19.2193
1971.67	20.1025
1974.62	20.7704
1977.58	20.6503
1980.53	20.8492
1983.48	21.4508
1986.43	21.005
1989.38	22.2235
1992.33	22.726
1995.28	23.4287
1998.23	23.7423
2001.18	23.2499
2004.12	23.9205
2007.06	23.9409
2010.01	24.1003
2012.95	26.6276
2015.89	26.8876
2018.83	26.4226
2021.77	26.3494
2024.71	25.983
2027.64	26.8845
2030.58	26.5582
2033.51	26.8454
2036.45	26.7323
2039.38	27.6851
2042.31	28.4411
2045.24	28.8902
2048.17	29.9407
2051.1	30.3829
2054.02	31.6891
2056.95	33.0273
2059.87	34.5015
2062.8	35.7081
2065.72	36.1919
2068.64	36.8328
2071.56	37.5841
2074.48	38.4662
2077.4	39.5563
2080.31	41.3473
2083.23	44.2015
2086.14	45.2346
2089.06	46.4901
2091.97	48.2398
2094.88	50.2352
2097.79	52.3386
2100.7	53.1443
2103.61	54.8948
2106.52	57.328
2109.43	60.4915
2112.33	64.1942
2115.24	68.2886
2118.14	72.0445
2121.04	76.7792
2123.94	79.9525
2126.84	84.0534
2129.74	87.8927
2132.64	92.5119
2135.54	96.4094
2138.43	101.704
2141.33	107.363
2144.22	112.398
2147.11	117.006
2150.01	121.744
2152.9	126.86
2155.79	131.12
2158.67	133.429
2161.56	135.993
2164.45	139.204
2167.33	140.558
2170.22	141.458
2173.1	141.131
2175.98	141.844
2178.86	141.286
2181.74	140.025
2184.62	137.719
2187.5	134.407
2190.38	129.755
2193.25	124.826
2196.13	119.591
2199	115.843
2201.88	110.999
2204.75	107.224
2207.62	102.907
2210.49	99.7014
2213.36	94.856
2216.22	89.4928
2219.09	85.2737
2221.96	80.7217
2224.82	76.122
2227.68	73.27
2230.55	69.9637
2233.41	65.7495
2236.27	61.8111
2239.12	57.7437
2241.98	54.7832
2244.84	52.2326
2247.7	49.7698
2250.55	48.3214
2253.41	46.6243
2256.26	44.4462
2259.11	42.2144
2261.96	40.6209
2264.81	39.8368
2267.66	39.9433
2270.51	39.4847
2273.35	38.9324
2276.2	38.2205
2279.04	37.5296
2281.89	36.3078
2284.73	34.2984
2287.57	33.1072
2290.41	32.2989
2293.25	30.3665
2296.09	29.7517
2298.93	28.3373
2301.76	26.3011
2304.6	25.771
2307.44	24.7125
2310.27	24.3575
2313.1	24.3172
2315.93	23.7007
2318.76	23.0733
2321.59	23.3229
2324.42	21.8449
2327.25	21.2408
2330.07	20.896
2332.9	20.2122
2335.72	18.5917
2338.55	17.8958
2341.37	17.1295
2344.19	16.0207
2347.01	14.4054
2349.83	13.6894
2352.65	12.5884
2355.46	11.5479
2358.28	10.2192
2361.09	9.38283
2363.91	9.19574
2366.72	8.67301
2369.53	8.14894
2372.34	7.64529
2375.15	8.33461
2377.96	8.64497
2380.77	8.60299
2383.58	9.17628
2386.38	9.33375
2389.19	9.43696
2391.99	9.31435
2394.8	9.60432
2397.6	9.97963
2400.4	8.86737
2403.2	9.24661
2406	9.19854
2408.79	9.83532
2411.59	10.9016
2414.39	10.7483
2417.18	10.8902
2419.98	11.5684
2422.77	11.1693
2425.56	10.1568
2428.35	10.8135
2431.14	9.9829
2433.93	9.03919
2436.72	8.60359
2439.5	8.41899
2442.29	9.519
2445.07	9.1951
2447.86	8.94089
2450.64	9.40539
2453.42	9.71261
2456.2	9.2962
2458.98	9.42515
2461.76	8.70784
2464.54	8.29154
2467.32	7.45129
2470.09	6.77356
2472.87	7.91257
2475.64	7.45932
2478.41	7.97425
2481.18	6.77418
2483.95	6.09802
2486.72	5.86628
2489.49	4.92942
2492.26	5.10945
2495.03	4.55763
2497.79	3.67055
2500.56	2.61431
2503.32	3.42207
2506.09	3.29321
2508.85	3.26619
2511.61	2.85464
2514.37	2.15565
2517.13	2.42349
2519.89	1.7681
2522.64	1.46828
2525.4	1.66465
2528.15	0.913017
2530.91	0.782069
2533.66	0.225844
2536.41	-0.293082
2539.16	-0.120779
2541.91	-0.257647
2544.66	-0.542653
2547.41	-0.128991
2550.16	-0.164577
2552.9	-0.10431
2555.65	0.303442
2558.39	0.768906
2561.13	1.49801
2563.88	0.596196
2566.62	1.45334
2569.36	1.8856
2572.1	1.7928
2574.84	1.39409
2577.57	0.865559
2580.31	0.784079
2583.05	1.1064
2585.78	1.23774
2588.51	1.23003
2591.24	1.7575
2593.98	1.0904
2596.71	0.830363
2599.44	0.730285
2602.16	0.386994
2604.89	1.08834
2607.62	1.47845
2610.34	1.8925
2613.07	1.74907
2615.79	2.00141
2618.52	2.1551
2621.24	1.88118
2623.96	2.56226
2626.68	2.34138
2629.4	3.10658
2632.11	3.08502
2634.83	3.93838
2637.55	3.66905
2640.26	2.8185
2642.98	2.13052
2645.69	2.45195
2648.4	2.15077
2651.11	2.21505
2653.82	3.03384
2656.53	2.45488
2659.24	1.47141
2661.95	1.28977
2664.65	1.60294
2667.36	1.64086
2670.06	2.00179
2672.76	1.85701
2675.47	2.11587
2678.17	1.40816
2680.87	1.16354
2683.57	0.976702
2686.27	0.900932
2688.97	1.65412
2691.66	1.80404
2694.36	2.70881
2697.05	3.09277
2699.75	3.28855
2702.44	4.12865
2705.13	5.28306
2707.82	6.66144
2710.51	7.68008
2713.2	8.16524
2715.89	9.21038
2718.57	10.7093
2721.26	11.9127
2723.95	11.3332
2726.63	12.4991
2729.31	13.8225
2732	13.7865
2734.68	14.1197
2737.36	14.0548
2740.04	14.119
2742.72	13.6999
2745.39	12.3604
2748.07	10.8644
2750.75	10.183
2753.42	9.2807
2756.09	8.58362
2758.77	8.54337
2761.44	6.70743
2764.11	6.22698
2766.78	5.44378
2769.45	4.92771
2772.12	4.78214
2774.78	3.92889
2777.45	3.46955
2780.12	2.15488
2782.78	2.06765
2785.44	2.01305
2788.11	1.58
2790.77	1.60805
2793.43	1.60006
2796.09	2.75248
2798.75	2.28881
2801.4	3.50483
2804.06	4.37784
2806.72	4.7535
2809.37	4.2041
2812.03	4.127
2814.68	4.51132
2817.33	6.94905
2819.98	9.68216
2822.63	13.731
2825.28	17.7673
2827.93	23.1872
2830.58	29.9762
2833.23	36.2794
2835.87	43.5873
2838.52	52.3588
2841.16	61.7878
2843.8	73.289
2846.44	84.8971
2849.08	98.7373
2851.73	113.156
2854.36	127.717
2857	142.427
2859.64	158.068
2862.28	171.937
2864.91	183.844
2867.55	195.933
2870.18	205.398
2872.81	214.468
2875.44	222.374
2878.07	231.215
2880.7	238.421
2883.33	244.875
2885.96	251.426
2888.59	256.37
2891.21	263.528
2893.84	271.39
2896.46	278.325
2899.09	286.067
2901.71	298.021
2904.33	310.747
2906.95	326.779
2909.57	344.319
2912.19	363.935
2914.81	384.837
2917.43	404.543
2920.04	422.045
2922.66	435.958
2925.27	447.041
2927.88	454.163
2930.5	458.504
2933.11	459.798
2935.72	457.61
2938.33	452.964
2940.94	443.547
2943.54	432.097
2946.15	417.721
2948.76	402.206
2951.36	385.595
2953.97	367.893
2956.57	348.819
2959.17	330.707
2961.77	312.386
2964.37	295.862
2966.97	279.785
2969.57	265.041
2972.17	252.01
2974.77	239.292
2977.36	227.49
2979.96	214.506
2982.55	199.581
2985.15	184.472
2987.74	169.813
2990.33	155.584
2992.92	142.608
2995.51	129.211
2998.1	116.961
3000.69	106.083
3003.27	94.4179
3005.86	84.1254
3008.44	74.8873
3011.03	67.1784
3013.61	60.8248
3016.19	55.1798
3018.78	50.1047
3021.36	46.2229
3023.94	43.6931
3026.51	41.4241
3029.09	38.9197
3031.67	38.2935
3034.24	39.5534
3036.82	40.9735
3039.39	42.581
3041.97	44.2014
3044.54	45.2128
3047.11	46.6556
3049.68	47.7662
3052.25	48.6273
3054.82	48.2739
3057.39	47.3711
3059.96	45.9373
3062.52	45.7006
3065.09	42.9164
3067.65	40.2043
3070.22	37.2898
3072.78	34.4079
3075.34	30.9273
3077.9	27.3974
3080.46	23.2873
3083.02	19.1728
3085.58	15.008
3088.14	11.7464
3090.69	8.78499
3093.25	6.96306
3095.8	6.15458
3098.36	5.06917
3100.91	4.08469
3103.46	2.55871
3106.01	2.58194
3108.56	1.58441
3111.11	1.50667
3113.66	1.39394
3116.21	1.21884
3118.76	0.519935
3121.3	1.08874
3123.85	1.48429
3126.39	2.29302
3128.93	1.65968
3131.48	2.00083
3134.02	1.52168
3136.56	0.790785
3139.1	0.320936
3141.64	-0.0347106
3144.17	-0.516464
3146.71	-0.259646
3149.25	0.965171