File: data/Raman/poly_smoothed/Thy_30_10_36_1x_45s_532 nm_x100_100%_600 gr_mm_01.txt
#Acq. time (s)=	45
#Accumulations=	2
#Range (cm-¹)=	200...3150
#Windows=	2
#Auto scanning=	Off
#Autofocus=	Off
#Macrospot=	Off
#AutoExposure=	Off
#Spike filter=	Multiple accum.
#Delay time (s)=	0
#Binning=	1
#Readout mode=	Signal
#DeNoise=	Off
#ICS correction=	On
#Dark correction=	Off
#Inst. Process=	Off
#Detector Gain=	Best Dynamic Range
#Detector ADC=	20 kHz
#Detector temperature (°C)=	-69.85
#Instrument=	LabRAM HR Evol
#Detector=	Synapse
#Objective=	x100
#Grating=	600 gr/mm
#ND Filter=	100%
#Laser (nm)=	532
#Hole=	100.021
#Range=	Auto
#Laser Pol.=	No
#Raman. Pol.=	No
#Laser Pol. (°)=	-0.0007625
#Raman Pol. (°)=	89.9995
#Collection=	Microscope
#StageXY=	Marzhauser
#StageZ=	Marzhauser
#X (µm)=	4738
#Y (µm)=	-7721.2
#Z (µm)=	584.8
#Full time(mm:ss)=	3:18
#Project=
#Sample=
#Site=
#Title=	Thy_30_10_36_2x_45s_532 nm_x100_100%_600 gr_mm
#Remark=
#Date=	30.06.2022 14:02
#Acquired=	30.06.2022 14:02:39
#Base:Fit=	10.08.2022 09:58:11
#Base:Sub=	10.08.2022 09:58:44
#Filter:Polynom=	16.08.2022 10:22:53
#AxisType[0]=Intens
#AxisUnit[0]=Cnt
#AxisType[1]=Spectr
#AxisUnit[1]=1/cm
200.533	33.3958
204.162	25.9636
207.792	21.4374
211.418	16.7665
215.044	13.8348
218.667	11.0178
222.289	10.2306
225.912	8.40116
229.531	7.96049
233.148	7.0679
236.766	6.09703
240.381	5.7559
243.994	5.3785
247.606	5.70259
251.217	6.62396
254.828	7.54595
258.436	7.46611
262.042	6.94322
265.647	8.016
269.25	8.80708
272.852	9.00939
276.453	8.2488
280.052	9.21261
283.65	8.34311
287.247	9.08608
290.842	9.08458
294.436	9.06944
298.028	9.08257
301.617	10.3402
305.206	11.1644
308.794	13.2931
312.381	13.1947
315.964	14.3191
319.548	14.3887
323.131	13.9114
326.71	15.0274
330.29	15.2308
333.868	15.03
337.443	15.3378
341.018	16.1534
344.591	15.5779
348.163	13.7624
351.733	13.0912
355.303	12.1865
358.869	10.987
362.435	9.66725
366.001	9.37582
369.563	7.46674
373.124	6.88887
376.686	7.08415
380.244	6.13549
383.801	5.62138
387.357	6.71789
390.911	7.53348
394.466	7.87219
398.018	8.30229
401.568	7.06765
405.117	8.63901
408.664	8.12708
412.21	9.07527
415.755	10.4332
419.298	11.4324
422.84	11.4826
426.38	11.2186
429.919	12.1872
433.455	11.1001
436.992	11.5996
440.527	10.4515
444.06	9.35751
447.593	9.27378
451.122	9.99699
454.651	10.2028
458.18	10.0416
461.705	10.5002
465.23	10.5504
468.752	10.1537
472.275	10.6804
475.797	11.1372
479.315	11.1367
482.834	13.4523
486.349	12.9908
489.863	14.0246
493.378	13.7364
496.889	14.2654
500.401	15.5547
503.91	16.2718
507.417	16.141
510.923	15.5928
514.43	15.8787
517.933	15.7991
521.435	15.8447
524.936	14.804
528.435	14.1299
531.933	14.1811
535.43	14.4851
538.927	15.115
542.421	13.8597
545.913	13.46
549.403	11.7989
552.893	10.6453
556.381	10.6247
559.868	9.60826
563.354	10.1212
566.839	9.24696
570.322	9.24238
573.802	7.33747
577.283	6.01226
580.762	5.90386
584.24	5.75502
587.714	5.24097
591.19	5.41438
594.663	3.76614
598.134	2.09552
601.605	2.14979
605.073	3.13091
608.542	1.24912
612.007	1.02961
615.473	0.180495
618.936	1.20191
622.397	2.48325
625.859	3.42093
629.318	3.19339
632.775	3.76134
636.233	4.21308
639.688	6.15679
643.142	6.9029
646.594	9.08137
650.045	10.0915
653.496	10.6155
656.944	11.0685
660.391	11.8388
663.837	14.0244
667.281	14.5708
670.724	16.1124
674.166	16.4251
677.606	15.8517
681.045	16.092
684.483	16.9666
687.917	18.9011
691.352	19.7643
694.786	20.4821
698.219	23.3223
701.65	24.9918
705.078	28.7764
708.506	32.0195
711.934	34.066
715.358	36.4547
718.782	38.1104
722.204	39.5458
725.626	41.9659
729.045	43.1225
732.464	44.0768
735.881	44.7381
739.297	45.6202
742.711	48.6129
746.125	50.9363
749.537	51.4639
752.946	53.1491
756.357	53.3121
759.764	55.443
763.17	56.0827
766.575	59.1917
769.978	61.4888
773.382	62.5557
776.783	64.4429
780.182	66.6014
783.581	69.1065
786.978	72.1898
790.373	73.1883
793.768	75.5135
797.161	76.522
800.552	78.0756
803.941	78.3983
807.33	80.1699
810.718	81.2286
814.105	81.2547
817.49	82.6123
820.873	84.8299
824.256	85.6712
827.637	85.3781
831.016	84.7632
834.395	83.7544
837.772	82.8242
841.147	80.9836
844.522	79.5488
847.894	76.5895
851.267	74.1384
854.637	71.5266
858.007	69.481
861.374	66.9958
864.739	64.7307
868.106	64.5
871.469	62.3974
874.831	61.4228
878.193	62.0972
881.553	61.0178
884.911	59.8347
888.268	57.7128
891.623	57.119
894.978	55.6709
898.331	55.994
901.683	55.8326
905.033	55.4158
908.383	54.413
911.731	54.0439
915.078	53.7614
918.423	53.0289
921.768	51.6837
925.111	50.4405
928.452	48.5403
931.791	45.863
935.13	45.9395
938.468	45.3672
941.803	45.5895
945.139	44.6883
948.473	43.7452
951.804	42.9139
955.136	42.7079
958.465	43.3235
961.794	42.4909
965.12	41.144
968.447	41.1829
971.771	42.8355
975.095	45.7869
978.417	47.3988
981.737	50.3823
985.057	50.8304
988.375	52.0104
991.691	52.5601
995.006	52.8534
998.32	52.8673
1001.63	51.5896
1004.95	50.5715
1008.26	49.5919
1011.56	48.49
1014.87	48.3551
1018.18	47.6594
1021.48	46.3058
1024.79	43.8976
1028.09	42.0071
1031.39	41.3803
1034.69	41.1573
1037.99	40.4066
1041.29	38.6801
1044.58	38.0563
1047.88	38.586
1051.17	39.6739
1054.46	36.763
1057.75	36.5048
1061.04	35.3835
1064.33	35.183
1067.62	33.2162
1070.9	32.4031
1074.19	31.606
1077.47	30.3187
1080.76	28.0088
1084.04	28.6401
1087.32	26.2817
1090.59	26.4111
1093.87	25.742
1097.15	25.7811
1100.42	26.4518
1103.69	26.0476
1106.97	24.9982
1110.24	24.5881
1113.51	23.6543
1116.77	23.5873
1120.04	22.5596
1123.31	22.1597
1126.57	21.1709
1129.83	18.8632
1133.1	17.4426
1136.36	16.4281
1139.62	16.5959
1142.87	15.8343
1146.13	16.7548
1149.38	16.5827
1152.64	15.2107
1155.89	15.3165
1159.14	14.8449
1162.39	14.145
1165.64	13.2979
1168.89	13.5983
1172.14	14.9171
1175.38	14.1304
1178.63	14.7105
1181.87	13.3614
1185.11	12.068
1188.35	12.711
1191.59	12.8456
1194.83	14.6853
1198.07	16.2562
1201.3	16.4957
1204.53	19.2114
1207.77	20.1456
1211	22.1377
1214.23	25.2203
1217.46	28.5435
1220.69	31.6682
1223.91	35.2475
1227.14	39.0003
1230.36	42.847
1233.59	46.8595
1236.81	50.8021
1240.03	52.8877
1243.25	54.6005
1246.46	58.1842
1249.68	60.0995
1252.9	61.644
1256.11	63.823
1259.32	64.1661
1262.54	65.8485
1265.75	68.1387
1268.96	68.9785
1272.16	69.2822
1275.37	69.2185
1278.57	68.374
1281.78	68.197
1284.98	67.8949
1288.18	68.9987
1291.38	69.8582
1294.58	70.0178
1297.78	70.6112
1300.98	71.7501
1304.17	73.2921
1307.37	73.2126
1310.56	73.9733
1313.76	73.0788
1316.95	72.9762
1320.14	72.4897
1323.32	73.1469
1326.51	73.1086
1329.7	71.5085
1332.88	71.2863
1336.07	69.1097
1339.25	65.9499
1342.43	63.8985
1345.61	61.099
1348.79	58.2161
1351.96	54.6452
1355.14	51.0858
1358.31	49.4161
1361.49	46.4782
1364.66	44.1309
1367.83	41.3133
1371	38.4276
1374.17	36.107
1377.34	35.031
1380.5	33.0166
1383.67	32.0142
1386.83	30.5082
1390	29.6166
1393.16	29.8942
1396.32	28.9801
1399.48	29.0077
1402.64	27.1715
1405.79	25.7756
1408.95	27.4325
1412.1	29.1513
1415.26	31.1872
1418.41	34.7818
1421.56	39.0538
1424.71	45.387
1427.86	50.8955
1431	56.6779
1434.15	62.5233
1437.29	67.2718
1440.44	70.7154
1443.58	72.4487
1446.72	75.5792
1449.86	76.6275
1453	77.6048
1456.14	75.8535
1459.27	71.7214
1462.41	67.8331
1465.54	62.7505
1468.67	57.2295
1471.81	48.2738
1474.94	40.0542
1478.07	32.0553
1481.19	25.163
1484.32	19.1109
1487.45	13.1117
1490.57	8.24734
1493.69	5.37218
1496.82	2.64448
1499.94	1.97238
1503.06	2.68193
1506.17	2.26026
1509.29	2.90805
1512.41	3.13319
1515.52	3.13167
1518.64	4.87945
1521.75	7.36267
1524.86	9.50132
1527.97	11.7467
1531.08	13.5811
1534.19	14.9782
1537.29	17.0284
1540.4	20.0689
1543.5	22.8974
1546.61	25.3755
1549.71	27.8907
1552.81	31.1353
1555.91	33.2687
1559.01	35.9588
1562.11	37.0995
1565.2	40.4938
1568.29	43.7036
1571.39	46.5339
1574.48	50.1097
1577.57	52.6346
1580.66	54.2128
1583.75	55.4169
1586.84	56.7895
1589.93	57.4879
1593.01	57.3897
1596.1	58.4647
1599.18	58.1313
1602.26	58.1061
1605.34	58.5197
1608.42	57.8139
1611.5	57.4889
1614.58	57.5677
1617.65	58.6365
1620.73	60.4578
1623.8	61.8708
1626.87	63.517
1629.95	66.6403
1633.02	69.9741
1636.09	73.7639
1639.15	77.5039
1642.22	81.6976
1645.29	85.9063
1648.35	89.6869
1651.42	93.0415
1654.48	94.436
1657.54	94.8775
1660.6	93.5294
1663.66	92.5942
1666.72	90.6916
1669.77	87.3303
1672.83	83.8465
1675.88	78.1284
1678.93	73.011
1681.99	65.7897
1685.04	58.3595
1688.09	51.9726
1691.13	45.5002
1694.18	38.6416
1697.23	33.3947
1700.27	26.954
1703.32	21.0467
1706.36	17.8631
1709.4	13.8767
1712.44	10.9799
1715.48	8.72254
1718.52	7.87955
1721.56	5.89557
1724.59	4.87193
1727.63	4.74268
1730.66	4.23543
1733.69	2.91231
1736.72	3.3579
1739.75	3.85595
1742.78	3.80208
1745.81	3.53665
1748.84	3.86239
1751.86	3.56682
1754.89	4.15611
1757.91	2.69254
1760.93	2.295
1763.95	0.972227
1766.97	0.0218165
1769.99	0.0378083
1773.01	-0.473655
1776.03	-1.69459
1779.04	-1.83558
1782.06	-1.3918
1785.07	-1.80005
1788.08	-1.52026
1791.09	-1.06162
1794.1	-0.26269
1797.11	0.392523
1800.12	1.00353
1803.12	1.91432
1806.13	2.09598
1809.13	2.25466
1812.14	2.85812
1815.14	4.38722
1818.14	5.01538
1821.14	5.08282
1824.14	4.80766
1827.13	4.31945
1830.13	4.85861
1833.12	5.1901
1836.12	5.43948
1839.11	5.34676
1842.1	6.43317
1845.09	6.25951
1848.08	6.1973
1851.07	6.73137
1854.06	7.33024
1857.04	6.9328
1860.03	6.88073
1863.01	7.79356
1866	8.72031
1868.98	8.47974
1871.96	8.83482
1874.94	9.20272
1877.92	9.32909
1880.89	10.1643
1882.48	10.3341
1885.47	11.0491
1888.46	11.1763
1891.44	11.7253
1894.43	11.4688
1897.41	12.4078
1900.4	12.8655
1903.38	14.4799
1906.36	14.9226
1909.34	16.4895
1912.32	17.1493
1915.29	17.6916
1918.27	17.5883
1921.25	17.7217
1924.22	18.2229
1927.2	17.8022
1930.17	17.5958
1933.14	18.0015
1936.11	18.2433
1939.08	18.8728
1942.05	17.7208
1945.01	18.2203
1947.98	19.4324
1950.94	18.839
1953.91	18.8452
1956.87	18.5541
1959.83	17.8615
1962.79	17.4734
1965.75	17.3289
1968.71	16.8488
1971.67	17.328
1974.62	16.3688
1977.58	15.9681
1980.53	16.2687
1983.48	16.42
1986.43	15.8183
1989.38	16.28
1992.33	16.8855
1995.28	17.3848
1998.23	17.485
2001.18	17.388
2004.12	18.1895
2007.06	17.9701
2010.01	17.9428
2012.95	17.4619
2015.89	18.5032
2018.83	18.7948
2021.77	18.7315
2024.71	18.1393
2027.64	18.4859
2030.58	18.328
2033.51	17.6986
2036.45	16.7922
2039.38	16.1042
2042.31	15.9858
2045.24	15.3152
2048.17	15.2043
2051.1	16.6444
2054.02	17.6593
2056.95	17.5744
2059.87	19.453
2062.8	21.2891
2065.72	21.7672
2068.64	22.4013
2071.56	23.6088
2074.48	24.1627
2077.4	26.5802
2080.31	27.231
2083.23	28.5038
2086.14	30.2931
2089.06	31.9406
2091.97	33.3118
2094.88	35.2205
2097.79	36.9655
2100.7	38.2991
2103.61	39.3202
2106.52	41.0858
2109.43	43.5401
2112.33	45.7572
2115.24	48.822
2118.14	51.4691
2121.04	54.6453
2123.94	57.2893
2126.84	60.3269
2129.74	64.1605
2132.64	67.8189
2135.54	71.2626
2138.43	75.0046
2141.33	79.8804
2144.22	82.6151
2147.11	86.1981
2150.01	89.1266
2152.9	92.0582
2155.79	94.7264
2158.67	97.9957
2161.56	99.3142
2164.45	100.895
2167.33	102.071
2170.22	103.161
2173.1	103.403
2175.98	103.009
2178.86	102.418
2181.74	100.523
2184.62	97.9861
2187.5	96.0597
2190.38	93.5632
2193.25	91.1041
2196.13	87.5426
2199	84.0557
2201.88	80.3668
2204.75	76.5501
2207.62	72.789
2210.49	69.7394
2213.36	65.831
2216.22	61.715
2219.09	58.8518
2221.96	56.7746
2224.82	54.8035
2227.68	52.14
2230.55	49.4807
2233.41	47.1194
2236.27	45.8827
2239.12	44.3448
2241.98	42.3365
2244.84	40.3219
2247.7	38.1977
2250.55	36.9862
2253.41	36.4761
2256.26	34.9284
2259.11	34.3061
2261.96	33.5079
2264.81	31.7033
2267.66	30.7844
2270.51	29.7551
2273.35	27.746
2276.2	26.1592
2279.04	24.7745
2281.89	23.8612
2284.73	23.4803
2287.57	22.9168
2290.41	21.762
2293.25	19.9661
2296.09	19.0446
2298.93	17.9085
2301.76	18.1221
2304.6	18.6685
2307.44	18.1558
2310.27	18.1147
2313.1	17.5481
2315.93	18.198
2318.76	17.9508
2321.59	17.3682
2324.42	18.0893
2327.25	18.4688
2330.07	18.47
2332.9	19.0271
2335.72	18.811
2338.55	18.0903
2341.37	16.8513
2344.19	15.6806
2347.01	16.1224
2349.83	14.3405
2352.65	11.8769
2355.46	10.072
2358.28	8.70551
2361.09	6.91146
2363.91	7.55435
2366.72	7.83123
2369.53	7.76129
2372.34	7.69624
2375.15	7.54148
2377.96	7.5195
2380.77	8.33988
2383.58	8.07519
2386.38	8.03021
2389.19	7.87415
2391.99	8.26171
2394.8	9.16678
2397.6	8.22586
2400.4	8.24073
2403.2	8.00098
2406	7.29556
2408.79	7.02909
2411.59	6.34612
2414.39	6.23757
2417.18	6.46137
2419.98	5.05218
2422.77	4.87444
2425.56	4.79287
2428.35	5.98323
2431.14	5.61592
2433.93	5.40111
2436.72	5.52498
2439.5	5.58259
2442.29	6.83664
2445.07	7.90493
2447.86	7.69359
2450.64	7.8757
2453.42	8.22877
2456.2	8.55237
2458.98	8.53944
2461.76	8.12264
2464.54	7.52922
2467.32	6.20457
2470.09	5.58797
2472.87	4.65144
2475.64	3.56405
2478.41	2.87666
2481.18	2.6182
2483.95	2.52323
2486.72	2.03484
2489.49	1.397
2492.26	0.861153
2495.03	0.69716
2497.79	0.47968
2500.56	0.249586
2503.32	0.0205752
2506.09	0.971955
2508.85	0.908127
2511.61	1.38505
2514.37	1.02521
2517.13	1.94793
2519.89	2.7149
2522.64	2.33473
2525.4	3.10905
2528.15	3.09712
2530.91	3.03536
2533.66	3.42945
2536.41	1.98372
2539.16	2.76688
2541.91	3.04546
2544.66	2.89673
2547.41	2.64604
2550.16	2.90951
2552.9	2.69368
2555.65	2.25457
2558.39	1.88184
2561.13	1.92597
2563.88	2.24267
2566.62	1.81347
2569.36	1.16751
2572.1	0.629326
2574.84	0.541269
2577.57	0.766986
2580.31	0.510882
2583.05	0.80193
2585.78	1.06862
2588.51	0.97327
2591.24	0.948472
2593.98	1.15389
2596.71	0.750949
2599.44	0.379591
2602.16	1.17982
2604.89	0.585648
2607.62	1.18324
2610.34	1.02766
2613.07	0.561485
2615.79	1.03981
2618.52	0.647641
2621.24	-0.216731
2623.96	-0.0937097
2626.68	-0.107981
2629.4	0.98263
2632.11	0.885914
2634.83	0.736436
2637.55	1.12864
2640.26	1.84998
2642.98	3.06343
2645.69	3.30007
2648.4	3.93403
2651.11	4.23203
2653.82	3.78487
2656.53	2.92648
2659.24	2.87625
2661.95	2.45498
2664.65	2.79271
2667.36	3.16593
2670.06	2.54654
2672.76	2.27768
2675.47	2.97677
2678.17	3.08359
2680.87	3.40999
2683.57	4.07093
2686.27	2.74978
2688.97	2.89682
2691.66	3.74237
2694.36	4.47994
2697.05	4.18497
2699.75	4.05074
2702.44	4.94062
2705.13	5.0055
2707.82	6.05601
2710.51	6.16524
2713.2	6.92244
2715.89	7.75677
2718.57	8.55503
2721.26	9.08765
2723.95	9.08327
2726.63	9.34354
2729.31	9.89459
2732	9.25956
2734.68	9.59509
2737.36	9.92977
2740.04	10.3946
2742.72	10.0111
2745.39	10.1365
2748.07	9.25988
2750.75	8.4184
2753.42	7.54835
2756.09	6.85232
2758.77	5.40376
2761.44	3.78397
2764.11	3.06722
2766.78	1.93952
2769.45	1.21315
2772.12	0.750862
2774.78	1.43959
2777.45	1.51647
2780.12	1.25812
2782.78	1.72536
2785.44	1.0477
2788.11	0.487652
2790.77	0.197975
2793.43	0.249655
2796.09	0.440809
2798.75	0.672269
2801.4	0.822525
2804.06	0.919495
2806.72	1.52323
2809.37	2.32856
2812.03	2.28722
2814.68	2.63157
2817.33	3.46233
2819.98	5.29975
2822.63	7.86313
2825.28	11.6363
2827.93	17.0692
2830.58	22.5266
2833.23	27.4758
2835.87	34.3505
2838.52	40.8384
2841.16	47.2566
2843.8	54.6225
2846.44	63.8349
2849.08	73.5044
2851.73	83.8418
2854.36	95.35
2857	106.441
2859.64	118.033
2862.28	128.425
2864.91	138.086
2867.55	147.053
2870.18	155.515
2872.81	162.43
2875.44	167.493
2878.07	172.15
2880.7	177.894
2883.33	182.686
2885.96	187.842
2888.59	194.328
2891.21	198.394
2893.84	203.501
2896.46	208.655
2899.09	215.902
2901.71	223.683
2904.33	233.484
2906.95	245.5
2909.57	259.176
2912.19	274.21
2914.81	288.927
2917.43	303.593
2920.04	316.197
2922.66	326.009
2925.27	334.18
2927.88	339.193
2930.5	342.873
2933.11	343.742
2935.72	341.641
2938.33	336.415
2940.94	329.75
2943.54	320.953
2946.15	310.581
2948.76	298.98
2951.36	286.065
2953.97	272.434
2956.57	257.879
2959.17	245.884
2961.77	233.835
2964.37	222.141
2966.97	210.798
2969.57	199.542
2972.17	189.306
2974.77	180.153
2977.36	170.145
2979.96	160.195
2982.55	149.521
2985.15	138.188
2987.74	127.419
2990.33	118.299
2992.92	108.945
2995.51	99.0162
2998.1	89.2976
3000.69	79.5694
3003.27	71.6063
3005.86	63.7197
3008.44	56.3459
3011.03	50.8366
3013.61	44.3998
3016.19	39.9878
3018.78	36.2677
3021.36	33.2568
3023.94	31.364
3026.51	29.5221
3029.09	27.8334
3031.67	27.9994
3034.24	28.5602
3036.82	30.2363
3039.39	31.2601
3041.97	33.7587
3044.54	35.0455
3047.11	37.0926
3049.68	38.5428
3052.25	39.8274
3054.82	39.7947
3057.39	38.96
3059.96	38.1156
3062.52	37.3602
3065.09	35.6076
3067.65	33.5686
3070.22	30.8483
3072.78	27.6039
3075.34	24.6199
3077.9	20.5022
3080.46	18.1025
3083.02	15.6151
3085.58	12.6139
3088.14	10.2012
3090.69	8.24493
3093.25	7.215
3095.8	6.41506
3098.36	6.27119
3100.91	6.19658
3103.46	6.39363
3106.01	6.55097
3108.56	6.53452
3111.11	7.18491
3113.66	7.99411
3116.21	8.82085
3118.76	8.71699
3121.3	9.45733
3123.85	9.80019
3126.39	9.68988
3128.93	9.27714
3131.48	8.38377
3134.02	7.74284
3136.56	6.81855
3139.1	6.09408
3141.64	4.36451
3144.17	2.39837
3146.71	-0.615532
3149.25	-2.8814