File: data/Raman/poly_smoothed/Thy_50_12_48_1x_45s_532 nm_x100_100%_600 gr_mm_01.txt
#Acq. time (s)=	45
#Accumulations=	2
#Range (cm-¹)=	200...3150
#Windows=	2
#Auto scanning=	Off
#Autofocus=	Off
#Macrospot=	Off
#AutoExposure=	Off
#Spike filter=	Multiple accum.
#Delay time (s)=	0
#Binning=	1
#Readout mode=	Signal
#DeNoise=	Off
#ICS correction=	On
#Dark correction=	Off
#Inst. Process=	Off
#Detector Gain=	Best Dynamic Range
#Detector ADC=	20 kHz
#Detector temperature (°C)=	-69.85
#Instrument=	LabRAM HR Evol
#Detector=	Synapse
#Objective=	x100
#Grating=	600 gr/mm
#ND Filter=	100%
#Laser (nm)=	532
#Hole=	100.021
#Range=	Auto
#Laser Pol.=	No
#Raman. Pol.=	No
#Laser Pol. (°)=	-0.0007625
#Raman Pol. (°)=	89.9995
#Collection=	Microscope
#StageXY=	Marzhauser
#StageZ=	Marzhauser
#X (µm)=	-5083.6
#Y (µm)=	1488.5
#Z (µm)=	63.8
#Full time(mm:ss)=	3:15
#Project=
#Sample=
#Site=
#Title=	Thy_50_12_48_2x_45s_532 nm_x100_100%_600 gr_mm
#Remark=
#Date=	07.07.2022 12:49
#Acquired=	07.07.2022 12:49:20
#Base:Fit=	10.08.2022 10:04:30
#Base:Sub=	10.08.2022 10:04:45
#Filter:Polynom=	16.08.2022 10:20:25
#AxisType[0]=Intens
#AxisUnit[0]=Cnt
#AxisType[1]=Spectr
#AxisUnit[1]=1/cm
200.43	-1.39379
204.061	0.535401
207.688	3.29311
211.316	5.49314
214.941	8.11717
218.566	7.92789
222.188	8.99771
225.809	10.0362
229.43	11.2579
233.047	10.8704
236.663	11.7896
240.278	10.2252
243.894	11.8368
247.506	12.7441
251.116	13.3594
254.725	12.9613
258.333	11.8883
261.939	11.8267
265.546	12.2713
269.15	12.5092
272.752	12.6458
276.353	12.1406
279.952	12.544
283.55	13.2057
287.146	12.7251
290.739	14.4228
294.333	15.5015
297.925	17.0356
301.516	17.1253
305.106	18.0862
308.694	19.5767
312.279	19.7342
315.864	20.3186
319.448	20.8094
323.029	21.1251
326.61	22.2967
330.19	22.0572
333.766	23.3672
337.343	21.8316
340.917	21.5299
344.491	21.5723
348.062	22.2987
351.633	22.2193
355.201	22.0779
358.77	19.8623
362.335	17.3554
365.899	15.8594
369.464	15.6061
373.025	14.7883
376.585	13.3238
380.143	13.1211
383.702	12.956
387.258	11.4708
390.812	10.0564
394.365	9.71234
397.916	8.66998
401.467	6.67997
405.015	6.39811
408.565	6.56314
412.111	7.31333
415.656	7.43231
419.197	8.61659
422.739	9.89867
426.279	11.5114
429.819	13.1086
433.356	14.2489
436.893	15.2086
440.428	16.925
443.96	16.3782
447.492	17.6599
451.023	20.2703
454.553	20.3241
458.079	21.5931
461.606	22.9937
465.132	24.3379
468.654	24.7718
472.177	24.8428
475.696	24.4826
479.217	24.7965
482.733	24.6078
486.251	24.3206
489.765	24.2446
493.278	25.4498
496.791	26.364
500.301	26.365
503.81	25.2437
507.319	25.2405
510.825	24.7054
514.33	23.3579
517.833	22.747
521.337	22.6009
524.838	21.8445
528.337	21.4506
531.835	20.6468
535.332	21.1064
538.827	19.7179
542.321	17.1638
545.814	17.8914
549.305	16.0361
552.795	15.5227
556.284	14.6756
559.771	13.8102
563.257	12.495
566.742	10.9189
570.223	10.0119
573.705	10.5429
577.185	9.88447
580.665	8.74412
584.141	7.33594
587.617	5.68394
591.092	5.64264
594.564	5.50438
598.037	5.68715
601.506	5.62025
604.976	6.41987
608.443	7.07741
611.91	6.94065
615.374	9.13952
618.839	8.19902
622.3	7.90136
625.761	8.91811
629.221	10.6112
632.679	11.8076
636.135	13.4559
639.592	15.982
643.045	15.8412
646.497	16.0389
649.948	17.1036
653.398	18.955
656.846	20.48
660.293	22.8742
663.738	22.1452
667.185	21.7543
670.628	21.8788
674.067	22.7907
677.508	24.3377
680.947	26.1668
684.385	27.3843
687.821	27.9196
691.256	28.352
694.69	28.8753
698.121	28.9488
701.552	30.5496
704.982	30.5281
708.41	31.9205
711.836	32.4298
715.262	32.923
718.685	34.582
722.108	37.234
725.53	37.8777
728.949	39.6956
732.369	42.603
735.785	44.6295
739.2	47.121
742.616	48.4154
746.028	49.9974
749.441	51.6717
752.851	55.1063
756.26	58.0475
759.667	61.2794
763.075	65.2221
766.479	67.2843
769.883	68.3694
773.285	71.2893
776.686	72.4109
780.085	73.5018
783.484	74.4201
786.881	75.5588
790.276	76.3616
793.671	77.7279
797.064	77.6749
800.456	77.8453
803.846	77.7547
807.236	78.52
810.624	78.5433
814.01	77.2885
817.394	76.4641
820.778	75.2649
824.161	75.9463
827.543	74.4107
830.921	74.1316
834.3	72.0555
837.676	71.6464
841.053	69.3205
844.426	66.9769
847.8	65.2361
851.171	63.6687
854.542	60.7992
857.911	58.1509
861.279	55.9215
864.645	55.3818
868.01	54.4456
871.375	53.3347
874.737	53.743
878.097	52.1763
881.457	51.227
884.817	49.9275
888.174	51.117
891.53	52.8074
894.884	51.7278
898.237	51.9284
901.589	53.2935
904.94	53.2377
908.289	52.422
911.637	50.6864
914.984	47.8991
918.33	46.9233
921.674	45.3535
925.015	42.4921
928.357	40.9204
931.698	37.2859
935.037	34.8279
938.373	33.0993
941.71	31.3206
945.046	29.0792
948.378	28.9236
951.711	29.1914
955.043	29.2461
958.372	29.2037
961.701	26.6165
965.027	27.3329
968.354	30.3158
971.678	31.3056
975	31.3191
978.324	32.7232
981.644	34.9976
984.962	35.8296
988.282	35.756
991.598	35.3111
994.913	35.1789
998.227	34.7231
1001.54	34.2168
1004.85	32.0211
1008.16	30.5005
1011.47	28.9783
1014.78	30.5585
1018.08	31.1936
1021.39	31.967
1024.69	32.6869
1028	34.3087
1031.3	36.1456
1034.6	35.9776
1037.9	35.1675
1041.19	34.8939
1044.49	35.3888
1047.79	36.3254
1051.08	37.0998
1054.37	35.4493
1057.66	33.9421
1060.95	32.8003
1064.24	30.9089
1067.53	28.5411
1070.81	25.4466
1074.1	23.902
1077.38	20.1873
1080.66	17.9701
1083.94	15.6767
1087.22	12.7487
1090.5	13.1281
1093.78	13.0765
1097.05	12.3816
1100.33	12.3219
1103.6	13.3563
1106.87	13.0254
1110.15	11.6348
1113.41	11.7639
1116.68	11.5177
1119.95	9.83584
1123.21	9.6682
1126.48	8.86049
1129.74	7.25882
1133	6.4962
1136.26	4.90207
1139.52	4.28447
1142.78	2.94908
1146.04	2.58238
1149.29	1.86403
1152.55	1.62485
1155.8	-0.053043
1159.05	1.05944
1162.3	3.31753
1165.55	2.90107
1168.8	4.01175
1172.05	4.36076
1175.29	4.99401
1178.54	5.6145
1181.78	4.89099
1185.02	5.3886
1188.26	6.03919
1191.5	7.16318
1194.74	7.00496
1197.97	8.13091
1201.21	8.38038
1204.44	10.8341
1207.68	13.1157
1210.91	15.0867
1214.14	18.1798
1217.37	19.4594
1220.6	21.5019
1223.82	24.0309
1227.05	26.1986
1230.27	27.6524
1233.49	30.659
1236.72	34.0475
1239.94	37.1044
1243.16	38.7369
1246.37	40.2319
1249.59	40.4617
1252.8	41.0715
1256.02	42.6305
1259.23	42.8722
1262.44	44.4531
1265.66	45.9547
1268.87	46.4456
1272.07	48.6222
1275.28	52.488
1278.48	54.4382
1281.69	58.0293
1284.89	60.5644
1288.09	64.2773
1291.3	65.6945
1294.49	65.8346
1297.69	66.9148
1300.89	66.1915
1304.09	67.8477
1307.28	68.5876
1310.47	69.7244
1313.66	70.3874
1316.86	70.5942
1320.05	71.3423
1323.23	70.5538
1326.42	68.9117
1329.61	68.7717
1332.79	67.096
1335.98	65.4371
1339.16	63.0223
1342.34	60.8698
1345.52	59.2201
1348.7	58.3091
1351.87	56.4854
1355.05	55.9006
1358.23	55.4468
1361.4	53.7358
1364.57	52.1837
1367.74	49.3484
1370.91	47.7065
1374.08	45.3364
1377.25	44.7179
1380.42	44.7959
1383.58	45.683
1386.75	44.632
1389.91	44.6902
1393.07	43.0574
1396.23	42.5966
1399.39	42.9025
1402.55	41.7136
1405.7	40.998
1408.86	41.5384
1412.01	42.3449
1415.17	42.985
1418.32	45.0159
1421.47	49.6032
1424.62	52.9439
1427.77	57.2432
1430.92	62.8194
1434.06	68.4096
1437.2	70.4866
1440.35	75.543
1443.49	78.7326
1446.63	80.3182
1449.77	83.0306
1452.91	82.6406
1456.05	83.5544
1459.18	81.8754
1462.32	77.7436
1465.45	73.4206
1468.59	67.7437
1471.72	63.753
1474.85	58.3846
1477.98	51.3007
1481.11	44.8
1484.23	40.3363
1487.36	35.3863
1490.48	29.7309
1493.61	26.8815
1496.73	24.1269
1499.85	21.4032
1502.97	19.4677
1506.09	19.7054
1509.2	18.4136
1512.32	17.0326
1515.44	15.7219
1518.55	16.7037
1521.66	18.2556
1524.77	20.5966
1527.88	21.0506
1530.99	23.5243
1534.1	25.8672
1537.21	27.5568
1540.31	29.7138
1543.42	33.2594
1546.52	39.1172
1549.62	43.2397
1552.72	46.6523
1555.82	49.9825
1558.92	55.4205
1562.02	57.5391
1565.11	61.0136
1568.21	64.4117
1571.3	66.1913
1574.39	69.0559
1577.49	72.0278
1580.58	73.1123
1583.67	73.4401
1586.75	72.4047
1589.84	71.782
1592.93	73.5387
1596.01	74.2517
1599.09	73.5568
1602.18	71.1152
1605.26	68.9328
1608.34	66.625
1611.41	65.2344
1614.49	66.1404
1617.57	66.2192
1620.64	68.8576
1623.72	69.4574
1626.79	68.9439
1629.86	70.9062
1632.93	73.0478
1636	74.4488
1639.07	75.5508
1642.14	77.3648
1645.2	79.5428
1648.27	81.3898
1651.33	82.9185
1654.39	83.0336
1657.45	82.3389
1660.51	80.1912
1663.57	79.5392
1666.63	79.1736
1669.69	76.4767
1672.74	71.8049
1675.79	66.5519
1678.85	61.0249
1681.9	56.3348
1684.95	51.0308
1688	45.7401
1691.05	41.301
1694.1	36.9763
1697.14	34.2124
1700.19	29.4691
1703.23	27.2222
1706.27	24.0363
1709.32	21.6044
1712.35	18.5924
1715.39	16.9858
1718.43	16.9045
1721.47	15.8186
1724.5	14.6482
1727.54	15.1284
1730.57	13.8019
1733.61	13.7663
1736.64	13.5345
1739.67	13.7825
1742.7	12.8236
1745.72	12.1817
1748.75	10.637
1751.78	10.3302
1754.8	9.15169
1757.82	8.90401
1760.85	8.54302
1763.87	8.79845
1766.89	9.22964
1769.91	8.96356
1772.92	8.93954
1775.94	8.24066
1778.96	8.24642
1781.97	7.66947
1784.98	8.97775
1788	8.94685
1791.01	9.14864
1794.01	9.34485
1797.02	9.58385
1800.03	9.95823
1803.04	9.62756
1806.04	7.75148
1809.05	7.33816
1812.05	6.69549
1815.05	6.42309
1818.05	5.94392
1821.05	5.73576
1824.05	5.27371
1827.05	4.55714
1830.04	3.93386
1833.04	3.35707
1836.03	2.75257
1839.03	2.66845
1842.02	2.6583
1845.01	2.17151
1848	1.99987
1850.99	3.06376
1853.97	3.28451
1856.96	4.23818
1859.94	4.97863
1862.93	5.54667
1865.91	5.1474
1868.89	5.61784
1871.87	5.98947
1874.85	6.28594
1877.83	6.95864
1880.81	7.13566
1882.56	7.09631
1885.55	8.33554
1888.54	7.25355
1891.52	5.98679
1894.51	6.05651
1897.49	4.88807
1900.48	3.99351
1903.46	3.84809
1906.44	4.61775
1909.42	3.39354
1912.4	3.07064
1915.38	1.78514
1918.35	0.423828
1921.33	0.379136
1924.3	1.72781
1927.28	1.09868
1930.25	0.770207
1933.22	1.05341
1936.19	1.68286
1939.16	1.43913
1942.13	2.85264
1945.09	3.18703
1948.06	4.62197
1951.03	5.40445
1953.99	5.67936
1956.95	5.64747
1959.91	4.88438
1962.87	4.46274
1965.83	5.59942
1968.79	4.73995
1971.75	5.49117
1974.7	5.61312
1977.66	4.92703
1980.61	4.52139
1983.56	3.81385
1986.52	4.00151
1989.47	3.87161
1992.41	4.88917
1995.36	5.53556
1998.31	5.01983
2001.26	4.78802
2004.2	6.14646
2007.15	6.8261
2010.09	6.73542
2013.03	6.72677
2015.97	6.99823
2018.91	7.11607
2021.85	7.96398
2024.79	8.27657
2027.72	7.56459
2030.66	8.19008
2033.59	8.90382
2036.53	9.78304
2039.46	10.1779
2042.39	10.5516
2045.32	11.6587
2048.25	11.484
2051.18	13.4424
2054.1	14.5811
2057.03	15.969
2059.95	17.0688
2062.88	18.4098
2065.8	18.8813
2068.72	19.5427
2071.64	20.5588
2074.56	21.9452
2077.48	22.9558
2080.39	23.4867
2083.31	23.3023
2086.22	24.8818
2089.14	26.8917
2092.05	28.4171
2094.96	30.106
2097.87	32.0544
2100.78	34.0959
2103.69	37.0404
2106.6	39.1287
2109.51	42.546
2112.41	46.0811
2115.32	48.0274
2118.22	51.3112
2121.12	54.8315
2124.02	58.5321
2126.92	62.2723
2129.82	66.2825
2132.72	70.0246
2135.62	73.126
2138.51	76.6036
2141.41	79.3263
2144.3	82.3206
2147.19	85.5703
2150.09	88.8891
2152.97	91.6866
2155.86	94.1756
2158.75	96.5044
2161.64	97.6762
2164.53	98.6915
2167.41	101.049
2170.3	102.11
2173.18	103.322
2176.06	101.833
2178.94	101.543
2181.82	100.312
2184.7	97.9777
2187.58	95.4701
2190.46	93.1452
2193.33	90.0738
2196.21	87.6769
2199.08	84.8433
2201.95	81.5079
2204.83	77.3858
2207.7	73.7957
2210.57	69.7905
2213.43	65.5318
2216.3	61.7063
2219.17	58.8425
2222.03	55.0163
2224.9	51.7087
2227.76	48.5853
2230.62	45.8965
2233.49	44.3211
2236.34	41.6836
2239.2	39.7174
2242.06	38.0008
2244.92	34.4539
2247.78	32.0223
2250.63	31.0359
2253.48	29.4827
2256.34	27.7208
2259.19	26.9673
2262.04	26.3451
2264.89	25.0932
2267.74	25.451
2270.59	24.5319
2273.43	22.8034
2276.28	21.483
2279.12	20.0415
2281.97	18.8011
2284.81	17.6551
2287.65	17.3113
2290.49	15.6647
2293.33	14.4022
2296.17	13.4423
2299.01	12.8627
2301.84	12.989
2304.68	13.2708
2307.51	13.4172
2310.35	13.1093
2313.18	12.8286
2316.01	12.4905
2318.84	12.3444
2321.67	12.985
2324.5	11.5137
2327.33	11.498
2330.15	11.2097
2332.98	9.94365
2335.8	9.12806
2338.62	8.10311
2341.45	6.27105
2344.27	4.8435
2347.09	4.43298
2349.91	4.24597
2352.72	3.21264
2355.54	2.02354
2358.36	1.45821
2361.17	0.610228
2363.98	0.728674
2366.8	2.66086
2369.61	3.86197
2372.42	4.63676
2375.23	4.07355
2378.04	4.86536
2380.85	5.22427
2383.66	5.80875
2386.46	6.67933
2389.26	6.28686
2392.07	5.83013
2394.87	6.15154
2397.67	6.83005
2400.47	7.40926
2403.27	6.937
2406.07	6.68908
2408.87	7.42965
2411.67	8.70216
2414.46	8.62941
2417.26	9.2893
2420.05	9.13274
2422.84	8.09527
2425.64	8.25293
2428.43	8.76514
2431.22	9.01419
2434.01	8.44154
2436.79	8.78096
2439.58	8.93969
2442.37	7.97527
2445.15	7.01211
2447.93	7.54043
2450.72	7.01993
2453.5	6.54188
2456.28	6.36518
2459.06	5.00138
2461.84	5.47951
2464.62	5.35309
2467.39	5.02521
2470.17	4.98453
2472.94	4.58484
2475.72	5.01437
2478.49	4.96122
2481.26	4.31754
2484.03	3.84217
2486.8	3.01124
2489.57	1.76862
2492.34	1.20214
2495.1	1.23765
2497.87	0.179931
2500.63	-0.851829
2503.4	-1.25947
2506.16	-1.14247
2508.92	-1.56758
2511.68	-2.37733
2514.44	-2.03689
2517.2	-1.80801
2519.96	-2.15002
2522.72	-2.45963
2525.47	-1.67224
2528.23	-0.925012
2530.98	1.28733
2533.74	2.19647
2536.49	3.41809
2539.24	3.36014
2541.99	3.69457
2544.74	3.61433
2547.49	3.86944
2550.23	4.57706
2552.98	4.50475
2555.72	4.27084
2558.47	3.90259
2561.21	4.33686
2563.95	4.66499
2566.69	4.13119
2569.43	3.95207
2572.17	4.49003
2574.91	4.14881
2577.65	4.29874
2580.39	4.27947
2583.12	3.95989
2585.85	3.81456
2588.59	4.3498
2591.32	4.6214
2594.05	5.38831
2596.78	6.14417
2599.51	5.52661
2602.24	5.34183
2604.97	4.50902
2607.69	4.24035
2610.42	4.47754
2613.14	4.03103
2615.87	3.06095
2618.59	3.25657
2621.31	3.61896
2624.03	3.89887
2626.75	3.88759
2629.47	3.95037
2632.19	3.68862
2634.91	2.86484
2637.62	2.79646
2640.34	3.48393
2643.05	3.99337
2645.76	4.72493
2648.48	4.77652
2651.19	4.64412
2653.9	5.11461
2656.6	5.8409
2659.31	6.62625
2662.02	6.69516
2664.73	6.71142
2667.43	8.28459
2670.14	9.52903
2672.84	10.1309
2675.54	10.3466
2678.24	10.6181
2680.94	11.0257
2683.64	11.3914
2686.34	12.0703
2689.04	11.9801
2691.74	11.3509
2694.43	10.3668
2697.13	10.7671
2699.82	10.7552
2702.51	9.35008
2705.21	9.41283
2707.9	10.2041
2710.58	9.44507
2713.27	8.10087
2715.96	7.62079
2718.65	8.18382
2721.33	8.04157
2724.02	8.47151
2726.71	8.33344
2729.39	8.08002
2732.07	9.31085
2734.75	9.29994
2737.43	9.44911
2740.11	8.66607
2742.79	8.01087
2745.47	7.85458
2748.14	7.28682
2750.82	6.30789
2753.49	5.83373
2756.17	4.75892
2758.84	4.19898
2761.51	4.10021
2764.18	4.14936
2766.85	2.37137
2769.52	1.67024
2772.19	2.4766
2774.86	2.46964
2777.52	0.361886
2780.19	0.277723
2782.85	0.970522
2785.52	0.83301
2788.18	0.24935
2790.84	0.617954
2793.5	-0.587396
2796.16	-1.02458
2798.82	-0.1067
2801.48	-0.362601
2804.13	-0.681471
2806.79	-1.7033
2809.45	-3.07767
2812.1	-3.14497
2814.75	-3.48426
2817.41	-2.27873
2820.06	0.344952
2822.71	3.47155
2825.36	8.88535
2828	13.6989
2830.65	18.7641
2833.3	25.2107
2835.94	31.5948
2838.59	37.4651
2841.23	44.3115
2843.87	51.3682
2846.52	58.864
2849.16	67.0769
2851.8	75.8166
2854.44	85.2724
2857.08	93.6872
2859.71	102.047
2862.35	109.025
2864.98	116.158
2867.62	121.897
2870.25	125.715
2872.88	129.774
2875.52	133.61
2878.15	138.87
2880.78	143.075
2883.41	147.175
2886.03	151.367
2888.66	156.13
2891.29	159.678
2893.91	164.102
2896.54	167.739
2899.16	172.33
2901.78	177.766
2904.4	183.266
2907.02	190.738
2909.64	199.172
2912.26	208.626
2914.88	218.771
2917.5	229.072
2920.11	237.922
2922.73	244.589
2925.34	249.555
2927.96	253.569
2930.57	254.996
2933.18	255.055
2935.79	253.329
2938.4	250.034
2941.01	245.341
2943.62	238.57
2946.22	229.86
2948.83	222.208
2951.43	213.498
2954.04	203.795
2956.64	193.38
2959.24	182.186
2961.84	171.767
2964.45	162.013
2967.05	152.438
2969.64	143.857
2972.24	136.523
2974.84	127.771
2977.43	119.861
2980.03	111.205
2982.62	102.817
2985.22	94.1663
2987.81	84.889
2990.4	75.629
2992.99	66.1912
2995.58	57.2533
2998.17	49.6845
3000.76	41.8628
3003.34	35.8673
3005.93	29.5337
3008.52	24.6141
3011.1	20.5802
3013.68	17.2088
3016.27	13.3574
3018.85	9.88115
3021.43	8.47826
3024.01	7.61217
3026.59	7.34371
3029.16	6.88183
3031.74	6.7573
3034.32	7.78031
3036.89	8.17197
3039.47	8.26167
3042.04	9.7439
3044.61	10.7059
3047.18	12.0886
3049.75	11.7005
3052.32	11.4711
3054.89	11.6362
3057.46	11.4861
3060.03	11.6465
3062.59	10.3659
3065.16	9.81267
3067.72	9.18921
3070.29	7.98434
3072.85	6.19775
3075.41	4.73033
3077.97	3.45493
3080.53	2.07704
3083.09	1.57426
3085.65	1.79136
3088.21	0.723751
3090.76	0.597519
3093.32	0.675838
3095.87	0.751633
3098.43	1.55673
3100.98	1.95185
3103.53	3.277
3106.08	4.03671
3108.63	5.27864
3111.18	6.05279
3113.73	6.4374
3116.28	8.15725
3118.83	9.02043
3121.37	10.0215
3123.92	11.0753
3126.46	12.5308
3129	13.1203
3131.55	14.198
3134.09	14.5265
3136.63	15.91
3139.17	17.4872
3141.71	19.4355
3144.24	21.1097
3146.78	21.8707
3149.32	23.0195