File: data/Raman/poly_smoothed/Thy_50_12_44_1x_45s_532 nm_x100_100%_600 gr_mm_01.txt
#Acq. time (s)=	45
#Accumulations=	2
#Range (cm-¹)=	200...3150
#Windows=	2
#Auto scanning=	Off
#Autofocus=	Off
#Macrospot=	Off
#AutoExposure=	Off
#Spike filter=	Multiple accum.
#Delay time (s)=	0
#Binning=	1
#Readout mode=	Signal
#DeNoise=	Off
#ICS correction=	On
#Dark correction=	Off
#Inst. Process=	Off
#Detector Gain=	Best Dynamic Range
#Detector ADC=	20 kHz
#Detector temperature (°C)=	-69.85
#Instrument=	LabRAM HR Evol
#Detector=	Synapse
#Objective=	x100
#Grating=	600 gr/mm
#ND Filter=	100%
#Laser (nm)=	532
#Hole=	100.021
#Range=	Auto
#Laser Pol.=	No
#Raman. Pol.=	No
#Laser Pol. (°)=	-0.0007625
#Raman Pol. (°)=	89.9995
#Collection=	Microscope
#StageXY=	Marzhauser
#StageZ=	Marzhauser
#X (µm)=	-5120.9
#Y (µm)=	1526.5
#Z (µm)=	63.25
#Full time(mm:ss)=	3:18
#Project=
#Sample=
#Site=
#Title=	Thy_50_12_44_2x_45s_532 nm_x100_100%_600 gr_mm
#Remark=
#Date=	07.07.2022 12:27
#Acquired=	07.07.2022 12:27:39
#Base:Fit=	10.08.2022 10:04:30
#Base:Sub=	10.08.2022 10:04:45
#Filter:Polynom=	16.08.2022 10:20:25
#AxisType[0]=Intens
#AxisUnit[0]=Cnt
#AxisType[1]=Spectr
#AxisUnit[1]=1/cm
200.43	5.71194
204.061	7.23622
207.688	6.80666
211.316	5.56801
214.941	4.48037
218.566	3.33509
222.188	2.69449
225.809	4.52385
229.43	4.51848
233.047	3.66852
236.663	3.37227
240.278	3.5273
243.894	1.55544
247.506	1.44787
251.116	3.27159
254.725	3.53642
258.333	4.22502
261.939	3.70936
265.546	5.88458
269.15	6.32081
272.752	6.18991
276.353	8.4302
279.952	7.59275
283.55	8.13766
287.146	9.6304
290.739	10.2938
294.333	9.53388
297.925	10.0068
301.516	10.9315
305.106	12.7096
308.694	13.0161
312.279	15.732
315.864	14.829
319.448	15.192
323.029	16.1237
326.61	16.2245
330.19	15.6587
333.766	15.3688
337.343	15.6616
340.917	16.0016
344.491	15.2677
348.062	13.6925
351.633	12.445
355.201	12.5082
358.77	10.8204
362.335	9.7683
365.899	8.50743
369.464	6.9535
373.025	5.77293
376.585	3.68398
380.143	2.03725
383.702	2.14036
387.258	4.0964
390.812	4.71099
394.365	6.11686
397.916	6.02138
401.467	7.1145
405.015	6.93986
408.565	8.77701
412.111	8.91987
415.656	7.27262
419.197	7.9688
422.739	7.55222
426.279	6.5993
429.819	6.09878
433.356	6.04344
436.893	7.229
440.428	7.86823
443.96	8.50312
447.492	9.57072
451.023	9.80905
454.553	9.6146
458.079	9.94697
461.606	9.11435
465.132	11.4363
468.654	13.0516
472.177	14.0086
475.696	14.0098
479.217	14.8685
482.733	15.3685
486.251	14.6268
489.765	16.8877
493.278	18.0044
496.791	19.7505
500.301	20.5706
503.81	21.3567
507.319	21.9492
510.825	20.5418
514.33	20.4661
517.833	19.6671
521.337	19.4241
524.838	20.0676
528.337	20.1983
531.835	19.0085
535.332	18.3853
538.827	16.4138
542.321	13.4773
545.814	12.0897
549.305	9.9349
552.795	8.17636
556.284	5.17677
559.771	2.57448
563.257	1.52935
566.742	1.55846
570.223	1.75102
573.705	3.49994
577.185	5.18217
580.665	6.42095
584.141	6.3519
587.617	6.9705
591.092	7.26932
594.564	8.38964
598.037	7.92304
601.506	9.6148
604.976	9.62783
608.443	11.7642
611.91	12.2563
615.374	12.2976
618.839	12.1941
622.3	12.82
625.761	12.5868
629.221	11.2647
632.679	12.428
636.135	11.1248
639.592	11.4326
643.045	12.6428
646.497	12.6172
649.948	14.3053
653.398	14.2234
656.846	15.9503
660.293	15.1184
663.738	15.0863
667.185	15.0848
670.628	18.146
674.067	17.6804
677.508	19.3001
680.947	21.483
684.385	22.8426
687.821	25.041
691.256	26.0583
694.69	26.3242
698.121	27.9633
701.552	30.0689
704.982	30.5943
708.41	30.8729
711.836	31.076
715.262	30.7266
718.685	32.2683
722.108	33.5167
725.53	34.827
728.949	34.8426
732.369	34.9055
735.785	35.3625
739.2	36.8111
742.616	37.2502
746.028	37.6683
749.441	38.9691
752.851	42.3505
756.26	45.231
759.667	47.0626
763.075	49.6305
766.479	51.5722
769.883	53.7343
773.285	56.2443
776.686	57.8197
780.085	59.8713
783.484	61.1738
786.881	61.9876
790.276	61.7721
793.671	62.0006
797.064	63.6399
800.456	65.3541
803.846	66.5413
807.236	66.7829
810.624	67.4089
814.01	68.6502
817.394	69.0328
820.778	66.0752
824.161	64.6623
827.543	62.8571
830.921	61.4235
834.3	59.8409
837.676	57.8826
841.053	54.9443
844.426	51.7434
847.8	48.5829
851.171	48.0646
854.542	46.5095
857.911	45.3867
861.279	43.7798
864.645	43.3618
868.01	43.9632
871.375	42.8641
874.737	42.6552
878.097	41.8774
881.457	41.3126
884.817	40.9261
888.174	39.908
891.53	39.0329
894.884	38.9904
898.237	36.4621
901.589	34.401
904.94	31.8785
908.289	30.5068
911.637	31.3258
914.984	28.4586
918.33	26.5476
921.674	25.8317
925.015	24.3917
928.357	23.5939
931.698	22.4361
935.037	22.0727
938.373	22.2556
941.71	22.169
945.046	22.8021
948.378	23.1004
951.711	22.0366
955.043	20.3862
958.372	18.7224
961.701	18.3268
965.027	19.428
968.354	18.1821
971.678	15.7392
975	15.5347
978.324	15.6958
981.644	16.1859
984.962	17.3667
988.282	17.6095
991.598	17.7872
994.913	17.667
998.227	18.2595
1001.54	18.862
1004.85	19.7571
1008.16	19.8785
1011.47	18.9497
1014.78	19.7637
1018.08	22.7486
1021.39	22.9935
1024.69	22.8692
1028	23.3278
1031.3	22.2239
1034.6	21.743
1037.9	21.8826
1041.19	21.1932
1044.49	21.4643
1047.79	20.0528
1051.08	16.9666
1054.37	16.4777
1057.66	16.7084
1060.95	14.5747
1064.24	11.8682
1067.53	10.2688
1070.81	8.00343
1074.1	7.51943
1077.38	8.51618
1080.66	8.16472
1083.94	5.35754
1087.22	5.58024
1090.5	4.6933
1093.78	6.12622
1097.05	5.653
1100.33	5.39766
1103.6	6.25415
1106.87	7.15358
1110.15	7.91969
1113.41	8.81435
1116.68	8.56038
1119.95	9.60534
1123.21	10.2582
1126.48	9.59107
1129.74	10.3973
1133	9.49539
1136.26	8.97386
1139.52	8.5187
1142.78	8.09505
1146.04	7.22812
1149.29	6.52673
1152.55	7.25778
1155.8	7.20068
1159.05	7.0123
1162.3	4.33339
1165.55	2.94079
1168.8	2.96176
1172.05	2.2331
1175.29	1.93401
1178.54	2.18737
1181.78	4.31814
1185.02	5.07556
1188.26	5.04873
1191.5	6.16065
1194.74	6.24841
1197.97	6.32141
1201.21	6.92978
1204.44	7.35169
1207.68	10.1309
1210.91	12.5645
1214.14	15.298
1217.37	18.0564
1220.6	21.0613
1223.82	23.5448
1227.05	26.3905
1230.27	29.5336
1233.49	33.0662
1236.72	35.1908
1239.94	37.1184
1243.16	39.1921
1246.37	42.2139
1249.59	44.5023
1252.8	48.5801
1256.02	51.1795
1259.23	54.3194
1262.44	56.2762
1265.66	59.5233
1268.87	62.107
1272.07	64.7848
1275.28	66.2354
1278.48	69.0201
1281.69	72.7344
1284.89	76.3041
1288.09	77.7111
1291.3	77.9968
1294.49	78.4043
1297.69	79.3797
1300.89	79.1908
1304.09	78.4996
1307.28	79.4169
1310.47	79.1521
1313.66	78.9884
1316.86	76.9292
1320.05	77.1868
1323.23	75.7203
1326.42	74.6206
1329.61	74.3054
1332.79	72.1856
1335.98	70.7669
1339.16	70.3472
1342.34	70.0079
1345.52	68.3885
1348.7	67.0134
1351.87	65.7516
1355.05	63.106
1358.23	62.0232
1361.4	59.1529
1364.57	56.8777
1367.74	55.1588
1370.91	52.9221
1374.08	50.9791
1377.25	49.6788
1380.42	48.0693
1383.58	47.084
1386.75	46.6539
1389.91	46.9976
1393.07	46.2933
1396.23	45.4951
1399.39	47.3123
1402.55	47.8638
1405.7	50.5739
1408.86	52.4919
1412.01	54.2832
1415.17	57.7898
1418.32	60.5643
1421.47	63.5556
1424.62	68.4277
1427.77	72.9102
1430.92	77.2012
1434.06	82.2643
1437.2	87.1586
1440.35	90.511
1443.49	94.1615
1446.63	95.613
1449.77	95.0355
1452.91	93.6334
1456.05	93.4047
1459.18	90.2454
1462.32	87.6551
1465.45	83.722
1468.59	78.2713
1471.72	73.3633
1474.85	67.7718
1477.98	63.9052
1481.11	58.8919
1484.23	53.7319
1487.36	50.0939
1490.48	47.1426
1493.61	44.4796
1496.73	42.5597
1499.85	41.9533
1502.97	41.2279
1506.09	42.6209
1509.2	42.3086
1512.32	42.36
1515.44	42.324
1518.55	44.0001
1521.66	44.8467
1524.77	45.4019
1527.88	46.3513
1530.99	48.4059
1534.1	51.0543
1537.21	53.1684
1540.31	55.577
1543.42	57.7066
1546.52	62.6361
1549.62	66.0366
1552.72	69.576
1555.82	73.0996
1558.92	77.304
1562.02	83.4244
1565.11	86.8965
1568.21	89.337
1571.3	92.6148
1574.39	94.9972
1577.49	96.2288
1580.58	97.2524
1583.67	97.7007
1586.75	97.5937
1589.84	96.4277
1592.93	95.3768
1596.01	92.92
1599.09	89.8163
1602.18	88.9329
1605.26	85.4898
1608.34	83.2069
1611.41	80.8856
1614.49	79.0392
1617.57	78.39
1620.64	78.2217
1623.72	80.0505
1626.79	81.0894
1629.86	81.6157
1632.93	83.5781
1636	86.0117
1639.07	87.2635
1642.14	86.9424
1645.2	87.379
1648.27	87.5748
1651.33	87.946
1654.39	86.9045
1657.45	85.5057
1660.51	84.9242
1663.57	82.1292
1666.63	78.6437
1669.69	74.3139
1672.74	70.9478
1675.79	66.5819
1678.85	61.5515
1681.9	56.4202
1684.95	52.0312
1688	47.6946
1691.05	44.0939
1694.1	40.6275
1697.14	37.9807
1700.19	34.623
1703.23	31.4554
1706.27	28.9386
1709.32	27.2652
1712.35	25.2653
1715.39	23.9268
1718.43	21.9563
1721.47	21.0801
1724.5	20.6808
1727.54	20.3091
1730.57	19.2225
1733.61	19.5083
1736.64	19.0483
1739.67	19.1641
1742.7	19.8534
1745.72	19.2614
1748.75	18.5538
1751.78	18.0645
1754.8	17.4628
1757.82	17.1484
1760.85	15.6282
1763.87	14.8701
1766.89	13.7247
1769.91	13.1857
1772.92	12.192
1775.94	10.7324
1778.96	11.0926
1781.97	10.1726
1784.98	10.4969
1788	10.5122
1791.01	10.2326
1794.01	9.52462
1797.02	9.21737
1800.03	9.56575
1803.04	9.41883
1806.04	9.76153
1809.05	9.64643
1812.05	9.43596
1815.05	9.44635
1818.05	9.71058
1821.05	8.94182
1824.05	8.82815
1827.05	9.33665
1830.04	9.87254
1833.04	10.0962
1836.03	10.5385
1839.03	11.2044
1842.02	11.7689
1845.01	11.8109
1848	12.1443
1850.99	11.1398
1853.97	10.7576
1856.96	10.6398
1859.94	9.61776
1862.93	9.13653
1865.91	7.50089
1868.89	6.66402
1871.87	6.51837
1874.85	5.42358
1877.83	4.35346
1880.81	4.75675
1882.56	4.89533
1885.55	5.16703
1888.54	5.48436
1891.52	5.20988
1894.51	6.18944
1897.49	7.03741
1900.48	7.29704
1903.46	9.3389
1906.44	11.4279
1909.42	13.0686
1912.4	13.4616
1915.38	14.3997
1918.35	13.2743
1921.33	13.4187
1924.3	12.0373
1927.28	11.54
1930.25	10.7538
1933.22	10.4871
1936.19	9.92189
1939.16	9.24927
1942.13	8.61424
1945.09	8.57008
1948.06	7.83463
1951.03	7.39023
1953.99	6.40899
1956.95	4.88157
1959.91	4.40553
1962.87	3.0004
1965.83	2.20234
1968.79	2.02801
1971.75	1.9505
1974.7	2.19575
1977.66	2.62142
1980.61	3.50843
1983.56	3.62897
1986.52	3.02335
1989.47	3.228
1992.41	3.32698
1995.36	3.95615
1998.31	3.82925
2001.26	3.61861
2004.2	4.79546
2007.15	5.46916
2010.09	5.71734
2013.03	5.87018
2015.97	6.13457
2018.91	5.58073
2021.85	5.71926
2024.79	5.42469
2027.72	5.45499
2030.66	5.864
2033.59	4.44413
2036.53	4.67594
2039.46	5.03606
2042.39	5.81231
2045.32	5.66748
2048.25	6.6369
2051.18	7.3964
2054.1	8.77225
2057.03	8.3414
2059.95	9.48134
2062.88	11.5338
2065.8	12.3537
2068.72	13.3769
2071.64	14.8064
2074.56	16.6951
2077.48	18.528
2080.39	19.1135
2083.31	19.9859
2086.22	20.8794
2089.14	21.8288
2092.05	23.8588
2094.96	25.4128
2097.87	26.7385
2100.78	29.374
2103.69	30.9366
2106.6	31.3672
2109.51	33.5823
2112.41	35.7666
2115.32	37.7243
2118.22	40.0556
2121.12	42.577
2124.02	45.2023
2126.92	48.7213
2129.82	52.5465
2132.72	56.9132
2135.62	59.8722
2138.51	64.3873
2141.41	68.3493
2144.3	72.613
2147.19	75.9855
2150.09	78.7254
2152.97	82.5196
2155.86	84.6808
2158.75	87.1958
2161.64	88.2886
2164.53	89.643
2167.41	90.9133
2170.3	91.6883
2173.18	91.859
2176.06	89.4561
2178.94	87.9392
2181.82	84.7406
2184.7	82.3099
2187.58	79.2988
2190.46	76.3187
2193.33	73.553
2196.21	70.6004
2199.08	67.7447
2201.95	65.2685
2204.83	61.9449
2207.7	59.0267
2210.57	56.4192
2213.43	53.817
2216.3	51.0523
2219.17	47.8972
2222.03	44.7758
2224.9	42.1592
2227.76	39.0379
2230.62	36.8038
2233.49	34.7881
2236.34	33.1979
2239.2	31.6
2242.06	29.4189
2244.92	27.5797
2247.78	25.8351
2250.63	25.3591
2253.48	23.8537
2256.34	23.1258
2259.19	22.6543
2262.04	22.0707
2264.89	20.7896
2267.74	20.1339
2270.59	20.167
2273.43	18.9369
2276.28	17.8501
2279.12	17.2186
2281.97	16.7338
2284.81	15.608
2287.65	13.1204
2290.49	11.4156
2293.33	10.4301
2296.17	10.7909
2299.01	10.5004
2301.84	11.036
2304.68	10.4685
2307.51	9.84245
2310.35	9.37856
2313.18	8.86967
2316.01	8.45516
2318.84	9.11876
2321.67	8.40907
2324.5	8.99292
2327.33	10.0591
2330.15	9.15458
2332.98	8.72848
2335.8	8.69483
2338.62	8.2382
2341.45	7.08557
2344.27	6.74308
2347.09	6.56955
2349.91	5.60209
2352.72	3.99446
2355.54	2.69998
2358.36	1.76579
2361.17	2.08976
2363.98	2.98459
2366.8	2.64466
2369.61	2.23957
2372.42	1.60338
2375.23	-0.0940112
2378.04	0.223515
2380.85	-0.83752
2383.66	0.676319
2386.46	0.618848
2389.26	1.16333
2392.07	1.26327
2394.87	3.62103
2397.67	3.12946
2400.47	3.86879
2403.27	4.13676
2406.07	5.34556
2408.87	4.68933
2411.67	5.98195
2414.46	6.46068
2417.26	7.76306
2420.05	8.37755
2422.84	8.13642
2425.64	8.64784
2428.43	8.91929
2431.22	8.35779
2434.01	8.22081
2436.79	7.56286
2439.58	7.01135
2442.37	6.24714
2445.15	6.63861
2447.93	6.92045
2450.72	5.9973
2453.5	5.68189
2456.28	5.41123
2459.06	5.64904
2461.84	5.86688
2464.62	5.32265
2467.39	6.31199
2470.17	7.44183
2472.94	7.77127
2475.72	7.37359
2478.49	7.63927
2481.26	8.08779
2484.03	7.82568
2486.8	8.82142
2489.57	8.65751
2492.34	8.36767
2495.1	8.11039
2497.87	8.6197
2500.63	8.82043
2503.4	8.01117
2506.16	7.39982
2508.92	6.80576
2511.68	7.15278
2514.44	6.4793
2517.2	5.68932
2519.96	5.26915
2522.72	4.83728
2525.47	4.28941
2528.23	4.92595
2530.98	5.41011
2533.74	5.56595
2536.49	5.3152
2539.24	4.62266
2541.99	3.66591
2544.74	3.75177
2547.49	3.45175
2550.23	3.13366
2552.98	2.58672
2555.72	2.59574
2558.47	2.10495
2561.21	1.14962
2563.95	1.4268
2566.69	2.20487
2569.43	1.23809
2572.17	1.73122
2574.91	1.68466
2577.65	2.39085
2580.39	2.89598
2583.12	3.08181
2585.85	3.03899
2588.59	3.15035
2591.32	4.45931
2594.05	5.48548
2596.78	5.30262
2599.51	4.70908
2602.24	4.42715
2604.97	5.17618
2607.69	4.42186
2610.42	4.60633
2613.14	4.38901
2615.87	3.51813
2618.59	2.43977
2621.31	2.303
2624.03	1.82138
2626.75	2.87491
2629.47	2.26787
2632.19	3.35852
2634.91	3.53371
2637.62	4.34875
2640.34	5.51265
2643.05	5.57324
2645.76	6.41788
2648.48	6.2362
2651.19	7.0882
2653.9	7.29633
2656.6	7.45265
2659.31	7.68762
2662.02	7.55277
2664.73	7.81091
2667.43	8.68521
2670.14	8.59843
2672.84	8.72237
2675.54	8.64425
2678.24	8.88035
2680.94	7.79394
2683.64	7.88631
2686.34	7.63439
2689.04	9.17847
2691.74	8.87883
2694.43	7.95929
2697.13	6.64011
2699.82	6.44611
2702.51	6.25437
2705.21	7.06909
2707.9	5.43197
2710.58	5.29216
2713.27	5.30579
2715.96	5.29042
2718.65	5.25648
2721.33	6.33948
2724.02	5.5488
2726.71	5.74748
2729.39	5.66965
2732.07	6.12752
2734.75	6.06471
2737.43	6.09394
2740.11	6.43479
2742.79	6.44106
2745.47	5.39809
2748.14	5.84525
2750.82	6.07405
2753.49	5.32334
2756.17	4.6863
2758.84	3.43292
2761.51	2.32638
2764.18	2.01351
2766.85	2.07534
2769.52	1.54378
2772.19	0.497051
2774.86	-0.0702266
2777.52	-0.00701095
2780.19	-0.142291
2782.85	0.249371
2785.52	0.544714
2788.18	1.07739
2790.84	0.580171
2793.5	0.698716
2796.16	0.952351
2798.82	1.55776
2801.48	1.51416
2804.13	1.31948
2806.79	1.10822
2809.45	0.224384
2812.1	0.16553
2814.75	0.195697
2817.41	-0.121054
2820.06	0.22677
2822.71	2.40121
2825.36	4.59734
2828	7.71686
2830.65	11.2222
2833.3	15.4909
2835.94	19.9204
2838.59	23.7554
2841.23	29.115
2843.87	34.6116
2846.52	41.6637
2849.16	49.4439
2851.8	57.3569
2854.44	66.283
2857.08	73.6409
2859.71	80.7235
2862.35	87.3912
2864.98	94.5125
2867.62	100.25
2870.25	106.041
2872.88	110.927
2875.52	115.334
2878.15	118.994
2880.78	121.96
2883.41	124.683
2886.03	128.359
2888.66	131.285
2891.29	135.51
2893.91	139.171
2896.54	143.498
2899.16	147.181
2901.78	152.584
2904.4	158.621
2907.02	166.229
2909.64	173.945
2912.26	183.016
2914.88	191.256
2917.5	199.387
2920.11	206.269
2922.73	211.87
2925.34	216.283
2927.96	220.108
2930.57	221.531
2933.18	221.036
2935.79	219.507
2938.4	216.3
2941.01	210.661
2943.62	204.441
2946.22	196.75
2948.83	189.884
2951.43	181.747
2954.04	173.533
2956.64	164.932
2959.24	157.105
2961.84	148.622
2964.45	140.993
2967.05	133.034
2969.64	125.491
2972.24	118.193
2974.84	110.615
2977.43	103.202
2980.03	95.641
2982.62	87.8303
2985.22	80.3892
2987.81	72.117
2990.4	63.6271
2992.99	56.7749
2995.58	49.5005
2998.17	41.4433
3000.76	35.2737
3003.34	28.723
3005.93	24.1391
3008.52	19.0563
3011.1	14.9206
3013.68	11.7044
3016.27	7.915
3018.85	5.63194
3021.43	3.45756
3024.01	2.74492
3026.59	2.36651
3029.16	2.38979
3031.74	3.09233
3034.32	3.75161
3036.89	4.65235
3039.47	5.60418
3042.04	7.5436
3044.61	8.38414
3047.18	9.2395
3049.75	10.3082
3052.32	9.89747
3054.89	9.85626
3057.46	10.0148
3060.03	8.46981
3062.59	7.96367
3065.16	7.45969
3067.72	6.15716
3070.29	4.92917
3072.85	2.78057
3075.41	2.06612
3077.97	0.620784
3080.53	0.30375
3083.09	0.165646
3085.65	0.617203
3088.21	1.66504
3090.76	3.03648
3093.32	4.3217
3095.87	5.3764
3098.43	6.6994
3100.98	8.52311
3103.53	10.9043
3106.08	12.537
3108.63	14.3794
3111.18	16.0369
3113.73	16.6708
3116.28	18.3816
3118.83	20.9163
3121.37	22.5967
3123.92	24.0816
3126.46	26.0735
3129	27.7851
3131.55	29.6931
3134.09	31.5356
3136.63	33.6656
3139.17	36.6865
3141.71	39.4751
3144.24	42.5807
3146.78	46.1415
3149.32	49.6902