File: data/Raman/poly_smoothed/Thy_20_09_20_1x_45s_532 nm_x100_100%_600 gr_mm_01.txt
#Acq. time (s)=	45
#Accumulations=	2
#Range (cm-¹)=	200...3150
#Windows=	2
#Auto scanning=	Off
#Autofocus=	Off
#Macrospot=	Off
#AutoExposure=	Off
#Spike filter=	Multiple accum.
#Delay time (s)=	0
#Binning=	1
#Readout mode=	Signal
#DeNoise=	Off
#ICS correction=	On
#Dark correction=	Off
#Inst. Process=	Off
#Detector Gain=	Best Dynamic Range
#Detector ADC=	20 kHz
#Detector temperature (°C)=	-69.85
#Instrument=	LabRAM HR Evol
#Detector=	Synapse
#Objective=	x100
#Grating=	600 gr/mm
#ND Filter=	100%
#Laser (nm)=	532
#Hole=	100.021
#Range=	Auto
#Laser Pol.=	No
#Raman. Pol.=	No
#Laser Pol. (°)=	-0.0007625
#Raman Pol. (°)=	89.9995
#Collection=	Microscope
#StageXY=	Marzhauser
#StageZ=	Marzhauser
#X (µm)=	-5898.9
#Y (µm)=	2880.6
#Z (µm)=	-223.6
#Full time(mm:ss)=	3:18
#Project=
#Sample=
#Site=
#Title=	Thy_20_09_20_2x_45s_532 nm_x100_100%_600 gr_mm
#Remark=
#Date=	29.06.2022 12:05
#Acquired=	29.06.2022 12:05:22
#Base:Fit=	10.08.2022 09:52:02
#Base:Fit=	10.08.2022 09:52:12
#Base:Sub=	10.08.2022 09:54:21
#Filter:Polynom=	16.08.2022 10:24:04
#AxisType[0]=Intens
#AxisUnit[0]=Cnt
#AxisType[1]=Spectr
#AxisUnit[1]=1/cm
200.523	11.7267
204.154	14.7147
207.781	20.2904
211.409	25.7374
215.034	30.7961
218.659	34.7422
222.281	36.7529
225.903	37.6987
229.522	38.8691
233.14	41.4494
236.756	43.4231
240.373	44.0412
243.986	46.4685
247.598	47.5446
251.208	47.6664
254.818	47.8429
258.427	45.9699
262.034	45.884
265.638	47.4828
269.242	45.9393
272.844	44.0875
276.445	41.2295
280.044	41.9092
283.642	41.9343
287.238	40.2773
290.833	40.3082
294.425	39.4069
298.017	38.409
301.608	37.3178
305.198	31.836
308.786	29.0861
312.371	26.9674
315.956	26.9814
319.54	26.2514
323.122	24.6396
326.701	23.5753
330.281	22.1152
333.857	22.2683
337.434	20.7323
341.008	18.8447
344.582	16.3274
348.153	16.209
351.724	16.0843
355.292	12.9862
358.861	11.8604
362.426	11.6148
365.99	11.3293
369.555	14.2976
373.116	15.0986
376.676	15.9229
380.236	15.9972
383.793	16.9213
387.349	16.9529
390.903	16.1162
394.456	15.1797
398.007	14.221
401.56	14.5114
405.108	17.005
408.656	15.6056
412.202	15.005
415.746	13.6369
419.29	13.7587
422.831	11.7356
426.37	9.69966
429.909	8.72042
433.447	5.71913
436.983	3.79861
440.519	1.92803
444.052	1.15376
447.583	0.29013
451.114	1.46233
454.643	3.84623
458.169	5.76949
461.696	6.22692
465.222	5.82175
468.744	7.9519
472.267	9.13546
475.787	9.19076
479.307	6.51273
482.823	8.31767
486.341	9.68706
489.855	11.3733
493.37	11.2422
496.881	10.7155
500.391	11.1356
503.902	10.891
507.409	12.5163
510.915	11.7273
514.42	10.7214
517.925	11.0028
521.427	10.5448
524.928	10.4367
528.427	12.2759
531.925	11.9337
535.422	14.3056
538.917	15.256
542.411	16.7521
545.903	15.3781
549.395	15.9132
552.884	15.8694
556.373	15.8918
559.86	12.5422
563.346	10.546
566.831	11.0007
570.314	11.0018
573.794	7.96954
577.274	6.30754
580.754	6.14619
584.23	5.45924
587.706	4.44423
591.181	5.6712
594.653	2.98523
598.126	1.69796
601.595	1.97303
605.065	1.85301
608.532	1.8861
611.999	2.45917
615.463	3.96555
618.928	2.94821
622.389	3.58813
625.851	4.07832
629.31	5.14809
632.767	4.68647
636.223	6.47819
639.68	8.474
643.134	8.24772
646.586	9.9421
650.037	13.4221
653.486	16.0877
656.936	16.5726
660.383	18.2755
663.829	22.3491
667.273	25.9615
670.716	26.6495
674.158	26.4928
677.598	30.4743
681.035	30.0627
684.473	30.3736
687.909	32.648
691.344	34.2771
694.778	35.29
698.211	34.5298
701.64	35.0321
705.07	35.9075
708.498	36.2881
711.924	37.7666
715.35	39.289
718.774	42.5464
722.196	44.8408
725.618	48.7439
729.037	51.2887
732.456	55.1918
735.873	59.63
739.289	63.4184
742.703	67.2705
746.116	71.789
749.529	74.9433
752.938	80.5707
756.347	84.9182
759.756	88.5123
763.162	92.5912
766.567	95.2234
769.97	96.9356
773.372	100.989
776.773	102.342
780.174	105.373
783.573	109.091
786.97	113.404
790.365	116.488
793.76	120.99
797.153	124.902
800.543	129.273
803.933	135.456
807.322	139.926
810.71	142.32
814.097	144.574
817.483	148.313
820.865	148.1
824.248	148.982
827.629	147.972
831.008	144.693
834.387	144.57
837.765	141.228
841.139	136.757
844.514	130.945
847.886	126.292
851.259	123.21
854.629	119.577
857.997	115.018
861.366	112.063
864.732	106.92
868.098	106.351
871.461	104.5
874.823	102.986
878.184	100.601
881.545	100.608
884.903	99.1568
888.26	97.7847
891.616	95.7374
894.97	91.4997
898.323	91.5636
901.675	88.5961
905.026	85.2921
908.375	82.9575
911.723	79.8501
915.07	77.34
918.415	76.0272
921.76	71.6757
925.103	69.0999
928.443	68.7446
931.783	68.3283
935.123	67.0186
938.461	63.9804
941.796	62.0879
945.131	57.29
948.465	55.4648
951.797	55.6637
955.128	54.6939
958.457	51.9915
961.786	47.4506
965.113	45.9903
968.44	44.199
971.763	41.1566
975.086	39.6495
978.409	39.3875
981.729	38.0432
985.048	36.9387
988.367	33.9324
991.683	32.3192
994.998	30.3187
998.312	32.4362
1001.62	30.1147
1004.94	29.8245
1008.25	30.8841
1011.56	29.1575
1014.86	28.7326
1018.17	27.5523
1021.48	24.491
1024.78	22.623
1028.08	22.5354
1031.38	22.6966
1034.68	22.4802
1037.98	19.945
1041.28	16.6937
1044.57	15.4426
1047.87	16.9543
1051.16	15.9696
1054.45	16.0481
1057.75	15.4533
1061.04	14.9996
1064.32	15.9202
1067.61	14.5376
1070.9	15.155
1074.18	17.7137
1077.47	20.4397
1080.75	19.9005
1084.03	16.5247
1087.31	15.4984
1090.59	14.1875
1093.86	13.5689
1097.14	13.9205
1100.41	14.0846
1103.69	14.1132
1106.96	12.7743
1110.23	13.3419
1113.5	13.0114
1116.77	11.5489
1120.03	10.8024
1123.3	11.0831
1126.56	11.4697
1129.83	11.6888
1133.09	8.00472
1136.35	8.06174
1139.61	5.95406
1142.86	8.78205
1146.12	7.82953
1149.38	5.64273
1152.63	5.82265
1155.88	4.50719
1159.14	3.04422
1162.39	0.429274
1165.63	1.45755
1168.88	0.308253
1172.13	1.69389
1175.38	2.16224
1178.62	1.95553
1181.86	5.25579
1185.1	4.65902
1188.34	7.51337
1191.58	10.0611
1194.82	9.96648
1198.06	11.7478
1201.29	15.7416
1204.53	18.4078
1207.76	21.9491
1210.99	25.1583
1214.22	28.4167
1217.45	30.6663
1220.68	32.4831
1223.91	34.7691
1227.13	37.0757
1230.36	39.1728
1233.58	41.8224
1236.8	42.4351
1240.02	43.7648
1243.24	46.0692
1246.46	46.2584
1249.67	48.2162
1252.89	50.1929
1256.1	50.1644
1259.32	51.0278
1262.53	51.4937
1265.74	51.1863
1268.95	50.8707
1272.15	52.5939
1275.36	53.4369
1278.57	54.1085
1281.77	58.486
1284.97	59.271
1288.18	61.836
1291.38	63.8424
1294.58	64.228
1297.78	66.0256
1300.97	67.6317
1304.17	70.2115
1307.36	71.6887
1310.55	72.4735
1313.75	72.9727
1316.94	73.8863
1320.13	77.7441
1323.32	78.2422
1326.5	78.3743
1329.69	79.217
1332.87	77.2823
1336.06	76.6211
1339.24	75.1741
1342.42	73.876
1345.6	71.4916
1348.78	68.9959
1351.96	64.4495
1355.13	63.1603
1358.31	61.9537
1361.48	59.7715
1364.65	57.4111
1367.82	55.0777
1370.99	52.6414
1374.16	50.5878
1377.33	50.0654
1380.5	44.6769
1383.66	41.0843
1386.83	36.9387
1389.99	35.9845
1393.15	34.5323
1396.31	33.6142
1399.47	31.7428
1402.63	30.9474
1405.78	30.2071
1408.94	31.9444
1412.1	33.0431
1415.25	34.8235
1418.4	39.472
1421.55	42.4402
1424.7	45.2969
1427.85	50.5968
1431	54.7942
1434.14	61.4063
1437.29	65.1956
1440.43	68.2694
1443.57	68.4772
1446.71	69.5178
1449.85	70.4896
1452.99	70.3149
1456.13	67.4165
1459.26	62.8119
1462.4	61.2231
1465.54	57.0717
1468.67	51.6314
1471.8	46.3692
1474.93	42.1552
1478.06	36.7133
1481.19	31.2661
1484.31	26.628
1487.44	22.7073
1490.56	18.5738
1493.69	16.0682
1496.81	12.6282
1499.93	11.35
1503.05	10.2443
1506.17	9.89196
1509.28	10.0881
1512.4	10.807
1515.52	11.6566
1518.63	13.5662
1521.74	15.1449
1524.85	19.1851
1527.96	20.842
1531.07	22.5171
1534.18	23.7082
1537.29	26.0261
1540.39	28.9976
1543.5	29.2576
1546.6	30.4942
1549.7	34.4098
1552.8	36.0797
1555.9	39.2894
1559	42.5911
1562.1	43.5889
1565.19	45.401
1568.29	48.2572
1571.38	50.099
1574.47	53.512
1577.56	54.856
1580.66	59.6735
1583.74	61.9229
1586.83	64.8487
1589.92	65.5563
1593.01	66.8875
1596.09	67.8401
1599.17	67.8274
1602.25	65.3884
1605.34	62.6423
1608.41	61.1148
1611.49	59.3446
1614.57	56.8666
1617.65	55.5673
1620.72	52.5952
1623.79	52.2285
1626.87	52.1567
1629.94	51.7603
1633.01	51.2548
1636.08	49.6684
1639.15	51.4729
1642.21	53.8521
1645.28	54.8376
1648.34	57.1467
1651.41	58.9713
1654.47	60.8288
1657.53	61.4824
1660.59	59.3763
1663.65	57.0448
1666.71	55.2057
1669.76	53.9388
1672.82	51.6557
1675.87	48.3522
1678.93	44.6248
1681.98	40.7472
1685.03	36.401
1688.08	32.7375
1691.13	26.8083
1694.17	21.8077
1697.22	18.395
1700.27	14.643
1703.31	11.3922
1706.35	7.92646
1709.39	4.401
1712.43	4.29595
1715.47	4.91361
1718.51	4.48335
1721.55	2.92369
1724.58	3.74965
1727.62	2.37916
1730.65	2.77842
1733.68	1.97532
1736.72	1.73372
1739.74	2.50161
1742.77	1.85228
1745.8	3.16075
1748.83	3.82548
1751.85	4.33968
1754.88	4.34686
1757.9	4.40808
1760.92	4.96675
1763.95	5.01723
1766.96	3.36634
1769.98	5.08266
1773	6.00517
1776.02	6.5363
1779.03	6.51689
1782.05	4.65026
1785.06	5.89424
1788.07	7.21712
1791.08	6.07313
1794.09	6.02029
1797.1	4.67897
1800.11	5.21987
1803.12	4.50397
1806.12	5.05628
1809.12	5.34559
1812.13	4.28582
1815.13	4.51965
1818.13	4.41757
1821.13	3.82772
1824.13	4.0968
1827.13	3.47678
1830.12	3.01726
1833.12	2.73198
1836.11	2.41918
1839.1	2.4488
1842.09	3.98843
1845.09	5.25158
1848.08	5.47148
1851.06	5.83235
1854.05	5.90025
1857.04	6.60008
1860.02	6.53998
1863.01	6.29121
1865.99	6.25137
1868.97	6.23611
1871.95	6.99314
1874.93	8.28188
1877.91	8.23092
1880.89	7.87266
1882.46	7.38677
1885.45	7.66275
1888.43	7.71772
1891.42	7.40116
1894.41	7.41576
1897.39	6.79613
1900.37	6.9167
1903.36	6.90755
1906.34	7.37187
1909.32	9.1375
1912.29	9.69028
1915.27	9.83991
1918.25	9.12269
1921.23	9.38921
1924.2	9.75854
1927.17	10.8198
1930.15	10.499
1933.12	9.95412
1936.09	9.3092
1939.06	8.46429
1942.02	7.24126
1944.99	7.14544
1947.96	6.49726
1950.92	5.36856
1953.88	5.39836
1956.85	6.38686
1959.81	5.55821
1962.77	4.50351
1965.73	2.81598
1968.69	3.04996
1971.64	3.48507
1974.6	3.18692
1977.55	2.23444
1980.51	0.967854
1983.46	1.89229
1986.41	2.07893
1989.36	2.4702
1992.31	4.53705
1995.26	5.12121
1998.21	5.82016
2001.15	5.60773
2004.1	4.577
2007.04	3.29475
2009.99	2.53987
2012.93	2.78653
2015.87	4.67223
2018.81	4.48043
2021.75	5.33833
2024.68	5.9741
2027.62	6.81708
2030.56	5.84166
2033.49	7.45004
2036.42	7.63914
2039.36	8.34
2042.29	10.0091
2045.22	12.4293
2048.14	13.9394
2051.07	16.3548
2054	16.3557
2056.93	18.346
2059.85	19.1883
2062.77	20.7227
2065.7	21.8881
2068.62	21.0369
2071.54	21.6169
2074.46	22.7167
2077.38	23.0699
2080.29	23.5987
2083.21	23.3352
2086.12	23.7513
2089.04	22.2775
2091.95	21.3675
2094.86	20.6792
2097.77	19.3232
2100.68	20.5778
2103.59	21.4553
2106.5	22.898
2109.41	23.8208
2112.31	23.811
2115.21	25.3685
2118.12	26.2533
2121.02	25.4939
2123.92	26.0688
2126.82	26.8722
2129.72	29.1159
2132.62	31.3666
2135.51	31.9897
2138.41	32.7913
2141.31	34.8238
2144.2	37.3794
2147.09	39.9488
2149.98	40.8252
2152.87	43.8669
2155.76	46.5632
2158.65	49.1357
2161.54	49.3612
2164.43	51.8223
2167.31	52.3433
2170.2	56.0291
2173.08	58.5342
2175.96	59.4372
2178.84	59.3771
2181.72	58.0198
2184.6	57.7267
2187.48	55.7737
2190.36	54.3421
2193.23	54.7007
2196.11	51.8456
2198.98	49.7355
2201.85	49.5192
2204.72	47.4768
2207.59	45.3302
2210.46	45.0234
2213.33	43.1355
2216.2	42.2358
2219.07	40.8486
2221.93	40.7895
2224.8	39.5292
2227.66	38.1068
2230.52	36.4792
2233.39	35.2689
2236.25	33.3886
2239.1	33.4972
2241.96	34.3245
2244.82	33.0745
2247.68	32.4044
2250.53	31.3249
2253.38	31.0544
2256.24	31.0834
2259.09	30.1788
2261.94	31.8435
2264.79	31.7431
2267.64	33.2448
2270.49	32.3631
2273.33	34.6496
2276.18	34.3723
2279.02	32.8682
2281.87	31.7819
2284.71	30.2359
2287.55	30.2979
2290.39	28.7997
2293.23	26.8039
2296.07	27.1998
2298.91	26.1921
2301.74	26.1721
2304.58	25.4893
2307.41	26.0679
2310.25	27.1117
2313.08	26.675
2315.91	26.552
2318.74	25.5099
2321.57	25.7891
2324.4	27.4626
2327.23	26.838
2330.05	27.092
2332.88	26.6761
2335.7	26.245
2338.52	25.0031
2341.35	25.0489
2344.17	24.6096
2346.99	21.2959
2349.81	19.8597
2352.62	19.2035
2355.44	17.434
2358.26	16.323
2361.07	15.5752
2363.89	15.8976
2366.7	15.6004
2369.51	16.2794
2372.32	16.4199
2375.13	15.7641
2377.94	16.7082
2380.75	16.5256
2383.56	16.2897
2386.36	15.9991
2389.17	16.62
2391.97	18.2302
2394.77	18.449
2397.58	18.1008
2400.38	18.7358
2403.18	19.5401
2405.97	19.62
2408.77	19.0134
2411.57	19.4432
2414.37	18.3924
2417.16	19.8922
2419.95	20.0257
2422.75	19.8288
2425.54	18.9031
2428.33	18.3276
2431.12	17.6678
2433.91	16.7461
2436.7	16.684
2439.48	14.5318
2442.27	14.0573
2445.05	15.5968
2447.84	14.9564
2450.62	15.606
2453.4	14.5149
2456.18	14.7845
2458.96	15.8503
2461.74	15.8794
2464.52	15.5316
2467.29	15.6185
2470.07	15.6358
2472.85	15.1424
2475.62	14.4412
2478.39	13.6725
2481.16	12.1187
2483.93	10.3161
2486.7	11.1006
2489.47	8.09387
2492.24	7.22023
2495.01	6.11871
2497.77	4.62233
2500.54	3.99914
2503.3	3.10481
2506.06	3.2539
2508.83	3.57164
2511.59	4.70346
2514.35	5.78175
2517.11	5.52899
2519.86	6.6329
2522.62	8.51877
2525.38	10.7542
2528.13	11.6859
2530.89	12.4297
2533.64	14.5528
2536.39	15.1982
2539.14	15.1585
2541.89	14.8075
2544.64	12.9174
2547.39	12.5736
2550.14	11.2449
2552.88	11.798
2555.63	12.4938
2558.37	11.9822
2561.11	11.7346
2563.86	11.6821
2566.6	8.39505
2569.34	7.19749
2572.08	5.35813
2574.82	3.58854
2577.55	3.37269
2580.29	2.64198
2583.02	2.54402
2585.76	2.15648
2588.49	3.04024
2591.22	3.26933
2593.96	3.51426
2596.69	3.67788
2599.42	2.89656
2602.14	3.65091
2604.87	1.87462
2607.6	0.255988
2610.32	0.812179
2613.05	1.11516
2615.77	1.93577
2618.49	2.29356
2621.22	4.4272
2623.94	4.61124
2626.66	4.56156
2629.37	4.79854
2632.09	4.28013
2634.81	2.51677
2637.53	2.88885
2640.24	3.63759
2642.96	5.49837
2645.67	6.58364
2648.38	6.78475
2651.09	8.30284
2653.8	8.71853
2656.51	8.57756
2659.22	8.99698
2661.93	8.99568
2664.63	8.32177
2667.34	7.25857
2670.04	7.43057
2672.75	6.39033
2675.45	7.4236
2678.15	7.66952
2680.85	8.24159
2683.55	7.60154
2686.25	7.08134
2688.94	6.48854
2691.64	7.06952
2694.34	5.46921
2697.03	5.03663
2699.73	4.37199
2702.42	5.17419
2705.11	4.80631
2707.8	5.22245
2710.49	5.10986
2713.18	5.03952
2715.87	5.4358
2718.55	6.66342
2721.24	8.18803
2723.93	8.79922
2726.61	9.76225
2729.29	10.2691
2731.98	10.5792
2734.66	11.2912
2737.34	12.4557
2740.02	13.6973
2742.7	13.3111
2745.37	12.4603
2748.05	12.7073
2750.72	12.1343
2753.4	11.5788
2756.07	10.5637
2758.75	9.02277
2761.42	6.81277
2764.09	4.3605
2766.76	3.22808
2769.43	1.32236
2772.1	0.891004
2774.76	1.16461
2777.43	0.730491
2780.1	0.32151
2782.76	0.7185
2785.42	1.44513
2788.09	2.64513
2790.75	2.25788
2793.41	2.38768
2796.07	1.24378
2798.73	0.0371481
2801.39	1.22983
2804.04	2.26162
2806.7	2.58335
2809.35	3.21365
2812.01	3.62585
2814.66	4.49324
2817.31	4.8922
2819.96	5.00588
2822.61	5.52324
2825.26	6.85083
2827.91	10.3059
2830.56	13.2626
2833.21	16.4545
2835.85	19.9727
2838.5	24.5569
2841.14	27.0182
2843.78	32.3964
2846.42	37.7604
2849.06	42.7816
2851.71	48.897
2854.34	53.6976
2856.98	58.5848
2859.62	65.2089
2862.26	69.5985
2864.89	74.9883
2867.53	80.2756
2870.16	85.9264
2872.79	91.6889
2875.42	95.4406
2878.05	97.4227
2880.68	101.854
2883.31	104.861
2885.94	108.296
2888.57	113.226
2891.19	117.155
2893.82	118.597
2896.44	121.234
2899.07	125.118
2901.69	128.749
2904.31	132.904
2906.93	137.786
2909.55	144.031
2912.17	150.824
2914.79	157.001
2917.41	164.289
2920.02	169.736
2922.64	173.922
2925.25	176.327
2927.86	178.173
2930.48	179.996
2933.09	181.038
2935.7	180.747
2938.31	178.155
2940.92	174.988
2943.53	170.799
2946.13	166.394
2948.74	161.733
2951.34	155.94
2953.95	150.85
2956.55	144.09
2959.15	137.132
2961.75	131.779
2964.35	126.424
2966.95	119.931
2969.55	115.981
2972.15	112.135
2974.75	107.622
2977.34	103.129
2979.94	97.5897
2982.53	90.9664
2985.13	84.0164
2987.72	78.3811
2990.31	72.3043
2992.9	65.6213
2995.49	60.0669
2998.08	53.7814
3000.67	47.623
3003.25	42.6496
3005.84	39.0626
3008.42	34.7076
3011.01	30.8758
3013.59	28.1255
3016.17	26.3066
3018.76	23.5208
3021.34	20.8521
3023.92	19.3291
3026.49	19.5052
3029.07	19.065
3031.65	19.376
3034.23	19.2317
3036.8	20.2192
3039.38	20.3807
3041.95	20.8612
3044.52	20.4433
3047.09	21.462
3049.66	22.9377
3052.23	22.8444
3054.8	22.8892
3057.37	23.6883
3059.94	23.6615
3062.5	24.6825
3065.07	23.8241
3067.63	22.7256
3070.2	21.0559
3072.76	19.9334
3075.32	18.9126
3077.88	17.5756
3080.44	15.994
3083	14.5123
3085.56	14.1706
3088.12	12.7483
3090.67	11.3442
3093.23	9.25347
3095.78	8.13363
3098.34	6.41836
3100.89	5.40589
3103.44	5.18675
3105.99	3.96373
3108.54	3.48357
3111.09	3.20033
3113.64	2.6171
3116.19	1.95215
3118.74	2.4588
3121.28	1.28554
3123.83	1.03475
3126.37	0.18186
3128.91	-1.60282
3131.46	-2.16012
3134	-1.16937
3136.54	-1.56323
3139.08	-0.695559
3141.62	-1.92898
3144.16	-2.74782
3146.69	-4.78269
3149.23	-6.1874