File: data/Raman/poly_smoothed/Thy_40_11_13_1x_45s_532 nm_x100_100%_600 gr_mm_01.txt
#Acq. time (s)=	45
#Accumulations=	2
#Range (cm-¹)=	200...3150
#Windows=	2
#Auto scanning=	Off
#Autofocus=	Off
#Macrospot=	Off
#AutoExposure=	Off
#Spike filter=	Multiple accum.
#Delay time (s)=	0
#Binning=	1
#Readout mode=	Signal
#DeNoise=	Off
#ICS correction=	On
#Dark correction=	Off
#Inst. Process=	Off
#Detector Gain=	Best Dynamic Range
#Detector ADC=	20 kHz
#Detector temperature (°C)=	-69.85
#Instrument=	LabRAM HR Evol
#Detector=	Synapse
#Objective=	x100
#Grating=	600 gr/mm
#ND Filter=	100%
#Laser (nm)=	532
#Hole=	100.021
#Range=	Auto
#Laser Pol.=	No
#Raman. Pol.=	No
#Laser Pol. (°)=	-0.0007625
#Raman Pol. (°)=	89.9995
#Collection=	Microscope
#StageXY=	Marzhauser
#StageZ=	Marzhauser
#X (µm)=	1961.9
#Y (µm)=	-59.5
#Z (µm)=	425.3
#Full time(mm:ss)=	3:18
#Project=
#Sample=
#Site=
#Title=	Thy_40_11_13_2x_45s_532 nm_x100_100%_600 gr_mm
#Remark=
#Date=	05.07.2022 10:47
#Acquired=	05.07.2022 10:47:53
#Base:Fit=	10.08.2022 10:01:35
#Base:Sub=	10.08.2022 10:01:52
#Filter:Polynom=	16.08.2022 10:21:53
#AxisType[0]=Intens
#AxisUnit[0]=Cnt
#AxisType[1]=Spectr
#AxisUnit[1]=1/cm
200.43	24.6204
204.059	18.4035
207.688	13.8288
211.314	10.8856
214.941	8.89215
218.564	6.46963
222.186	4.81724
225.809	4.24636
229.428	3.31589
233.045	2.60072
236.663	0.73652
240.278	-0.078261
243.891	-0.0340017
247.503	1.09437
251.116	1.80958
254.725	2.56211
258.333	4.36015
261.939	3.94869
265.544	3.89249
269.148	4.16948
272.75	4.2827
276.351	5.22572
279.95	5.61592
283.548	5.69352
287.144	5.84669
290.739	5.64368
294.333	7.06645
297.925	7.99398
301.514	9.61501
305.104	10.9706
308.692	12.3654
312.279	14.3898
315.862	13.9305
319.446	14.8994
323.029	15.3886
326.608	14.5359
330.188	15.3571
333.766	17.1868
337.341	17.4722
340.917	17.9936
344.489	19.089
348.062	19.9291
351.631	17.6307
355.201	17.0824
358.768	16.7942
362.333	15.0944
365.899	15.293
369.462	13.9632
373.023	13.5354
376.585	11.9554
380.143	12.1378
383.7	12.5928
387.256	12.1553
390.812	12.6162
394.365	13.2918
397.916	13.1719
401.467	11.4683
405.015	9.69766
408.563	8.47164
412.109	8.17006
415.654	7.29613
419.197	8.02734
422.739	7.55635
426.279	6.50827
429.819	5.64206
433.356	5.45598
436.891	4.88925
440.426	3.05156
443.96	3.30442
447.492	4.54594
451.021	3.52493
454.551	3.98095
458.079	4.99605
461.604	5.72665
465.13	5.94906
468.654	7.61996
472.175	9.70917
475.696	12.2281
479.215	14.1902
482.733	15.0506
486.249	15.9932
489.765	16.1279
493.278	18.1655
496.789	21.1026
500.301	22.6773
503.81	23.5376
507.317	24.2782
510.825	23.07
514.33	24.0001
517.833	24.9971
521.335	24.1939
524.836	23.5164
528.335	21.6815
531.835	20.29
535.332	17.8968
538.827	15.789
542.321	14.1495
545.814	11.9224
549.305	11.5638
552.795	8.91344
556.282	7.9097
559.769	7.43748
563.255	5.88594
566.739	4.52158
570.223	4.19594
573.705	3.27023
577.183	3.14406
580.663	3.53914
584.141	3.86655
587.615	2.86935
591.09	1.75174
594.564	3.27648
598.035	3.12822
601.506	4.27206
604.974	5.10865
608.443	5.65781
611.908	6.33274
615.374	6.64245
618.837	7.3518
622.3	7.89749
625.761	8.96403
629.219	9.74148
632.677	10.8301
636.135	11.9171
639.59	13.583
643.043	17.1236
646.495	18.9715
649.948	20.1101
653.398	22.2439
656.846	24.6572
660.293	24.298
663.738	26.2102
667.183	25.4314
670.626	25.0777
674.067	25.4747
677.508	27.3029
680.947	29.9446
684.385	32.4941
687.821	33.1278
691.254	34.8368
694.688	34.6747
698.121	36.5841
701.552	37.7866
704.98	37.9191
708.409	38.5931
711.836	40.4716
715.26	41.0052
718.685	42.6305
722.108	43.7116
725.528	45.5099
728.949	47.1697
732.367	49.1348
735.785	51.4752
739.2	53.1989
742.614	54.4823
746.028	55.7415
749.439	58.8098
752.849	61.1191
756.26	64.3192
759.667	67.3918
763.073	72.3331
766.477	73.0272
769.883	73.5792
773.285	76.0087
776.686	77.6116
780.085	79.6858
783.484	82.0692
786.881	82.2122
790.276	81.7862
793.671	83.0747
797.064	84.188
800.456	84.1642
803.846	84.9447
807.234	85.4559
810.622	86.1167
814.008	87.6707
817.394	87.4633
820.778	87.447
824.159	88.2154
827.541	88.0052
830.921	88.5612
834.298	88.324
837.676	87.1816
841.051	84.0552
844.426	81.5405
847.798	77.1147
851.171	74.923
854.54	75.8224
857.911	73.7514
861.278	70.1709
864.645	66.8198
868.01	63.9366
871.373	61.4966
874.735	60.5672
878.097	60.4115
881.457	59.1953
884.815	57.1007
888.172	55.6726
891.528	53.9227
894.882	54.9113
898.237	53.173
901.589	52.0213
904.94	53.285
908.289	53.0149
911.635	51.6203
914.982	50.1505
918.328	47.2711
921.672	46.9476
925.015	45.9182
928.357	46.7799
931.698	47.6265
935.035	46.3741
938.373	46.2146
941.71	43.3651
945.044	41.7004
948.378	42.2302
951.709	44.4331
955.041	44.3845
958.372	41.888
961.699	41.6064
965.027	41.9079
968.352	42.2558
971.676	44.1948
975	44.588
978.322	45.8008
981.642	47.6563
984.962	49.3752
988.28	48.5182
991.596	48.7024
994.911	48.2933
998.227	48.5086
1001.54	48.7608
1004.85	48.8805
1008.16	51.2119
1011.47	50.1903
1014.78	49.0257
1018.08	48.8436
1021.39	50.7293
1024.69	50.2339
1028	53.0212
1031.3	52.0557
1034.6	49.9613
1037.9	46.4358
1041.19	44.1075
1044.49	44.8056
1047.78	45.1245
1051.08	42.9156
1054.37	40.3046
1057.66	38.286
1060.95	37.1313
1064.24	36.2008
1067.53	34.3789
1070.81	31.6001
1074.1	31.5354
1077.38	30.4412
1080.66	29.4902
1083.94	28.9399
1087.22	30.0204
1090.5	31.4286
1093.78	32.1034
1097.05	33.1326
1100.33	34.4345
1103.6	34.3895
1106.87	33.9422
1110.14	32.9063
1113.41	31.0365
1116.68	28.527
1119.95	26.7406
1123.21	25.6788
1126.48	24.8933
1129.74	21.8273
1133	18.9011
1136.26	17.2941
1139.52	17.0313
1142.78	15.8092
1146.04	14.5336
1149.29	13.3181
1152.55	11.5408
1155.8	10.2106
1159.05	7.45528
1162.3	6.47558
1165.55	4.89446
1168.8	4.11787
1172.05	5.59186
1175.29	5.99732
1178.54	6.7669
1181.78	7.86708
1185.02	7.96689
1188.26	9.77105
1191.5	12.1166
1194.74	12.7638
1197.97	14.4377
1201.21	17.8604
1204.44	19.9484
1207.68	21.9912
1210.91	24.934
1214.14	28.2775
1217.37	32.7993
1220.59	37.8215
1223.82	40.0738
1227.05	43.4988
1230.27	46.1457
1233.49	47.974
1236.72	51.0491
1239.94	54.0604
1243.16	55.8487
1246.37	58.3761
1249.59	62.4406
1252.8	64.6619
1256.02	66.2129
1259.23	67.7174
1262.44	69.1376
1265.66	70.5242
1268.86	72.3078
1272.07	74.7996
1275.28	75.0124
1278.48	75.8146
1281.69	76.5729
1284.89	78.7026
1288.09	80.2272
1291.29	81.1819
1294.49	82.6413
1297.69	85.068
1300.89	86.0358
1304.08	87.3857
1307.28	88.425
1310.47	90.2322
1313.66	93.0483
1316.85	93.426
1320.04	92.3437
1323.23	92.0112
1326.42	92.1811
1329.61	90.2254
1332.79	85.8513
1335.97	82.3699
1339.16	80.5035
1342.34	78.1645
1345.52	74.9604
1348.7	71.807
1351.87	67.8446
1355.05	64.1185
1358.22	61.7457
1361.4	58.5541
1364.57	55.6559
1367.74	52.7955
1370.91	50.8617
1374.08	48.1067
1377.25	47.5559
1380.41	47.9647
1383.58	47.5173
1386.74	46.2458
1389.91	46.4291
1393.07	47.1201
1396.23	45.815
1399.39	45.6094
1402.55	45.0562
1405.7	43.1367
1408.86	42.9054
1412.01	43.9927
1415.17	45.7231
1418.32	49.001
1421.47	51.9305
1424.62	55.0841
1427.77	59.9773
1430.91	65.6653
1434.06	71.5695
1437.2	75.969
1440.35	80.0599
1443.49	83.3445
1446.63	84.9238
1449.77	85.8199
1452.91	87.3202
1456.05	87.0152
1459.18	84.9671
1462.32	82.0896
1465.45	77.6676
1468.59	73.7108
1471.72	68.4707
1474.85	60.9305
1477.98	54.0461
1481.1	46.7946
1484.23	40.6059
1487.36	34.7012
1490.48	27.8461
1493.61	24.0294
1496.73	21.7559
1499.85	18.5058
1502.97	17.4568
1506.09	16.9574
1509.2	18.6475
1512.32	17.6979
1515.43	18.2084
1518.55	18.2709
1521.66	19.4018
1524.77	21.6617
1527.88	23.7703
1530.99	24.8455
1534.1	26.6304
1537.21	29.0382
1540.31	31.1867
1543.42	33.0953
1546.52	37.1101
1549.62	39.3878
1552.72	41.7182
1555.82	44.3268
1558.92	48.0812
1562.02	50.9653
1565.11	52.6806
1568.21	56.357
1571.3	59.7929
1574.39	62.7802
1577.49	65.59
1580.57	70.2971
1583.66	72.6018
1586.75	73.7649
1589.84	73.6956
1592.92	72.0572
1596.01	72.7357
1599.09	72.675
1602.17	72.0474
1605.25	70.2612
1608.33	68.9036
1611.41	69.0444
1614.49	68.5309
1617.57	69.3439
1620.64	69.6269
1623.72	70.9164
1626.79	71.8395
1629.86	75.4456
1632.93	78.7087
1636	82.6854
1639.07	85.5243
1642.13	88.6111
1645.2	92.4866
1648.26	95.7784
1651.33	98.4314
1654.39	100.224
1657.45	101.26
1660.51	100.378
1663.57	99.7346
1666.63	95.8298
1669.68	93.2876
1672.74	89.8519
1675.79	83.97
1678.85	78.5897
1681.9	72.5739
1684.95	65.6502
1688	58.9907
1691.05	52.1042
1694.09	44.3513
1697.14	37.845
1700.18	31.3193
1703.23	26.7018
1706.27	22.2795
1709.31	17.89
1712.35	13.9696
1715.39	10.5648
1718.43	8.58018
1721.47	7.53558
1724.5	6.53358
1727.54	5.6274
1730.57	5.36076
1733.61	6.47285
1736.64	7.01391
1739.67	6.90043
1742.7	6.00745
1745.72	6.65073
1748.75	7.27581
1751.77	7.46195
1754.8	7.23324
1757.82	6.31467
1760.84	6.03793
1763.87	5.38723
1766.89	4.14508
1769.91	2.25814
1772.92	1.75688
1775.94	1.23545
1778.95	1.36367
1781.97	0.958043
1784.98	0.947628
1787.99	0.450732
1791.01	-0.291555
1794.01	-0.0432904
1797.02	-0.290052
1800.03	0.199733
1803.04	0.044326
1806.04	0.556276
1809.05	1.04524
1812.05	0.9335
1815.05	0.0255674
1818.05	0.264253
1821.05	1.21449
1824.05	1.19424
1827.05	1.43857
1830.04	0.971673
1833.04	1.27552
1836.03	0.928607
1839.03	1.37762
1842.02	1.74857
1845.01	2.1047
1848	2.83435
1850.99	3.28241
1853.97	2.7984
1856.96	2.86588
1859.94	3.55968
1862.93	3.32349
1865.91	3.80288
1868.89	3.4545
1871.87	4.47931
1874.85	5.0574
1877.83	5.62668
1880.81	5.37029
1882.57	5.30428
1885.56	4.58414
1888.55	4.67731
1891.54	4.3961
1894.52	4.66958
1897.51	5.06139
1900.49	4.96043
1903.47	4.89316
1906.45	6.24976
1909.43	5.41648
1912.41	4.66253
1915.39	5.07017
1918.37	4.97124
1921.34	5.8814
1924.32	6.0835
1927.29	5.35847
1930.26	6.01068
1933.23	5.4913
1936.2	5.47921
1939.17	5.51732
1942.14	5.83844
1945.11	5.45671
1948.07	5.49949
1951.04	5.11454
1954	4.22404
1956.96	3.45076
1959.93	3.45931
1962.89	3.05358
1965.85	2.80617
1968.8	3.056
1971.76	2.30577
1974.72	1.05407
1977.67	1.0437
1980.63	0.187039
1983.58	-0.331449
1986.53	-0.43049
1989.48	-0.0333708
1992.43	0.134979
1995.38	0.872138
1998.32	1.18533
2001.27	0.374241
2004.22	1.06329
2007.16	0.640969
2010.1	1.01306
2013.04	0.775972
2015.98	1.39402
2018.92	3.16778
2021.86	3.59087
2024.8	3.77402
2027.74	4.48471
2030.67	5.14219
2033.61	5.1712
2036.54	4.51894
2039.47	5.50811
2042.4	5.7563
2045.33	6.52901
2048.26	7.74428
2051.19	8.42666
2054.12	8.44685
2057.04	8.90234
2059.97	9.82516
2062.89	10.3246
2065.81	11.5506
2068.73	13.0782
2071.65	14.5479
2074.57	15.2995
2077.49	17.0889
2080.41	18.1244
2083.32	20.3819
2086.24	22.1646
2089.15	25.0953
2092.07	26.5712
2094.98	27.5977
2097.89	29.7678
2100.8	31.5758
2103.71	33.9817
2106.61	35.5098
2109.52	38.8954
2112.43	41.762
2115.33	45.0123
2118.23	46.934
2121.13	49.8632
2124.04	52.2924
2126.94	56.3075
2129.83	59.7642
2132.73	64.6386
2135.63	68.1173
2138.53	71.7908
2141.42	76.2726
2144.31	80.3302
2147.21	84.1808
2150.1	89.3576
2152.99	94.0055
2155.88	98.2968
2158.77	101.833
2161.65	104.332
2164.54	107.473
2167.43	109.292
2170.31	110.393
2173.19	110.721
2176.07	111.186
2178.96	110.347
2181.84	108.555
2184.72	106.923
2187.59	105.052
2190.47	101.74
2193.35	97.4327
2196.22	94.2979
2199.09	89.8963
2201.97	85.2423
2204.84	80.2022
2207.71	75.7952
2210.58	70.8925
2213.45	66.9699
2216.31	62.5731
2219.18	59.3513
2222.05	56.706
2224.91	52.9418
2227.78	49.5134
2230.64	46.3305
2233.5	44.1921
2236.36	41.4624
2239.22	38.5701
2242.08	36.4012
2244.93	34.9112
2247.79	32.0649
2250.64	30.0463
2253.5	29.4028
2256.35	28.0562
2259.2	26.8715
2262.05	24.4161
2264.9	23.8888
2267.75	21.9248
2270.6	21.1235
2273.45	19.9261
2276.29	19.4118
2279.14	18.5664
2281.98	17.7774
2284.82	16.9561
2287.66	16.2472
2290.5	15.0684
2293.34	13.9461
2296.18	12.8557
2299.02	12.6153
2301.86	12.6601
2304.69	12.429
2307.53	11.1986
2310.36	11.2532
2313.19	12.4691
2316.02	11.4009
2318.85	10.4744
2321.68	10.1139
2324.51	10.5215
2327.34	9.02502
2330.16	8.53059
2332.99	7.16627
2335.81	6.561
2338.64	5.17792
2341.46	5.64797
2344.28	4.90861
2347.1	4.22263
2349.92	3.86645
2352.74	3.29978
2355.55	2.46985
2358.37	1.56494
2361.19	2.05673
2364	1.89925
2366.81	2.99764
2369.62	3.71031
2372.44	3.33011
2375.24	3.07539
2378.05	3.5985
2380.86	4.084
2383.67	5.05971
2386.47	4.41027
2389.28	4.30697
2392.08	5.90678
2394.89	5.4226
2397.69	5.86539
2400.49	5.87157
2403.29	5.90223
2406.09	6.42282
2408.88	7.24332
2411.68	8.41491
2414.48	7.58518
2417.27	8.31346
2420.06	7.76529
2422.86	7.90738
2425.65	7.23084
2428.44	8.10556
2431.23	7.89925
2434.02	6.2713
2436.81	5.14151
2439.59	4.71747
2442.38	5.22154
2445.16	4.64568
2447.95	4.76258
2450.73	4.29279
2453.51	4.43707
2456.29	3.83309
2459.07	3.97805
2461.85	4.16125
2464.63	4.11533
2467.4	3.8691
2470.18	4.51525
2472.95	5.3145
2475.73	5.13378
2478.5	5.44577
2481.27	5.2029
2484.04	4.69093
2486.81	4.26329
2489.58	2.61553
2492.35	2.19722
2495.12	2.04654
2497.88	1.82996
2500.65	0.636178
2503.41	0.0883679
2506.17	0.278936
2508.94	1.38126
2511.7	0.7149
2514.46	0.751383
2517.22	1.05243
2519.97	1.60614
2522.73	0.663758
2525.49	0.762696
2528.24	0.976492
2530.99	1.39692
2533.75	2.08593
2536.5	2.9539
2539.25	2.95229
2542	3.76646
2544.75	3.89595
2547.5	4.18331
2550.24	3.71135
2552.99	3.77721
2555.74	3.3621
2558.48	3.87608
2561.22	4.58702
2563.96	5.07818
2566.71	4.91586
2569.45	5.12351
2572.18	4.7173
2574.92	4.71296
2577.66	5.35641
2580.4	5.90268
2583.13	7.31615
2585.87	7.02855
2588.6	5.70829
2591.33	5.47511
2594.06	6.38466
2596.79	6.53696
2599.52	6.95643
2602.25	7.21493
2604.98	6.28512
2607.71	5.86157
2610.43	6.18183
2613.16	5.48143
2615.88	6.00742
2618.6	5.58629
2621.32	5.48598
2624.04	5.87505
2626.76	6.05625
2629.48	6.72842
2632.2	6.54145
2634.92	5.50365
2637.63	5.19587
2640.35	4.98144
2643.06	5.18517
2645.77	5.06355
2648.49	4.23783
2651.2	3.78726
2653.91	2.98508
2656.62	3.66262
2659.33	4.71786
2662.03	5.30896
2664.74	5.06879
2667.44	5.23695
2670.15	5.57637
2672.85	5.88694
2675.55	5.77518
2678.26	6.57197
2680.96	7.43455
2683.66	8.34625
2686.35	8.83964
2689.05	8.79372
2691.75	9.68709
2694.44	10.0409
2697.14	10.6605
2699.83	11.0473
2702.52	10.5952
2705.22	10.638
2707.91	10.5314
2710.6	11.0249
2713.29	10.881
2715.97	10.3999
2718.66	10.6133
2721.35	11.8525
2724.03	12.7343
2726.72	13.0865
2729.4	12.3774
2732.08	13.2696
2734.76	13.6752
2737.44	13.2234
2740.12	12.8856
2742.8	12.5605
2745.48	12.9202
2748.16	12.966
2750.83	12.2217
2753.51	10.7092
2756.18	10.2469
2758.85	10.3779
2761.53	9.20379
2764.2	8.38719
2766.87	7.05443
2769.54	5.08521
2772.2	3.96583
2774.87	2.37255
2777.54	1.90504
2780.2	1.07189
2782.87	1.5408
2785.53	2.80002
2788.19	2.68767
2790.85	2.08174
2793.51	3.09824
2796.17	3.7965
2798.83	5.06499
2801.49	4.85962
2804.15	4.9889
2806.8	5.77278
2809.46	5.2615
2812.11	5.53191
2814.76	5.32005
2817.42	6.24018
2820.07	7.95578
2822.72	10.3379
2825.37	13.0522
2828.02	14.8717
2830.66	18.4149
2833.31	21.8857
2835.96	25.6323
2838.6	31.0141
2841.24	36.8377
2843.89	43.1917
2846.53	50.555
2849.17	59.9753
2851.81	68.8956
2854.45	77.7835
2857.09	87.0898
2859.72	95.9632
2862.36	104.62
2865	112.524
2867.63	119.343
2870.26	124.997
2872.9	130.322
2875.53	136.089
2878.16	140.947
2880.79	146.563
2883.42	151.362
2886.05	156.149
2888.67	160.223
2891.3	164.689
2893.92	168.976
2896.55	174.692
2899.17	181.008
2901.79	188.378
2904.42	197.418
2907.04	208.633
2909.66	219.271
2912.27	231.423
2914.89	246.183
2917.51	258.345
2920.13	269.29
2922.74	279.575
2925.35	287.784
2927.97	293.203
2930.58	295.902
2933.19	297.057
2935.8	295.977
2938.41	293.727
2941.02	288.222
2943.63	281.623
2946.24	272.799
2948.84	263.09
2951.45	252.316
2954.05	241.566
2956.65	228.852
2959.26	216.812
2961.86	204.999
2964.46	193.045
2967.06	181.854
2969.66	171.077
2972.25	161.667
2974.85	151.841
2977.45	143.989
2980.04	135.638
2982.64	126.192
2985.23	117.094
2987.82	107.264
2990.41	96.7246
2993	86.9862
2995.59	77.982
2998.18	69.9522
3000.77	62.8166
3003.36	55.1462
3005.94	49.1378
3008.53	42.6191
3011.11	37.3052
3013.69	32.6237
3016.28	28.1694
3018.86	24.4368
3021.44	20.3143
3024.02	18.0888
3026.6	15.7451
3029.18	14.4148
3031.75	13.5472
3034.33	13.0358
3036.9	13.9962
3039.48	15.0408
3042.05	15.6442
3044.62	17.0776
3047.19	17.4851
3049.77	17.5203
3052.34	16.958
3054.9	16.7877
3057.47	17.0871
3060.04	16.5778
3062.61	15.9604
3065.17	14.2259
3067.74	12.9983
3070.3	11.5064
3072.86	8.94598
3075.42	7.56577
3077.99	6.00413
3080.54	4.5552
3083.1	2.40077
3085.66	1.60538
3088.22	0.0533765
3090.78	-0.205469
3093.33	-0.735352
3095.89	-0.165801
3098.44	0.439649
3100.99	0.592343
3103.54	0.798467
3106.1	1.04489
3108.65	0.448191
3111.2	-0.0165288
3113.74	0.231096
3116.29	0.171267
3118.84	1.11609
3121.38	1.54642
3123.93	0.908411
3126.47	1.75796
3129.01	2.2759
3131.56	2.37573
3134.1	2.784
3136.64	3.64207
3139.18	5.07465
3141.72	6.46472
3144.26	7.82788
3146.79	9.40436
3149.33	11.6813