File: data/Raman/poly_smoothed/Thy_00_07_5_1x_45s_532 nm_x100_100%_600 gr_mm_01.txt
#Acq. time (s)=	45
#Accumulations=	2
#Range (cm-¹)=	200...3150
#Windows=	2
#Auto scanning=	Off
#Autofocus=	Off
#Macrospot=	Off
#AutoExposure=	Off
#Spike filter=	Multiple accum.
#Delay time (s)=	0
#Binning=	1
#Readout mode=	Signal
#DeNoise=	Off
#ICS correction=	On
#Dark correction=	Off
#Inst. Process=	Off
#Detector Gain=	Best Dynamic Range
#Detector ADC=	20 kHz
#Detector temperature (°C)=	-69.85
#Instrument=	LabRAM HR Evol
#Detector=	Synapse
#Objective=	x100
#Grating=	600 gr/mm
#ND Filter=	100%
#Laser (nm)=	532
#Hole=	100.021
#Range=	Auto
#Laser Pol.=	No
#Raman. Pol.=	No
#Laser Pol. (°)=	-0.0007625
#Raman Pol. (°)=	89.9995
#Collection=	Microscope
#StageXY=	Marzhauser
#StageZ=	Marzhauser
#X (µm)=	9000.2
#Y (µm)=	-3097.9
#Z (µm)=	-55.3
#Full time(mm:ss)=	3:05
#Project=
#Sample=
#Site=
#Title=	Thy_00_07_5_2x_45s_532 nm_x100_100%_600 gr_mm
#Remark=
#Date=	28.06.2022 10:21
#Acquired=	28.06.2022 10:21:10
#Base:Fit=	10.08.2022 10:07:56
#Base:Sub=	10.08.2022 10:08:40
#Filter:Polynom=	16.08.2022 10:26:06
#AxisType[0]=Intens
#AxisUnit[0]=Cnt
#AxisType[1]=Spectr
#AxisUnit[1]=1/cm
200.407	28.5552
204.035	27.1667
207.665	23.219
211.291	19.4212
214.916	16.91
218.541	12.5516
222.163	10.3958
225.785	8.29996
229.404	7.01211
233.022	6.90821
236.638	5.27777
240.255	3.77161
243.868	2.94835
247.48	3.6209
251.091	4.12396
254.702	3.89163
258.31	5.30106
261.916	4.65585
265.521	5.1381
269.125	5.39511
272.727	6.77395
276.328	8.52334
279.927	9.61043
283.525	11.6525
287.121	12.652
290.716	12.2955
294.31	13.1044
297.9	14.2838
301.491	16.6688
305.081	16.7681
308.669	16.9315
312.256	20.7738
315.839	21.3044
319.423	22.272
323.006	21.7522
326.585	21.8825
330.165	21.9932
333.741	23.4865
337.318	21.6759
340.894	19.7519
344.466	19.6309
348.039	19.745
351.608	20.1284
355.176	22.3919
358.745	23.8876
362.31	26.2585
365.876	28.0125
369.439	28.8014
373	29.8089
376.56	30.5713
380.12	30.5289
383.677	29.9681
387.233	30.2249
390.787	28.7163
394.34	27.6174
397.894	26.5694
401.444	23.6516
404.993	20.4778
408.54	18.1229
412.086	15.9429
415.631	12.9064
419.174	10.6275
422.716	7.6718
426.257	3.80297
429.794	3.40064
433.332	1.70775
436.868	0.967197
440.403	2.91044
443.937	4.5776
447.468	7.13252
450.999	9.36025
454.528	11.8051
458.057	14.8166
461.582	17.199
465.107	16.6138
468.629	18.6745
472.152	20.9959
475.672	23.5541
479.192	25.0842
482.709	26.5159
486.226	27.5936
489.74	31.0064
493.255	34.4
496.767	36.941
500.277	39.7475
503.788	41.4529
507.295	41.7513
510.801	41.4144
514.308	40.0896
517.811	39.3281
521.313	37.3585
524.814	36.2471
528.313	33.4654
531.811	30.5835
535.308	27.5061
538.803	24.3078
542.297	22.6047
545.789	18.1663
549.281	12.978
552.771	10.1334
556.259	7.97133
559.747	5.74269
563.233	2.51411
566.717	2.51034
570.2	1.43509
573.68	2.55244
577.161	3.71864
580.64	4.40043
584.118	5.94868
587.593	6.42203
591.068	6.72581
594.54	8.17682
598.013	8.60928
601.484	8.60741
604.952	9.49969
608.421	8.25391
611.886	8.03347
615.35	6.58833
618.815	7.21691
622.276	5.92309
625.738	6.94903
629.197	6.04429
632.655	4.37607
636.113	3.55042
639.568	4.37379
643.021	4.23469
646.473	5.52343
649.924	6.3727
653.376	5.8682
656.824	6.44018
660.271	5.93983
663.716	5.07973
667.161	4.48195
670.604	4.63378
674.045	5.37529
677.486	7.34982
680.925	8.74197
684.361	9.89536
687.797	12.5908
691.232	14.2263
694.666	15.6197
698.099	15.4975
701.528	16.4488
704.958	17.0265
708.387	18.0372
711.814	19.5838
715.238	19.7092
718.663	22.208
722.084	23.6011
725.506	27.2085
728.925	28.8489
732.345	31.4234
735.761	34.9424
739.178	38.3737
742.592	43.0538
746.006	48.4491
749.417	55.4146
752.827	63.0273
756.236	70.0822
759.645	75.3748
763.051	80.5751
766.456	84.7738
769.859	90.4613
773.261	92.2784
776.664	92.5623
780.064	91.7462
783.462	89.0266
786.859	88.0209
790.255	85.0216
793.649	82.9241
797.042	79.4055
800.434	75.5206
803.823	72.5641
807.212	68.3664
810.6	64.4053
813.987	61.014
817.372	59.5321
820.754	58.3541
824.137	58.6182
827.519	58.3797
830.897	59.4258
834.276	59.0632
837.654	58.273
841.029	55.1728
844.404	54.6803
847.776	54.2892
851.149	54.3238
854.519	52.1832
857.889	51.1828
861.256	48.3605
864.622	46.6461
867.988	45.3789
871.351	44.7283
874.713	43.1295
878.074	42.1547
881.435	40.3568
884.794	37.6078
888.15	36.8476
891.506	34.7441
894.861	33.7783
898.214	34.4179
901.566	34.1862
904.916	35.3232
908.266	37.0627
911.614	37.8204
914.961	38.7399
918.306	39.608
921.651	39.4593
924.994	40.9381
928.336	40.4555
931.674	38.9984
935.014	39.1161
938.352	36.4451
941.687	35.0103
945.022	33.6333
948.357	31.476
951.688	30.627
955.02	27.6766
958.348	24.0404
961.678	19.4212
965.004	18.4533
968.331	19.1122
971.655	19.9492
974.979	19.8757
978.3	20.3809
981.62	21.4519
984.941	21.4825
988.259	22.5819
991.575	23.8602
994.89	25.5975
998.204	28.0626
1001.52	31.5177
1004.83	35.3538
1008.14	39.0684
1011.45	41.8195
1014.76	44.8549
1018.06	46.5375
1021.37	48.5672
1024.67	49.3438
1027.97	47.8111
1031.27	46.622
1034.57	44.9982
1037.87	40.434
1041.17	37.7527
1044.47	35.3984
1047.76	34.5646
1051.06	31.347
1054.35	27.0772
1057.64	24.0871
1060.93	21.8596
1064.22	20.2895
1067.5	19.4436
1070.79	19.0777
1074.08	20.9886
1077.36	21.4729
1080.64	23.5757
1083.92	24.9636
1087.2	25.4667
1090.48	27.1104
1093.76	28.2349
1097.03	28.7816
1100.31	30.5424
1103.58	30.505
1106.85	28.99
1110.12	27.2876
1113.39	25.6332
1116.66	22.8977
1119.93	19.4083
1123.19	17.4768
1126.46	15.6195
1129.72	13.5373
1132.98	12.3347
1136.24	11.4607
1139.5	13.0445
1142.76	14.1974
1146.01	12.8389
1149.27	13.6145
1152.53	11.9017
1155.78	10.6076
1159.03	9.43269
1162.28	8.58105
1165.53	7.52576
1168.78	7.9276
1172.02	8.74165
1175.27	9.57736
1178.51	10.0623
1181.76	10.4355
1185	8.88702
1188.24	8.65599
1191.48	7.86128
1194.71	9.28173
1197.95	8.82997
1201.19	8.93319
1204.42	10.2684
1207.65	12.3146
1210.88	15.6083
1214.12	19.1829
1217.35	22.9689
1220.57	26.8612
1223.8	29.8904
1227.03	33.2299
1230.25	36.1793
1233.47	38.2279
1236.69	40.4604
1239.92	42.2676
1243.13	45.1509
1246.35	46.4447
1249.57	47.8338
1252.78	47.5008
1256	47.4648
1259.21	46.7903
1262.42	45.5635
1265.63	44.1467
1268.84	42.1369
1272.05	40.7329
1275.26	39.656
1278.46	38.7903
1281.67	40.4467
1284.87	40.6995
1288.07	41.723
1291.27	41.9353
1294.47	44.8297
1297.67	47.9621
1300.87	50.631
1304.06	55.476
1307.26	58.3581
1310.45	61.7689
1313.64	66.8743
1316.83	69.5101
1320.02	72.427
1323.21	74.8987
1326.4	77.0618
1329.59	78.0323
1332.77	76.8422
1335.95	76.6483
1339.14	76.3377
1342.32	74.317
1345.5	71.8717
1348.67	69.6594
1351.85	67.9697
1355.03	65.6508
1358.2	63.8185
1361.38	60.5181
1364.55	57.5342
1367.72	55.0432
1370.89	54.9851
1374.06	54.2947
1377.23	53.8361
1380.39	53.7958
1383.56	54.3251
1386.72	53.4754
1389.89	52.8556
1393.05	52.8593
1396.21	51.1306
1399.37	49.0467
1402.52	47.7436
1405.68	48.8469
1408.84	48.2111
1411.99	48.5979
1415.15	52.249
1418.3	53.9112
1421.45	55.8738
1424.6	59.9256
1427.75	64.605
1430.89	69.7281
1434.04	72.768
1437.18	75.9955
1440.33	78.4579
1443.47	80.2669
1446.61	82.9156
1449.75	84.1554
1452.89	83.0897
1456.03	81.0139
1459.16	79.1932
1462.3	74.5753
1465.43	70.0969
1468.56	64.2388
1471.7	57.8346
1474.83	51.2911
1477.96	46.4243
1481.08	40.5412
1484.21	35.7381
1487.34	30.7711
1490.46	27.4679
1493.58	25.4194
1496.71	21.5953
1499.83	20.6375
1502.95	19.6014
1506.07	18.806
1509.18	17.319
1512.3	16.517
1515.41	16.0029
1518.53	17.4646
1521.64	19.327
1524.75	21.4956
1527.86	23.0531
1530.97	24.2669
1534.08	27.2113
1537.19	29.2863
1540.29	31.6437
1543.4	34.2745
1546.5	35.7533
1549.6	38.4543
1552.7	41.2011
1555.8	44.1967
1558.9	46.1483
1562	49.7893
1565.09	51.555
1568.19	54.4144
1571.28	56.9647
1574.37	57.9206
1577.47	60.4016
1580.56	60.6244
1583.64	61.6139
1586.73	63.1285
1589.82	63.686
1592.9	64.0101
1595.99	65.2447
1599.07	66.0568
1602.15	65.8004
1605.23	64.4134
1608.31	63.4196
1611.39	62.8869
1614.47	61.2591
1617.55	59.9609
1620.62	58.3688
1623.7	58.1412
1626.77	59.2795
1629.84	59.4406
1632.91	60.7402
1635.98	60.9164
1639.05	62.5377
1642.11	64.1694
1645.18	66.3362
1648.24	67.1932
1651.31	67.2116
1654.37	67.5586
1657.43	66.5796
1660.49	65.1237
1663.55	63.5025
1666.61	61.2784
1669.66	58.4714
1672.72	55.2493
1675.77	53.1122
1678.83	49.8481
1681.88	45.9078
1684.93	43.1021
1687.98	38.5286
1691.03	34.1831
1694.07	28.9608
1697.12	25.9579
1700.17	24.0908
1703.21	21.3147
1706.25	18.796
1709.29	16.3563
1712.33	15.2743
1715.37	14.9851
1718.41	13.1463
1721.45	11.5382
1724.49	10.3241
1727.52	8.75028
1730.55	7.6191
1733.59	7.12928
1736.62	6.85261
1739.65	7.03381
1742.68	7.36758
1745.7	7.22664
1748.73	7.85793
1751.76	9.43128
1754.78	8.64553
1757.8	8.55465
1760.83	8.28528
1763.85	6.85273
1766.87	6.56439
1769.89	5.83633
1772.9	6.06978
1775.92	5.89368
1778.94	4.82598
1781.95	3.56966
1784.96	2.75107
1787.97	3.0535
1790.99	1.40992
1794	1.62148
1797	1.95158
1800.01	1.88984
1803.02	1.99215
1806.02	2.81852
1809.03	2.80114
1812.03	3.18994
1815.03	3.46526
1818.03	4.12222
1821.03	4.51882
1824.03	4.50087
1827.03	4.1057
1830.02	3.75508
1833.02	4.14509
1836.01	4.19702
1839.01	3.97147
1842	4.08283
1844.99	2.83934
1847.98	1.8639
1850.97	1.85311
1853.95	1.40425
1856.94	0.847639
1859.93	0.994194
1862.91	0.826276
1865.89	1.05307
1868.87	1.17494
1871.85	0.709487
1874.83	1.07655
1877.81	1.02096
1880.79	0.885793
1882.52	0.285157
1885.51	-0.424321
1888.5	-0.149637
1891.49	1.35187
1894.47	1.29574
1897.46	1.76996
1900.44	1.7629
1903.42	2.52628
1906.4	2.95132
1909.38	3.46684
1912.36	2.97184
1915.34	3.28319
1918.32	4.41172
1921.29	5.18008
1924.27	4.90607
1927.24	4.65736
1930.21	4.19564
1933.18	4.93058
1936.15	4.80895
1939.12	4.74337
1942.09	3.99698
1945.06	3.60509
1948.02	2.50516
1950.99	1.88624
1953.95	0.964837
1956.91	0.541447
1959.88	0.642318
1962.84	1.25884
1965.8	0.677616
1968.75	-0.156203
1971.71	-0.34234
1974.67	-0.610467
1977.62	-0.636718
1980.58	-0.830884
1983.53	-0.126437
1986.48	0.435605
1989.43	1.60851
1992.38	2.01165
1995.33	1.67667
1998.27	2.46089
2001.22	2.92499
2004.16	4.27492
2007.11	4.47437
2010.05	4.17141
2012.99	4.01074
2015.93	3.95553
2018.87	4.73041
2021.81	4.24753
2024.75	4.63066
2027.69	4.44733
2030.62	4.29797
2033.56	3.74121
2036.49	3.78293
2039.42	3.07519
2042.35	3.6354
2045.28	3.02835
2048.21	3.37911
2051.14	3.05818
2054.07	4.38363
2056.99	4.69262
2059.92	5.02999
2062.84	5.10674
2065.76	5.05855
2068.68	4.54591
2071.6	5.16699
2074.52	5.13468
2077.44	4.47363
2080.36	3.42783
2083.27	3.25291
2086.19	3.13694
2089.1	3.02025
2092.02	2.74689
2094.93	2.26214
2097.84	2.21991
2100.75	1.76218
2103.66	2.18002
2106.56	2.92053
2109.47	2.46393
2112.38	2.80676
2115.28	3.70535
2118.18	2.96367
2121.09	3.11238
2123.99	3.88469
2126.89	4.24638
2129.79	4.03678
2132.68	4.65471
2135.58	3.76567
2138.48	2.90571
2141.37	2.91776
2144.27	2.2716
2147.16	1.81388
2150.05	1.13153
2152.94	0.432239
2155.83	0.273101
2158.72	0.487007
2161.6	0.402872
2164.49	1.74423
2167.38	1.64887
2170.26	0.945449
2173.14	1.76221
2176.03	2.53069
2178.91	2.33429
2181.79	2.54536
2184.67	3.0377
2187.54	3.51334
2190.42	4.35276
2193.3	4.66365
2196.17	5.57656
2199.05	6.52259
2201.92	6.40263
2204.79	6.39021
2207.66	6.16728
2210.53	6.47612
2213.4	6.41451
2216.27	6.00951
2219.13	5.14208
2222	5.09215
2224.86	4.27785
2227.72	5.21642
2230.59	4.37548
2233.45	4.40543
2236.31	4.88981
2239.17	4.94178
2242.03	3.54744
2244.88	3.77867
2247.74	4.30376
2250.59	3.11852
2253.45	2.78557
2256.3	3.01563
2259.15	2.90751
2262	2.31156
2264.85	2.59384
2267.7	2.95445
2270.55	3.15566
2273.4	3.59536
2276.24	4.35427
2279.09	4.62291
2281.93	4.68747
2284.77	4.90927
2287.62	4.65704
2290.46	4.09819
2293.3	3.49999
2296.13	2.97971
2298.97	2.94977
2301.81	3.43303
2304.64	4.45116
2307.48	4.92146
2310.31	4.34442
2313.14	4.40487
2315.98	5.41438
2318.81	5.18548
2321.64	4.62845
2324.46	4.51212
2327.29	3.65625
2330.12	3.84645
2332.94	4.06861
2335.77	4.76461
2338.59	5.41597
2341.41	6.17959
2344.23	7.11625
2347.05	7.14152
2349.87	6.35006
2352.69	6.4598
2355.51	6.45663
2358.32	4.72324
2361.14	4.22987
2363.95	4.43894
2366.76	4.85383
2369.58	4.4242
2372.39	4.55217
2375.2	3.82225
2378	2.84127
2380.81	3.25646
2383.62	2.69898
2386.43	1.67099
2389.23	0.854872
2392.03	0.569916
2394.84	0.391965
2397.64	0.183035
2400.44	0.414126
2403.24	0.0673928
2406.04	1.46659
2408.84	2.64165
2411.63	4.26257
2414.43	5.9508
2417.22	8.08878
2420.02	8.84883
2422.81	10.3361
2425.6	11.1964
2428.39	12.0422
2431.18	13.1426
2433.97	12.8149
2436.76	12.0057
2439.54	11.8488
2442.33	12.1468
2445.12	10.9887
2447.9	11.3027
2450.68	10.3888
2453.46	8.7999
2456.24	7.24071
2459.02	6.29924
2461.8	6.34144
2464.58	5.4932
2467.36	5.06047
2470.13	4.11097
2472.91	4.13115
2475.68	3.93489
2478.45	3.57945
2481.23	3.66088
2484	3.01948
2486.77	2.60458
2489.54	2.62492
2492.3	3.64996
2495.07	4.43897
2497.84	4.03827
2500.6	3.77009
2503.36	4.22418
2506.13	5.54797
2508.89	6.8343
2511.65	7.16826
2514.41	6.9695
2517.17	7.307
2519.93	6.51751
2522.68	6.18217
2525.44	7.57717
2528.19	8.99609
2530.95	10.0785
2533.7	9.11329
2536.45	8.53067
2539.2	7.86123
2541.95	7.96905
2544.7	7.56195
2547.45	6.6583
2550.2	6.63319
2552.94	6.23588
2555.69	6.28164
2558.43	6.46711
2561.18	6.70958
2563.92	6.03665
2566.66	6.31386
2569.4	7.4328
2572.14	7.83844
2574.88	7.63335
2577.61	6.61235
2580.35	5.80028
2583.09	4.89321
2585.82	4.32273
2588.55	4.0125
2591.29	4.10233
2594.02	4.63016
2596.75	5.37443
2599.48	5.42769
2602.21	5.21273
2604.93	5.48455
2607.66	5.97008
2610.39	6.29126
2613.11	6.42982
2615.83	7.12885
2618.56	8.02513
2621.28	8.63071
2624	9.92554
2626.72	10.268
2629.44	11.2079
2632.15	12.0275
2634.87	12.9632
2637.59	13.0056
2640.3	13.2636
2643.02	12.2505
2645.73	12.6827
2648.44	12.9897
2651.15	12.6682
2653.86	12.8332
2656.57	12.8676
2659.28	12.1523
2661.99	12.5856
2664.69	12.5459
2667.4	12.1552
2670.1	11.2436
2672.81	10.3055
2675.51	11.0873
2678.21	11.6266
2680.91	11.5887
2683.61	12.3003
2686.31	12.0717
2689	11.9243
2691.7	11.9229
2694.4	12.2973
2697.09	12.7712
2699.79	12.6207
2702.48	13.6477
2705.17	14.9774
2707.86	15.4824
2710.55	16.437
2713.24	18.1361
2715.93	17.9419
2718.62	18.0059
2721.3	17.7131
2723.99	16.5208
2726.67	16.2329
2729.35	16.7966
2732.04	16.6327
2734.72	15.6452
2737.4	15.3941
2740.08	15.1216
2742.76	14.8879
2745.43	14.8445
2748.11	14.4264
2750.79	14.6977
2753.46	13.8343
2756.14	13.3803
2758.81	12.621
2761.48	12.2068
2764.15	11.8258
2766.82	11.8994
2769.49	12.5688
2772.16	12.4882
2774.82	11.7118
2777.49	10.104
2780.16	9.19052
2782.82	8.02268
2785.48	6.70952
2788.15	5.94084
2790.81	5.10548
2793.47	4.91327
2796.13	4.58481
2798.79	3.63748
2801.44	2.88896
2804.1	2.81311
2806.76	1.79571
2809.41	0.943401
2812.07	1.37767
2814.72	1.4932
2817.37	2.76703
2820.02	4.80684
2822.67	8.12139
2825.32	12.2618
2827.97	16.3333
2830.62	22.1574
2833.26	27.5045
2835.91	34.3482
2838.56	39.9765
2841.2	47.299
2843.84	55.6938
2846.48	65.4404
2849.12	75.9264
2851.77	87.5455
2854.4	98.8903
2857.04	109.69
2859.68	121.13
2862.32	131.537
2864.95	140.569
2867.59	150.512
2870.22	158.985
2872.85	168.162
2875.48	175.727
2878.11	183.784
2880.74	191.08
2883.37	198.251
2886	205.86
2888.63	213.394
2891.25	218.715
2893.88	224.854
2896.5	232.852
2899.13	239.016
2901.75	247.67
2904.37	258.373
2906.99	269.317
2909.61	281.374
2912.23	293.305
2914.85	306.175
2917.46	316.672
2920.08	324.269
2922.7	330.188
2925.31	334.593
2927.92	336.151
2930.54	335.439
2933.15	333.967
2935.76	329.107
2938.37	322.651
2940.98	313.098
2943.58	303.264
2946.19	292.336
2948.8	280.46
2951.4	268.015
2954.01	255.005
2956.61	241.887
2959.21	230.724
2961.81	220.412
2964.41	209.206
2967.01	200.433
2969.61	190.624
2972.21	182.246
2974.81	174.304
2977.4	165.914
2980	155.329
2982.59	144.667
2985.18	133.79
2987.78	121.976
2990.37	109.9
2992.96	98.4333
2995.55	87.437
2998.14	76.6022
3000.73	65.3366
3003.31	54.9834
3005.9	45.0346
3008.48	36.5877
3011.07	29.2601
3013.65	23.4578
3016.23	17.1741
3018.81	12.7089
3021.4	9.45982
3023.97	6.11513
3026.55	3.06865
3029.13	1.32923
3031.71	0.501089
3034.28	0.541635
3036.86	1.55262
3039.43	2.14851
3042.01	3.67679
3044.58	4.37339
3047.15	5.56109
3049.72	6.83941
3052.29	7.63712
3054.86	8.86446
3057.43	9.86892
3060	10.033
3062.56	9.87297
3065.13	9.02638
3067.69	8.69642
3070.26	8.50777
3072.82	8.10545
3075.38	7.63603
3077.94	6.41076
3080.5	4.38002
3083.06	3.03632
3085.62	1.70951
3088.18	0.425575
3090.73	-0.29888
3093.29	-0.211205
3095.84	0.793512
3098.4	0.905498
3100.95	1.71702
3103.5	1.72307
3106.05	2.28233
3108.6	3.77488
3111.15	5.34054
3113.7	7.02592
3116.25	8.88574
3118.79	9.86787
3121.34	11.628
3123.88	13.1359
3126.43	14.825
3128.97	16.7134
3131.51	18.3674
3134.06	20.9743
3136.6	22.4432
3139.14	24.274
3141.67	25.4656
3144.21	27.2265
3146.75	28.8338
3149.29	32.148