File: data/Raman/poly_smoothed/Thy_10_08_29_1x_45s_532 nm_x100_100%_600 gr_mm_01.txt
#Acq. time (s)=	45
#Accumulations=	2
#Range (cm-¹)=	200...3150
#Windows=	2
#Auto scanning=	Off
#Autofocus=	Off
#Macrospot=	Off
#AutoExposure=	Off
#Spike filter=	Multiple accum.
#Delay time (s)=	0
#Binning=	1
#Readout mode=	Signal
#DeNoise=	Off
#ICS correction=	On
#Dark correction=	Off
#Inst. Process=	Off
#Detector Gain=	Best Dynamic Range
#Detector ADC=	20 kHz
#Detector temperature (°C)=	-69.85
#Instrument=	LabRAM HR Evol
#Detector=	Synapse
#Objective=	x100
#Grating=	600 gr/mm
#ND Filter=	100%
#Laser (nm)=	532
#Hole=	100.021
#Range=	Auto
#Laser Pol.=	No
#Raman. Pol.=	No
#Laser Pol. (°)=	-0.0007625
#Raman Pol. (°)=	89.9995
#Collection=	Microscope
#StageXY=	Marzhauser
#StageZ=	Marzhauser
#X (µm)=	2202.6
#Y (µm)=	1210.1
#Z (µm)=	442.5
#Full time(mm:ss)=	3:18
#Project=
#Sample=
#Site=
#Title=	Thy_10_08_29_2x_45s_532 nm_x100_100%_600 gr_mm
#Remark=
#Date=	05.07.2022 16:18
#Acquired=	05.07.2022 16:18:32
#Base:Fit=	10.08.2022 09:46:25
#Base:Sub=	10.08.2022 09:46:49
#Filter:Polynom=	16.08.2022 10:24:56
#AxisType[0]=Intens
#AxisUnit[0]=Cnt
#AxisType[1]=Spectr
#AxisUnit[1]=1/cm
200.43	1.38513
204.059	0.859074
207.688	2.17802
211.314	3.43758
214.941	4.50147
218.564	5.73281
222.186	6.73408
225.809	6.15457
229.428	6.80871
233.045	8.65586
236.663	8.76965
240.278	8.91769
243.891	8.11518
247.503	6.97739
251.116	5.7354
254.725	5.74362
258.333	6.80979
261.939	8.9765
265.544	10.0316
269.148	9.5295
272.75	8.39219
276.351	7.11962
279.95	6.69536
283.548	5.21735
287.144	6.48423
290.739	7.47076
294.333	9.80579
297.925	10.1806
301.514	10.8681
305.104	12.1124
308.692	13.3641
312.279	14.8099
315.862	16.6836
319.446	18.384
323.029	19.4159
326.608	19.3498
330.188	19.9122
333.766	19.4993
337.341	19.0203
340.917	19.8729
344.489	20.2741
348.062	20.9921
351.631	19.4106
355.201	19.2693
358.768	15.4948
362.333	15.6465
365.899	14.7039
369.462	13.1708
373.023	13.0068
376.585	12.8715
380.143	11.1247
383.7	11.1804
387.256	10.8409
390.812	10.8329
394.365	12.2613
397.916	14.0178
401.467	13.9812
405.015	14.6387
408.563	13.9619
412.109	14.9325
415.654	15.5147
419.197	14.3085
422.739	13.6068
426.279	12.9395
429.819	14.1679
433.356	14.9676
436.891	15.0493
440.426	15.4021
443.96	15.6807
447.492	14.3478
451.021	14.2529
454.551	11.1048
458.079	11.9773
461.604	11.1337
465.13	10.5803
468.654	11.3894
472.175	11.3588
475.696	9.90563
479.215	10.0764
482.733	11.7165
486.249	10.9207
489.765	10.3886
493.278	11.4009
496.789	11.2757
500.301	11.1739
503.81	10.972
507.317	12.0229
510.825	13.9342
514.33	14.7067
517.833	16.1161
521.335	16.699
524.836	17.9186
528.335	18.0906
531.835	18.8239
535.332	18.2646
538.827	18.1809
542.321	19.9662
545.814	20.9671
549.305	20.4258
552.795	19.7351
556.282	19.6998
559.769	18.633
563.255	16.2109
566.739	15.3353
570.223	14.6
573.705	12.7587
577.183	11.8421
580.663	11.6646
584.141	12.6804
587.615	12.4164
591.09	11.1924
594.564	9.08499
598.035	7.32525
601.506	5.45891
604.974	5.16074
608.443	3.89826
611.908	5.37656
615.374	5.75777
618.837	6.18336
622.3	7.31137
625.761	8.21724
629.219	8.5763
632.677	9.69544
636.135	11.6304
639.59	12.0545
643.043	12.8134
646.495	11.5346
649.948	11.6229
653.398	14.9695
656.846	15.807
660.293	16.2119
663.738	17.5368
667.183	19.4695
670.626	19.8803
674.067	19.2902
677.508	19.3303
680.947	20.3781
684.385	21.1942
687.821	23.5641
691.254	25.3274
694.688	27.6811
698.121	30.1574
701.552	32.4505
704.98	34.0839
708.409	34.8926
711.836	38.4389
715.26	39.379
718.685	41.4562
722.108	43.276
725.528	42.5975
728.949	43.9144
732.367	44.663
735.785	45.5909
739.2	46.6997
742.614	46.6414
746.028	47.8728
749.439	50.6603
752.849	53.0868
756.26	54.6177
759.667	55.6206
763.073	56.4982
766.477	59.3106
769.883	62.1414
773.285	63.7505
776.686	68.1352
780.085	69.3971
783.484	71.1298
786.881	73.1429
790.276	74.0844
793.671	76.0375
797.064	76.8794
800.456	76.4837
803.846	75.8468
807.234	76.309
810.622	74.791
814.008	76.4393
817.394	75.8462
820.778	76.4678
824.159	76.0166
827.541	76.91
830.921	77.3547
834.298	77.187
837.676	76.8533
841.051	74.4607
844.426	72.4463
847.798	72.0219
851.171	69.5337
854.54	67.1502
857.911	66.0013
861.278	64.311
864.645	61.0335
868.01	60.2865
871.373	59.1071
874.735	56.9488
878.097	54.8337
881.457	52.1375
884.815	50.9695
888.172	50.4718
891.528	50.5674
894.882	49.097
898.237	48.9178
901.589	50.043
904.94	49.6841
908.289	49.5043
911.635	49.7912
914.982	49.3027
918.328	50.0855
921.672	48.7369
925.015	46.6622
928.357	45.521
931.698	43.3856
935.035	41.2683
938.373	41.5429
941.71	40.8075
945.044	39.7766
948.378	38.8553
951.709	36.6346
955.041	35.262
958.372	34.1823
961.699	31.3924
965.027	31.1064
968.352	32.6577
971.676	32.2981
975	31.4585
978.322	32.2048
981.642	34.2989
984.962	34.2959
988.28	35.2094
991.596	36.2078
994.911	36.7912
998.227	36.7816
1001.54	36.1577
1004.85	35.1806
1008.16	35.848
1011.47	34.974
1014.78	34.2662
1018.08	34.5694
1021.39	32.7495
1024.69	30.8459
1028	30.8944
1031.3	28.4234
1034.6	26.4011
1037.9	25.1449
1041.19	22.3205
1044.49	22.2109
1047.78	23.2544
1051.08	21.1411
1054.37	19.2383
1057.66	19.2658
1060.95	19.6515
1064.24	18.6372
1067.53	17.2176
1070.81	16.9526
1074.1	16.0995
1077.38	16.6231
1080.66	16.8833
1083.94	18.5545
1087.22	17.3117
1090.5	17.1086
1093.78	15.1636
1097.05	16.2071
1100.33	15.9873
1103.6	15.2802
1106.87	15.8924
1110.14	14.82
1113.41	13.617
1116.68	14.7513
1119.95	14.3971
1123.21	12.6093
1126.48	12.0041
1129.74	10.5417
1133	9.41279
1136.26	9.30014
1139.52	8.41832
1142.78	7.83925
1146.04	6.81433
1149.29	7.27525
1152.55	6.49512
1155.8	7.41189
1159.05	7.07367
1162.3	5.38569
1165.55	3.60869
1168.8	2.7077
1172.05	1.93479
1175.29	2.11574
1178.54	3.8287
1181.78	4.64778
1185.02	4.77159
1188.26	6.45597
1191.5	7.64297
1194.74	11.0872
1197.97	13.4055
1201.21	14.7185
1204.44	18.2169
1207.68	22.2137
1210.91	23.2213
1214.14	25.489
1217.37	30.269
1220.59	35.2016
1223.82	40.3723
1227.05	43.3912
1230.27	46.7345
1233.49	50.3138
1236.72	52.9632
1239.94	53.6205
1243.16	54.4157
1246.37	56.5306
1249.59	57.4574
1252.8	58.6357
1256.02	60.4294
1259.23	60.9277
1262.44	58.605
1265.66	57.602
1268.86	57.0295
1272.07	56.2041
1275.28	56.4354
1278.48	55.7177
1281.69	55.6701
1284.89	54.7157
1288.09	55.6654
1291.29	56.3028
1294.49	57.8498
1297.69	59.317
1300.89	60.1629
1304.08	61.6408
1307.28	62.2366
1310.47	63.3463
1313.66	65.3093
1316.85	66.5309
1320.04	68.4145
1323.23	70.8134
1326.42	71.6041
1329.61	71.8388
1332.79	71.2051
1335.97	71.1112
1339.16	69.0425
1342.34	67.3041
1345.52	66.7829
1348.7	64.4443
1351.87	63.6771
1355.05	63.3134
1358.22	61.6571
1361.4	58.585
1364.57	55.699
1367.74	53.1543
1370.91	48.5591
1374.08	46.951
1377.25	43.8168
1380.41	41.2958
1383.58	39.3532
1386.74	38.8795
1389.91	38.5282
1393.07	37.3649
1396.23	37.0513
1399.39	35.2502
1402.55	35.5413
1405.7	35.2131
1408.86	36.9115
1412.01	39.6366
1415.17	44.1864
1418.32	48.0276
1421.47	52.7671
1424.62	58.4236
1427.77	64.6395
1430.91	70.4452
1434.06	76.2507
1437.2	81.344
1440.35	84.208
1443.49	86.2137
1446.63	88.2943
1449.77	89.8169
1452.91	88.4033
1456.05	86.4366
1459.18	82.8571
1462.32	78.9294
1465.45	73.7034
1468.59	67.1102
1471.72	59.3821
1474.85	52.4856
1477.98	45.2935
1481.1	39.9989
1484.23	33.4441
1487.36	27.9067
1490.48	23.1103
1493.61	19.9252
1496.73	15.8997
1499.85	13.3823
1502.97	11.9528
1506.09	11.8012
1509.2	10.6575
1512.32	10.5884
1515.43	11.3911
1518.55	10.678
1521.66	13.3313
1524.77	14.5315
1527.88	14.2259
1530.99	15.8889
1534.1	18.0847
1537.21	20.2131
1540.31	21.3902
1543.42	23.1726
1546.52	25.6757
1549.62	28.2584
1552.72	31.2555
1555.82	33.8077
1558.92	36.0611
1562.02	37.9196
1565.11	40.5286
1568.21	44.3843
1571.3	47.2114
1574.39	49.9849
1577.49	52.5885
1580.57	53.7921
1583.66	56.5824
1586.75	59.8546
1589.84	61.7132
1592.92	63.0079
1596.01	63.357
1599.09	62.3865
1602.17	60.2862
1605.25	59.9445
1608.33	60.3964
1611.41	59.2533
1614.49	59.3238
1617.57	58.6674
1620.64	59.1386
1623.72	59.0444
1626.79	59.0414
1629.86	58.9533
1632.93	59.3237
1636	59.8436
1639.07	62.0625
1642.13	63.0106
1645.2	64.2277
1648.26	65.4493
1651.33	65.8089
1654.39	66.2666
1657.45	68.1681
1660.51	67.6743
1663.57	66.0188
1666.63	64.7315
1669.68	61.7836
1672.74	58.4712
1675.79	55.5336
1678.85	52.1124
1681.9	48.3775
1684.95	44.3465
1688	39.8139
1691.05	34.7594
1694.09	30.1167
1697.14	25.9794
1700.18	21.821
1703.23	18.8451
1706.27	14.6958
1709.31	10.8443
1712.35	9.42487
1715.39	7.39008
1718.43	5.42406
1721.47	5.27726
1724.5	4.55376
1727.54	3.55951
1730.57	3.38348
1733.61	2.90397
1736.64	1.1982
1739.67	1.76201
1742.7	1.99622
1745.72	2.2803
1748.75	2.90397
1751.77	2.81489
1754.8	2.73986
1757.82	1.54206
1760.84	-0.306435
1763.87	-0.636277
1766.89	-0.262594
1769.91	0.12157
1772.92	-0.00134936
1775.94	-0.0257208
1778.95	-0.720053
1781.97	0.440267
1784.98	0.522394
1787.99	1.3185
1791.01	2.03107
1794.01	2.4228
1797.02	3.18159
1800.03	2.96716
1803.04	3.71461
1806.04	3.50204
1809.05	3.5455
1812.05	4.41612
1815.05	5.66533
1818.05	7.11517
1821.05	7.84842
1824.05	8.56276
1827.05	9.30304
1830.04	8.97469
1833.04	8.82531
1836.03	9.28378
1839.03	9.66998
1842.02	10.4353
1845.01	9.30476
1848	9.10159
1850.99	9.51182
1853.97	9.71049
1856.96	9.67584
1859.94	10.282
1862.93	10.1453
1865.91	10.8926
1868.89	11.2638
1871.87	10.6896
1874.85	11.0629
1877.83	11.2191
1880.81	11.6036
1882.57	12.8244
1885.56	14.0596
1888.55	14.4387
1891.54	15.3759
1894.52	15.9846
1897.51	17.0664
1900.49	17.102
1903.47	16.0555
1906.45	17.1847
1909.43	17.1195
1912.41	16.2673
1915.39	17.162
1918.37	16.8116
1921.34	18.2142
1924.32	18.0338
1927.29	18.195
1930.26	17.9818
1933.23	17.7741
1936.2	17.6085
1939.17	17.9076
1942.14	16.8368
1945.11	16.8484
1948.07	17.4029
1951.04	17.5036
1954	18.1527
1956.96	17.9396
1959.93	17.3466
1962.89	17.1078
1965.85	17.4081
1968.8	16.9219
1971.76	17.8468
1974.72	18.3756
1977.67	18.4812
1980.63	19.2836
1983.58	19.2202
1986.53	19.6293
1989.48	20.0784
1992.43	21.0862
1995.38	22.5907
1998.32	22.6262
2001.27	22.68
2004.22	22.1655
2007.16	22.1276
2010.1	23.4437
2013.04	23.2284
2015.98	22.9305
2018.92	23.1898
2021.86	22.8333
2024.8	22.3314
2027.74	21.7621
2030.67	21.0223
2033.61	21.0904
2036.54	21.3461
2039.47	20.8628
2042.4	21.2935
2045.33	21.4967
2048.26	21.7425
2051.19	21.4228
2054.12	22.7262
2057.04	22.5497
2059.97	23.3183
2062.89	24.094
2065.81	24.9744
2068.73	24.8054
2071.65	26.4391
2074.57	26.2056
2077.49	27.2811
2080.41	28.2944
2083.32	28.2556
2086.24	27.4178
2089.15	27.5771
2092.07	27.1614
2094.98	27.7386
2097.89	27.5456
2100.8	27.6959
2103.71	28.0777
2106.61	28.0179
2109.52	26.6035
2112.43	26.9232
2115.33	27.5683
2118.23	28.3111
2121.13	28.679
2124.04	29.5866
2126.94	30.9253
2129.83	30.9057
2132.73	31.6874
2135.63	33.0449
2138.53	34.8601
2141.42	35.8268
2144.31	37.5379
2147.21	38.1011
2150.1	39.5655
2152.99	41.7233
2155.88	41.8446
2158.77	43.459
2161.65	43.983
2164.54	44.8692
2167.43	45.3904
2170.31	45.4866
2173.19	46.5188
2176.07	47.7224
2178.96	46.3251
2181.84	46.7908
2184.72	45.3424
2187.59	44.9657
2190.47	44.0018
2193.35	42.1724
2196.22	41.1582
2199.09	40.4755
2201.97	37.7095
2204.84	35.9082
2207.71	34.3322
2210.58	32.9652
2213.45	32.3192
2216.31	31.7604
2219.18	31.399
2222.05	30.849
2224.91	30.0788
2227.78	28.0305
2230.64	27.5803
2233.5	28.1979
2236.36	27.0727
2239.22	27.5553
2242.08	28.6749
2244.93	29.0831
2247.79	28.6647
2250.64	28.4918
2253.5	28.6011
2256.35	28.0736
2259.2	28.6758
2262.05	27.9353
2264.9	26.8558
2267.75	26.5786
2270.6	25.8297
2273.45	24.1625
2276.29	22.9187
2279.14	21.5589
2281.98	20.5387
2284.82	19.7186
2287.66	19.2321
2290.5	18.6073
2293.34	17.0487
2296.18	15.4104
2299.02	15.0018
2301.86	15.5637
2304.69	16.4705
2307.53	16.0846
2310.36	17.384
2313.19	17.9772
2316.02	18.4925
2318.85	19.5098
2321.68	19.5921
2324.51	19.8205
2327.34	20.32
2330.16	21.2336
2332.99	21.5161
2335.81	21.4968
2338.64	21.5795
2341.46	20.7679
2344.28	19.4152
2347.1	19.5207
2349.92	18.863
2352.74	18.3438
2355.55	17.5086
2358.37	16.4715
2361.19	15.7572
2364	15.3995
2366.81	15.7394
2369.62	15.9134
2372.44	14.8197
2375.24	14.2395
2378.05	14.0068
2380.86	13.6871
2383.67	12.9192
2386.47	12.7595
2389.28	12.0963
2392.08	11.8338
2394.89	12.7508
2397.69	13.0016
2400.49	12.5302
2403.29	12.9647
2406.09	12.2948
2408.88	12.0709
2411.68	12.3823
2414.48	12.273
2417.27	12.7365
2420.06	12.9235
2422.86	13.571
2425.65	13.2631
2428.44	13.7459
2431.23	13.7444
2434.02	13.836
2436.81	14.3355
2439.59	13.0909
2442.38	13.2452
2445.16	13.0827
2447.95	12.8688
2450.73	12.7612
2453.51	12.8764
2456.29	12.1656
2459.07	12.2111
2461.85	12.1233
2464.63	11.2782
2467.4	10.5291
2470.18	10.382
2472.95	9.84748
2475.73	8.12059
2478.5	7.31538
2481.27	6.17547
2484.04	4.64233
2486.81	3.81703
2489.58	2.82595
2492.35	1.68049
2495.12	0.629691
2497.88	-0.0451613
2500.65	-0.482044
2503.41	0.514923
2506.17	0.14345
2508.94	0.0268308
2511.7	0.573016
2514.46	0.56836
2517.22	1.2466
2519.97	2.52181
2522.73	3.02594
2525.49	3.84288
2528.24	4.29136
2530.99	4.79414
2533.75	5.61746
2536.5	5.66691
2539.25	6.13751
2542	5.34443
2544.75	5.35561
2547.5	5.17497
2550.24	5.09997
2552.99	4.00013
2555.74	4.23532
2558.48	4.63582
2561.22	5.07059
2563.96	5.69217
2566.71	5.56247
2569.45	5.2943
2572.18	5.82175
2574.92	5.75926
2577.66	5.45868
2580.4	4.93918
2583.13	4.40427
2585.87	4.15032
2588.6	3.89024
2591.33	4.00366
2594.06	2.86366
2596.79	1.52598
2599.52	1.45705
2602.25	1.10097
2604.98	1.32092
2607.71	1.19498
2610.43	0.537307
2613.16	-0.0123531
2615.88	-0.115455
2618.6	-1.0015
2621.32	-0.608903
2624.04	0.245069
2626.76	0.483549
2629.48	1.2684
2632.2	1.4468
2634.92	2.40603
2637.63	3.69077
2640.35	4.04044
2643.06	3.80145
2645.77	3.42812
2648.49	2.86223
2651.2	3.14401
2653.91	2.89843
2656.62	2.81167
2659.33	1.78031
2662.03	0.733122
2664.74	0.411216
2667.44	0.381806
2670.15	0.0340488
2672.85	-0.116871
2675.55	-0.246234
2678.26	-1.10489
2680.96	-0.490347
2683.66	-1.0913
2686.35	0.131018
2689.05	0.773473
2691.75	1.37562
2694.44	1.60886
2697.14	3.29672
2699.83	5.07203
2702.52	5.94447
2705.22	6.62168
2707.91	7.29893
2710.6	8.24069
2713.29	8.59414
2715.97	8.78923
2718.66	7.00565
2721.35	6.0733
2724.03	6.29133
2726.72	6.90122
2729.4	7.31592
2732.08	7.26112
2734.76	7.36769
2737.44	7.13295
2740.12	6.81788
2742.8	6.22866
2745.48	5.67564
2748.16	5.10317
2750.83	5.02033
2753.51	4.93046
2756.18	5.16565
2758.85	4.94196
2761.53	4.46415
2764.2	4.8601
2766.87	4.97471
2769.54	5.22468
2772.2	4.60504
2774.87	4.27174
2777.54	2.59202
2780.2	1.66669
2782.87	0.397553
2785.53	0.0390032
2788.19	0.55732
2790.85	0.838179
2793.51	1.00062
2796.17	0.848338
2798.83	1.03443
2801.49	1.21778
2804.15	1.39146
2806.8	1.74721
2809.46	1.30683
2812.11	1.90142
2814.76	1.73682
2817.42	3.04893
2820.07	4.46923
2822.72	6.21685
2825.37	9.47331
2828.02	13.1751
2830.66	16.9851
2833.31	21.5164
2835.96	25.4452
2838.6	30.8503
2841.24	36.2186
2843.89	43.6864
2846.53	51.3293
2849.17	59.1959
2851.81	67.7094
2854.45	77.9167
2857.09	87.3329
2859.72	96.8718
2862.36	106.144
2865	115.493
2867.63	123.87
2870.26	131.441
2872.9	138.208
2875.53	144.087
2878.16	149.899
2880.79	155.508
2883.42	160.632
2886.05	165.635
2888.67	170.823
2891.3	174.4
2893.92	178.409
2896.55	182.43
2899.17	187.679
2901.79	194.19
2904.42	201.422
2907.04	210.006
2909.66	219.374
2912.27	229.53
2914.89	239.228
2917.51	249.15
2920.13	257.949
2922.74	263.964
2925.35	269.893
2927.97	274.821
2930.58	277.432
2933.19	278.625
2935.8	277.149
2938.41	274.351
2941.02	269.44
2943.63	263.493
2946.24	255.704
2948.84	247.468
2951.45	237.731
2954.05	227.795
2956.65	217.654
2959.26	208.474
2961.86	200.346
2964.46	191.393
2967.06	184.194
2969.66	177.143
2972.25	170.145
2974.85	163.654
2977.45	156.206
2980.04	148.566
2982.64	140.692
2985.23	132.661
2987.82	124.351
2990.41	115.362
2993	106.63
2995.59	97.5869
2998.18	89.2102
3000.77	80.2585
3003.36	71.6031
3005.94	62.7286
3008.53	55.3582
3011.11	47.9651
3013.69	41.424
3016.28	36.309
3018.86	31.2368
3021.44	27.9141
3024.02	25.4918
3026.6	23.2487
3029.18	21.1521
3031.75	19.7619
3034.33	19.9826
3036.9	21.0056
3039.48	21.7162
3042.05	23.5379
3044.62	24.2726
3047.19	26.2236
3049.77	27.7898
3052.34	28.5288
3054.9	28.4101
3057.47	28.7314
3060.04	28.8672
3062.61	28.2735
3065.17	27.416
3067.74	26.6746
3070.3	25.4362
3072.86	24.4319
3075.42	21.6488
3077.99	20.313
3080.54	17.8452
3083.1	15.3588
3085.66	13.1517
3088.22	10.6741
3090.78	8.63718
3093.33	6.02626
3095.89	4.87648
3098.44	3.63356
3100.99	2.8291
3103.54	2.24016
3106.1	2.01611
3108.65	1.54181
3111.2	1.70341
3113.74	1.26153
3116.29	0.662153
3118.84	0.447138
3121.38	0.981969
3123.93	0.877624
3126.47	1.74003
3129.01	2.11697
3131.56	2.6929
3134.1	2.5888
3136.64	2.31294
3139.18	2.09857
3141.72	1.4411
3144.26	-0.0921949
3146.79	-2.26137
3149.33	-4.53654