File: data/Raman/poly_smoothed/Thy_20_09_40_1x_45s_532 nm_x100_100%_600 gr_mm_01.txt
#Acq. time (s)=	45
#Accumulations=	2
#Range (cm-¹)=	200...3150
#Windows=	2
#Auto scanning=	Off
#Autofocus=	Off
#Macrospot=	Off
#AutoExposure=	Off
#Spike filter=	Multiple accum.
#Delay time (s)=	0
#Binning=	1
#Readout mode=	Signal
#DeNoise=	Off
#ICS correction=	On
#Dark correction=	Off
#Inst. Process=	Off
#Detector Gain=	Best Dynamic Range
#Detector ADC=	20 kHz
#Detector temperature (°C)=	-69.85
#Instrument=	LabRAM HR Evol
#Detector=	Synapse
#Objective=	x100
#Grating=	600 gr/mm
#ND Filter=	100%
#Laser (nm)=	532
#Hole=	100.021
#Range=	Auto
#Laser Pol.=	No
#Raman. Pol.=	No
#Laser Pol. (°)=	-0.0007625
#Raman Pol. (°)=	89.9995
#Collection=	Microscope
#StageXY=	Marzhauser
#StageZ=	Marzhauser
#X (µm)=	-5916.5
#Y (µm)=	2861.5
#Z (µm)=	-223.25
#Full time(mm:ss)=	3:18
#Project=
#Sample=
#Site=
#Title=	Thy_20_09_40_2x_45s_532 nm_x100_100%_600 gr_mm
#Remark=
#Date=	29.06.2022 13:28
#Acquired=	29.06.2022 13:28:38
#Base:Fit=	10.08.2022 09:52:02
#Base:Fit=	10.08.2022 09:52:12
#Base:Sub=	10.08.2022 09:54:21
#Filter:Polynom=	16.08.2022 10:24:04
#AxisType[0]=Intens
#AxisUnit[0]=Cnt
#AxisType[1]=Spectr
#AxisUnit[1]=1/cm
200.523	1.92557
204.154	1.35525
207.781	1.43035
211.409	0.321263
215.034	-0.592728
218.659	-1.00015
222.281	-1.06536
225.903	-0.491271
229.522	-0.116968
233.14	1.59198
236.756	2.9689
240.373	4.74065
243.986	6.38321
247.598	7.02497
251.208	8.07964
254.818	9.32113
258.427	10.4763
262.034	11.1628
265.638	14.2984
269.242	14.4287
272.844	14.386
276.445	14.9296
280.044	14.8032
283.642	14.2422
287.238	14.3103
290.833	13.9073
294.425	13.4233
298.017	13.5847
301.608	13.9551
305.198	14.6316
308.786	14.2799
312.371	15.2482
315.956	15.8259
319.54	16.8528
323.122	16.6808
326.701	15.961
330.281	15.345
333.857	14.6602
337.434	14.6897
341.008	13.9822
344.582	14.55
348.153	14.3469
351.724	13.6925
355.292	12.5657
358.861	9.93957
362.426	10.0835
365.99	9.31112
369.555	8.53819
373.116	8.24635
376.676	8.57437
380.236	9.18039
383.793	9.43453
387.349	10.0808
390.903	10.411
394.456	10.9843
398.007	10.475
401.56	11.1161
405.108	12.3143
408.656	11.1895
412.202	10.6375
415.746	10.7208
419.29	11.5422
422.831	10.9095
426.37	9.81821
429.909	9.28987
433.447	9.04359
436.983	8.323
440.519	7.54015
444.052	7.08236
447.583	6.905
451.114	6.42881
454.643	7.19326
458.169	7.38844
461.696	7.87179
465.222	8.31944
468.744	8.32656
472.267	9.18014
475.787	9.57434
479.307	11.0372
482.823	11.678
486.341	13.6378
489.855	16.1013
493.37	16.9886
496.881	17.845
500.391	18.2399
503.902	17.9178
507.409	17.4354
510.915	17.0454
514.42	17.6627
517.925	17.4273
521.427	17.5901
524.928	16.5588
528.427	16.4182
531.925	14.8968
535.422	15.2859
538.917	14.5544
542.411	14.2574
545.903	13.3935
549.395	12.1191
552.884	9.62583
556.373	8.21779
559.86	7.53614
563.346	7.57843
566.831	7.02422
570.314	6.42893
573.794	6.34847
577.274	5.17435
580.754	4.45509
584.23	3.2733
587.706	2.03971
591.181	1.75125
594.653	1.42291
598.126	0.594816
601.595	1.16373
605.065	1.15062
608.532	1.48781
611.999	2.56896
615.463	4.75391
618.928	6.00998
622.389	7.49216
625.851	9.05831
629.31	9.06005
632.767	9.80902
636.223	9.70715
639.68	9.72902
643.134	10.405
646.586	10.3648
650.037	11.0681
653.486	11.2397
656.936	11.6882
660.383	12.2762
663.829	13.4874
667.273	13.2758
670.716	13.0089
674.158	12.8605
677.598	12.6948
681.035	13.3128
684.473	14.7683
687.909	16.1546
691.344	17.6842
694.778	19.6849
698.211	21.219
701.64	22.2596
705.07	22.9305
708.498	23.0196
711.924	25.6356
715.35	25.9784
718.774	27.4673
722.196	27.8296
725.618	29.1005
729.037	31.3242
732.456	33.6622
735.873	36.0219
739.289	37.8323
742.703	40.7381
746.116	42.1939
749.529	44.6785
752.938	47.6443
756.347	48.6041
759.756	51.1571
763.162	53.1906
766.567	54.175
769.97	56.4265
773.372	56.7964
776.773	58.1178
780.174	60.8189
783.573	62.2234
786.97	62.6406
790.365	64.1804
793.76	65.5741
797.153	67.3918
800.543	66.6692
803.933	68.0004
807.322	67.574
810.71	68.8099
814.097	68.9973
817.483	67.9276
820.865	67.0399
824.248	65.6532
827.629	64.6245
831.008	65.5345
834.387	64.8603
837.765	62.004
841.139	58.9927
844.514	57.6845
847.886	55.0865
851.259	52.7054
854.629	49.6464
857.997	48.3858
861.366	47.9931
864.732	46.7507
868.098	44.9482
871.461	43.7278
874.823	42.4546
878.184	40.3464
881.545	38.7675
884.903	38.8533
888.26	39.7704
891.616	37.2903
894.97	36.4714
898.323	35.9113
901.675	34.9987
905.026	32.5866
908.375	32.9898
911.723	32.0219
915.07	32.5049
918.415	30.9386
921.76	30.0837
925.103	29.8176
928.443	29.8507
931.783	29.443
935.123	28.155
938.461	29.251
941.796	30.168
945.131	28.7933
948.465	28.4505
951.797	27.5364
955.128	26.1699
958.457	24.7578
961.786	23.657
965.113	23.7943
968.44	23.5755
971.763	21.2099
975.086	20.6524
978.409	20.4307
981.729	19.274
985.048	17.846
988.367	16.452
991.683	15.673
994.998	17.0653
998.312	18.487
1001.62	18.3398
1004.94	18.84
1008.25	19.0381
1011.56	19.7728
1014.86	18.636
1018.17	19.3885
1021.48	18.2122
1024.78	16.2375
1028.08	15.1236
1031.38	13.7553
1034.68	12.3455
1037.98	10.0597
1041.28	8.50239
1044.57	8.23125
1047.87	8.00718
1051.16	6.63341
1054.45	6.43856
1057.75	5.0926
1061.04	3.50055
1064.32	3.3991
1067.61	3.33364
1070.9	3.48291
1074.18	4.5416
1077.47	4.19568
1080.75	4.83553
1084.03	4.68166
1087.31	3.90522
1090.59	4.84276
1093.86	5.14963
1097.14	5.31727
1100.41	5.92114
1103.69	5.10252
1106.96	5.61745
1110.23	6.19732
1113.5	4.83302
1116.77	4.79034
1120.03	5.21201
1123.3	5.1311
1126.56	3.92833
1129.83	2.71627
1133.09	2.27172
1136.35	2.77641
1139.61	4.10692
1142.86	3.61526
1146.12	3.52013
1149.38	3.71381
1152.63	3.63118
1155.88	3.48876
1159.14	2.33365
1162.39	2.5563
1165.63	2.57892
1168.88	1.86171
1172.13	3.25525
1175.38	3.04186
1178.62	3.66797
1181.86	4.00004
1185.1	4.79949
1188.34	5.10592
1191.58	7.20281
1194.82	8.4468
1198.06	9.0019
1201.29	9.66914
1204.53	9.84979
1207.76	12.0294
1210.99	13.7746
1214.22	15.4154
1217.45	18.5253
1220.68	20.6819
1223.91	20.9367
1227.13	22.917
1230.36	23.345
1233.58	23.9944
1236.8	23.0779
1240.02	23.0431
1243.24	23.3087
1246.46	24.3827
1249.67	25.7641
1252.89	28.1077
1256.1	30.1067
1259.32	31.9763
1262.53	34.1331
1265.74	37.7286
1268.95	39.4804
1272.15	41.2441
1275.36	42.098
1278.57	42.6427
1281.77	44.6798
1284.97	46.7891
1288.18	49.2099
1291.38	49.0024
1294.58	49.9988
1297.78	50.7577
1300.97	50.867
1304.17	50.2847
1307.36	49.45
1310.55	48.7379
1313.75	47.7299
1316.94	47.9232
1320.13	48.7593
1323.32	48.3301
1326.5	48.5197
1329.69	48.8279
1332.87	49.2643
1336.06	49.4515
1339.24	49.6644
1342.42	47.8257
1345.6	45.7467
1348.78	44.7836
1351.96	44.125
1355.13	42.7956
1358.31	42.4386
1361.48	41.2724
1364.65	40.3212
1367.82	39.0826
1370.99	37.8352
1374.16	36.3024
1377.33	34.4807
1380.5	33.4856
1383.66	32.4036
1386.83	31.9366
1389.99	30.3047
1393.15	29.3513
1396.31	28.6932
1399.47	27.5356
1402.63	26.4677
1405.78	25.9488
1408.94	26.0744
1412.1	25.9695
1415.25	27.5128
1418.4	28.6537
1421.55	30.634
1424.7	34.3877
1427.85	39.0233
1431	41.843
1434.14	45.94
1437.29	49.0448
1440.43	51.8739
1443.57	54.2976
1446.71	55.1668
1449.85	55.9372
1452.99	56.5424
1456.13	56.4987
1459.26	55.6419
1462.4	54.2926
1465.54	51.3198
1468.67	48.0944
1471.8	45.4294
1474.93	40.3195
1478.06	35.3784
1481.19	32.1936
1484.31	29.3672
1487.44	25.7408
1490.56	22.7996
1493.69	22.3933
1496.81	21.3848
1499.93	21.4867
1503.05	21.3175
1506.17	20.5778
1509.28	19.8719
1512.4	19.9032
1515.52	19.2085
1518.63	20.0277
1521.74	20.409
1524.85	20.9797
1527.96	22.2127
1531.07	23.7496
1534.18	25.1476
1537.29	26.4863
1540.39	27.6481
1543.5	29.9069
1546.6	32.4867
1549.7	34.2335
1552.8	36.0124
1555.9	38.6559
1559	40.7035
1562.1	42.5777
1565.19	43.4254
1568.29	46.0479
1571.38	48.4687
1574.47	49.4457
1577.56	51.6471
1580.66	53.147
1583.74	53.9517
1586.83	56.4508
1589.92	57.7713
1593.01	58.4843
1596.09	57.6438
1599.17	57.9098
1602.25	56.2751
1605.34	55.4789
1608.41	52.5115
1611.49	50.968
1614.57	48.8377
1617.65	46.1192
1620.72	46.0827
1623.79	45.1331
1626.87	43.8699
1629.94	43.1295
1633.01	41.4834
1636.08	40.7525
1639.15	40.9115
1642.21	40.5464
1645.28	40.885
1648.34	40.8056
1651.41	42.445
1654.47	43.1035
1657.53	43.628
1660.59	44.1271
1663.65	45.0355
1666.71	43.3598
1669.76	42.5533
1672.82	40.4317
1675.87	38.9559
1678.93	36.3871
1681.98	33.3778
1685.03	30.053
1688.08	27.535
1691.13	24.0692
1694.17	22.0623
1697.22	19.441
1700.27	16.7523
1703.31	14.3247
1706.35	12.1735
1709.39	10.8762
1712.43	9.76722
1715.47	8.54159
1718.51	6.91589
1721.55	5.55879
1724.58	4.67216
1727.62	4.19771
1730.65	3.64256
1733.68	3.81702
1736.72	3.84709
1739.74	3.6592
1742.77	3.51106
1745.8	3.88249
1748.83	3.00143
1751.85	3.04487
1754.88	1.83974
1757.9	0.994009
1760.92	0.660877
1763.95	0.995694
1766.96	0.0113881
1769.98	-0.790233
1773	-0.714021
1776.02	-0.339599
1779.03	-0.145792
1782.05	0.991273
1785.06	0.894097
1788.07	1.29289
1791.08	0.575702
1794.09	0.464066
1797.1	0.437035
1800.11	1.19076
1803.12	1.85104
1806.12	2.17815
1809.12	2.28244
1812.13	2.08887
1815.13	1.83764
1818.13	2.4132
1821.13	2.48596
1824.13	2.63629
1827.13	3.01767
1830.12	2.74102
1833.12	2.36636
1836.11	2.77919
1839.1	2.51058
1842.09	2.38799
1845.09	2.2565
1848.08	2.41191
1851.06	1.1924
1854.05	1.40657
1857.04	1.8434
1860.02	1.9019
1863.01	2.12014
1865.99	2.41962
1868.97	2.47485
1871.95	3.62138
1874.93	4.35052
1877.91	4.61892
1880.89	5.11733
1882.46	4.54637
1885.45	4.58245
1888.43	5.60165
1891.42	6.27442
1894.41	6.8488
1897.39	5.96889
1900.37	5.42028
1903.36	6.31765
1906.34	6.41762
1909.32	6.00249
1912.29	6.21005
1915.27	5.70551
1918.25	5.71323
1921.23	5.37546
1924.2	5.34012
1927.17	6.6987
1930.15	6.98376
1933.12	7.13931
1936.09	7.11915
1939.06	6.92222
1942.02	6.63485
1944.99	6.84227
1947.96	5.94291
1950.92	5.16284
1953.88	5.58854
1956.85	5.69353
1959.81	6.81943
1962.77	7.46917
1965.73	7.03258
1968.69	6.77146
1971.64	6.49578
1974.6	7.22153
1977.55	7.52649
1980.51	6.70099
1983.46	6.50317
1986.41	5.71389
1989.36	6.83593
1992.31	7.83126
1995.26	7.29732
1998.21	6.70272
2001.15	5.94515
2004.1	4.99582
2007.04	3.63027
2009.99	3.33809
2012.93	2.01973
2015.87	1.74836
2018.81	2.26623
2021.75	1.87051
2024.68	2.94456
2027.62	3.43035
2030.56	3.78667
2033.49	4.21019
2036.42	5.19362
2039.36	4.93946
2042.29	5.6545
2045.22	7.3917
2048.14	8.03286
2051.07	7.8741
2054	8.02483
2056.93	9.01014
2059.85	9.71731
2062.77	10.1983
2065.7	9.29655
2068.62	8.08981
2071.54	6.87478
2074.46	6.77657
2077.38	7.3127
2080.29	7.22431
2083.21	7.17998
2086.12	7.88366
2089.04	8.5153
2091.95	9.77873
2094.86	9.48225
2097.77	9.70624
2100.68	9.82952
2103.59	9.71257
2106.5	10.1082
2109.41	10.3661
2112.31	10.8315
2115.21	12.1267
2118.12	12.9462
2121.02	13.1154
2123.92	13.3082
2126.82	14.2663
2129.72	16.2345
2132.62	16.9552
2135.51	17.5408
2138.41	18.0668
2141.31	19.223
2144.2	21.019
2147.09	23.6
2149.98	24.475
2152.87	26.2141
2155.76	27.6231
2158.65	28.1422
2161.54	28.9217
2164.43	28.1169
2167.31	27.7156
2170.2	28.8177
2173.08	28.2943
2175.96	28.3456
2178.84	28.1503
2181.72	26.6935
2184.6	26.0164
2187.48	26.7106
2190.36	25.8612
2193.23	25.435
2196.11	24.198
2198.98	23.4351
2201.85	24.2363
2204.72	23.1945
2207.59	21.4468
2210.46	20.8219
2213.33	19.8787
2216.2	18.827
2219.07	17.9648
2221.93	16.5528
2224.8	15.2566
2227.66	13.5218
2230.52	11.3747
2233.39	11.6829
2236.25	11.4426
2239.1	10.9057
2241.96	10.2334
2244.82	9.30888
2247.68	9.22883
2250.53	8.51307
2253.38	8.25689
2256.24	8.00669
2259.09	7.31488
2261.94	7.68455
2264.79	7.76922
2267.64	8.21952
2270.49	8.86549
2273.33	8.6201
2276.18	8.39602
2279.02	8.02914
2281.87	7.42696
2284.71	6.7173
2287.55	7.00104
2290.39	6.95579
2293.23	5.93959
2296.07	6.31912
2298.91	6.40164
2301.74	7.21414
2304.58	7.72863
2307.41	7.22873
2310.25	7.22684
2313.08	6.83555
2315.91	6.50095
2318.74	5.95698
2321.57	6.03027
2324.4	5.58324
2327.23	5.60996
2330.05	6.17209
2332.88	6.73642
2335.7	6.89741
2338.52	6.40876
2341.35	5.59445
2344.17	4.49398
2346.99	3.7438
2349.81	2.70342
2352.62	2.30062
2355.44	2.54333
2358.26	2.73127
2361.07	3.4246
2363.89	4.5391
2366.7	5.51165
2369.51	5.68826
2372.32	6.55791
2375.13	7.15715
2377.94	6.5034
2380.75	6.07123
2383.56	5.17046
2386.36	5.24108
2389.17	5.55627
2391.97	5.16231
2394.77	4.04028
2397.58	4.78964
2400.38	4.93803
2403.18	4.88434
2405.97	4.68443
2408.77	4.98371
2411.57	4.68158
2414.37	5.15532
2417.16	5.57223
2419.95	6.01345
2422.75	6.1296
2425.54	6.69233
2428.33	6.66559
2431.12	7.1766
2433.91	6.92635
2436.7	8.23122
2439.48	8.25719
2442.27	7.90212
2445.05	7.08838
2447.84	5.61858
2450.62	4.71389
2453.4	3.55047
2456.18	3.1656
2458.96	2.04215
2461.74	2.15978
2464.52	3.08619
2467.29	4.12597
2470.07	4.60139
2472.85	5.37169
2475.62	6.42527
2478.39	7.48649
2481.16	6.51281
2483.93	6.32165
2486.7	6.02716
2489.47	5.41158
2492.24	5.91568
2495.01	5.67283
2497.77	7.12656
2500.54	7.08701
2503.3	6.66997
2506.06	6.21738
2508.83	5.39565
2511.59	5.40071
2514.35	5.05958
2517.11	5.00488
2519.86	4.95418
2522.62	4.64949
2525.38	6.2808
2528.13	7.1722
2530.89	7.1333
2533.64	7.28508
2536.39	7.46321
2539.14	6.6061
2541.89	5.85968
2544.64	5.28041
2547.39	4.96178
2550.14	4.52125
2552.88	4.25869
2555.63	4.54108
2558.37	3.89484
2561.11	3.82492
2563.86	3.85421
2566.6	3.76743
2569.34	3.40252
2572.08	4.11532
2574.82	4.63335
2577.55	5.39796
2580.29	6.06932
2583.02	6.97962
2585.76	7.40873
2588.49	8.77814
2591.22	9.7296
2593.96	9.1671
2596.69	8.22316
2599.42	6.73085
2602.14	6.64197
2604.87	5.64145
2607.6	4.9598
2610.32	5.11864
2613.05	5.11357
2615.77	5.0582
2618.49	5.50935
2621.22	4.7542
2623.94	3.32948
2626.66	2.82359
2629.37	2.89769
2632.09	3.86768
2634.81	3.84337
2637.53	5.41944
2640.24	4.99056
2642.96	4.66283
2645.67	5.40435
2648.38	6.08252
2651.09	6.8872
2653.8	6.52583
2656.51	5.98773
2659.22	5.79317
2661.93	5.35105
2664.63	5.23918
2667.34	6.22468
2670.04	6.4706
2672.75	6.18787
2675.45	6.75819
2678.15	6.94047
2680.85	7.4933
2683.55	7.74081
2686.25	7.20041
2688.94	7.12817
2691.64	8.23731
2694.34	8.66232
2697.03	9.51512
2699.73	9.87475
2702.42	10.2916
2705.11	10.0237
2707.8	9.19693
2710.49	9.64252
2713.18	9.38755
2715.87	9.74263
2718.55	9.85891
2721.24	9.28934
2723.93	9.93003
2726.61	10.822
2729.29	11.1352
2731.98	10.7222
2734.66	10.6404
2737.34	10.0489
2740.02	9.82785
2742.7	10.992
2745.37	10.8694
2748.05	10.0826
2750.72	9.61988
2753.4	9.52194
2756.07	9.58419
2758.75	10.0235
2761.42	10.337
2764.09	10.2035
2766.76	9.45661
2769.43	8.16738
2772.1	6.45016
2774.76	6.77859
2777.43	6.36223
2780.1	6.43702
2782.76	6.61191
2785.42	6.96987
2788.09	6.50728
2790.75	6.09885
2793.41	4.48933
2796.07	4.03684
2798.73	3.00172
2801.39	2.58623
2804.04	2.96465
2806.7	3.71765
2809.35	3.72101
2812.01	3.0797
2814.66	2.75807
2817.31	3.35005
2819.96	4.61658
2822.61	5.75468
2825.26	6.97377
2827.91	8.41535
2830.56	8.87307
2833.21	11.3944
2835.85	13.0532
2838.5	15.0703
2841.14	17.7341
2843.78	20.4777
2846.42	24.6597
2849.06	28.3791
2851.71	31.8572
2854.34	35.1921
2856.98	39.1413
2859.62	43.3688
2862.26	47.3212
2864.89	51.5924
2867.53	54.8961
2870.16	58.4846
2872.79	60.3581
2875.42	62.3988
2878.05	64.3074
2880.68	66.9488
2883.31	69.119
2885.94	71.6852
2888.57	73.5911
2891.19	74.7279
2893.82	76.2836
2896.44	80.0538
2899.07	82.7669
2901.69	85.6647
2904.31	89.5067
2906.93	94.2375
2909.55	99.4329
2912.17	104.501
2914.79	109.791
2917.41	115.175
2920.02	119.198
2922.64	122.615
2925.25	124.764
2927.86	125.886
2930.48	125.962
2933.09	125.288
2935.7	124.256
2938.31	121.737
2940.92	118.961
2943.53	116.237
2946.13	112.815
2948.74	108.715
2951.34	105.382
2953.95	101.095
2956.55	96.9033
2959.15	93.2493
2961.75	89.1651
2964.35	84.5669
2966.95	80.4626
2969.55	77.2487
2972.15	74.9143
2974.75	71.6287
2977.34	68.016
2979.94	64.5289
2982.53	60.641
2985.13	56.2102
2987.72	51.701
2990.31	47.6342
2992.9	43.1483
2995.49	38.4355
2998.08	34.5161
3000.67	30.1497
3003.25	27.2276
3005.84	23.7275
3008.42	21.3807
3011.01	19.0822
3013.59	17.7646
3016.17	15.9924
3018.76	13.7932
3021.34	12.1047
3023.92	10.8036
3026.49	9.9787
3029.07	10.039
3031.65	10.3221
3034.23	11.192
3036.8	12.4424
3039.38	12.1361
3041.95	13.158
3044.52	14.3789
3047.09	15.1781
3049.66	15.2538
3052.23	15.6477
3054.8	15.4762
3057.37	15.4289
3059.94	14.5878
3062.5	13.6254
3065.07	13.0581
3067.63	11.6047
3070.2	9.55286
3072.76	8.93219
3075.32	7.03801
3077.88	5.6852
3080.44	4.42216
3083	2.83896
3085.56	2.305
3088.12	2.55506
3090.67	1.82069
3093.23	1.15421
3095.78	1.71301
3098.34	3.0024
3100.89	2.94707
3103.44	2.76199
3105.99	3.59034
3108.54	3.38719
3111.09	4.17995
3113.64	4.05155
3116.19	5.06591
3118.74	4.40049
3121.28	4.30472
3123.83	3.81544
3126.37	3.92599
3128.91	2.97274
3131.46	2.84749
3134	2.9485
3136.54	3.01624
3139.08	2.89055
3141.62	3.19654
3144.16	4.27061
3146.69	4.44008
3149.23	4.72803