File: data/Raman/poly_smoothed/Thy_30_10_06_1x_45s_532 nm_x100_100%_600 gr_mm_01.txt
#Acq. time (s)=	45
#Accumulations=	2
#Range (cm-¹)=	200...3150
#Windows=	2
#Auto scanning=	Off
#Autofocus=	Off
#Macrospot=	Off
#AutoExposure=	Off
#Spike filter=	Multiple accum.
#Delay time (s)=	0
#Binning=	1
#Readout mode=	Signal
#DeNoise=	Off
#ICS correction=	On
#Dark correction=	Off
#Inst. Process=	Off
#Detector Gain=	Best Dynamic Range
#Detector ADC=	20 kHz
#Detector temperature (°C)=	-69.85
#Instrument=	LabRAM HR Evol
#Detector=	Synapse
#Objective=	x100
#Grating=	600 gr/mm
#ND Filter=	100%
#Laser (nm)=	532
#Hole=	100.021
#Range=	Auto
#Laser Pol.=	No
#Raman. Pol.=	No
#Laser Pol. (°)=	-0.0007625
#Raman Pol. (°)=	89.9995
#Collection=	Microscope
#StageXY=	Marzhauser
#StageZ=	Marzhauser
#X (µm)=	4752.4
#Y (µm)=	-7737.3
#Z (µm)=	584.25
#Full time(mm:ss)=	3:18
#Project=
#Sample=
#Site=
#Title=	Thy_30_10_06_2x_45s_532 nm_x100_100%_600 gr_mm
#Remark=
#Date=	30.06.2022 11:48
#Acquired=	30.06.2022 11:48:30
#Base:Fit=	10.08.2022 09:56:48
#Base:Fit=	10.08.2022 09:57:06
#Base:Fit=	10.08.2022 09:57:43
#Base:Fit=	10.08.2022 09:57:50
#Base:Fit=	10.08.2022 09:58:11
#Base:Sub=	10.08.2022 09:58:44
#Filter:Polynom=	16.08.2022 10:22:53
#AxisType[0]=Intens
#AxisUnit[0]=Cnt
#AxisType[1]=Spectr
#AxisUnit[1]=1/cm
200.533	14.9305
204.162	14.6425
207.792	12.9255
211.418	11.1198
215.044	9.64798
218.667	8.20024
222.289	6.07915
225.912	4.90125
229.531	3.15427
233.148	2.96229
236.766	2.06322
240.381	1.26915
243.994	0.958147
247.606	0.242362
251.217	-0.856742
254.828	-0.146215
258.436	-0.849371
262.042	1.79134
265.647	3.46266
269.25	3.77524
272.852	4.1239
276.453	3.80372
280.052	4.46682
283.65	5.53997
287.247	6.62803
290.842	7.66215
294.436	7.86198
298.028	9.93845
301.617	11.1485
305.206	11.9543
308.794	12.2261
312.381	12.9045
315.964	12.4616
319.548	13.5225
323.131	14.5288
326.71	15.4295
330.29	15.9837
333.868	15.8293
337.443	13.9735
341.018	15.5672
344.591	15.3912
348.163	14.1698
351.733	13.6648
355.303	11.8322
358.869	9.86269
362.435	9.08931
366.001	7.7582
369.563	6.73842
373.124	6.87891
376.686	6.70626
380.244	6.28765
383.801	6.02821
387.357	5.21495
390.911	4.12685
394.466	2.85612
398.018	2.31636
401.568	2.52844
405.117	2.84235
408.664	4.09122
412.21	4.32168
415.755	4.27285
419.298	3.84006
422.84	4.49049
426.38	4.95755
429.919	6.45269
433.455	6.225
436.992	7.59382
440.527	9.40315
444.06	10.108
447.593	10.604
451.122	11.0419
454.651	13.3707
458.18	14.5384
461.705	16.5296
465.23	16.0813
468.752	17.1547
472.275	15.1897
475.797	14.4259
479.315	14.8853
482.834	15.7083
486.349	16.39
489.863	15.5873
493.378	16.4782
496.889	16.4089
500.401	16.9746
503.91	17.598
507.417	18.4761
510.923	18.3917
514.43	18.7447
517.933	18.0778
521.435	19.1654
524.936	20.2404
528.435	19.6078
531.933	19.5167
535.43	18.7415
538.927	19.8242
542.421	18.883
545.913	17.735
549.403	16.377
552.893	15.2944
556.381	15.1983
559.868	13.5643
563.354	14.5788
566.839	14.9641
570.322	13.671
573.802	12.369
577.283	11.8252
580.762	11.9882
584.24	10.7281
587.714	9.27725
591.19	8.5207
594.663	8.4328
598.134	8.58195
601.605	7.12717
605.073	7.47232
608.542	8.6322
612.007	10.0915
615.473	11.0003
618.936	11.1905
622.397	11.9402
625.859	13.0227
629.318	15.3943
632.775	16.6508
636.233	19.0712
639.688	20.5753
643.142	22.5231
646.594	25.1761
650.045	26.6354
653.496	27.666
656.944	27.8386
660.391	27.8101
663.837	28.1975
667.281	28.5118
670.724	28.2857
674.166	29.4403
677.606	29.5477
681.045	28.5933
684.483	27.6556
687.917	27.8263
691.352	28.5738
694.786	30.0335
698.219	31.2223
701.65	31.5988
705.078	32.5247
708.506	33.869
711.934	35.4978
715.358	37.647
718.782	38.3051
722.204	40.052
725.626	43.3178
729.045	44.1727
732.464	45.2361
735.881	46.7736
739.297	48.1266
742.711	49.552
746.125	51.8971
749.537	54.0902
752.946	56.5971
756.357	57.9405
759.764	59.3236
763.17	62.1036
766.575	62.3785
769.978	64.8418
773.382	68.0134
776.783	70.6754
780.182	73.8264
783.581	76.1667
786.978	78.1355
790.373	81.0846
793.768	82.3936
797.161	84.6143
800.552	86.2626
803.941	86.2271
807.33	87.7786
810.718	87.4717
814.105	88.6704
817.49	89.9398
820.873	89.1155
824.256	88.8601
827.637	87.9765
831.016	86.8252
834.395	86.083
837.772	85.5908
841.147	84.4633
844.522	84.0114
847.894	82.5772
851.267	80.9181
854.637	79.2212
858.007	78.1536
861.374	74.881
864.739	74.4627
868.106	73.7044
871.469	72.4495
874.831	71.535
878.193	69.1994
881.553	67.1056
884.911	65.5292
888.268	65.0407
891.623	64.8957
894.978	65.0713
898.331	63.9157
901.683	62.5128
905.033	61.7618
908.383	61.2861
911.731	60.2054
915.078	60.0349
918.423	59.9269
921.768	60.3973
925.111	59.1978
928.452	58.3881
931.791	57.2739
935.13	55.1331
938.468	54.1331
941.803	53.7269
945.139	52.5443
948.473	52.9092
951.804	51.0282
955.136	50.0263
958.465	47.4422
961.794	45.5864
965.12	45.8631
968.447	45.8232
971.771	45.1295
975.095	46.2186
978.417	47.0208
981.737	46.6046
985.057	46.3674
988.375	45.3824
991.691	46.0354
995.006	46.3485
998.32	46.2019
1001.63	45.6978
1004.95	44.3449
1008.26	43.9158
1011.56	44.1495
1014.87	43.969
1018.18	44.263
1021.48	43.6286
1024.79	42.2642
1028.09	41.3942
1031.39	39.9895
1034.69	40.5053
1037.99	40.6835
1041.29	38.2436
1044.58	38.1936
1047.88	37.3785
1051.17	36.4973
1054.46	35.5509
1057.75	35.3118
1061.04	35.2277
1064.33	34.6179
1067.62	34.0343
1070.9	34.0184
1074.19	34.8132
1077.47	33.9735
1080.76	34.1184
1084.04	34.038
1087.32	35.6639
1090.59	35.9562
1093.87	36.322
1097.15	35.5796
1100.42	35.9771
1103.69	35.6337
1106.97	36.3151
1110.24	34.853
1113.51	32.9177
1116.77	30.5481
1120.04	27.647
1123.31	25.0299
1126.57	21.8154
1129.83	19.0475
1133.1	16.7308
1136.36	13.841
1139.62	13.6243
1142.87	12.0288
1146.13	10.5707
1149.38	10.7589
1152.64	9.17676
1155.89	8.19331
1159.14	8.49449
1162.39	9.3929
1165.64	10.1198
1168.89	12.195
1172.14	12.454
1175.38	14.5782
1178.63	16.9406
1181.87	19.0376
1185.11	19.9684
1188.35	19.8385
1191.59	19.4997
1194.83	20.5175
1198.07	21.9754
1201.3	23.8824
1204.53	25.4072
1207.77	25.8733
1211	26.87
1214.23	28.5396
1217.46	30.5828
1220.69	32.8
1223.91	35.9943
1227.14	36.5667
1230.36	38.4799
1233.59	39.57
1236.81	41.0009
1240.03	43.2972
1243.25	45.309
1246.46	46.9368
1249.68	48.0674
1252.9	48.5008
1256.11	49.3021
1259.32	49.0697
1262.54	49.4101
1265.75	47.9629
1268.96	47.2689
1272.16	49.4129
1275.37	50.7577
1278.57	51.7067
1281.78	52.9915
1284.98	52.9824
1288.18	53.0983
1291.38	54.3132
1294.58	56.1205
1297.78	57.6271
1300.98	57.6471
1304.17	59.3881
1307.37	59.8715
1310.56	62.2968
1313.76	63.2617
1316.95	63.8496
1320.14	64.5282
1323.32	63.8786
1326.51	63.4421
1329.7	60.4622
1332.88	58.065
1336.07	55.5638
1339.25	52.0047
1342.43	49.4731
1345.61	47.2103
1348.79	46.2319
1351.96	43.4701
1355.14	40.9138
1358.31	38.2071
1361.49	35.2443
1364.66	32.0452
1367.83	29.5777
1371	28.4905
1374.17	25.9698
1377.34	25.0796
1380.5	24.5621
1383.67	24.5594
1386.83	24.7195
1390	25.2518
1393.16	23.9481
1396.32	24.1354
1399.48	24.7152
1402.64	25.4546
1405.79	25.1974
1408.95	26.494
1412.1	28.1293
1415.26	30.6534
1418.41	33.0049
1421.56	35.9653
1424.71	40.6614
1427.86	44.414
1431	48.0014
1434.15	51.9242
1437.29	54.8386
1440.44	56.467
1443.58	57.3
1446.72	57.5156
1449.86	58.0769
1453	56.351
1456.14	54.4121
1459.27	51.4948
1462.41	48.5842
1465.54	45.325
1468.67	42.2756
1471.81	38.1367
1474.94	33.1094
1478.07	28.5831
1481.19	23.5721
1484.32	19.8601
1487.45	17.564
1490.57	15.4182
1493.69	13.2944
1496.82	10.9354
1499.94	10.3096
1503.06	10.1596
1506.17	8.98204
1509.29	7.59346
1512.41	7.32538
1515.52	6.03389
1518.64	7.14064
1521.75	7.11639
1524.86	7.46223
1527.97	7.99483
1531.08	7.85317
1534.19	9.30363
1537.29	11.5579
1540.4	13.4149
1543.5	14.3303
1546.61	16.4879
1549.71	17.373
1552.81	18.9877
1555.91	20.8569
1559.01	23.162
1562.11	25.862
1565.2	26.6509
1568.29	28.9631
1571.39	29.7945
1574.48	31.1201
1577.57	32.6636
1580.66	33.6917
1583.75	35.9952
1586.84	36.5974
1589.93	38.1528
1593.01	38.2167
1596.1	39.2998
1599.18	38.1831
1602.26	38.7692
1605.34	37.9213
1608.42	37.1782
1611.5	38.1324
1614.58	39.0181
1617.65	39.2858
1620.73	40.0804
1623.8	41.3382
1626.87	42.5597
1629.95	42.7627
1633.02	44.4167
1636.09	45.7443
1639.15	47.7997
1642.22	50.2946
1645.29	53.0504
1648.35	55.3952
1651.42	57.4911
1654.48	58.3064
1657.54	59.4244
1660.6	58.9863
1663.66	57.543
1666.72	56.3109
1669.77	54.9072
1672.83	52.2038
1675.88	48.942
1678.93	45.0282
1681.99	40.2466
1685.04	36.0783
1688.09	31.4561
1691.13	26.0756
1694.18	23.1574
1697.23	18.5364
1700.27	14.5865
1703.32	10.3289
1706.36	8.30782
1709.4	6.76076
1712.44	4.58164
1715.48	3.4112
1718.52	2.30749
1721.56	1.56247
1724.59	1.58741
1727.63	1.06893
1730.66	1.29865
1733.69	0.493737
1736.72	1.60405
1739.75	2.05747
1742.78	1.90561
1745.81	1.98816
1748.84	1.54124
1751.86	0.575569
1754.89	0.188026
1757.91	0.505003
1760.93	0.49242
1763.95	0.638511
1766.97	1.1602
1769.99	1.11138
1773.01	0.618025
1776.03	1.05593
1779.04	1.67753
1782.06	1.7014
1785.07	1.41223
1788.08	0.854575
1791.09	0.758974
1794.1	-0.0642861
1797.11	-0.00304128
1800.12	0.428769
1803.12	0.178327
1806.13	0.198736
1809.13	0.992954
1812.14	0.63682
1815.14	0.472518
1818.14	-0.00531132
1821.14	0.20233
1824.14	-0.132949
1827.13	0.658535
1830.13	1.10556
1833.12	1.2466
1836.12	1.79162
1839.11	2.74413
1842.1	3.00672
1845.09	3.68038
1848.08	5.1242
1851.07	4.38376
1854.06	4.21281
1857.04	3.79394
1860.03	4.23393
1863.01	4.44774
1866	3.88215
1868.98	3.79151
1871.96	3.72413
1874.94	3.86316
1877.92	3.5398
1880.89	2.96491
1882.48	2.19704
1885.47	1.456
1888.46	1.90991
1891.44	1.27934
1894.43	0.976364
1897.41	1.98958
1900.4	1.94634
1903.38	2.60222
1906.36	3.77996
1909.34	4.52613
1912.32	4.84773
1915.29	6.52677
1918.27	7.40123
1921.25	7.98226
1924.22	8.1438
1927.2	9.90206
1930.17	10.7221
1933.14	10.1653
1936.11	9.70806
1939.08	9.60231
1942.05	9.7723
1945.01	9.53335
1947.98	8.75142
1950.94	7.63774
1953.91	7.11455
1956.87	6.86965
1959.83	7.21928
1962.79	5.28999
1965.75	5.50554
1968.71	5.39474
1971.67	5.2127
1974.62	4.98517
1977.58	5.38625
1980.53	5.78432
1983.48	6.23575
1986.43	7.88636
1989.38	7.89798
1992.33	7.89451
1995.28	8.87346
1998.23	9.60219
2001.18	10.5759
2004.12	10.4622
2007.06	10.3192
2010.01	10.9701
2012.95	11.2512
2015.89	11.0508
2018.83	9.7797
2021.77	9.79358
2024.71	10.501
2027.64	10.9356
2030.58	10.723
2033.51	10.4375
2036.45	10.1253
2039.38	9.71902
2042.31	9.37614
2045.24	7.88818
2048.17	8.23292
2051.1	8.3995
2054.02	8.42541
2056.95	7.90322
2059.87	8.28389
2062.8	8.23409
2065.72	8.69378
2068.64	9.65355
2071.56	10.159
2074.48	10.79
2077.4	11.5719
2080.31	12.3789
2083.23	14.1216
2086.14	15.3944
2089.06	16.2672
2091.97	17.8547
2094.88	19.2951
2097.79	21.73
2100.7	22.741
2103.61	23.7064
2106.52	24.6722
2109.43	25.4626
2112.33	26.7206
2115.24	28.6137
2118.14	29.9851
2121.04	32.5129
2123.94	34.5542
2126.84	35.9637
2129.74	39.3658
2132.64	40.5376
2135.54	43.3644
2138.43	46.0904
2141.33	48.4433
2144.22	50.8811
2147.11	54.1381
2150.01	56.3214
2152.9	58.4599
2155.79	61.3404
2158.67	63.6899
2161.56	64.7926
2164.45	65.488
2167.33	65.1782
2170.22	65.6129
2173.1	66.2149
2175.98	66.0604
2178.86	65.2629
2181.74	64.6337
2184.62	64.0729
2187.5	62.0794
2190.38	60.8429
2193.25	58.9768
2196.13	58.2802
2199	56.5804
2201.88	54.9915
2204.75	53.8798
2207.62	52.3847
2210.49	50.2268
2213.36	48.018
2216.22	45.6166
2219.09	43.2226
2221.96	41.4442
2224.82	39.1766
2227.68	37.1378
2230.55	33.6575
2233.41	30.7768
2236.27	28.5732
2239.12	26.5815
2241.98	24.8279
2244.84	23.6643
2247.7	21.7547
2250.55	20.2895
2253.41	20.1452
2256.26	19.5352
2259.11	19.2676
2261.96	18.5988
2264.81	19.216
2267.66	19.423
2270.51	19.0412
2273.35	19.9217
2276.2	19.4485
2279.04	18.9496
2281.89	18.599
2284.73	18.7584
2287.57	18.6804
2290.41	17.0386
2293.25	14.984
2296.09	14.3784
2298.93	14.7926
2301.76	13.9733
2304.6	14.8528
2307.44	15.0258
2310.27	14.7818
2313.1	13.9963
2315.93	14.1788
2318.76	14.3037
2321.59	14.7184
2324.42	14.15
2327.25	13.5147
2330.07	12.7663
2332.9	12.5692
2335.72	11.9787
2338.55	11.0537
2341.37	11.0378
2344.19	9.8162
2347.01	8.06243
2349.83	7.51359
2352.65	7.40351
2355.46	5.86818
2358.28	3.86703
2361.09	3.13434
2363.91	3.6871
2366.72	4.30139
2369.53	3.74359
2372.34	4.01912
2375.15	4.43308
2377.96	4.08815
2380.77	3.03678
2383.58	2.40659
2386.38	3.16587
2389.19	3.72179
2391.99	3.41451
2394.8	3.1324
2397.6	3.17142
2400.4	3.86833
2403.2	4.16378
2406	4.71335
2408.79	5.12996
2411.59	5.21475
2414.39	5.71442
2417.18	5.69861
2419.98	6.3168
2422.77	6.93171
2425.56	6.71197
2428.35	7.0732
2431.14	7.43578
2433.93	7.00301
2436.72	6.55718
2439.5	7.01293
2442.29	7.04817
2445.07	6.65329
2447.86	4.92152
2450.64	4.48937
2453.42	3.36899
2456.2	2.79785
2458.98	1.87619
2461.76	1.5037
2464.54	1.63449
2467.32	1.36529
2470.09	1.10722
2472.87	1.8287
2475.64	1.97023
2478.41	2.50629
2481.18	1.85363
2483.95	1.99678
2486.72	2.45677
2489.49	2.73674
2492.26	3.54899
2495.03	2.94365
2497.79	3.37995
2500.56	3.48503
2503.32	3.97054
2506.09	4.2223
2508.85	4.79832
2511.61	4.96969
2514.37	4.90799
2517.13	4.49531
2519.89	5.10798
2522.64	5.49778
2525.4	4.58398
2528.15	4.19747
2530.91	3.9927
2533.66	3.41635
2536.41	3.08517
2539.16	3.34688
2541.91	2.50951
2544.66	2.19129
2547.41	2.25905
2550.16	2.32131
2552.9	2.94014
2555.65	2.87438
2558.39	3.6279
2561.13	3.60612
2563.88	3.61613
2566.62	4.0427
2569.36	4.19395
2572.1	4.19068
2574.84	4.16
2577.57	4.19588
2580.31	4.20857
2583.05	4.36615
2585.78	4.63081
2588.51	5.53735
2591.24	4.43233
2593.98	3.73068
2596.71	4.50341
2599.44	4.15649
2602.16	4.39509
2604.89	4.02983
2607.62	3.09843
2610.34	3.28719
2613.07	3.4187
2615.79	3.0159
2618.52	2.97126
2621.24	3.11851
2623.96	2.62876
2626.68	2.12669
2629.4	1.39981
2632.11	0.8292
2634.83	0.990935
2637.55	0.274046
2640.26	0.763375
2642.98	0.0596367
2645.69	0.310448
2648.4	0.504926
2651.11	1.76384
2653.82	2.06335
2656.53	2.46165
2659.24	2.42213
2661.95	3.02757
2664.65	3.54164
2667.36	4.08827
2670.06	3.6748
2672.76	3.86675
2675.47	3.94196
2678.17	4.34108
2680.87	3.99594
2683.57	4.53017
2686.27	5.32388
2688.97	5.04231
2691.66	5.55973
2694.36	5.61946
2697.05	6.27546
2699.75	6.82043
2702.44	7.53219
2705.13	8.27397
2707.82	8.6909
2710.51	8.67212
2713.2	9.9286
2715.89	10.7272
2718.57	11.0259
2721.26	10.9875
2723.95	11.7901
2726.63	11.8238
2729.31	11.5577
2732	11.6021
2734.68	11.0988
2737.36	10.6185
2740.04	10.2458
2742.72	9.51998
2745.39	8.79706
2748.07	8.4953
2750.75	7.94138
2753.42	7.15623
2756.09	6.38975
2758.77	6.32357
2761.44	6.00062
2764.11	4.92824
2766.78	4.74157
2769.45	4.66005
2772.12	5.17049
2774.78	5.30084
2777.45	5.81199
2780.12	6.70869
2782.78	7.00514
2785.44	7.16652
2788.11	7.79238
2790.77	7.50544
2793.43	7.27977
2796.09	7.4608
2798.75	6.57542
2801.4	4.91176
2804.06	4.89644
2806.72	4.69526
2809.37	4.53203
2812.03	4.08316
2814.68	4.5577
2817.33	5.52779
2819.98	6.96469
2822.63	8.22519
2825.28	10.5524
2827.93	11.7965
2830.58	13.9847
2833.23	16.8868
2835.87	19.909
2838.52	23.3666
2841.16	27.836
2843.8	33.3669
2846.44	37.99
2849.08	44.1901
2851.73	50.7843
2854.36	58.4203
2857	65.7721
2859.64	72.2467
2862.28	78.8001
2864.91	85.1083
2867.55	90.6877
2870.18	97.0226
2872.81	101.292
2875.44	106.101
2878.07	109.996
2880.7	114.28
2883.33	117.324
2885.96	120.378
2888.59	123.704
2891.21	126.982
2893.84	130.246
2896.46	134.344
2899.09	138.671
2901.71	144.519
2904.33	151.531
2906.95	159.295
2909.57	167.247
2912.19	176.607
2914.81	186.34
2917.43	195.865
2920.04	204.104
2922.66	210.75
2925.27	215.494
2927.88	219.584
2930.5	221.12
2933.11	221.425
2935.72	220.327
2938.33	217.338
2940.94	213.813
2943.54	208.471
2946.15	203.412
2948.76	196.206
2951.36	189.14
2953.97	181.983
2956.57	174.332
2959.17	166.956
2961.77	159.51
2964.37	151.801
2966.97	144.21
2969.57	137.223
2972.17	130.598
2974.77	124.005
2977.36	117.391
2979.96	111.044
2982.55	103.775
2985.15	96.013
2987.74	89.4267
2990.33	81.7855
2992.92	74.9331
2995.51	68.229
2998.1	62.5586
3000.69	56.7533
3003.27	52.0444
3005.86	47.3951
3008.44	43.6518
3011.03	39.6066
3013.61	35.7591
3016.19	32.4227
3018.78	29.8658
3021.36	27.6439
3023.94	26.0465
3026.51	24.2237
3029.09	22.9613
3031.67	22.8453
3034.24	22.9888
3036.82	23.0627
3039.39	23.2493
3041.97	23.3075
3044.54	23.6538
3047.11	23.9073
3049.68	23.9884
3052.25	24.6679
3054.82	25.5146
3057.39	25.7172
3059.96	25.6072
3062.52	25.2296
3065.09	23.7309
3067.65	21.4916
3070.22	19.9765
3072.78	18.2397
3075.34	15.9865
3077.9	14.9858
3080.46	13.9287
3083.02	12.8606
3085.58	11.2184
3088.14	9.39295
3090.69	8.53212
3093.25	7.83699
3095.8	6.98815
3098.36	6.09604
3100.91	5.74964
3103.46	4.41293
3106.01	4.30475
3108.56	3.91641
3111.11	3.65912
3113.66	3.57353
3116.21	3.93185
3118.76	3.71049
3121.3	3.05034
3123.85	2.61245
3126.39	1.6236
3128.93	0.327952
3131.48	0.491813
3134.02	0.427166
3136.56	-0.0620696
3139.1	0.569686
3141.64	0.409231
3144.17	-0.196775
3146.71	-0.167681
3149.25	0.195327