File: data/Raman/poly_smoothed/Thy_00_07_44_1x_45s_532 nm_x100_100%_600 gr_mm_01_0.txt
#Acq. time (s)=	45
#Accumulations=	2
#Range (cm-¹)=	200...3150
#Windows=	2
#Auto scanning=	Off
#Autofocus=	Off
#Macrospot=	Off
#AutoExposure=	Off
#Spike filter=	Multiple accum.
#Delay time (s)=	0
#Binning=	1
#Readout mode=	Signal
#DeNoise=	Off
#ICS correction=	On
#Dark correction=	Off
#Inst. Process=	Off
#Detector Gain=	Best Dynamic Range
#Detector ADC=	20 kHz
#Detector temperature (°C)=	-69.85
#Instrument=	LabRAM HR Evol
#Detector=	Synapse
#Objective=	x100
#Grating=	600 gr/mm
#ND Filter=	100%
#Laser (nm)=	532
#Hole=	100.021
#Range=	Auto
#Laser Pol.=	No
#Raman. Pol.=	No
#Laser Pol. (°)=	-0.0007625
#Raman Pol. (°)=	89.9995
#Collection=	Microscope
#StageXY=	Marzhauser
#StageZ=	Marzhauser
#X (µm)=	-1439.6
#Y (µm)=	-615.3
#Z (µm)=	-227.95
#Full time(mm:ss)=	3:18
#Project=
#Sample=
#Site=
#Title=	Thy_00_07_44_2x_45s_532 nm_x100_100%_600 gr_mm
#Remark=
#Date=	29.06.2022 09:37
#Acquired=	29.06.2022 09:37:24
#Base:Fit=	10.08.2022 10:07:56
#Base:Sub=	10.08.2022 10:08:40
#Filter:Polynom=	16.08.2022 10:26:06
#AxisType[0]=Intens
#AxisUnit[0]=Cnt
#AxisType[1]=Spectr
#AxisUnit[1]=1/cm
200.523	39.755
204.154	34.2676
207.781	29.593
211.409	26.2141
215.034	24.3673
218.659	21.915
222.281	18.4062
225.903	16.8848
229.522	15.675
233.14	13.0506
236.756	11.5464
240.373	10.3142
243.986	9.12275
247.598	9.06624
251.208	8.06514
254.818	7.60946
258.427	7.18159
262.034	6.38727
265.638	5.18162
269.242	5.1226
272.844	3.90248
276.445	3.5554
280.044	3.66863
283.642	3.35382
287.238	3.37673
290.833	5.25547
294.425	6.93181
298.017	8.46339
301.608	10.0837
305.198	10.3871
308.786	11.8866
312.371	12.9052
315.956	13.4613
319.54	13.2607
323.122	13.8329
326.701	14.1208
330.281	14.1139
333.857	14.6725
337.434	14.0559
341.008	13.6763
344.582	11.9145
348.153	9.99766
351.724	8.11787
355.292	6.90986
358.861	5.87808
362.426	5.14311
365.99	4.73063
369.555	4.18941
373.116	3.16441
376.676	3.28165
380.236	3.15892
383.793	2.45716
387.349	1.80448
390.903	1.69434
394.456	1.502
398.007	1.43428
401.56	1.20449
405.108	1.49657
408.656	1.51571
412.202	2.34664
415.746	1.75563
419.29	3.21351
422.831	3.75114
426.37	3.33373
429.909	2.95302
433.447	3.44573
436.983	5.59622
440.519	5.78362
444.052	5.69269
447.583	6.10215
451.114	7.7854
454.643	8.80864
458.169	8.80842
461.696	8.87102
465.222	9.23809
468.744	11.459
472.267	11.2824
475.787	12.5599
479.307	13.9478
482.823	14.1162
486.341	15.4302
489.855	17.6768
493.37	18.7875
496.881	20.6678
500.391	21.7156
503.902	21.9186
507.409	22.4912
510.915	22.2725
514.42	23.5304
517.925	25.5356
521.427	26.8464
524.928	26.3671
528.427	24.3095
531.925	23.9475
535.422	23.6109
538.917	21.1673
542.411	20.0897
545.903	18.406
549.395	16.0049
552.884	15.3619
556.373	13.6829
559.86	11.6057
563.346	11.5865
566.831	10.2086
570.314	9.24372
573.794	9.80387
577.274	8.54343
580.754	6.32403
584.23	5.46585
587.706	5.21309
591.181	4.90501
594.653	5.50258
598.126	5.60161
601.595	6.62108
605.065	7.81966
608.532	8.71594
611.999	8.03697
615.463	8.43838
618.928	8.51766
622.389	8.45764
625.851	9.72442
629.31	9.08333
632.767	8.88099
636.223	9.73434
639.68	10.7809
643.134	13.2167
646.586	14.7385
650.037	15.6647
653.486	16.9532
656.936	17.5864
660.383	16.8579
663.829	17.3615
667.273	19.3442
670.716	22.4124
674.158	23.9471
677.598	23.5893
681.035	24.6367
684.473	25.9149
687.909	29.9313
691.344	32.4767
694.778	33.0963
698.211	34.188
701.64	35.6503
705.07	36.4463
708.498	37.6596
711.924	39.6049
715.35	39.2603
718.774	42.6509
722.196	43.2928
725.618	47.109
729.037	49.2816
732.456	49.2753
735.873	50.0672
739.289	51.5949
742.703	52.7715
746.116	56.0076
749.529	60.2271
752.938	62.0496
756.347	63.2094
759.756	64.7175
763.162	65.5698
766.567	67.289
769.97	69.0396
773.372	71.126
776.773	71.5855
780.174	72.7614
783.573	74.3393
786.97	74.3528
790.365	75.4548
793.76	76.9842
797.153	78.0422
800.543	80.1223
803.933	79.9179
807.322	79.1982
810.71	81.3503
814.097	79.3509
817.483	79.7647
820.865	80.751
824.248	82.576
827.629	82.8667
831.008	81.9787
834.387	80.0954
837.765	77.1081
841.139	74.9595
844.514	71.6865
847.886	68.3995
851.259	65.3725
854.629	63.5536
857.997	60.3974
861.366	58.2798
864.732	56.3429
868.098	53.0826
871.461	51.3225
874.823	50.1673
878.184	50.3993
881.545	49.642
884.903	49.1687
888.26	48.1916
891.616	49.4037
894.97	50.461
898.323	51.4505
901.675	53.5231
905.026	54.5247
908.375	55.9995
911.723	56.5577
915.07	56.6523
918.415	55.8557
921.76	55.2961
925.103	55.2982
928.443	56.0626
931.783	54.3596
935.123	52.342
938.461	49.4702
941.796	47.6734
945.131	46.0759
948.465	42.8771
951.797	40.3169
955.128	38.015
958.457	33.679
961.786	32.3754
965.113	33.5006
968.44	34.41
971.763	35.0361
975.086	36.7874
978.409	37.2001
981.729	37.3207
985.048	36.7052
988.367	35.5048
991.683	35.1258
994.998	35.0052
998.312	34.459
1001.62	35.2201
1004.94	35.7703
1008.25	37.1576
1011.56	37.2871
1014.86	35.7121
1018.17	33.9432
1021.48	32.7356
1024.78	31.0652
1028.08	29.3994
1031.38	26.833
1034.68	23.2232
1037.98	22.2756
1041.28	21.8006
1044.57	22.9814
1047.87	23.9192
1051.16	22.0132
1054.45	21.4225
1057.75	19.0173
1061.04	16.2316
1064.32	15.102
1067.61	13.5659
1070.9	13.8513
1074.18	15.0711
1077.47	15.3737
1080.75	16.701
1084.03	17.4469
1087.31	17.8689
1090.59	19.1838
1093.86	20.9066
1097.14	21.4067
1100.41	23.3975
1103.69	24.3391
1106.96	24.0097
1110.23	23.1731
1113.5	23.0344
1116.77	22.8956
1120.03	21.1902
1123.3	19.5223
1126.56	18.1816
1129.83	17.1425
1133.09	16.3586
1136.35	15.6543
1139.61	14.1936
1142.86	12.97
1146.12	12.084
1149.38	11.5242
1152.63	10.4985
1155.88	9.12278
1159.14	8.77158
1162.39	7.43437
1165.63	6.06366
1168.88	5.61655
1172.13	7.44198
1175.38	9.21794
1178.62	9.67289
1181.86	9.57299
1185.1	8.97284
1188.34	9.50825
1191.58	11.3655
1194.82	11.6868
1198.06	11.2447
1201.29	12.0663
1204.53	14.1084
1207.76	17.1253
1210.99	19.9132
1214.22	22.8695
1217.45	26.6651
1220.68	29.8065
1223.91	34.5991
1227.13	37.9537
1230.36	40.502
1233.58	42.4768
1236.8	44.4535
1240.02	46.9318
1243.24	48.6509
1246.46	50.7678
1249.67	52.5478
1252.89	52.1497
1256.1	51.9138
1259.32	50.3031
1262.53	49.4373
1265.74	46.7826
1268.95	45.8895
1272.15	43.3874
1275.36	42.0744
1278.57	42.5616
1281.77	44.924
1284.97	46.8022
1288.18	48.0284
1291.38	50.4591
1294.58	52.047
1297.78	53.7932
1300.97	57.3307
1304.17	59.6461
1307.36	62.2082
1310.55	66.3134
1313.75	70.2521
1316.94	73.3006
1320.13	76.347
1323.32	76.2152
1326.5	76.7845
1329.69	75.9831
1332.87	73.2184
1336.06	72.8439
1339.24	71.6416
1342.42	69.1831
1345.6	67.528
1348.78	65.8431
1351.96	62.4237
1355.13	60.9507
1358.31	58.3271
1361.48	53.9146
1364.65	50.7964
1367.82	46.6431
1370.99	44.6196
1374.16	42.9519
1377.33	43.1587
1380.5	41.767
1383.66	41.5638
1386.83	42.4344
1389.99	41.0058
1393.15	40.6417
1396.31	40.077
1399.47	38.0955
1402.63	38.6063
1405.78	39.9966
1408.94	40.6012
1412.1	43.9016
1415.25	47.1424
1418.4	50.0116
1421.55	54.1113
1424.7	58.0508
1427.85	62.8562
1431	67.2463
1434.14	71.9717
1437.29	74.6186
1440.43	78.2522
1443.57	82.0435
1446.71	83.9347
1449.85	86.2316
1452.99	86.5781
1456.13	85.9566
1459.26	81.5971
1462.4	78.5577
1465.54	73.4698
1468.67	67.9086
1471.8	62.6407
1474.93	55.4369
1478.06	49.4246
1481.19	44.1954
1484.31	38.3375
1487.44	33.0656
1490.56	27.4354
1493.69	23.679
1496.81	20.9057
1499.93	18.7239
1503.05	16.2059
1506.17	15.4033
1509.28	12.9535
1512.4	11.7052
1515.52	10.4286
1518.63	10.2044
1521.74	10.418
1524.85	9.90984
1527.96	11.6856
1531.07	13.9699
1534.18	14.7346
1537.29	19.062
1540.39	21.9155
1543.5	24.2547
1546.6	28.1802
1549.7	31.3233
1552.8	36.0996
1555.9	41.0969
1559	44.8485
1562.1	47.2666
1565.19	50.9445
1568.29	55.2188
1571.38	57.7685
1574.47	60.1895
1577.56	62.5576
1580.66	64.512
1583.74	66.5657
1586.83	66.9928
1589.92	66.8329
1593.01	67.195
1596.09	65.4686
1599.17	63.9193
1602.25	63.8294
1605.34	63.1914
1608.41	62.2102
1611.49	60.4849
1614.57	57.7678
1617.65	55.115
1620.72	55.0655
1623.79	54.9905
1626.87	55.9878
1629.94	56.9146
1633.01	58.4848
1636.08	60.284
1639.15	63.9387
1642.21	68.2689
1645.28	70.7806
1648.34	72.8949
1651.41	75.1487
1654.47	78.6565
1657.53	80.9733
1660.59	82.1636
1663.65	81.1079
1666.71	79.2254
1669.76	75.9729
1672.82	72.793
1675.87	69.9431
1678.93	64.6517
1681.98	58.3553
1685.03	51.1164
1688.08	44.399
1691.13	39.485
1694.17	34.3208
1697.22	30.1904
1700.27	25.7144
1703.31	22.1344
1706.35	18.472
1709.39	16.796
1712.43	14.7032
1715.47	13.4891
1718.51	11.5667
1721.55	9.66641
1724.58	8.69284
1727.62	8.84893
1730.65	9.86685
1733.68	8.8787
1736.72	7.3155
1739.74	7.22976
1742.77	6.24064
1745.8	5.92647
1748.83	5.43189
1751.85	4.65999
1754.88	3.66281
1757.9	2.07653
1760.92	2.31227
1763.95	2.36597
1766.96	1.87651
1769.98	1.8668
1773	2.21622
1776.02	2.06319
1779.03	2.04
1782.05	2.22942
1785.06	2.30135
1788.07	1.98535
1791.08	2.10187
1794.09	1.50865
1797.1	1.17064
1800.11	1.23774
1803.12	0.850346
1806.12	0.385873
1809.12	0.274296
1812.13	0.668095
1815.13	0.573809
1818.13	0.588533
1821.13	0.500076
1824.13	0.73859
1827.13	0.661533
1830.12	0.498019
1833.12	0.179649
1836.11	0.163748
1839.1	0.944384
1842.09	1.3049
1845.09	1.66227
1848.08	2.10705
1851.06	2.00505
1854.05	2.15671
1857.04	2.37979
1860.02	2.3012
1863.01	2.58635
1865.99	3.09914
1868.97	3.11551
1871.95	3.28708
1874.93	2.92095
1877.91	2.58534
1880.89	3.44291
1882.46	3.29227
1885.45	2.78527
1888.43	2.41922
1891.42	2.8561
1894.41	2.70574
1897.39	2.25134
1900.37	2.03962
1903.36	2.02439
1906.34	2.74995
1909.32	3.69766
1912.29	4.25708
1915.27	5.67669
1918.25	6.38886
1921.23	6.22042
1924.2	7.4443
1927.17	8.10804
1930.15	8.47986
1933.12	8.55757
1936.09	8.99963
1939.06	9.2353
1942.02	9.14214
1944.99	8.36504
1947.96	7.94135
1950.92	7.96229
1953.88	7.85766
1956.85	6.42361
1959.81	5.64716
1962.77	4.71438
1965.73	4.54716
1968.69	3.76503
1971.64	2.72148
1974.6	3.32241
1977.55	3.56938
1980.51	4.28438
1983.46	4.70918
1986.41	6.38846
1989.36	7.37378
1992.31	7.71905
1995.26	8.07562
1998.21	9.22575
2001.15	9.24385
2004.1	9.18125
2007.04	9.28499
2009.99	8.83995
2012.93	8.46913
2015.87	7.5807
2018.81	7.92612
2021.75	7.51203
2024.68	6.3043
2027.62	5.71837
2030.56	5.15868
2033.49	4.63726
2036.42	4.43374
2039.36	3.34922
2042.29	2.47816
2045.22	2.38659
2048.14	2.67048
2051.07	3.60172
2054	4.49095
2056.93	5.59279
2059.85	5.496
2062.77	5.91557
2065.7	7.18624
2068.62	7.73339
2071.54	7.98131
2074.46	7.27284
2077.38	8.19072
2080.29	8.14744
2083.21	8.43612
2086.12	8.6575
2089.04	10.0808
2091.95	10.3684
2094.86	9.84829
2097.77	10.3931
2100.68	10.1763
2103.59	9.5821
2106.5	9.05838
2109.41	8.98724
2112.31	8.09295
2115.21	7.27123
2118.12	6.68294
2121.02	7.22161
2123.92	6.86819
2126.82	6.12121
2129.72	5.85152
2132.62	5.57733
2135.51	5.17454
2138.41	3.79699
2141.31	3.26067
2144.2	3.4806
2147.09	3.74556
2149.98	3.10648
2152.87	4.24959
2155.76	4.34004
2158.65	5.71241
2161.54	6.90129
2164.43	7.02052
2167.31	7.93521
2170.2	8.92614
2173.08	8.97574
2175.96	9.40289
2178.84	9.58884
2181.72	9.79041
2184.6	9.37085
2187.48	9.3165
2190.36	9.77647
2193.23	8.86867
2196.11	7.73027
2198.98	6.26796
2201.85	4.71448
2204.72	4.10473
2207.59	3.54652
2210.46	2.37977
2213.33	2.43948
2216.2	2.8401
2219.07	2.99933
2221.93	3.91029
2224.8	4.58967
2227.66	4.99912
2230.52	5.20477
2233.39	5.88705
2236.25	6.14337
2239.1	7.01345
2241.96	6.70191
2244.82	7.82116
2247.68	8.71781
2250.53	9.21676
2253.38	9.02916
2256.24	9.08362
2259.09	9.22841
2261.94	8.41937
2264.79	8.14457
2267.64	8.2158
2270.49	7.80131
2273.33	7.63872
2276.18	8.58308
2279.02	8.55853
2281.87	8.94152
2284.71	9.38261
2287.55	9.80891
2290.39	8.91486
2293.23	7.78982
2296.07	7.86135
2298.91	7.74257
2301.74	8.14775
2304.58	8.95937
2307.41	8.8054
2310.25	9.57274
2313.08	9.74119
2315.91	10.8281
2318.74	9.62761
2321.57	8.83431
2324.4	8.32475
2327.23	7.79853
2330.05	7.47735
2332.88	7.29455
2335.7	6.47903
2338.52	5.31849
2341.35	4.59976
2344.17	3.69085
2346.99	3.39782
2349.81	2.44409
2352.62	1.25411
2355.44	0.959467
2358.26	-0.109634
2361.07	-0.896869
2363.89	-0.451401
2366.7	0.77363
2369.51	1.71052
2372.32	1.80544
2375.13	1.96937
2377.94	2.46616
2380.75	2.69107
2383.56	2.46909
2386.36	1.78114
2389.17	1.41733
2391.97	1.60447
2394.77	2.51462
2397.58	2.55738
2400.38	2.35713
2403.18	2.64681
2405.97	3.03253
2408.77	4.15136
2411.57	5.2231
2414.37	6.29629
2417.16	6.9538
2419.95	7.17962
2422.75	7.41268
2425.54	7.93957
2428.33	7.71369
2431.12	8.48294
2433.91	8.40219
2436.7	7.96534
2439.48	7.77089
2442.27	6.83371
2445.05	5.6931
2447.84	4.34712
2450.62	4.40337
2453.4	3.32999
2456.18	3.08056
2458.96	2.15371
2461.74	1.2889
2464.52	0.919006
2467.29	1.06254
2470.07	0.542077
2472.85	1.10428
2475.62	1.2206
2478.39	1.854
2481.16	2.53342
2483.93	2.78658
2486.7	2.72387
2489.47	2.97198
2492.24	3.68878
2495.01	3.57648
2497.77	3.37049
2500.54	2.97706
2503.3	2.00153
2506.06	2.11478
2508.83	2.49949
2511.59	2.75735
2514.35	2.14683
2517.11	2.76549
2519.86	2.83533
2522.62	2.70988
2525.38	2.69247
2528.13	2.26604
2530.89	2.16707
2533.64	2.82225
2536.39	2.37515
2539.14	2.78356
2541.89	3.20862
2544.64	2.84452
2547.39	3.72693
2550.14	3.58249
2552.88	3.87336
2555.63	3.88786
2558.37	4.24273
2561.11	3.68479
2563.86	2.80977
2566.6	2.71167
2569.34	2.61541
2572.08	1.92857
2574.82	2.0639
2577.55	1.67391
2580.29	1.6368
2583.02	1.37245
2585.76	0.858679
2588.49	0.904305
2591.22	0.11154
2593.96	0.766954
2596.69	0.638964
2599.42	0.688386
2602.14	1.38557
2604.87	2.02129
2607.6	2.05997
2610.32	2.36516
2613.05	2.70041
2615.77	2.98508
2618.49	3.02639
2621.22	2.70104
2623.94	2.14665
2626.66	1.65352
2629.37	1.74448
2632.09	1.59818
2634.81	1.20773
2637.53	1.69012
2640.24	1.78953
2642.96	2.11191
2645.67	1.78768
2648.38	1.88756
2651.09	1.00643
2653.8	3.04698
2656.51	3.59323
2659.22	4.24352
2661.93	5.52443
2664.63	5.63511
2667.34	5.78563
2670.04	6.4625
2672.75	6.86967
2675.45	6.8778
2678.15	7.56715
2680.85	7.23942
2683.55	6.44974
2686.25	6.49187
2688.94	6.52804
2691.64	6.6609
2694.34	7.05183
2697.03	6.90197
2699.73	6.74392
2702.42	6.81971
2705.11	7.58419
2707.8	7.69636
2710.49	8.0744
2713.18	8.56145
2715.87	9.4486
2718.55	10.4519
2721.24	11.6031
2723.93	11.7921
2726.61	11.3296
2729.29	11.6571
2731.98	11.0187
2734.66	10.9845
2737.34	12.071
2740.02	11.7498
2742.7	11.4905
2745.37	11.3751
2748.05	10.2818
2750.72	10.2902
2753.4	9.75349
2756.07	9.01189
2758.75	7.18429
2761.42	6.24432
2764.09	5.21486
2766.76	4.43102
2769.43	4.19598
2772.1	4.30912
2774.76	3.28649
2777.43	2.47061
2780.1	1.97881
2782.76	1.35583
2785.42	2.04241
2788.09	0.85559
2790.75	0.199015
2793.41	-0.0204501
2796.07	-0.237814
2798.73	-0.463719
2801.39	-0.103143
2804.04	-0.325174
2806.7	-0.961686
2809.35	-0.0300499
2812.01	-0.483499
2814.66	-0.2798
2817.31	1.48815
2819.96	2.83906
2822.61	4.87114
2825.26	7.68567
2827.91	10.9694
2830.56	14.5752
2833.21	18.9658
2835.85	24.1771
2838.5	30.4834
2841.14	37.0418
2843.78	45.1994
2846.42	55.0214
2849.06	66.04
2851.71	76.7553
2854.34	87.4346
2856.98	98.0501
2859.62	108.02
2862.26	117.907
2864.89	127.388
2867.53	136.495
2870.16	144.505
2872.79	152.63
2875.42	158.895
2878.05	165.354
2880.68	171.981
2883.31	176.845
2885.94	181.297
2888.57	185.269
2891.19	189.294
2893.82	194.497
2896.44	200.043
2899.07	206.065
2901.69	213.849
2904.31	224.007
2906.93	234.97
2909.55	246.9
2912.17	259.321
2914.79	271.265
2917.41	282.1
2920.02	290.05
2922.64	296.788
2925.25	301.563
2927.86	303.626
2930.48	304.794
2933.09	302.94
2935.7	299.654
2938.31	294.775
2940.92	286.747
2943.53	278.981
2946.13	268.146
2948.74	256.788
2951.34	246.595
2953.95	236.039
2956.55	224.895
2959.15	215.06
2961.75	205.42
2964.35	196.652
2966.95	188.838
2969.55	180.76
2972.15	173.28
2974.75	165.647
2977.34	157.242
2979.94	147.828
2982.53	137.728
2985.13	126.533
2987.72	116.623
2990.31	106.69
2992.9	95.8974
2995.49	85.7847
2998.08	75.8608
3000.67	66.6392
3003.25	56.8489
3005.84	48.7437
3008.42	41.2786
3011.01	35.4121
3013.59	29.8108
3016.17	25.6196
3018.76	22.0758
3021.34	18.2363
3023.92	16.164
3026.49	14.0482
3029.07	12.265
3031.65	10.1607
3034.23	10.2885
3036.8	10.3803
3039.38	10.5505
3041.95	11.5971
3044.52	12.8656
3047.09	14.4175
3049.66	16.2041
3052.23	17.1821
3054.8	17.5341
3057.37	17.8818
3059.94	18.7032
3062.5	19.1393
3065.07	19.0648
3067.63	18.6312
3070.2	18.3383
3072.76	17.027
3075.32	15.435
3077.88	13.8913
3080.44	12.1474
3083	10.3927
3085.56	8.71524
3088.12	6.51295
3090.67	4.19383
3093.23	2.72505
3095.78	1.714
3098.34	1.51582
3100.89	1.35836
3103.44	1.35208
3105.99	2.13424
3108.54	2.28492
3111.09	2.75046
3113.64	3.03812
3116.19	2.97842
3118.74	4.05687
3121.28	5.24064
3123.83	6.34756
3126.37	6.72412
3128.91	7.72863
3131.46	7.97082
3134	8.3869
3136.54	9.11736
3139.08	10.2615
3141.62	11.0546
3144.16	11.5338
3146.69	11.2239
3149.23	11.9489