File: data/Raman/poly_smoothed/Thy_10_08_26_1x_45s_532 nm_x100_100%_600 gr_mm_01.txt
#Acq. time (s)=	45
#Accumulations=	2
#Range (cm-¹)=	200...3150
#Windows=	2
#Auto scanning=	Off
#Autofocus=	Off
#Macrospot=	Off
#AutoExposure=	Off
#Spike filter=	Multiple accum.
#Delay time (s)=	0
#Binning=	1
#Readout mode=	Signal
#DeNoise=	Off
#ICS correction=	On
#Dark correction=	Off
#Inst. Process=	Off
#Detector Gain=	Best Dynamic Range
#Detector ADC=	20 kHz
#Detector temperature (°C)=	-69.85
#Instrument=	LabRAM HR Evol
#Detector=	Synapse
#Objective=	x100
#Grating=	600 gr/mm
#ND Filter=	100%
#Laser (nm)=	532
#Hole=	100.021
#Range=	Auto
#Laser Pol.=	No
#Raman. Pol.=	No
#Laser Pol. (°)=	-0.0007625
#Raman Pol. (°)=	89.9995
#Collection=	Microscope
#StageXY=	Marzhauser
#StageZ=	Marzhauser
#X (µm)=	2212.6
#Y (µm)=	1214.8
#Z (µm)=	442.55
#Full time(mm:ss)=	3:18
#Project=
#Sample=
#Site=
#Title=	Thy_10_08_26_2x_45s_532 nm_x100_100%_600 gr_mm
#Remark=
#Date=	05.07.2022 16:05
#Acquired=	05.07.2022 16:05:26
#Base:Fit=	10.08.2022 09:46:25
#Base:Sub=	10.08.2022 09:46:49
#Filter:Polynom=	16.08.2022 10:24:56
#AxisType[0]=Intens
#AxisUnit[0]=Cnt
#AxisType[1]=Spectr
#AxisUnit[1]=1/cm
200.43	-0.458699
204.059	-1.47536
207.688	1.99593
211.314	3.27791
214.941	3.60937
218.564	2.66572
222.186	2.61676
225.809	2.44214
229.428	4.1205
233.045	4.10019
236.663	4.47227
240.278	6.06375
243.891	6.47858
247.503	7.40458
251.116	7.61403
254.725	8.99445
258.333	9.60858
261.939	11.6053
265.544	11.4351
269.148	12.2773
272.75	12.699
276.351	15.264
279.95	16.0609
283.548	15.6628
287.144	16.9982
290.739	17.7394
294.333	18.2435
297.925	17.0477
301.514	17.0809
305.104	18.6222
308.692	18.8365
312.279	19.4123
315.862	20.7558
319.446	19.5013
323.029	19.5337
326.608	19.321
330.188	20.3015
333.766	20.1754
337.341	20.1649
340.917	18.3183
344.489	18.1989
348.062	17.2436
351.631	16.9379
355.201	14.9778
358.768	15.0236
362.333	13.9741
365.899	13.6044
369.462	11.734
373.023	10.7339
376.585	11.3391
380.143	9.26914
383.7	8.78212
387.256	8.99003
390.812	9.28708
394.365	9.63402
397.916	9.15025
401.467	7.83781
405.015	6.64514
408.563	6.70999
412.109	7.21851
415.654	6.66771
419.197	6.16928
422.739	5.99925
426.279	6.16119
429.819	6.14464
433.356	6.07556
436.891	6.36873
440.426	5.82849
443.96	6.01243
447.492	7.38715
451.021	6.62667
454.551	7.70076
458.079	8.32533
461.604	10.0666
465.13	9.44786
468.654	10.2983
472.175	11.4532
475.696	13.2823
479.215	15.1783
482.733	14.9607
486.249	14.8747
489.765	16.5912
493.278	17.0518
496.789	18.4215
500.301	19.54
503.81	21.9288
507.317	21.9112
510.825	22.7077
514.33	23.5453
517.833	23.1362
521.335	23.5072
524.836	22.9225
528.335	21.5805
531.835	20.559
535.332	19.7089
538.827	18.384
542.321	18.7514
545.814	17.7576
549.305	14.7321
552.795	12.2269
556.282	10.4058
559.769	10.2803
563.255	9.21732
566.739	9.51125
570.223	6.98742
573.705	5.70612
577.183	4.75391
580.663	3.19685
584.141	4.28096
587.615	4.56013
591.09	4.57765
594.564	2.98987
598.035	2.25014
601.506	2.31761
604.974	3.21118
608.443	4.86653
611.908	3.3181
615.374	5.23959
618.837	6.73421
622.3	7.33151
625.761	9.34153
629.219	10.7344
632.677	11.7154
636.135	13.2999
639.59	17.0556
643.043	19.4098
646.495	22.0204
649.948	24.77
653.398	27.2628
656.846	27.4344
660.293	29.5978
663.738	30.3216
667.183	30.9939
670.626	32.3852
674.067	32.0943
677.508	32.3819
680.947	32.1993
684.385	31.7552
687.821	31.2317
691.254	30.1084
694.688	29.3009
698.121	30.042
701.552	30.354
704.98	29.735
708.409	30.2978
711.836	32.7113
715.26	35.6328
718.685	35.8097
722.108	37.0886
725.528	39.1834
728.949	42.7874
732.367	44.8818
735.785	47.6928
739.2	49.6461
742.614	51.5041
746.028	54.1327
749.439	55.5191
752.849	58.0331
756.26	61.501
759.667	64.401
763.073	65.6794
766.477	66.2804
769.883	68.4102
773.285	69.4498
776.686	71.876
780.085	74.7648
783.484	76.2687
786.881	79.76
790.276	80.8116
793.671	81.8037
797.064	82.9746
800.456	84.3183
803.846	84.4073
807.234	86.7666
810.622	88.3141
814.008	89.5381
817.394	90.2743
820.778	90.9235
824.159	89.6357
827.541	87.9999
830.921	87.7957
834.298	87.4459
837.676	86.0874
841.051	84.4153
844.426	81.1289
847.798	79.8316
851.171	77.6152
854.54	74.8004
857.911	72.3845
861.278	71.087
864.645	68.1268
868.01	65.2614
871.373	63.2355
874.735	60.4369
878.097	60.1214
881.457	60.7036
884.815	59.7806
888.172	59.0412
891.528	59.4961
894.882	58.8944
898.237	59.1655
901.589	58.1307
904.94	57.8068
908.289	57.4884
911.635	57.7798
914.982	57.6686
918.328	56.9401
921.672	55.9161
925.015	54.4661
928.357	52.8325
931.698	53.4027
935.035	52.7647
938.373	53.1443
941.71	50.612
945.044	47.8466
948.378	46.343
951.709	45.2166
955.041	44.5595
958.372	42.3694
961.699	39.569
965.027	39.3242
968.352	37.6188
971.676	37.6106
975	38.4509
978.322	38.4389
981.642	38.6153
984.962	38.0644
988.28	37.7119
991.596	36.2659
994.911	34.4034
998.227	33.4875
1001.54	33.0711
1004.85	31.8399
1008.16	31.518
1011.47	30.5584
1014.78	28.7462
1018.08	28.2632
1021.39	24.9072
1024.69	23.5817
1028	21.6413
1031.3	21.951
1034.6	20.6955
1037.9	20.0954
1041.19	19.5719
1044.49	20.783
1047.78	21.6705
1051.08	22.0834
1054.37	22.3159
1057.66	23.0458
1060.95	21.9177
1064.24	20.8988
1067.53	21.256
1070.81	20.4447
1074.1	20.7591
1077.38	21.6854
1080.66	20.88
1083.94	20.9543
1087.22	20.829
1090.5	21.0071
1093.78	21.238
1097.05	20.661
1100.33	21.3845
1103.6	20.2469
1106.87	20.6376
1110.14	20.3063
1113.41	20.0724
1116.68	19.2223
1119.95	17.8809
1123.21	15.8423
1126.48	14.0502
1129.74	13.31
1133	11.7203
1136.26	9.969
1139.52	9.15238
1142.78	8.78856
1146.04	7.88039
1149.29	8.35979
1152.55	7.84847
1155.8	7.83278
1159.05	6.89304
1162.3	5.45752
1165.55	4.87284
1168.8	6.22313
1172.05	6.41866
1175.29	6.8193
1178.54	6.66722
1181.78	7.33711
1185.02	8.24566
1188.26	9.64388
1191.5	10.4071
1194.74	10.7286
1197.97	9.85025
1201.21	12.6888
1204.44	15.7998
1207.68	17.336
1210.91	20.2762
1214.14	22.3671
1217.37	25.9238
1220.59	28.4038
1223.82	30.4515
1227.05	35.3943
1230.27	38.5262
1233.49	41.7203
1236.72	43.31
1239.94	45.8962
1243.16	48.6671
1246.37	52.1404
1249.59	54.3225
1252.8	54.9476
1256.02	54.4355
1259.23	54.9934
1262.44	54.7286
1265.66	55.2652
1268.86	55.1726
1272.07	54.534
1275.28	53.4184
1278.48	54.4864
1281.69	54.6478
1284.89	53.9935
1288.09	55.2427
1291.29	55.6551
1294.49	54.7365
1297.69	55.1939
1300.89	56.3417
1304.08	59.7936
1307.28	62.2423
1310.47	64.4086
1313.66	65.1056
1316.85	66.7964
1320.04	69.9051
1323.23	70.6929
1326.42	70.7418
1329.61	70.365
1332.79	68.4771
1335.97	67.7416
1339.16	66.0243
1342.34	64.537
1345.52	63.5065
1348.7	61.0027
1351.87	59.0565
1355.05	56.3773
1358.22	53.3066
1361.4	50.9498
1364.57	49.6684
1367.74	47.7343
1370.91	45.122
1374.08	41.8743
1377.25	40.1862
1380.41	38.9705
1383.58	37.2123
1386.74	35.9715
1389.91	34.872
1393.07	35.0327
1396.23	33.2397
1399.39	31.5761
1402.55	30.1061
1405.7	29.86
1408.86	30.305
1412.01	30.2868
1415.17	32.0877
1418.32	34.9781
1421.47	38.1036
1424.62	42.4833
1427.77	47.7132
1430.91	54.3654
1434.06	57.9996
1437.2	61.5479
1440.35	66.02
1443.49	71.0481
1446.63	73.1513
1449.77	74.2435
1452.91	74.1751
1456.05	72.443
1459.18	69.0413
1462.32	65.2017
1465.45	60.606
1468.59	54.7309
1471.72	47.2783
1474.85	39.1685
1477.98	32.4116
1481.1	27.6153
1484.23	20.4456
1487.36	15.089
1490.48	10.4919
1493.61	7.26526
1496.73	4.10505
1499.85	3.8725
1502.97	4.00159
1506.09	2.73876
1509.2	2.71204
1512.32	2.47461
1515.43	3.97807
1518.55	6.46474
1521.66	7.82836
1524.77	9.22814
1527.88	10.9866
1530.99	12.0784
1534.1	11.9877
1537.21	13.6708
1540.31	15.2664
1543.42	16.7955
1546.52	18.7212
1549.62	21.4943
1552.72	22.9221
1555.82	25.9156
1558.92	28.8681
1562.02	29.6787
1565.11	32.7358
1568.21	35.3995
1571.3	38.4329
1574.39	40.607
1577.49	43.9604
1580.57	46.0775
1583.66	47.915
1586.75	49.9378
1589.84	50.3976
1592.92	50.1526
1596.01	50.3885
1599.09	49.5555
1602.17	47.792
1605.25	47.0364
1608.33	45.9713
1611.41	45.2518
1614.49	44.5381
1617.57	44.0648
1620.64	44.1251
1623.72	44.352
1626.79	45.267
1629.86	44.7044
1632.93	45.9726
1636	47.3382
1639.07	49.0843
1642.13	52.728
1645.2	56.4768
1648.26	59.4939
1651.33	62.8013
1654.39	63.6122
1657.45	63.5023
1660.51	63.5634
1663.57	62.4613
1666.63	61.7212
1669.68	60.6616
1672.74	58.1019
1675.79	55.4873
1678.85	52.1911
1681.9	47.8271
1684.95	42.9672
1688	38.5105
1691.05	32.542
1694.09	28.0356
1697.14	23.4483
1700.18	17.8908
1703.23	16.4608
1706.27	12.8165
1709.31	11.9557
1712.35	9.58164
1715.39	8.34843
1718.43	6.74464
1721.47	5.30039
1724.5	3.87674
1727.54	3.13633
1730.57	2.29528
1733.61	3.31542
1736.64	3.14008
1739.67	2.71312
1742.7	3.02389
1745.72	1.52467
1748.75	1.59105
1751.77	0.97
1754.8	-0.0839342
1757.82	-0.849471
1760.84	-0.19671
1763.87	-0.271248
1766.89	-0.486903
1769.91	-0.224703
1772.92	0.516094
1775.94	1.0114
1778.95	2.72722
1781.97	3.37213
1784.98	3.6854
1787.99	2.92819
1791.01	3.05743
1794.01	2.97274
1797.02	3.82845
1800.03	3.95011
1803.04	4.15012
1806.04	3.6295
1809.05	2.54952
1812.05	1.65191
1815.05	0.885775
1818.05	1.02642
1821.05	1.43123
1824.05	1.72587
1827.05	2.38857
1830.04	2.9152
1833.04	2.91678
1836.03	3.42434
1839.03	2.96211
1842.02	3.62491
1845.01	4.45343
1848	4.27799
1850.99	5.73472
1853.97	5.93342
1856.96	7.17512
1859.94	7.4625
1862.93	7.55143
1865.91	7.46872
1868.89	8.06529
1871.87	8.36865
1874.85	9.11586
1877.83	9.3217
1880.81	8.89114
1882.57	9.67425
1885.56	10.3304
1888.55	11.508
1891.54	12.0106
1894.52	13.1832
1897.51	13.3586
1900.49	12.1695
1903.47	12.1157
1906.45	11.7024
1909.43	11.9323
1912.41	12.2319
1915.39	12.4276
1918.37	12.0415
1921.34	12.0183
1924.32	11.9171
1927.29	11.8718
1930.26	11.1104
1933.23	11.066
1936.2	10.0984
1939.17	11.0272
1942.14	10.3757
1945.11	10.9289
1948.07	10.7796
1951.04	10.6361
1954	11.5448
1956.96	11.634
1959.93	11.561
1962.89	11.6257
1965.85	11.473
1968.8	10.2421
1971.76	9.21893
1974.72	8.20818
1977.67	8.76788
1980.63	7.64151
1983.58	7.68887
1986.53	8.18528
1989.48	8.2168
1992.43	8.7819
1995.38	9.237
1998.32	10.4878
2001.27	12.0769
2004.22	13.5748
2007.16	14.2969
2010.1	14.9974
2013.04	15.9721
2015.98	17.3396
2018.92	18.2244
2021.86	18.7499
2024.8	20.0018
2027.74	20.1036
2030.67	19.4992
2033.61	19.6
2036.54	18.665
2039.47	18.3992
2042.4	17.713
2045.33	17.1503
2048.26	15.3332
2051.19	14.1832
2054.12	13.8104
2057.04	13.8849
2059.97	14.4198
2062.89	14.3181
2065.81	15.2111
2068.73	16.786
2071.65	18.5337
2074.57	18.8934
2077.49	19.227
2080.41	19.7858
2083.32	19.9057
2086.24	21.3065
2089.15	22.3465
2092.07	23.5977
2094.98	24.3449
2097.89	24.4801
2100.8	22.9793
2103.71	23.6704
2106.61	23.1215
2109.52	22.4478
2112.43	22.6841
2115.33	22.3266
2118.23	21.3469
2121.13	21.6618
2124.04	22.4004
2126.94	22.5898
2129.83	22.9656
2132.73	24.1429
2135.63	25.6022
2138.53	25.855
2141.42	26.7322
2144.31	27.4012
2147.21	27.1596
2150.1	27.8445
2152.99	28.686
2155.88	30.0389
2158.77	31.6618
2161.65	34.0553
2164.54	34.8702
2167.43	36.0848
2170.31	36.6965
2173.19	37.4538
2176.07	37.6352
2178.96	37.8086
2181.84	37.6619
2184.72	37.996
2187.59	38.0982
2190.47	38.1761
2193.35	38.4172
2196.22	37.0988
2199.09	36.1873
2201.97	35.0713
2204.84	33.8561
2207.71	30.689
2210.58	28.0297
2213.45	26.6325
2216.31	24.3
2219.18	22.8155
2222.05	22.2808
2224.91	21.622
2227.78	21.3574
2230.64	20.2473
2233.5	20.7676
2236.36	21.3371
2239.22	21.1003
2242.08	21.4571
2244.93	20.131
2247.79	19.683
2250.64	19.6284
2253.5	19.392
2256.35	19.5734
2259.2	20.2028
2262.05	20.1261
2264.9	19.8397
2267.75	19.3554
2270.6	18.4395
2273.45	17.2303
2276.29	15.7728
2279.14	14.6907
2281.98	14.9634
2284.82	14.0333
2287.66	14.1811
2290.5	14.0951
2293.34	12.2148
2296.18	11.3537
2299.02	12.7236
2301.86	13.9455
2304.69	14.9122
2307.53	16.0148
2310.36	16.4732
2313.19	16.3455
2316.02	16.5384
2318.85	16.8961
2321.68	16.9076
2324.51	16.2334
2327.34	17.2225
2330.16	17.4729
2332.99	17.9252
2335.81	17.2946
2338.64	16.2448
2341.46	14.074
2344.28	13.3694
2347.1	12.396
2349.92	11.4341
2352.74	10.0914
2355.55	8.43992
2358.37	7.24915
2361.19	5.44084
2364	4.86019
2366.81	5.98114
2369.62	5.84665
2372.44	5.46087
2375.24	3.82209
2378.05	3.42622
2380.86	2.56052
2383.67	2.14933
2386.47	1.90835
2389.28	2.15316
2392.08	1.8691
2394.89	2.73144
2397.69	2.83749
2400.49	3.41566
2403.29	3.76281
2406.09	3.47267
2408.88	3.76038
2411.68	3.72154
2414.48	4.44162
2417.27	4.60237
2420.06	5.23962
2422.86	6.28515
2425.65	7.44316
2428.44	8.6012
2431.23	8.06495
2434.02	8.15796
2436.81	8.3467
2439.59	8.46782
2442.38	7.5582
2445.16	6.88538
2447.95	6.81496
2450.73	6.46742
2453.51	6.01325
2456.29	5.19333
2459.07	4.88407
2461.85	5.16371
2464.63	3.56609
2467.4	3.47332
2470.18	3.52441
2472.95	2.70276
2475.73	2.78301
2478.5	2.36631
2481.27	2.00568
2484.04	1.6561
2486.81	1.32224
2489.58	0.989319
2492.35	0.94687
2495.12	0.618967
2497.88	-0.436649
2500.65	-0.653891
2503.41	-0.426428
2506.17	-0.544889
2508.94	-0.30051
2511.7	-0.56595
2514.46	-0.942271
2517.22	-0.674091
2519.97	-0.348306
2522.73	0.0361228
2525.49	-0.685417
2528.24	-0.00875428
2530.99	0.637902
2533.75	1.13172
2536.5	2.5958
2539.25	3.72854
2542	4.80686
2544.75	5.94421
2547.5	6.40408
2550.24	5.76896
2552.99	6.0726
2555.74	4.95328
2558.48	4.81002
2561.22	5.00896
2563.96	4.48986
2566.71	4.44897
2569.45	4.24579
2572.18	3.59929
2574.92	3.18608
2577.66	2.81427
2580.4	1.74265
2583.13	1.8563
2585.87	1.43613
2588.6	0.991748
2591.33	0.752246
2594.06	0.521531
2596.79	1.03873
2599.52	0.758562
2602.25	0.92381
2604.98	0.983385
2607.71	1.53102
2610.43	1.58294
2613.16	2.04183
2615.88	1.94602
2618.6	2.22413
2621.32	2.38836
2624.04	2.68677
2626.76	2.66786
2629.48	2.98508
2632.2	4.00268
2634.92	4.10002
2637.63	5.87374
2640.35	6.23106
2643.06	6.40923
2645.77	6.11939
2648.49	6.24466
2651.2	5.61144
2653.91	5.15505
2656.62	4.98902
2659.33	3.90922
2662.03	3.04403
2664.74	2.15461
2667.44	1.04634
2670.15	0.118772
2672.85	-0.0661285
2675.55	-0.584778
2678.26	-1.27401
2680.96	-1.03652
2683.66	-1.53415
2686.35	-2.08377
2689.05	-1.42778
2691.75	0.00973527
2694.44	1.22704
2697.14	2.908
2699.83	4.31304
2702.52	6.28916
2705.22	7.05208
2707.91	7.48652
2710.6	8.22145
2713.29	9.1523
2715.97	10.0559
2718.66	9.79963
2721.35	10.3592
2724.03	10.5816
2726.72	9.75822
2729.4	9.66834
2732.08	8.57878
2734.76	8.58519
2737.44	7.71757
2740.12	7.15173
2742.8	7.17559
2745.48	7.19129
2748.16	7.56599
2750.83	8.02448
2753.51	8.10231
2756.18	7.89713
2758.85	7.88499
2761.53	7.7142
2764.2	7.87141
2766.87	7.76343
2769.54	7.61098
2772.2	7.39737
2774.87	7.52649
2777.54	8.22978
2780.2	8.10096
2782.87	8.90075
2785.53	8.43894
2788.19	7.70753
2790.85	7.80911
2793.51	7.22405
2796.17	7.19052
2798.83	6.58847
2801.49	7.44822
2804.15	6.94013
2806.8	7.84737
2809.46	8.51316
2812.11	8.73683
2814.76	9.31509
2817.42	9.47466
2820.07	10.2828
2822.72	11.4192
2825.37	14.4159
2828.02	17.4002
2830.66	20.6378
2833.31	24.5604
2835.96	27.9151
2838.6	32.0617
2841.24	38.0513
2843.89	44.2452
2846.53	51.2927
2849.17	59.5606
2851.81	66.4378
2854.45	74.7862
2857.09	82.076
2859.72	90.1882
2862.36	98.039
2865	105.802
2867.63	113.475
2870.26	119.217
2872.9	125.718
2875.53	130.767
2878.16	135.53
2880.79	140.12
2883.42	144.8
2886.05	147.874
2888.67	152.021
2891.3	156.336
2893.92	159.706
2896.55	164.242
2899.17	168.702
2901.79	174.37
2904.42	181.074
2907.04	188.352
2909.66	196.765
2912.27	205.448
2914.89	213.755
2917.51	222.071
2920.13	228.996
2922.74	235.48
2925.35	239.954
2927.97	243.771
2930.58	244.877
2933.19	245.269
2935.8	243.972
2938.41	240.611
2941.02	236.516
2943.63	231.146
2946.24	225.642
2948.84	218.819
2951.45	210.316
2954.05	203.097
2956.65	195.452
2959.26	188.087
2961.86	181.216
2964.46	175.002
2967.06	167.792
2969.66	161.267
2972.25	154.686
2974.85	148.149
2977.45	141.326
2980.04	134.132
2982.64	126.082
2985.23	118.508
2987.82	110.189
2990.41	101.943
2993	93.6819
2995.59	85.2893
2998.18	77.8985
3000.77	70.2509
3003.36	62.7942
3005.94	57.8074
3008.53	52.5783
3011.11	48.2409
3013.69	42.9391
3016.28	38.8836
3018.86	36.5135
3021.44	33.0516
3024.02	31.6054
3026.6	30.0792
3029.18	28.198
3031.75	27.2575
3034.33	26.7403
3036.9	27.0969
3039.48	27.5503
3042.05	27.2551
3044.62	26.7595
3047.19	26.4868
3049.77	26.7436
3052.34	26.6745
3054.9	25.8333
3057.47	25.3275
3060.04	25.2186
3062.61	24.5882
3065.17	23.8322
3067.74	23.5193
3070.3	22.5696
3072.86	21.1666
3075.42	18.9584
3077.99	16.4395
3080.54	14.4311
3083.1	12.1904
3085.66	10.5752
3088.22	9.5349
3090.78	8.08213
3093.33	7.822
3095.89	6.18198
3098.44	5.3729
3100.99	4.13159
3103.54	2.71088
3106.1	1.82371
3108.65	1.63711
3111.2	2.09656
3113.74	1.5533
3116.29	0.787197
3118.84	0.378296
3121.38	0.622115
3123.93	0.726368
3126.47	1.65611
3129.01	1.65979
3131.56	1.24492
3134.1	1.46024
3136.64	1.56454
3139.18	3.04084
3141.72	4.39811
3144.26	6.16171
3146.79	7.84863
3149.33	8.80818