File: data/Raman/poly_smoothed/Thy_30_10_20_1x_45s_532 nm_x100_100%_600 gr_mm_01.txt
#Acq. time (s)=	45
#Accumulations=	2
#Range (cm-¹)=	200...3150
#Windows=	2
#Auto scanning=	Off
#Autofocus=	Off
#Macrospot=	Off
#AutoExposure=	Off
#Spike filter=	Multiple accum.
#Delay time (s)=	0
#Binning=	1
#Readout mode=	Signal
#DeNoise=	Off
#ICS correction=	On
#Dark correction=	Off
#Inst. Process=	Off
#Detector Gain=	Best Dynamic Range
#Detector ADC=	20 kHz
#Detector temperature (°C)=	-69.85
#Instrument=	LabRAM HR Evol
#Detector=	Synapse
#Objective=	x100
#Grating=	600 gr/mm
#ND Filter=	100%
#Laser (nm)=	532
#Hole=	100.021
#Range=	Auto
#Laser Pol.=	No
#Raman. Pol.=	No
#Laser Pol. (°)=	-0.0007625
#Raman Pol. (°)=	89.9995
#Collection=	Microscope
#StageXY=	Marzhauser
#StageZ=	Marzhauser
#X (µm)=	4768
#Y (µm)=	-7729.5
#Z (µm)=	584.55
#Full time(mm:ss)=	3:18
#Project=
#Sample=
#Site=
#Title=	Thy_30_10_20_2x_45s_532 nm_x100_100%_600 gr_mm
#Remark=
#Date=	30.06.2022 12:54
#Acquired=	30.06.2022 12:54:56
#Base:Fit=	10.08.2022 09:58:11
#Base:Sub=	10.08.2022 09:58:44
#Filter:Polynom=	16.08.2022 10:22:53
#AxisType[0]=Intens
#AxisUnit[0]=Cnt
#AxisType[1]=Spectr
#AxisUnit[1]=1/cm
200.533	6.05248
204.162	4.89952
207.792	6.75604
211.418	6.97589
215.044	7.27342
218.667	5.99727
222.289	5.36351
225.912	5.93244
229.531	4.27283
233.148	3.51651
236.766	4.79544
240.381	5.34922
243.994	6.97097
247.606	7.52143
251.217	9.14167
254.828	8.83158
258.436	7.77681
262.042	7.8918
265.647	8.37589
269.25	11.0186
272.852	11.2762
276.453	12.4444
280.052	13.4209
283.65	14.5942
287.247	15.1581
290.842	16.4177
294.436	17.6186
298.028	17.0291
301.617	16.5482
305.206	18.1204
308.794	17.9384
312.381	18.5201
315.964	18.8962
319.548	19.7165
323.131	21.0129
326.71	21.5391
330.29	21.1441
333.868	21.3985
337.443	20.6343
341.018	20.8171
344.591	19.5027
348.163	19.9946
351.733	20.9406
355.303	20.7177
358.869	20.0107
362.435	18.5527
366.001	17.6811
369.563	19.2581
373.124	19.7265
376.686	19.6529
380.244	19.1662
383.801	20.0541
387.357	19.6726
390.911	19.7849
394.466	18.0539
398.018	16.8961
401.568	15.8802
405.117	15.7278
408.664	15.4688
412.21	13.9927
415.755	13.2333
419.298	12.4962
422.84	11.6874
426.38	11.6488
429.919	11.2715
433.455	11.2896
436.992	11.4629
440.527	10.5073
444.06	10.2559
447.593	10.7395
451.122	11.0279
454.651	13.2731
458.18	14.45
461.705	14.7588
465.23	14.3168
468.752	15.1199
472.275	15.5303
475.797	15.3168
479.315	15.5431
482.834	17.1415
486.349	18.5866
489.863	20.158
493.378	21.0393
496.889	20.6579
500.401	21.4795
503.91	21.7511
507.417	21.5673
510.923	22.2342
514.43	22.5462
517.933	21.6742
521.435	21.9514
524.936	21.4309
528.435	20.7844
531.933	20.079
535.43	20.5697
538.927	19.3822
542.421	19.1703
545.913	18.4786
549.403	17.6939
552.893	16.9389
556.381	16.4614
559.868	15.3982
563.354	14.6579
566.839	12.2559
570.322	10.6225
573.802	10.7669
577.283	10.4742
580.762	10.6042
584.24	9.56656
587.714	8.07183
591.19	7.46455
594.663	6.2664
598.134	5.51472
601.605	5.44312
605.073	5.29234
608.542	5.74818
612.007	7.79054
615.473	8.73985
618.936	10.8495
622.397	12.2641
625.859	13.9242
629.318	16.2298
632.775	18.0257
636.233	18.8683
639.688	18.6998
643.142	18.7567
646.594	18.7739
650.045	18.8687
653.496	19.7332
656.944	21.2244
660.391	22.3208
663.837	22.6425
667.281	22.7328
670.724	22.4699
674.166	22.5692
677.606	23.7314
681.045	24.2818
684.483	24.7212
687.917	25.902
691.352	28.8515
694.786	31.2258
698.219	32.8742
701.65	33.0922
705.078	34.7468
708.506	36.2245
711.934	38.5816
715.358	39.4002
718.782	40.5168
722.204	41.3047
725.626	40.8205
729.045	41.9256
732.464	40.8782
735.881	42.2671
739.297	43.075
742.711	45.0913
746.125	47.1445
749.537	48.5206
752.946	50.255
756.357	52.0483
759.764	53.6749
763.17	54.4787
766.575	56.419
769.978	59.3434
773.382	62.2021
776.783	62.4854
780.182	64.4637
783.581	66.4669
786.978	68.7429
790.373	69.2076
793.768	69.4889
797.161	69.4686
800.552	71.2726
803.941	71.5569
807.33	69.7881
810.718	69.8501
814.105	71.2767
817.49	71.7226
820.873	72.6024
824.256	72.1288
827.637	70.6562
831.016	68.8897
834.395	66.9806
837.772	65.4846
841.147	64.777
844.522	61.3464
847.894	59.7063
851.267	58.8461
854.637	55.8656
858.007	54.1999
861.374	52.4025
864.739	52.6999
868.106	49.9651
871.469	47.7634
874.831	45.1451
878.193	43.5431
881.553	43.1712
884.911	41.2464
888.268	41.6865
891.623	42.0794
894.978	42.528
898.331	41.3533
901.683	39.8397
905.033	38.4626
908.383	37.0203
911.731	37.1965
915.078	36.0646
918.423	36.0929
921.768	36.2266
925.111	35.8436
928.452	35.0477
931.791	34.4597
935.13	34.8074
938.468	34.4601
941.803	33.4989
945.139	31.1395
948.473	30.249
951.804	27.7975
955.136	28.2036
958.465	26.9982
961.794	25.8705
965.12	25.6913
968.447	25.8565
971.771	24.7095
975.095	24.5247
978.417	22.736
981.737	21.907
985.057	20.0944
988.375	20.4964
991.691	19.1005
995.006	18.9788
998.32	19.1017
1001.63	20.0681
1004.95	19.5443
1008.26	18.4775
1011.56	18.6979
1014.87	17.6466
1018.18	17.4416
1021.48	14.7685
1024.79	14.0176
1028.09	12.85
1031.39	14.0712
1034.69	13.5926
1037.99	12.7473
1041.29	12.9265
1044.58	13.1651
1047.88	12.4083
1051.17	11.4462
1054.46	11.2669
1057.75	11.1169
1061.04	10.5062
1064.33	10.9368
1067.62	10.5152
1070.9	9.69765
1074.19	9.08388
1077.47	11.0976
1080.76	11.8447
1084.04	11.3413
1087.32	10.7227
1090.59	11.5167
1093.87	11.0398
1097.15	9.99392
1100.42	9.88362
1103.69	9.59914
1106.97	8.39017
1110.24	8.53196
1113.51	7.47881
1116.77	6.29322
1120.04	6.01954
1123.31	5.52307
1126.57	4.01496
1129.83	2.39239
1133.1	2.47638
1136.36	2.76763
1139.62	0.999442
1142.87	1.29309
1146.13	1.85405
1149.38	0.979955
1152.64	0.684432
1155.89	2.13634
1159.14	2.17701
1162.39	1.24403
1165.64	0.408687
1168.89	1.32504
1172.14	1.49473
1175.38	-0.068143
1178.63	0.970277
1181.87	2.22039
1185.11	2.89876
1188.35	3.1486
1191.59	3.2645
1194.83	3.98929
1198.07	4.85004
1201.3	6.56536
1204.53	6.88839
1207.77	9.44695
1211	11.7407
1214.23	15.6199
1217.46	17.1767
1220.69	18.5486
1223.91	21.0697
1227.14	22.192
1230.36	23.9501
1233.59	24.8393
1236.81	26.715
1240.03	28.1009
1243.25	28.9235
1246.46	30.2349
1249.68	31.6328
1252.9	33.5721
1256.11	34.734
1259.32	35.686
1262.54	37.3245
1265.75	38.7658
1268.96	38.8558
1272.16	39.238
1275.37	40.119
1278.57	41.8052
1281.78	43.3207
1284.98	44.842
1288.18	45.1889
1291.38	46.034
1294.58	46.5166
1297.78	47.0079
1300.98	47.0906
1304.17	47.3009
1307.37	48.2811
1310.56	48.4904
1313.76	48.8765
1316.95	48.9301
1320.14	49.5726
1323.32	49.0751
1326.51	48.5804
1329.7	48.2582
1332.88	48.0632
1336.07	46.2044
1339.25	45.3848
1342.43	43.5529
1345.61	41.6408
1348.79	40.4999
1351.96	38.8349
1355.14	37.8003
1358.31	35.1891
1361.49	32.8744
1364.66	30.6863
1367.83	30.1563
1371	28.8805
1374.17	27.3706
1377.34	26.5735
1380.5	25.2243
1383.67	25.4362
1386.83	24.9563
1390	24.5599
1393.16	24.3188
1396.32	24.2062
1399.48	23.3423
1402.64	23.0087
1405.79	22.6919
1408.95	23.7807
1412.1	25.3066
1415.26	27.0814
1418.41	28.7104
1421.56	31.6619
1424.71	34.7916
1427.86	36.858
1431	39.4213
1434.15	42.0881
1437.29	45.0622
1440.44	47.0966
1443.58	50.0238
1446.72	49.9399
1449.86	49.5213
1453	49.253
1456.14	49.1253
1459.27	48.4356
1462.41	47.4167
1465.54	44.6749
1468.67	41.3546
1471.81	37.7647
1474.94	33.8334
1478.07	31.1581
1481.19	28.1376
1484.32	25.4414
1487.45	23.6759
1490.57	21.3929
1493.69	20.1853
1496.82	17.9018
1499.94	15.5281
1503.06	14.4106
1506.17	14.7779
1509.29	15.2275
1512.41	15.4755
1515.52	15.2159
1518.64	14.7455
1521.75	15.5959
1524.86	16.4653
1527.97	17.455
1531.08	18.5714
1534.19	19.96
1537.29	21.4415
1540.4	22.7327
1543.5	24.0248
1546.61	26.659
1549.71	30.8997
1552.81	32.9762
1555.91	35.8098
1559.01	38.2201
1562.11	39.7295
1565.2	41.5488
1568.29	43.9383
1571.39	46.176
1574.48	47.2414
1577.57	48.5744
1580.66	50.5911
1583.75	52.7156
1586.84	53.5875
1589.93	53.1861
1593.01	53.1041
1596.1	53.3889
1599.18	52.7226
1602.26	50.8684
1605.34	49.3034
1608.42	48.6842
1611.5	46.869
1614.58	46.6894
1617.65	46.5477
1620.73	47.0206
1623.8	46.4643
1626.87	47.2999
1629.95	46.6381
1633.02	46.9259
1636.09	47.8427
1639.15	48.2741
1642.22	49.8153
1645.29	51.3087
1648.35	51.3083
1651.42	51.4915
1654.48	53.0145
1657.54	51.4796
1660.6	51.0496
1663.66	50.1135
1666.72	48.7038
1669.77	45.9032
1672.83	43.4495
1675.88	39.6941
1678.93	37.3351
1681.99	34.2764
1685.04	31.0396
1688.09	27.5638
1691.13	25.0485
1694.18	22.0849
1697.23	19.0192
1700.27	16.1124
1703.32	13.3353
1706.36	10.854
1709.4	10.0421
1712.44	7.67732
1715.48	6.32538
1718.52	4.78718
1721.56	4.40473
1724.59	3.82625
1727.63	3.4771
1730.66	3.53315
1733.69	3.34689
1736.72	3.89968
1739.75	3.87654
1742.78	3.6192
1745.81	3.47029
1748.84	2.8207
1751.86	3.0688
1754.89	3.17768
1757.91	3.95358
1760.93	3.94093
1763.95	3.80395
1766.97	4.42243
1769.99	3.31249
1773.01	2.57706
1776.03	2.76362
1779.04	2.79466
1782.06	2.91147
1785.07	1.77111
1788.08	1.90435
1791.09	2.40333
1794.1	1.75017
1797.11	1.22256
1800.12	0.446409
1803.12	0.622721
1806.13	0.783182
1809.13	0.156101
1812.14	-0.057013
1815.14	-0.961028
1818.14	-0.652442
1821.14	-0.772735
1824.14	-0.727621
1827.13	-0.496557
1830.13	0.00539712
1833.12	0.0978831
1836.12	0.0315273
1839.11	0.28743
1842.1	1.03331
1845.09	0.79325
1848.08	1.98013
1851.07	2.15762
1854.06	2.77216
1857.04	3.28455
1860.03	3.2522
1863.01	3.85119
1866	3.69873
1868.98	3.94352
1871.96	3.85989
1874.94	4.26659
1877.92	4.26007
1880.89	4.36462
1882.48	4.93057
1885.47	4.40543
1888.46	4.91162
1891.44	5.35422
1894.43	5.39151
1897.41	5.46307
1900.4	5.4357
1903.38	5.09249
1906.36	4.52466
1909.34	5.50777
1912.32	5.93892
1915.29	5.87616
1918.27	6.23707
1921.25	5.8927
1924.22	6.20575
1927.2	6.59287
1930.17	6.44469
1933.14	6.43278
1936.11	6.15919
1939.08	6.48412
1942.05	6.59371
1945.01	5.46475
1947.98	5.67023
1950.94	5.49019
1953.91	5.60974
1956.87	6.13218
1959.83	5.61784
1962.79	6.21404
1965.75	6.27039
1968.71	6.55808
1971.67	6.51708
1974.62	5.42055
1977.58	5.4378
1980.53	6.52817
1983.48	7.39426
1986.43	6.86856
1989.38	6.5538
1992.33	6.87124
1995.28	7.35184
1998.23	8.85286
2001.18	9.57798
2004.12	10.0145
2007.06	10.354
2010.01	11.5557
2012.95	12.63
2015.89	12.7894
2018.83	12.6972
2021.77	13.5623
2024.71	14.4487
2027.64	14.8737
2030.58	15.5342
2033.51	15.497
2036.45	15.0037
2039.38	14.0651
2042.31	13.7351
2045.24	12.031
2048.17	11.3695
2051.1	11.2379
2054.02	10.8289
2056.95	9.99237
2059.87	9.5368
2062.8	10.1017
2065.72	11.0173
2068.64	10.7795
2071.56	10.198
2074.48	10.9446
2077.4	12.7224
2080.31	13.0408
2083.23	13.2937
2086.14	13.6373
2089.06	15.1414
2091.97	15.5223
2094.88	17.652
2097.79	18.4033
2100.7	20.4655
2103.61	21.2176
2106.52	21.5719
2109.43	21.95
2112.33	22.759
2115.24	22.8372
2118.14	23.7301
2121.04	25.2712
2123.94	27.3301
2126.84	28.8103
2129.74	30.1873
2132.64	31.1191
2135.54	33.3682
2138.43	34.1788
2141.33	35.3411
2144.22	37.0708
2147.11	38.4795
2150.01	39.1204
2152.9	41.6495
2155.79	43.1497
2158.67	45.4351
2161.56	47.6371
2164.45	49.4476
2167.33	50.2981
2170.22	51.3721
2173.1	52.2013
2175.98	52.041
2178.86	51.1842
2181.74	50.3281
2184.62	49.1128
2187.5	47.0788
2190.38	46.3068
2193.25	44.9465
2196.13	43.3338
2199	41.4139
2201.88	39.3571
2204.75	37.7113
2207.62	35.296
2210.49	32.8908
2213.36	31.1382
2216.22	29.579
2219.09	27.1471
2221.96	27.0126
2224.82	25.8297
2227.68	24.73
2230.55	24.0337
2233.41	23.484
2236.27	22.5359
2239.12	21.9033
2241.98	21.9756
2244.84	21.4532
2247.7	21.3281
2250.55	20.499
2253.41	19.6413
2256.26	18.6776
2259.11	17.9222
2261.96	17.4926
2264.81	17.9422
2267.66	18.1158
2270.51	17.5167
2273.35	17.3893
2276.2	16.9472
2279.04	16.6921
2281.89	16.3046
2284.73	15.3309
2287.57	13.9325
2290.41	12.5489
2293.25	11.4965
2296.09	10.7426
2298.93	10.4987
2301.76	10.7142
2304.6	10.8959
2307.44	11.1005
2310.27	12.0512
2313.1	12.6152
2315.93	12.4125
2318.76	11.5597
2321.59	11.6761
2324.42	11.6519
2327.25	11.6308
2330.07	10.9619
2332.9	11.3249
2335.72	11.7427
2338.55	10.6337
2341.37	9.72886
2344.19	9.36788
2347.01	8.31125
2349.83	7.87245
2352.65	7.48299
2355.46	4.66752
2358.28	3.44147
2361.09	2.96026
2363.91	3.72867
2366.72	4.60919
2369.53	4.79365
2372.34	4.75297
2375.15	5.04181
2377.96	5.51461
2380.77	5.71462
2383.58	5.09695
2386.38	5.34533
2389.19	5.67184
2391.99	5.83558
2394.8	5.56177
2397.6	5.61548
2400.4	5.41453
2403.2	5.96615
2406	4.97184
2408.79	5.57394
2411.59	5.40142
2414.39	5.10669
2417.18	4.35591
2419.98	4.74185
2422.77	3.42256
2425.56	3.20231
2428.35	3.5484
2431.14	3.33262
2433.93	3.04555
2436.72	2.70565
2439.5	2.33086
2442.29	2.29296
2445.07	2.22964
2447.86	2.55306
2450.64	2.28155
2453.42	3.13061
2456.2	3.31955
2458.98	4.12554
2461.76	4.50972
2464.54	4.38661
2467.32	4.55512
2470.09	4.88361
2472.87	5.13847
2475.64	6.09066
2478.41	6.2794
2481.18	5.87295
2483.95	6.32939
2486.72	6.15874
2489.49	5.42199
2492.26	4.8871
2495.03	4.53545
2497.79	3.80687
2500.56	3.68794
2503.32	3.01335
2506.09	2.99818
2508.85	2.75495
2511.61	3.01943
2514.37	2.469
2517.13	2.48505
2519.89	2.53116
2522.64	2.39375
2525.4	1.79747
2528.15	1.26271
2530.91	0.512728
2533.66	0.267274
2536.41	-0.0801359
2539.16	-0.130201
2541.91	0.824083
2544.66	0.35501
2547.41	0.0868316
2550.16	-0.452734
2552.9	-0.460127
2555.65	-1.86933
2558.39	-1.40695
2561.13	-0.94116
2563.88	-0.00969435
2566.62	0.649121
2569.36	0.627472
2572.1	0.854585
2574.84	1.36133
2577.57	1.39061
2580.31	1.22787
2583.05	1.4691
2585.78	1.892
2588.51	1.7794
2591.24	1.52592
2593.98	1.32434
2596.71	1.41426
2599.44	1.54377
2602.16	1.38852
2604.89	1.50401
2607.62	1.6185
2610.34	1.7549
2613.07	1.68177
2615.79	1.70227
2618.52	2.16168
2621.24	2.51436
2623.96	2.38389
2626.68	3.43895
2629.4	3.57875
2632.11	2.62022
2634.83	2.26663
2637.55	2.17068
2640.26	2.21863
2642.98	2.98535
2645.69	2.97891
2648.4	2.46092
2651.11	2.65985
2653.82	2.48159
2656.53	1.86161
2659.24	1.78219
2661.95	1.86978
2664.65	3.68238
2667.36	3.53085
2670.06	4.07457
2672.76	4.11588
2675.47	4.14831
2678.17	4.59262
2680.87	5.09591
2683.57	5.52226
2686.27	5.815
2688.97	5.89994
2691.66	5.9212
2694.36	6.20928
2697.05	6.10217
2699.75	6.50257
2702.44	7.01724
2705.13	7.19196
2707.82	7.4244
2710.51	6.94932
2713.2	6.6646
2715.89	6.12297
2718.57	6.49714
2721.26	6.40676
2723.95	6.49832
2726.63	7.1344
2729.31	7.53581
2732	8.17846
2734.68	8.20827
2737.36	8.24581
2740.04	8.16771
2742.72	8.72977
2745.39	8.78281
2748.07	8.62663
2750.75	8.79781
2753.42	9.70849
2756.09	9.16554
2758.77	8.59463
2761.44	7.80942
2764.11	6.8282
2766.78	6.47175
2769.45	5.28078
2772.12	4.97071
2774.78	4.58814
2777.45	4.44712
2780.12	4.07982
2782.78	3.25529
2785.44	2.82724
2788.11	3.04876
2790.77	3.25584
2793.43	3.6873
2796.09	4.50236
2798.75	4.64815
2801.4	4.13825
2804.06	4.10558
2806.72	4.06078
2809.37	4.23828
2812.03	4.89709
2814.68	5.55217
2817.33	6.05612
2819.98	6.21221
2822.63	5.95483
2825.28	7.29382
2827.93	10.0715
2830.58	12.4442
2833.23	14.7137
2835.87	17.1737
2838.52	19.9874
2841.16	23.2082
2843.8	26.334
2846.44	28.9137
2849.08	33.3186
2851.73	37.8611
2854.36	42.0292
2857	46.732
2859.64	51.4936
2862.28	56.4183
2864.91	58.8754
2867.55	62.3039
2870.18	65.7505
2872.81	68.3618
2875.44	70.8861
2878.07	72.4547
2880.7	74.2627
2883.33	77.8185
2885.96	80.6623
2888.59	84.1549
2891.21	88.1849
2893.84	90.8498
2896.46	93.4473
2899.09	97.2546
2901.71	101.358
2904.33	106.661
2906.95	112.569
2909.57	118.23
2912.19	124.882
2914.81	131.888
2917.43	138.897
2920.04	145.312
2922.66	151.062
2925.27	154.328
2927.88	156.641
2930.5	157.343
2933.11	158.536
2935.72	157.977
2938.33	156.217
2940.94	154.333
2943.54	151.719
2946.15	148.37
2948.76	144.863
2951.36	139.103
2953.97	134.106
2956.57	128.712
2959.17	123.251
2961.77	118.557
2964.37	114.457
2966.97	109.844
2969.57	105.374
2972.17	101.268
2974.77	97.9272
2977.36	94.0668
2979.96	90.169
2982.55	85.8003
2985.15	80.1282
2987.74	75.4083
2990.33	69.4506
2992.92	64.919
2995.51	60.12
2998.1	56.1546
3000.69	51.2476
3003.27	46.5753
3005.86	42.5881
3008.44	37.8539
3011.03	32.9586
3013.61	29.4294
3016.19	26.1757
3018.78	22.9855
3021.36	21.4192
3023.94	20.564
3026.51	19.4245
3029.09	18.4757
3031.67	18.028
3034.24	18.2954
3036.82	18.699
3039.39	19.7673
3041.97	20.3143
3044.54	20.9782
3047.11	21.8862
3049.68	22.1156
3052.25	22.8457
3054.82	22.7085
3057.39	22.5282
3059.96	22.8174
3062.52	22.7479
3065.09	21.3605
3067.65	20.2679
3070.22	18.6193
3072.78	16.6951
3075.34	15.3162
3077.9	14.736
3080.46	13.7405
3083.02	12.4847
3085.58	11.2745
3088.14	10.2382
3090.69	8.63577
3093.25	7.43833
3095.8	6.20341
3098.36	5.92992
3100.91	5.7816
3103.46	4.98943
3106.01	4.39584
3108.56	4.01143
3111.11	4.25281
3113.66	3.91859
3116.21	3.86969
3118.76	3.55863
3121.3	3.34245
3123.85	3.62329
3126.39	3.82957
3128.93	3.68387
3131.48	3.51145
3134.02	3.52464
3136.56	3.9961
3139.1	3.62587
3141.64	2.89646
3144.17	1.27676
3146.71	-0.364877
3149.25	-2.29347