File: data/Raman/poly_smoothed/Thy_30_10_45_1x_45s_532 nm_x100_100%_600 gr_mm_01.txt
#Acq. time (s)=	45
#Accumulations=	2
#Range (cm-¹)=	200...3150
#Windows=	2
#Auto scanning=	Off
#Autofocus=	Off
#Macrospot=	Off
#AutoExposure=	Off
#Spike filter=	Multiple accum.
#Delay time (s)=	0
#Binning=	1
#Readout mode=	Signal
#DeNoise=	Off
#ICS correction=	On
#Dark correction=	Off
#Inst. Process=	Off
#Detector Gain=	Best Dynamic Range
#Detector ADC=	20 kHz
#Detector temperature (°C)=	-69.85
#Instrument=	LabRAM HR Evol
#Detector=	Synapse
#Objective=	x100
#Grating=	600 gr/mm
#ND Filter=	100%
#Laser (nm)=	532
#Hole=	100.021
#Range=	Auto
#Laser Pol.=	No
#Raman. Pol.=	No
#Laser Pol. (°)=	-0.0007625
#Raman Pol. (°)=	89.9995
#Collection=	Microscope
#StageXY=	Marzhauser
#StageZ=	Marzhauser
#X (µm)=	4719
#Y (µm)=	-7702.5
#Z (µm)=	584.35
#Full time(mm:ss)=	3:18
#Project=
#Sample=
#Site=
#Title=	Thy_30_10_45_2x_45s_532 nm_x100_100%_600 gr_mm
#Remark=
#Date=	30.06.2022 14:38
#Acquired=	30.06.2022 14:38:40
#Base:Fit=	10.08.2022 09:58:11
#Base:Sub=	10.08.2022 09:58:44
#Filter:Polynom=	16.08.2022 10:22:53
#AxisType[0]=Intens
#AxisUnit[0]=Cnt
#AxisType[1]=Spectr
#AxisUnit[1]=1/cm
200.533	1.64566
204.162	7.12073
207.792	8.25116
211.418	8.51303
215.044	9.13427
218.667	9.12416
222.289	8.177
225.912	8.31239
229.531	8.66885
233.148	8.69
236.766	7.66374
240.381	6.86816
243.994	6.4285
247.606	6.07916
251.217	5.26327
254.828	4.13877
258.436	3.04457
262.042	1.48808
265.647	1.54503
269.25	1.70498
272.852	0.79127
276.453	1.29685
280.052	3.16477
283.65	4.12608
287.247	6.54558
290.842	5.38699
294.436	5.42658
298.028	7.77118
301.617	9.45311
305.206	10.3527
308.794	11.1164
312.381	12.8514
315.964	14.206
319.548	14.5336
323.131	16.6547
326.71	15.8962
330.29	16.136
333.868	16.3579
337.443	16.5864
341.018	15.8088
344.591	14.6665
348.163	14.1151
351.733	13.9525
355.303	13.6707
358.869	12.5594
362.435	11.6689
366.001	11.3281
369.563	9.98388
373.124	8.55822
376.686	6.66345
380.244	4.95976
383.801	5.35488
387.357	5.02199
390.911	3.68314
394.466	3.21137
398.018	2.84189
401.568	3.01129
405.117	2.76083
408.664	1.98381
412.21	1.32187
415.755	2.74799
419.298	4.0051
422.84	5.65249
426.38	7.15483
429.919	7.63778
433.455	7.94846
436.992	7.81775
440.527	7.64253
444.06	7.2977
447.593	6.79341
451.122	6.7808
454.651	5.55359
458.18	5.12727
461.705	6.14517
465.23	7.57984
468.752	8.7738
472.275	9.90813
475.797	10.454
479.315	10.6669
482.834	11.6346
486.349	13.0144
489.863	13.0217
493.378	13.0789
496.889	16.1169
500.401	18.3862
503.91	20.8632
507.417	22.5409
510.923	24.2145
514.43	25.464
517.933	25.7516
521.435	25.55
524.936	25.154
528.435	23.3722
531.933	22.4893
535.43	21.4372
538.927	21.7975
542.421	20.0772
545.913	19.6147
549.403	19.3462
552.893	16.9241
556.381	15.1578
559.868	14.6188
563.354	12.1437
566.839	10.9496
570.322	8.49783
573.802	6.18429
577.283	5.42266
580.762	4.85542
584.24	4.15964
587.714	2.97976
591.19	1.74105
594.663	1.4932
598.134	1.1813
601.605	0.998507
605.073	1.64424
608.542	1.43242
612.007	0.879004
615.473	1.30471
618.936	2.91865
622.397	5.52669
625.859	6.30699
629.318	8.05538
632.775	9.22359
636.233	8.90142
639.688	11.2735
643.142	14.1675
646.594	16.5695
650.045	17.8653
653.496	19.3309
656.944	20.1966
660.391	21.053
663.837	22.1154
667.281	21.6086
670.724	22.5245
674.166	23.9379
677.606	24.7071
681.045	26.9631
684.483	27.4744
687.917	30.5358
691.352	32.4129
694.786	33.0687
698.219	33.9266
701.65	34.2057
705.078	35.3551
708.506	35.4512
711.934	35.6679
715.358	37.4484
718.782	37.9745
722.204	39.9314
725.626	40.6827
729.045	42.5288
732.464	42.9883
735.881	44.6064
739.297	46.1924
742.711	49.144
746.125	51.8695
749.537	54.26
752.946	56.6117
756.357	59.4635
759.764	61.846
763.17	66.606
766.575	69.8013
769.978	73.3679
773.382	76.1999
776.783	77.2882
780.182	78.0193
783.581	77.8153
786.978	78.5064
790.373	80.4091
793.768	79.8955
797.161	80.6927
800.552	82.3453
803.941	83.4306
807.33	84.478
810.718	85.6144
814.105	86.5573
817.49	87.7872
820.873	89.7753
824.256	90.4168
827.637	91.1695
831.016	89.0947
834.395	87.4015
837.772	86.2825
841.147	84.7137
844.522	83.5051
847.894	82.2079
851.267	79.2774
854.637	76.4235
858.007	73.5234
861.374	71.2297
864.739	67.4105
868.106	64.9646
871.469	64.8329
874.831	63.6969
878.193	61.5075
881.553	60.7886
884.911	62.2968
888.268	61.7039
891.623	61.7902
894.978	62.5217
898.331	61.3665
901.683	63.178
905.033	62.1025
908.383	62.3866
911.731	62.4679
915.078	61.2703
918.423	61.155
921.768	60.8786
925.111	60.37
928.452	58.9356
931.791	56.9051
935.13	55.0015
938.468	53.4019
941.803	50.3563
945.139	46.4409
948.473	43.8549
951.804	45.425
955.136	45.9353
958.465	44.5142
961.794	43.5376
965.12	44.2155
968.447	47.1426
971.771	47.8867
975.095	49.9247
978.417	51.6786
981.737	53.7399
985.057	56.4662
988.375	57.725
991.691	60.1045
995.006	61.1266
998.32	61.5508
1001.63	62.3541
1004.95	62.8433
1008.26	60.7554
1011.56	59.6641
1014.87	58.1312
1018.18	55.7404
1021.48	53.4446
1024.79	51.659
1028.09	50.6629
1031.39	51.4188
1034.69	49.4691
1037.99	46.5972
1041.29	44.2048
1044.58	43.4518
1047.88	43.8523
1051.17	41.9563
1054.46	40.4001
1057.75	38.4858
1061.04	36.957
1064.33	34.9791
1067.62	34.1323
1070.9	32.8657
1074.19	31.9487
1077.47	32.9557
1080.76	33.8147
1084.04	34.1546
1087.32	34.2378
1090.59	35.5993
1093.87	37.4681
1097.15	37.2431
1100.42	39.1719
1103.69	38.0045
1106.97	39.2994
1110.24	38.6075
1113.51	36.312
1116.77	37.2198
1120.04	36.2382
1123.31	35.4914
1126.57	31.7902
1129.83	28.1805
1133.1	24.6289
1136.36	22.2279
1139.62	19.9128
1142.87	17.9192
1146.13	16.428
1149.38	14.6938
1152.64	12.1689
1155.89	10.4566
1159.14	10.9111
1162.39	9.22773
1165.64	8.6629
1168.89	10.5579
1172.14	11.4122
1175.38	12.6403
1178.63	14.3835
1181.87	16.2702
1185.11	17.3502
1188.35	20.6856
1191.59	22.373
1194.83	24.8821
1198.07	28.0498
1201.3	29.7607
1204.53	32.8872
1207.77	36.7403
1211	41.0713
1214.23	46.2242
1217.46	49.6329
1220.69	53.4222
1223.91	56.611
1227.14	59.1755
1230.36	61.1279
1233.59	64.4023
1236.81	66.4832
1240.03	69.907
1243.25	73.0369
1246.46	76.5928
1249.68	79.1986
1252.9	81.4096
1256.11	84.0732
1259.32	85.8752
1262.54	86.819
1265.75	89.803
1268.96	91.6166
1272.16	92.1563
1275.37	95.807
1278.57	98.1687
1281.78	100.318
1284.98	104.32
1288.18	104.418
1291.38	104.644
1294.58	105.621
1297.78	105.392
1300.98	105.823
1304.17	106.873
1307.37	108.2
1310.56	107.605
1313.76	107.921
1316.95	107.903
1320.14	108.026
1323.32	108.246
1326.51	107.133
1329.7	105.713
1332.88	104.621
1336.07	101.977
1339.25	100.629
1342.43	97.0322
1345.61	93.0843
1348.79	88.6651
1351.96	85.7946
1355.14	83.5412
1358.31	78.9149
1361.49	75.6594
1364.66	71.1439
1367.83	67.6541
1371	65.2075
1374.17	64.2472
1377.34	60.3502
1380.5	59.9638
1383.67	59.2635
1386.83	57.1825
1390	55.8948
1393.16	54.3443
1396.32	52.4026
1399.48	50.7146
1402.64	51.0811
1405.79	50.0527
1408.95	50.05
1412.1	50.7945
1415.26	51.938
1418.41	53.4022
1421.56	55.9534
1424.71	59.7858
1427.86	65.1647
1431	71.6376
1434.15	76.7933
1437.29	83.7111
1440.44	87.806
1443.58	91.4494
1446.72	95.8774
1449.86	97.0454
1453	97.9497
1456.14	97.834
1459.27	95.6428
1462.41	92.7092
1465.54	87.1218
1468.67	80.4868
1471.81	73.8849
1474.94	67.0657
1478.07	61.022
1481.19	53.0118
1484.32	45.9477
1487.45	40.5104
1490.57	36.1119
1493.69	31.2813
1496.82	29.0143
1499.94	28.552
1503.06	27.9848
1506.17	27.3012
1509.29	26.9593
1512.41	26.6901
1515.52	26.8415
1518.64	27.3966
1521.75	27.7716
1524.86	28.814
1527.97	29.076
1531.08	30.5525
1534.19	31.0979
1537.29	31.5866
1540.4	33.945
1543.5	35.4248
1546.61	38.0903
1549.71	41.0987
1552.81	45.1345
1555.91	47.8653
1559.01	51.9565
1562.11	55.9248
1565.2	59.7701
1568.29	64.4996
1571.39	68.4303
1574.48	72.4978
1577.57	75.9146
1580.66	78.4303
1583.75	80.1446
1586.84	81.7878
1589.93	83.9417
1593.01	85.0419
1596.1	84.7653
1599.18	85.4323
1602.26	85.211
1605.34	83.6249
1608.42	82.3708
1611.5	82.0425
1614.58	82.614
1617.65	82.9516
1620.73	84.124
1623.8	85.9353
1626.87	87.5414
1629.95	90.6598
1633.02	93.7638
1636.09	97.0238
1639.15	100.569
1642.22	104.785
1645.29	109.025
1648.35	113.386
1651.42	117.264
1654.48	120.345
1657.54	122.456
1660.6	122.077
1663.66	122.458
1666.72	121.158
1669.77	117.359
1672.83	113.099
1675.88	107.838
1678.93	100.817
1681.99	93.6177
1685.04	86.3454
1688.09	80.0433
1691.13	71.1087
1694.18	63.1845
1697.23	55.0304
1700.27	47.8809
1703.32	41.3114
1706.36	34.7294
1709.4	28.9913
1712.44	25.402
1715.48	21.5147
1718.52	18.6757
1721.56	16.7455
1724.59	14.7567
1727.63	12.8018
1730.66	11.2762
1733.69	9.45176
1736.72	9.35221
1739.75	8.88702
1742.78	7.94579
1745.81	8.72092
1748.84	8.66761
1751.86	8.15491
1754.89	8.1807
1757.91	8.19208
1760.93	8.98602
1763.95	8.81027
1766.97	8.33627
1769.99	6.63394
1773.01	6.14545
1776.03	6.46804
1779.04	5.85871
1782.06	4.80647
1785.07	4.07109
1788.08	3.52068
1791.09	2.80961
1794.1	1.85276
1797.11	1.48162
1800.12	0.997959
1803.12	0.345797
1806.13	-0.403922
1809.13	-0.153985
1812.14	-0.0264491
1815.14	-0.106618
1818.14	0.0314742
1821.14	1.00609
1824.14	0.57135
1827.13	1.33698
1830.13	1.59668
1833.12	1.83164
1836.12	1.45576
1839.11	0.429711
1842.1	0.762754
1845.09	1.37362
1848.08	2.59892
1851.07	2.44806
1854.06	1.87058
1857.04	1.40259
1860.03	2.07343
1863.01	2.6566
1866	3.63959
1868.98	4.46412
1871.96	4.61046
1874.94	5.07943
1877.92	5.11041
1880.89	5.85349
1882.48	6.09831
1885.47	6.53184
1888.46	7.23313
1891.44	7.9084
1894.43	8.68325
1897.41	8.31144
1900.4	6.9086
1903.38	5.73989
1906.36	5.197
1909.34	5.5671
1912.32	5.80223
1915.29	6.23856
1918.27	6.24202
1921.25	4.76409
1924.22	3.93953
1927.2	4.22254
1930.17	4.254
1933.14	4.38524
1936.11	4.4921
1939.08	4.98331
1942.05	4.81333
1945.01	5.127
1947.98	5.16358
1950.94	6.01314
1953.91	6.69572
1956.87	7.4354
1959.83	7.844
1962.79	8.1131
1965.75	7.46813
1968.71	6.97697
1971.67	5.72447
1974.62	5.55837
1977.58	5.3805
1980.53	5.74183
1983.48	5.69059
1986.43	4.74174
1989.38	3.71804
1992.33	4.03138
1995.28	3.63332
1998.23	2.77671
2001.18	2.55421
2004.12	1.93482
2007.06	1.11337
2010.01	1.18064
2012.95	0.789031
2015.89	1.91898
2018.83	3.22298
2021.77	3.93694
2024.71	4.19315
2027.64	4.84585
2030.58	5.54323
2033.51	6.78372
2036.45	6.64165
2039.38	7.55162
2042.31	9.13957
2045.24	9.81586
2048.17	10.6149
2051.1	11.8264
2054.02	12.8187
2056.95	14.3318
2059.87	14.3227
2062.8	14.464
2065.72	15.7755
2068.64	16.41
2071.56	16.8996
2074.48	17.0562
2077.4	17.7773
2080.31	18.8019
2083.23	20.6053
2086.14	21.634
2089.06	23.3758
2091.97	23.8244
2094.88	23.9656
2097.79	23.9948
2100.7	25.4762
2103.61	27.0347
2106.52	29.1412
2109.43	31.5537
2112.33	34.7445
2115.24	37.9451
2118.14	40.8264
2121.04	44.4962
2123.94	48.9942
2126.84	53.9282
2129.74	58.2677
2132.64	63.4422
2135.54	68.6602
2138.43	73.984
2141.33	77.8863
2144.22	82.9946
2147.11	86.8607
2150.01	90.5794
2152.9	94.7703
2155.79	98.5244
2158.67	101.024
2161.56	103.376
2164.45	104.915
2167.33	107.044
2170.22	108.434
2173.1	107.951
2175.98	107.493
2178.86	105.508
2181.74	103.957
2184.62	101.862
2187.5	99.9343
2190.38	97.4313
2193.25	94.9992
2196.13	91.8708
2199	88.2082
2201.88	83.3495
2204.75	78.8056
2207.62	73.5457
2210.49	69.1404
2213.36	64.2142
2216.22	59.7431
2219.09	55.8914
2221.96	52.5105
2224.82	50.2148
2227.68	46.4934
2230.55	44.331
2233.41	41.0306
2236.27	38.8225
2239.12	36.0299
2241.98	33.2491
2244.84	30.4846
2247.7	28.7415
2250.55	27.3451
2253.41	26.0913
2256.26	25.2001
2259.11	24.1905
2261.96	24.2051
2264.81	23.7574
2267.66	22.6203
2270.51	21.4531
2273.35	20.1102
2276.2	19.2602
2279.04	18.601
2281.89	17.6073
2284.73	16.4157
2287.57	15.2362
2290.41	13.6336
2293.25	11.4763
2296.09	10.8244
2298.93	10.1465
2301.76	9.85088
2304.6	9.60427
2307.44	9.96172
2310.27	8.76102
2313.1	7.70893
2315.93	6.89712
2318.76	6.7338
2321.59	6.27235
2324.42	6.70221
2327.25	6.25501
2330.07	6.17484
2332.9	5.82292
2335.72	5.51878
2338.55	4.94417
2341.37	3.9789
2344.19	3.17175
2347.01	2.95535
2349.83	2.35262
2352.65	1.40572
2355.46	1.17881
2358.28	0.581243
2361.09	-0.706257
2363.91	0.233612
2366.72	0.812543
2369.53	0.843818
2372.34	0.54376
2375.15	0.395604
2377.96	-0.843456
2380.77	-0.180675
2383.58	0.880453
2386.38	1.25616
2389.19	2.26249
2391.99	2.29867
2394.8	1.89645
2397.6	2.67304
2400.4	3.19014
2403.2	3.58647
2406	4.09407
2408.79	4.40388
2411.59	4.8436
2414.39	5.05649
2417.18	6.04386
2419.98	6.20712
2422.77	6.39961
2425.56	6.7868
2428.35	6.36344
2431.14	5.69644
2433.93	5.05663
2436.72	4.35252
2439.5	3.8309
2442.29	4.06125
2445.07	2.76087
2447.86	3.32213
2450.64	4.83483
2453.42	4.47354
2456.2	3.9732
2458.98	3.75769
2461.76	3.67739
2464.54	3.51099
2467.32	3.64758
2470.09	3.45884
2472.87	3.69731
2475.64	4.316
2478.41	4.55347
2481.18	3.84978
2483.95	2.95907
2486.72	2.64601
2489.49	2.09046
2492.26	2.13674
2495.03	1.37383
2497.79	0.58879
2500.56	-0.0472475
2503.32	-0.765324
2506.09	-1.08315
2508.85	-1.4446
2511.61	-0.822081
2514.37	-0.645162
2517.13	1.03992
2519.89	0.619299
2522.64	0.222823
2525.4	0.467353
2528.15	1.40213
2530.91	1.52147
2533.66	1.6283
2536.41	2.43461
2539.16	2.83346
2541.91	3.9688
2544.66	3.84632
2547.41	2.9868
2550.16	2.92598
2552.9	3.75798
2555.65	3.81647
2558.39	3.64262
2561.13	4.33784
2563.88	4.77088
2566.62	4.22868
2569.36	4.52169
2572.1	5.20228
2574.84	5.24136
2577.57	5.84051
2580.31	6.19186
2583.05	6.48891
2585.78	7.27837
2588.51	7.47825
2591.24	7.46516
2593.98	7.14205
2596.71	6.0936
2599.44	6.2778
2602.16	5.36735
2604.89	5.14488
2607.62	5.28569
2610.34	5.03656
2613.07	3.83699
2615.79	3.71063
2618.52	3.91796
2621.24	3.93086
2623.96	4.567
2626.68	4.97863
2629.4	5.66836
2632.11	6.22881
2634.83	7.03346
2637.55	7.89041
2640.26	9.20455
2642.98	10.1413
2645.69	10.5802
2648.4	10.5183
2651.11	11.3204
2653.82	11.1316
2656.53	10.0557
2659.24	8.68594
2661.95	7.24105
2664.65	6.69959
2667.36	5.97202
2670.06	6.09166
2672.76	5.72776
2675.47	5.20825
2678.17	4.04023
2680.87	4.72558
2683.57	6.06635
2686.27	6.30761
2688.97	7.69322
2691.66	7.97711
2694.36	9.55207
2697.05	11.9687
2699.75	13.6671
2702.44	15.4098
2705.13	17.2693
2707.82	18.7006
2710.51	19.8595
2713.2	20.152
2715.89	21.4596
2718.57	22.2852
2721.26	22.826
2723.95	23.6419
2726.63	24.8151
2729.31	25.0894
2732	25.4306
2734.68	24.8517
2737.36	24.7873
2740.04	25.0317
2742.72	24.2046
2745.39	24.2191
2748.07	23.4612
2750.75	23.3944
2753.42	23.3541
2756.09	23.6533
2758.77	23.2122
2761.44	23.5052
2764.11	22.6706
2766.78	22.1893
2769.45	21.3796
2772.12	21.0698
2774.78	20.0832
2777.45	19.2845
2780.12	19.469
2782.78	19.2326
2785.44	19.747
2788.11	20.024
2790.77	19.1471
2793.43	18.7378
2796.09	18.9324
2798.75	18.7888
2801.4	19.2866
2804.06	20.7277
2806.72	21.4431
2809.37	22.2108
2812.03	22.4104
2814.68	23.7308
2817.33	25.1781
2819.98	27.1242
2822.63	30.9083
2825.28	34.8214
2827.93	39.4638
2830.58	44.519
2833.23	50.3964
2835.87	55.3525
2838.52	62.0291
2841.16	69.8668
2843.8	77.7992
2846.44	87.6398
2849.08	98.8794
2851.73	110.786
2854.36	123.464
2857	136.729
2859.64	149.431
2862.28	161.582
2864.91	172.843
2867.55	184.312
2870.18	193.766
2872.81	201.842
2875.44	209.011
2878.07	215.434
2880.7	221.956
2883.33	228.273
2885.96	235.22
2888.59	241.282
2891.21	247.844
2893.84	254.906
2896.46	261.101
2899.09	269.116
2901.71	278.017
2904.33	289.628
2906.95	303.063
2909.57	319.284
2912.19	336.303
2914.81	353.817
2917.43	371.602
2920.04	386.246
2922.66	399.01
2925.27	410.668
2927.88	418.723
2930.5	423.629
2933.11	425.983
2935.72	424.275
2938.33	420.44
2940.94	413.105
2943.54	403.434
2946.15	391.903
2948.76	379.041
2951.36	365.603
2953.97	351.221
2956.57	336.02
2959.17	319.809
2961.77	304.497
2964.37	290.266
2966.97	276.709
2969.57	263.77
2972.17	252.802
2974.77	239.458
2977.36	228.333
2979.96	217.417
2982.55	204.571
2985.15	192.18
2987.74	179.961
2990.33	167.335
2992.92	153.626
2995.51	141.645
2998.1	129.214
3000.69	117.7
3003.27	107.033
3005.86	96.7905
3008.44	88.2865
3011.03	81.0538
3013.61	74.0374
3016.19	68.9298
3018.78	63.9107
3021.36	59.6756
3023.94	56.2059
3026.51	54.0909
3029.09	52.7913
3031.67	51.8033
3034.24	51.3327
3036.82	52.094
3039.39	52.5112
3041.97	54.523
3044.54	55.62
3047.11	56.7
3049.68	57.7695
3052.25	58.3621
3054.82	58.2013
3057.39	57.8736
3059.96	56.7138
3062.52	55.9348
3065.09	53.8791
3067.65	51.5348
3070.22	49.5383
3072.78	46.1998
3075.34	42.3343
3077.9	39.9849
3080.46	37.1635
3083.02	33.0498
3085.58	29.9413
3088.14	26.9666
3090.69	24.0454
3093.25	21.3214
3095.8	19.6263
3098.36	18.1832
3100.91	16.9344
3103.46	15.0421
3106.01	15.1459
3108.56	14.0895
3111.11	12.9637
3113.66	11.3018
3116.21	10.3209
3118.76	8.83245
3121.3	7.64453
3123.85	6.7668
3126.39	5.68824
3128.93	4.55132
3131.48	4.0671
3134.02	2.5291
3136.56	1.37671
3139.1	1.58819
3141.64	1.1164
3144.17	1.0586
3146.71	1.38923
3149.25	2.71373