File: data/Raman/poly_smoothed/Thy_50_12_28_1x_45s_532 nm_x100_100%_600 gr_mm_01.txt
#Acq. time (s)=	45
#Accumulations=	2
#Range (cm-¹)=	200...3150
#Windows=	2
#Auto scanning=	Off
#Autofocus=	Off
#Macrospot=	Off
#AutoExposure=	Off
#Spike filter=	Multiple accum.
#Delay time (s)=	0
#Binning=	1
#Readout mode=	Signal
#DeNoise=	Off
#ICS correction=	On
#Dark correction=	Off
#Inst. Process=	Off
#Detector Gain=	Best Dynamic Range
#Detector ADC=	20 kHz
#Detector temperature (°C)=	-69.85
#Instrument=	LabRAM HR Evol
#Detector=	Synapse
#Objective=	x100
#Grating=	600 gr/mm
#ND Filter=	100%
#Laser (nm)=	532
#Hole=	100.021
#Range=	Auto
#Laser Pol.=	No
#Raman. Pol.=	No
#Laser Pol. (°)=	-0.0007625
#Raman Pol. (°)=	89.9995
#Collection=	Microscope
#StageXY=	Marzhauser
#StageZ=	Marzhauser
#X (µm)=	-5141.6
#Y (µm)=	1503.1
#Z (µm)=	63.2
#Full time(mm:ss)=	3:18
#Project=
#Sample=
#Site=
#Title=	Thy_50_12_28_2x_45s_532 nm_x100_100%_600 gr_mm
#Remark=
#Date=	07.07.2022 11:18
#Acquired=	07.07.2022 11:18:00
#Base:Fit=	10.08.2022 10:04:29
#Base:Sub=	10.08.2022 10:04:45
#Filter:Polynom=	16.08.2022 10:20:25
#AxisType[0]=Intens
#AxisUnit[0]=Cnt
#AxisType[1]=Spectr
#AxisUnit[1]=1/cm
200.43	17.9676
204.061	22.7003
207.688	23.7243
211.316	22.0901
214.941	19.8758
218.566	17.1591
222.188	15.8133
225.809	15.2064
229.43	13.8593
233.047	11.1457
236.663	10.5855
240.278	10.9066
243.894	11.1604
247.506	10.8624
251.116	8.53903
254.725	7.63389
258.333	5.91622
261.939	5.52089
265.546	7.33087
269.15	8.21223
272.752	9.94523
276.353	11.0319
279.952	11.9224
283.55	11.9225
287.146	12.8294
290.739	12.9738
294.333	10.9811
297.925	11.1017
301.516	11.5592
305.106	11.8458
308.694	12.3232
312.279	11.5728
315.864	11.4118
319.448	9.18333
323.029	8.82816
326.61	9.98121
330.19	10.1669
333.766	10.1635
337.343	9.15235
340.917	7.02564
344.491	7.46055
348.062	8.06871
351.633	8.69407
355.201	8.92558
358.77	8.09209
362.335	8.60744
365.899	7.39592
369.464	7.21956
373.025	7.00725
376.585	5.95877
380.143	5.87233
383.702	3.60122
387.258	4.25217
390.812	3.92347
394.365	2.06104
397.916	1.67925
401.467	1.78478
405.015	0.383446
408.565	1.39306
412.111	1.16438
415.656	3.00179
419.197	4.86287
422.739	4.73099
426.279	4.72732
429.819	6.72961
433.356	6.71411
436.893	5.88987
440.428	6.76847
443.96	6.10224
447.492	6.20086
451.023	6.1688
454.553	6.56722
458.079	7.62171
461.606	7.52801
465.132	8.08611
468.654	10.128
472.177	12.503
475.696	14.7915
479.217	15.5222
482.733	17.2377
486.251	18.6468
489.765	20.1146
493.278	21.7534
496.791	24.463
500.301	25.8563
503.81	28.0574
507.319	28.0493
510.825	27.7073
514.33	28.202
517.833	28.4246
521.337	29.3083
524.838	28.5689
528.337	28.2312
531.835	26.5599
535.332	25.3324
538.827	23.3221
542.321	22.9812
545.814	21.1152
549.305	20.8781
552.795	20.7606
556.284	19.5888
559.771	18.5183
563.257	17.3137
566.742	14.1134
570.223	11.6973
573.705	10.5772
577.185	10.4077
580.665	10.1714
584.141	8.35865
587.617	7.22681
591.092	6.55424
594.564	6.15065
598.037	7.16153
601.506	8.13756
604.976	8.67552
608.443	9.09294
611.91	7.35613
615.374	7.2187
618.839	8.5966
622.3	8.63654
625.761	9.87814
629.221	11.466
632.679	12.3042
636.135	12.9316
639.592	14.2725
643.045	15.5641
646.497	15.5239
649.948	17.1456
653.398	18.8958
656.846	20.9369
660.293	23.4639
663.738	23.2583
667.185	24.4072
670.628	24.6323
674.067	27.3451
677.508	30.3042
680.947	32.9389
684.385	36.0032
687.821	37.3053
691.256	39.4959
694.69	39.8922
698.121	41.7
701.552	42.9271
704.982	44.2143
708.41	44.9648
711.836	46.4866
715.262	47.0988
718.685	46.5583
722.108	49.2837
725.53	51.2771
728.949	51.2102
732.369	52.3407
735.785	52.7965
739.2	51.4855
742.616	51.7914
746.028	52.2853
749.441	53.8061
752.851	58.2692
756.26	60.913
759.667	64.4896
763.075	67.0071
766.479	69.8521
769.883	70.909
773.285	71.8095
776.686	73.2519
780.085	75.3658
783.484	76.9376
786.881	78.9099
790.276	81.1394
793.671	82.0267
797.064	83.3616
800.456	83.9013
803.846	85.0832
807.236	84.7948
810.624	83.176
814.01	81.3732
817.394	80.9835
820.778	80.25
824.161	79.4175
827.543	80.1563
830.921	77.971
834.3	78.0771
837.676	76.9716
841.053	74.3488
844.426	72.1411
847.8	68.9091
851.171	65.8492
854.542	62.2562
857.911	61.043
861.279	59.6243
864.645	60.5455
868.01	59.5404
871.375	58.0476
874.737	56.3713
878.097	53.8186
881.457	53.1768
884.817	51.5672
888.174	49.4911
891.53	48.6286
894.884	47.1141
898.237	47.1442
901.589	47.938
904.94	45.4283
908.289	45.6726
911.637	45.4694
914.984	44.628
918.33	43.6454
921.674	43.1408
925.015	41.2884
928.357	41.4785
931.698	39.4333
935.037	39.3892
938.373	39.5198
941.71	39.3726
945.046	37.5429
948.378	37.232
951.711	37.3171
955.043	37.2622
958.372	36.2689
961.701	34.5072
965.027	34.492
968.354	34.058
971.678	33.5493
975	33.748
978.324	32.9626
981.644	34.8859
984.962	34.5123
988.282	34.8243
991.598	36.8106
994.913	36.9548
998.227	37.0174
1001.54	39.2688
1004.85	37.9137
1008.16	38.2631
1011.47	37.7251
1014.78	37.3687
1018.08	37.6143
1021.39	36.7381
1024.69	35.0546
1028	35.1003
1031.3	35.8399
1034.6	36.0299
1037.9	34.4192
1041.19	33.67
1044.49	33.4853
1047.79	33.2348
1051.08	32.9303
1054.37	30.9643
1057.66	31.2716
1060.95	29.5471
1064.24	30.7238
1067.53	29.9369
1070.81	30.0249
1074.1	29.8596
1077.38	28.734
1080.66	27.3452
1083.94	25.2088
1087.22	23.244
1090.5	23.1225
1093.78	22.931
1097.05	22.1083
1100.33	20.5175
1103.6	20.5277
1106.87	17.8503
1110.15	17.8644
1113.41	17.4957
1116.68	17.3041
1119.95	15.8535
1123.21	14.4235
1126.48	13.9685
1129.74	12.9492
1133	11.0878
1136.26	11.6833
1139.52	11.0776
1142.78	11.5009
1146.04	8.97353
1149.29	9.17251
1152.55	8.08719
1155.8	6.79261
1159.05	5.16894
1162.3	3.89556
1165.55	3.5487
1168.8	2.49976
1172.05	3.49361
1175.29	3.93
1178.54	4.39905
1181.78	3.40054
1185.02	3.3392
1188.26	2.53627
1191.5	3.49649
1194.74	3.39528
1197.97	3.89608
1201.21	3.96214
1204.44	5.45835
1207.68	7.99581
1210.91	10.8909
1214.14	14.3149
1217.37	15.5667
1220.6	18.3952
1223.82	22.1288
1227.05	26.6325
1230.27	30.4735
1233.49	33.8059
1236.72	37.7877
1239.94	41.5818
1243.16	44.964
1246.37	47.8893
1249.59	51.1458
1252.8	53.9324
1256.02	57.4851
1259.23	58.8956
1262.44	59.7984
1265.66	63.164
1268.87	66.0045
1272.07	69.6412
1275.28	72.5445
1278.48	75.3112
1281.69	76.9706
1284.89	78.7531
1288.09	80.6368
1291.3	80.1672
1294.49	80.6871
1297.69	80.4243
1300.89	81.0397
1304.09	81.7836
1307.28	82.2916
1310.47	82.6354
1313.66	81.6241
1316.86	79.9536
1320.05	76.7521
1323.23	74.7164
1326.42	72.1983
1329.61	70.1756
1332.79	67.4137
1335.98	66.5954
1339.16	65.5942
1342.34	64.7379
1345.52	64.3419
1348.7	63.8541
1351.87	62.9983
1355.05	63.2491
1358.23	60.6834
1361.4	58.8626
1364.57	56.9999
1367.74	54.8181
1370.91	52.9032
1374.08	51.633
1377.25	49.4867
1380.42	48.3479
1383.58	48.1812
1386.75	47.0406
1389.91	44.4556
1393.07	41.7567
1396.23	39.4872
1399.39	38.8291
1402.55	38.2445
1405.7	37.8563
1408.86	37.7178
1412.01	37.8037
1415.17	39.3875
1418.32	42.6332
1421.47	45.4768
1424.62	51.2335
1427.77	55.4983
1430.92	61.1858
1434.06	66.4718
1437.2	70.1328
1440.35	74.459
1443.49	76.8304
1446.63	79.0047
1449.77	80.4306
1452.91	82.0814
1456.05	81.3773
1459.18	80.2587
1462.32	77.3617
1465.45	73.0791
1468.59	67.0247
1471.72	61.2349
1474.85	56.6404
1477.98	50.8037
1481.11	44.7703
1484.23	38.6457
1487.36	33.6973
1490.48	27.8883
1493.61	24.895
1496.73	22.627
1499.85	22.2674
1502.97	20.6094
1506.09	20.4454
1509.2	21.027
1512.32	22.7316
1515.44	23.5207
1518.55	24.5562
1521.66	26.0968
1524.77	28.4787
1527.88	31.0089
1530.99	32.9453
1534.1	35.127
1537.21	37.8736
1540.31	40.6165
1543.42	44.2179
1546.52	47.7846
1549.62	52.4172
1552.72	55.5002
1555.82	58.6361
1558.92	62.0415
1562.02	65.7625
1565.11	69.2335
1568.21	73.586
1571.3	78.3299
1574.39	81.6145
1577.49	83.9699
1580.58	86.2919
1583.67	88.3402
1586.75	90.2919
1589.84	91.8209
1592.93	89.9333
1596.01	90.0631
1599.09	89.1428
1602.18	87.9443
1605.26	86.9301
1608.34	84.9197
1611.41	83.1882
1614.49	82.8624
1617.57	82.562
1620.64	82.5141
1623.72	82.7563
1626.79	83.3393
1629.86	85.9167
1632.93	89.5043
1636	92.5531
1639.07	95.9802
1642.14	99.5388
1645.2	101.893
1648.27	102.843
1651.33	104.048
1654.39	104.607
1657.45	106.119
1660.51	105.613
1663.57	104.182
1666.63	100.633
1669.69	97.169
1672.74	92.1913
1675.79	86.9814
1678.85	80.1035
1681.9	72.1518
1684.95	65.095
1688	59.1431
1691.05	53.582
1694.1	47.7766
1697.14	41.9434
1700.19	37.6864
1703.23	33.6804
1706.27	31.3212
1709.32	26.9708
1712.35	24.5084
1715.39	22.783
1718.43	20.5246
1721.47	19.0233
1724.5	17.1194
1727.54	16.5618
1730.57	15.7785
1733.61	14.5677
1736.64	14.4182
1739.67	13.1757
1742.7	12.9721
1745.72	12.0511
1748.75	10.8944
1751.78	10.7506
1754.8	9.752
1757.82	8.97943
1760.85	9.29696
1763.87	9.06652
1766.89	8.16702
1769.91	8.28388
1772.92	7.35618
1775.94	7.54201
1778.96	6.27922
1781.97	5.86526
1784.98	5.24648
1788	5.02906
1791.01	4.97978
1794.01	4.10105
1797.02	3.7693
1800.03	3.32575
1803.04	2.80726
1806.04	3.07912
1809.05	3.45407
1812.05	4.63617
1815.05	4.33269
1818.05	4.73854
1821.05	5.15519
1824.05	5.05743
1827.05	5.52808
1830.04	5.85102
1833.04	5.90369
1836.03	6.29232
1839.03	6.15173
1842.02	6.24083
1845.01	5.41934
1848	4.81943
1850.99	4.00319
1853.97	3.31059
1856.96	3.04834
1859.94	2.85785
1862.93	2.22128
1865.91	2.12709
1868.89	1.20452
1871.87	1.26667
1874.85	1.60212
1877.83	1.09291
1880.81	0.614164
1882.56	1.52105
1885.55	1.97394
1888.54	2.66693
1891.52	2.82806
1894.51	2.90122
1897.49	3.19715
1900.48	3.69996
1903.46	4.8012
1906.44	5.20376
1909.42	6.50283
1912.4	7.37304
1915.38	6.60247
1918.35	5.77788
1921.33	6.06999
1924.3	6.18126
1927.28	6.09755
1930.25	5.97893
1933.22	4.70613
1936.19	4.08861
1939.16	2.44347
1942.13	2.95498
1945.09	2.21176
1948.06	2.05328
1951.03	1.48857
1953.99	2.18887
1956.95	2.57939
1959.91	2.89357
1962.87	2.07438
1965.83	1.50737
1968.79	1.25231
1971.75	2.20266
1974.7	2.9939
1977.66	3.39245
1980.61	5.38601
1983.56	5.77977
1986.52	5.34911
1989.47	5.93802
1992.41	6.39342
1995.36	6.52912
1998.31	6.3387
2001.26	6.47493
2004.2	6.58221
2007.15	7.23073
2010.09	6.74356
2013.03	6.67354
2015.97	7.20569
2018.91	6.13763
2021.85	6.42736
2024.79	6.95365
2027.72	6.96538
2030.66	7.22213
2033.59	8.11801
2036.53	7.71818
2039.46	7.94185
2042.39	9.24384
2045.32	10.2126
2048.25	11.732
2051.18	13.5057
2054.1	14.2634
2057.03	13.5641
2059.95	15.0882
2062.88	16.2363
2065.8	17.8308
2068.72	19.2801
2071.64	21.5083
2074.56	23.7631
2077.48	25.814
2080.39	27.1113
2083.31	28.1488
2086.22	30.1309
2089.14	32.4291
2092.05	34.21
2094.96	36.5433
2097.87	39.7532
2100.78	42.2636
2103.69	44.7453
2106.6	48.5172
2109.51	51.0735
2112.41	54.5935
2115.32	58.8578
2118.22	62.9453
2121.12	66.703
2124.02	71.8941
2126.92	78.3896
2129.82	84.4031
2132.72	91.2394
2135.62	97.5194
2138.51	103.492
2141.41	108.617
2144.3	113.824
2147.19	118.555
2150.09	122.778
2152.97	126.083
2155.86	129.207
2158.75	131.976
2161.64	134.161
2164.53	134.497
2167.41	135.351
2170.3	133.987
2173.18	132.152
2176.06	131.31
2178.94	129.844
2181.82	126.563
2184.7	123.034
2187.58	120.692
2190.46	117.271
2193.33	114.332
2196.21	110.947
2199.08	107.564
2201.95	102.976
2204.83	98.9015
2207.7	94.5846
2210.57	89.7889
2213.43	84.609
2216.3	80.8948
2219.17	76.9973
2222.03	73.3159
2224.9	68.4816
2227.76	65.0901
2230.62	60.3462
2233.49	56.3122
2236.34	52.4564
2239.2	48.4018
2242.06	44.6947
2244.92	42.9966
2247.78	40.901
2250.63	38.1875
2253.48	36.5235
2256.34	33.7895
2259.19	32.1816
2262.04	30.472
2264.89	28.534
2267.74	27.9626
2270.59	25.9838
2273.43	24.2934
2276.28	22.5788
2279.12	20.4556
2281.97	19.1729
2284.81	18.5376
2287.65	16.4105
2290.49	15.2647
2293.33	12.1044
2296.17	12.1882
2299.01	12.1622
2301.84	11.3317
2304.68	10.0447
2307.51	9.90728
2310.35	10.2858
2313.18	10.6178
2316.01	10.229
2318.84	10.0047
2321.67	9.8765
2324.5	8.63358
2327.33	8.32066
2330.15	8.2598
2332.98	8.24378
2335.8	6.55731
2338.62	5.28005
2341.45	4.03341
2344.27	3.38223
2347.09	2.2562
2349.91	1.40694
2352.72	-0.244633
2355.54	-0.913909
2358.36	-1.55188
2361.17	-1.19919
2363.98	-0.290034
2366.8	0.315753
2369.61	-0.529193
2372.42	-0.952133
2375.23	-0.86323
2378.04	-0.466295
2380.85	0.256419
2383.66	0.31631
2386.46	0.93661
2389.26	1.08954
2392.07	1.78592
2394.87	2.9775
2397.67	3.68165
2400.47	4.71387
2403.27	5.27395
2406.07	4.65193
2408.87	6.00487
2411.67	5.7457
2414.46	5.58268
2417.26	4.6471
2420.05	4.60135
2422.84	4.20948
2425.64	4.47897
2428.43	6.00673
2431.22	6.44117
2434.01	6.30345
2436.79	6.26816
2439.58	5.43311
2442.37	5.68804
2445.15	7.03492
2447.93	6.64206
2450.72	6.44538
2453.5	6.93746
2456.28	5.98122
2459.06	6.05296
2461.84	6.11553
2464.62	5.78742
2467.39	5.60847
2470.17	4.98843
2472.94	4.08488
2475.72	5.14073
2478.49	3.85454
2481.26	2.69069
2484.03	1.74589
2486.8	1.6751
2489.57	1.9424
2492.34	2.08696
2495.1	3.00613
2497.87	3.10615
2500.63	3.14545
2503.4	3.27173
2506.16	2.8523
2508.92	2.94769
2511.68	2.71804
2514.44	2.67962
2517.2	2.89735
2519.96	2.41773
2522.72	1.66889
2525.47	1.3864
2528.23	2.0683
2530.98	2.24304
2533.74	3.11926
2536.49	2.84488
2539.24	3.42166
2541.99	4.57505
2544.74	4.92909
2547.49	4.01016
2550.23	4.37184
2552.98	4.9602
2555.72	5.68755
2558.47	5.67706
2561.21	5.9846
2563.95	5.39359
2566.69	5.90497
2569.43	4.98764
2572.17	4.78911
2574.91	3.6168
2577.65	2.60365
2580.39	1.42993
2583.12	1.3848
2585.85	0.602626
2588.59	0.511336
2591.32	0.287115
2594.05	0.176445
2596.78	-0.0609905
2599.51	-0.28827
2602.24	0.395893
2604.97	0.31975
2607.69	1.597
2610.42	1.79664
2613.14	2.12303
2615.87	3.35952
2618.59	4.29012
2621.31	4.95485
2624.03	5.75721
2626.75	6.53222
2629.47	6.87989
2632.19	7.42987
2634.91	7.90445
2637.62	7.74942
2640.34	6.53859
2643.05	6.26581
2645.76	6.53227
2648.48	7.10131
2651.19	7.29803
2653.9	7.10729
2656.6	7.02797
2659.31	6.46776
2662.02	6.36202
2664.73	6.13931
2667.43	7.50207
2670.14	7.50953
2672.84	7.50316
2675.54	7.62905
2678.24	7.6542
2680.94	8.24292
2683.64	8.48298
2686.34	8.45233
2689.04	8.88943
2691.74	9.41401
2694.43	9.73256
2697.13	9.90093
2699.82	10.1878
2702.51	10.5216
2705.21	10.0145
2707.9	10.6604
2710.58	11.4636
2713.27	11.6653
2715.96	12.5397
2718.65	12.8696
2721.33	12.9405
2724.02	13.5285
2726.71	14.3559
2729.39	14.9592
2732.07	14.5722
2734.75	14.0007
2737.43	13.777
2740.11	12.5525
2742.79	12.0601
2745.47	10.7011
2748.14	10.1881
2750.82	9.95698
2753.49	9.22986
2756.17	7.94997
2758.84	7.38521
2761.51	6.74792
2764.18	6.66928
2766.85	6.44918
2769.52	6.0133
2772.19	5.62046
2774.86	5.21788
2777.52	4.0749
2780.19	4.26489
2782.85	4.21635
2785.52	4.18098
2788.18	4.06524
2790.84	3.98526
2793.5	3.61903
2796.16	3.40617
2798.82	1.78286
2801.48	1.63932
2804.13	1.43471
2806.79	0.550038
2809.45	-0.402539
2812.1	-0.218138
2814.75	0.0959122
2817.41	1.80895
2820.06	4.81904
2822.71	9.13519
2825.36	16.678
2828	23.6839
2830.65	30.6942
2833.3	37.9355
2835.94	45.2688
2838.59	52.7509
2841.23	60.9426
2843.87	70.6059
2846.52	79.4028
2849.16	89.474
2851.8	99.4426
2854.44	111.211
2857.08	120.978
2859.71	131.484
2862.35	139.868
2864.98	147.199
2867.62	154.379
2870.25	160.746
2872.88	164.841
2875.52	169.915
2878.15	174.209
2880.78	178.44
2883.41	183.269
2886.03	188.684
2888.66	194.533
2891.29	199.813
2893.91	204.259
2896.54	209.422
2899.16	216.354
2901.78	222.71
2904.4	231.191
2907.02	241.277
2909.64	252.603
2912.26	265.996
2914.88	278.398
2917.5	290.438
2920.11	301.413
2922.73	309.746
2925.34	317.031
2927.96	320.866
2930.57	324.095
2933.18	323.889
2935.79	321.593
2938.4	316.901
2941.01	310.372
2943.62	301.309
2946.22	290.926
2948.83	279.784
2951.43	268.269
2954.04	254.307
2956.64	240.865
2959.24	228.531
2961.84	215.472
2964.45	202.426
2967.05	190.696
2969.64	180.364
2972.24	169.789
2974.84	159.702
2977.43	147.868
2980.03	136.049
2982.62	125.423
2985.22	113.818
2987.81	102.317
2990.4	91.7537
2992.99	81.4448
2995.58	71.4187
2998.17	62.3339
3000.76	54.4142
3003.34	46.6762
3005.93	40.016
3008.52	33.2558
3011.1	28.5238
3013.68	23.5043
3016.27	20.1601
3018.85	16.8333
3021.43	14.782
3024.01	12.9834
3026.59	11.3638
3029.16	10.7238
3031.74	10.985
3034.32	10.789
3036.89	10.6137
3039.47	9.97207
3042.04	11.1791
3044.61	11.9672
3047.18	12.3118
3049.75	12.8427
3052.32	13.0454
3054.89	13.272
3057.46	12.8674
3060.03	12.2581
3062.59	11.93
3065.16	11.6102
3067.72	10.2768
3070.29	9.33278
3072.85	8.41312
3075.41	6.41484
3077.97	5.86105
3080.53	3.98265
3083.09	2.28355
3085.65	0.61377
3088.21	0.650091
3090.76	0.251509
3093.32	-0.40789
3095.87	-0.980546
3098.43	-0.512974
3100.98	-0.630634
3103.53	-0.183025
3106.08	0.331079
3108.63	0.194393
3111.18	1.00739
3113.73	0.650439
3116.28	0.997259
3118.83	0.989827
3121.37	1.27492
3123.92	2.08891
3126.46	2.3994
3129	2.61847
3131.55	2.90721
3134.09	4.12303
3136.63	5.37304
3139.17	6.22203
3141.71	7.14578
3144.24	8.13159
3146.78	9.18087
3149.32	9.81205