File: data/Raman/poly_smoothed/Thy_50_12_36_1x_45s_532 nm_x100_100%_600 gr_mm_01.txt
#Acq. time (s)=	45
#Accumulations=	2
#Range (cm-¹)=	200...3150
#Windows=	2
#Auto scanning=	Off
#Autofocus=	Off
#Macrospot=	Off
#AutoExposure=	Off
#Spike filter=	Multiple accum.
#Delay time (s)=	0
#Binning=	1
#Readout mode=	Signal
#DeNoise=	Off
#ICS correction=	On
#Dark correction=	Off
#Inst. Process=	Off
#Detector Gain=	Best Dynamic Range
#Detector ADC=	20 kHz
#Detector temperature (°C)=	-69.85
#Instrument=	LabRAM HR Evol
#Detector=	Synapse
#Objective=	x100
#Grating=	600 gr/mm
#ND Filter=	100%
#Laser (nm)=	532
#Hole=	100.021
#Range=	Auto
#Laser Pol.=	No
#Raman. Pol.=	No
#Laser Pol. (°)=	-0.0007625
#Raman Pol. (°)=	89.9995
#Collection=	Microscope
#StageXY=	Marzhauser
#StageZ=	Marzhauser
#X (µm)=	-5131.5
#Y (µm)=	1515.4
#Z (µm)=	63.7
#Full time(mm:ss)=	3:18
#Project=
#Sample=
#Site=
#Title=	Thy_50_12_36_2x_45s_532 nm_x100_100%_600 gr_mm
#Remark=
#Date=	07.07.2022 11:54
#Acquired=	07.07.2022 11:54:59
#Base:Fit=	10.08.2022 10:04:30
#Base:Sub=	10.08.2022 10:04:45
#Filter:Polynom=	16.08.2022 10:20:25
#AxisType[0]=Intens
#AxisUnit[0]=Cnt
#AxisType[1]=Spectr
#AxisUnit[1]=1/cm
200.43	6.57291
204.061	7.52634
207.688	7.17027
211.316	7.73692
214.941	7.88674
218.566	7.27714
222.188	7.79624
225.809	7.28247
229.43	6.49776
233.047	5.27191
236.663	4.78691
240.278	4.53891
243.894	3.79701
247.506	4.36662
251.116	3.27909
254.725	3.69372
258.333	1.60007
261.939	3.95757
265.546	5.56395
269.15	5.79255
272.752	6.54536
276.353	5.72045
279.952	5.34251
283.55	6.12456
287.146	6.13693
290.739	7.18999
294.333	7.52885
297.925	9.17141
301.516	9.06174
305.106	9.96045
308.694	10.9061
312.279	12.4996
315.864	12.2891
319.448	11.1346
323.029	10.5162
326.61	11.4254
330.19	10.7458
333.766	11.8494
337.343	10.5996
340.917	9.4723
344.491	8.58449
348.062	9.10642
351.633	10.7228
355.201	10.1517
358.77	8.4145
362.335	6.53692
365.899	5.43317
369.464	7.49445
373.025	7.32196
376.585	7.71831
380.143	7.47493
383.702	8.18565
387.258	8.51516
390.812	8.86472
394.365	8.72598
397.916	8.28789
401.467	7.37823
405.015	5.49781
408.565	5.42408
412.111	6.59026
415.656	5.82685
419.197	6.4526
422.739	6.69054
426.279	6.38994
429.819	5.75263
433.356	7.02831
436.893	7.66794
440.428	7.61915
443.96	6.19202
447.492	5.54328
451.023	6.63579
454.553	7.31036
458.079	8.81575
461.606	11.083
465.132	13.5479
468.654	14.9122
472.177	18.0307
475.696	18.4143
479.217	20.409
482.733	23.1545
486.251	25.7298
489.765	26.5149
493.278	27.6954
496.791	29.8578
500.301	29.9877
503.81	31.4329
507.319	31.5565
510.825	30.5677
514.33	30.9022
517.833	30.216
521.337	29.0703
524.838	27.407
528.337	24.9367
531.835	23.0694
535.332	20.9577
538.827	20.5731
542.321	20.0976
545.814	19.3757
549.305	18.9901
552.795	18.4373
556.284	17.902
559.771	15.5076
563.257	13.7873
566.742	14.1207
570.223	12.8005
573.705	11.5108
577.185	8.82127
580.665	7.16597
584.141	5.77157
587.617	4.90126
591.092	4.11691
594.564	2.46142
598.037	2.19327
601.506	3.07573
604.976	2.57656
608.443	2.79736
611.91	2.29011
615.374	3.41524
618.839	3.33658
622.3	2.33019
625.761	3.78176
629.221	3.3995
632.679	3.35773
636.135	5.25903
639.592	6.77168
643.045	7.51058
646.497	9.7475
649.948	9.35403
653.398	10.5435
656.846	11.5734
660.293	12.291
663.738	14.1167
667.185	14.9843
670.628	16.547
674.067	16.0509
677.508	17.5962
680.947	18.7255
684.385	19.834
687.821	20.7274
691.256	20.9028
694.69	22.9683
698.121	23.9986
701.552	25.3674
704.982	26.3868
708.41	28.5925
711.836	32.0128
715.262	34.6519
718.685	37.851
722.108	39.0934
725.53	40.7127
728.949	40.7276
732.369	41.6814
735.785	42.4784
739.2	45.937
742.616	47.5424
746.028	50.139
749.441	53.2625
752.851	54.9691
756.26	56.7853
759.667	60.2523
763.075	62.3646
766.479	63.5574
769.883	65.2169
773.285	68.9677
776.686	69.4611
780.085	71.2429
783.484	72.4096
786.881	74.2955
790.276	76.3343
793.671	78.7275
797.064	80.1765
800.456	80.6411
803.846	79.7542
807.236	79.1151
810.624	78.8919
814.01	80.7746
817.394	78.8861
820.778	79.5339
824.161	78.6763
827.543	78.5512
830.921	79.3334
834.3	80.3398
837.676	76.8375
841.053	74.7866
844.426	71.9627
847.8	68.7608
851.171	65.5859
854.542	64.1909
857.911	60.5582
861.279	57.9068
864.645	57.2271
868.01	56.1439
871.375	55.0562
874.737	55.371
878.097	55.0567
881.457	54.9193
884.817	50.9546
888.174	50.1839
891.53	48.1875
894.884	46.9797
898.237	45.0064
901.589	43.2729
904.94	44.3394
908.289	41.9792
911.637	39.1301
914.984	36.5048
918.33	33.8391
921.674	31.3381
925.015	31.7061
928.357	29.4065
931.698	27.2662
935.037	26.006
938.373	26.3698
941.71	26.2595
945.046	27.6503
948.378	29.0145
951.711	31.9154
955.043	34.3049
958.372	34.7714
961.701	35.972
965.027	35.5077
968.354	36.8364
971.678	36.8641
975	38.2727
978.324	38.1502
981.644	38.6313
984.962	38.1039
988.282	36.9066
991.598	35.5056
994.913	36.5852
998.227	36.3031
1001.54	35.6144
1004.85	35.6047
1008.16	33.7441
1011.47	34.087
1014.78	36.2295
1018.08	38.3057
1021.39	39.0557
1024.69	39.7688
1028	43.5238
1031.3	48.395
1034.6	49.0644
1037.9	49.1611
1041.19	49.7257
1044.49	49.2722
1047.79	49.2152
1051.08	47.1101
1054.37	43.7075
1057.66	41.0596
1060.95	38.6052
1064.24	36.2276
1067.53	32.5668
1070.81	30.9282
1074.1	28.624
1077.38	25.8533
1080.66	23.3829
1083.94	20.9413
1087.22	19.1161
1090.5	19.7554
1093.78	21.5628
1097.05	21.5826
1100.33	21.3477
1103.6	22.1394
1106.87	23.7704
1110.15	26.201
1113.41	24.2826
1116.68	24.0513
1119.95	23.8325
1123.21	23.5446
1126.48	22.4192
1129.74	21.0986
1133	19.3408
1136.26	18.085
1139.52	18.4334
1142.78	15.5399
1146.04	13.5559
1149.29	11.7058
1152.55	10.1749
1155.8	9.01016
1159.05	5.03586
1162.3	3.18987
1165.55	1.82491
1168.8	1.68089
1172.05	2.43083
1175.29	2.41615
1178.54	3.69568
1181.78	4.76246
1185.02	5.24683
1188.26	6.05209
1191.5	7.01276
1194.74	8.5839
1197.97	9.90126
1201.21	10.3461
1204.44	14.0944
1207.68	15.9077
1210.91	18.6316
1214.14	22.0836
1217.37	25.4136
1220.6	27.9387
1223.82	29.3408
1227.05	33.7895
1230.27	38.6342
1233.49	41.1091
1236.72	44.6283
1239.94	48.2685
1243.16	52.1846
1246.37	54.8132
1249.59	57.4093
1252.8	60.3422
1256.02	66.3412
1259.23	69.107
1262.44	71.1072
1265.66	73.2338
1268.87	76.126
1272.07	78.8133
1275.28	80.5676
1278.48	82.6769
1281.69	84.3415
1284.89	86.9581
1288.09	88.5051
1291.3	89.1458
1294.49	91.0084
1297.69	91.8916
1300.89	92.5063
1304.09	94.3353
1307.28	95.6287
1310.47	96.68
1313.66	95.7782
1316.86	94.5393
1320.05	92.4012
1323.23	91.1196
1326.42	89.2358
1329.61	88.3602
1332.79	87.0793
1335.98	85.0682
1339.16	81.1478
1342.34	77.4118
1345.52	74.8847
1348.7	71.9612
1351.87	69.2481
1355.05	65.5542
1358.23	62.4155
1361.4	59.7096
1364.57	57.2699
1367.74	56.4477
1370.91	53.1058
1374.08	52.5818
1377.25	51.8635
1380.42	51.2056
1383.58	50.3069
1386.75	50.6608
1389.91	49.5133
1393.07	50.0833
1396.23	50.9703
1399.39	51.748
1402.55	52.9983
1405.7	54.7922
1408.86	56.5381
1412.01	58.7852
1415.17	61.8264
1418.32	66.7979
1421.47	71.8347
1424.62	78.3918
1427.77	83.5109
1430.92	87.3959
1434.06	93.2175
1437.2	97.6021
1440.35	102.101
1443.49	104.646
1446.63	105.579
1449.77	104.283
1452.91	104.089
1456.05	103.188
1459.18	99.4161
1462.32	94.938
1465.45	89.3322
1468.59	82.5918
1471.72	76.6854
1474.85	68.1315
1477.98	60.7141
1481.11	53.2671
1484.23	46.2784
1487.36	39.1643
1490.48	35.4812
1493.61	31.2027
1496.73	28.393
1499.85	26.0078
1502.97	23.4582
1506.09	22.4262
1509.2	23.0826
1512.32	23.3045
1515.44	24.4877
1518.55	25.4553
1521.66	26.8391
1524.77	28.9965
1527.88	32.0997
1530.99	34.4672
1534.1	34.9645
1537.21	37.7565
1540.31	42.5446
1543.42	47.2261
1546.52	51.8119
1549.62	55.464
1552.72	58.3366
1555.82	62.4987
1558.92	64.9044
1562.02	67.0122
1565.11	72.0273
1568.21	75.7332
1571.3	79.6325
1574.39	83.4033
1577.49	85.3614
1580.58	88.1926
1583.67	89.0862
1586.75	91.0902
1589.84	91.9733
1592.93	91.9131
1596.01	91.3247
1599.09	90.2743
1602.18	88.7974
1605.26	86.9129
1608.34	85.4558
1611.41	84.8898
1614.49	85.7038
1617.57	86.3785
1620.64	88.1678
1623.72	89.5149
1626.79	92.6411
1629.86	94.3176
1632.93	95.8885
1636	99.5169
1639.07	102.482
1642.14	106.378
1645.2	107.82
1648.27	110.05
1651.33	110.631
1654.39	110.755
1657.45	110.095
1660.51	108.635
1663.57	107.114
1666.63	102.437
1669.69	99.135
1672.74	92.7312
1675.79	86.7387
1678.85	77.6904
1681.9	70.6852
1684.95	63.2806
1688	57.5244
1691.05	51.2109
1694.1	47.1236
1697.14	43.4764
1700.19	38.7556
1703.23	34.5374
1706.27	30.2572
1709.32	27.2604
1712.35	25.0432
1715.39	22.4734
1718.43	20.5247
1721.47	18.6815
1724.5	18.2517
1727.54	16.9825
1730.57	16.2926
1733.61	16.1659
1736.64	15.5801
1739.67	14.4886
1742.7	13.4997
1745.72	12.3741
1748.75	10.6667
1751.78	8.41751
1754.8	7.55405
1757.82	6.87267
1760.85	7.67546
1763.87	7.21078
1766.89	7.3353
1769.91	6.80528
1772.92	6.1564
1775.94	5.96875
1778.96	5.45455
1781.97	5.02396
1784.98	4.61866
1788	4.76203
1791.01	5.00545
1794.01	4.0595
1797.02	4.76263
1800.03	5.02961
1803.04	5.25875
1806.04	5.17011
1809.05	4.34829
1812.05	3.25269
1815.05	3.21266
1818.05	3.7153
1821.05	3.53751
1824.05	2.44351
1827.05	2.08795
1830.04	2.1832
1833.04	2.227
1836.03	2.33469
1839.03	2.14798
1842.02	2.5237
1845.01	2.04785
1848	1.95585
1850.99	1.21675
1853.97	1.52168
1856.96	0.61273
1859.94	0.86591
1862.93	1.07646
1865.91	0.427311
1868.89	0.717352
1871.87	1.32735
1874.85	1.45169
1877.83	1.09647
1880.81	0.907709
1882.56	0.895787
1885.55	0.603086
1888.54	2.35321
1891.52	2.14966
1894.51	2.32385
1897.49	3.71018
1900.48	3.7892
1903.46	5.47147
1906.44	6.55583
1909.42	7.17907
1912.4	6.83754
1915.38	6.76558
1918.35	6.49254
1921.33	6.03117
1924.3	5.62349
1927.28	5.43382
1930.25	5.01239
1933.22	6.16184
1936.19	5.19874
1939.16	5.562
1942.13	5.72078
1945.09	4.80697
1948.06	5.83069
1951.03	4.93117
1953.99	4.6701
1956.95	5.53109
1959.91	5.22594
1962.87	5.346
1965.83	5.23977
1968.79	5.56991
1971.75	4.31134
1974.7	3.91336
1977.66	2.73437
1980.61	2.48471
1983.56	1.0456
1986.52	0.339459
1989.47	0.0597599
1992.41	-0.336593
1995.36	-0.697407
1998.31	-1.06118
2001.26	-1.09233
2004.2	-0.483616
2007.15	-0.644136
2010.09	0.595951
2013.03	1.91625
2015.97	1.83388
2018.91	2.34325
2021.85	3.3462
2024.79	2.83704
2027.72	3.29668
2030.66	4.34535
2033.59	4.7063
2036.53	5.97498
2039.46	6.72157
2042.39	7.9168
2045.32	8.69066
2048.25	10.221
2051.18	11.303
2054.1	12.3846
2057.03	13.2658
2059.95	14.7982
2062.88	16.5676
2065.8	17.8597
2068.72	18.4897
2071.64	21.3076
2074.56	23.3539
2077.48	25.5956
2080.39	28.0329
2083.31	31.1208
2086.22	33.163
2089.14	34.6899
2092.05	37.9925
2094.96	40.7293
2097.87	43.4871
2100.78	46.5009
2103.69	51.1777
2106.6	56.3894
2109.51	60.5458
2112.41	65.0021
2115.32	69.0063
2118.22	73.6749
2121.12	78.1539
2124.02	83.264
2126.92	88.9339
2129.82	95.277
2132.72	101.361
2135.62	107.277
2138.51	113.277
2141.41	119.48
2144.3	126.702
2147.19	130.959
2150.09	136.24
2152.97	140.514
2155.86	144.471
2158.75	146.731
2161.64	149.328
2164.53	151.001
2167.41	151.401
2170.3	152.082
2173.18	152.18
2176.06	149.624
2178.94	147.633
2181.82	143.784
2184.7	140.272
2187.58	137.257
2190.46	132.779
2193.33	128.402
2196.21	124.668
2199.08	120.549
2201.95	115.282
2204.83	110.123
2207.7	104.452
2210.57	98.4781
2213.43	93.1509
2216.3	87.3566
2219.17	81.8948
2222.03	76.8794
2224.9	72.4357
2227.76	67.3979
2230.62	63.0984
2233.49	58.8857
2236.34	54.5784
2239.2	50.6125
2242.06	47.1257
2244.92	43.473
2247.78	41.1421
2250.63	39.5128
2253.48	37.6717
2256.34	36.8916
2259.19	35.5568
2262.04	33.5965
2264.89	33.9298
2267.74	32.4566
2270.59	30.6229
2273.43	30.0368
2276.28	28.6095
2279.12	27.6406
2281.97	26.0197
2284.81	24.8954
2287.65	24.5077
2290.49	21.4869
2293.33	19.3909
2296.17	18.3702
2299.01	17.1187
2301.84	14.9617
2304.68	14.4952
2307.51	13.7789
2310.35	12.4057
2313.18	12.5989
2316.01	12.2781
2318.84	11.5011
2321.67	10.865
2324.5	9.88626
2327.33	9.00818
2330.15	8.859
2332.98	8.29652
2335.8	7.94828
2338.62	7.35499
2341.45	7.70182
2344.27	6.93255
2347.09	6.07717
2349.91	5.38964
2352.72	4.02522
2355.54	3.85609
2358.36	2.30188
2361.17	3.4172
2363.98	4.4495
2366.8	6.1387
2369.61	6.09789
2372.42	5.72842
2375.23	6.301
2378.04	6.26624
2380.85	7.08201
2383.66	7.10888
2386.46	6.78171
2389.26	6.82639
2392.07	6.63663
2394.87	6.75301
2397.67	6.46701
2400.47	7.44243
2403.27	6.99618
2406.07	8.35353
2408.87	9.29575
2411.67	9.81801
2414.46	8.79255
2417.26	9.3955
2420.05	9.70473
2422.84	10.5556
2425.64	10.9313
2428.43	11.0798
2431.22	11.5762
2434.01	10.8645
2436.79	9.68972
2439.58	9.1384
2442.37	8.8081
2445.15	8.92794
2447.93	8.68408
2450.72	8.01636
2453.5	7.34343
2456.28	7.29533
2459.06	7.01608
2461.84	6.57586
2464.62	5.65167
2467.39	5.76086
2470.17	5.81765
2472.94	5.4769
2475.72	5.62413
2478.49	5.3843
2481.26	4.27394
2484.03	3.30144
2486.8	3.0224
2489.57	2.85349
2492.34	3.07046
2495.1	2.15295
2497.87	2.15804
2500.63	1.67407
2503.4	0.485855
2506.16	0.333626
2508.92	0.394898
2511.68	0.00209265
2514.44	0.674008
2517.2	0.792984
2519.96	1.64175
2522.72	1.85263
2525.47	2.32373
2528.23	2.03545
2530.98	2.3508
2533.74	2.77993
2536.49	3.43077
2539.24	4.73475
2541.99	5.00025
2544.74	5.23235
2547.49	5.41274
2550.23	6.36508
2552.98	5.9042
2555.72	6.22222
2558.47	6.64996
2561.21	5.91695
2563.95	5.50616
2566.69	3.98535
2569.43	2.82928
2572.17	2.26158
2574.91	1.74437
2577.65	1.32321
2580.39	0.986494
2583.12	0.743475
2585.85	0.264677
2588.59	1.11899
2591.32	1.53382
2594.05	2.23529
2596.78	2.12948
2599.51	2.65762
2602.24	3.18336
2604.97	3.71196
2607.69	4.92425
2610.42	4.91976
2613.14	5.0274
2615.87	6.15976
2618.59	6.02196
2621.31	4.88131
2624.03	4.25808
2626.75	3.95765
2629.47	3.87764
2632.19	2.83868
2634.91	2.60731
2637.62	2.85296
2640.34	2.54727
2643.05	1.96215
2645.76	1.90754
2648.48	2.17245
2651.19	3.04417
2653.9	3.69851
2656.6	3.63579
2659.31	3.44324
2662.02	3.49433
2664.73	3.69565
2667.43	4.71248
2670.14	5.4292
2672.84	6.30183
2675.54	5.61283
2678.24	5.14841
2680.94	5.60837
2683.64	6.01833
2686.34	5.48087
2689.04	5.50866
2691.74	5.5205
2694.43	6.6713
2697.13	7.18306
2699.82	7.04704
2702.51	7.4785
2705.21	7.8008
2707.9	6.71007
2710.58	7.32007
2713.27	8.70632
2715.96	8.17831
2718.65	8.71483
2721.33	8.30955
2724.02	8.90802
2726.71	9.7877
2729.39	9.76958
2732.07	10.2579
2734.75	9.447
2737.43	8.54578
2740.11	8.59164
2742.79	8.47071
2745.47	8.67684
2748.14	9.47147
2750.82	8.52461
2753.49	8.08767
2756.17	7.20384
2758.84	6.81928
2761.51	6.64641
2764.18	5.44582
2766.85	4.57696
2769.52	3.72161
2772.19	3.08968
2774.86	2.38991
2777.52	2.55024
2780.19	1.53699
2782.85	0.751115
2785.52	0.81579
2788.18	0.462427
2790.84	0.753428
2793.5	0.450997
2796.16	-0.271078
2798.82	0.397098
2801.48	0.18797
2804.13	0.936323
2806.79	1.7512
2809.45	1.1381
2812.1	0.344184
2814.75	0.778559
2817.41	1.8396
2820.06	5.76877
2822.71	10.0353
2825.36	15.5024
2828	21.7422
2830.65	27.9694
2833.3	34.3098
2835.94	42.3978
2838.59	50.617
2841.23	58.6494
2843.87	68.3933
2846.52	78.8255
2849.16	90.4419
2851.8	102.531
2854.44	114.409
2857.08	126.492
2859.71	137.271
2862.35	147.09
2864.98	156.92
2867.62	165.099
2870.25	171.288
2872.88	177.361
2875.52	182.637
2878.15	189.07
2880.78	194.799
2883.41	201.876
2886.03	208.31
2888.66	214.162
2891.29	219.901
2893.91	226.964
2896.54	232.735
2899.16	240.971
2901.78	250.03
2904.4	259.721
2907.02	271.659
2909.64	284.376
2912.26	298.761
2914.88	313.516
2917.5	326.736
2920.11	337.831
2922.73	347.058
2925.34	354.829
2927.96	359.255
2930.57	362.667
2933.18	363.157
2935.79	360.775
2938.4	355.235
2941.01	347.857
2943.62	338.114
2946.22	328.005
2948.83	316.013
2951.43	302.181
2954.04	288.876
2956.64	273.855
2959.24	258.408
2961.84	244.004
2964.45	230.688
2967.05	216.75
2969.64	204.748
2972.24	191.618
2974.84	180.264
2977.43	168.398
2980.03	156.58
2982.62	144.57
2985.22	132.299
2987.81	120.265
2990.4	108.299
2992.99	97.2044
2995.58	86.2969
2998.17	74.1329
3000.76	63.5735
3003.34	53.9939
3005.93	45.2328
3008.52	37.8646
3011.1	30.9303
3013.68	24.427
3016.27	18.7031
3018.85	14.3572
3021.43	10.9937
3024.01	8.85422
3026.59	7.62145
3029.16	6.81699
3031.74	6.76346
3034.32	7.611
3036.89	8.6059
3039.47	9.91668
3042.04	12.2883
3044.61	13.9372
3047.18	15.5932
3049.75	17.1181
3052.32	18.4962
3054.89	19.0931
3057.46	19.1506
3060.03	18.9251
3062.59	17.2491
3065.16	16.809
3067.72	14.9315
3070.29	13.4143
3072.85	11.0732
3075.41	9.13345
3077.97	6.56799
3080.53	5.45423
3083.09	3.90776
3085.65	2.47129
3088.21	0.879826
3090.76	0.577784
3093.32	-0.0299074
3095.87	0.537066
3098.43	0.861244
3100.98	1.39854
3103.53	2.23952
3106.08	3.37908
3108.63	4.53326
3111.18	5.61344
3113.73	7.1785
3116.28	8.06106
3118.83	8.74761
3121.37	10.1817
3123.92	11.5224
3126.46	12.2698
3129	14.408
3131.55	15.4395
3134.09	16.6869
3136.63	18.7437
3139.17	20.5696
3141.71	22.3809
3144.24	24.6451
3146.78	27.0727
3149.32	30.8495