File: data/Raman/poly_smoothed/Thy_30_10_15_1x_45s_532 nm_x100_100%_600 gr_mm_01.txt
#Acq. time (s)=	45
#Accumulations=	2
#Range (cm-¹)=	200...3150
#Windows=	2
#Auto scanning=	Off
#Autofocus=	Off
#Macrospot=	Off
#AutoExposure=	Off
#Spike filter=	Multiple accum.
#Delay time (s)=	0
#Binning=	1
#Readout mode=	Signal
#DeNoise=	Off
#ICS correction=	On
#Dark correction=	Off
#Inst. Process=	Off
#Detector Gain=	Best Dynamic Range
#Detector ADC=	20 kHz
#Detector temperature (°C)=	-70.08
#Instrument=	LabRAM HR Evol
#Detector=	Synapse
#Objective=	x100
#Grating=	600 gr/mm
#ND Filter=	100%
#Laser (nm)=	532
#Hole=	100.021
#Range=	Auto
#Laser Pol.=	No
#Raman. Pol.=	No
#Laser Pol. (°)=	-0.0007625
#Raman Pol. (°)=	89.9995
#Collection=	Microscope
#StageXY=	Marzhauser
#StageZ=	Marzhauser
#X (µm)=	4749.7
#Y (µm)=	-7725.1
#Z (µm)=	583.7
#Full time(mm:ss)=	3:18
#Project=
#Sample=
#Site=
#Title=	Thy_30_10_15_2x_45s_532 nm_x100_100%_600 gr_mm
#Remark=
#Date=	30.06.2022 12:32
#Acquired=	30.06.2022 12:32:26
#Base:Fit=	10.08.2022 09:58:11
#Base:Sub=	10.08.2022 09:58:44
#Filter:Polynom=	16.08.2022 10:22:53
#AxisType[0]=Intens
#AxisUnit[0]=Cnt
#AxisType[1]=Spectr
#AxisUnit[1]=1/cm
200.533	-3.98042
204.162	-1.47182
207.792	-0.205214
211.418	0.521553
215.044	0.545221
218.667	1.09285
222.289	1.85362
225.912	1.56518
229.531	2.10044
233.148	2.51784
236.766	3.91604
240.381	4.60647
243.994	4.95416
247.606	5.08273
251.217	5.18132
254.828	5.54436
258.436	7.80514
262.042	7.77217
265.647	8.57009
269.25	10.196
272.852	11.707
276.453	12.8837
280.052	13.5944
283.65	14.0814
287.247	14.4805
290.842	15.154
294.436	15.3714
298.028	15.5993
301.617	16.0807
305.206	16.4497
308.794	16.7108
312.381	16.6964
315.964	16.6011
319.548	16.267
323.131	15.7298
326.71	16.0777
330.29	14.5558
333.868	15.0778
337.443	15.4719
341.018	14.896
344.591	15.1149
348.163	16.4091
351.733	15.8749
355.303	16.3861
358.869	16.2794
362.435	17.3508
366.001	17.19
369.563	16.9013
373.124	16.8666
376.686	16.6657
380.244	16.3628
383.801	16.7616
387.357	16.6911
390.911	16.7569
394.466	15.8747
398.018	14.2323
401.568	13.1814
405.117	11.9759
408.664	10.5151
412.21	10.0858
415.755	9.88857
419.298	10.6574
422.84	9.56606
426.38	9.57554
429.919	8.04675
433.455	8.19999
436.992	7.51292
440.527	8.50829
444.06	9.04508
447.593	10.1212
451.122	10.3804
454.651	10.2199
458.18	9.52481
461.705	9.83242
465.23	10.647
468.752	12.4883
472.275	13.5241
475.797	13.772
479.315	12.6257
482.834	11.9968
486.349	12.1484
489.863	11.8708
493.378	12.1841
496.889	12.4671
500.401	12.2295
503.91	12.7323
507.417	13.2178
510.923	13.7107
514.43	13.7816
517.933	13.0154
521.435	13.2649
524.936	12.9114
528.435	12.489
531.933	12.3098
535.43	12.3604
538.927	11.6942
542.421	11.5771
545.913	10.9919
549.403	10.9358
552.893	10.233
556.381	9.26574
559.868	7.39972
563.354	5.77337
566.839	3.84567
570.322	3.00893
573.802	1.7924
577.283	1.33574
580.762	1.09218
584.24	1.47134
587.714	2.17929
591.19	1.99513
594.663	2.22873
598.134	2.4006
601.605	2.59691
605.073	3.02796
608.542	3.38627
612.007	3.67572
615.473	4.36143
618.936	6.29069
622.397	7.08408
625.859	7.75225
629.318	8.33088
632.775	9.04125
636.233	10.6714
639.688	11.1198
643.142	12.0761
646.594	12.7964
650.045	14.0452
653.496	14.8468
656.944	16.8087
660.391	18.6898
663.837	20.1094
667.281	20.7824
670.724	22.0876
674.166	23.2686
677.606	24.0825
681.045	25.2392
684.483	26.96
687.917	28.4328
691.352	29.3165
694.786	30.5503
698.219	32.2592
701.65	33.6617
705.078	35.2099
708.506	36.7992
711.934	38.3638
715.358	39.202
718.782	40.6891
722.204	41.734
725.626	42.9277
729.045	43.7406
732.464	44.7395
735.881	47.2407
739.297	47.4734
742.711	48.233
746.125	49.9826
749.537	51.5225
752.946	52.8154
756.357	55.6421
759.764	57.426
763.17	58.0628
766.575	60.4502
769.978	62.6464
773.382	64.8566
776.783	65.8409
780.182	66.4859
783.581	68.3583
786.978	69.9217
790.373	71.3792
793.768	72.8453
797.161	73.3611
800.552	73.4409
803.941	74.4841
807.33	74.6867
810.718	74.3819
814.105	74.8015
817.49	74.3776
820.873	74.143
824.256	73.2218
827.637	72.2749
831.016	72.0684
834.395	70.732
837.772	68.6344
841.147	67.6938
844.522	62.6356
847.894	61.2257
851.267	59.1038
854.637	57.2788
858.007	55.3839
861.374	52.0793
864.739	51.5878
868.106	50.2542
871.469	48.1579
874.831	47.0372
878.193	45.6266
881.553	45.0295
884.911	45.4223
888.268	43.4753
891.623	43.1345
894.978	42.8164
898.331	43.1148
901.683	43.432
905.033	43.3316
908.383	43.0823
911.731	42.4564
915.078	42.3296
918.423	41.191
921.768	41.0691
925.111	40.1314
928.452	39.5698
931.791	39.9974
935.13	40.4262
938.468	39.1425
941.803	38.645
945.139	37.8953
948.473	35.8771
951.804	35.4329
955.136	33.5744
958.465	32.4192
961.794	31.5397
965.12	29.0219
968.447	27.3429
971.771	25.9366
975.095	25.225
978.417	25.9513
981.737	25.3806
985.057	24.2266
988.375	22.1134
991.691	20.4834
995.006	19.2965
998.32	18.58
1001.63	17.7839
1004.95	17.3182
1008.26	17.5919
1011.56	17.2473
1014.87	16.834
1018.18	16.4993
1021.48	16.1904
1024.79	14.7149
1028.09	15.0533
1031.39	14.5788
1034.69	13.7795
1037.99	13.1324
1041.29	12.0939
1044.58	11.7346
1047.88	11.465
1051.17	11.0408
1054.46	10.4843
1057.75	10.6638
1061.04	11.0049
1064.33	10.1229
1067.62	8.32247
1070.9	7.72013
1074.19	6.79006
1077.47	6.9627
1080.76	6.85191
1084.04	7.69761
1087.32	8.78451
1090.59	7.87698
1093.87	8.53966
1097.15	9.34527
1100.42	11.2134
1103.69	11.0942
1106.97	11.788
1110.24	11.2649
1113.51	11.883
1116.77	11.4697
1120.04	11.1423
1123.31	10.9522
1126.57	11.5011
1129.83	10.8263
1133.1	10.0801
1136.36	10.438
1139.62	10.6122
1142.87	10.5796
1146.13	10.1888
1149.38	7.92811
1152.64	6.98519
1155.89	5.55421
1159.14	6.04477
1162.39	5.3352
1165.64	4.83163
1168.89	4.53935
1172.14	3.75926
1175.38	4.87582
1178.63	5.83641
1181.87	6.30898
1185.11	6.26095
1188.35	6.37029
1191.59	6.28237
1194.83	7.24424
1198.07	9.0402
1201.3	11.2045
1204.53	13.0696
1207.77	15.1673
1211	15.6954
1214.23	16.8841
1217.46	19.15
1220.69	21.3318
1223.91	22.9657
1227.14	23.9985
1230.36	25.2206
1233.59	26.7462
1236.81	28.4579
1240.03	29.6539
1243.25	30.0544
1246.46	31.2798
1249.68	32.6662
1252.9	32.7429
1256.11	33.8513
1259.32	34.424
1262.54	36.328
1265.75	37.8564
1268.96	39.0693
1272.16	39.1326
1275.37	39.8419
1278.57	39.6346
1281.78	40.669
1284.98	41.7056
1288.18	41.9641
1291.38	42.8253
1294.58	43.6902
1297.78	44.7868
1300.98	46.6243
1304.17	46.4272
1307.37	47.5417
1310.56	48.614
1313.76	49.5381
1316.95	51.8487
1320.14	51.52
1323.32	51.8559
1326.51	52.4886
1329.7	52.2001
1332.88	53.2167
1336.07	52.1754
1339.25	51.816
1342.43	50.9729
1345.61	48.8256
1348.79	46.4407
1351.96	43.7
1355.14	41.1629
1358.31	39.7931
1361.49	36.9479
1364.66	34.1311
1367.83	30.7949
1371	28.7334
1374.17	27.458
1377.34	26.0884
1380.5	24.5027
1383.67	23.5256
1386.83	22.5031
1390	22.0546
1393.16	21.0102
1396.32	21.058
1399.48	21.039
1402.64	21.6516
1405.79	21.635
1408.95	22.5863
1412.1	24.7462
1415.26	25.9069
1418.41	27.0036
1421.56	28.8426
1424.71	30.8745
1427.86	34.2406
1431	36.2532
1434.15	37.8165
1437.29	41.2002
1440.44	42.7482
1443.58	44.5976
1446.72	46.6578
1449.86	48.3568
1453	48.1837
1456.14	46.6832
1459.27	45.3148
1462.41	43.4545
1465.54	40.6728
1468.67	38.6211
1471.81	35.2868
1474.94	31.9042
1478.07	28.6738
1481.19	25.9631
1484.32	22.5651
1487.45	20.5646
1490.57	18.1089
1493.69	15.7658
1496.82	13.9829
1499.94	13.371
1503.06	13.553
1506.17	13.5132
1509.29	12.4802
1512.41	12.4949
1515.52	13.6068
1518.64	14.606
1521.75	15.4976
1524.86	17.9977
1527.97	20.0357
1531.08	20.7547
1534.19	24.4175
1537.29	27.1987
1540.4	30.224
1543.5	32.0418
1546.61	34.1807
1549.71	37.6719
1552.81	41.838
1555.91	44.128
1559.01	46.8831
1562.11	49.3912
1565.2	52.2017
1568.29	54.3759
1571.39	56.1171
1574.48	57.841
1577.57	58.8706
1580.66	58.3494
1583.75	57.456
1586.84	57.0246
1589.93	56.6125
1593.01	55.8715
1596.1	54.3874
1599.18	51.7893
1602.26	50.3108
1605.34	48.1228
1608.42	46.8644
1611.5	46.2482
1614.58	43.9133
1617.65	42.5689
1620.73	42.9425
1623.8	43.2961
1626.87	43.0465
1629.95	43.2795
1633.02	43.7199
1636.09	44.3515
1639.15	45.121
1642.22	44.8166
1645.29	44.8148
1648.35	44.7812
1651.42	44.6042
1654.48	44.2951
1657.54	44.144
1660.6	42.8918
1663.66	42.4982
1666.72	41.1679
1669.77	38.6352
1672.83	36.6678
1675.88	33.9176
1678.93	31.4454
1681.99	29.0305
1685.04	25.7036
1688.09	23.7209
1691.13	22.2104
1694.18	21.1197
1697.23	19.1383
1700.27	15.887
1703.32	14.9932
1706.36	12.9057
1709.4	10.8858
1712.44	8.40054
1715.48	5.69853
1718.52	3.99348
1721.56	3.83687
1724.59	2.86135
1727.63	3.16396
1730.66	2.56647
1733.69	2.14814
1736.72	2.54416
1739.75	2.78844
1742.78	2.50823
1745.81	2.32602
1748.84	2.23953
1751.86	2.22321
1754.89	2.88605
1757.91	3.48528
1760.93	4.84618
1763.95	5.70859
1766.97	5.47536
1769.99	5.10579
1773.01	5.11059
1776.03	5.21449
1779.04	4.52121
1782.06	4.78846
1785.07	4.41497
1788.08	4.76147
1791.09	4.74364
1794.1	5.25396
1797.11	5.37689
1800.12	6.17131
1803.12	6.28758
1806.13	6.07512
1809.13	6.1131
1812.14	6.3262
1815.14	6.51094
1818.14	7.13387
1821.14	7.71844
1824.14	8.12596
1827.13	8.63919
1830.13	9.13543
1833.12	9.46545
1836.12	9.62904
1839.11	9.16634
1842.1	9.61502
1845.09	9.69784
1848.08	9.81435
1851.07	10.4432
1854.06	11.4951
1857.04	12.1636
1860.03	12.8455
1863.01	13.2919
1866	13.1339
1868.98	13.2931
1871.96	14.0284
1874.94	13.9821
1877.92	13.6576
1880.89	13.4035
1882.48	13.9979
1885.47	15.6952
1888.46	16.5001
1891.44	17.6123
1894.43	18.1582
1897.41	17.7818
1900.4	19.0209
1903.38	19.9163
1906.36	18.3907
1909.34	18.6069
1912.32	18.271
1915.29	18.8453
1918.27	17.5651
1921.25	17.3049
1924.22	17.0881
1927.2	16.5256
1930.17	15.6307
1933.14	15.5432
1936.11	14.5212
1939.08	14.0956
1942.05	13.643
1945.01	13.6174
1947.98	12.4297
1950.94	12.8432
1953.91	13.5922
1956.87	15.1421
1959.83	15.0124
1962.79	14.6117
1965.75	13.9546
1968.71	13.6845
1971.67	13.9372
1974.62	14.5871
1977.58	14.2414
1980.53	14.5171
1983.48	15.0331
1986.43	16.0875
1989.38	15.7075
1992.33	16.4338
1995.28	17.2533
1998.23	17.7248
2001.18	18.5611
2004.12	19.9584
2007.06	21.0861
2010.01	21.4219
2012.95	21.8802
2015.89	21.5945
2018.83	21.9839
2021.77	22.1461
2024.71	22.3585
2027.64	21.9262
2030.58	21.1763
2033.51	21.1122
2036.45	21.3534
2039.38	20.6932
2042.31	21.6523
2045.24	21.815
2048.17	21.6357
2051.1	20.7273
2054.02	20.3403
2056.95	20.5821
2059.87	20.4837
2062.8	20.6374
2065.72	21.0731
2068.64	21.5038
2071.56	22.7462
2074.48	23.6152
2077.4	24.4468
2080.31	25.0636
2083.23	25.8924
2086.14	26.6607
2089.06	27.3386
2091.97	27.9477
2094.88	28.0995
2097.79	28.1859
2100.7	28.9347
2103.61	30.0761
2106.52	31.1589
2109.43	32.7896
2112.33	33.3481
2115.24	33.0442
2118.14	33.7893
2121.04	34.4454
2123.94	35.1002
2126.84	37.3722
2129.74	39.2537
2132.64	41.1375
2135.54	42.9943
2138.43	45.2114
2141.33	47.3781
2144.22	48.8353
2147.11	51.2231
2150.01	52.5914
2152.9	55.1432
2155.79	56.6014
2158.67	57.6643
2161.56	57.7223
2164.45	58.0657
2167.33	58.7715
2170.22	58.6707
2173.1	58.5726
2175.98	58.5371
2178.86	57.7299
2181.74	56.5057
2184.62	54.5405
2187.5	53.2719
2190.38	52.6605
2193.25	51.4278
2196.13	50.2622
2199	49.4136
2201.88	47.3762
2204.75	45.58
2207.62	43.6017
2210.49	42.3159
2213.36	40.354
2216.22	39.6243
2219.09	38.6824
2221.96	36.8279
2224.82	35.4432
2227.68	34.0821
2230.55	32.6016
2233.41	32.3052
2236.27	31.1534
2239.12	29.853
2241.98	28.4843
2244.84	27.5374
2247.7	26.1127
2250.55	25.216
2253.41	24.2501
2256.26	24.1408
2259.11	24.146
2261.96	23.2964
2264.81	22.7701
2267.66	23.1143
2270.51	22.9764
2273.35	21.7557
2276.2	20.4599
2279.04	18.756
2281.89	18.1449
2284.73	17.32
2287.57	17.4591
2290.41	16.3466
2293.25	15.8303
2296.09	16.0181
2298.93	16.2415
2301.76	16.4077
2304.6	17.5857
2307.44	17.0968
2310.27	17.0636
2313.1	16.8749
2315.93	17.4104
2318.76	17.6391
2321.59	15.8516
2324.42	16.5017
2327.25	16.6196
2330.07	15.6584
2332.9	15.2094
2335.72	14.4627
2338.55	13.7832
2341.37	11.3769
2344.19	9.89896
2347.01	8.34319
2349.83	7.83017
2352.65	6.87344
2355.46	5.8191
2358.28	4.82424
2361.09	4.82305
2363.91	4.17428
2366.72	4.77593
2369.53	5.80691
2372.34	5.60305
2375.15	5.97346
2377.96	5.18894
2380.77	5.07372
2383.58	4.634
2386.38	4.62108
2389.19	4.59837
2391.99	4.74568
2394.8	5.78893
2397.6	6.1638
2400.4	7.30364
2403.2	7.61199
2406	8.01064
2408.79	9.03304
2411.59	9.17265
2414.39	9.2187
2417.18	10.1203
2419.98	9.97795
2422.77	9.4624
2425.56	9.56732
2428.35	8.76619
2431.14	7.8877
2433.93	7.45491
2436.72	7.54471
2439.5	6.33666
2442.29	5.04394
2445.07	3.72815
2447.86	2.73985
2450.64	2.87408
2453.42	3.15253
2456.2	2.70177
2458.98	2.53392
2461.76	2.56188
2464.54	3.18288
2467.32	3.58039
2470.09	3.50217
2472.87	3.48046
2475.64	3.56078
2478.41	3.33779
2481.18	3.56852
2483.95	3.03633
2486.72	3.05355
2489.49	1.11162
2492.26	1.15358
2495.03	0.363403
2497.79	-0.391832
2500.56	-0.0395356
2503.32	0.441844
2506.09	0.751847
2508.85	1.19996
2511.61	1.58826
2514.37	2.01832
2517.13	2.30806
2519.89	2.58588
2522.64	3.17294
2525.4	3.58712
2528.15	3.10874
2530.91	3.26695
2533.66	4.00356
2536.41	4.1586
2539.16	4.74709
2541.91	4.35819
2544.66	4.13636
2547.41	4.10199
2550.16	3.02199
2552.9	2.41356
2555.65	1.67646
2558.39	1.01673
2561.13	1.09827
2563.88	1.22709
2566.62	1.59497
2569.36	1.92528
2572.1	1.20781
2574.84	0.50405
2577.57	0.895025
2580.31	0.151527
2583.05	-0.112038
2585.78	-0.705993
2588.51	-1.10071
2591.24	-1.60046
2593.98	-2.20686
2596.71	-1.91852
2599.44	-0.609564
2602.16	-0.137085
2604.89	0.347254
2607.62	0.775065
2610.34	0.541055
2613.07	0.906665
2615.79	0.844484
2618.52	1.54979
2621.24	2.31129
2623.96	2.58804
2626.68	3.05524
2629.4	2.8871
2632.11	3.18142
2634.83	4.14361
2637.55	4.24205
2640.26	4.70013
2642.98	4.85887
2645.69	4.99492
2648.4	4.79986
2651.11	4.57136
2653.82	4.52848
2656.53	4.13532
2659.24	4.16751
2661.95	4.47823
2664.65	4.88299
2667.36	5.35797
2670.06	4.71067
2672.76	4.54163
2675.47	4.49683
2678.17	3.91764
2680.87	3.60673
2683.57	3.8186
2686.27	3.56272
2688.97	3.59754
2691.66	3.13411
2694.36	3.45923
2697.05	3.37667
2699.75	4.40161
2702.44	5.30192
2705.13	5.07228
2707.82	5.00731
2710.51	5.94914
2713.2	5.48045
2715.89	6.22042
2718.57	5.7113
2721.26	5.35805
2723.95	5.62989
2726.63	5.57842
2729.31	5.65797
2732	5.96984
2734.68	5.47052
2737.36	4.54908
2740.04	4.30353
2742.72	3.64123
2745.39	2.82164
2748.07	2.15803
2750.75	2.25014
2753.42	1.75583
2756.09	2.10013
2758.77	1.86926
2761.44	1.42168
2764.11	1.82048
2766.78	2.19958
2769.45	2.46577
2772.12	2.34837
2774.78	2.43109
2777.45	2.28792
2780.12	1.66958
2782.78	1.17565
2785.44	0.690687
2788.11	1.44891
2790.77	0.961808
2793.43	0.698299
2796.09	0.513959
2798.75	0.387819
2801.4	-0.425836
2804.06	0.176076
2806.72	0.1068
2809.37	-0.16682
2812.03	0.135597
2814.68	1.06035
2817.33	2.10644
2819.98	3.8212
2822.63	5.95141
2825.28	8.28199
2827.93	10.5081
2830.58	13.4793
2833.23	15.359
2835.87	17.7753
2838.52	20.1163
2841.16	23.2411
2843.8	26.809
2846.44	30.4732
2849.08	35.2612
2851.73	39.8469
2854.36	45.2715
2857	49.4536
2859.64	54.7645
2862.28	59.8476
2864.91	63.6362
2867.55	67.7342
2870.18	71.0885
2872.81	74.0796
2875.44	76.0136
2878.07	78.6928
2880.7	81.0625
2883.33	83.3345
2885.96	86.1209
2888.59	88.0268
2891.21	90.9397
2893.84	93.582
2896.46	95.9095
2899.09	97.8964
2901.71	101.863
2904.33	107.965
2906.95	112.764
2909.57	118.589
2912.19	125.906
2914.81	132.641
2917.43	138.497
2920.04	143.988
2922.66	148.753
2925.27	151.891
2927.88	154.643
2930.5	156.343
2933.11	156.773
2935.72	156.83
2938.33	155.434
2940.94	153.012
2943.54	150.754
2946.15	147.267
2948.76	142.203
2951.36	138.673
2953.97	132.813
2956.57	127.776
2959.17	123.366
2961.77	118.2
2964.37	113.904
2966.97	110.02
2969.57	105.628
2972.17	100.382
2974.77	96.923
2977.36	92.0423
2979.96	87.1523
2982.55	82.4953
2985.15	77.2914
2987.74	72.0054
2990.33	66.8009
2992.92	62.2677
2995.51	57.6103
2998.1	52.3591
3000.69	47.8116
3003.27	42.7648
3005.86	39.2117
3008.44	34.944
3011.03	31.1711
3013.61	28.334
3016.19	25.1927
3018.78	23.0463
3021.36	21.8405
3023.94	20.3056
3026.51	18.2263
3029.09	17.0475
3031.67	17.0729
3034.24	16.4648
3036.82	16.7375
3039.39	17.1867
3041.97	18.3986
3044.54	18.7986
3047.11	18.4545
3049.68	18.3002
3052.25	17.5964
3054.82	17.4912
3057.39	16.9796
3059.96	16.8294
3062.52	15.5985
3065.09	14.2206
3067.65	13.5294
3070.22	12.8845
3072.78	11.6005
3075.34	10.7377
3077.9	8.91982
3080.46	8.13849
3083.02	7.05298
3085.58	5.16682
3088.14	3.71818
3090.69	2.69089
3093.25	2.12436
3095.8	2.34664
3098.36	1.85775
3100.91	1.8285
3103.46	2.17704
3106.01	1.52618
3108.56	1.25224
3111.11	1.12239
3113.66	0.964994
3116.21	0.534048
3118.76	0.487786
3121.3	0.743192
3123.85	0.218819
3126.39	-0.0551567
3128.93	0.434765
3131.48	0.315098
3134.02	0.640729
3136.56	0.555056
3139.1	1.28531
3141.64	1.41958
3144.17	1.0881
3146.71	1.77729
3149.25	3.68311