File: data/Raman/poly_smoothed/Thy_40_11_04_1x_45s_532 nm_x100_100%_600 gr_mm_01.txt
#Acq. time (s)=	45
#Accumulations=	2
#Range (cm-¹)=	200...3150
#Windows=	2
#Auto scanning=	Off
#Autofocus=	Off
#Macrospot=	Off
#AutoExposure=	Off
#Spike filter=	Multiple accum.
#Delay time (s)=	0
#Binning=	1
#Readout mode=	Signal
#DeNoise=	Off
#ICS correction=	On
#Dark correction=	Off
#Inst. Process=	Off
#Detector Gain=	Best Dynamic Range
#Detector ADC=	20 kHz
#Detector temperature (°C)=	-69.85
#Instrument=	LabRAM HR Evol
#Detector=	Synapse
#Objective=	x100
#Grating=	600 gr/mm
#ND Filter=	100%
#Laser (nm)=	532
#Hole=	100.021
#Range=	Auto
#Laser Pol.=	No
#Raman. Pol.=	No
#Laser Pol. (°)=	-0.0007625
#Raman Pol. (°)=	89.9995
#Collection=	Microscope
#StageXY=	Marzhauser
#StageZ=	Marzhauser
#X (µm)=	1969.4
#Y (µm)=	-88.7
#Z (µm)=	425.85
#Full time(mm:ss)=	3:18
#Project=
#Sample=
#Site=
#Title=	Thy_40_11_04_2x_45s_532 nm_x100_100%_600 gr_mm
#Remark=
#Date=	05.07.2022 10:09
#Acquired=	05.07.2022 10:09:21
#Base:Fit=	10.08.2022 10:00:48
#Base:Fit=	10.08.2022 10:01:07
#Base:Fit=	10.08.2022 10:01:15
#Base:Fit=	10.08.2022 10:01:35
#Base:Sub=	10.08.2022 10:01:52
#Filter:Polynom=	16.08.2022 10:21:53
#AxisType[0]=Intens
#AxisUnit[0]=Cnt
#AxisType[1]=Spectr
#AxisUnit[1]=1/cm
200.43	14.3997
204.059	14.4779
207.688	13.2882
211.314	12.0244
214.941	11.4832
218.564	11.0578
222.186	9.24393
225.809	7.51887
229.428	6.57542
233.045	5.09123
236.663	4.17975
240.278	3.45012
243.891	3.90774
247.503	4.13393
251.116	4.25748
254.725	5.17621
258.333	6.09224
261.939	7.65486
265.544	8.41208
269.148	8.26533
272.75	7.69441
276.351	7.08691
279.95	5.54117
283.548	5.54806
287.144	7.35428
290.739	6.91434
294.333	10.0379
297.925	11.4757
301.514	13.8451
305.104	14.194
308.692	14.8439
312.279	15.0678
315.862	16.4533
319.446	16.9977
323.029	16.9259
326.608	18.2552
330.188	19.9585
333.766	21.0277
337.341	21.6312
340.917	21.6534
344.489	20.9683
348.062	21.5266
351.631	20.1736
355.201	17.9226
358.768	15.8652
362.333	15.0639
365.899	14.2121
369.462	14.1827
373.023	13.9889
376.585	14.0469
380.143	15.8867
383.7	16.5102
387.256	17.1334
390.812	17.3719
394.365	16.9188
397.916	17.8411
401.467	18.5881
405.015	17.5119
408.563	18.476
412.109	19.202
415.654	18.5486
419.197	17.9734
422.739	17.3979
426.279	15.8279
429.819	15.0458
433.356	14.6125
436.891	12.654
440.426	11.64
443.96	11.3292
447.492	10.0376
451.021	9.72657
454.551	9.02969
458.079	9.4407
461.604	9.94017
465.13	10.0708
468.654	11.6335
472.175	11.3685
475.696	12.3637
479.215	13.072
482.733	13.9168
486.249	15.4642
489.765	17.0571
493.278	18.3507
496.789	20.5228
500.301	21.6982
503.81	20.6263
507.317	22.2256
510.825	22.8735
514.33	22.762
517.833	21.989
521.335	23.0449
524.836	23.6282
528.335	24.2728
531.835	24.2722
535.332	24.6167
538.827	23.744
542.321	23.0948
545.814	21.768
549.305	19.6162
552.795	17.5795
556.282	15.5273
559.769	13.0415
563.255	11.6713
566.739	8.90151
570.223	7.51833
573.705	6.78263
577.183	5.8747
580.663	5.35013
584.141	5.38559
587.615	4.10665
591.09	2.82005
594.564	2.3329
598.035	2.33348
601.506	2.28238
604.974	2.3739
608.443	4.40853
611.908	5.54573
615.374	5.99515
618.837	6.72353
622.3	5.81788
625.761	6.22185
629.219	6.10873
632.677	6.51674
636.135	6.27084
639.59	5.63068
643.043	4.62343
646.495	5.84819
649.948	6.98389
653.398	8.55837
656.846	9.57203
660.293	12.9228
663.738	14.2686
667.183	15.3277
670.626	17.0341
674.067	18.0385
677.508	19.2218
680.947	21.2593
684.385	22.4038
687.821	25.3427
691.254	27.9682
694.688	31.2091
698.121	34.5933
701.552	37.3754
704.98	40.624
708.409	43.0598
711.836	45.077
715.26	48.1788
718.685	46.939
722.108	47.0644
725.528	47.4714
728.949	48.4652
732.367	49.8167
735.785	50.0475
739.2	50.1183
742.614	51.3376
746.028	52.1213
749.439	53.3893
752.849	54.7234
756.26	55.399
759.667	57.0078
763.073	60.301
766.477	62.715
769.883	65.1274
773.285	68.3943
776.686	71.8244
780.085	75.1111
783.484	77.8806
786.881	78.4902
790.276	80.7598
793.671	80.9527
797.064	80.8977
800.456	80.5408
803.846	79.627
807.234	79.4577
810.622	79.2444
814.008	79.4654
817.394	78.9785
820.778	79.3827
824.159	79.3483
827.541	79.3445
830.921	78.5645
834.298	78.3476
837.676	78.1145
841.051	77.0109
844.426	75.6347
847.798	74.1514
851.171	71.6161
854.54	70.6352
857.911	69.515
861.278	67.8328
864.645	65.7191
868.01	62.2938
871.373	59.5795
874.735	56.6259
878.097	54.2706
881.457	53.7378
884.815	51.72
888.172	51.8001
891.528	51.0157
894.882	50.356
898.237	48.6018
901.589	47.6069
904.94	47.2483
908.289	47.3588
911.635	47.0492
914.982	45.7707
918.328	45.2886
921.672	44.1499
925.015	43.0512
928.357	41.9001
931.698	40.5829
935.035	39.372
938.373	38.9816
941.71	38.0727
945.044	35.9418
948.378	35.2483
951.709	37.0455
955.041	37.6426
958.372	37.1793
961.699	37.7983
965.027	39.2153
968.352	40.5968
971.676	42.6651
975	42.3314
978.322	42.6312
981.642	43.1967
984.962	43.1563
988.28	44.7844
991.596	44.3468
994.911	43.1597
998.227	42.2821
1001.54	40.765
1004.85	38.49
1008.16	36.1637
1011.47	33.065
1014.78	31.5203
1018.08	30.5649
1021.39	29.463
1024.69	28.832
1028	29.7878
1031.3	30.0961
1034.6	30.3407
1037.9	29.2045
1041.19	28.3156
1044.49	29.0995
1047.78	28.0529
1051.08	28.4153
1054.37	27.1196
1057.66	26.6704
1060.95	26.0405
1064.24	24.4813
1067.53	24.927
1070.81	25.0478
1074.1	25.1872
1077.38	25.716
1080.66	26.2175
1083.94	25.8975
1087.22	24.8034
1090.5	24.6109
1093.78	24.4752
1097.05	25.3824
1100.33	25.9217
1103.6	27.1905
1106.87	26.6023
1110.14	27.341
1113.41	25.6183
1116.68	23.1885
1119.95	20.878
1123.21	19.947
1126.48	16.8823
1129.74	14.4412
1133	14.1946
1136.26	10.971
1139.52	8.59619
1142.78	6.91537
1146.04	4.33057
1149.29	3.77483
1152.55	3.80595
1155.8	3.17375
1159.05	2.71675
1162.3	2.40731
1165.55	2.7298
1168.8	3.64102
1172.05	5.08882
1175.29	6.7216
1178.54	7.46092
1181.78	9.03283
1185.02	10.6316
1188.26	10.296
1191.5	12.324
1194.74	12.7401
1197.97	15.6641
1201.21	18.5997
1204.44	20.6425
1207.68	22.8213
1210.91	25.1591
1214.14	28.0381
1217.37	28.9873
1220.59	31.7723
1223.82	34.5537
1227.05	38.0259
1230.27	41.5532
1233.49	46.1582
1236.72	47.8517
1239.94	52.1676
1243.16	56.199
1246.37	58.7849
1249.59	60.8509
1252.8	61.8121
1256.02	62.6093
1259.23	65.2902
1262.44	67.3471
1265.66	68.3702
1268.86	70.4611
1272.07	73.28
1275.28	75.688
1278.48	77.53
1281.69	79.2427
1284.89	81.0997
1288.09	81.5422
1291.29	82.2205
1294.49	82.5342
1297.69	82.3862
1300.89	83.3862
1304.08	84.5946
1307.28	84.5912
1310.47	85.4026
1313.66	86.1741
1316.85	86.2905
1320.04	86.7403
1323.23	84.4524
1326.42	83.0952
1329.61	80.5994
1332.79	77.2619
1335.97	75.2963
1339.16	73.5155
1342.34	70.3541
1345.52	68.9113
1348.7	66.794
1351.87	63.5417
1355.05	61.1522
1358.22	58.1988
1361.4	54.8795
1364.57	52.4352
1367.74	50.7042
1370.91	47.8734
1374.08	45.8349
1377.25	44.7322
1380.41	43.2745
1383.58	42.3899
1386.74	42.5074
1389.91	42.885
1393.07	44.1149
1396.23	44.6422
1399.39	44.1234
1402.55	43.227
1405.7	43.2742
1408.86	42.1429
1412.01	44.3559
1415.17	44.8337
1418.32	48.3703
1421.47	52.8053
1424.62	56.0065
1427.77	60.1369
1430.91	64.1358
1434.06	67.2401
1437.2	70.4657
1440.35	73.2799
1443.49	76.04
1446.63	77.2221
1449.77	77.1976
1452.91	76.6818
1456.05	77.7479
1459.18	76.2184
1462.32	73.9694
1465.45	70.1041
1468.59	67.2783
1471.72	62.1971
1474.85	57.0794
1477.98	50.4786
1481.1	45.1926
1484.23	41.1384
1487.36	38.644
1490.48	36.5435
1493.61	32.6234
1496.73	30.9479
1499.85	29.3212
1502.97	26.5809
1506.09	25.7023
1509.2	25.7473
1512.32	25.5527
1515.43	25.4307
1518.55	26.0086
1521.66	27.3093
1524.77	28.5892
1527.88	28.9745
1530.99	31.669
1534.1	31.7466
1537.21	33.3878
1540.31	35.6464
1543.42	37.8737
1546.52	41.8103
1549.62	44.522
1552.72	48.5702
1555.82	50.8004
1558.92	55.5096
1562.02	59.1237
1565.11	60.8259
1568.21	63.3405
1571.3	64.673
1574.39	67.8544
1577.49	69.3159
1580.57	71.9334
1583.66	73.0802
1586.75	75.144
1589.84	75.3979
1592.92	73.8249
1596.01	74.5823
1599.09	74.0468
1602.17	72.4596
1605.25	71.2215
1608.33	70.3334
1611.41	69.2438
1614.49	71.5076
1617.57	72.2147
1620.64	73.8251
1623.72	75.9076
1626.79	77.9182
1629.86	79.6907
1632.93	82.1595
1636	86.5075
1639.07	89.5218
1642.13	92.9348
1645.2	95.0661
1648.26	96.7681
1651.33	98.1046
1654.39	99.551
1657.45	100.748
1660.51	99.5859
1663.57	98.352
1666.63	95.2754
1669.68	91.3325
1672.74	87.11
1675.79	79.4586
1678.85	73.3814
1681.9	67.1175
1684.95	60.4832
1688	55.6322
1691.05	50.4427
1694.09	43.6749
1697.14	38.6744
1700.18	32.8363
1703.23	30.086
1706.27	26.8156
1709.31	23.6579
1712.35	21.6249
1715.39	18.5674
1718.43	17.1068
1721.47	15.7262
1724.5	14.0316
1727.54	13.8564
1730.57	13.9707
1733.61	14.2667
1736.64	12.9843
1739.67	12.1409
1742.7	12.2933
1745.72	10.0926
1748.75	7.93032
1751.77	6.9805
1754.8	6.80545
1757.82	5.55473
1760.84	4.38844
1763.87	3.78869
1766.89	2.3846
1769.91	1.54136
1772.92	0.718198
1775.94	0.877271
1778.95	0.548548
1781.97	-1.07196
1784.98	-1.42142
1787.99	-1.22954
1791.01	-1.19295
1794.01	-1.56089
1797.02	-0.74578
1800.03	-0.172331
1803.04	1.15525
1806.04	2.15276
1809.05	3.69763
1812.05	4.06181
1815.05	5.77727
1818.05	5.97383
1821.05	5.93611
1824.05	6.57634
1827.05	5.85325
1830.04	5.9645
1833.04	5.71343
1836.03	5.06674
1839.03	5.1268
1842.02	4.39726
1845.01	4.28467
1848	4.02219
1850.99	4.73692
1853.97	4.27632
1856.96	4.20191
1859.94	5.04605
1862.93	4.23245
1865.91	4.07785
1868.89	4.22828
1871.87	4.91932
1874.85	5.3901
1877.83	5.9829
1880.81	7.15307
1882.57	6.76451
1885.56	7.4514
1888.55	7.0409
1891.54	6.07059
1894.52	6.46431
1897.51	5.6818
1900.49	5.4916
1903.47	5.44532
1906.45	5.41956
1909.43	5.33009
1912.41	6.09617
1915.39	5.94026
1918.37	7.02114
1921.34	7.29389
1924.32	7.96884
1927.29	8.15736
1930.26	7.4416
1933.23	7.92898
1936.2	7.3642
1939.17	6.71884
1942.14	6.19926
1945.11	6.36914
1948.07	5.47487
1951.04	5.10655
1954	4.44028
1956.96	3.32184
1959.93	2.55699
1962.89	1.14826
1965.85	1.44884
1968.8	0.429907
1971.76	0.191749
1974.72	0.481556
1977.67	0.0365966
1980.63	0.307547
1983.58	-0.752099
1986.53	-0.576272
1989.48	0.345946
1992.43	0.771517
1995.38	1.72961
1998.32	2.41319
2001.27	2.83151
2004.22	3.53503
2007.16	4.08957
2010.1	4.17359
2013.04	4.56457
2015.98	4.14314
2018.92	4.20398
2021.86	4.39078
2024.8	5.05349
2027.74	5.91646
2030.67	6.14559
2033.61	6.98169
2036.54	6.28366
2039.47	6.9779
2042.4	8.1027
2045.33	8.117
2048.26	7.82818
2051.19	8.11578
2054.12	8.26892
2057.04	8.63439
2059.97	9.45663
2062.89	9.7182
2065.81	9.96437
2068.73	10.9769
2071.65	12.6654
2074.57	14.4228
2077.49	15.213
2080.41	16.9686
2083.32	17.7369
2086.24	18.6767
2089.15	20.4594
2092.07	22.7365
2094.98	24.7736
2097.89	27.1243
2100.8	29.2289
2103.71	31.0326
2106.61	32.5521
2109.52	33.9935
2112.43	35.9469
2115.33	38.1165
2118.23	40.7001
2121.13	44.3874
2124.04	47.6094
2126.94	49.8701
2129.83	52.0217
2132.73	55.4005
2135.63	60.0988
2138.53	64.3184
2141.42	69.804
2144.31	74.2577
2147.21	78.3516
2150.1	81.6454
2152.99	86.2311
2155.88	89.3164
2158.77	92.7916
2161.65	95.1905
2164.54	96.2342
2167.43	98.7903
2170.31	98.44
2173.19	98.5128
2176.07	98.1747
2178.96	95.7794
2181.84	93.4455
2184.72	92.3339
2187.59	90.5517
2190.47	87.7931
2193.35	83.76
2196.22	79.9241
2199.09	76.2191
2201.97	73.6611
2204.84	70.7194
2207.71	68.1598
2210.58	63.9556
2213.45	59.9748
2216.31	55.3575
2219.18	52.7979
2222.05	49.9383
2224.91	47.1169
2227.78	44.1793
2230.64	41.0214
2233.5	38.8642
2236.36	36.582
2239.22	34.8494
2242.08	32.583
2244.93	31.9328
2247.79	30.2716
2250.64	28.4969
2253.5	27.497
2256.35	27.013
2259.2	26.4981
2262.05	24.9573
2264.9	24.2386
2267.75	23.2177
2270.6	22.0434
2273.45	19.8674
2276.29	18.6286
2279.14	16.8313
2281.98	15.6179
2284.82	14.2531
2287.66	12.7
2290.5	11.2431
2293.34	8.54437
2296.18	7.9201
2299.02	7.92219
2301.86	8.21266
2304.69	7.89093
2307.53	7.75914
2310.36	7.63298
2313.19	6.97672
2316.02	7.66123
2318.85	7.46414
2321.68	6.9889
2324.51	7.23374
2327.34	6.71904
2330.16	5.9458
2332.99	5.56409
2335.81	5.19452
2338.64	5.15022
2341.46	4.90524
2344.28	4.96375
2347.1	5.24525
2349.92	5.02351
2352.74	5.96538
2355.55	5.53351
2358.37	4.83487
2361.19	4.46939
2364	4.65871
2366.81	5.92959
2369.62	5.85312
2372.44	4.48734
2375.24	3.90677
2378.05	3.91523
2380.86	2.76665
2383.67	2.41047
2386.47	2.54711
2389.28	1.40768
2392.08	1.76672
2394.89	1.30632
2397.69	1.1108
2400.49	0.661164
2403.29	1.2226
2406.09	2.01544
2408.88	3.10837
2411.68	4.56481
2414.48	5.77985
2417.27	7.29229
2420.06	8.75019
2422.86	10.1816
2425.65	10.3362
2428.44	10.2896
2431.23	11.2742
2434.02	10.8064
2436.81	10.6531
2439.59	9.10838
2442.38	8.69456
2445.16	7.52107
2447.95	7.01716
2450.73	6.05947
2453.51	5.62743
2456.29	4.77556
2459.07	4.43578
2461.85	4.69327
2464.63	5.17987
2467.4	5.0415
2470.18	5.15471
2472.95	5.64486
2475.73	5.91842
2478.5	6.28538
2481.27	6.55093
2484.04	6.57473
2486.81	6.37104
2489.58	7.22185
2492.35	6.84131
2495.12	7.2123
2497.88	6.60675
2500.65	6.55788
2503.41	6.03478
2506.17	5.82937
2508.94	6.3575
2511.7	6.49641
2514.46	5.8331
2517.22	5.76191
2519.97	5.67187
2522.73	5.40006
2525.49	5.1501
2528.24	5.80507
2530.99	5.77389
2533.75	4.65223
2536.5	4.47402
2539.25	3.30907
2542	2.94975
2544.75	3.14064
2547.5	2.4722
2550.24	2.48711
2552.99	2.31779
2555.74	3.30592
2558.48	3.21585
2561.22	3.46782
2563.96	3.96541
2566.71	4.93977
2569.45	5.4308
2572.18	5.98033
2574.92	6.22916
2577.66	7.10851
2580.4	6.06477
2583.13	5.16726
2585.87	5.04659
2588.6	5.11199
2591.33	5.0138
2594.06	5.5914
2596.79	4.86952
2599.52	4.73539
2602.25	5.31388
2604.98	5.08756
2607.71	4.69176
2610.43	4.02215
2613.16	4.14199
2615.88	3.97607
2618.6	3.8945
2621.32	4.31484
2624.04	4.32941
2626.76	4.10219
2629.48	5.19656
2632.2	5.78086
2634.92	6.09539
2637.63	5.56158
2640.35	5.66007
2643.06	5.61056
2645.77	6.11281
2648.49	6.43894
2651.2	6.13589
2653.91	7.55618
2656.62	7.34086
2659.33	7.34863
2662.03	7.63159
2664.74	7.57644
2667.44	7.39204
2670.15	7.08359
2672.85	6.33409
2675.55	5.69215
2678.26	5.52311
2680.96	5.08024
2683.66	4.90668
2686.35	4.29947
2689.05	4.3844
2691.75	5.43526
2694.44	5.94516
2697.14	5.30816
2699.83	5.10477
2702.52	4.81873
2705.22	5.26113
2707.91	5.71581
2710.6	6.52767
2713.29	7.0693
2715.97	7.83835
2718.66	8.82457
2721.35	10.2136
2724.03	10.8906
2726.72	12.2627
2729.4	12.3525
2732.08	12.8324
2734.76	12.7577
2737.44	12.1129
2740.12	11.6351
2742.8	11.3301
2745.48	10.9658
2748.16	10.4326
2750.83	9.08887
2753.51	8.62439
2756.18	8.35879
2758.85	7.51374
2761.53	6.00589
2764.2	5.48877
2766.87	4.795
2769.54	4.29058
2772.2	4.43338
2774.87	4.2565
2777.54	3.50139
2780.2	3.64226
2782.87	3.21382
2785.53	3.32059
2788.19	2.65951
2790.85	1.69894
2793.51	0.760717
2796.17	0.165885
2798.83	-0.0889501
2801.49	-0.641447
2804.15	-0.590836
2806.8	-0.469155
2809.46	-0.80852
2812.11	-2.45486
2814.76	-2.95951
2817.42	-2.95988
2820.07	-3.48606
2822.72	-2.19016
2825.37	-0.594248
2828.02	2.75965
2830.66	6.04799
2833.31	9.7139
2835.96	13.6788
2838.6	18.2422
2841.24	23.2691
2843.89	28.1532
2846.53	34.6742
2849.17	42.5723
2851.81	50.8453
2854.45	58.9958
2857.09	68.3386
2859.72	77.4006
2862.36	86.9061
2865	94.8797
2867.63	101.078
2870.26	107.041
2872.9	113.102
2875.53	116.363
2878.16	120.106
2880.79	124.17
2883.42	126.739
2886.05	130.535
2888.67	135.757
2891.3	140.264
2893.92	144.313
2896.55	148.652
2899.17	154.027
2901.79	161.546
2904.42	169.413
2907.04	178.951
2909.66	190.779
2912.27	203.631
2914.89	216.755
2917.51	229.257
2920.13	241.005
2922.74	251.527
2925.35	259.241
2927.97	265.258
2930.58	268.239
2933.19	270.22
2935.8	269.361
2938.41	266.602
2941.02	262.574
2943.63	256.578
2946.24	249.421
2948.84	239.475
2951.45	229.966
2954.05	220.351
2956.65	208.031
2959.26	197.238
2961.86	186.991
2964.46	176.924
2967.06	166.399
2969.66	157.488
2972.25	148.538
2974.85	139.69
2977.45	131.248
2980.04	121.838
2982.64	112.646
2985.23	102.697
2987.82	92.1054
2990.41	82.5086
2993	72.8035
2995.59	64.1134
2998.18	55.6449
3000.77	47.3543
3003.36	40.7983
3005.94	32.5461
3008.53	26.2695
3011.11	20.3053
3013.69	15.1885
3016.28	11.854
3018.86	8.67513
3021.44	6.33721
3024.02	4.12406
3026.6	3.23673
3029.18	1.96094
3031.75	2.34578
3034.33	2.49096
3036.9	4.04862
3039.48	5.30575
3042.05	6.43837
3044.62	7.35022
3047.19	8.65389
3049.77	9.72077
3052.34	10.3339
3054.9	10.8975
3057.47	11.0567
3060.04	10.9999
3062.61	10.5674
3065.17	8.95651
3067.74	7.68478
3070.3	6.87843
3072.86	5.61053
3075.42	4.06231
3077.99	3.16777
3080.54	1.64291
3083.1	0.548322
3085.66	-0.263146
3088.22	-0.352541
3090.78	-0.606017
3093.33	0.15502
3095.89	0.825102
3098.44	1.60712
3100.99	2.77366
3103.54	3.69556
3106.1	4.64019
3108.65	5.65676
3111.2	6.40049
3113.74	7.42943
3116.29	7.66126
3118.84	8.30896
3121.38	9.02672
3123.93	9.63853
3126.47	11.0599
3129.01	12.171
3131.56	13.5639
3134.1	14.2326
3136.64	15.4446
3139.18	16.8464
3141.72	18.536
3144.26	20.6814
3146.79	23.9366
3149.33	27.5759