File: data/Raman/poly_smoothed/Thy_00_07_38_1x_45s_532 nm_x100_100%_600 gr_mm_01.txt
#Acq. time (s)=	45
#Accumulations=	2
#Range (cm-¹)=	200...3150
#Windows=	2
#Auto scanning=	Off
#Autofocus=	Off
#Macrospot=	Off
#AutoExposure=	Off
#Spike filter=	Multiple accum.
#Delay time (s)=	0
#Binning=	1
#Readout mode=	Signal
#DeNoise=	Off
#ICS correction=	On
#Dark correction=	Off
#Inst. Process=	Off
#Detector Gain=	Best Dynamic Range
#Detector ADC=	20 kHz
#Detector temperature (°C)=	-69.85
#Instrument=	LabRAM HR Evol
#Detector=	Synapse
#Objective=	x100
#Grating=	600 gr/mm
#ND Filter=	100%
#Laser (nm)=	532
#Hole=	100.021
#Range=	Auto
#Laser Pol.=	No
#Raman. Pol.=	No
#Laser Pol. (°)=	-0.0007625
#Raman Pol. (°)=	89.9995
#Collection=	Microscope
#StageXY=	Marzhauser
#StageZ=	Marzhauser
#X (µm)=	8968.1
#Y (µm)=	-3055.8
#Z (µm)=	-54.85
#Full time(mm:ss)=	3:18
#Project=
#Sample=
#Site=
#Title=	Thy_00_07_38_2x_45s_532 nm_x100_100%_600 gr_mm
#Remark=
#Date=	28.06.2022 12:53
#Acquired=	28.06.2022 12:53:47
#Base:Fit=	10.08.2022 10:07:56
#Base:Sub=	10.08.2022 10:08:40
#Filter:Polynom=	16.08.2022 10:26:06
#AxisType[0]=Intens
#AxisUnit[0]=Cnt
#AxisType[1]=Spectr
#AxisUnit[1]=1/cm
200.407	55.4646
204.035	46.5456
207.665	41.4511
211.291	36.611
214.916	31.3324
218.541	26.4498
222.163	22.2779
225.785	16.895
229.404	14.6681
233.022	12.9724
236.638	10.4724
240.255	9.00517
243.868	7.60964
247.48	7.73848
251.091	7.88017
254.702	7.09802
258.31	7.88655
261.916	8.58143
265.521	9.08184
269.125	8.77467
272.727	8.59786
276.328	7.99767
279.927	8.38563
283.525	9.69799
287.121	10.8915
290.716	11.5863
294.31	12.8763
297.9	12.1788
301.491	12.0388
305.081	12.1004
308.669	11.1545
312.256	10.7782
315.839	12.1057
319.423	12.3785
323.006	11.1511
326.585	9.44634
330.165	10.4273
333.741	10.6422
337.318	9.9717
340.894	9.07985
344.466	8.86631
348.039	8.35376
351.608	7.26517
355.176	6.00211
358.745	4.93973
362.31	4.18451
365.876	3.11234
369.439	3.58716
373	3.6403
376.56	3.48692
380.12	2.81166
383.677	4.6056
387.233	4.72694
390.787	4.33786
394.34	4.04112
397.894	3.55251
401.444	4.41485
404.993	4.74529
408.54	3.33889
412.086	4.54115
415.631	6.79221
419.174	7.96215
422.716	7.44654
426.257	8.21685
429.794	8.72926
433.332	8.13984
436.868	7.03058
440.403	7.50408
443.937	8.55902
447.468	10.8469
450.999	14.0786
454.528	16.5691
458.057	19.6037
461.582	21.2919
465.107	23.7987
468.629	25.3464
472.152	27.522
475.672	28.1163
479.192	27.1493
482.709	27.6136
486.226	29.1518
489.74	29.0299
493.255	30.1265
496.767	30.1727
500.277	30.7391
503.788	29.4987
507.295	26.7191
510.801	24.0944
514.308	20.3164
517.811	17.1545
521.313	14.1073
524.814	13.3225
528.313	11.1189
531.811	11.2192
535.308	10.5082
538.803	11.1919
542.297	11.8725
545.789	11.4264
549.281	10.3699
552.771	10.5766
556.259	11.4941
559.747	12.4092
563.233	13.3602
566.717	13.2279
570.2	14.1744
573.68	14.1684
577.161	13.6999
580.64	13.836
584.118	14.2362
587.593	13.8099
591.068	12.4525
594.54	12.7857
598.013	11.7804
601.484	10.2498
604.952	9.12365
608.421	6.97769
611.886	5.62434
615.35	6.85559
618.815	6.09357
622.276	5.98874
625.738	6.1749
629.197	8.0191
632.655	6.78871
636.113	7.73825
639.568	9.36099
643.021	9.86987
646.473	10.6699
649.924	10.4889
653.376	10.4709
656.824	8.97878
660.271	8.02258
663.716	9.21394
667.161	10.6636
670.604	11.5872
674.045	14.4397
677.486	15.5251
680.925	16.5088
684.361	16.979
687.797	18.5377
691.232	19.2886
694.666	22.238
698.099	23.9363
701.528	24.8562
704.958	25.3467
708.387	26.7509
711.814	27.9937
715.238	30.3971
718.663	32.4062
722.084	34.1968
725.506	35.111
728.925	36.4241
732.345	38.8576
735.761	39.8159
739.178	41.3092
742.592	43.8306
746.006	47.3781
749.417	50.1505
752.827	53.2883
756.236	56.795
759.645	59.1865
763.051	59.6005
766.456	62.9294
769.859	64.9476
773.261	66.145
776.664	67.2971
780.064	68.9934
783.462	68.5201
786.859	68.3146
790.255	68.3347
793.649	68.3264
797.042	70.111
800.434	71.1564
803.823	70.3243
807.212	71.1181
810.6	71.7093
813.987	72.8018
817.372	75.068
820.754	77.4342
824.137	79.578
827.519	81.5955
830.897	82.3835
834.276	84.4829
837.654	85.3539
841.029	85.4097
844.404	85.3782
847.776	85.1907
851.149	83.2445
854.519	80.979
857.889	79.4063
861.256	76.6551
864.622	73.2153
867.988	70.1813
871.351	67.3026
874.713	63.2285
878.074	62.6227
881.435	58.8779
884.794	55.5222
888.15	53.4641
891.506	53.0752
894.861	52.7324
898.214	51.6166
901.566	53.3705
904.916	55.3057
908.266	57.8513
911.614	61.9025
914.961	63.7348
918.306	64.7279
921.651	66.3163
924.994	65.6379
928.336	67.2895
931.674	66.284
935.014	65.401
938.352	64.3008
941.687	61.6777
945.022	59.1476
948.357	55.7387
951.688	52.4644
955.02	49.7079
958.348	47.115
961.678	41.395
965.004	36.8517
968.331	36.2591
971.655	36.2744
974.979	33.8706
978.3	34.0013
981.62	33.5694
984.941	32.9372
988.259	32.1208
991.575	31.8762
994.89	31.0395
998.204	30.1397
1001.52	30.0305
1004.83	30.5384
1008.14	30.769
1011.45	31.6804
1014.76	31.2549
1018.06	31.6043
1021.37	31.522
1024.67	32.6974
1027.97	31.9013
1031.27	32.2888
1034.57	31.4739
1037.87	30.1092
1041.17	29.161
1044.47	29.8221
1047.76	31.5545
1051.06	32.4345
1054.35	33.3674
1057.64	33.4159
1060.93	33.8153
1064.22	34.295
1067.5	35.6449
1070.79	35.9094
1074.08	36.7698
1077.36	37.1734
1080.64	39.8387
1083.92	40.0392
1087.2	41.5916
1090.48	43.4656
1093.76	46.6142
1097.03	49.6905
1100.31	50.3521
1103.58	52.3063
1106.85	53.1454
1110.12	52.8823
1113.39	52.3751
1116.66	51.5451
1119.93	51.8424
1123.19	51.9749
1126.46	50.2764
1129.72	48.243
1132.98	45.8022
1136.24	44.3475
1139.5	40.6728
1142.76	38.4978
1146.01	35.1334
1149.27	29.4412
1152.53	25.2216
1155.78	20.1269
1159.03	16.093
1162.28	11.8888
1165.53	8.60738
1168.78	6.49404
1172.02	6.12105
1175.27	6.52416
1178.51	6.5031
1181.76	5.33963
1185	5.56101
1188.24	5.54873
1191.48	4.99051
1194.71	5.68657
1197.95	6.60092
1201.19	6.58624
1204.42	7.23447
1207.65	8.44475
1210.88	10.2116
1214.12	12.2353
1217.35	14.6611
1220.57	16.5952
1223.8	19.7168
1227.03	21.0879
1230.25	21.9183
1233.47	24.264
1236.69	26.2863
1239.92	29.3309
1243.13	30.1273
1246.35	31.576
1249.57	33.9533
1252.78	35.807
1256	36.4262
1259.21	35.1605
1262.42	32.955
1265.63	33.8034
1268.84	31.5275
1272.05	30.6821
1275.26	30.3997
1278.46	28.9743
1281.67	28.7718
1284.87	28.4323
1288.07	29.9877
1291.27	29.7091
1294.47	30.8824
1297.67	33.7989
1300.87	36.0484
1304.06	39.6139
1307.26	43.0902
1310.45	48.5315
1313.64	53.659
1316.83	57.5825
1320.02	62.7267
1323.21	66.4547
1326.4	69.476
1329.59	70.8199
1332.77	71.8599
1335.95	71.1166
1339.14	70.4622
1342.32	70.2922
1345.5	69.5252
1348.67	68.3636
1351.85	65.6757
1355.03	63.5603
1358.2	60.9236
1361.38	58.8908
1364.55	57.0479
1367.72	54.5081
1370.89	51.5731
1374.06	49.2125
1377.23	48.8561
1380.39	48.585
1383.56	48.1215
1386.72	48.8545
1389.89	48.5743
1393.05	48.5508
1396.21	48.732
1399.37	47.985
1402.52	45.3996
1405.68	43.0008
1408.84	41.0281
1411.99	40.5262
1415.15	39.1597
1418.3	39.3077
1421.45	42.0613
1424.6	44.6826
1427.75	48.1995
1430.89	52.2268
1434.04	56.2966
1437.18	61.081
1440.33	63.7187
1443.47	64.3992
1446.61	65.0322
1449.75	66.0712
1452.89	67.0721
1456.03	66.5875
1459.16	64.9347
1462.3	59.8051
1465.43	55.1965
1468.56	49.9126
1471.7	44.9023
1474.83	39.3384
1477.96	33.5639
1481.08	26.0747
1484.21	20.3072
1487.34	14.7013
1490.46	9.4341
1493.58	5.20494
1496.71	3.59367
1499.83	4.2511
1502.95	3.22076
1506.07	3.77968
1509.18	2.90396
1512.3	4.25835
1515.41	5.80539
1518.53	5.3589
1521.64	7.34155
1524.75	8.82219
1527.86	9.5041
1530.97	11.9452
1534.08	12.2089
1537.19	12.9858
1540.29	13.55
1543.4	14.8934
1546.5	16.6885
1549.6	18.649
1552.7	20.0989
1555.8	21.0546
1558.9	21.9964
1562	23.4036
1565.09	24.2764
1568.19	25.7039
1571.28	28.1792
1574.37	29.7879
1577.47	31.1102
1580.56	32.1095
1583.64	33.5027
1586.73	35.0872
1589.82	36.1691
1592.9	36.9066
1595.99	39.2438
1599.07	39.1316
1602.15	39.8514
1605.23	40.1158
1608.31	38.5174
1611.39	38.4054
1614.47	38.0064
1617.55	36.5856
1620.62	36.3992
1623.7	35.7269
1626.77	36.09
1629.84	36.0185
1632.91	36.5934
1635.98	36.6431
1639.05	37.1341
1642.11	36.7069
1645.18	37.6178
1648.24	38.1668
1651.31	39.4782
1654.37	40.008
1657.43	40.2444
1660.49	39.9024
1663.55	40.4138
1666.61	40.1644
1669.66	39.7488
1672.72	38.44
1675.77	36.5283
1678.83	33.9508
1681.88	31.3344
1684.93	29.7469
1687.98	26.4851
1691.03	24.1809
1694.07	19.7163
1697.12	17.2669
1700.17	15.3116
1703.21	15.1574
1706.25	12.8974
1709.29	12.0816
1712.33	10.2194
1715.37	8.9746
1718.41	8.71876
1721.45	9.3539
1724.49	9.21818
1727.52	8.4645
1730.55	8.13143
1733.59	7.39628
1736.62	6.97453
1739.65	6.66727
1742.68	5.97026
1745.7	5.94123
1748.73	5.86799
1751.76	5.46668
1754.78	4.34802
1757.8	4.11426
1760.83	2.72305
1763.85	2.8007
1766.87	2.65982
1769.89	2.12554
1772.9	2.82911
1775.92	3.17605
1778.94	4.11852
1781.95	4.52418
1784.96	4.86897
1787.97	4.85657
1790.99	5.17855
1794	5.43892
1797	4.9695
1800.01	4.29456
1803.02	4.64592
1806.02	4.99891
1809.03	4.76499
1812.03	4.95126
1815.03	5.3751
1818.03	5.29349
1821.03	5.42904
1824.03	5.79647
1827.03	6.10266
1830.02	6.59406
1833.02	6.71187
1836.01	6.90425
1839.01	7.37314
1842	6.72502
1844.99	6.78138
1847.98	6.86349
1850.97	6.72661
1853.95	6.1635
1856.94	5.26116
1859.93	4.7121
1862.91	3.74816
1865.89	3.88804
1868.87	3.27268
1871.85	3.29942
1874.83	3.82631
1877.81	4.38658
1880.79	3.8958
1882.52	4.73823
1885.51	4.32496
1888.5	3.40762
1891.49	3.60269
1894.47	2.90808
1897.46	3.60703
1900.44	2.9467
1903.42	3.66807
1906.4	3.49729
1909.38	3.16289
1912.36	3.17454
1915.34	2.27257
1918.32	1.88872
1921.29	1.37528
1924.27	1.58428
1927.24	1.05199
1930.21	1.38623
1933.18	2.19908
1936.15	2.78933
1939.12	2.51767
1942.09	2.4271
1945.06	3.1972
1948.02	3.72816
1950.99	3.32276
1953.95	3.38818
1956.91	3.80068
1959.88	3.47432
1962.84	3.43567
1965.8	3.15682
1968.75	3.44934
1971.71	3.71775
1974.67	4.33663
1977.62	4.87197
1980.58	4.83629
1983.53	4.06102
1986.48	3.34804
1989.43	2.77439
1992.38	2.9306
1995.33	3.31612
1998.27	1.71063
2001.22	1.34289
2004.16	1.76932
2007.11	1.45543
2010.05	1.73934
2012.99	2.32731
2015.93	2.89097
2018.87	3.27452
2021.81	3.11038
2024.75	3.37746
2027.69	3.84934
2030.62	4.08265
2033.56	4.73011
2036.49	5.17178
2039.42	6.32322
2042.35	7.07247
2045.28	7.32562
2048.21	6.87149
2051.14	6.25405
2054.07	5.74019
2056.99	4.70799
2059.92	4.94557
2062.84	3.48812
2065.76	2.99855
2068.68	2.58856
2071.6	1.73283
2074.52	1.71897
2077.44	2.49567
2080.36	2.28719
2083.27	1.71716
2086.19	1.20244
2089.1	1.06822
2092.02	1.50726
2094.93	1.24081
2097.84	1.16713
2100.75	1.49351
2103.66	2.43022
2106.56	2.69013
2109.47	2.90847
2112.38	3.25282
2115.28	3.26746
2118.18	3.19004
2121.09	3.06381
2123.99	3.58764
2126.89	3.99126
2129.79	4.20779
2132.68	5.21922
2135.58	5.44876
2138.48	6.03728
2141.37	6.40866
2144.27	7.08303
2147.16	6.91549
2150.05	6.63586
2152.94	5.79148
2155.83	6.39471
2158.72	6.72228
2161.6	5.80035
2164.49	5.17877
2167.38	4.13495
2170.26	3.39742
2173.14	3.04947
2176.03	2.74067
2178.91	1.78117
2181.79	2.45853
2184.67	2.7453
2187.54	3.20722
2190.42	2.53157
2193.3	2.22736
2196.17	2.50789
2199.05	3.31488
2201.92	4.42818
2204.79	3.77864
2207.66	3.48391
2210.53	5.33518
2213.4	4.99318
2216.27	4.83903
2219.13	4.24498
2222	4.14497
2224.86	4.31473
2227.72	4.16857
2230.59	3.68951
2233.45	4.01029
2236.31	3.81434
2239.17	4.11659
2242.03	4.22557
2244.88	4.33558
2247.74	4.22006
2250.59	4.55004
2253.45	5.21809
2256.3	5.08803
2259.15	4.25151
2262	4.18504
2264.85	4.22245
2267.7	5.6986
2270.55	6.43218
2273.4	6.45182
2276.24	5.83496
2279.09	6.40706
2281.93	6.07698
2284.77	5.3838
2287.62	5.48493
2290.46	4.90622
2293.3	4.93324
2296.13	5.43116
2298.97	5.62219
2301.81	6.10835
2304.64	6.53549
2307.48	6.68666
2310.31	5.76304
2313.14	6.36481
2315.98	6.6515
2318.81	7.12536
2321.64	7.54162
2324.46	7.85401
2327.29	7.79258
2330.12	8.40945
2332.94	8.7736
2335.77	9.19386
2338.59	9.15744
2341.41	9.33082
2344.23	8.92438
2347.05	9.04637
2349.87	7.89448
2352.69	7.44321
2355.51	7.13938
2358.32	6.46214
2361.14	6.16839
2363.95	4.8796
2366.76	4.49266
2369.58	3.25657
2372.39	2.2983
2375.2	2.33572
2378	1.78207
2380.81	0.878338
2383.62	0.394422
2386.43	0.326544
2389.23	0.0149332
2392.03	0.449732
2394.84	-0.135692
2397.64	0.163307
2400.44	-0.373217
2403.24	0.113601
2406.04	1.31268
2408.84	2.71275
2411.63	3.44553
2414.43	4.8169
2417.22	5.90227
2420.02	6.62492
2422.81	8.42892
2425.6	9.86441
2428.39	9.88537
2431.18	10.1477
2433.97	10.3368
2436.76	10.4552
2439.54	10.2869
2442.33	11.2707
2445.12	11.186
2447.9	10.7176
2450.68	10.5796
2453.46	10.7649
2456.24	9.90127
2459.02	8.34079
2461.8	7.167
2464.58	6.35947
2467.36	6.34107
2470.13	5.53889
2472.91	5.31758
2475.68	5.22881
2478.45	4.36874
2481.23	3.77591
2484	3.53448
2486.77	3.08004
2489.54	2.2883
2492.3	2.11671
2495.07	1.43185
2497.84	1.174
2500.6	1.28862
2503.36	1.38877
2506.13	2.06662
2508.89	2.60107
2511.65	2.73048
2514.41	3.40803
2517.17	4.66276
2519.93	5.71804
2522.68	5.73467
2525.44	5.1205
2528.19	6.3788
2530.95	6.62709
2533.7	7.7814
2536.45	8.07012
2539.2	7.5738
2541.95	7.1859
2544.7	6.58628
2547.45	6.37178
2550.2	5.40024
2552.94	4.96083
2555.69	3.99812
2558.43	2.79124
2561.18	2.58612
2563.92	2.94148
2566.66	2.72483
2569.4	2.38287
2572.14	2.95185
2574.88	4.0705
2577.61	4.51857
2580.35	5.09684
2583.09	5.92295
2585.82	5.90391
2588.55	5.90607
2591.29	6.29638
2594.02	6.07831
2596.75	6.10325
2599.48	6.54146
2602.21	6.17878
2604.93	5.44418
2607.66	6.06979
2610.39	5.84743
2613.11	6.25343
2615.83	7.3137
2618.56	6.9616
2621.28	6.82754
2624	7.20733
2626.72	7.30464
2629.44	8.43694
2632.15	8.87634
2634.87	9.80157
2637.59	10.5231
2640.3	11.2034
2643.02	11.6834
2645.73	10.9686
2648.44	11.0162
2651.15	11.3421
2653.86	10.9771
2656.57	11.1084
2659.28	10.7159
2661.99	10.1818
2664.69	9.69431
2667.4	9.30102
2670.1	9.2251
2672.81	9.6178
2675.51	10.4863
2678.21	10.3924
2680.91	10.0785
2683.61	10.2253
2686.31	9.66396
2689	9.39624
2691.7	9.10307
2694.4	9.27386
2697.09	9.48551
2699.79	9.11199
2702.48	9.27557
2705.17	9.38287
2707.86	9.65661
2710.55	10.5874
2713.24	11.2288
2715.93	12.4384
2718.62	12.7218
2721.3	12.5253
2723.99	14.1152
2726.67	14.8804
2729.35	15.2023
2732.04	15.2613
2734.72	15.6202
2737.4	16.3927
2740.08	15.9158
2742.76	14.83
2745.43	13.8961
2748.11	14.404
2750.79	13.6375
2753.46	12.6192
2756.14	12.7775
2758.81	12.2708
2761.48	11.3265
2764.15	10.6141
2766.82	9.3215
2769.49	8.12708
2772.16	7.15343
2774.82	6.56466
2777.49	5.33815
2780.16	4.88517
2782.82	4.47867
2785.48	4.46391
2788.15	4.73348
2790.81	5.4214
2793.47	5.50468
2796.13	5.9136
2798.79	5.5326
2801.44	5.69297
2804.1	6.22907
2806.76	5.92207
2809.41	5.72417
2812.07	6.31287
2814.72	7.59333
2817.37	7.8033
2820.02	9.81324
2822.67	12.0077
2825.32	13.215
2827.97	15.1834
2830.62	18.0062
2833.26	20.1594
2835.91	23.0541
2838.56	26.6095
2841.2	30.5407
2843.84	35.1312
2846.48	40.394
2849.12	46.9376
2851.77	53.8559
2854.4	60.6852
2857.04	68.5936
2859.68	76.4138
2862.32	85.3903
2864.95	93.8669
2867.59	103.294
2870.22	111.379
2872.85	119.977
2875.48	128.926
2878.11	138.027
2880.74	146.758
2883.37	155.599
2886	164.335
2888.63	172.423
2891.25	180.28
2893.88	187.439
2896.5	193.363
2899.13	199.682
2901.75	205.992
2904.37	212.431
2906.99	217.917
2909.61	223.65
2912.23	229.594
2914.85	234.645
2917.46	239.286
2920.08	243.042
2922.7	247.057
2925.31	248.952
2927.92	249.152
2930.54	247.968
2933.15	245.76
2935.76	241.725
2938.37	237.446
2940.98	231.831
2943.58	224.863
2946.19	217.498
2948.8	208.957
2951.4	200.338
2954.01	192.096
2956.61	182.361
2959.21	173.998
2961.81	165.442
2964.41	156.843
2967.01	148.247
2969.61	139.862
2972.21	132.329
2974.81	125.342
2977.4	118.017
2980	110.386
2982.59	102.803
2985.18	94.2362
2987.78	86.6568
2990.37	78.1113
2992.96	69.6189
2995.55	61.029
2998.14	53.6142
3000.73	46.8895
3003.31	39.9905
3005.9	33.5621
3008.48	27.3332
3011.07	22.381
3013.65	18.364
3016.23	15.2276
3018.81	12.0836
3021.4	9.06184
3023.97	6.43722
3026.55	4.48047
3029.13	2.69901
3031.71	1.60627
3034.28	1.17969
3036.86	1.65765
3039.43	1.31405
3042.01	2.00827
3044.58	2.57422
3047.15	3.83217
3049.72	4.46069
3052.29	5.37763
3054.86	5.75271
3057.43	5.49859
3060	6.15178
3062.56	6.45811
3065.13	6.37231
3067.69	5.89337
3070.26	5.84496
3072.82	5.72842
3075.38	5.23605
3077.94	5.28642
3080.5	4.62393
3083.06	3.26935
3085.62	2.53407
3088.18	2.42433
3090.73	1.64128
3093.29	1.75784
3095.84	2.08849
3098.4	3.46951
3100.95	4.07873
3103.5	5.53946
3106.05	7.43369
3108.6	9.45505
3111.15	11.079
3113.7	12.8534
3116.25	15.0704
3118.79	16.874
3121.34	18.4297
3123.88	19.7269
3126.43	21.0901
3128.97	22.7085
3131.51	24.117
3134.06	26.0107
3136.6	27.4635
3139.14	27.6624
3141.67	27.9173
3144.21	27.3554
3146.75	26.3519
3149.29	24.5401