File: data/Raman/poly_smoothed/Thy_50_12_09_1x_45s_532 nm_x100_100%_600 gr_mm_01.txt
#Acq. time (s)=	45
#Accumulations=	2
#Range (cm-¹)=	200...3150
#Windows=	2
#Auto scanning=	Off
#Autofocus=	Off
#Macrospot=	Off
#AutoExposure=	Off
#Spike filter=	Multiple accum.
#Delay time (s)=	0
#Binning=	1
#Readout mode=	Signal
#DeNoise=	Off
#ICS correction=	On
#Dark correction=	Off
#Inst. Process=	Off
#Detector Gain=	Best Dynamic Range
#Detector ADC=	20 kHz
#Detector temperature (°C)=	-69.85
#Instrument=	LabRAM HR Evol
#Detector=	Synapse
#Objective=	x100
#Grating=	600 gr/mm
#ND Filter=	100%
#Laser (nm)=	532
#Hole=	100.021
#Range=	Auto
#Laser Pol.=	No
#Raman. Pol.=	No
#Laser Pol. (°)=	-0.0007625
#Raman Pol. (°)=	89.9995
#Collection=	Microscope
#StageXY=	Marzhauser
#StageZ=	Marzhauser
#X (µm)=	-5107.7
#Y (µm)=	1504.9
#Z (µm)=	63.1
#Full time(mm:ss)=	3:19
#Project=
#Sample=
#Site=
#Title=	Thy_50_12_09_2x_45s_532 nm_x100_100%_600 gr_mm
#Remark=
#Date=	07.07.2022 09:53
#Acquired=	07.07.2022 09:53:02
#Base:Fit=	10.08.2022 10:03:08
#Base:Fit=	10.08.2022 10:03:15
#Base:Fit=	10.08.2022 10:03:19
#Base:Fit=	10.08.2022 10:04:29
#Base:Sub=	10.08.2022 10:04:45
#Filter:Polynom=	16.08.2022 10:20:24
#AxisType[0]=Intens
#AxisUnit[0]=Cnt
#AxisType[1]=Spectr
#AxisUnit[1]=1/cm
200.43	22.3528
204.061	20.7585
207.688	20.0742
211.316	18.0712
214.941	16.6263
218.566	14.0164
222.188	12.935
225.809	11.3842
229.43	10.8568
233.047	9.94487
236.663	8.18409
240.278	8.41758
243.894	9.2242
247.506	8.66448
251.116	8.13728
254.725	9.77483
258.333	10.731
261.939	11.3232
265.546	11.3688
269.15	12.7557
272.752	16.1677
276.353	17.9086
279.952	17.4624
283.55	19.38
287.146	19.0436
290.739	18.7936
294.333	20.779
297.925	21.9763
301.516	21.2454
305.106	21.5846
308.694	20.0385
312.279	18.9736
315.864	18.7514
319.448	18.2029
323.029	16.8086
326.61	16.5387
330.19	18.1787
333.766	19.4031
337.343	17.6456
340.917	17.8871
344.491	18.1176
348.062	17.6035
351.633	18.8055
355.201	18.8514
358.77	18.422
362.335	15.2846
365.899	14.9372
369.464	14.4739
373.025	14.252
376.585	12.6022
380.143	11.9453
383.702	11.1858
387.258	9.46844
390.812	7.09004
394.365	5.93993
397.916	5.81415
401.467	5.2826
405.015	6.09304
408.565	5.08443
412.111	5.96563
415.656	7.2099
419.197	8.93262
422.739	9.07633
426.279	8.86091
429.819	10.8973
433.356	10.2085
436.893	11.3166
440.428	11.2519
443.96	9.79017
447.492	10.2519
451.023	10.2118
454.553	12.281
458.079	13.6904
461.606	14.931
465.132	15.0163
468.654	17.0504
472.177	18.1033
475.696	20.3279
479.217	20.4891
482.733	21.6641
486.251	22.6352
489.765	23.2665
493.278	24.5053
496.791	25.1435
500.301	27.9218
503.81	29.7528
507.319	28.4857
510.825	28.9971
514.33	29.2139
517.833	28.1419
521.337	27.444
524.838	28.3043
528.337	26.8322
531.835	25.9878
535.332	24.7594
538.827	22.967
542.321	23.2207
545.814	23.2489
549.305	22.6593
552.795	22.5001
556.284	23.2112
559.771	23.0046
563.257	20.5209
566.742	18.5917
570.223	18.5931
573.705	17.5657
577.185	16.0796
580.665	15.1745
584.141	16.648
587.617	15.4428
591.092	15.1894
594.564	14.0599
598.037	13.5917
601.506	12.6487
604.976	13.6874
608.443	12.5743
611.91	11.4886
615.374	11.171
618.839	11.4563
622.3	12.4719
625.761	14.9581
629.221	18.1697
632.679	21.7176
636.135	24.5012
639.592	25.789
643.045	27.5018
646.497	27.4558
649.948	29.0458
653.398	30.0447
656.846	30.2323
660.293	31.3553
663.738	31.16
667.185	32.1383
670.628	33.1309
674.067	33.9167
677.508	33.3295
680.947	31.7769
684.385	32.5967
687.821	34.0019
691.256	34.2958
694.69	35.5905
698.121	37.8171
701.552	37.6345
704.982	39.0365
708.41	42.2438
711.836	44.9721
715.262	47.5732
718.685	50.0081
722.108	52.5535
725.53	55.5219
728.949	58.0527
732.369	58.5244
735.785	61.0806
739.2	62.5882
742.616	62.9381
746.028	65.4784
749.441	67.8576
752.851	69.9955
756.26	72.753
759.667	73.9122
763.075	75.1636
766.479	77.3431
769.883	80.5883
773.285	80.5628
776.686	82.0428
780.085	82.8129
783.484	84.7995
786.881	86.3754
790.276	88.7455
793.671	91.1181
797.064	90.6902
800.456	92.3805
803.846	93.6188
807.236	93.9977
810.624	94.0064
814.01	94.4269
817.394	94.1915
820.778	95.848
824.161	93.5302
827.543	92.4455
830.921	90.8341
834.3	89.6765
837.676	86.9733
841.053	85.12
844.426	83.3562
847.8	80.5179
851.171	77.9143
854.542	75.6098
857.911	73.0877
861.279	70.8905
864.645	68.6296
868.01	66.6729
871.375	63.7648
874.737	60.5097
878.097	58.0831
881.457	57.6051
884.817	56.9166
888.174	57.1458
891.53	55.4201
894.884	54.9785
898.237	55.7704
901.589	56.3157
904.94	55.3472
908.289	54.1689
911.637	53.7556
914.984	52.8952
918.33	52.0475
921.674	51.2629
925.015	51.6415
928.357	51.7444
931.698	51.0807
935.037	51.4913
938.373	50.2269
941.71	48.8189
945.046	47.167
948.378	46.0363
951.711	45.4049
955.043	45.2869
958.372	43.4175
961.701	43.0251
965.027	42.6331
968.354	40.7945
971.678	40.1869
975	39.0748
978.324	39.4484
981.644	37.7514
984.962	36.4098
988.282	35.2158
991.598	33.4852
994.913	32.19
998.227	30.3462
1001.54	29.6766
1004.85	29.1658
1008.16	29.5997
1011.47	29.7889
1014.78	31.4856
1018.08	32.7643
1021.39	33.2184
1024.69	34.0765
1028	35.298
1031.3	36.4295
1034.6	37.7832
1037.9	38.6027
1041.19	37.806
1044.49	37.7373
1047.79	36.8154
1051.08	36.45
1054.37	36.6357
1057.66	35.5361
1060.95	34.2771
1064.24	32.0691
1067.53	29.9358
1070.81	27.1176
1074.1	25.7422
1077.38	23.1008
1080.66	20.1237
1083.94	17.8295
1087.22	15.9551
1090.5	14.0638
1093.78	14.8642
1097.05	16.4926
1100.33	15.8559
1103.6	16.833
1106.87	16.4749
1110.15	17.6182
1113.41	19.7472
1116.68	18.4718
1119.95	17.2859
1123.21	16.6099
1126.48	16.2628
1129.74	16.0876
1133	15.7268
1136.26	14.5989
1139.52	15.1162
1142.78	13.7914
1146.04	12.6361
1149.29	11.2924
1152.55	9.45202
1155.8	7.16814
1159.05	5.54161
1162.3	4.56965
1165.55	3.6241
1168.8	2.97988
1172.05	3.34643
1175.29	5.55998
1178.54	6.37259
1181.78	7.02298
1185.02	7.59801
1188.26	8.62073
1191.5	10.5523
1194.74	10.1594
1197.97	9.1067
1201.21	9.52686
1204.44	9.99981
1207.68	11.0011
1210.91	12.3829
1214.14	12.6353
1217.37	14.6416
1220.6	17.0614
1223.82	18.3113
1227.05	21.1241
1230.27	21.4963
1233.49	21.9893
1236.72	23.5134
1239.94	26.7004
1243.16	27.8487
1246.37	30.0422
1249.59	33.0198
1252.8	33.9919
1256.02	35.8266
1259.23	38.1595
1262.44	41.0181
1265.66	42.1076
1268.87	46.2497
1272.07	47.4396
1275.28	48.3402
1278.48	49.1659
1281.69	51.623
1284.89	53.4659
1288.09	54.7997
1291.3	56.6126
1294.49	57.2345
1297.69	56.9854
1300.89	56.9864
1304.09	56.6929
1307.28	55.5215
1310.47	52.9115
1313.66	51.4953
1316.86	51.1034
1320.05	49.4123
1323.23	48.2497
1326.42	46.7699
1329.61	44.5626
1332.79	41.5324
1335.98	41.2122
1339.16	39.1833
1342.34	38.7363
1345.52	36.2725
1348.7	35.7152
1351.87	34.0686
1355.05	34.5413
1358.23	33.5473
1361.4	34.9083
1364.57	33.2348
1367.74	34.0877
1370.91	32.0449
1374.08	31.0795
1377.25	30.9559
1380.42	31.7714
1383.58	32.8269
1386.75	32.687
1389.91	31.7663
1393.07	32.4954
1396.23	32.8436
1399.39	33.579
1402.55	33.589
1405.7	34.5304
1408.86	35.0725
1412.01	36.6013
1415.17	38.481
1418.32	39.5361
1421.47	42.0986
1424.62	45.2083
1427.77	49.0084
1430.92	52.3396
1434.06	56.3772
1437.2	60.1371
1440.35	62.4107
1443.49	65.4235
1446.63	66.1667
1449.77	66.77
1452.91	67.0806
1456.05	65.8771
1459.18	63.7243
1462.32	60.6339
1465.45	55.3525
1468.59	50.2315
1471.72	45.5063
1474.85	39.1936
1477.98	34.4659
1481.11	31.1578
1484.23	25.7711
1487.36	20.608
1490.48	17.3219
1493.61	13.1161
1496.73	10.5889
1499.85	9.9212
1502.97	9.84102
1506.09	9.81156
1509.2	9.46769
1512.32	11.0367
1515.44	12.2121
1518.55	13.5191
1521.66	14.8797
1524.77	16.6377
1527.88	17.4043
1530.99	19.3473
1534.1	19.1705
1537.21	22.7041
1540.31	23.7667
1543.42	27.4476
1546.52	30.1238
1549.62	32.8567
1552.72	37.0184
1555.82	40.6012
1558.92	42.9121
1562.02	45.9005
1565.11	49.1265
1568.21	51.1695
1571.3	53.1858
1574.39	54.4676
1577.49	55.3755
1580.58	55.584
1583.67	54.1763
1586.75	53.1233
1589.84	52.1731
1592.93	51.7658
1596.01	49.1796
1599.09	48.1368
1602.18	45.8612
1605.26	45.4151
1608.34	45.0623
1611.41	44.4327
1614.49	44.2575
1617.57	44.0164
1620.64	44.9124
1623.72	43.7738
1626.79	44.8084
1629.86	46.0211
1632.93	48.0238
1636	51.0454
1639.07	53.5518
1642.14	55.8025
1645.2	55.759
1648.27	56.797
1651.33	57.0825
1654.39	56.7699
1657.45	55.7712
1660.51	53.2089
1663.57	52.7199
1666.63	51.9108
1669.69	48.3746
1672.74	46.8767
1675.79	45.7376
1678.85	43.1523
1681.9	41.2706
1684.95	37.5802
1688	31.8474
1691.05	27.5873
1694.1	24.1777
1697.14	20.8949
1700.19	18.7276
1703.23	16.1904
1706.27	14.3608
1709.32	13.9557
1712.35	12.7854
1715.39	9.91916
1718.43	8.52357
1721.47	7.67037
1724.5	7.54323
1727.54	5.23932
1730.57	5.26362
1733.61	4.90252
1736.64	4.76861
1739.67	4.51038
1742.7	4.18443
1745.72	3.83601
1748.75	4.59904
1751.78	4.71875
1754.8	5.04541
1757.82	3.62441
1760.85	2.87323
1763.87	3.66566
1766.89	3.44744
1769.91	3.13728
1772.92	3.51036
1775.94	3.03684
1778.96	1.66792
1781.97	1.80366
1784.98	1.73818
1788	1.68848
1791.01	1.37137
1794.01	0.956362
1797.02	0.49721
1800.03	1.28008
1803.04	0.735504
1806.04	1.51214
1809.05	1.02904
1812.05	0.73175
1815.05	0.750201
1818.05	-0.256368
1821.05	-0.081039
1824.05	1.08646
1827.05	0.348036
1830.04	1.17476
1833.04	0.760377
1836.03	1.03126
1839.03	0.938537
1842.02	0.938773
1845.01	1.61454
1848	2.20239
1850.99	1.82454
1853.97	3.12512
1856.96	4.17451
1859.94	4.14543
1862.93	3.87509
1865.91	3.6971
1868.89	4.26037
1871.87	5.10895
1874.85	5.30214
1877.83	6.45178
1880.81	6.77011
1882.56	7.62139
1885.55	7.7775
1888.54	7.69899
1891.52	8.18775
1894.51	8.57625
1897.49	9.99627
1900.48	9.72551
1903.46	10.0022
1906.44	8.20729
1909.42	8.16718
1912.4	8.49395
1915.38	8.97956
1918.35	9.20518
1921.33	9.16818
1924.3	10.182
1927.28	10.1995
1930.25	8.42947
1933.22	6.68706
1936.19	6.00443
1939.16	5.05624
1942.13	5.00039
1945.09	4.55999
1948.06	4.55925
1951.03	4.73595
1953.99	3.68276
1956.95	3.46797
1959.91	3.92517
1962.87	4.88006
1965.83	5.46193
1968.79	4.95495
1971.75	5.47796
1974.7	4.18357
1977.66	3.78346
1980.61	4.25444
1983.56	5.32363
1986.52	6.35169
1989.47	7.61893
1992.41	8.18214
1995.36	8.42633
1998.31	8.22277
2001.26	7.89718
2004.2	6.61965
2007.15	6.42879
2010.09	6.17028
2013.03	7.38199
2015.97	7.97538
2018.91	7.63955
2021.85	8.50126
2024.79	8.49806
2027.72	8.95087
2030.66	10.5649
2033.59	11.3135
2036.53	11.223
2039.46	10.2089
2042.39	10.1757
2045.32	10.8986
2048.25	10.3709
2051.18	11.1266
2054.1	11.4251
2057.03	11.2316
2059.95	12.1245
2062.88	12.5491
2065.8	12.4287
2068.72	13.6847
2071.64	16.2583
2074.56	17.6344
2077.48	18.7728
2080.39	20.611
2083.31	23.0697
2086.22	24.6622
2089.14	26.5532
2092.05	28.2263
2094.96	30.1903
2097.87	32.0458
2100.78	34.4908
2103.69	36.8889
2106.6	38.5173
2109.51	39.2867
2112.41	40.9931
2115.32	42.1877
2118.22	44.2103
2121.12	44.6727
2124.02	45.9651
2126.92	47.0227
2129.82	49.0318
2132.72	50.6566
2135.62	52.1894
2138.51	54.6801
2141.41	57.1145
2144.3	60.2149
2147.19	62.5229
2150.09	63.992
2152.97	66.0667
2155.86	67.5223
2158.75	69.3359
2161.64	71.4225
2164.53	72.1238
2167.41	73.5747
2170.3	74.9944
2173.18	75.5585
2176.06	75.2249
2178.94	75.2341
2181.82	74.995
2184.7	73.4835
2187.58	71.9997
2190.46	69.7024
2193.33	67.6427
2196.21	64.9856
2199.08	63.6568
2201.95	61.089
2204.83	58.0858
2207.7	56.5238
2210.57	53.3718
2213.43	50.8483
2216.3	47.1988
2219.17	43.4692
2222.03	40.392
2224.9	37.4512
2227.76	36.5697
2230.62	34.5649
2233.49	32.1766
2236.34	30.0744
2239.2	28.8471
2242.06	27.6813
2244.92	25.9817
2247.78	25.7635
2250.63	25.7784
2253.48	24.6655
2256.34	23.471
2259.19	22.4917
2262.04	23.6352
2264.89	24.0002
2267.74	23.5326
2270.59	23.9855
2273.43	23.0786
2276.28	22.8783
2279.12	21.6371
2281.97	20.729
2284.81	19.1108
2287.65	17.8807
2290.49	16.1157
2293.33	14.1232
2296.17	13.9845
2299.01	13.6677
2301.84	12.9366
2304.68	12.1972
2307.51	12.1587
2310.35	11.049
2313.18	9.47733
2316.01	9.05724
2318.84	8.10237
2321.67	7.73216
2324.5	7.74632
2327.33	8.45255
2330.15	8.60158
2332.98	8.74439
2335.8	8.1616
2338.62	8.67404
2341.45	9.08449
2344.27	8.89397
2347.09	7.45381
2349.91	7.15451
2352.72	7.38434
2355.54	5.57482
2358.36	4.21387
2361.17	2.86598
2363.98	3.76013
2366.8	4.55781
2369.61	3.86756
2372.42	2.76
2375.23	1.42579
2378.04	0.63077
2380.85	-0.192678
2383.66	-0.044297
2386.46	0.553164
2389.26	2.63398
2392.07	3.6603
2394.87	4.30357
2397.67	4.59024
2400.47	4.6595
2403.27	6.05181
2406.07	6.82294
2408.87	6.40319
2411.67	7.39988
2414.46	7.56173
2417.26	6.85974
2420.05	7.5389
2422.84	7.05465
2425.64	6.63864
2428.43	6.12825
2431.22	6.92926
2434.01	6.29837
2436.79	5.56134
2439.58	5.13607
2442.37	5.10316
2445.15	4.90039
2447.93	4.54349
2450.72	5.18529
2453.5	5.87207
2456.28	6.1668
2459.06	5.63322
2461.84	4.38515
2464.62	4.89396
2467.39	4.37149
2470.17	3.41557
2472.94	3.24062
2475.72	2.68445
2478.49	3.00611
2481.26	2.57484
2484.03	3.02446
2486.8	3.10811
2489.57	2.85717
2492.34	2.81609
2495.1	2.32628
2497.87	2.59214
2500.63	2.41477
2503.4	2.56939
2506.16	3.31832
2508.92	3.35173
2511.68	2.49237
2514.44	1.9526
2517.2	2.20863
2519.96	1.66966
2522.72	2.25867
2525.47	1.7071
2528.23	1.88741
2530.98	2.24649
2533.74	2.91883
2536.49	3.23831
2539.24	2.80169
2541.99	4.67459
2544.74	5.46529
2547.49	5.87
2550.23	5.63337
2552.98	6.34221
2555.72	6.48561
2558.47	7.41925
2561.21	7.38423
2563.95	7.14213
2566.69	7.70821
2569.43	7.30011
2572.17	6.91499
2574.91	6.64503
2577.65	6.45022
2580.39	6.20113
2583.12	6.09102
2585.85	6.20559
2588.59	6.24879
2591.32	6.28471
2594.05	6.72138
2596.78	7.02336
2599.51	6.59942
2602.24	6.3218
2604.97	6.41873
2607.69	6.05897
2610.42	5.80273
2613.14	4.26322
2615.87	3.60891
2618.59	3.68001
2621.31	3.71567
2624.03	3.49184
2626.75	2.83282
2629.47	2.42411
2632.19	1.77296
2634.91	1.70534
2637.62	0.759135
2640.34	0.887466
2643.05	1.65697
2645.76	1.19946
2648.48	1.15968
2651.19	1.59411
2653.9	1.70018
2656.6	1.56971
2659.31	0.835861
2662.02	0.806991
2664.73	0.561234
2667.43	0.0307249
2670.14	-0.163881
2672.84	-0.123873
2675.54	-0.910143
2678.24	-1.16456
2680.94	-1.62704
2683.64	-0.672901
2686.34	1.40707
2689.04	1.928
2691.74	2.53057
2694.43	3.79199
2697.13	5.02957
2699.82	5.48613
2702.51	6.76029
2705.21	7.37468
2707.9	7.96444
2710.58	8.81494
2713.27	9.87967
2715.96	9.57625
2718.65	9.37822
2721.33	8.92447
2724.02	8.3328
2726.71	8.37756
2729.39	8.40893
2732.07	7.25706
2734.75	5.89504
2737.43	5.61556
2740.11	5.06396
2742.79	4.15273
2745.47	3.26992
2748.14	3.74877
2750.82	4.15565
2753.49	4.40274
2756.17	4.11056
2758.84	4.44473
2761.51	4.41309
2764.18	4.22795
2766.85	4.31507
2769.52	4.52076
2772.19	5.49661
2774.86	3.72877
2777.52	4.18623
2780.19	4.15053
2782.85	4.56168
2785.52	4.50835
2788.18	4.36078
2790.84	4.0991
2793.5	3.21374
2796.16	2.14901
2798.82	1.3933
2801.48	0.892145
2804.13	0.395233
2806.79	0.211295
2809.45	-0.109082
2812.1	-0.665454
2814.75	-1.49899
2817.41	-0.910749
2820.06	0.956477
2822.71	3.57496
2825.36	6.22018
2828	9.32457
2830.65	13.3001
2833.3	17.432
2835.94	22.1481
2838.59	26.182
2841.23	30.8115
2843.87	36.2788
2846.52	41.1933
2849.16	47.6675
2851.8	52.5386
2854.44	58.2374
2857.08	64.5793
2859.71	71.1136
2862.35	76.9222
2864.98	82.873
2867.62	87.4239
2870.25	92.0006
2872.88	95.5888
2875.52	97.7037
2878.15	100.363
2880.78	104.261
2883.41	107.571
2886.03	111.723
2888.66	115.564
2891.29	118.674
2893.91	122
2896.54	126.014
2899.16	129.469
2901.78	131.602
2904.4	136.068
2907.02	139.737
2909.64	144.927
2912.26	150.152
2914.88	157.388
2917.5	163.386
2920.11	168.646
2922.73	174.041
2925.34	177.867
2927.96	179.774
2930.57	180.664
2933.18	180.678
2935.79	178.824
2938.4	176.157
2941.01	172.998
2943.62	168.868
2946.22	164.533
2948.83	159.009
2951.43	152.961
2954.04	146.885
2956.64	140.633
2959.24	134.685
2961.84	128.131
2964.45	121.07
2967.05	115.924
2969.64	110.465
2972.24	104.323
2974.84	98.722
2977.43	93.6549
2980.03	88.0485
2982.62	80.8928
2985.22	74.7139
2987.81	68.2871
2990.4	61.1697
2992.99	54.7061
2995.58	48.379
2998.17	42.7575
3000.76	36.2347
3003.34	31.328
3005.93	27.2968
3008.52	22.8461
3011.1	19.1054
3013.68	15.7585
3016.27	14.0223
3018.85	11.8541
3021.43	10.8103
3024.01	9.8345
3026.59	9.11929
3029.16	8.74966
3031.74	8.46194
3034.32	8.38939
3036.89	7.98591
3039.47	7.91467
3042.04	8.20344
3044.61	8.28343
3047.18	7.91624
3049.75	7.31212
3052.32	7.80396
3054.89	7.55485
3057.46	7.57272
3060.03	7.41912
3062.59	7.21989
3065.16	6.52502
3067.72	6.30187
3070.29	5.90938
3072.85	5.65157
3075.41	4.44977
3077.97	2.84067
3080.53	2.06715
3083.09	0.996846
3085.65	0.302791
3088.21	-0.55071
3090.76	-0.15329
3093.32	0.0192875
3095.87	0.844113
3098.43	1.72467
3100.98	2.08169
3103.53	3.16829
3106.08	3.94197
3108.63	5.04391
3111.18	6.55383
3113.73	8.0177
3116.28	9.00734
3118.83	10.3644
3121.37	11.7069
3123.92	13.3511
3126.46	13.9314
3129	15.4439
3131.55	15.6442
3134.09	16.248
3136.63	16.0559
3139.17	15.6629
3141.71	15.2113
3144.24	15.2647
3146.78	16.0272
3149.32	17.0659