File: data/Raman/poly_smoothed/Thy_30_10_08_1x_45s_532 nm_x100_100%_600 gr_mm_01.txt
#Acq. time (s)=	45
#Accumulations=	2
#Range (cm-¹)=	200...3150
#Windows=	2
#Auto scanning=	Off
#Autofocus=	Off
#Macrospot=	Off
#AutoExposure=	Off
#Spike filter=	Multiple accum.
#Delay time (s)=	0
#Binning=	1
#Readout mode=	Signal
#DeNoise=	Off
#ICS correction=	On
#Dark correction=	Off
#Inst. Process=	Off
#Detector Gain=	Best Dynamic Range
#Detector ADC=	20 kHz
#Detector temperature (°C)=	-69.85
#Instrument=	LabRAM HR Evol
#Detector=	Synapse
#Objective=	x100
#Grating=	600 gr/mm
#ND Filter=	100%
#Laser (nm)=	532
#Hole=	100.021
#Range=	Auto
#Laser Pol.=	No
#Raman. Pol.=	No
#Laser Pol. (°)=	-0.0007625
#Raman Pol. (°)=	89.9995
#Collection=	Microscope
#StageXY=	Marzhauser
#StageZ=	Marzhauser
#X (µm)=	4748.5
#Y (µm)=	-7738.5
#Z (µm)=	584.6
#Full time(mm:ss)=	3:18
#Project=
#Sample=
#Site=
#Title=	Thy_30_10_08_2x_45s_532 nm_x100_100%_600 gr_mm
#Remark=
#Date=	30.06.2022 11:56
#Acquired=	30.06.2022 11:56:10
#Base:Fit=	10.08.2022 09:56:48
#Base:Fit=	10.08.2022 09:57:06
#Base:Fit=	10.08.2022 09:57:43
#Base:Fit=	10.08.2022 09:57:50
#Base:Fit=	10.08.2022 09:58:11
#Base:Sub=	10.08.2022 09:58:44
#Filter:Polynom=	16.08.2022 10:22:53
#AxisType[0]=Intens
#AxisUnit[0]=Cnt
#AxisType[1]=Spectr
#AxisUnit[1]=1/cm
200.533	-1.0653
204.162	7.74252
207.792	13.9863
211.418	18.3695
215.044	20.4224
218.667	21.7859
222.289	22.2015
225.912	21.7205
229.531	21.7373
233.148	19.2248
236.766	20.1353
240.381	20.4885
243.994	20.913
247.606	19.4378
251.217	17.2489
254.828	16.2915
258.436	15.41
262.042	13.2757
265.647	14.6378
269.25	13.631
272.852	13.832
276.453	13.3948
280.052	13.3999
283.65	13.708
287.247	13.8065
290.842	13.4645
294.436	13.0724
298.028	11.8118
301.617	12.2379
305.206	11.5209
308.794	12.6814
312.381	13.5069
315.964	13.6432
319.548	12.7363
323.131	13.5048
326.71	14.5179
330.29	13.6692
333.868	13.1617
337.443	11.6518
341.018	11.3939
344.591	10.1484
348.163	8.18941
351.733	7.28606
355.303	7.22872
358.869	5.94666
362.435	5.12363
366.001	3.95466
369.563	3.53285
373.124	2.66437
376.686	1.46248
380.244	0.649605
383.801	2.46627
387.357	2.1565
390.911	2.80173
394.466	2.67603
398.018	3.50016
401.568	4.0486
405.117	3.43327
408.664	3.53471
412.21	3.77213
415.755	3.14902
419.298	3.0698
422.84	3.30137
426.38	3.97421
429.919	4.35204
433.455	2.38885
436.992	2.46635
440.527	2.77342
444.06	3.16327
447.593	2.44354
451.122	3.02233
454.651	2.68563
458.18	3.94923
461.705	4.70078
465.23	5.75421
468.752	7.18973
472.275	7.53668
475.797	6.92217
479.315	7.75265
482.834	9.14669
486.349	10.2422
489.863	11.3468
493.378	11.7024
496.889	12.586
500.401	13.9009
503.91	14.0553
507.417	15.489
510.923	15.806
514.43	13.984
517.933	12.191
521.435	12.2355
524.936	11.617
528.435	11.6354
531.933	10.9267
535.43	10.8307
538.927	9.4953
542.421	9.45858
545.913	10.1446
549.403	9.19778
552.893	7.67272
556.381	6.66341
559.868	5.2237
563.354	4.46272
566.839	4.30147
570.322	2.89269
573.802	3.16998
577.283	2.37535
580.762	2.20937
584.24	2.00862
587.714	1.61293
591.19	-0.254033
594.663	-0.99664
598.134	-1.97329
601.605	-2.14042
605.073	-0.0343153
608.542	0.181414
612.007	1.44875
615.473	3.1885
618.936	4.26194
622.397	5.57346
625.859	6.57101
629.318	7.45192
632.775	8.20969
636.233	9.09187
639.688	10.3333
643.142	10.9799
646.594	12.0882
650.045	11.904
653.496	13.5072
656.944	13.6308
660.391	15.4576
663.837	16.2326
667.281	17.1421
670.724	19.6442
674.166	20.3522
677.606	21.9197
681.045	23.6745
684.483	24.9133
687.917	25.854
691.352	27.5486
694.786	30.2724
698.219	31.5432
701.65	34.6732
705.078	36.1136
708.506	37.8021
711.934	38.685
715.358	40.4086
718.782	41.3542
722.204	42.3253
725.626	42.7519
729.045	44.9129
732.464	45.5889
735.881	48.2429
739.297	50.1129
742.711	51.7404
746.125	54.6399
749.537	56.5913
752.946	61.0872
756.357	62.5145
759.764	65.3467
763.17	66.4174
766.575	68.3969
769.978	71.6021
773.382	73.9945
776.783	77.4598
780.182	80.5427
783.581	83.4831
786.978	84.8074
790.373	86.0427
793.768	87.9306
797.161	89.5673
800.552	91.1413
803.941	92.7129
807.33	94.366
810.718	96.3031
814.105	98.7894
817.49	98.6434
820.873	100.18
824.256	99.9273
827.637	99.0624
831.016	98.404
834.395	97.8592
837.772	96.984
841.147	94.6146
844.522	91.9677
847.894	90.6762
851.267	88.5396
854.637	86.8699
858.007	84.7739
861.374	84.0491
864.739	82.593
868.106	79.0825
871.469	76.7601
874.831	75.8111
878.193	73.8737
881.553	72.4757
884.911	70.5849
888.268	69.5139
891.623	69.2355
894.978	68.5717
898.331	66.7163
901.683	66.2409
905.033	63.9444
908.383	63.3459
911.731	63.4047
915.078	62.6485
918.423	62.887
921.768	62.6451
925.111	63.8046
928.452	64.9677
931.791	64.5196
935.13	64.8731
938.468	63.7746
941.803	63.9959
945.139	63.5248
948.473	61.9521
951.804	61.8971
955.136	61.6068
958.465	59.9344
961.794	57.6131
965.12	57.3029
968.447	58.4657
971.771	58.6859
975.095	57.6959
978.417	57.785
981.737	58.5822
985.057	60.1557
988.375	59.4663
991.691	59.8353
995.006	60.3489
998.32	61.0828
1001.63	62.1175
1004.95	62.9631
1008.26	63.3579
1011.56	62.8433
1014.87	62.9127
1018.18	61.0218
1021.48	59.3664
1024.79	58.5732
1028.09	57.8747
1031.39	57.2119
1034.69	56.1475
1037.99	53.6429
1041.29	51.4054
1044.58	49.7305
1047.88	50.1324
1051.17	49.4947
1054.46	46.9541
1057.75	45.7133
1061.04	46.6485
1064.33	44.5784
1067.62	43.7533
1070.9	42.7769
1074.19	42.7755
1077.47	43.7238
1080.76	42.9534
1084.04	42.389
1087.32	42.3958
1090.59	43.8192
1093.87	46.2398
1097.15	44.8215
1100.42	45.3625
1103.69	47.7475
1106.97	49.0696
1110.24	49.1273
1113.51	49.0755
1116.77	47.5285
1120.04	46.8693
1123.31	46.5324
1126.57	45.7667
1129.83	44.8655
1133.1	42.0898
1136.36	42.6702
1139.62	41.6859
1142.87	40.9986
1146.13	38.3115
1149.38	37.1269
1152.64	34.8493
1155.89	33.3132
1159.14	31.4334
1162.39	29.5991
1165.64	27.5235
1168.89	28.2385
1172.14	27.9143
1175.38	27.9807
1178.63	27.5896
1181.87	27.7676
1185.11	28.0669
1188.35	28.1008
1191.59	29.5008
1194.83	29.9345
1198.07	32.0223
1201.3	34.1757
1204.53	37.4922
1207.77	40.3329
1211	42.4797
1214.23	46.9231
1217.46	51.5274
1220.69	54.8276
1223.91	58.7673
1227.14	60.4819
1230.36	63.5704
1233.59	66.0581
1236.81	67.5806
1240.03	69.7526
1243.25	71.5185
1246.46	72.9873
1249.68	74.3598
1252.9	74.7002
1256.11	75.4398
1259.32	76.8354
1262.54	78.5774
1265.75	80.6493
1268.96	82.5468
1272.16	83.5076
1275.37	86.4293
1278.57	87.5313
1281.78	89.0379
1284.98	90.3067
1288.18	90.8822
1291.38	91.3997
1294.58	92.8725
1297.78	92.9995
1300.98	92.7262
1304.17	90.7759
1307.37	90.6958
1310.56	90.7649
1313.76	87.8072
1316.95	87.2671
1320.14	84.8303
1323.32	82.6302
1326.51	81.1451
1329.7	80.1078
1332.88	78.6289
1336.07	77.952
1339.25	76.4688
1342.43	75.6049
1345.61	74.4586
1348.79	73.2278
1351.96	71.8017
1355.14	70.1564
1358.31	68.1894
1361.49	68.0435
1364.66	66.0913
1367.83	64.1189
1371	63.0584
1374.17	62.0721
1377.34	59.7434
1380.5	57.6413
1383.67	55.1899
1386.83	53.6539
1390	50.0688
1393.16	48.3035
1396.32	46.6567
1399.48	43.7264
1402.64	43.3378
1405.79	43.8352
1408.95	42.9105
1412.1	44.2281
1415.26	45.2258
1418.41	46.6526
1421.56	49.2381
1424.71	51.7516
1427.86	54.8159
1431	58.8364
1434.15	64.45
1437.29	69.2093
1440.44	72.5744
1443.58	74.9168
1446.72	77.5166
1449.86	78.2714
1453	77.378
1456.14	75.1708
1459.27	73.6015
1462.41	70.0566
1465.54	66.9375
1468.67	62.8702
1471.81	58.2217
1474.94	53.0101
1478.07	49.1899
1481.19	44.6983
1484.32	38.7052
1487.45	32.8978
1490.57	27.7574
1493.69	23.9492
1496.82	21.4065
1499.94	19.1667
1503.06	16.7544
1506.17	16.7913
1509.29	18.1898
1512.41	17.6164
1515.52	16.3976
1518.64	16.3294
1521.75	17.1758
1524.86	17.2821
1527.97	18.8754
1531.08	20.5822
1534.19	23.3729
1537.29	24.6359
1540.4	26.7147
1543.5	29.7635
1546.61	31.5086
1549.71	34.4568
1552.81	38.6655
1555.91	41.5744
1559.01	43.8295
1562.11	44.743
1565.2	46.6464
1568.29	49.9399
1571.39	51.7356
1574.48	54.1062
1577.57	56.0794
1580.66	58.9792
1583.75	60.6204
1586.84	60.7521
1589.93	58.9651
1593.01	58.0704
1596.1	58.2231
1599.18	57.0359
1602.26	55.5951
1605.34	54.7066
1608.42	53.7512
1611.5	52.0723
1614.58	50.9195
1617.65	49.8697
1620.73	50.5123
1623.8	52.7561
1626.87	54.6204
1629.95	57.9293
1633.02	59.3733
1636.09	62.488
1639.15	66.1565
1642.22	71.371
1645.29	74.7026
1648.35	77.217
1651.42	80.9468
1654.48	82.479
1657.54	82.4472
1660.6	81.2746
1663.66	80.9594
1666.72	79.0857
1669.77	75.3544
1672.83	71.6268
1675.88	66.1355
1678.93	60.0225
1681.99	54.1583
1685.04	47.173
1688.09	39.3763
1691.13	32.8112
1694.18	26.8831
1697.23	21.9042
1700.27	17.4669
1703.32	13.6275
1706.36	10.5685
1709.4	8.37077
1712.44	6.51311
1715.48	5.01673
1718.52	3.81298
1721.56	2.2929
1724.59	2.06241
1727.63	1.23262
1730.66	-0.0141806
1733.69	-0.208547
1736.72	0.377822
1739.75	0.868108
1742.78	0.519255
1745.81	-0.158109
1748.84	-0.78425
1751.86	-0.91698
1754.89	-1.48122
1757.91	-1.37418
1760.93	-2.14829
1763.95	-2.54739
1766.97	-2.28153
1769.99	-1.61271
1773.01	-1.01159
1776.03	-1.42354
1779.04	-0.964963
1782.06	-0.0429108
1785.07	0.410007
1788.08	1.49152
1791.09	1.58541
1794.1	2.17396
1797.11	2.52883
1800.12	3.26689
1803.12	3.5196
1806.13	4.27445
1809.13	5.07252
1812.14	5.49273
1815.14	6.41292
1818.14	6.10758
1821.14	5.94625
1824.14	6.84104
1827.13	7.08135
1830.13	7.38879
1833.12	7.77503
1836.12	8.2483
1839.11	8.17039
1842.1	9.07856
1845.09	10.3079
1848.08	10.7652
1851.07	10.2958
1854.06	10.99
1857.04	10.807
1860.03	10.1895
1863.01	9.15809
1866	8.25618
1868.98	8.52894
1871.96	8.38413
1874.94	7.88169
1877.92	7.4056
1880.89	8.09145
1882.48	7.71194
1885.47	7.71194
1888.46	7.68806
1891.44	7.28737
1894.43	6.85633
1897.41	8.63184
1900.4	7.80898
1903.38	8.08858
1906.36	7.99639
1909.34	8.81723
1912.32	9.7503
1915.29	11.2781
1918.27	11.9607
1921.25	11.5352
1924.22	11.9984
1927.2	11.6177
1930.17	11.9714
1933.14	10.8169
1936.11	10.9784
1939.08	10.8167
1942.05	10.735
1945.01	11.0062
1947.98	10.6536
1950.94	10.3496
1953.91	10.6853
1956.87	9.60283
1959.83	9.86699
1962.79	8.8443
1965.75	8.81352
1968.71	9.0558
1971.67	9.38692
1974.62	9.34858
1977.58	10.3231
1980.53	10.6724
1983.48	12.1805
1986.43	12.4378
1989.38	13.0382
1992.33	14.0123
1995.28	14.1589
1998.23	14.5364
2001.18	15.3217
2004.12	15.7891
2007.06	16.182
2010.01	16.4956
2012.95	17.0705
2015.89	17.7551
2018.83	16.8227
2021.77	16.6133
2024.71	17.3892
2027.64	17.5547
2030.58	17.6927
2033.51	17.2454
2036.45	16.705
2039.38	17.4983
2042.31	17.771
2045.24	17.8176
2048.17	17.8353
2051.1	17.3634
2054.02	17.1941
2056.95	17.5751
2059.87	17.6674
2062.8	17.5134
2065.72	17.6797
2068.64	18.3685
2071.56	19.0498
2074.48	19.4252
2077.4	20.2961
2080.31	21.3985
2083.23	23.4456
2086.14	25.0274
2089.06	26.1946
2091.97	27.114
2094.88	28.9361
2097.79	30.8202
2100.7	31.8048
2103.61	33.6255
2106.52	35.3486
2109.43	37.6668
2112.33	39.1822
2115.24	40.2784
2118.14	43.1986
2121.04	45.3899
2123.94	47.5052
2126.84	51.0085
2129.74	54.1286
2132.64	56.7085
2135.54	60.1154
2138.43	63.752
2141.33	66.9268
2144.22	69.5039
2147.11	73.2748
2150.01	76.7569
2152.9	80.1209
2155.79	83.5262
2158.67	85.8848
2161.56	87.2602
2164.45	89.5871
2167.33	91.545
2170.22	93.1103
2173.1	93.5818
2175.98	93.817
2178.86	93.3863
2181.74	91.7021
2184.62	90.6073
2187.5	89.7685
2190.38	88.1526
2193.25	85.5859
2196.13	82.9326
2199	80.6387
2201.88	76.8409
2204.75	73.5809
2207.62	69.5519
2210.49	65.1804
2213.36	61.1251
2216.22	56.8057
2219.09	53.4506
2221.96	49.5437
2224.82	45.9141
2227.68	41.7031
2230.55	37.9952
2233.41	35.7604
2236.27	33.9242
2239.12	31.7761
2241.98	30.064
2244.84	28.674
2247.7	27.2429
2250.55	25.6835
2253.41	25.1822
2256.26	25.9834
2259.11	25.8339
2261.96	26.2136
2264.81	26.0764
2267.66	25.8311
2270.51	25.2531
2273.35	24.3458
2276.2	24.0053
2279.04	23.0005
2281.89	22.9146
2284.73	22.2997
2287.57	21.8734
2290.41	19.8773
2293.25	18.1865
2296.09	16.8833
2298.93	15.2706
2301.76	15.7501
2304.6	16.2135
2307.44	16.1257
2310.27	15.6949
2313.1	15.8046
2315.93	14.4595
2318.76	14.2394
2321.59	14.1768
2324.42	14.7153
2327.25	14.6136
2330.07	14.2484
2332.9	13.8247
2335.72	13.945
2338.55	11.9477
2341.37	11.2775
2344.19	10.4726
2347.01	10.2165
2349.83	9.11804
2352.65	8.10762
2355.46	6.8339
2358.28	6.66911
2361.09	6.00751
2363.91	5.15803
2366.72	5.74787
2369.53	5.88945
2372.34	5.80735
2375.15	6.07514
2377.96	6.04945
2380.77	5.81077
2383.58	5.65514
2386.38	5.67915
2389.19	6.06385
2391.99	6.01725
2394.8	6.25834
2397.6	5.91959
2400.4	6.48842
2403.2	7.46937
2406	6.87691
2408.79	6.51156
2411.59	7.19531
2414.39	7.27748
2417.18	7.50728
2419.98	7.60598
2422.77	8.04405
2425.56	9.66206
2428.35	10.9758
2431.14	9.92586
2433.93	11.0293
2436.72	10.5167
2439.5	9.55038
2442.29	9.70288
2445.07	9.15859
2447.86	8.6862
2450.64	7.79099
2453.42	7.43309
2456.2	6.74023
2458.98	5.89858
2461.76	6.13942
2464.54	5.82947
2467.32	5.015
2470.09	5.08215
2472.87	4.42566
2475.64	3.56563
2478.41	3.84335
2481.18	3.10592
2483.95	2.78651
2486.72	2.64294
2489.49	2.80509
2492.26	3.34054
2495.03	4.19164
2497.79	4.12292
2500.56	4.2182
2503.32	4.04364
2506.09	4.62463
2508.85	4.2924
2511.61	4.1762
2514.37	3.77596
2517.13	3.06557
2519.89	2.13285
2522.64	1.67183
2525.4	1.51549
2528.15	1.09617
2530.91	0.895998
2533.66	1.36955
2536.41	1.96273
2539.16	1.50258
2541.91	1.65063
2544.66	1.40412
2547.41	2.11363
2550.16	3.12126
2552.9	3.64887
2555.65	4.96539
2558.39	5.55312
2561.13	5.523
2563.88	6.48388
2566.62	7.13386
2569.36	7.89714
2572.1	8.12424
2574.84	6.85811
2577.57	6.00471
2580.31	5.54131
2583.05	5.01358
2585.78	4.21212
2588.51	3.86292
2591.24	3.49669
2593.98	1.61657
2596.71	0.956172
2599.44	1.06754
2602.16	0.902509
2604.89	-0.233805
2607.62	-1.03172
2610.34	-1.4488
2613.07	-1.94888
2615.79	-1.11658
2618.52	-1.78887
2621.24	-1.56178
2623.96	-1.82754
2626.68	-1.8489
2629.4	-2.0791
2632.11	-1.69046
2634.83	-1.66981
2637.55	-1.36986
2640.26	-1.20208
2642.98	-1.01819
2645.69	1.04892
2648.4	1.5327
2651.11	1.74697
2653.82	1.45326
2656.53	1.3329
2659.24	1.58296
2661.95	3.13788
2664.65	3.28105
2667.36	4.53206
2670.06	4.85539
2672.76	5.0842
2675.47	6.4276
2678.17	6.24301
2680.87	6.37444
2683.57	6.4537
2686.27	6.19726
2688.97	6.11976
2691.66	5.66272
2694.36	6.07027
2697.05	6.49919
2699.75	7.3014
2702.44	8.57466
2705.13	8.15976
2707.82	7.73558
2710.51	8.68425
2713.2	8.66927
2715.89	8.41469
2718.57	8.94488
2721.26	8.98761
2723.95	8.92778
2726.63	9.8231
2729.31	10.1122
2732	9.35826
2734.68	9.98755
2737.36	10.4794
2740.04	10.9588
2742.72	10.421
2745.39	9.01418
2748.07	8.43358
2750.75	7.73305
2753.42	6.50647
2756.09	4.96845
2758.77	4.24307
2761.44	5.22356
2764.11	4.95758
2766.78	4.68333
2769.45	4.04981
2772.12	3.3157
2774.78	3.56991
2777.45	3.58586
2780.12	3.74342
2782.78	4.09775
2785.44	4.3094
2788.11	3.56613
2790.77	4.10184
2793.43	4.51832
2796.09	5.56924
2798.75	5.06004
2801.4	5.79844
2804.06	5.63849
2806.72	4.86887
2809.37	5.04092
2812.03	4.21502
2814.68	4.12484
2817.33	4.03287
2819.98	5.25163
2822.63	8.48092
2825.28	13.1154
2827.93	18.0233
2830.58	22.1324
2833.23	27.1531
2835.87	32.5653
2838.52	38.1465
2841.16	44.699
2843.8	52.285
2846.44	60.9913
2849.08	70.4262
2851.73	80.7316
2854.36	90.5991
2857	100.468
2859.64	109.344
2862.28	117.671
2864.91	125.066
2867.55	132.824
2870.18	138.702
2872.81	145.058
2875.44	149.87
2878.07	153.648
2880.7	157.944
2883.33	162.71
2885.96	168.053
2888.59	173.002
2891.21	178.447
2893.84	183.186
2896.46	188.437
2899.09	195.063
2901.71	202.278
2904.33	211.732
2906.95	222.272
2909.57	234.592
2912.19	247.863
2914.81	260.493
2917.43	272.113
2920.04	281.65
2922.66	289.757
2925.27	296.274
2927.88	300.889
2930.5	302.014
2933.11	302.529
2935.72	300.661
2938.33	296.084
2940.94	289.409
2943.54	281.393
2946.15	272.494
2948.76	263.176
2951.36	252.139
2953.97	241.155
2956.57	230.057
2959.17	217.879
2961.77	206.992
2964.37	197.24
2966.97	187.663
2969.57	178.956
2972.17	170.194
2974.77	162.544
2977.36	154.038
2979.96	145.691
2982.55	136.14
2985.15	127.111
2987.74	117.21
2990.33	107.675
2992.92	97.7186
2995.51	89.3119
2998.1	81.3071
3000.69	72.9723
3003.27	65.6282
3005.86	59.136
3008.44	52.7638
3011.03	46.9403
3013.61	41.5385
3016.19	36.7276
3018.78	33.4763
3021.36	29.6683
3023.94	28.5226
3026.51	27.1318
3029.09	26.5392
3031.67	25.4933
3034.24	25.8001
3036.82	26.104
3039.39	26.5451
3041.97	27.1416
3044.54	27.5517
3047.11	27.7815
3049.68	27.7694
3052.25	28.0331
3054.82	27.8033
3057.39	27.6637
3059.96	27.5415
3062.52	27.0847
3065.09	25.8585
3067.65	24.4611
3070.22	22.6088
3072.78	20.7368
3075.34	18.781
3077.9	16.6685
3080.46	14.9282
3083.02	12.9673
3085.58	11.724
3088.14	10.3215
3090.69	8.91392
3093.25	7.87055
3095.8	7.00607
3098.36	5.80957
3100.91	5.82107
3103.46	5.33165
3106.01	4.57878
3108.56	3.78697
3111.11	3.22553
3113.66	2.72227
3116.21	2.33975
3118.76	2.21087
3121.3	2.2951
3123.85	1.83521
3126.39	1.70138
3128.93	0.740491
3131.48	-0.263386
3134.02	-0.193011
3136.56	-0.424113
3139.1	-0.774545
3141.64	-0.806149
3144.17	-0.482463
3146.71	-0.00715339
3149.25	1.39753