File: data/Raman/poly_smoothed/Thy_30_10_32_1x_45s_532 nm_x100_100%_600 gr_mm_01.txt
#Acq. time (s)=	45
#Accumulations=	2
#Range (cm-¹)=	200...3150
#Windows=	2
#Auto scanning=	Off
#Autofocus=	Off
#Macrospot=	Off
#AutoExposure=	Off
#Spike filter=	Multiple accum.
#Delay time (s)=	0
#Binning=	1
#Readout mode=	Signal
#DeNoise=	Off
#ICS correction=	On
#Dark correction=	Off
#Inst. Process=	Off
#Detector Gain=	Best Dynamic Range
#Detector ADC=	20 kHz
#Detector temperature (°C)=	-69.85
#Instrument=	LabRAM HR Evol
#Detector=	Synapse
#Objective=	x100
#Grating=	600 gr/mm
#ND Filter=	100%
#Laser (nm)=	532
#Hole=	100.021
#Range=	Auto
#Laser Pol.=	No
#Raman. Pol.=	No
#Laser Pol. (°)=	-0.0007625
#Raman Pol. (°)=	89.9995
#Collection=	Microscope
#StageXY=	Marzhauser
#StageZ=	Marzhauser
#X (µm)=	4755
#Y (µm)=	-7706.9
#Z (µm)=	584.4
#Full time(mm:ss)=	3:08
#Project=
#Sample=
#Site=
#Title=	Thy_30_10_32_2x_45s_532 nm_x100_100%_600 gr_mm
#Remark=
#Date=	30.06.2022 13:45
#Acquired=	30.06.2022 13:45:54
#Base:Fit=	10.08.2022 09:58:11
#Base:Sub=	10.08.2022 09:58:44
#Filter:Polynom=	16.08.2022 10:22:53
#AxisType[0]=Intens
#AxisUnit[0]=Cnt
#AxisType[1]=Spectr
#AxisUnit[1]=1/cm
200.533	9.90937
204.162	8.9069
207.792	8.81709
211.418	8.15484
215.044	8.77691
218.667	10.038
222.289	10.3317
225.912	9.9765
229.531	8.45226
233.148	8.40474
236.766	7.59735
240.381	7.63343
243.994	6.5672
247.606	6.11275
251.217	6.9174
254.828	5.63573
258.436	6.13422
262.042	6.07175
265.647	5.4622
269.25	6.58048
272.852	7.47361
276.453	7.67138
280.052	9.10226
283.65	9.719
287.247	11.8823
290.842	11.6282
294.436	12.3275
298.028	12.9545
301.617	14.8502
305.206	15.0087
308.794	15.0469
312.381	13.8143
315.964	13.1346
319.548	12.9985
323.131	12.5668
326.71	11.7775
330.29	11.2668
333.868	10.7893
337.443	10.9174
341.018	9.41412
344.591	7.92139
348.163	6.4067
351.733	6.05611
355.303	6.78272
358.869	5.82532
362.435	5.40482
366.001	5.77966
369.563	4.81841
373.124	3.14017
376.686	3.46122
380.244	2.43136
383.801	3.32749
387.357	2.92318
390.911	2.34837
394.466	1.74822
398.018	2.17266
401.568	1.35008
405.117	2.01262
408.664	0.879272
412.21	0.84444
415.755	0.697231
419.298	1.94429
422.84	2.72191
426.38	2.39586
429.919	2.98265
433.455	3.32483
436.992	4.30165
440.527	3.75627
444.06	4.719
447.593	5.55932
451.122	5.71272
454.651	5.43704
458.18	6.19778
461.705	7.87411
465.23	8.84085
468.752	9.09719
472.275	9.56114
475.797	10.3967
479.315	11.6114
482.834	11.9789
486.349	12.2617
489.863	12.3516
493.378	12.7821
496.889	12.125
500.401	12.9051
503.91	14.5512
507.417	16.3523
510.923	15.2283
514.43	14.7318
517.933	14.3674
521.435	13.9936
524.936	13.4262
528.435	12.1528
531.933	10.7875
535.43	10.3928
538.927	9.65061
542.421	8.71674
545.913	8.41265
549.403	7.00655
552.893	7.07534
556.381	6.32437
559.868	5.69541
563.354	5.36111
566.839	5.40217
570.322	5.3132
573.802	4.59991
577.283	4.54848
580.762	4.72439
584.24	5.08656
587.714	5.07912
591.19	3.80321
594.663	2.28634
598.134	1.19498
601.605	2.07058
605.073	2.36772
608.542	3.16233
612.007	4.69194
615.473	6.12819
618.936	8.07197
622.397	8.65629
625.859	8.60194
629.318	8.79857
632.775	8.87513
636.233	10.0378
639.688	9.78877
643.142	9.30872
646.594	10.5036
650.045	12.2042
653.496	13.2403
656.944	12.9468
660.391	14.5724
663.837	14.3602
667.281	13.6043
670.724	13.3247
674.166	13.7865
677.606	14.5763
681.045	15.7023
684.483	17.5151
687.917	20.0279
691.352	22.9735
694.786	25.2836
698.219	27.7186
701.65	29.6979
705.078	31.2746
708.506	34.1718
711.934	36.2135
715.358	38.7143
718.782	40.1252
722.204	40.0515
725.626	40.9292
729.045	41.9307
732.464	43.4503
735.881	44.5351
739.297	45.8723
742.711	47.4147
746.125	50.3219
749.537	51.576
752.946	54.7063
756.357	56.6501
759.764	58.7829
763.17	60.9896
766.575	61.4419
769.978	63.5667
773.382	65.0079
776.783	67.125
780.182	67.8243
783.581	69.0111
786.978	70.876
790.373	72.8695
793.768	74.379
797.161	74.1544
800.552	75.0695
803.941	75.1165
807.33	74.9936
810.718	74.9265
814.105	75.2495
817.49	76.1403
820.873	78.314
824.256	81.2778
827.637	82.8994
831.016	83.1323
834.395	82.893
837.772	81.878
841.147	80.1011
844.522	78.9486
847.894	76.1502
851.267	73.9884
854.637	71.8382
858.007	68.5177
861.374	65.0356
864.739	63.2976
868.106	61.8231
871.469	61.2089
874.831	59.5202
878.193	57.4531
881.553	56.3194
884.911	56.9419
888.268	55.1958
891.623	53.4591
894.978	54.1171
898.331	54.5585
901.683	54.1055
905.033	54.6777
908.383	53.7866
911.731	51.9649
915.078	51.0515
918.423	51.714
921.768	50.6215
925.111	49.4849
928.452	48.0628
931.791	45.7221
935.13	44.5643
938.468	44.0464
941.803	41.7104
945.139	41.5204
948.473	41.283
951.804	40.7997
955.136	39.8313
958.465	38.419
961.794	37.5212
965.12	39.7202
968.447	39.8636
971.771	39.9184
975.095	40.1367
978.417	42.2491
981.737	42.6015
985.057	43.1609
988.375	44.2387
991.691	44.846
995.006	45.2821
998.32	46.3129
1001.63	44.9678
1004.95	43.7765
1008.26	43.1926
1011.56	41.6272
1014.87	40.8623
1018.18	40.2249
1021.48	38.6164
1024.79	36.4799
1028.09	35.8975
1031.39	34.8651
1034.69	33.0905
1037.99	29.6495
1041.29	27.9856
1044.58	26.7776
1047.88	25.7566
1051.17	25.3748
1054.46	24.2503
1057.75	23.2372
1061.04	22.5024
1064.33	21.3099
1067.62	20.5414
1070.9	20.9404
1074.19	20.9723
1077.47	21.3794
1080.76	22.6492
1084.04	22.5585
1087.32	23.2054
1090.59	24.4942
1093.87	26.1238
1097.15	28.4402
1100.42	29.5712
1103.69	30.8931
1106.97	33.1167
1110.24	34.7731
1113.51	35.7631
1116.77	35.2883
1120.04	32.5944
1123.31	31.2966
1126.57	30.2931
1129.83	29.1252
1133.1	25.6806
1136.36	23.6464
1139.62	21.7554
1142.87	20.0732
1146.13	17.5559
1149.38	14.8913
1152.64	14.6029
1155.89	14.0741
1159.14	11.497
1162.39	9.52886
1165.64	8.43226
1168.89	8.46019
1172.14	10.5158
1175.38	11.6159
1178.63	11.966
1181.87	14.4151
1185.11	15.7317
1188.35	18.3923
1191.59	20.4637
1194.83	22.5375
1198.07	23.4664
1201.3	24.9234
1204.53	26.6004
1207.77	29.0867
1211	31.6314
1214.23	35.4579
1217.46	39.5474
1220.69	42.6924
1223.91	46.9719
1227.14	51.4892
1230.36	55.7341
1233.59	58.6615
1236.81	60.7847
1240.03	63.4095
1243.25	67.3837
1246.46	69.9201
1249.68	72.5387
1252.9	73.217
1256.11	74.1182
1259.32	75.7593
1262.54	76.9089
1265.75	77.1991
1268.96	78.1817
1272.16	77.656
1275.37	76.7943
1278.57	76.8349
1281.78	77.7821
1284.98	77.8447
1288.18	78.7995
1291.38	79.5245
1294.58	79.8989
1297.78	80.3595
1300.98	82.159
1304.17	84.3438
1307.37	85.8045
1310.56	86.0394
1313.76	87.0385
1316.95	88.3909
1320.14	88.8316
1323.32	89.3251
1326.51	88.6849
1329.7	87.9267
1332.88	86.6973
1336.07	85.0229
1339.25	84.3052
1342.43	82.6293
1345.61	81.3544
1348.79	79.9814
1351.96	77.9198
1355.14	74.8942
1358.31	74.6628
1361.49	72.6482
1364.66	69.6336
1367.83	67.446
1371	64.3969
1374.17	62.6446
1377.34	60.5071
1380.5	58.2758
1383.67	55.9835
1386.83	52.4257
1390	48.8155
1393.16	46.5546
1396.32	45.3716
1399.48	44.3166
1402.64	42.0408
1405.79	40.2561
1408.95	40.3473
1412.1	40.5369
1415.26	42.0908
1418.41	45.388
1421.56	49.417
1424.71	53.7926
1427.86	57.9655
1431	61.3364
1434.15	66.9035
1437.29	70.8939
1440.44	74.3366
1443.58	77.529
1446.72	79.9211
1449.86	81.5092
1453	80.5241
1456.14	79.813
1459.27	77.1164
1462.41	73.8302
1465.54	70.1047
1468.67	66.7538
1471.81	61.5806
1474.94	55.8853
1478.07	50.312
1481.19	44.7815
1484.32	39.7804
1487.45	35.906
1490.57	31.6058
1493.69	29.8204
1496.82	27.6906
1499.94	26.73
1503.06	25.6355
1506.17	23.7362
1509.29	21.6904
1512.41	23.8821
1515.52	22.6568
1518.64	24.1525
1521.75	25.8541
1524.86	27.8303
1527.97	29.1586
1531.08	31.0037
1534.19	33.8009
1537.29	36.0042
1540.4	38.3806
1543.5	40.9245
1546.61	44.0986
1549.71	48.0175
1552.81	51.4046
1555.91	55.1784
1559.01	59.3404
1562.11	62.6785
1565.2	66.0359
1568.29	69.3254
1571.39	70.9556
1574.48	73.3641
1577.57	76.189
1580.66	76.9143
1583.75	76.7743
1586.84	76.8967
1589.93	76.6847
1593.01	75.4978
1596.1	76.0012
1599.18	73.9088
1602.26	71.9933
1605.34	70.1732
1608.42	68.733
1611.5	67.4723
1614.58	66.4601
1617.65	66.4587
1620.73	67.8572
1623.8	69.8451
1626.87	72.1467
1629.95	74.479
1633.02	76.4239
1636.09	79.4861
1639.15	81.7735
1642.22	84.38
1645.29	86.4706
1648.35	89.9636
1651.42	92.9555
1654.48	94.6055
1657.54	94.0993
1660.6	93.1528
1663.66	90.7914
1666.72	86.8907
1669.77	82.6701
1672.83	79.4937
1675.88	74.5268
1678.93	68.3954
1681.99	62.3985
1685.04	56.3636
1688.09	50.0943
1691.13	44.7567
1694.18	39.5014
1697.23	34.4981
1700.27	30.4225
1703.32	25.2614
1706.36	22.2088
1709.4	17.6562
1712.44	15.5336
1715.48	13.6135
1718.52	11.5382
1721.56	10.8427
1724.59	10.3173
1727.63	8.62903
1730.66	8.10565
1733.69	6.32911
1736.72	4.21522
1739.75	3.13453
1742.78	2.1397
1745.81	2.50708
1748.84	2.20694
1751.86	0.546925
1754.89	-0.595502
1757.91	-0.743487
1760.93	-1.51497
1763.95	-2.14134
1766.97	-1.79254
1769.99	-1.8717
1773.01	-1.84427
1776.03	-1.85342
1779.04	-0.400358
1782.06	1.57662
1785.07	1.49719
1788.08	2.28114
1791.09	3.27453
1794.1	2.77998
1797.11	2.90094
1800.12	3.72007
1803.12	3.20348
1806.13	2.69261
1809.13	2.5234
1812.14	2.38731
1815.14	2.94762
1818.14	2.91443
1821.14	2.87863
1824.14	2.39964
1827.13	1.83426
1830.13	1.85631
1833.12	1.54055
1836.12	1.20271
1839.11	1.52527
1842.1	2.27441
1845.09	2.18306
1848.08	2.22215
1851.07	2.66778
1854.06	3.22853
1857.04	2.94618
1860.03	2.54489
1863.01	1.26598
1866	0.940788
1868.98	0.854827
1871.96	1.4636
1874.94	2.18512
1877.92	2.03215
1880.89	2.96485
1882.48	2.53494
1885.47	3.18875
1888.46	4.18924
1891.44	5.14528
1894.43	5.87396
1897.41	7.0612
1900.4	7.62196
1903.38	8.03501
1906.36	8.4269
1909.34	9.18548
1912.32	10.4147
1915.29	10.7183
1918.27	10.445
1921.25	10.2944
1924.22	10.6409
1927.2	9.696
1930.17	8.9364
1933.14	7.86324
1936.11	7.49622
1939.08	7.73624
1942.05	7.70589
1945.01	7.20513
1947.98	6.3497
1950.94	5.3868
1953.91	5.15529
1956.87	4.66066
1959.83	3.75568
1962.79	2.82047
1965.75	2.76186
1968.71	2.69896
1971.67	1.65858
1974.62	1.86572
1977.58	2.7915
1980.53	3.66315
1983.48	4.71962
1986.43	5.5006
1989.38	5.93536
1992.33	7.61234
1995.28	8.32995
1998.23	8.90327
2001.18	10.1541
2004.12	11.6071
2007.06	11.7712
2010.01	13.2569
2012.95	13.2551
2015.89	13.0383
2018.83	13.4416
2021.77	13.9039
2024.71	13.2896
2027.64	12.6053
2030.58	11.0294
2033.51	10.6573
2036.45	10.7996
2039.38	11.3169
2042.31	11.3771
2045.24	11.1683
2048.17	12.5852
2051.1	12.4917
2054.02	12.161
2056.95	13.6244
2059.87	14.328
2062.8	15.3499
2065.72	16.4073
2068.64	17.6079
2071.56	19.0305
2074.48	19.9054
2077.4	20.0397
2080.31	19.315
2083.23	20.9516
2086.14	21.7363
2089.06	22.6223
2091.97	24.5617
2094.88	25.602
2097.79	26.0483
2100.7	26.6711
2103.61	27.5262
2106.52	28.5943
2109.43	29.6398
2112.33	30.3165
2115.24	32.1864
2118.14	33.6046
2121.04	35.2651
2123.94	37.9109
2126.84	40.8945
2129.74	42.9153
2132.64	46.2568
2135.54	48.7604
2138.43	52.4134
2141.33	55.2641
2144.22	57.2776
2147.11	59.9107
2150.01	62.7863
2152.9	66.8757
2155.79	71.1185
2158.67	73.8979
2161.56	76.46
2164.45	79.146
2167.33	80.4412
2170.22	80.5446
2173.1	81.2169
2175.98	81.2694
2178.86	80.3565
2181.74	79.5723
2184.62	78.1712
2187.5	77.2769
2190.38	74.0009
2193.25	71.919
2196.13	69.6203
2199	66.5465
2201.88	64.0743
2204.75	60.6207
2207.62	56.3693
2210.49	52.6305
2213.36	49.4856
2216.22	45.9548
2219.09	44.1105
2221.96	41.4422
2224.82	39.2975
2227.68	36.8724
2230.55	34.9712
2233.41	32.7858
2236.27	31.0508
2239.12	30.0593
2241.98	29.3563
2244.84	28.2298
2247.7	27.5102
2250.55	27.4976
2253.41	26.5378
2256.26	25.6308
2259.11	25.208
2261.96	25.1848
2264.81	24.1886
2267.66	23.3405
2270.51	22.8572
2273.35	22.174
2276.2	21.4071
2279.04	21.3813
2281.89	19.9239
2284.73	18.7017
2287.57	17.9322
2290.41	16.7748
2293.25	15.0762
2296.09	13.9616
2298.93	13.8766
2301.76	13.6253
2304.6	12.5034
2307.44	12.6887
2310.27	13.0739
2313.1	13.2849
2315.93	13.5847
2318.76	14.6796
2321.59	13.0625
2324.42	13.0115
2327.25	12.5736
2330.07	12.391
2332.9	12.0767
2335.72	10.6683
2338.55	9.74759
2341.37	10.0713
2344.19	9.33232
2347.01	9.01611
2349.83	8.0511
2352.65	7.24137
2355.46	6.82023
2358.28	6.33666
2361.09	6.05433
2363.91	5.55693
2366.72	6.8101
2369.53	6.28948
2372.34	6.51044
2375.15	7.76207
2377.96	8.62528
2380.77	8.87412
2383.58	9.47542
2386.38	9.96841
2389.19	10.4877
2391.99	9.79471
2394.8	9.81483
2397.6	9.7422
2400.4	9.29016
2403.2	9.1756
2406	9.05344
2408.79	9.21594
2411.59	8.84577
2414.39	9.09344
2417.18	10.1156
2419.98	9.62672
2422.77	9.13041
2425.56	8.16566
2428.35	7.2483
2431.14	7.21783
2433.93	7.02515
2436.72	6.49562
2439.5	6.6604
2442.29	7.00741
2445.07	7.3124
2447.86	6.45311
2450.64	6.09369
2453.42	5.73832
2456.2	5.27603
2458.98	4.48212
2461.76	3.79058
2464.54	4.09771
2467.32	4.53572
2470.09	4.41717
2472.87	4.67786
2475.64	4.42143
2478.41	2.94005
2481.18	3.30412
2483.95	3.86102
2486.72	3.81032
2489.49	3.87672
2492.26	4.91297
2495.03	4.87218
2497.79	5.27373
2500.56	4.94986
2503.32	5.23829
2506.09	5.29096
2508.85	5.65103
2511.61	5.53197
2514.37	4.96539
2517.13	3.19263
2519.89	2.68589
2522.64	2.09956
2525.4	0.575207
2528.15	-0.322436
2530.91	-0.359235
2533.66	-0.492539
2536.41	-0.915813
2539.16	-1.83309
2541.91	-1.60616
2544.66	-2.38877
2547.41	-1.6287
2550.16	0.49674
2552.9	1.60558
2555.65	3.63941
2558.39	5.0682
2561.13	6.25178
2563.88	6.92651
2566.62	7.37539
2569.36	7.91533
2572.1	8.69386
2574.84	8.84246
2577.57	8.55954
2580.31	7.86713
2583.05	7.29729
2585.78	7.44276
2588.51	6.34685
2591.24	5.37421
2593.98	4.53328
2596.71	4.80501
2599.44	4.48081
2602.16	4.39765
2604.89	3.4144
2607.62	2.99134
2610.34	3.06487
2613.07	3.2757
2615.79	4.2166
2618.52	4.58912
2621.24	4.81462
2623.96	4.73595
2626.68	5.40845
2629.4	5.65282
2632.11	5.40571
2634.83	5.27217
2637.55	5.78089
2640.26	5.73498
2642.98	5.91809
2645.69	5.30159
2648.4	5.02587
2651.11	5.39309
2653.82	4.87663
2656.53	3.80919
2659.24	3.62477
2661.95	3.41749
2664.65	3.76787
2667.36	3.80337
2670.06	3.46489
2672.76	2.69028
2675.47	3.42734
2678.17	3.67988
2680.87	3.33087
2683.57	2.66915
2686.27	1.687
2688.97	0.47896
2691.66	0.942734
2694.36	1.20519
2697.05	1.73933
2699.75	2.60858
2702.44	3.76051
2705.13	4.72964
2707.82	5.05424
2710.51	5.4597
2713.2	5.62971
2715.89	7.20202
2718.57	7.98085
2721.26	9.02041
2723.95	10.2879
2726.63	11.6126
2729.31	12.7552
2732	13.5405
2734.68	13.8292
2737.36	13.8094
2740.04	14.0228
2742.72	13.542
2745.39	12.3402
2748.07	11.1272
2750.75	10.2666
2753.42	9.99338
2756.09	9.98986
2758.77	10.756
2761.44	10.7503
2764.11	10.8797
2766.78	9.8764
2769.45	8.89722
2772.12	8.24854
2774.78	7.53101
2777.45	7.05306
2780.12	7.54065
2782.78	7.20685
2785.44	6.89272
2788.11	6.25863
2790.77	6.15871
2793.43	6.20266
2796.09	6.53397
2798.75	6.37241
2801.4	5.9458
2804.06	6.61732
2806.72	6.61636
2809.37	7.39499
2812.03	7.86111
2814.68	9.21906
2817.33	11.0042
2819.98	12.4305
2822.63	14.5695
2825.28	17.5074
2827.93	20.3768
2830.58	23.6513
2833.23	27.036
2835.87	30.9865
2838.52	35.3573
2841.16	39.9512
2843.8	45.0094
2846.44	51.0217
2849.08	57.8112
2851.73	64.6306
2854.36	73.5268
2857	82.1044
2859.64	90.2796
2862.28	98.281
2864.91	105.628
2867.55	113.003
2870.18	119.498
2872.81	124.995
2875.44	129.483
2878.07	134.706
2880.7	138.706
2883.33	143.187
2885.96	147.274
2888.59	152.186
2891.21	157.09
2893.84	162.376
2896.46	167.52
2899.09	173.63
2901.71	179.165
2904.33	187.074
2906.95	196.418
2909.57	207.849
2912.19	220.257
2914.81	231.729
2917.43	244.396
2920.04	254.356
2922.66	263.756
2925.27	270.894
2927.88	275.935
2930.5	278.674
2933.11	280.362
2935.72	278.738
2938.33	276.721
2940.94	272.271
2943.54	267.015
2946.15	259.976
2948.76	250.461
2951.36	241.48
2953.97	231.706
2956.57	222.38
2959.17	211.368
2961.77	201.35
2964.37	191.226
2966.97	181.592
2969.57	174.325
2972.17	165.403
2974.77	157.824
2977.36	149.487
2979.96	141.753
2982.55	132.941
2985.15	123.434
2987.74	114.717
2990.33	105.899
2992.92	95.9749
2995.51	87.1621
2998.1	79.0099
3000.69	71.4215
3003.27	65.439
3005.86	57.9305
3008.44	52.5682
3011.03	46.2385
3013.61	41.6371
3016.19	37.7774
3018.78	34.4622
3021.36	31.6259
3023.94	30.1994
3026.51	29.3587
3029.09	27.9843
3031.67	28.1788
3034.24	28.3581
3036.82	29.3843
3039.39	31.258
3041.97	33.1691
3044.54	34.2877
3047.11	35.2416
3049.68	35.8578
3052.25	35.101
3054.82	35.3021
3057.39	34.8757
3059.96	34.6914
3062.52	33.2044
3065.09	31.4684
3067.65	29.8763
3070.22	27.9038
3072.78	25.7481
3075.34	23.2223
3077.9	20.6765
3080.46	18.1614
3083.02	15.8427
3085.58	14.2521
3088.14	12.5502
3090.69	10.5362
3093.25	9.30426
3095.8	8.76776
3098.36	8.81488
3100.91	8.97319
3103.46	8.78689
3106.01	8.7834
3108.56	8.31207
3111.11	7.66151
3113.66	7.01158
3116.21	6.38286
3118.76	6.06392
3121.3	5.30541
3123.85	4.59281
3126.39	4.40155
3128.93	3.90478
3131.48	3.56594
3134.02	3.26849
3136.56	2.30202
3139.1	1.1219
3141.64	0.386771
3144.17	-0.19713
3146.71	-0.462295
3149.25	-0.202776