File: data/Raman/poly_smoothed/Thy_40_11_28_1x_45s_532 nm_x100_100%_600 gr_mm_01.txt
#Acq. time (s)=	45
#Accumulations=	2
#Range (cm-¹)=	200...3150
#Windows=	2
#Auto scanning=	Off
#Autofocus=	Off
#Macrospot=	Off
#AutoExposure=	Off
#Spike filter=	Multiple accum.
#Delay time (s)=	0
#Binning=	1
#Readout mode=	Signal
#DeNoise=	Off
#ICS correction=	On
#Dark correction=	Off
#Inst. Process=	Off
#Detector Gain=	Best Dynamic Range
#Detector ADC=	20 kHz
#Detector temperature (°C)=	-69.85
#Instrument=	LabRAM HR Evol
#Detector=	Synapse
#Objective=	x100
#Grating=	600 gr/mm
#ND Filter=	100%
#Laser (nm)=	532
#Hole=	100.021
#Range=	Auto
#Laser Pol.=	No
#Raman. Pol.=	No
#Laser Pol. (°)=	-0.0007625
#Raman Pol. (°)=	89.9995
#Collection=	Microscope
#StageXY=	Marzhauser
#StageZ=	Marzhauser
#X (µm)=	1939.4
#Y (µm)=	-44.4
#Z (µm)=	425.2
#Full time(mm:ss)=	3:19
#Project=
#Sample=
#Site=
#Title=	Thy_40_11_28_2x_45s_532 nm_x100_100%_600 gr_mm
#Remark=
#Date=	05.07.2022 11:51
#Acquired=	05.07.2022 11:51:15
#Base:Fit=	10.08.2022 10:01:35
#Base:Sub=	10.08.2022 10:01:52
#Filter:Polynom=	16.08.2022 10:21:53
#AxisType[0]=Intens
#AxisUnit[0]=Cnt
#AxisType[1]=Spectr
#AxisUnit[1]=1/cm
200.43	17.87
204.059	17.963
207.688	17.0488
211.314	15.9105
214.941	15.4671
218.564	14.4344
222.186	13.9536
225.809	13.2965
229.428	11.2632
233.045	10.3092
236.663	9.43741
240.278	9.29662
243.891	8.08967
247.503	6.82491
251.116	5.13045
254.725	6.59945
258.333	4.9315
261.939	5.70291
265.544	5.82845
269.148	6.08016
272.75	6.39689
276.351	6.79164
279.95	6.84776
283.548	5.80574
287.144	5.84113
290.739	6.2048
294.333	6.60283
297.925	8.05229
301.514	7.45682
305.104	9.6832
308.692	7.4779
312.279	6.28011
315.862	6.44712
319.446	6.69311
323.029	6.96551
326.608	7.13211
330.188	7.91838
333.766	8.50387
337.341	9.09834
340.917	9.47016
344.489	9.1075
348.062	8.87383
351.631	7.98461
355.201	6.85801
358.768	5.9171
362.333	5.39086
365.899	6.52213
369.462	6.06281
373.023	5.21315
376.585	4.40098
380.143	3.92922
383.7	4.23064
387.256	2.97308
390.812	2.99441
394.365	0.894674
397.916	1.63797
401.467	3.67096
405.015	4.78128
408.563	5.40534
412.109	6.25086
415.654	6.93583
419.197	7.90072
422.739	7.71421
426.279	7.55753
429.819	7.3956
433.356	6.59477
436.891	6.85544
440.426	5.38977
443.96	6.14534
447.492	6.4624
451.021	7.45145
454.551	7.28142
458.079	7.72129
461.604	9.16615
465.13	10.8154
468.654	12.5216
472.175	15.1185
475.696	16.5761
479.215	19.0409
482.733	19.9281
486.249	22.3232
489.765	23.7398
493.278	25.1044
496.789	25.8107
500.301	25.5669
503.81	26.1699
507.317	26.337
510.825	25.7592
514.33	25.16
517.833	22.7855
521.335	21.9808
524.836	21.9869
528.335	19.669
531.835	19.0771
535.332	18.5612
538.827	16.9776
542.321	17.2619
545.814	15.8665
549.305	16.6805
552.795	17.0673
556.282	16.9214
559.769	15.5457
563.255	15.6218
566.739	15.3249
570.223	13.9037
573.705	14.6661
577.183	13.3757
580.663	12.6224
584.141	11.0415
587.615	8.85226
591.09	7.51636
594.564	5.59331
598.035	4.66398
601.506	3.71151
604.974	4.44825
608.443	4.66494
611.908	5.25937
615.374	5.71534
618.837	8.90788
622.3	11.3683
625.761	14.2471
629.219	17.629
632.677	18.7666
636.135	21.3556
639.59	24.0434
643.043	26.4943
646.495	30.4969
649.948	32.9641
653.398	33.4371
656.846	36.4822
660.293	38.3398
663.738	38.8775
667.183	39.7042
670.626	41.7092
674.067	40.6499
677.508	41.3645
680.947	41.474
684.385	42.708
687.821	42.2304
691.254	44.0697
694.688	44.8651
698.121	46.6486
701.552	48.0579
704.98	49.1451
708.409	49.1342
711.836	49.3492
715.26	49.1229
718.685	49.6325
722.108	52.0248
725.528	52.9342
728.949	54.5188
732.367	55.8028
735.785	57.63
739.2	59.9766
742.614	64.6928
746.028	65.9951
749.439	70.3566
752.849	73.6993
756.26	74.9824
759.667	76.1209
763.073	78.0277
766.477	79.4731
769.883	80.9777
773.285	83.2244
776.686	85.9552
780.085	86.7188
783.484	89.8671
786.881	90.8275
790.276	92.3213
793.671	93.468
797.064	94.3258
800.456	94.0085
803.846	94.2897
807.234	94.3352
810.622	92.4762
814.008	93.1853
817.394	91.1278
820.778	93.1367
824.159	90.8836
827.541	90.0719
830.921	88.7446
834.298	87.6827
837.676	86.0243
841.051	83.6897
844.426	81.1134
847.798	78.4083
851.171	74.9983
854.54	74.2468
857.911	72.1208
861.278	71.299
864.645	70.5687
868.01	70.6629
871.373	69.649
874.735	69.935
878.097	69.3015
881.457	68.3449
884.815	68.6167
888.172	68.7336
891.528	68.6431
894.882	68.9225
898.237	69.7547
901.589	68.2564
904.94	67.8585
908.289	66.9922
911.635	65.8685
914.982	64.1414
918.328	61.8012
921.672	61.0883
925.015	58.3526
928.357	54.3074
931.698	51.0694
935.035	50.7698
938.373	49.298
941.71	49.9136
945.044	48.1475
948.378	47.4035
951.709	47.4141
955.041	46.8827
958.372	47.3145
961.699	46.5774
965.027	48.1155
968.352	50.6303
971.676	50.3956
975	51.6347
978.322	51.9694
981.642	52.7395
984.962	51.1877
988.28	51.1072
991.596	50.7522
994.911	48.8256
998.227	47.8436
1001.54	46.4895
1004.85	45.7061
1008.16	43.5501
1011.47	43.2698
1014.78	43.4158
1018.08	43.4851
1021.39	43.292
1024.69	42.2977
1028	40.3327
1031.3	40.0859
1034.6	40.4227
1037.9	38.7971
1041.19	38.1977
1044.49	37.1955
1047.78	37.4665
1051.08	37.0353
1054.37	35.1138
1057.66	34.5707
1060.95	34.4216
1064.24	33.4415
1067.53	31.6201
1070.81	31.3514
1074.1	30.8171
1077.38	29.8802
1080.66	28.6852
1083.94	27.4203
1087.22	27.8404
1090.5	28.5047
1093.78	29.8498
1097.05	30.7405
1100.33	31.1371
1103.6	30.9516
1106.87	30.3721
1110.14	28.4501
1113.41	27.0736
1116.68	26.316
1119.95	25.7297
1123.21	25.1307
1126.48	24.5629
1129.74	23.8538
1133	22.1398
1136.26	21.7712
1139.52	21.3245
1142.78	19.0286
1146.04	19.169
1149.29	19.0891
1152.55	18.1963
1155.8	16.5146
1159.05	14.0402
1162.3	12.1189
1165.55	11.5482
1168.8	10.8936
1172.05	10.7601
1175.29	9.76349
1178.54	10.272
1181.78	9.52772
1185.02	8.8869
1188.26	8.5062
1191.5	9.30487
1194.74	8.94856
1197.97	10.4718
1201.21	12.7997
1204.44	16.5168
1207.68	19.0162
1210.91	22.7962
1214.14	24.5617
1217.37	28.1113
1220.59	32.2316
1223.82	37.0526
1227.05	42.1941
1230.27	44.939
1233.49	47.6666
1236.72	51.2999
1239.94	53.3564
1243.16	55.3675
1246.37	58.459
1249.59	60.9597
1252.8	64.3269
1256.02	66.3128
1259.23	66.3273
1262.44	67.7621
1265.66	68.3508
1268.86	68.0116
1272.07	67.0411
1275.28	67.865
1278.48	69.7768
1281.69	69.9015
1284.89	70.4126
1288.09	69.7444
1291.29	69.7344
1294.49	71.7425
1297.69	73.3489
1300.89	72.858
1304.08	73.1347
1307.28	74.1161
1310.47	74.235
1313.66	74.6026
1316.85	74.3945
1320.04	74.7282
1323.23	73.111
1326.42	73.0028
1329.61	70.9984
1332.79	70.7449
1335.97	69.1931
1339.16	67.6379
1342.34	67.314
1345.52	64.6915
1348.7	62.9131
1351.87	59.8898
1355.05	58.3506
1358.22	56.0972
1361.4	53.9718
1364.57	50.9814
1367.74	50.1778
1370.91	48.7723
1374.08	47.2265
1377.25	45.4851
1380.41	44.0995
1383.58	43.4242
1386.74	42.9364
1389.91	40.6793
1393.07	38.6099
1396.23	37.7371
1399.39	35.0837
1402.55	33.8754
1405.7	33.0878
1408.86	33.2255
1412.01	33.8882
1415.17	33.1545
1418.32	35.4813
1421.47	37.1604
1424.62	39.8563
1427.77	44.5215
1430.91	48.4119
1434.06	51.9481
1437.2	55.9978
1440.35	59.928
1443.49	64.0161
1446.63	66.7738
1449.77	69.8398
1452.91	72.0786
1456.05	71.8753
1459.18	71.8687
1462.32	69.992
1465.45	68.1462
1468.59	64.1563
1471.72	59.3298
1474.85	53.5182
1477.98	47.6095
1481.1	42.5666
1484.23	37.5129
1487.36	33.7841
1490.48	29.1662
1493.61	26.7746
1496.73	24.8344
1499.85	23.2501
1502.97	21.0853
1506.09	20.3468
1509.2	17.7945
1512.32	17.3051
1515.43	17.2056
1518.55	18.7417
1521.66	19.7332
1524.77	21.7553
1527.88	23.9259
1530.99	25.0887
1534.1	25.8742
1537.21	27.6861
1540.31	30.3257
1543.42	33.4909
1546.52	36.6196
1549.62	39.9512
1552.72	43.8764
1555.82	47.9004
1558.92	52.4312
1562.02	55.8697
1565.11	57.6374
1568.21	59.6964
1571.3	62.6774
1574.39	62.8554
1577.49	65.0586
1580.57	66.4063
1583.66	67.3752
1586.75	69.1885
1589.84	70.1396
1592.92	70.3422
1596.01	70.5107
1599.09	69.1137
1602.17	67.6754
1605.25	64.6413
1608.33	62.4044
1611.41	61.2786
1614.49	62.516
1617.57	63.035
1620.64	64.2531
1623.72	65.476
1626.79	66.4303
1629.86	66.97
1632.93	67.5444
1636	67.8818
1639.07	69.4552
1642.13	70.5419
1645.2	71.5334
1648.26	73.5946
1651.33	75.2948
1654.39	77.0514
1657.45	76.6784
1660.51	77.2859
1663.57	76.531
1666.63	73.6528
1669.68	70.1746
1672.74	66.4588
1675.79	62.5905
1678.85	57.7862
1681.9	53.4105
1684.95	48.0487
1688	43.4712
1691.05	39.415
1694.09	35.2045
1697.14	30.9223
1700.18	28.1168
1703.23	25.0356
1706.27	21.2576
1709.31	18.7002
1712.35	16.2517
1715.39	14.1785
1718.43	12.2106
1721.47	10.3899
1724.5	9.94498
1727.54	8.69105
1730.57	8.59018
1733.61	8.36682
1736.64	7.83616
1739.67	7.3826
1742.7	7.03729
1745.72	6.51643
1748.75	6.72657
1751.77	6.63613
1754.8	5.98906
1757.82	5.94369
1760.84	5.2937
1763.87	5.33584
1766.89	5.92331
1769.91	6.29094
1772.92	6.93855
1775.94	6.72475
1778.95	7.04248
1781.97	5.34365
1784.98	5.80636
1787.99	4.4749
1791.01	4.06671
1794.01	3.98902
1797.02	2.98561
1800.03	2.31509
1803.04	2.03047
1806.04	2.18747
1809.05	1.04577
1812.05	1.13827
1815.05	1.57583
1818.05	1.68407
1821.05	1.83149
1824.05	2.12031
1827.05	2.34359
1830.04	2.07753
1833.04	2.52688
1836.03	2.59502
1839.03	2.93134
1842.02	3.97832
1845.01	4.5444
1848	4.84472
1850.99	4.40854
1853.97	4.07083
1856.96	3.60512
1859.94	2.80531
1862.93	1.70392
1865.91	0.90283
1868.89	0.571937
1871.87	-0.0363403
1874.85	0.305604
1877.83	-0.190523
1880.81	0.391702
1882.57	0.510314
1885.56	1.47848
1888.55	2.04046
1891.54	3.41213
1894.52	3.08035
1897.51	3.59748
1900.49	3.99156
1903.47	4.86179
1906.45	6.11694
1909.43	7.21806
1912.41	6.94282
1915.39	7.48796
1918.37	8.36334
1921.34	8.12879
1924.32	9.41681
1927.29	8.73687
1930.26	8.43698
1933.23	7.62766
1936.2	7.2532
1939.17	7.96771
1942.14	7.93563
1945.11	7.97891
1948.07	8.66547
1951.04	8.39992
1954	7.9397
1956.96	6.85316
1959.93	6.69108
1962.89	7.41731
1965.85	8.0504
1968.8	7.43312
1971.76	6.81654
1974.72	6.22791
1977.67	6.07797
1980.63	5.0468
1983.58	4.63189
1986.53	3.00137
1989.48	4.34227
1992.43	6.04182
1995.38	6.00017
1998.32	6.23627
2001.27	5.53813
2004.22	6.32321
2007.16	6.68612
2010.1	7.46914
2013.04	7.60592
2015.98	6.97746
2018.92	8.20263
2021.86	8.02551
2024.8	7.79766
2027.74	7.2862
2030.67	7.92992
2033.61	8.96677
2036.54	9.58412
2039.47	9.65316
2042.4	9.45001
2045.33	9.62297
2048.26	9.78823
2051.19	10.3968
2054.12	10.0385
2057.04	10.3864
2059.97	11.08
2062.89	12.6651
2065.81	13.7592
2068.73	14.7907
2071.65	15.9191
2074.57	17.7786
2077.49	18.2625
2080.41	18.1011
2083.32	17.6089
2086.24	18.9323
2089.15	20.6492
2092.07	22.5181
2094.98	22.8884
2097.89	23.9326
2100.8	24.7448
2103.71	26.433
2106.61	28.9629
2109.52	31.4776
2112.43	33.7817
2115.33	36.6381
2118.23	38.6128
2121.13	40.6936
2124.04	42.2992
2126.94	44.8836
2129.83	49.2932
2132.73	53.6377
2135.63	57.5522
2138.53	61.3908
2141.42	64.9398
2144.31	67.3852
2147.21	69.2063
2150.1	70.7582
2152.99	72.8908
2155.88	76.6276
2158.77	79.7629
2161.65	81.8804
2164.54	83.6139
2167.43	85.0824
2170.31	86.2355
2173.19	86.5109
2176.07	86.2044
2178.96	85.3532
2181.84	83.8228
2184.72	82.3955
2187.59	80.617
2190.47	77.8013
2193.35	74.7396
2196.22	73.6184
2199.09	71.8296
2201.97	69.4862
2204.84	66.3238
2207.71	62.1647
2210.58	57.6674
2213.45	54.2358
2216.31	50.0195
2219.18	46.4983
2222.05	43.8223
2224.91	41.7262
2227.78	39.4571
2230.64	36.7396
2233.5	35.0966
2236.36	32.6307
2239.22	30.8628
2242.08	28.4657
2244.93	26.7403
2247.79	26.5795
2250.64	25.963
2253.5	25.4817
2256.35	25.4858
2259.2	25.436
2262.05	24.1076
2264.9	24.078
2267.75	23.5963
2270.6	22.6081
2273.45	20.8063
2276.29	20.3613
2279.14	19.3635
2281.98	18.4738
2284.82	18.054
2287.66	16.2976
2290.5	14.6177
2293.34	11.6059
2296.18	10.5852
2299.02	10.2724
2301.86	9.78366
2304.69	9.10089
2307.53	8.67245
2310.36	8.80249
2313.19	9.00977
2316.02	8.76526
2318.85	9.2303
2321.68	9.81327
2324.51	9.78674
2327.34	9.67512
2330.16	10.1906
2332.99	10.5168
2335.81	10.0389
2338.64	8.92013
2341.46	8.10889
2344.28	8.30732
2347.1	8.00242
2349.92	7.91205
2352.74	7.44241
2355.55	6.70289
2358.37	5.45842
2361.19	3.77328
2364	4.05307
2366.81	4.76752
2369.62	4.85303
2372.44	4.36805
2375.24	4.5225
2378.05	4.9228
2380.86	5.60434
2383.67	6.99991
2386.47	7.58429
2389.28	7.4015
2392.08	6.86437
2394.89	6.81324
2397.69	7.07267
2400.49	6.1121
2403.29	5.88532
2406.09	5.35298
2408.88	5.77396
2411.68	6.71456
2414.48	7.82066
2417.27	7.58307
2420.06	7.65684
2422.86	8.02123
2425.65	8.47419
2428.44	8.17294
2431.23	8.21994
2434.02	8.68973
2436.81	8.95788
2439.59	7.98684
2442.38	8.65427
2445.16	9.24446
2447.95	8.90292
2450.73	8.75097
2453.51	8.0386
2456.29	6.31758
2459.07	5.61151
2461.85	4.57589
2464.63	4.20597
2467.4	3.8285
2470.18	3.97217
2472.95	3.18088
2475.73	2.19872
2478.5	1.691
2481.27	1.3535
2484.04	0.568964
2486.81	0.219846
2489.58	0.582254
2492.35	1.43252
2495.12	1.05875
2497.88	1.29882
2500.65	1.54364
2503.41	1.67768
2506.17	1.02075
2508.94	1.81072
2511.7	2.60402
2514.46	2.46805
2517.22	2.61537
2519.97	3.29038
2522.73	3.45823
2525.49	3.5362
2528.24	3.2105
2530.99	3.63825
2533.75	3.77011
2536.5	4.0042
2539.25	3.05874
2542	2.71996
2544.75	3.16007
2547.5	2.13745
2550.24	2.77798
2552.99	1.28688
2555.74	1.50624
2558.48	1.52496
2561.22	1.35445
2563.96	0.890118
2566.71	1.01679
2569.45	1.48576
2572.18	1.85954
2574.92	2.66002
2577.66	3.02466
2580.4	3.52591
2583.13	3.19812
2585.87	3.71425
2588.6	3.27671
2591.33	2.90357
2594.06	2.96585
2596.79	3.09527
2599.52	3.24495
2602.25	3.55348
2604.98	3.19173
2607.71	3.02323
2610.43	2.00458
2613.16	1.51012
2615.88	1.57999
2618.6	0.261168
2621.32	-0.505673
2624.04	-0.173225
2626.76	0.134043
2629.48	0.500518
2632.2	1.16067
2634.92	2.69516
2637.63	3.89677
2640.35	4.73705
2643.06	5.55108
2645.77	5.06258
2648.49	5.26635
2651.2	5.40409
2653.91	5.06876
2656.62	5.28586
2659.33	6.0806
2662.03	4.93371
2664.74	5.48194
2667.44	5.7966
2670.15	5.90663
2672.85	6.4817
2675.55	6.58403
2678.26	6.42417
2680.96	7.22915
2683.66	7.04117
2686.35	6.8093
2689.05	7.48581
2691.75	8.48186
2694.44	9.26948
2697.14	9.51601
2699.83	9.9262
2702.52	9.97896
2705.22	10.8172
2707.91	9.72299
2710.6	8.92142
2713.29	7.99876
2715.97	8.31336
2718.66	8.29608
2721.35	8.34939
2724.03	8.86683
2726.72	8.62064
2729.4	8.36756
2732.08	8.77981
2734.76	8.10634
2737.44	8.08759
2740.12	7.10821
2742.8	7.31487
2745.48	6.84577
2748.16	6.87608
2750.83	6.09529
2753.51	5.29067
2756.18	4.87521
2758.85	4.13434
2761.53	3.66446
2764.2	2.7685
2766.87	2.72646
2769.54	3.07199
2772.2	2.21957
2774.87	1.947
2777.54	0.94856
2780.2	1.20941
2782.87	1.8057
2785.53	1.05355
2788.19	0.691091
2790.85	0.928764
2793.51	0.758489
2796.17	1.15768
2798.83	0.709941
2801.49	1.08222
2804.15	1.68388
2806.8	1.82974
2809.46	2.08251
2812.11	1.89755
2814.76	2.02489
2817.42	2.84675
2820.07	4.19146
2822.72	6.42955
2825.37	7.95004
2828.02	10.8405
2830.66	14.1554
2833.31	16.3657
2835.96	18.9681
2838.6	22.211
2841.24	25.5934
2843.89	30.7287
2846.53	35.5031
2849.17	41.3429
2851.81	47.8374
2854.45	54.0086
2857.09	60.1387
2859.72	66.8061
2862.36	72.7238
2865	79.4406
2867.63	84.7375
2870.26	88.8387
2872.9	93.0021
2875.53	97.6898
2878.16	100.595
2880.79	104.999
2883.42	108.753
2886.05	112.211
2888.67	116.426
2891.3	120.183
2893.92	123.999
2896.55	128.196
2899.17	132.654
2901.79	139.522
2904.42	147.17
2907.04	155.106
2909.66	164.635
2912.27	174.024
2914.89	183.447
2917.51	192.596
2920.13	201.166
2922.74	207.772
2925.35	213.428
2927.97	218.056
2930.58	219.048
2933.19	218.943
2935.8	218.653
2938.41	216.852
2941.02	213.615
2943.63	207.902
2946.24	201.113
2948.84	194.042
2951.45	186.133
2954.05	177.725
2956.65	168.479
2959.26	159.995
2961.86	151.778
2964.46	143.202
2967.06	135.172
2969.66	127.759
2972.25	120.115
2974.85	112.859
2977.45	106.132
2980.04	98.5617
2982.64	91.3901
2985.23	82.9526
2987.82	75.1904
2990.41	68.418
2993	60.3263
2995.59	54.4812
2998.18	49.293
3000.77	44.0425
3003.36	37.9899
3005.94	31.9091
3008.53	27.2208
3011.11	23.1494
3013.69	19.9021
3016.28	16.4623
3018.86	14.6269
3021.44	12.544
3024.02	10.4861
3026.6	9.39772
3029.18	8.17882
3031.75	8.82549
3034.33	8.51141
3036.9	8.0346
3039.48	9.50596
3042.05	9.85348
3044.62	11.0402
3047.19	11.1927
3049.77	11.821
3052.34	12.7947
3054.9	13.5073
3057.47	14.2627
3060.04	14.262
3062.61	13.2106
3065.17	12.3594
3067.74	10.8514
3070.3	9.98727
3072.86	8.77513
3075.42	6.66325
3077.99	5.38917
3080.54	4.19629
3083.1	3.03581
3085.66	1.78674
3088.22	1.07525
3090.78	0.278422
3093.33	-0.459127
3095.89	-0.546349
3098.44	-1.4256
3100.99	-0.147316
3103.54	0.498697
3106.1	0.306713
3108.65	0.216434
3111.2	1.05024
3113.74	2.14163
3116.29	3.93108
3118.84	3.98498
3121.38	4.50829
3123.93	5.14217
3126.47	5.81004
3129.01	6.25877
3131.56	6.78433
3134.1	6.58605
3136.64	6.89441
3139.18	6.68224
3141.72	6.10282
3144.26	5.21146
3146.79	3.77143
3149.33	2.28586