File: data/Raman/poly_smoothed/Thy_00_07_3_1x_30s_532 nm_x100_100%_600 gr_mm_01.txt
#Acq. time (s)=	30
#Accumulations=	2
#Range (cm-¹)=	200...3150
#Windows=	2
#Auto scanning=	Off
#Autofocus=	Off
#Macrospot=	Off
#AutoExposure=	Off
#Spike filter=	Multiple accum.
#Delay time (s)=	0
#Binning=	1
#Readout mode=	Signal
#DeNoise=	Off
#ICS correction=	On
#Dark correction=	Off
#Inst. Process=	Off
#Detector Gain=	Best Dynamic Range
#Detector ADC=	20 kHz
#Detector temperature (°C)=	-69.85
#Instrument=	LabRAM HR Evol
#Detector=	Synapse
#Objective=	x100
#Grating=	600 gr/mm
#ND Filter=	100%
#Laser (nm)=	532
#Hole=	100.021
#Range=	Auto
#Laser Pol.=	No
#Raman. Pol.=	No
#Laser Pol. (°)=	-0.0007625
#Raman Pol. (°)=	89.9995
#Collection=	Microscope
#StageXY=	Marzhauser
#StageZ=	Marzhauser
#X (µm)=	9000.8
#Y (µm)=	-3083.2
#Z (µm)=	-54.85
#Full time(mm:ss)=	2:18
#Project=
#Sample=
#Site=
#Title=	Thy_00_07_3_2x_30s_532 nm_x100_100%_600 gr_mm
#Remark=
#Date=	28.06.2022 10:06
#Acquired=	28.06.2022 10:06:28
#Base:Fit=	10.08.2022 10:07:56
#Base:Sub=	10.08.2022 10:08:40
#Filter:Polynom=	16.08.2022 10:26:06
#AxisType[0]=Intens
#AxisUnit[0]=Cnt
#AxisType[1]=Spectr
#AxisUnit[1]=1/cm
200.407	40.4907
204.035	32.622
207.665	24.8072
211.291	18.936
214.916	14.4262
218.541	10.6716
222.163	9.54173
225.785	7.48503
229.404	4.53751
233.022	3.57872
236.638	3.08699
240.255	2.31839
243.868	2.78651
247.48	2.00964
251.091	2.94418
254.702	5.01421
258.31	6.97809
261.916	9.40052
265.521	11.3821
269.125	12.3153
272.727	11.5384
276.328	11.8751
279.927	12.8717
283.525	13.1848
287.121	13.0632
290.716	11.9515
294.31	11.688
297.9	13.2232
301.491	11.8999
305.081	11.9482
308.669	11.5732
312.256	10.6736
315.839	10.0191
319.423	8.8705
323.006	8.35795
326.585	7.1339
330.165	6.07829
333.741	4.1283
337.318	3.20974
340.894	4.90077
344.466	6.57996
348.039	6.67876
351.608	7.68481
355.176	7.95101
358.745	7.51171
362.31	7.67275
365.876	7.56662
369.439	7.99023
373	7.94475
376.56	8.02539
380.12	8.53352
383.677	10.0901
387.233	9.14042
390.787	8.60602
394.34	10.1255
397.894	9.40041
401.444	8.79934
404.993	7.44345
408.54	6.40728
412.086	6.65716
415.631	6.34004
419.174	6.24318
422.716	5.24482
426.257	6.92358
429.794	5.66599
433.332	4.6175
436.868	5.05545
440.403	4.39779
443.937	4.30003
447.468	3.66488
450.999	3.71675
454.528	4.17182
458.057	4.88916
461.582	7.00682
465.107	8.33538
468.629	8.05856
472.152	10.1571
475.672	11.653
479.192	14.6562
482.709	15.5284
486.226	16.7246
489.74	17.8926
493.255	19.9854
496.767	21.7814
500.277	22.0203
503.788	23.0203
507.295	22.0795
510.801	21.5102
514.308	21.6941
517.811	19.5272
521.313	19.1059
524.814	17.7517
528.313	16.9395
531.811	16.7379
535.308	15.9349
538.803	14.822
542.297	14.5341
545.789	12.134
549.281	11.264
552.771	9.58991
556.259	8.45501
559.747	8.62244
563.233	7.92015
566.717	6.97562
570.2	7.04947
573.68	7.58784
577.161	7.80913
580.64	8.43155
584.118	8.80749
587.593	9.90894
591.068	11.2681
594.54	12.2183
598.013	13.8304
601.484	14.4771
604.952	15.751
608.421	17.1146
611.886	18.2771
615.35	18.4298
618.815	18.0412
622.276	17.9879
625.738	16.7029
629.197	15.8662
632.655	13.5035
636.113	12.9088
639.568	10.9342
643.021	10.0847
646.473	9.00625
649.924	8.68184
653.376	9.95732
656.824	10.3466
660.271	11.8774
663.716	12.2735
667.161	14.3703
670.604	16.6022
674.045	18.9871
677.486	21.2326
680.925	23.3606
684.361	24.5858
687.797	26.3891
691.232	27.7294
694.666	29.0878
698.099	29.9255
701.528	30.035
704.958	29.8135
708.387	28.636
711.814	28.2816
715.238	27.3406
718.663	27.9294
722.084	28.6993
725.506	29.6711
728.925	31.2223
732.345	30.442
735.761	31.8279
739.178	32.181
742.592	32.3081
746.006	35.0091
749.417	35.1155
752.827	38.0317
756.236	41.3637
759.645	42.0345
763.051	45.0855
766.456	46.6756
769.859	47.7268
773.261	49.5006
776.664	48.9419
780.064	49.3235
783.462	49.9602
786.859	50.4912
790.255	51.3455
793.649	53.128
797.042	53.9759
800.434	55.6657
803.823	57.1873
807.212	58.4744
810.6	59.4841
813.987	59.9449
817.372	58.0941
820.754	57.6239
824.137	57.5827
827.519	58.4754
830.897	58.7187
834.276	59.5591
837.654	59.9753
841.029	58.3534
844.404	56.6241
847.776	53.9886
851.149	52.1447
854.519	49.5412
857.889	46.749
861.256	44.3914
864.622	41.8701
867.988	39.7634
871.351	38.289
874.713	36.0673
878.074	34.6042
881.435	33.6911
884.794	34.0284
888.15	34.2633
891.506	32.6459
894.861	32.9411
898.214	33.4703
901.566	33.5106
904.916	35.9721
908.266	37.797
911.614	38.7804
914.961	40.0231
918.306	39.1774
921.651	37.739
924.994	37.0868
928.336	37.5528
931.674	36.0963
935.014	35.6889
938.352	34.7921
941.687	33.1326
945.022	32.1531
948.357	31.5054
951.688	30.7359
955.02	30.3324
958.348	29.7932
961.678	27.9525
965.004	27.7528
968.331	28.6621
971.655	29.1406
974.979	31.2016
978.3	32.2589
981.62	33.9376
984.941	35.4701
988.259	36.4766
991.575	37.4303
994.89	38.7345
998.204	38.9641
1001.52	39.3969
1004.83	39.561
1008.14	40.0029
1011.45	38.6256
1014.76	37.9838
1018.06	37.0201
1021.37	34.9948
1024.67	33.2224
1027.97	32.0067
1031.27	30.3397
1034.57	27.7982
1037.87	25.5333
1041.17	23.8187
1044.47	21.5739
1047.76	21.9989
1051.06	21.1743
1054.35	20.6445
1057.64	18.9032
1060.93	18.4003
1064.22	18.6528
1067.5	18.3671
1070.79	19.3855
1074.08	21.9434
1077.36	22.4374
1080.64	22.2649
1083.92	21.9348
1087.2	21.8435
1090.48	21.5247
1093.76	21.778
1097.03	22.4466
1100.31	22.583
1103.58	22.9529
1106.85	22.5499
1110.12	22.5504
1113.39	22.6555
1116.66	22.7957
1119.93	22.449
1123.19	20.0702
1126.46	17.9232
1129.72	15.4577
1132.98	14.7765
1136.24	12.7898
1139.5	11.4583
1142.76	11.8819
1146.01	11.7192
1149.27	13.4127
1152.53	13.8283
1155.78	14.0062
1159.03	14.1265
1162.28	14.1604
1165.53	15.0832
1168.78	15.3735
1172.02	15.7411
1175.27	17.8596
1178.51	18.3584
1181.76	19.2888
1185	20.4047
1188.24	21.019
1191.48	21.9692
1194.71	22.8036
1197.95	23.629
1201.19	22.59
1204.42	23.3563
1207.65	26.3302
1210.88	29.5816
1214.12	32.7636
1217.35	36.0496
1220.57	41.1478
1223.8	43.632
1227.03	47.0023
1230.25	49.1569
1233.47	50.4074
1236.69	51.5813
1239.92	53.1372
1243.13	54.1804
1246.35	55.5207
1249.57	55.1038
1252.78	55.8374
1256	54.1959
1259.21	53.3559
1262.42	51.3706
1265.63	50.0679
1268.84	49.2776
1272.05	49.9436
1275.26	50.7055
1278.46	51.5913
1281.67	53.773
1284.87	56.3893
1288.07	58.9543
1291.27	62.3868
1294.47	64.1718
1297.67	66.4231
1300.87	69.691
1304.06	69.739
1307.26	73.1217
1310.45	74.9239
1313.64	78.2381
1316.83	79.6431
1320.02	82.1313
1323.21	83.4007
1326.4	82.8506
1329.59	82.3878
1332.77	79.8448
1335.95	79.3247
1339.14	78.3679
1342.32	75.496
1345.5	74.5877
1348.67	72.55
1351.85	71.1983
1355.03	67.8851
1358.2	66.2804
1361.38	63.6188
1364.55	62.8014
1367.72	61.24
1370.89	58.1664
1374.06	55.5244
1377.23	56.2091
1380.39	54.1949
1383.56	53.038
1386.72	52.5009
1389.89	51.1872
1393.05	50.1792
1396.21	48.632
1399.37	47.5944
1402.52	45.8737
1405.68	45.0054
1408.84	45.3704
1411.99	47.0568
1415.15	48.0767
1418.3	51.919
1421.45	54.4358
1424.6	58.336
1427.75	62.0447
1430.89	66.6134
1434.04	71.6784
1437.18	76.9394
1440.33	80.4494
1443.47	82.28
1446.61	83.6125
1449.75	84.7587
1452.89	85.9504
1456.03	84.9964
1459.16	83.7311
1462.3	80.657
1465.43	77.3095
1468.56	72.8467
1471.7	67.869
1474.83	62.5069
1477.96	56.7958
1481.08	52.06
1484.21	48.497
1487.34	44.9134
1490.46	42.5471
1493.58	40.2253
1496.71	38.2959
1499.83	35.2706
1502.95	34.0158
1506.07	32.6135
1509.18	32.1503
1512.3	31.192
1515.41	28.6964
1518.53	26.8137
1521.64	26.9685
1524.75	27.6548
1527.86	28.292
1530.97	29.3513
1534.08	31.3839
1537.19	32.3648
1540.29	33.6638
1543.4	35.0407
1546.5	36.9258
1549.6	37.762
1552.7	41.8434
1555.8	46.7501
1558.9	50.8662
1562	54.8252
1565.09	58.0635
1568.19	60.5947
1571.28	63.8286
1574.37	66.8589
1577.47	68.6019
1580.56	70.5452
1583.64	73.2006
1586.73	73.8391
1589.82	75.0156
1592.9	75.8146
1595.99	75.4099
1599.07	75.3589
1602.15	73.9435
1605.23	72.6624
1608.31	71.8063
1611.39	69.8214
1614.47	67.5842
1617.55	65.8662
1620.62	65.181
1623.7	65.4824
1626.77	65.3772
1629.84	68.0449
1632.91	68.9657
1635.98	69.855
1639.05	72.1495
1642.11	72.8031
1645.18	76.1202
1648.24	77.2418
1651.31	79.0636
1654.37	80.3145
1657.43	81.6176
1660.49	80.4029
1663.55	78.2911
1666.61	76.1566
1669.66	72.8639
1672.72	68.7272
1675.77	65.2345
1678.83	61.008
1681.88	56.6776
1684.93	51.9594
1687.98	46.8386
1691.03	42.66
1694.07	37.6536
1697.12	34.6744
1700.17	30.741
1703.21	28.3083
1706.25	25.9912
1709.29	23.476
1712.33	22.2005
1715.37	20.3322
1718.41	18.7082
1721.45	18.0927
1724.49	16.4854
1727.52	14.2453
1730.55	12.7576
1733.59	10.807
1736.62	9.79506
1739.65	9.5088
1742.68	8.45637
1745.7	8.32913
1748.73	7.78389
1751.76	7.35912
1754.78	5.86581
1757.8	4.34064
1760.83	3.53303
1763.85	4.0729
1766.87	3.96832
1769.89	4.11522
1772.9	3.90961
1775.92	4.12007
1778.94	4.21763
1781.95	4.38715
1784.96	4.01837
1787.97	3.41474
1790.99	3.18964
1794	2.58351
1797	1.71656
1800.01	0.973844
1803.02	1.30231
1806.02	1.79201
1809.03	1.54655
1812.03	0.814402
1815.03	1.23987
1818.03	1.46811
1821.03	1.36423
1824.03	0.866866
1827.03	0.317974
1830.02	-0.308765
1833.02	-0.463324
1836.01	0.11594
1839.01	1.15021
1842	1.04005
1844.99	0.121897
1847.98	0.109496
1850.97	-0.281054
1853.95	0.327695
1856.94	1.65858
1859.93	2.33484
1862.91	3.00259
1865.89	3.51653
1868.87	3.39245
1871.85	3.38608
1874.83	4.08453
1877.81	4.28326
1880.79	4.75331
1882.52	5.2349
1885.51	5.53189
1888.5	5.53801
1891.49	5.23325
1894.47	4.97332
1897.46	4.56373
1900.44	4.60261
1903.42	3.7427
1906.4	3.16437
1909.38	3.80704
1912.36	3.89355
1915.34	3.71794
1918.32	3.50596
1921.29	3.89985
1924.27	4.38721
1927.24	5.68202
1930.21	5.87579
1933.18	5.84726
1936.15	5.7793
1939.12	5.48398
1942.09	5.86527
1945.06	5.62095
1948.02	6.22929
1950.99	6.43966
1953.95	6.24754
1956.91	5.23247
1959.88	5.10119
1962.84	5.07033
1965.8	4.18187
1968.75	4.0289
1971.71	4.16549
1974.67	3.448
1977.62	4.13915
1980.58	4.49963
1983.53	4.52871
1986.48	3.16958
1989.43	2.20652
1992.38	2.10623
1995.33	2.96479
1998.27	3.31795
2001.22	3.39215
2004.16	4.16404
2007.11	3.83465
2010.05	4.58697
2012.99	5.23187
2015.93	4.95112
2018.87	5.18951
2021.81	6.0395
2024.75	5.91339
2027.69	6.12476
2030.62	6.53897
2033.56	6.48383
2036.49	6.20082
2039.42	6.45295
2042.35	6.76747
2045.28	6.11113
2048.21	6.36536
2051.14	6.22518
2054.07	6.53562
2056.99	5.98003
2059.92	5.71688
2062.84	5.95129
2065.76	6.6671
2068.68	6.70323
2071.6	6.82708
2074.52	7.57312
2077.44	7.65
2080.36	8.71077
2083.27	8.21033
2086.19	8.50363
2089.1	8.85444
2092.02	8.99452
2094.93	8.95102
2097.84	8.60899
2100.75	8.80137
2103.66	8.30578
2106.56	8.24122
2109.47	7.62903
2112.38	6.6961
2115.28	5.64084
2118.18	5.40528
2121.09	4.85192
2123.99	3.82508
2126.89	4.26428
2129.79	2.40678
2132.68	2.80529
2135.58	3.74157
2138.48	3.88786
2141.37	4.39533
2144.27	4.61561
2147.16	4.82671
2150.05	5.27472
2152.94	5.94965
2155.83	6.35183
2158.72	8.05195
2161.6	8.72386
2164.49	10.2806
2167.38	10.552
2170.26	11.6267
2173.14	11.7847
2176.03	11.0716
2178.91	12.2899
2181.79	11.4998
2184.67	11.4833
2187.54	11.7479
2190.42	11.582
2193.3	11.6661
2196.17	11.6036
2199.05	10.9178
2201.92	10.3356
2204.79	11.1132
2207.66	9.84172
2210.53	8.39372
2213.4	7.37095
2216.27	5.25887
2219.13	4.79175
2222	3.6498
2224.86	3.30388
2227.72	2.82404
2230.59	2.43379
2233.45	2.65223
2236.31	2.66735
2239.17	2.71742
2242.03	2.09432
2244.88	3.16149
2247.74	3.80672
2250.59	4.71568
2253.45	6.23317
2256.3	7.47021
2259.15	8.2125
2262	9.46933
2264.85	10.8254
2267.7	11.0485
2270.55	11.8837
2273.4	12.1266
2276.24	11.0492
2279.09	9.42839
2281.93	9.0315
2284.77	8.56675
2287.62	7.97725
2290.46	7.45798
2293.3	6.08248
2296.13	6.5086
2298.97	6.94024
2301.81	7.26395
2304.64	7.82877
2307.48	7.92455
2310.31	8.48912
2313.14	9.39914
2315.98	10.5474
2318.81	11.4602
2321.64	12.8633
2324.46	14.1346
2327.29	14.4737
2330.12	15.174
2332.94	15.4457
2335.77	14.7489
2338.59	13.2606
2341.41	11.0258
2344.23	8.67002
2347.05	6.83811
2349.87	5.96117
2352.69	5.72773
2355.51	4.86391
2358.32	4.02347
2361.14	2.35277
2363.95	2.37108
2366.76	2.37608
2369.58	1.79339
2372.39	1.25952
2375.2	1.22141
2378	1.55161
2380.81	2.81439
2383.62	3.0536
2386.43	3.02568
2389.23	4.10884
2392.03	4.09279
2394.84	4.8669
2397.64	4.1023
2400.44	3.97908
2403.24	4.61501
2406.04	5.29043
2408.84	5.47275
2411.63	5.2357
2414.43	5.70511
2417.22	6.72905
2420.02	7.45321
2422.81	8.13715
2425.6	7.82727
2428.39	8.07115
2431.18	7.9257
2433.97	8.17951
2436.76	7.72021
2439.54	7.24703
2442.33	7.38263
2445.12	6.87671
2447.9	6.34804
2450.68	6.31832
2453.46	6.27986
2456.24	5.52522
2459.02	5.13103
2461.8	4.16351
2464.58	3.69613
2467.36	2.7771
2470.13	3.21813
2472.91	3.27557
2475.68	2.6798
2478.45	1.79234
2481.23	1.12879
2484	1.21881
2486.77	1.21259
2489.54	0.895711
2492.3	0.454029
2495.07	0.505742
2497.84	-0.62622
2500.6	-0.0267983
2503.36	0.603436
2506.13	0.650574
2508.89	1.53918
2511.65	1.67139
2514.41	3.02263
2517.17	3.80555
2519.93	4.87572
2522.68	4.99161
2525.44	5.33492
2528.19	5.72156
2530.95	6.25337
2533.7	5.93361
2536.45	5.72035
2539.2	5.64391
2541.95	5.67255
2544.7	5.63763
2547.45	5.97185
2550.2	6.04962
2552.94	6.37117
2555.69	5.24585
2558.43	4.55939
2561.18	4.3034
2563.92	3.59576
2566.66	4.58625
2569.4	4.15374
2572.14	3.96263
2574.88	3.53901
2577.61	3.06718
2580.35	2.56109
2583.09	2.21488
2585.82	2.58236
2588.55	2.78409
2591.29	2.67928
2594.02	2.30476
2596.75	1.41284
2599.48	1.46591
2602.21	1.93387
2604.93	2.58787
2607.66	2.77308
2610.39	3.45368
2613.11	3.29363
2615.83	3.6078
2618.56	4.41519
2621.28	4.55923
2624	5.02426
2626.72	5.21292
2629.44	5.36228
2632.15	5.77756
2634.87	6.26476
2637.59	6.35399
2640.3	6.63849
2643.02	6.22028
2645.73	7.10872
2648.44	6.43604
2651.15	5.77512
2653.86	4.87806
2656.57	4.6904
2659.28	3.65959
2661.99	3.45296
2664.69	3.25991
2667.4	4.35623
2670.1	4.43438
2672.81	4.60145
2675.51	3.60284
2678.21	3.69758
2680.91	3.78612
2683.61	4.12226
2686.31	5.06385
2689	5.39987
2691.7	5.67047
2694.4	6.30437
2697.09	7.03209
2699.79	7.97862
2702.48	9.05013
2705.17	9.45438
2707.86	9.39701
2710.55	10.2477
2713.24	11.0359
2715.93	11.0261
2718.62	11.3171
2721.3	11.4177
2723.99	10.8249
2726.67	10.8658
2729.35	11.2469
2732.04	11.2885
2734.72	11.1634
2737.4	10.795
2740.08	11.0041
2742.76	10.4779
2745.43	10.4717
2748.11	10.4599
2750.79	10.1814
2753.46	9.35913
2756.14	9.29169
2758.81	9.14732
2761.48	8.38259
2764.15	7.59492
2766.82	7.01834
2769.49	6.62779
2772.16	6.02442
2774.82	5.22425
2777.49	4.95717
2780.16	3.67805
2782.82	2.64678
2785.48	3.06353
2788.15	1.9763
2790.81	1.92017
2793.47	2.1065
2796.13	1.83674
2798.79	0.952976
2801.44	0.870525
2804.1	1.2569
2806.76	1.01537
2809.41	0.534647
2812.07	-0.118658
2814.72	-0.340747
2817.37	-0.0228754
2820.02	1.66253
2822.67	3.75221
2825.32	5.84875
2827.97	9.19281
2830.62	12.4455
2833.26	15.7121
2835.91	19.3315
2838.56	22.8662
2841.2	28.2825
2843.84	33.9669
2846.48	41.1059
2849.12	48.5233
2851.77	56.3806
2854.4	64.1247
2857.04	72.0729
2859.68	79.9508
2862.32	87.373
2864.95	94.4658
2867.59	101.176
2870.22	107.18
2872.85	112.43
2875.48	116.901
2878.11	122.344
2880.74	126.331
2883.37	130.641
2886	135.668
2888.63	139.719
2891.25	143.408
2893.88	146.332
2896.5	150.306
2899.13	155.535
2901.75	161.563
2904.37	167.945
2906.99	174.964
2909.61	182.542
2912.23	190.076
2914.85	198.246
2917.46	206.995
2920.08	213.933
2922.7	219.229
2925.31	223.785
2927.92	225.645
2930.54	225.939
2933.15	223.893
2935.76	222.397
2938.37	218.804
2940.98	213.521
2943.58	207.54
2946.19	200.439
2948.8	193.513
2951.4	185.818
2954.01	178.689
2956.61	171.382
2959.21	164.877
2961.81	159.015
2964.41	153.086
2967.01	146.363
2969.61	140.486
2972.21	134.525
2974.81	128.121
2977.4	122.629
2980	116.977
2982.59	109.489
2985.18	101.205
2987.78	92.2888
2990.37	83.8546
2992.96	74.9009
2995.55	66.5797
2998.14	58.2823
3000.73	50.6171
3003.31	43.7262
3005.9	36.8989
3008.48	30.9611
3011.07	25.4036
3013.65	20.5384
3016.23	16.8495
3018.81	13.986
3021.4	11.1328
3023.97	8.60665
3026.55	7.45458
3029.13	6.34931
3031.71	5.68785
3034.28	6.17759
3036.86	7.35529
3039.43	7.84875
3042.01	9.72618
3044.58	10.1158
3047.15	10.7416
3049.72	12.249
3052.29	12.5402
3054.86	13.355
3057.43	13.5134
3060	13.0631
3062.56	12.8363
3065.13	12.3822
3067.69	11.4831
3070.26	10.9764
3072.82	9.06316
3075.38	6.48755
3077.94	5.08435
3080.5	4.06625
3083.06	2.6802
3085.62	1.47906
3088.18	0.35233
3090.73	-0.23744
3093.29	-0.734017
3095.84	-0.443043
3098.4	0.0284339
3100.95	0.203765
3103.5	0.0987943
3106.05	0.863539
3108.6	1.35478
3111.15	2.71305
3113.7	2.19193
3116.25	3.03877
3118.79	3.86791
3121.34	4.96754
3123.88	6.09354
3126.43	7.3325
3128.97	8.63508
3131.51	10
3134.06	11.2578
3136.6	12.9825
3139.14	15.2934
3141.67	17.8187
3144.21	20.3476
3146.75	22.848
3149.29	26.4514