File: data/Raman/poly_smoothed/Thy_00_07_12_1x_45s_532 nm_x100_100%_600 gr_mm_01.txt
#Acq. time (s)=	45
#Accumulations=	2
#Range (cm-¹)=	200...3150
#Windows=	2
#Auto scanning=	Off
#Autofocus=	Off
#Macrospot=	Off
#AutoExposure=	Off
#Spike filter=	Multiple accum.
#Delay time (s)=	0
#Binning=	1
#Readout mode=	Signal
#DeNoise=	Off
#ICS correction=	On
#Dark correction=	Off
#Inst. Process=	Off
#Detector Gain=	Best Dynamic Range
#Detector ADC=	20 kHz
#Detector temperature (°C)=	-69.62
#Instrument=	LabRAM HR Evol
#Detector=	Synapse
#Objective=	x100
#Grating=	600 gr/mm
#ND Filter=	100%
#Laser (nm)=	532
#Hole=	100.021
#Range=	Auto
#Laser Pol.=	No
#Raman. Pol.=	No
#Laser Pol. (°)=	-0.0007625
#Raman Pol. (°)=	89.9995
#Collection=	Microscope
#StageXY=	Marzhauser
#StageZ=	Marzhauser
#X (µm)=	9026
#Y (µm)=	-3094.5
#Z (µm)=	-55.1
#Full time(mm:ss)=	3:18
#Project=
#Sample=
#Site=
#Title=	Thy_00_07_12_2x_45s_532 nm_x100_100%_600 gr_mm
#Remark=
#Date=	28.06.2022 10:53
#Acquired=	28.06.2022 10:53:58
#Base:Fit=	10.08.2022 10:06:44
#Base:Fit=	10.08.2022 10:07:16
#Base:Fit=	10.08.2022 10:07:25
#Base:Fit=	10.08.2022 10:07:44
#Base:Fit=	10.08.2022 10:07:56
#Base:Sub=	10.08.2022 10:08:39
#Filter:Polynom=	16.08.2022 10:26:06
#AxisType[0]=Intens
#AxisUnit[0]=Cnt
#AxisType[1]=Spectr
#AxisUnit[1]=1/cm
200.407	36.7021
204.035	39.7085
207.665	42.1123
211.291	43.5872
214.916	44.2949
218.541	43.5774
222.163	43.0556
225.785	41.3266
229.404	38.2137
233.022	38.3994
236.638	35.3467
240.255	30.7521
243.868	27.7298
247.48	23.5622
251.091	20.5589
254.702	18.374
258.31	17.2913
261.916	16.1092
265.521	14.3711
269.125	10.4163
272.727	8.70878
276.328	8.36272
279.927	6.74482
283.525	6.37497
287.121	6.52863
290.716	7.90623
294.31	9.22947
297.9	11.6567
301.491	13.4839
305.081	14.6887
308.669	15.8727
312.256	17.1103
315.839	18.0285
319.423	18.9984
323.006	19.4695
326.585	18.9802
330.165	19.6327
333.741	19.8262
337.318	19.7715
340.894	18.9002
344.466	18.0336
348.039	15.9543
351.608	16.0112
355.176	14.0627
358.745	13.319
362.31	12.418
365.876	9.70353
369.439	10.3543
373	11.2212
376.56	10.9803
380.12	11.4579
383.677	12.4868
387.233	13.3327
390.787	11.4561
394.34	12.0418
397.894	11.3064
401.444	12.348
404.993	13.989
408.54	15.2498
412.086	17.4646
415.631	18.1769
419.174	18.3759
422.716	17.664
426.257	17.7317
429.794	15.6667
433.332	14.2443
436.868	14.538
440.403	14.5087
443.937	12.7364
447.468	14.3436
450.999	14.8594
454.528	15.1358
458.057	15.5378
461.582	15.8357
465.107	14.6935
468.629	15.2791
472.152	13.7123
475.672	15.5164
479.192	16.3432
482.709	19.0072
486.226	22.0258
489.74	24.6847
493.255	26.7305
496.767	29.8062
500.277	31.0296
503.788	33.0907
507.295	34.3162
510.801	33.7863
514.308	30.5179
517.811	28.8118
521.313	25.9509
524.814	25.0064
528.313	23.9938
531.811	24.96
535.308	24.3155
538.803	23.73
542.297	21.3758
545.789	19.6114
549.281	17.6595
552.771	16.8963
556.259	15.9046
559.747	16.7034
563.233	16.5199
566.717	16.5908
570.2	16.0431
573.68	14.4844
577.161	12.9751
580.64	12.809
584.118	12.3403
587.593	12.5664
591.068	11.6761
594.54	9.77811
598.013	7.2835
601.484	7.27877
604.952	7.89684
608.421	8.15516
611.886	8.94775
615.35	8.73005
618.815	7.30167
622.276	7.64155
625.738	8.14838
629.197	8.62969
632.655	10.5273
636.113	9.69271
639.568	9.08821
643.021	8.99574
646.473	8.96519
649.924	10.107
653.376	10.5525
656.824	9.09994
660.271	10.5557
663.716	13.0158
667.161	15.9129
670.604	15.5338
674.045	18.2688
677.486	20.3417
680.925	21.6767
684.361	24.1566
687.797	27.3695
691.232	28.7245
694.666	27.6157
698.099	30.5031
701.528	30.7961
704.958	31.5876
708.387	32.9557
711.814	35.9363
715.238	36.2476
718.663	36.0473
722.084	35.8887
725.506	39.7784
728.925	40.9265
732.345	45.5034
735.761	47.3925
739.178	51.0271
742.592	55.2874
746.006	59.0203
749.417	62.148
752.827	64.5261
756.236	69.1242
759.645	73.3127
763.051	74.5602
766.456	77.3031
769.859	79.3499
773.261	79.0004
776.664	78.2531
780.064	79.0667
783.462	78.5373
786.859	76.4712
790.255	76.8144
793.649	77.3271
797.042	77.1074
800.434	75.3143
803.823	73.353
807.212	73.2238
810.6	71.1146
813.987	69.768
817.372	69.9352
820.754	69.2243
824.137	68.9994
827.519	70.0815
830.897	69.0007
834.276	68.9271
837.654	68.7147
841.029	67.6888
844.404	66.5756
847.776	64.2447
851.149	61.3764
854.519	58.601
857.889	56.5371
861.256	55.4166
864.622	54.2148
867.988	53.2915
871.351	53.1904
874.713	51.3958
878.074	50.4016
881.435	48.5091
884.794	45.8929
888.15	43.8047
891.506	41.7443
894.861	41.7136
898.214	40.0307
901.566	39.1214
904.916	41.0563
908.266	41.9924
911.614	40.1109
914.961	40.2504
918.306	38.2526
921.651	37.3343
924.994	36.4421
928.336	34.1653
931.674	34.6939
935.014	36.0359
938.352	37.4195
941.687	37.5092
945.022	36.9989
948.357	38.3054
951.688	38.9061
955.02	36.959
958.348	36.9173
961.678	34.0255
965.004	34.6079
968.331	37.5281
971.655	39.4646
974.979	41.7174
978.3	42.0147
981.62	43.3068
984.941	45.3797
988.259	43.6168
991.575	39.7431
994.89	38.8831
998.204	37.2132
1001.52	36.5496
1004.83	38.8487
1008.14	40.1376
1011.45	43.7553
1014.76	46.3776
1018.06	47.2699
1021.37	46.6745
1024.67	45.8538
1027.97	45.7139
1031.27	43.3216
1034.57	38.6027
1037.87	34.9404
1041.17	31.3419
1044.47	29.5542
1047.76	30.841
1051.06	28.0685
1054.35	26.1221
1057.64	22.5932
1060.93	20.1366
1064.22	16.2636
1067.5	14.2602
1070.79	10.7016
1074.08	10.9431
1077.36	11.1328
1080.64	11.8703
1083.92	13.7085
1087.2	16.5129
1090.48	17.8121
1093.76	21.3496
1097.03	23.6641
1100.31	26.6425
1103.58	29.1961
1106.85	30.8836
1110.12	31.269
1113.39	31.6601
1116.66	29.5322
1119.93	29.5563
1123.19	30.1652
1126.46	29.0951
1129.72	28.2643
1132.98	26.8716
1136.24	26.7974
1139.5	27.7017
1142.76	29.274
1146.01	28.4263
1149.27	28.192
1152.53	27.4978
1155.78	26.1043
1159.03	22.5108
1162.28	18.7447
1165.53	16.7798
1168.78	16.8669
1172.02	17.3476
1175.27	18.4121
1178.51	19.2439
1181.76	19.0088
1185	18.1464
1188.24	19.218
1191.48	18.7458
1194.71	19.83
1197.95	22.4295
1201.19	25.6694
1204.42	27.7302
1207.65	31.4308
1210.88	35.0017
1214.12	40.7758
1217.35	46.5377
1220.57	51.3076
1223.8	55.536
1227.03	58.6435
1230.25	63.8245
1233.47	66.8373
1236.69	68.6749
1239.92	69.3362
1243.13	72.1979
1246.35	73.4675
1249.57	73.8612
1252.78	73.626
1256	71.1163
1259.21	69.1248
1262.42	68.0353
1265.63	66.8528
1268.84	66.4829
1272.05	66.4947
1275.26	67.3615
1278.46	69.6874
1281.67	72.8147
1284.87	76.0986
1288.07	81.1018
1291.27	85.1926
1294.47	90.3737
1297.67	97.2886
1300.87	102.962
1304.06	109.861
1307.26	117.624
1310.45	123.457
1313.64	129.42
1316.83	134.14
1320.02	138.214
1323.21	138.474
1326.4	137.934
1329.59	138.341
1332.77	136.148
1335.95	134.249
1339.14	130.95
1342.32	128.81
1345.5	124.993
1348.67	121.024
1351.85	118.463
1355.03	115.351
1358.2	112.605
1361.38	109.115
1364.55	106.011
1367.72	104.5
1370.89	102.159
1374.06	101.001
1377.23	99.7179
1380.39	100.001
1383.56	99.5672
1386.72	98.5226
1389.89	98.1622
1393.05	94.7486
1396.21	93.0536
1399.37	88.6816
1402.52	87.3842
1405.68	85.4832
1408.84	84.8827
1411.99	85.9925
1415.15	89.0574
1418.3	93.0759
1421.45	97.9059
1424.6	102.999
1427.75	109.049
1430.89	114.449
1434.04	119.968
1437.18	126.527
1440.33	130.85
1443.47	135.633
1446.61	138.321
1449.75	139.166
1452.89	139.073
1456.03	137.586
1459.16	135.325
1462.3	130.357
1465.43	124.204
1468.56	114.958
1471.7	108.273
1474.83	98.8415
1477.96	88.8848
1481.08	79.6739
1484.21	71.4608
1487.34	67.0027
1490.46	62.4715
1493.58	57.6635
1496.71	53.2655
1499.83	49.5935
1502.95	46.0962
1506.07	44.8565
1509.18	43.7123
1512.3	44.6582
1515.41	43.327
1518.53	42.9155
1521.64	46.468
1524.75	47.7606
1527.86	50.143
1530.97	53.7597
1534.08	56.6294
1537.19	61.1986
1540.29	65.1239
1543.4	69.0727
1546.5	72.6894
1549.6	76.6205
1552.7	82.0199
1555.8	87.0848
1558.9	94.1051
1562	102.239
1565.09	107.844
1568.19	112.133
1571.28	117.489
1574.37	122.667
1577.47	126.285
1580.56	131.125
1583.64	134.263
1586.73	135.971
1589.82	138.379
1592.9	138.886
1595.99	139.652
1599.07	138.814
1602.15	136.834
1605.23	134.886
1608.31	131.847
1611.39	128.412
1614.47	127.249
1617.55	122.739
1620.62	121.131
1623.7	120.277
1626.77	120.336
1629.84	120.138
1632.91	120.42
1635.98	122.834
1639.05	122.018
1642.11	122.79
1645.18	124.021
1648.24	124.924
1651.31	123.81
1654.37	125.057
1657.43	124.47
1660.49	122.648
1663.55	117.091
1666.61	113.079
1669.66	107.554
1672.72	101.491
1675.77	95.5581
1678.83	89.6207
1681.88	82.7964
1684.93	75.6019
1687.98	68.9651
1691.03	63.2022
1694.07	55.8358
1697.12	50.553
1700.17	44.8771
1703.21	39.4055
1706.25	35.3683
1709.29	32.5608
1712.33	29.2967
1715.37	25.632
1718.41	24.3676
1721.45	22.0779
1724.49	20.51
1727.52	19.5508
1730.55	17.572
1733.59	15.2022
1736.62	13.9973
1739.65	13.1161
1742.68	12.426
1745.7	10.5223
1748.73	8.23435
1751.76	7.39929
1754.78	6.46142
1757.8	5.33675
1760.83	4.45555
1763.85	3.4399
1766.87	2.81368
1769.89	1.85093
1772.9	1.47758
1775.92	2.23999
1778.94	2.27073
1781.95	2.31976
1784.96	1.96575
1787.97	1.65016
1790.99	2.08641
1794	2.45014
1797	3.1688
1800.01	2.83936
1803.02	3.79052
1806.02	4.53227
1809.03	5.86865
1812.03	5.49866
1815.03	5.884
1818.03	5.75259
1821.03	5.95586
1824.03	6.35119
1827.03	6.16536
1830.02	6.37828
1833.02	6.36246
1836.01	5.56862
1839.01	6.45442
1842	7.45264
1844.99	8.28904
1847.98	7.73124
1850.97	7.90387
1853.95	6.88255
1856.94	6.49883
1859.93	7.40877
1862.91	8.47769
1865.89	9.11347
1868.87	9.16829
1871.85	9.60043
1874.83	10.0485
1877.81	10.2042
1880.79	10.0014
1882.52	8.60936
1885.51	8.54104
1888.5	8.80961
1891.49	8.79666
1894.47	7.09876
1897.46	5.49635
1900.44	4.35999
1903.42	4.22208
1906.4	2.82698
1909.38	2.99273
1912.36	3.8783
1915.34	3.83922
1918.32	3.53069
1921.29	3.60586
1924.27	3.86259
1927.24	3.96722
1930.21	3.99925
1933.18	3.77218
1936.15	3.62933
1939.12	4.7378
1942.09	4.84192
1945.06	5.65056
1948.02	5.38174
1950.99	4.84297
1953.95	5.17865
1956.91	5.20041
1959.88	4.82156
1962.84	4.16617
1965.8	3.47888
1968.75	2.59008
1971.71	2.20996
1974.67	2.14487
1977.62	2.09363
1980.58	2.89997
1983.53	3.27271
1986.48	3.72964
1989.43	4.08549
1992.38	4.74745
1995.33	5.52276
1998.27	6.32808
2001.22	6.08016
2004.16	6.18522
2007.11	6.12237
2010.05	6.83816
2012.99	7.38755
2015.93	7.15273
2018.87	6.96055
2021.81	6.51027
2024.75	8.02151
2027.69	8.15788
2030.62	7.40169
2033.56	7.7939
2036.49	7.47208
2039.42	7.85939
2042.35	6.74463
2045.28	5.92408
2048.21	5.57776
2051.14	5.48959
2054.07	6.12886
2056.99	6.43626
2059.92	6.82058
2062.84	8.33229
2065.76	8.70113
2068.68	8.89854
2071.6	8.83376
2074.52	8.32837
2077.44	8.22875
2080.36	8.48363
2083.27	8.6957
2086.19	9.10057
2089.1	9.39523
2092.02	9.07319
2094.93	10.1381
2097.84	9.16176
2100.75	8.75862
2103.66	8.44984
2106.56	8.41867
2109.47	8.13281
2112.38	7.83003
2115.28	6.14777
2118.18	5.53677
2121.09	4.71684
2123.99	5.56934
2126.89	5.04756
2129.79	4.9112
2132.68	4.10718
2135.58	4.33637
2138.48	5.03134
2141.37	5.01293
2144.27	5.41066
2147.16	5.96027
2150.05	5.24993
2152.94	5.4363
2155.83	5.47513
2158.72	5.66589
2161.6	5.21157
2164.49	4.85271
2167.38	4.38919
2170.26	4.17076
2173.14	4.85013
2176.03	4.81298
2178.91	4.79571
2181.79	3.31736
2184.67	3.52355
2187.54	2.74092
2190.42	3.7481
2193.3	4.09966
2196.17	4.43268
2199.05	5.06683
2201.92	5.91103
2204.79	6.04544
2207.66	5.73235
2210.53	5.94133
2213.4	4.65747
2216.27	5.52366
2219.13	5.16714
2222	4.14247
2224.86	4.27469
2227.72	3.22969
2230.59	3.34861
2233.45	3.36882
2236.31	3.30311
2239.17	2.57093
2242.03	2.34889
2244.88	2.57757
2247.74	1.31415
2250.59	0.955715
2253.45	1.8149
2256.3	3.68249
2259.15	4.98641
2262	4.94306
2264.85	5.35676
2267.7	7.09857
2270.55	8.17041
2273.4	7.88043
2276.24	6.04123
2279.09	6.72912
2281.93	7.04702
2284.77	6.99129
2287.62	7.33699
2290.46	6.72397
2293.3	5.84825
2296.13	5.23201
2298.97	5.44055
2301.81	6.17431
2304.64	6.86067
2307.48	5.34569
2310.31	4.56652
2313.14	5.29962
2315.98	4.50378
2318.81	3.74525
2321.64	3.89463
2324.46	3.88856
2327.29	5.24138
2330.12	5.31609
2332.94	6.20295
2335.77	6.31151
2338.59	5.39171
2341.41	4.36872
2344.23	3.78546
2347.05	3.25588
2349.87	4.87941
2352.69	3.20905
2355.51	2.96293
2358.32	2.82663
2361.14	2.54812
2363.95	1.85923
2366.76	2.84181
2369.58	4.05672
2372.39	4.53575
2375.2	4.37825
2378	5.43523
2380.81	4.99573
2383.62	4.1379
2386.43	3.4477
2389.23	2.91238
2392.03	2.85237
2394.84	3.18955
2397.64	2.541
2400.44	2.37403
2403.24	2.44361
2406.04	2.06048
2408.84	1.64828
2411.63	2.2724
2414.43	1.91714
2417.22	3.78379
2420.02	4.06363
2422.81	5.04499
2425.6	5.46889
2428.39	6.18349
2431.18	6.49069
2433.97	6.89639
2436.76	7.18283
2439.54	8.6024
2442.33	8.66424
2445.12	8.60424
2447.9	7.79751
2450.68	6.26837
2453.46	5.54675
2456.24	4.57349
2459.02	3.72571
2461.8	3.28509
2464.58	3.02967
2467.36	2.67065
2470.13	2.94363
2472.91	2.64366
2475.68	1.78467
2478.45	1.86398
2481.23	2.81786
2484	3.20095
2486.77	3.03916
2489.54	2.7425
2492.3	3.16509
2495.07	3.59947
2497.84	3.95048
2500.6	4.06921
2503.36	4.68044
2506.13	5.0871
2508.89	5.60945
2511.65	5.6264
2514.41	6.81499
2517.17	7.07617
2519.93	7.21518
2522.68	6.98313
2525.44	7.79709
2528.19	6.93521
2530.95	6.63823
2533.7	7.55848
2536.45	6.90067
2539.2	6.72346
2541.95	5.62622
2544.7	5.43045
2547.45	5.60712
2550.2	5.99257
2552.94	5.04558
2555.69	5.03016
2558.43	5.57248
2561.18	5.969
2563.92	5.68151
2566.66	4.40955
2569.4	4.30794
2572.14	4.03787
2574.88	4.23291
2577.61	4.21264
2580.35	5.85776
2583.09	4.7497
2585.82	2.87054
2588.55	2.9345
2591.29	3.4471
2594.02	4.20411
2596.75	4.89295
2599.48	6.32619
2602.21	6.34273
2604.93	6.55438
2607.66	6.51822
2610.39	7.63559
2613.11	9.50533
2615.83	9.88285
2618.56	10.5633
2621.28	10.9572
2624	11.6989
2626.72	10.8349
2629.44	10.5145
2632.15	9.14541
2634.87	9.2382
2637.59	9.51523
2640.3	8.91331
2643.02	8.37975
2645.73	7.702
2648.44	6.44686
2651.15	5.83908
2653.86	5.45874
2656.57	6.27366
2659.28	6.86427
2661.99	6.81602
2664.69	7.52257
2667.4	7.54746
2670.1	7.76799
2672.81	8.41493
2675.51	10.127
2678.21	10.6191
2680.91	9.91767
2683.61	9.61941
2686.31	10.7136
2689	11.5489
2691.7	11.8619
2694.4	11.0171
2697.09	11.8492
2699.79	11.4409
2702.48	12.2653
2705.17	12.9333
2707.86	13.4285
2710.55	13.4615
2713.24	13.7934
2715.93	14.398
2718.62	14.7147
2721.3	14.3565
2723.99	14.8046
2726.67	14.9865
2729.35	15.1376
2732.04	15.846
2734.72	16.1017
2737.4	15.915
2740.08	15.8532
2742.76	15.1036
2745.43	13.6798
2748.11	12.8792
2750.79	13.3778
2753.46	13.532
2756.14	11.9432
2758.81	11.388
2761.48	9.74279
2764.15	9.56809
2766.82	10.0753
2769.49	8.69842
2772.16	7.88289
2774.82	6.90634
2777.49	5.8033
2780.16	4.37524
2782.82	3.25666
2785.48	2.48693
2788.15	1.38867
2790.81	1.85303
2793.47	2.18652
2796.13	1.17027
2798.79	1.13745
2801.44	0.612701
2804.1	-0.404008
2806.76	-1.03972
2809.41	-1.15301
2812.07	-0.366802
2814.72	-0.307258
2817.37	2.33191
2820.02	4.3381
2822.67	9.45882
2825.32	13.7821
2827.97	20.0527
2830.62	26.5441
2833.26	32.7557
2835.91	39.007
2838.56	47.1638
2841.2	57.208
2843.84	68.7932
2846.48	82.3107
2849.12	96.7477
2851.77	111.871
2854.4	126.732
2857.04	141.793
2859.68	154.704
2862.32	167.306
2864.95	180.546
2867.59	192.143
2870.22	202.834
2872.85	212.994
2875.48	222.285
2878.11	229.831
2880.74	236.371
2883.37	243.098
2886	249.107
2888.63	254.895
2891.25	261.118
2893.88	269.266
2896.5	275.023
2899.13	282.642
2901.75	292.39
2904.37	304.195
2906.99	318.531
2909.61	333.504
2912.23	348.495
2914.85	362.951
2917.46	377.621
2920.08	389.297
2922.7	399.188
2925.31	404.631
2927.92	408.151
2930.54	408.693
2933.15	406.408
2935.76	401.032
2938.37	393.9
2940.98	383.485
2943.58	370.899
2946.19	358.195
2948.8	345.257
2951.4	331.454
2954.01	316.684
2956.61	302.537
2959.21	286.712
2961.81	271.461
2964.41	259.133
2967.01	246.843
2969.61	235.741
2972.21	224.059
2974.81	212.793
2977.4	200.983
2980	188.409
2982.59	175.661
2985.18	162.483
2987.78	147.988
2990.37	132.002
2992.96	117.783
2995.55	104.714
2998.14	91.7252
3000.73	80.0596
3003.31	69.9986
3005.9	59.6649
3008.48	50.0218
3011.07	42.8621
3013.65	36.2393
3016.23	28.9335
3018.81	23.8268
3021.4	17.8086
3023.97	13.9757
3026.55	11.2734
3029.13	9.50704
3031.71	7.66704
3034.28	8.2673
3036.86	9.18669
3039.43	10.3341
3042.01	12.6374
3044.58	14.4412
3047.15	15.4898
3049.72	17.547
3052.29	19.0253
3054.86	20.6587
3057.43	21.845
3060	22.2515
3062.56	23.9791
3065.13	24.6695
3067.69	23.6198
3070.26	23.1534
3072.82	22.1744
3075.38	20.1012
3077.94	17.0817
3080.5	14.732
3083.06	11.3891
3085.62	9.34354
3088.18	7.98435
3090.73	5.01053
3093.29	5.18738
3095.84	5.22102
3098.4	5.43541
3100.95	6.22738
3103.5	6.5026
3106.05	5.43426
3108.6	5.74062
3111.15	6.79568
3113.7	8.13812
3116.25	8.85643
3118.79	10.9702
3121.34	12.8582
3123.88	15.3744
3126.43	17.6101
3128.97	19.0923
3131.51	21.8735
3134.06	23.555
3136.6	25.3594
3139.14	27.8708
3141.67	32.8916
3144.21	36.865
3146.75	41.7971
3149.29	46.768