File: data/Raman/poly_smoothed/Thy_10_08_35_1x_45s_532 nm_x100_100%_600 gr_mm_01.txt
#Acq. time (s)=	45
#Accumulations=	2
#Range (cm-¹)=	200...3150
#Windows=	2
#Auto scanning=	Off
#Autofocus=	Off
#Macrospot=	Off
#AutoExposure=	Off
#Spike filter=	Multiple accum.
#Delay time (s)=	0
#Binning=	1
#Readout mode=	Signal
#DeNoise=	Off
#ICS correction=	On
#Dark correction=	Off
#Inst. Process=	Off
#Detector Gain=	Best Dynamic Range
#Detector ADC=	20 kHz
#Detector temperature (°C)=	-69.85
#Instrument=	LabRAM HR Evol
#Detector=	Synapse
#Objective=	x100
#Grating=	600 gr/mm
#ND Filter=	100%
#Laser (nm)=	532
#Hole=	100.021
#Range=	Auto
#Laser Pol.=	No
#Raman. Pol.=	No
#Laser Pol. (°)=	-0.0007625
#Raman Pol. (°)=	89.9995
#Collection=	Microscope
#StageXY=	Marzhauser
#StageZ=	Marzhauser
#X (µm)=	2174.2
#Y (µm)=	1235.3
#Z (µm)=	443.35
#Full time(mm:ss)=	3:18
#Project=
#Sample=
#Site=
#Title=	Thy_10_08_35_2x_45s_532 nm_x100_100%_600 gr_mm
#Remark=
#Date=	05.07.2022 16:46
#Acquired=	05.07.2022 16:46:11
#Base:Fit=	10.08.2022 09:46:25
#Base:Sub=	10.08.2022 09:46:49
#Filter:Polynom=	16.08.2022 10:24:56
#AxisType[0]=Intens
#AxisUnit[0]=Cnt
#AxisType[1]=Spectr
#AxisUnit[1]=1/cm
200.43	0.103055
204.059	0.196526
207.688	0.261943
211.314	0.955415
214.941	1.21714
218.564	2.56741
222.186	3.3556
225.809	3.86036
229.428	5.13003
233.045	6.24638
236.663	8.1457
240.278	9.38471
243.891	10.5752
247.503	11.4478
251.116	12.546
254.725	12.995
258.333	13.4098
261.939	13.7105
265.544	13.2324
269.148	13.5572
272.75	12.6368
276.351	13.3005
279.95	13.0517
283.548	13.5863
287.144	14.2935
290.739	14.9258
294.333	16.3721
297.925	16.3827
301.514	16.5107
305.104	17.2246
308.692	18.7167
312.279	20.0063
315.862	20.6322
319.446	21.8236
323.029	23.0132
326.608	23.6126
330.188	24.0664
333.766	23.6594
337.341	23.3816
340.917	22.0876
344.489	21.1443
348.062	21.0945
351.631	20.3137
355.201	19.4992
358.768	19.007
362.333	17.7225
365.899	16.5381
369.462	16.1513
373.023	15.494
376.585	15.3586
380.143	15.7308
383.7	14.675
387.256	13.7033
390.812	13.9232
394.365	14.449
397.916	14.9189
401.467	14.4814
405.015	13.9781
408.563	13.1925
412.109	12.8604
415.654	12.2764
419.197	11.3321
422.739	11.5722
426.279	10.9257
429.819	10.7272
433.356	10.5122
436.891	10.2811
440.426	9.97879
443.96	9.38192
447.492	9.43235
451.021	9.78873
454.551	10.4232
458.079	11.0525
461.604	12.2772
465.13	14.2821
468.654	15.5635
472.175	15.9131
475.696	15.5829
479.215	15.7149
482.733	17.3894
486.249	16.9318
489.765	16.2762
493.278	16.1826
496.789	15.584
500.301	14.9764
503.81	14.3827
507.317	14.4359
510.825	14.3549
514.33	13.971
517.833	14.2038
521.335	13.9742
524.836	14.3296
528.335	14.849
531.835	14.1065
535.332	14.2604
538.827	14.8208
542.321	14.7036
545.814	15.0818
549.305	14.6157
552.795	14.0993
556.282	12.0023
559.769	10.389
563.255	10.3935
566.739	9.61421
570.223	7.92906
573.705	5.56955
577.183	4.24657
580.663	3.61717
584.141	2.80267
587.615	2.36295
591.09	2.09966
594.564	2.43686
598.035	1.4673
601.506	2.84627
604.974	3.08882
608.443	3.94024
611.908	3.06365
615.374	3.46162
618.837	4.19941
622.3	4.74344
625.761	5.85752
629.219	7.71685
632.677	8.32451
636.135	9.39604
639.59	10.614
643.043	12.3662
646.495	14.483
649.948	14.7405
653.398	15.7826
656.846	16.7517
660.293	18.0507
663.738	19.6351
667.183	21.4694
670.626	23.0309
674.067	24.5454
677.508	26.1966
680.947	27.7889
684.385	29.0655
687.821	31.2404
691.254	32.6431
694.688	33.5129
698.121	34.4203
701.552	35.211
704.98	35.7137
708.409	37.7761
711.836	39.2749
715.26	40.3734
718.685	41.4098
722.108	42.7762
725.528	45.2671
728.949	46.17
732.367	47.0222
735.785	47.5005
739.2	48.5293
742.614	49.6108
746.028	51.097
749.439	52.9682
752.849	54.986
756.26	57.1787
759.667	58.813
763.073	61.0526
766.477	62.096
769.883	65.0466
773.285	66.5935
776.686	68.7561
780.085	69.4509
783.484	70.9501
786.881	71.0453
790.276	72.9781
793.671	74.949
797.064	78.6761
800.456	80.5936
803.846	81.9397
807.234	82.8046
810.622	82.7324
814.008	82.4877
817.394	82.08
820.778	80.4391
824.159	79.3575
827.541	78.3847
830.921	77.4814
834.298	76.4912
837.676	74.9926
841.051	71.7616
844.426	69.4156
847.798	67.3895
851.171	64.9386
854.54	61.8991
857.911	58.5626
861.278	56.8764
864.645	52.9077
868.01	51.453
871.373	50.9418
874.735	50.8112
878.097	50.8003
881.457	50.0041
884.815	49.0406
888.172	48.2141
891.528	47.859
894.882	48.2764
898.237	48.128
901.589	48.2676
904.94	48.4568
908.289	49.957
911.635	51.8417
914.982	51.7357
918.328	51.8875
921.672	50.9586
925.015	51.1242
928.357	50.9507
931.698	50.5179
935.035	48.2379
938.373	47.8993
941.71	46.4663
945.044	44.4279
948.378	42.2621
951.709	40.5445
955.041	38.2495
958.372	34.3033
961.699	32.661
965.027	30.8587
968.352	29.0678
971.676	28.3114
975	27.9082
978.322	26.8623
981.642	27.6066
984.962	26.6418
988.28	26.5765
991.596	26.0094
994.911	23.927
998.227	23.9566
1001.54	22.239
1004.85	21.7649
1008.16	21.9414
1011.47	22.1256
1014.78	20.5045
1018.08	19.036
1021.39	18.3543
1024.69	17.6937
1028	17.0783
1031.3	16.4545
1034.6	15.9035
1037.9	14.4095
1041.19	13.6247
1044.49	13.8925
1047.78	14.3168
1051.08	14.5348
1054.37	14.6388
1057.66	13.9852
1060.95	13.6003
1064.24	13.4033
1067.53	12.8274
1070.81	12.4102
1074.1	9.44676
1077.38	8.86969
1080.66	7.65709
1083.94	6.55614
1087.22	5.75555
1090.5	5.63482
1093.78	5.12438
1097.05	4.44772
1100.33	5.16601
1103.6	6.01123
1106.87	6.64968
1110.14	7.14748
1113.41	7.21503
1116.68	7.27856
1119.95	6.82025
1123.21	7.37164
1126.48	8.24657
1129.74	9.3451
1133	10.0985
1136.26	10.7234
1139.52	11.8965
1142.78	13.0466
1146.04	12.9116
1149.29	13.5466
1152.55	12.9717
1155.8	12.2426
1159.05	12.2991
1162.3	11.6575
1165.55	11.2606
1168.8	10.4363
1172.05	10.5824
1175.29	9.59651
1178.54	8.59431
1181.78	8.1728
1185.02	7.47668
1188.26	6.34385
1191.5	4.3784
1194.74	4.71254
1197.97	4.21771
1201.21	5.81179
1204.44	7.42822
1207.68	8.83753
1210.91	11.6703
1214.14	13.5535
1217.37	15.3914
1220.59	17.5216
1223.82	18.4934
1227.05	20.9928
1230.27	22.5545
1233.49	23.9468
1236.72	24.2989
1239.94	25.456
1243.16	25.6867
1246.37	26.1543
1249.59	25.8166
1252.8	25.2791
1256.02	25.6506
1259.23	25.6216
1262.44	24.4726
1265.66	23.9859
1268.86	23.2175
1272.07	23.5341
1275.28	24.6395
1278.48	25.7278
1281.69	27.1954
1284.89	28.5374
1288.09	29.9355
1291.29	30.2068
1294.49	32.038
1297.69	33.0702
1300.89	34.6893
1304.08	36.2666
1307.28	37.9752
1310.47	38.5409
1313.66	39.3882
1316.85	39.3955
1320.04	40.9276
1323.23	41.3697
1326.42	41.337
1329.61	41.0538
1332.79	41.0789
1335.97	41.1975
1339.16	40.5125
1342.34	39.6876
1345.52	39.0598
1348.7	37.5661
1351.87	36.0758
1355.05	35.1721
1358.22	33.5898
1361.4	32.768
1364.57	32.6638
1367.74	32.1231
1370.91	31.9955
1374.08	31.4586
1377.25	30.8902
1380.41	30.3203
1383.58	28.8647
1386.74	27.2202
1389.91	25.3889
1393.07	23.682
1396.23	22.0623
1399.39	21.1455
1402.55	19.3881
1405.7	18.8004
1408.86	20.2263
1412.01	20.5866
1415.17	21.9423
1418.32	22.5027
1421.47	24.2863
1424.62	25.8314
1427.77	29.0743
1430.91	31.2343
1434.06	34.3905
1437.2	37.4645
1440.35	40.9637
1443.49	43.2864
1446.63	44.6885
1449.77	45.3303
1452.91	44.9472
1456.05	44.6266
1459.18	44.6866
1462.32	42.7232
1465.45	40.9822
1468.59	38.684
1471.72	35.0994
1474.85	32.5323
1477.98	30.0417
1481.1	28.1807
1484.23	26.8649
1487.36	24.4436
1490.48	21.2838
1493.61	19.3709
1496.73	17.2606
1499.85	16.3462
1502.97	16.2915
1506.09	15.8034
1509.2	15.3809
1512.32	15.4277
1515.43	15.8557
1518.55	15.8547
1521.66	15.5545
1524.77	16.5265
1527.88	17.6567
1530.99	19.0361
1534.1	21.1025
1537.21	21.9541
1540.31	22.9552
1543.42	24.0098
1546.52	26.0781
1549.62	28.3603
1552.72	30.7838
1555.82	32.3553
1558.92	34.6559
1562.02	37.3872
1565.11	39.0496
1568.21	41.4656
1571.3	43.6894
1574.39	46.009
1577.49	48.7315
1580.57	50.1659
1583.66	50.524
1586.75	51.9677
1589.84	52.9892
1592.92	52.636
1596.01	52.5442
1599.09	52.2701
1602.17	51.2922
1605.25	50.4877
1608.33	49.6698
1611.41	48.1264
1614.49	46.1876
1617.57	45.0105
1620.64	44.1701
1623.72	43.8572
1626.79	43.7211
1629.86	42.7812
1632.93	42.4037
1636	43.1662
1639.07	42.5972
1642.13	42.8365
1645.2	43.3349
1648.26	43.2921
1651.33	43.7812
1654.39	42.4015
1657.45	41.7033
1660.51	41.4571
1663.57	41.2134
1666.63	40.2775
1669.68	38.6772
1672.74	37.1945
1675.79	36.3349
1678.85	34.4165
1681.9	32.9427
1684.95	30.6044
1688	28.0587
1691.05	25.16
1694.09	22.6517
1697.14	21.2652
1700.18	19.5182
1703.23	17.7228
1706.27	16.0534
1709.31	14.8664
1712.35	13.3986
1715.39	13.4186
1718.43	12.6309
1721.47	12.4424
1724.5	11.9756
1727.54	11.7535
1730.57	12.0882
1733.61	12.8192
1736.64	12.9989
1739.67	13.0912
1742.7	13.2865
1745.72	12.497
1748.75	12.976
1751.77	12.1727
1754.8	11.4825
1757.82	10.3485
1760.84	10.3242
1763.87	9.58299
1766.89	9.71647
1769.91	10.0571
1772.92	10.3327
1775.94	10.3009
1778.95	10.4613
1781.97	10.3252
1784.98	9.92337
1787.99	9.71236
1791.01	8.78571
1794.01	8.33438
1797.02	8.4182
1800.03	8.1891
1803.04	7.79203
1806.04	7.82786
1809.05	7.42577
1812.05	6.19969
1815.05	6.27008
1818.05	5.1111
1821.05	5.12649
1824.05	4.79328
1827.05	3.83835
1830.04	3.34518
1833.04	3.38623
1836.03	3.46145
1839.03	3.84255
1842.02	3.77532
1845.01	3.30357
1848	2.67074
1850.99	2.08391
1853.97	1.37289
1856.96	0.290064
1859.94	0.209894
1862.93	-1.05916
1865.91	-1.79306
1868.89	-0.861337
1871.87	-0.838732
1874.85	0.0456367
1877.83	0.446899
1880.81	1.21096
1882.57	1.71944
1885.56	1.49574
1888.55	1.69961
1891.54	2.9058
1894.52	3.58533
1897.51	4.57748
1900.49	5.2509
1903.47	5.80996
1906.45	5.9073
1909.43	5.52758
1912.41	5.6837
1915.39	6.15639
1918.37	5.50413
1921.34	5.28344
1924.32	4.36022
1927.29	4.02036
1930.26	3.58057
1933.23	3.07262
1936.2	2.89649
1939.17	4.15982
1942.14	3.77128
1945.11	4.06523
1948.07	4.8214
1951.04	4.84399
1954	4.35755
1956.96	4.52362
1959.93	4.31953
1962.89	5.18616
1965.85	6.08783
1968.8	6.33304
1971.76	5.31682
1974.72	4.44422
1977.67	3.52352
1980.63	3.54327
1983.58	4.22409
1986.53	4.61013
1989.48	4.8368
1992.43	3.88704
1995.38	3.32108
1998.32	3.36659
2001.27	2.58053
2004.22	2.8763
2007.16	3.01003
2010.1	4.0501
2013.04	3.62772
2015.98	3.27525
2018.92	3.24073
2021.86	4.12826
2024.8	4.38991
2027.74	4.26397
2030.67	5.15112
2033.61	5.44215
2036.54	5.82885
2039.47	5.99994
2042.4	6.29159
2045.33	5.87177
2048.26	6.77177
2051.19	8.22653
2054.12	8.84643
2057.04	10.2091
2059.97	9.7067
2062.89	10.0963
2065.81	10.4417
2068.73	9.96971
2071.65	10.4405
2074.57	9.79336
2077.49	10.3379
2080.41	10.2644
2083.32	9.90717
2086.24	9.7242
2089.15	9.85987
2092.07	10.2713
2094.98	10.1881
2097.89	10.3385
2100.8	10.735
2103.71	11.0873
2106.61	10.8018
2109.52	11.9157
2112.43	12.1205
2115.33	12.4177
2118.23	12.5161
2121.13	12.6245
2124.04	13.3588
2126.94	13.3498
2129.83	13.2576
2132.73	13.6912
2135.63	14.4407
2138.53	14.1541
2141.42	14.0137
2144.31	14.2386
2147.21	14.2026
2150.1	14.9066
2152.99	14.9376
2155.88	15.579
2158.77	16.6629
2161.65	17.0779
2164.54	17.2825
2167.43	17.6239
2170.31	17.9887
2173.19	18.0288
2176.07	18.5928
2178.96	19.2498
2181.84	18.7457
2184.72	18.0736
2187.59	17.3097
2190.47	17.0995
2193.35	15.9596
2196.22	15.0395
2199.09	15.0275
2201.97	13.4137
2204.84	12.6218
2207.71	11.6488
2210.58	11.0214
2213.45	10.1992
2216.31	9.44972
2219.18	8.86333
2222.05	7.83537
2224.91	7.53169
2227.78	7.39916
2230.64	6.65649
2233.5	7.25608
2236.36	6.94837
2239.22	7.15634
2242.08	6.89756
2244.93	6.67382
2247.79	7.69337
2250.64	6.9457
2253.5	7.27926
2256.35	7.38397
2259.2	7.03617
2262.05	7.09056
2264.9	7.29282
2267.75	6.52805
2270.6	6.3534
2273.45	6.56438
2276.29	6.49093
2279.14	6.16289
2281.98	6.67407
2284.82	6.13798
2287.66	5.88475
2290.5	4.90012
2293.34	4.46267
2296.18	4.38139
2299.02	5.42161
2301.86	6.17945
2304.69	6.9217
2307.53	7.22559
2310.36	7.63149
2313.19	7.87324
2316.02	8.18517
2318.85	8.51953
2321.68	8.1764
2324.51	8.17107
2327.34	7.67245
2330.16	7.02368
2332.99	7.45519
2335.81	7.3083
2338.64	7.24819
2341.46	6.50802
2344.28	5.86652
2347.1	5.06662
2349.92	4.37388
2352.74	3.8889
2355.55	2.64945
2358.37	2.03974
2361.19	1.62288
2364	2.71898
2366.81	3.55289
2369.62	3.75711
2372.44	3.86974
2375.24	4.16985
2378.05	3.33333
2380.86	2.6474
2383.67	2.80725
2386.47	3.27186
2389.28	3.00011
2392.08	3.66258
2394.89	3.94318
2397.69	4.3779
2400.49	5.23933
2403.29	6.13482
2406.09	5.3598
2408.88	4.21069
2411.68	4.55088
2414.48	4.71311
2417.27	4.84545
2420.06	5.48167
2422.86	5.53535
2425.65	5.17124
2428.44	5.8824
2431.23	6.34869
2434.02	6.23251
2436.81	5.83034
2439.59	5.29654
2442.38	4.8152
2445.16	4.25135
2447.95	3.59743
2450.73	2.48706
2453.51	2.52748
2456.29	1.89971
2459.07	2.12652
2461.85	1.77687
2464.63	1.48055
2467.4	1.77669
2470.18	1.15452
2472.95	1.44291
2475.73	1.03006
2478.5	1.57585
2481.27	2.01029
2484.04	2.0088
2486.81	2.22195
2489.58	2.31366
2492.35	1.6248
2495.12	2.0897
2497.88	2.1653
2500.65	2.55044
2503.41	1.59991
2506.17	1.66118
2508.94	1.889
2511.7	1.36099
2514.46	1.50655
2517.22	1.52381
2519.97	1.94941
2522.73	2.57139
2525.49	2.72337
2528.24	3.40244
2530.99	3.07005
2533.75	4.50318
2536.5	5.48523
2539.25	6.65319
2542	6.38948
2544.75	5.74188
2547.5	4.88758
2550.24	4.10202
2552.99	3.56881
2555.74	3.52353
2558.48	3.31317
2561.22	3.06211
2563.96	2.7124
2566.71	2.48303
2569.45	2.20628
2572.18	1.70089
2574.92	2.27741
2577.66	1.85524
2580.4	2.13467
2583.13	2.32167
2585.87	2.34337
2588.6	2.72051
2591.33	2.98103
2594.06	2.42951
2596.79	2.04833
2599.52	2.22732
2602.25	2.44733
2604.98	2.37563
2607.71	1.22817
2610.43	0.749209
2613.16	0.212433
2615.88	-0.0932125
2618.6	-0.113453
2621.32	0.595155
2624.04	0.681733
2626.76	1.77709
2629.48	1.79863
2632.2	2.1711
2634.92	2.03387
2637.63	2.95736
2640.35	3.72748
2643.06	4.23189
2645.77	4.20212
2648.49	4.85519
2651.2	4.95179
2653.91	4.98336
2656.62	4.19414
2659.33	2.78242
2662.03	2.75769
2664.74	2.77781
2667.44	2.28616
2670.15	1.70459
2672.85	1.52269
2675.55	0.957014
2678.26	0.856783
2680.96	0.518935
2683.66	0.93948
2686.35	0.613524
2689.05	0.961737
2691.75	1.35815
2694.44	1.84878
2697.14	2.27602
2699.83	1.65789
2702.52	2.5751
2705.22	4.28181
2707.91	4.15103
2710.6	4.30563
2713.29	4.00891
2715.97	3.71689
2718.66	3.08058
2721.35	3.10749
2724.03	2.80587
2726.72	3.15944
2729.4	3.41803
2732.08	3.65017
2734.76	3.5284
2737.44	3.50105
2740.12	3.6235
2742.8	3.61182
2745.48	3.64415
2748.16	3.77991
2750.83	3.58706
2753.51	3.15512
2756.18	3.29683
2758.85	3.56824
2761.53	3.40818
2764.2	3.63225
2766.87	3.86349
2769.54	4.70314
2772.2	4.77451
2774.87	4.2664
2777.54	3.83789
2780.2	4.0883
2782.87	3.72447
2785.53	3.69726
2788.19	3.76306
2790.85	4.43517
2793.51	4.32209
2796.17	3.942
2798.83	3.27029
2801.49	2.68016
2804.15	1.70966
2806.8	1.28924
2809.46	0.814423
2812.11	0.591251
2814.76	0.236934
2817.42	0.749423
2820.07	1.17093
2822.72	2.18235
2825.37	2.31923
2828.02	3.70053
2830.66	4.72625
2833.31	5.97012
2835.96	7.00689
2838.6	9.02477
2841.24	10.3157
2843.89	12.0894
2846.53	14.6002
2849.17	16.9882
2851.81	19.2195
2854.45	21.2653
2857.09	22.6198
2859.72	23.8259
2862.36	25.4317
2865	27.1674
2867.63	29.9636
2870.26	32.366
2872.9	34.0409
2875.53	35.9835
2878.16	37.6383
2880.79	39.3453
2883.42	41.7377
2886.05	43.4809
2888.67	45.0072
2891.3	46.1273
2893.92	47.2968
2896.55	48.6749
2899.17	50.46
2901.79	53.3712
2904.42	54.6254
2907.04	56.7939
2909.66	60.0686
2912.27	62.2072
2914.89	64.5987
2917.51	66.6025
2920.13	67.9588
2922.74	69.2827
2925.35	71.0395
2927.97	72.3303
2930.58	73.1807
2933.19	73.1439
2935.8	72.6287
2938.41	71.6413
2941.02	70.6201
2943.63	69.3136
2946.24	68.0579
2948.84	66.7863
2951.45	64.5499
2954.05	61.8796
2956.65	59.546
2959.26	56.9511
2961.86	54.8817
2964.46	51.9767
2967.06	49.8903
2969.66	47.5913
2972.25	46.3718
2974.85	44.4031
2977.45	40.8493
2980.04	38.2523
2982.64	36.0166
2985.23	33.1737
2987.82	30.4293
2990.41	27.6909
2993	25.3198
2995.59	23.5126
2998.18	21.4609
3000.77	19.6065
3003.36	17.8252
3005.94	16.9749
3008.53	15.145
3011.11	14.1189
3013.69	12.9621
3016.28	12.0295
3018.86	11.2477
3021.44	9.54221
3024.02	9.27217
3026.6	8.20457
3029.18	7.99913
3031.75	8.43696
3034.33	8.58856
3036.9	8.23934
3039.48	7.08828
3042.05	6.46863
3044.62	6.49014
3047.19	6.8477
3049.77	6.63001
3052.34	7.05432
3054.9	7.15047
3057.47	7.08349
3060.04	6.87113
3062.61	7.09612
3065.17	6.91138
3067.74	7.33452
3070.3	6.60232
3072.86	6.17387
3075.42	6.41479
3077.99	6.08466
3080.54	5.79244
3083.1	4.89204
3085.66	4.01345
3088.22	3.5426
3090.78	3.0327
3093.33	2.67397
3095.89	3.45844
3098.44	2.73149
3100.99	2.80773
3103.54	2.27729
3106.1	2.4857
3108.65	2.88037
3111.2	2.96772
3113.74	3.11437
3116.29	2.77668
3118.84	2.60062
3121.38	2.73187
3123.93	2.45688
3126.47	2.61654
3129.01	2.79364
3131.56	2.29075
3134.1	2.24847
3136.64	1.85987
3139.18	0.822183
3141.72	-0.293486
3144.26	-1.43387
3146.79	-1.9838
3149.33	-1.08288