File: data/Raman/poly_smoothed/Thy_20_09_03_1x_45s_532 nm_x100_100%_600 gr_mm_01.txt
#Acq. time (s)=	45
#Accumulations=	2
#Range (cm-¹)=	200...3150
#Windows=	2
#Auto scanning=	Off
#Autofocus=	Off
#Macrospot=	Off
#AutoExposure=	Off
#Spike filter=	Multiple accum.
#Delay time (s)=	0
#Binning=	1
#Readout mode=	Signal
#DeNoise=	Off
#ICS correction=	On
#Dark correction=	Off
#Inst. Process=	Off
#Detector Gain=	Best Dynamic Range
#Detector ADC=	20 kHz
#Detector temperature (°C)=	-69.85
#Instrument=	LabRAM HR Evol
#Detector=	Synapse
#Objective=	x100
#Grating=	600 gr/mm
#ND Filter=	100%
#Laser (nm)=	532
#Hole=	100.021
#Range=	Auto
#Laser Pol.=	No
#Raman. Pol.=	No
#Laser Pol. (°)=	-0.0007625
#Raman Pol. (°)=	89.9995
#Collection=	Microscope
#StageXY=	Marzhauser
#StageZ=	Marzhauser
#X (µm)=	-5924.4
#Y (µm)=	2830.8
#Z (µm)=	-223.35
#Full time(mm:ss)=	3:05
#Project=
#Sample=
#Site=
#Title=	Thy_20_09_03_2x_45s_532 nm_x100_100%_600 gr_mm
#Remark=
#Date=	29.06.2022 10:56
#Acquired=	29.06.2022 10:56:09
#Base:Fit=	10.08.2022 09:49:32
#Base:Fit=	10.08.2022 09:49:42
#Base:Fit=	10.08.2022 09:49:53
#Base:Fit=	10.08.2022 09:50:12
#Base:Fit=	10.08.2022 09:50:26
#Base:Fit=	10.08.2022 09:50:30
#Base:Fit=	10.08.2022 09:50:43
#Base:Fit=	10.08.2022 09:52:02
#Base:Fit=	10.08.2022 09:52:12
#Base:Sub=	10.08.2022 09:54:21
#Filter:Polynom=	16.08.2022 10:24:04
#AxisType[0]=Intens
#AxisUnit[0]=Cnt
#AxisType[1]=Spectr
#AxisUnit[1]=1/cm
200.523	22.7171
204.154	16.2149
207.781	11.8061
211.409	9.82144
215.034	8.01659
218.659	8.17582
222.281	5.25589
225.903	4.20972
229.522	4.95144
233.14	4.38379
236.756	3.72891
240.373	3.67592
243.986	1.49261
247.598	2.87905
251.208	4.04329
254.818	2.75337
258.427	3.77215
262.034	4.00378
265.638	4.20017
269.242	4.1388
272.844	5.30318
276.445	4.53432
280.044	2.79498
283.642	5.91255
287.238	7.29835
290.833	9.46657
294.425	10.545
298.017	11.9595
301.608	13.1746
305.198	13.9391
308.786	14.6522
312.371	15.2462
315.956	15.232
319.54	15.4819
323.122	15.1238
326.701	14.2215
330.281	14.0651
333.857	14.6964
337.434	15.2602
341.008	15.3556
344.582	14.4935
348.153	15.4896
351.724	16.5929
355.292	14.7167
358.861	13.4039
362.426	11.9965
365.99	12.2997
369.555	12.6896
373.116	13.3835
376.676	12.5141
380.236	12.0094
383.793	10.803
387.349	11.5956
390.903	10.7823
394.456	10.0473
398.007	9.78091
401.56	9.15218
405.108	7.7686
408.656	8.34518
412.202	7.32526
415.746	7.03463
419.29	7.45117
422.831	6.96729
426.37	6.8996
429.909	7.36197
433.447	8.38878
436.983	8.23167
440.519	8.01645
444.052	7.14812
447.583	9.19119
451.114	10.2554
454.643	10.0638
458.169	10.7587
461.696	11.9232
465.222	12.935
468.744	13.4096
472.267	13.1565
475.787	15.0574
479.307	15.1289
482.823	16.5082
486.341	16.382
489.855	16.8675
493.37	17.6448
496.881	17.3194
500.391	17.0462
503.902	16.4415
507.409	14.0295
510.915	14.1708
514.42	14.5099
517.925	15.4298
521.427	16.5781
524.928	15.3829
528.427	15.436
531.925	14.8729
535.422	13.5454
538.917	11.6
542.411	10.4896
545.903	9.14936
549.395	8.38393
552.884	7.04115
556.373	6.23967
559.86	5.57878
563.346	6.02642
566.831	5.32053
570.314	6.17972
573.794	6.53811
577.274	6.69905
580.754	6.99454
584.23	7.75348
587.706	7.60209
591.181	7.77576
594.653	7.07675
598.126	8.53789
601.595	9.06569
605.065	9.44051
608.532	12.5033
611.999	12.0605
615.463	11.5314
618.928	10.1565
622.389	10.3841
625.851	10.2345
629.31	8.15389
632.767	8.122
636.223	8.31713
639.68	11.3839
643.134	10.7942
646.586	11.316
650.037	12.3081
653.486	13.6574
656.936	14.7618
660.383	14.9469
663.829	16.4473
667.273	17.9427
670.716	19.1667
674.158	20.7961
677.598	21.9014
681.035	22.5062
684.473	26.2513
687.909	28.2596
691.344	30.0729
694.778	31.5204
698.211	30.8239
701.64	30.231
705.07	31.1261
708.498	32.5902
711.924	34.6346
715.35	34.953
718.774	37.3269
722.196	39.2819
725.618	39.9841
729.037	39.6993
732.456	39.8761
735.873	41.2213
739.289	42.8654
742.703	44.9664
746.116	47.9611
749.529	52.1899
752.938	56.5734
756.347	60.3379
759.756	63.0725
763.162	66.1851
766.567	70.5253
769.97	73.1579
773.372	74.2888
776.773	76.232
780.174	78.1925
783.573	80.0798
786.97	80.9845
790.365	84.5461
793.76	85.6879
797.153	86.3924
800.543	86.6059
803.933	87.6971
807.322	87.5614
810.71	86.2432
814.097	86.4475
817.483	86.9896
820.865	88.4779
824.248	89.5712
827.629	89.4153
831.008	90.8598
834.387	90.0565
837.765	88.324
841.139	86.3331
844.514	83.8447
847.886	82.9428
851.259	79.7173
854.629	78.1154
857.997	75.4925
861.366	74.4263
864.732	73.2954
868.098	70.388
871.461	70.6894
874.823	70.2879
878.184	68.1512
881.545	66.9076
884.903	65.7552
888.26	63.7161
891.616	62.0959
894.97	62.8291
898.323	61.1841
901.675	59.9025
905.026	59.0321
908.375	58.3247
911.723	58.6607
915.07	57.2881
918.415	56.8012
921.76	55.5793
925.103	55.9536
928.443	55.2673
931.783	54.6636
935.123	53.7772
938.461	52.8812
941.796	50.7597
945.131	49.5617
948.465	48.0054
951.797	46.9551
955.128	45.6072
958.457	40.5001
961.786	39.1801
965.113	35.3015
968.44	34.3919
971.763	31.9404
975.086	31.1724
978.409	30.2233
981.729	29.3434
985.048	29.1086
988.367	30.145
991.683	30.9321
994.998	30.5512
998.312	29.0733
1001.62	29.479
1004.94	29.9113
1008.25	29.1982
1011.56	28.6004
1014.86	27.883
1018.17	24.9922
1021.48	21.6976
1024.78	19.1085
1028.08	18.5213
1031.38	16.9573
1034.68	14.2644
1037.98	10.1249
1041.28	7.92827
1044.57	9.03907
1047.87	8.58085
1051.16	10.1566
1054.45	12.0282
1057.75	12.5488
1061.04	12.577
1064.32	14.0649
1067.61	16.1364
1070.9	18.1783
1074.18	19.077
1077.47	19.9162
1080.75	19.7579
1084.03	18.8892
1087.31	20.2505
1090.59	21.3408
1093.86	21.4619
1097.14	20.6782
1100.41	19.2075
1103.69	18.6289
1106.96	19.8522
1110.23	18.9725
1113.5	17.9659
1116.77	17.3795
1120.03	19.3103
1123.3	19.5466
1126.56	18.1704
1129.83	17.7084
1133.09	17.9397
1136.35	17.3346
1139.61	16.2605
1142.86	16.8519
1146.12	16.5466
1149.38	15.3728
1152.63	12.5696
1155.88	10.6628
1159.14	7.54181
1162.39	6.66521
1165.63	6.36729
1168.88	6.42535
1172.13	7.45897
1175.38	7.19799
1178.62	6.6871
1181.86	8.42699
1185.1	9.27754
1188.34	11.4022
1191.58	12.297
1194.82	15.6734
1198.06	16.3536
1201.29	18.4677
1204.53	18.8305
1207.76	20.4403
1210.99	23.1962
1214.22	25.956
1217.45	27.9285
1220.68	31.7228
1223.91	32.8075
1227.13	35.0304
1230.36	36.0919
1233.58	38.32
1236.8	40.9777
1240.02	43.8006
1243.24	46.1643
1246.46	48.336
1249.67	50.4037
1252.89	51.9069
1256.1	52.0585
1259.32	52.5778
1262.53	53.6134
1265.74	53.0673
1268.95	54.525
1272.15	54.7144
1275.36	58.4269
1278.57	59.2873
1281.77	61.0607
1284.97	61.6775
1288.18	63.5175
1291.38	65.2307
1294.58	67.2651
1297.78	67.7432
1300.97	69.803
1304.17	71.5093
1307.36	73.9036
1310.55	75.857
1313.75	76.5694
1316.94	78.1353
1320.13	79.3905
1323.32	78.4924
1326.5	78.2475
1329.69	77.1472
1332.87	74.6402
1336.06	73.6504
1339.24	70.8206
1342.42	70.6873
1345.6	68.3953
1348.78	68.1286
1351.96	67.1192
1355.13	65.023
1358.31	62.3907
1361.48	60.4726
1364.65	56.9257
1367.82	55.576
1370.99	55.1727
1374.16	52.9804
1377.33	52.603
1380.5	52.7533
1383.66	51.0668
1386.83	49.3789
1389.99	48.8089
1393.15	45.6648
1396.31	45.6098
1399.47	45.5047
1402.63	44.5116
1405.78	43.1519
1408.94	44.0781
1412.1	44.0998
1415.25	45.9185
1418.4	47.297
1421.55	52.3668
1424.7	54.5334
1427.85	57.1407
1431	60.3423
1434.14	63.4605
1437.29	66.044
1440.43	68.8182
1443.57	70.8521
1446.71	73.1218
1449.85	72.6218
1452.99	70.9863
1456.13	67.4548
1459.26	65.1051
1462.4	61.4315
1465.54	57.9881
1468.67	53.0634
1471.8	48.4552
1474.93	43.5632
1478.06	38.2108
1481.19	32.5568
1484.31	28.7208
1487.44	25.2921
1490.56	22.004
1493.69	20.9943
1496.81	20.5632
1499.93	20.9685
1503.05	18.922
1506.17	20.8899
1509.28	21.4842
1512.4	22.242
1515.52	23.0083
1518.63	24.3178
1521.74	26.8771
1524.85	26.9318
1527.96	28.0662
1531.07	29.8686
1534.18	31.63
1537.29	34.0647
1540.39	36.5767
1543.5	38.0866
1546.6	39.8535
1549.7	42.3969
1552.8	44.0508
1555.9	44.7878
1559	47.1099
1562.1	48.6511
1565.19	50.9909
1568.29	53.0167
1571.38	55.4933
1574.47	55.7745
1577.56	57.4826
1580.66	60.681
1583.74	61.7611
1586.83	63.7263
1589.92	65.1625
1593.01	65.6556
1596.09	66.4862
1599.17	66.1336
1602.25	67.6033
1605.34	65.6104
1608.41	64.9751
1611.49	63.6152
1614.57	60.8454
1617.65	60.2713
1620.72	59.1982
1623.79	57.7341
1626.87	56.4564
1629.94	54.6682
1633.01	53.3069
1636.08	54.2666
1639.15	55.3817
1642.21	57.587
1645.28	57.3905
1648.34	57.4459
1651.41	57.7541
1654.47	60.1939
1657.53	59.8198
1660.59	59.4633
1663.65	58.9076
1666.71	56.7112
1669.76	56.1511
1672.82	53.0794
1675.87	49.9007
1678.93	45.9485
1681.98	41.0513
1685.03	35.3224
1688.08	31.1834
1691.13	25.9658
1694.17	21.5388
1697.22	18.0653
1700.27	14.6761
1703.31	12.456
1706.35	9.73032
1709.39	8.6623
1712.43	8.68731
1715.47	7.32315
1718.51	6.99127
1721.55	6.35199
1724.58	7.23637
1727.62	7.83301
1730.65	8.64201
1733.68	8.44868
1736.72	9.62664
1739.74	9.96852
1742.77	10.3311
1745.8	10.1338
1748.83	9.46065
1751.85	8.92712
1754.88	8.05534
1757.9	7.12539
1760.92	5.66316
1763.95	4.57619
1766.96	3.90356
1769.98	2.96754
1773	2.1743
1776.02	2.07882
1779.03	2.04492
1782.05	1.27354
1785.06	2.48002
1788.07	2.50369
1791.08	3.10698
1794.09	3.98599
1797.1	3.56531
1800.11	3.95293
1803.12	4.53472
1806.12	5.00258
1809.12	5.34802
1812.13	7.00291
1815.13	7.54782
1818.13	8.13035
1821.13	7.432
1824.13	7.42027
1827.13	6.581
1830.12	5.87656
1833.12	5.75135
1836.11	4.61951
1839.1	3.34145
1842.09	2.51745
1845.09	2.20266
1848.08	2.40949
1851.06	2.71157
1854.05	3.50702
1857.04	3.43373
1860.02	3.3455
1863.01	2.47134
1865.99	2.79317
1868.97	1.86078
1871.95	1.7494
1874.93	2.88499
1877.91	3.71128
1880.89	4.28065
1882.46	4.59617
1885.45	4.33522
1888.43	4.52776
1891.42	5.14386
1894.41	4.83525
1897.39	3.89517
1900.37	3.70878
1903.36	3.97761
1906.34	3.42591
1909.32	2.42607
1912.29	1.74104
1915.27	2.88731
1918.25	3.72002
1921.23	5.13987
1924.2	5.89305
1927.17	6.28506
1930.15	5.65552
1933.12	6.24834
1936.09	6.75217
1939.06	5.82926
1942.02	5.04564
1944.99	5.65927
1947.96	6.72125
1950.92	6.31037
1953.88	7.09202
1956.85	7.97212
1959.81	6.86607
1962.77	8.31916
1965.73	8.38195
1968.69	7.50919
1971.64	6.68083
1974.6	6.69352
1977.55	5.63137
1980.51	5.1346
1983.46	4.73191
1986.41	4.82127
1989.36	4.69056
1992.31	4.8035
1995.26	4.68876
1998.21	5.02847
2001.15	4.5014
2004.1	3.59157
2007.04	3.51368
2009.99	3.36034
2012.93	2.85552
2015.87	2.53839
2018.81	3.68485
2021.75	3.7624
2024.68	4.11309
2027.62	4.27009
2030.56	4.84077
2033.49	4.1874
2036.42	5.59224
2039.36	5.90202
2042.29	5.69388
2045.22	5.46825
2048.14	5.57001
2051.07	4.69904
2054	4.5472
2056.93	4.38465
2059.85	3.75653
2062.77	5.04675
2065.7	3.97946
2068.62	3.76833
2071.54	3.19467
2074.46	2.72545
2077.38	2.92493
2080.29	2.97903
2083.21	3.6631
2086.12	4.29358
2089.04	5.6853
2091.95	6.77284
2094.86	7.78269
2097.77	8.66179
2100.68	9.14392
2103.59	9.92935
2106.5	10.5605
2109.41	12.2886
2112.31	14.186
2115.21	16.3344
2118.12	16.1907
2121.02	16.8909
2123.92	18.1756
2126.82	19.0106
2129.72	19.6895
2132.62	20.7921
2135.51	21.6532
2138.41	21.9379
2141.31	22.4984
2144.2	23.7792
2147.09	24.7948
2149.98	25.8025
2152.87	27.6755
2155.76	28.7652
2158.65	31.6034
2161.54	34.1674
2164.43	36.2098
2167.31	36.9925
2170.2	37.9976
2173.08	38.3885
2175.96	40.4214
2178.84	41.4646
2181.72	43.0136
2184.6	43.3524
2187.48	42.103
2190.36	40.7486
2193.23	38.8692
2196.11	37.3139
2198.98	35.8102
2201.85	33.6469
2204.72	31.1369
2207.59	28.3811
2210.46	25.6307
2213.33	23.4685
2216.2	20.7307
2219.07	19.2881
2221.93	18.0705
2224.8	16.752
2227.66	16.3321
2230.52	16.2393
2233.39	16.8211
2236.25	16.4538
2239.1	15.2418
2241.96	15.7047
2244.82	16.0632
2247.68	16.227
2250.53	16.0951
2253.38	16.9926
2256.24	17.3574
2259.09	16.9573
2261.94	16.6272
2264.79	16.0744
2267.64	15.7699
2270.49	14.8947
2273.33	14.0333
2276.18	13.9518
2279.02	12.5797
2281.87	11.3173
2284.71	11.0346
2287.55	11.3125
2290.39	10.1266
2293.23	8.00095
2296.07	6.34947
2298.91	6.95147
2301.74	7.56509
2304.58	8.05174
2307.41	8.40975
2310.25	8.89297
2313.08	9.18695
2315.91	9.18076
2318.74	9.65228
2321.57	10.6551
2324.4	10.3689
2327.23	10.0825
2330.05	9.65867
2332.88	9.2648
2335.7	7.24549
2338.52	6.59735
2341.35	5.85894
2344.17	5.73386
2346.99	5.09617
2349.81	5.39158
2352.62	4.07822
2355.44	3.70752
2358.26	2.17856
2361.07	0.65986
2363.89	-0.228658
2366.7	0.855491
2369.51	0.884269
2372.32	1.04267
2375.13	2.40242
2377.94	2.66185
2380.75	3.18835
2383.56	3.21629
2386.36	3.71519
2389.17	4.16603
2391.97	3.4537
2394.77	2.67142
2397.58	3.7294
2400.38	3.29128
2403.18	2.97092
2405.97	3.46877
2408.77	3.64462
2411.57	3.784
2414.37	5.00345
2417.16	5.64707
2419.95	5.82098
2422.75	5.66059
2425.54	5.70228
2428.33	6.00286
2431.12	5.92662
2433.91	6.39174
2436.7	6.27371
2439.48	6.21716
2442.27	6.77841
2445.05	7.68336
2447.84	7.03835
2450.62	6.14207
2453.4	6.434
2456.18	6.58177
2458.96	5.92344
2461.74	5.5738
2464.52	5.96715
2467.29	6.0673
2470.07	6.1203
2472.85	5.41798
2475.62	4.35024
2478.39	3.90023
2481.16	3.30401
2483.93	3.78334
2486.7	2.8704
2489.47	3.1478
2492.24	2.80953
2495.01	2.55696
2497.77	2.1687
2500.54	1.64809
2503.3	1.5475
2506.06	0.580661
2508.83	0.852307
2511.59	1.0159
2514.35	1.30415
2517.11	2.71535
2519.86	3.63392
2522.62	5.18907
2525.38	6.85721
2528.13	7.76418
2530.89	9.7496
2533.64	11.7464
2536.39	12.2121
2539.14	13.1473
2541.89	12.6465
2544.64	11.9918
2547.39	12.0672
2550.14	11.8596
2552.88	11.7761
2555.63	11.2037
2558.37	10.0077
2561.11	9.31843
2563.86	9.7962
2566.6	8.68076
2569.34	6.8345
2572.08	6.44651
2574.82	5.53509
2577.55	5.30479
2580.29	5.23989
2583.02	4.86065
2585.76	4.11777
2588.49	4.03997
2591.22	4.01546
2593.96	4.04085
2596.69	4.60898
2599.42	5.36946
2602.14	4.66264
2604.87	4.72462
2607.6	5.1725
2610.32	4.88088
2613.05	5.63682
2615.77	4.64016
2618.49	5.39205
2621.22	5.50845
2623.94	5.53477
2626.66	6.52121
2629.37	7.62362
2632.09	7.41061
2634.81	7.80679
2637.53	7.96002
2640.24	9.29638
2642.96	8.82119
2645.67	9.55951
2648.38	9.14199
2651.09	9.2533
2653.8	9.28947
2656.51	8.92394
2659.22	9.58186
2661.93	9.65733
2664.63	9.66706
2667.34	9.5904
2670.04	10.194
2672.75	10.4944
2675.45	11.0615
2678.15	10.429
2680.85	9.60049
2683.55	9.38865
2686.25	10.3036
2688.94	10.013
2691.64	10.5622
2694.34	10.5188
2697.03	10.0425
2699.73	11.1891
2702.42	11.1114
2705.11	11.9059
2707.8	11.4193
2710.49	12.3177
2713.18	12.1236
2715.87	11.1125
2718.55	10.8745
2721.24	10.5161
2723.93	10.48
2726.61	9.32281
2729.29	8.99351
2731.98	8.71004
2734.66	8.84686
2737.34	8.33171
2740.02	7.93408
2742.7	6.74318
2745.37	6.40833
2748.05	6.62939
2750.72	5.66412
2753.4	4.67485
2756.07	4.94132
2758.75	4.56091
2761.42	4.21532
2764.09	3.76383
2766.76	2.53115
2769.43	2.28235
2772.1	1.65992
2774.76	1.70982
2777.43	1.34979
2780.1	1.15505
2782.76	0.927921
2785.42	0.873827
2788.09	0.53237
2790.75	-0.279717
2793.41	-0.0975647
2796.07	-0.00436344
2798.73	0.450734
2801.39	-0.792712
2804.04	-0.793882
2806.7	-2.11363
2809.35	-2.36816
2812.01	-1.75339
2814.66	-2.23948
2817.31	-1.67074
2819.96	0.0153816
2822.61	2.26342
2825.26	5.02668
2827.91	8.15281
2830.56	11.7599
2833.21	15.1641
2835.85	19.1365
2838.5	23.7928
2841.14	29.0178
2843.78	34.1048
2846.42	40.698
2849.06	47.3826
2851.71	53.227
2854.34	60.0291
2856.98	66.8965
2859.62	72.3953
2862.26	78.443
2864.89	84.0999
2867.53	88.1189
2870.16	92.3595
2872.79	96.0329
2875.42	99.5813
2878.05	102.141
2880.68	105.564
2883.31	108.784
2885.94	112.431
2888.57	115.389
2891.19	118.116
2893.82	120.942
2896.44	124.623
2899.07	128.035
2901.69	132.836
2904.31	137.544
2906.93	143.574
2909.55	150.786
2912.17	157.599
2914.79	164.636
2917.41	170.326
2920.02	176.455
2922.64	179.693
2925.25	183.19
2927.86	185.779
2930.48	185.677
2933.09	184.027
2935.7	181.956
2938.31	178.151
2940.92	172.764
2943.53	167.549
2946.13	162.026
2948.74	155.683
2951.34	149.357
2953.95	141.602
2956.55	134.513
2959.15	127.121
2961.75	119.733
2964.35	112.96
2966.95	107.553
2969.55	102.065
2972.15	96.8505
2974.75	92.7814
2977.34	87.0629
2979.94	82.0515
2982.53	75.3194
2985.13	68.2581
2987.72	62.5814
2990.31	55.8662
2992.9	49.6367
2995.49	42.5799
2998.08	37.0294
3000.67	32.2272
3003.25	25.5586
3005.84	20.9958
3008.42	17.1714
3011.01	12.6263
3013.59	9.58595
3016.17	6.40133
3018.76	3.30957
3021.34	1.73332
3023.92	0.967105
3026.49	-0.307525
3029.07	-0.212637
3031.65	-0.00455449
3034.23	0.570464
3036.8	2.10514
3039.38	3.39384
3041.95	3.39073
3044.52	3.96847
3047.09	5.05572
3049.66	6.13242
3052.23	6.1574
3054.8	6.73046
3057.37	6.99051
3059.94	6.564
3062.5	7.1188
3065.07	6.85277
3067.63	5.79551
3070.2	5.57841
3072.76	4.74195
3075.32	5.15074
3077.88	4.30934
3080.44	3.52891
3083	3.30305
3085.56	2.43845
3088.12	1.56984
3090.67	1.22965
3093.23	0.393096
3095.78	0.222051
3098.34	0.452521
3100.89	0.450797
3103.44	0.95101
3105.99	0.540576
3108.54	1.69679
3111.09	3.41155
3113.64	3.82397
3116.19	5.50705
3118.74	6.65064
3121.28	7.70878
3123.83	8.90261
3126.37	11.1575
3128.91	12.9219
3131.46	13.5402
3134	15.2002
3136.54	17.3447
3139.08	18.7906
3141.62	18.7223
3144.16	18.8615
3146.69	17.904
3149.23	15.5978