File: data/Raman/poly_smoothed/Thy_30_10_10_1x_45s_532 nm_x100_100%_600 gr_mm_01.txt
#Acq. time (s)=	45
#Accumulations=	2
#Range (cm-¹)=	200...3150
#Windows=	2
#Auto scanning=	Off
#Autofocus=	Off
#Macrospot=	Off
#AutoExposure=	Off
#Spike filter=	Multiple accum.
#Delay time (s)=	0
#Binning=	1
#Readout mode=	Signal
#DeNoise=	Off
#ICS correction=	On
#Dark correction=	Off
#Inst. Process=	Off
#Detector Gain=	Best Dynamic Range
#Detector ADC=	20 kHz
#Detector temperature (°C)=	-69.85
#Instrument=	LabRAM HR Evol
#Detector=	Synapse
#Objective=	x100
#Grating=	600 gr/mm
#ND Filter=	100%
#Laser (nm)=	532
#Hole=	100.021
#Range=	Auto
#Laser Pol.=	No
#Raman. Pol.=	No
#Laser Pol. (°)=	-0.0007625
#Raman Pol. (°)=	89.9995
#Collection=	Microscope
#StageXY=	Marzhauser
#StageZ=	Marzhauser
#X (µm)=	4740.7
#Y (µm)=	-7738.4
#Z (µm)=	584.6
#Full time(mm:ss)=	3:18
#Project=
#Sample=
#Site=
#Title=	Thy_30_10_10_2x_45s_532 nm_x100_100%_600 gr_mm
#Remark=
#Date=	30.06.2022 12:03
#Acquired=	30.06.2022 12:03:59
#Base:Fit=	10.08.2022 09:58:11
#Base:Sub=	10.08.2022 09:58:44
#Filter:Polynom=	16.08.2022 10:22:53
#AxisType[0]=Intens
#AxisUnit[0]=Cnt
#AxisType[1]=Spectr
#AxisUnit[1]=1/cm
200.533	2.77775
204.162	2.34845
207.792	2.15512
211.418	2.08859
215.044	2.94133
218.667	2.70628
222.289	2.55156
225.912	1.22371
229.531	2.28538
233.148	3.22384
236.766	3.76667
240.381	3.32624
243.994	3.33756
247.606	3.61249
251.217	3.71317
254.828	3.92455
258.436	3.73318
262.042	4.25134
265.647	5.54877
269.25	5.70075
272.852	5.27034
276.453	4.58849
280.052	4.84626
283.65	4.16185
287.247	5.23137
290.842	5.60558
294.436	7.69368
298.028	9.20981
301.617	10.9185
305.206	11.0968
308.794	11.1616
312.381	13.0535
315.964	15.2373
319.548	17.131
323.131	18.9297
326.71	19.8709
330.29	19.881
333.868	20.0276
337.443	20.2767
341.018	19.7122
344.591	18.4963
348.163	17.329
351.733	16.8288
355.303	14.2979
358.869	11.3902
362.435	9.96006
366.001	8.24616
369.563	8.50496
373.124	8.0987
376.686	7.71748
380.244	7.41863
383.801	8.253
387.357	7.44985
390.911	5.93807
394.466	6.66084
398.018	7.01575
401.568	9.05187
405.117	8.59026
408.664	10.0331
412.21	9.70827
415.755	8.91103
419.298	6.87437
422.84	6.32739
426.38	6.93716
429.919	6.09917
433.455	4.94069
436.992	3.2581
440.527	4.14603
444.06	3.63197
447.593	3.30635
451.122	3.63063
454.651	3.19791
458.18	3.39655
461.705	1.994
465.23	1.92159
468.752	2.34772
472.275	3.52811
475.797	4.38334
479.315	5.39422
482.834	7.29153
486.349	6.56693
489.863	6.84541
493.378	7.23843
496.889	8.11316
500.401	7.64841
503.91	8.414
507.417	7.78076
510.923	8.80996
514.43	9.54686
517.933	9.13926
521.435	9.16091
524.936	10.6942
528.435	10.1515
531.933	8.99591
535.43	8.44933
538.927	6.19579
542.421	5.67698
545.913	4.06436
549.403	3.6069
552.893	3.47318
556.381	3.21329
559.868	3.7025
563.354	2.70808
566.839	1.91152
570.322	0.266186
573.802	-0.769785
577.283	0.0659236
580.762	-0.214017
584.24	-0.851598
587.714	-0.19719
591.19	1.78595
594.663	1.59405
598.134	2.90096
601.605	2.96675
605.073	4.34286
608.542	5.83769
612.007	5.36192
615.473	6.87052
618.936	7.16485
622.397	6.69712
625.859	6.64216
629.318	6.09974
632.775	6.07769
636.233	6.06383
639.688	6.34147
643.142	5.55972
646.594	5.32256
650.045	5.03725
653.496	3.86177
656.944	3.71956
660.391	3.29434
663.837	2.72368
667.281	2.5284
670.724	3.3748
674.166	5.44434
677.606	6.51585
681.045	6.89858
684.483	8.46588
687.917	8.8829
691.352	11.3954
694.786	11.7334
698.219	13.0138
701.65	13.1775
705.078	15.2699
708.506	15.3759
711.934	17.0017
715.358	19.7202
718.782	21.8797
722.204	23.3977
725.626	24.4666
729.045	25.4564
732.464	27.5362
735.881	26.8307
739.297	27.2641
742.711	29.4458
746.125	32.4519
749.537	35.8536
752.946	37.7426
756.357	39.888
759.764	41.5305
763.17	43.3178
766.575	44.9083
769.978	46.3488
773.382	48.0974
776.783	51.2696
780.182	51.7021
783.581	53.5181
786.978	55.7239
790.373	57.4444
793.768	59.8891
797.161	61.4982
800.552	63.3181
803.941	63.336
807.33	64.1498
810.718	64.4812
814.105	63.8712
817.49	62.9719
820.873	59.613
824.256	60.4745
827.637	61.243
831.016	60.407
834.395	57.2507
837.772	56.2124
841.147	54.7394
844.522	53.952
847.894	52.908
851.267	51.3611
854.637	49.976
858.007	48.3965
861.374	47.5545
864.739	45.0053
868.106	43.3073
871.469	43.5889
874.831	43.1425
878.193	41.6938
881.553	42.9879
884.911	42.7817
888.268	41.2162
891.623	41.1674
894.978	40.7214
898.331	40.6161
901.683	39.222
905.033	38.8204
908.383	38.4249
911.731	37.1433
915.078	35.8134
918.423	35.4691
921.768	36.3346
925.111	36.9722
928.452	34.3743
931.791	32.6511
935.13	31.9758
938.468	30.7123
941.803	29.9905
945.139	28.7067
948.473	27.0949
951.804	28.2227
955.136	27.2184
958.465	25.3049
961.794	25.3765
965.12	24.16
968.447	24.9294
971.771	24.6093
975.095	25.9191
978.417	26.8926
981.737	26.69
985.057	25.1568
988.375	24.0464
991.691	21.6513
995.006	21.7164
998.32	22.6529
1001.63	22.6003
1004.95	22.353
1008.26	21.7521
1011.56	20.8114
1014.87	19.7388
1018.18	19.9326
1021.48	18.3109
1024.79	17.1323
1028.09	17.0398
1031.39	15.8446
1034.69	14.3137
1037.99	12.2227
1041.29	12.0458
1044.58	11.7482
1047.88	10.9867
1051.17	10.0668
1054.46	10.8914
1057.75	12.0692
1061.04	11.6529
1064.33	8.69896
1067.62	8.19374
1070.9	6.44536
1074.19	8.25514
1077.47	9.25963
1080.76	9.7538
1084.04	9.62086
1087.32	9.21607
1090.59	9.62644
1093.87	9.57556
1097.15	8.35638
1100.42	7.90062
1103.69	7.82738
1106.97	7.56037
1110.24	9.02375
1113.51	8.10036
1116.77	5.88141
1120.04	5.99751
1123.31	5.49986
1126.57	3.64802
1129.83	4.03569
1133.1	5.53301
1136.36	6.02748
1139.62	5.94958
1142.87	4.66673
1146.13	3.67183
1149.38	4.69338
1152.64	5.98131
1155.89	5.08756
1159.14	5.43362
1162.39	5.22204
1165.64	3.9263
1168.89	4.0011
1172.14	4.30797
1175.38	4.66064
1178.63	4.74364
1181.87	4.51721
1185.11	4.7165
1188.35	5.13906
1191.59	3.75008
1194.83	3.26656
1198.07	4.07471
1201.3	5.17315
1204.53	6.67493
1207.77	8.71451
1211	11.6666
1214.23	14.8651
1217.46	16.8577
1220.69	19.2023
1223.91	20.9828
1227.14	23.6325
1230.36	26.3522
1233.59	27.8213
1236.81	27.6062
1240.03	28.6563
1243.25	30.0819
1246.46	31.6958
1249.68	33.6159
1252.9	35.1842
1256.11	35.1647
1259.32	36.0591
1262.54	37.0353
1265.75	38.3199
1268.96	37.9565
1272.16	40.2057
1275.37	40.8476
1278.57	41.1293
1281.78	40.9329
1284.98	42.2328
1288.18	43.0585
1291.38	45.2334
1294.58	46.4471
1297.78	45.7915
1300.98	46.4106
1304.17	46.168
1307.37	45.255
1310.56	44.9894
1313.76	43.945
1316.95	44.5281
1320.14	45.1263
1323.32	45.5325
1326.51	45.9419
1329.7	45.6957
1332.88	44.9071
1336.07	44.8659
1339.25	44.0298
1342.43	43.7439
1345.61	43.2724
1348.79	40.9104
1351.96	40.9471
1355.14	39.853
1358.31	37.7955
1361.49	35.3637
1364.66	34.9128
1367.83	35.4083
1371	35.7606
1374.17	34.1377
1377.34	32.8807
1380.5	32.8258
1383.67	30.7529
1386.83	29.7306
1390	29.6047
1393.16	29.2662
1396.32	26.6292
1399.48	24.608
1402.64	23.5565
1405.79	22.8636
1408.95	22.2065
1412.1	22.3014
1415.26	22.8434
1418.41	23.4552
1421.56	26.5197
1424.71	27.2295
1427.86	30.737
1431	35.542
1434.15	39.2812
1437.29	42.6642
1440.44	46.0924
1443.58	49.489
1446.72	52.6514
1449.86	53.3743
1453	54.6789
1456.14	54.2128
1459.27	53.6094
1462.41	51.2296
1465.54	48.1523
1468.67	44.6703
1471.81	39.2671
1474.94	35.1085
1478.07	30.8108
1481.19	26.752
1484.32	22.8904
1487.45	19.9137
1490.57	17.932
1493.69	15.874
1496.82	13.7513
1499.94	12.8063
1503.06	12.5423
1506.17	15.0478
1509.29	15.3202
1512.41	15.0693
1515.52	15.2845
1518.64	15.4343
1521.75	18.2941
1524.86	20.1361
1527.97	21.0557
1531.08	23.4729
1534.19	24.9244
1537.29	25.1557
1540.4	26.1994
1543.5	26.4484
1546.61	29.4872
1549.71	31.9041
1552.81	34.4095
1555.91	36.9566
1559.01	41.2351
1562.11	44.8236
1565.2	47.8046
1568.29	49.8549
1571.39	51.7641
1574.48	53.1868
1577.57	55.7253
1580.66	56.4062
1583.75	56.5464
1586.84	55.7933
1589.93	57.1091
1593.01	56.8486
1596.1	57.9998
1599.18	58.1018
1602.26	58.4235
1605.34	57.1269
1608.42	56.1118
1611.5	53.624
1614.58	51.5449
1617.65	51.9278
1620.73	51.8695
1623.8	52.8766
1626.87	52.8322
1629.95	53.4174
1633.02	54.6375
1636.09	54.7859
1639.15	54.4355
1642.22	55.8763
1645.29	56.3327
1648.35	57.1761
1651.42	57.0647
1654.48	56.6093
1657.54	56.8802
1660.6	57.6993
1663.66	56.5039
1666.72	56.5995
1669.77	54.7929
1672.83	53.3754
1675.88	51.8118
1678.93	48.9308
1681.99	44.2862
1685.04	38.8403
1688.09	34.8321
1691.13	32.9747
1694.18	28.4171
1697.23	25.0083
1700.27	21.1427
1703.32	17.0975
1706.36	14.1042
1709.4	9.81663
1712.44	8.04016
1715.48	6.60043
1718.52	6.59621
1721.56	5.68589
1724.59	4.86733
1727.63	5.43491
1730.66	6.60619
1733.69	6.67683
1736.72	7.22957
1739.75	7.71873
1742.78	8.31934
1745.81	8.4862
1748.84	7.73392
1751.86	7.60882
1754.89	6.87475
1757.91	6.25694
1760.93	6.77611
1763.95	6.04899
1766.97	4.77172
1769.99	3.47212
1773.01	3.15535
1776.03	2.79688
1779.04	2.55386
1782.06	2.08352
1785.07	2.19947
1788.08	2.7672
1791.09	3.42343
1794.1	4.32049
1797.11	4.56645
1800.12	5.48981
1803.12	6.53693
1806.13	6.7378
1809.13	7.38784
1812.14	7.39692
1815.14	7.8433
1818.14	7.65756
1821.14	7.83942
1824.14	7.81942
1827.13	8.10528
1830.13	7.3258
1833.12	6.36099
1836.12	4.68693
1839.11	3.60873
1842.1	3.21802
1845.09	3.43867
1848.08	3.49579
1851.07	1.74102
1854.06	1.36173
1857.04	0.0486501
1860.03	-0.591546
1863.01	-0.414752
1866	-0.391264
1868.98	-0.0827836
1871.96	0.226481
1874.94	0.230509
1877.92	0.316005
1880.89	0.704258
1882.48	1.5622
1885.47	2.24875
1888.46	3.82605
1891.44	3.82507
1894.43	4.62081
1897.41	4.85435
1900.4	5.19065
1903.38	4.3309
1906.36	3.99884
1909.34	4.53225
1912.32	6.00985
1915.29	7.34908
1918.27	7.25607
1921.25	6.93611
1924.22	6.88378
1927.2	7.12033
1930.17	7.31588
1933.14	7.97684
1936.11	8.93357
1939.08	8.29767
1942.05	8.25895
1945.01	8.12035
1947.98	7.5412
1950.94	7.12862
1953.91	7.89572
1956.87	7.54627
1959.83	6.45092
1962.79	5.14244
1965.75	5.27065
1968.71	5.38376
1971.67	4.3653
1974.62	4.40618
1977.58	3.86968
1980.53	5.04432
1983.48	6.74415
1986.43	7.46125
1989.38	7.30271
1992.33	6.97663
1995.28	6.93417
1998.23	7.52647
2001.18	8.62937
2004.12	8.83171
2007.06	9.11311
2010.01	8.4245
2012.95	8.07041
2015.89	8.84279
2018.83	8.01463
2021.77	8.9947
2024.71	8.59276
2027.64	9.11578
2030.58	9.68759
2033.51	10.3731
2036.45	10.9192
2039.38	11.9717
2042.31	12.8809
2045.24	13.3034
2048.17	14.7084
2051.1	15.0917
2054.02	16.1491
2056.95	16.0021
2059.87	16.0563
2062.8	15.9245
2065.72	17.0389
2068.64	18.137
2071.56	18.5459
2074.48	17.4449
2077.4	18.0636
2080.31	18.5295
2083.23	17.9869
2086.14	18.6167
2089.06	19.6565
2091.97	19.9984
2094.88	21.9957
2097.79	22.9832
2100.7	23.8135
2103.61	24.985
2106.52	27.1587
2109.43	28.5665
2112.33	29.7638
2115.24	31.209
2118.14	33.9126
2121.04	34.6109
2123.94	35.8236
2126.84	37.845
2129.74	40.1225
2132.64	43.0256
2135.54	45.9387
2138.43	48.862
2141.33	50.1745
2144.22	51.8644
2147.11	54.475
2150.01	55.9694
2152.9	57.2632
2155.79	58.9436
2158.67	60.8816
2161.56	62.4717
2164.45	63.1803
2167.33	64.9014
2170.22	64.9471
2173.1	65.6317
2175.98	65.7088
2178.86	65.9129
2181.74	64.2019
2184.62	63.7149
2187.5	62.6372
2190.38	60.3408
2193.25	58.6058
2196.13	56.1194
2199	55.2631
2201.88	53.1452
2204.75	51.0963
2207.62	48.0141
2210.49	45.9574
2213.36	43.8665
2216.22	41.0006
2219.09	38.9106
2221.96	37.474
2224.82	35.0325
2227.68	34.1138
2230.55	32.8071
2233.41	31.5939
2236.27	29.955
2239.12	29.0897
2241.98	27.8928
2244.84	27.7105
2247.7	26.6288
2250.55	25.8833
2253.41	24.3796
2256.26	24.2286
2259.11	23.5888
2261.96	23.2461
2264.81	22.7769
2267.66	21.9188
2270.51	22.1029
2273.35	21.2865
2276.2	20.6143
2279.04	19.558
2281.89	19.4012
2284.73	18.7637
2287.57	18.2328
2290.41	17.8425
2293.25	16.2692
2296.09	16.2599
2298.93	15.9345
2301.76	16.1604
2304.6	15.9981
2307.44	16.6034
2310.27	15.7338
2313.1	16.562
2315.93	16.0125
2318.76	16.7078
2321.59	17.2983
2324.42	18.305
2327.25	19.2674
2330.07	19.2789
2332.9	18.8984
2335.72	18.1345
2338.55	18.6347
2341.37	18.3132
2344.19	16.398
2347.01	15.4924
2349.83	15.4185
2352.65	15.2923
2355.46	14.1988
2358.28	12.8684
2361.09	11.2347
2363.91	10.054
2366.72	10.2835
2369.53	9.44069
2372.34	9.15359
2375.15	8.39165
2377.96	7.50357
2380.77	6.9771
2383.58	7.37599
2386.38	7.76809
2389.19	7.28397
2391.99	6.66676
2394.8	6.47902
2397.6	5.62206
2400.4	5.59808
2403.2	6.03445
2406	6.74589
2408.79	7.93544
2411.59	8.34512
2414.39	9.38253
2417.18	10.7142
2419.98	11.5306
2422.77	11.7198
2425.56	11.3493
2428.35	10.9162
2431.14	11.4584
2433.93	11.0565
2436.72	11.6761
2439.5	10.6459
2442.29	10.8058
2445.07	10.454
2447.86	10.3598
2450.64	9.68573
2453.42	9.59303
2456.2	8.85406
2458.98	7.98339
2461.76	8.18379
2464.54	7.43996
2467.32	6.54529
2470.09	6.30884
2472.87	7.00307
2475.64	7.3207
2478.41	7.20203
2481.18	6.23194
2483.95	6.21768
2486.72	5.74145
2489.49	5.69873
2492.26	4.92884
2495.03	4.12111
2497.79	4.89564
2500.56	3.78876
2503.32	3.02381
2506.09	3.34092
2508.85	2.70934
2511.61	2.76852
2514.37	1.95104
2517.13	1.05432
2519.89	0.788928
2522.64	1.42615
2525.4	0.759341
2528.15	1.05469
2530.91	0.580337
2533.66	1.02351
2536.41	1.97525
2539.16	2.24914
2541.91	2.49067
2544.66	2.76601
2547.41	3.09742
2550.16	3.17078
2552.9	3.36205
2555.65	3.75697
2558.39	4.54702
2561.13	4.52871
2563.88	4.87304
2566.62	4.70559
2569.36	4.21737
2572.1	4.57428
2574.84	3.88885
2577.57	3.10169
2580.31	2.05244
2583.05	1.9821
2585.78	2.38352
2588.51	2.66282
2591.24	3.67066
2593.98	4.69832
2596.71	4.72471
2599.44	4.7683
2602.16	5.2558
2604.89	5.3966
2607.62	4.69009
2610.34	5.24704
2613.07	4.82532
2615.79	4.21936
2618.52	3.99913
2621.24	4.1259
2623.96	5.00857
2626.68	4.07357
2629.4	3.9069
2632.11	3.13086
2634.83	2.33163
2637.55	1.69595
2640.26	1.00724
2642.98	-0.151157
2645.69	-0.908482
2648.4	-1.33318
2651.11	-1.10483
2653.82	-0.987719
2656.53	-0.446932
2659.24	0.405461
2661.95	0.747957
2664.65	1.49575
2667.36	2.06368
2670.06	2.94418
2672.76	3.38513
2675.47	4.19173
2678.17	5.67943
2680.87	6.54708
2683.57	6.58259
2686.27	7.98471
2688.97	7.77664
2691.66	7.72959
2694.36	7.07944
2697.05	7.42128
2699.75	5.74521
2702.44	5.62482
2705.13	5.12239
2707.82	4.45922
2710.51	3.7591
2713.2	3.90568
2715.89	4.99576
2718.57	6.19224
2721.26	7.23819
2723.95	7.92911
2726.63	8.39052
2729.31	8.19418
2732	8.03775
2734.68	7.46338
2737.36	8.54603
2740.04	8.53921
2742.72	8.63531
2745.39	7.44733
2748.07	7.64979
2750.75	7.23181
2753.42	7.0427
2756.09	6.34196
2758.77	6.19866
2761.44	5.41249
2764.11	4.08973
2766.78	4.3263
2769.45	3.77082
2772.12	3.44672
2774.78	3.17533
2777.45	3.59131
2780.12	4.58775
2782.78	4.61173
2785.44	4.26284
2788.11	3.50208
2790.77	3.24855
2793.43	3.16372
2796.09	3.09715
2798.75	3.37041
2801.4	4.41208
2804.06	4.45747
2806.72	5.00651
2809.37	5.45455
2812.03	6.20818
2814.68	6.6459
2817.33	6.90906
2819.98	7.51914
2822.63	9.04214
2825.28	10.495
2827.93	12.8797
2830.58	15.0061
2833.23	18.082
2835.87	21.0849
2838.52	24.6616
2841.16	28.8418
2843.8	34.0048
2846.44	38.0497
2849.08	44.4493
2851.73	50.7908
2854.36	57.577
2857	64.4698
2859.64	70.8299
2862.28	77.3892
2864.91	82.4745
2867.55	87.4536
2870.18	92.1801
2872.81	96.8782
2875.44	100.273
2878.07	103.413
2880.7	105.715
2883.33	108.15
2885.96	110.865
2888.59	114.3
2891.21	116.354
2893.84	118.126
2896.46	120.389
2899.09	125.02
2901.71	129.402
2904.33	135.459
2906.95	141.985
2909.57	149.544
2912.19	157.412
2914.81	165.7
2917.43	172.872
2920.04	179.911
2922.66	185.06
2925.27	190.364
2927.88	192.471
2930.5	195
2933.11	195.662
2935.72	195.708
2938.33	194.602
2940.94	191.264
2943.54	186.69
2946.15	180.961
2948.76	175.452
2951.36	169.331
2953.97	161.285
2956.57	152.824
2959.17	144.882
2961.77	138.583
2964.37	131.707
2966.97	125.742
2969.57	118.901
2972.17	112.871
2974.77	107.294
2977.36	101.143
2979.96	94.2754
2982.55	88.8676
2985.15	82.8378
2987.74	76.8143
2990.33	70.8724
2992.92	64.9987
2995.51	60.1759
2998.1	55.7932
3000.69	50.3309
3003.27	45.7212
3005.86	42.0268
3008.44	38.3616
3011.03	35.2835
3013.61	32.3369
3016.19	28.2823
3018.78	25.3977
3021.36	24.0257
3023.94	21.9393
3026.51	21.0278
3029.09	20.4785
3031.67	19.5549
3034.24	19.1441
3036.82	19.492
3039.39	21.1329
3041.97	21.3887
3044.54	22.932
3047.11	24.182
3049.68	25.4203
3052.25	26.8683
3054.82	27.6215
3057.39	26.9201
3059.96	27.1373
3062.52	26.9117
3065.09	26.4249
3067.65	24.971
3070.22	23.5987
3072.78	22.3217
3075.34	20.2994
3077.9	17.7941
3080.46	16.0103
3083.02	14.4369
3085.58	12.3062
3088.14	9.75153
3090.69	7.79662
3093.25	6.22811
3095.8	4.87613
3098.36	4.36578
3100.91	3.86868
3103.46	3.05869
3106.01	2.44583
3108.56	2.04349
3111.11	1.81672
3113.66	2.63625
3116.21	2.00326
3118.76	1.17293
3121.3	1.14505
3123.85	2.0854
3126.39	2.19109
3128.93	0.472163
3131.48	0.141675
3134.02	0.988355
3136.56	1.35856
3139.1	0.659548
3141.64	0.217383
3144.17	0.0529989
3146.71	-0.759876
3149.25	-1.08521