File: data/Raman/poly_smoothed/Thy_30_10_31_1x_45s_532 nm_x100_100%_600 gr_mm_01.txt
#Acq. time (s)=	45
#Accumulations=	2
#Range (cm-¹)=	200...3150
#Windows=	2
#Auto scanning=	Off
#Autofocus=	Off
#Macrospot=	Off
#AutoExposure=	Off
#Spike filter=	Multiple accum.
#Delay time (s)=	0
#Binning=	1
#Readout mode=	Signal
#DeNoise=	Off
#ICS correction=	On
#Dark correction=	Off
#Inst. Process=	Off
#Detector Gain=	Best Dynamic Range
#Detector ADC=	20 kHz
#Detector temperature (°C)=	-69.85
#Instrument=	LabRAM HR Evol
#Detector=	Synapse
#Objective=	x100
#Grating=	600 gr/mm
#ND Filter=	100%
#Laser (nm)=	532
#Hole=	100.021
#Range=	Auto
#Laser Pol.=	No
#Raman. Pol.=	No
#Laser Pol. (°)=	-0.0007625
#Raman Pol. (°)=	89.9995
#Collection=	Microscope
#StageXY=	Marzhauser
#StageZ=	Marzhauser
#X (µm)=	4753
#Y (µm)=	-7710.3
#Z (µm)=	584.4
#Full time(mm:ss)=	3:18
#Project=
#Sample=
#Site=
#Title=	Thy_30_10_31_2x_45s_532 nm_x100_100%_600 gr_mm
#Remark=
#Date=	30.06.2022 13:40
#Acquired=	30.06.2022 13:40:36
#Base:Fit=	10.08.2022 09:58:11
#Base:Sub=	10.08.2022 09:58:44
#Filter:Polynom=	16.08.2022 10:22:53
#AxisType[0]=Intens
#AxisUnit[0]=Cnt
#AxisType[1]=Spectr
#AxisUnit[1]=1/cm
200.533	0.932674
204.162	2.6463
207.792	3.38109
211.418	3.58128
215.044	3.1553
218.667	2.0253
222.289	2.36533
225.912	1.87592
229.531	2.06034
233.148	1.61183
236.766	1.2215
240.381	0.975487
243.994	1.17303
247.606	0.0878814
251.217	-0.0755032
254.828	0.3223
258.436	1.29845
262.042	1.49388
265.647	2.44928
269.25	3.38598
272.852	5.37466
276.453	6.25324
280.052	6.99034
283.65	7.57952
287.247	8.74135
290.842	8.28941
294.436	8.41058
298.028	7.78322
301.617	8.68635
305.206	9.13033
308.794	9.02611
312.381	10.2257
315.964	9.14091
319.548	7.77871
323.131	7.38038
326.71	7.19601
330.29	6.3857
333.868	5.45472
337.443	6.70562
341.018	7.56267
344.591	8.88513
348.163	9.02176
351.733	9.07232
355.303	9.08121
358.869	9.80128
362.435	10.2495
366.001	9.42659
369.563	9.55221
373.124	10.256
376.686	9.11278
380.244	9.0001
383.801	9.11892
387.357	8.27167
390.911	8.68064
394.466	8.12914
398.018	6.71292
401.568	6.53949
405.117	5.47438
408.664	5.62821
412.21	5.11856
415.755	6.08709
419.298	5.73322
422.84	6.38558
426.38	6.39821
429.919	6.79273
433.455	6.09525
436.992	5.68917
440.527	4.78768
444.06	5.5079
447.593	7.44139
451.122	7.95532
454.651	8.42221
458.18	8.32463
461.705	9.15869
465.23	9.54859
468.752	10.4665
472.275	10.9016
475.797	12.7835
479.315	14.8815
482.834	15.1023
486.349	16.4442
489.863	17.8181
493.378	18.202
496.889	18.4391
500.401	20.0105
503.91	20.3488
507.417	19.6974
510.923	20.418
514.43	20.3359
517.933	19.4281
521.435	18.6211
524.936	18.8106
528.435	19.3055
531.933	19.6335
535.43	18.5587
538.927	16.648
542.421	14.6583
545.913	14.025
549.403	13.3617
552.893	12.8902
556.381	13.0846
559.868	13.903
563.354	12.8705
566.839	9.84954
570.322	8.45657
573.802	7.70626
577.283	7.6564
580.762	5.94303
584.24	5.28442
587.714	5.62325
591.19	5.23774
594.663	4.33529
598.134	2.96658
601.605	3.5604
605.073	3.84783
608.542	3.89895
612.007	5.02955
615.473	3.9559
618.936	4.27843
622.397	3.74165
625.859	4.69804
629.318	5.99166
632.775	7.91326
636.233	9.3896
639.688	12.3229
643.142	13.3744
646.594	13.1304
650.045	12.9416
653.496	16.2651
656.944	18.2176
660.391	19.9253
663.837	20.7606
667.281	21.4025
670.724	23.8762
674.166	26.057
677.606	26.545
681.045	28.2574
684.483	29.5748
687.917	31.2446
691.352	31.1771
694.786	31.5164
698.219	30.5644
701.65	31.0016
705.078	32.2992
708.506	34.4271
711.934	35.7674
715.358	35.6368
718.782	36.7262
722.204	37.0471
725.626	37.3797
729.045	37.7066
732.464	37.9886
735.881	39.44
739.297	39.9695
742.711	40.7349
746.125	42.9134
749.537	46.0823
752.946	49.0865
756.357	51.5812
759.764	52.9546
763.17	54.6334
766.575	56.3747
769.978	58.2392
773.382	60.9434
776.783	62.5897
780.182	63.4877
783.581	64.9551
786.978	66.2733
790.373	70.1042
793.768	70.9158
797.161	72.007
800.552	72.2088
803.941	74.0569
807.33	73.6697
810.718	73.2684
814.105	72.8552
817.49	74.3796
820.873	76.6894
824.256	74.8263
827.637	74.9545
831.016	73.6742
834.395	73.7764
837.772	72.81
841.147	71.06
844.522	70.4855
847.894	69.229
851.267	67.8324
854.637	67.6393
858.007	64.6989
861.374	63.2572
864.739	59.8795
868.106	60.0334
871.469	58.9175
874.831	58.2122
878.193	56.9047
881.553	56.5056
884.911	56.74
888.268	55.4934
891.623	55.0586
894.978	55.1698
898.331	54.6277
901.683	54.5484
905.033	52.8015
908.383	50.3268
911.731	50.2764
915.078	50.3101
918.423	50.6185
921.768	50.2313
925.111	50.7352
928.452	50.6854
931.791	47.946
935.13	46.8829
938.468	46.5073
941.803	45.0327
945.139	42.5817
948.473	41.5503
951.804	41.2044
955.136	41.6403
958.465	40.3623
961.794	38.6005
965.12	37.2397
968.447	37.8908
971.771	37.5034
975.095	36.6663
978.417	37.5043
981.737	38.3433
985.057	39.0932
988.375	38.9868
991.691	39.7807
995.006	40.6592
998.32	41.398
1001.63	41.959
1004.95	42.1428
1008.26	42.3588
1011.56	42.5926
1014.87	42.248
1018.18	43.7241
1021.48	42.8312
1024.79	41.1828
1028.09	41.4604
1031.39	40.4952
1034.69	39.5077
1037.99	37.0545
1041.29	34.5137
1044.58	34.7577
1047.88	34.6324
1051.17	35.3089
1054.46	33.8824
1057.75	32.4157
1061.04	31.4093
1064.33	29.2074
1067.62	28.4455
1070.9	27.9512
1074.19	27.4549
1077.47	26.0943
1080.76	26.0801
1084.04	24.4998
1087.32	24.3433
1090.59	24.9321
1093.87	24.7783
1097.15	26.0463
1100.42	26.3445
1103.69	27.0797
1106.97	26.6591
1110.24	26.9151
1113.51	26.2149
1116.77	26.4444
1120.04	24.8061
1123.31	23.7585
1126.57	22.8276
1129.83	21.5316
1133.1	19.3603
1136.36	16.0342
1139.62	13.5919
1142.87	13.554
1146.13	11.1535
1149.38	9.35624
1152.64	8.22545
1155.89	4.55309
1159.14	2.37067
1162.39	-0.153647
1165.64	-0.738997
1168.89	0.10118
1172.14	2.03297
1175.38	4.16512
1178.63	5.6613
1181.87	6.69625
1185.11	7.65866
1188.35	9.05455
1191.59	11.4446
1194.83	12.5257
1198.07	13.3313
1201.3	14.7345
1204.53	17.9246
1207.77	20.6829
1211	23.2566
1214.23	26.8988
1217.46	31.1054
1220.69	34.9974
1223.91	38.518
1227.14	40.2803
1230.36	43.136
1233.59	45.2164
1236.81	47.5521
1240.03	50.0643
1243.25	52.6191
1246.46	55.3742
1249.68	57.9577
1252.9	59.9062
1256.11	61.5244
1259.32	61.5768
1262.54	63.6517
1265.75	64.4547
1268.96	65.4512
1272.16	65.9468
1275.37	66.1013
1278.57	67.0994
1281.78	68.2527
1284.98	70.228
1288.18	72.107
1291.38	74.1341
1294.58	74.4319
1297.78	75.1448
1300.98	75.7201
1304.17	75.6938
1307.37	75.9913
1310.56	76.8193
1313.76	76.8584
1316.95	76.1696
1320.14	75.6018
1323.32	74.6341
1326.51	73.16
1329.7	71.5921
1332.88	70.6748
1336.07	68.686
1339.25	66.5028
1342.43	64.2633
1345.61	62.3989
1348.79	59.2113
1351.96	55.9636
1355.14	53.3311
1358.31	50.5142
1361.49	47.8293
1364.66	45.851
1367.83	42.0584
1371	38.9735
1374.17	37.5407
1377.34	37.5258
1380.5	35.6898
1383.67	35.4784
1386.83	35.1216
1390	33.9786
1393.16	33.8553
1396.32	33.4958
1399.48	33.5957
1402.64	32.1501
1405.79	31.8821
1408.95	33.5374
1412.1	34.9029
1415.26	37.142
1418.41	39.6012
1421.56	42.783
1424.71	46.5494
1427.86	50.9356
1431	55.8691
1434.15	60.9255
1437.29	65.8534
1440.44	69.3569
1443.58	71.2867
1446.72	73.2811
1449.86	75.0847
1453	72.9649
1456.14	71.6058
1459.27	67.5653
1462.41	63.3252
1465.54	58.5206
1468.67	54.2416
1471.81	48.3638
1474.94	42.9667
1478.07	35.3617
1481.19	30.0749
1484.32	24.8844
1487.45	19.7792
1490.57	15.7935
1493.69	11.6568
1496.82	8.84736
1499.94	7.75249
1503.06	7.55661
1506.17	7.72648
1509.29	7.08459
1512.41	6.85103
1515.52	5.45377
1518.64	5.63643
1521.75	5.8363
1524.86	6.62901
1527.97	7.37823
1531.08	8.62163
1534.19	10.0283
1537.29	11.3744
1540.4	13.9438
1543.5	18.7968
1546.61	22.7051
1549.71	27.0554
1552.81	29.9705
1555.91	33.2864
1559.01	38.1087
1562.11	40.6005
1565.2	44.0564
1568.29	47.5521
1571.39	50.056
1574.48	52.8927
1577.57	55.3446
1580.66	56.598
1583.75	58.2081
1586.84	59.8824
1589.93	60.3654
1593.01	60.4893
1596.1	59.7492
1599.18	60.7827
1602.26	58.9761
1605.34	57.3904
1608.42	57.0212
1611.5	56.6479
1614.58	56.0921
1617.65	58.047
1620.73	59.0058
1623.8	61.0092
1626.87	63.4037
1629.95	65.5909
1633.02	68.4187
1636.09	72.4973
1639.15	75.4191
1642.22	79.4582
1645.29	82.0343
1648.35	84.8753
1651.42	86.6212
1654.48	89.1079
1657.54	90.0881
1660.6	92.068
1663.66	89.9698
1666.72	86.8463
1669.77	83.6432
1672.83	79.6949
1675.88	75.5221
1678.93	69.6337
1681.99	63.9293
1685.04	57.4053
1688.09	50.4769
1691.13	44.4446
1694.18	37.5361
1697.23	32.145
1700.27	26.4679
1703.32	20.5961
1706.36	14.9663
1709.4	11.3587
1712.44	8.19404
1715.48	5.4419
1718.52	3.59934
1721.56	2.21131
1724.59	2.94499
1727.63	2.53326
1730.66	2.5571
1733.69	2.72705
1736.72	2.56028
1739.75	2.31606
1742.78	2.01213
1745.81	3.03584
1748.84	3.27749
1751.86	3.24485
1754.89	4.15711
1757.91	3.38548
1760.93	2.82749
1763.95	2.8149
1766.97	2.54436
1769.99	2.21963
1773.01	1.6763
1776.03	0.854674
1779.04	-0.19944
1782.06	-0.756895
1785.07	-0.31713
1788.08	-0.309004
1791.09	0.0222165
1794.1	0.394373
1797.11	0.411498
1800.12	0.348863
1803.12	0.54665
1806.13	0.66128
1809.13	0.652182
1812.14	0.615963
1815.14	0.760807
1818.14	0.78325
1821.14	1.498
1824.14	1.59693
1827.13	2.09505
1830.13	2.47004
1833.12	3.02201
1836.12	3.17011
1839.11	3.57146
1842.1	3.84625
1845.09	4.34592
1848.08	4.37414
1851.07	4.09098
1854.06	4.67878
1857.04	5.45486
1860.03	6.77349
1863.01	6.7124
1866	7.22279
1868.98	7.86797
1871.96	8.67947
1874.94	9.3237
1877.92	9.31856
1880.89	9.59763
1882.48	10.4171
1885.47	11.0451
1888.46	10.6631
1891.44	11.787
1894.43	11.9758
1897.41	11.7024
1900.4	12.4216
1903.38	13.2181
1906.36	13.348
1909.34	13.1592
1912.32	13.4383
1915.29	14.0054
1918.27	13.9523
1921.25	14.0724
1924.22	14.5175
1927.2	15.3366
1930.17	15.3273
1933.14	14.9274
1936.11	15.2822
1939.08	15.1515
1942.05	14.3568
1945.01	14.4424
1947.98	13.8259
1950.94	13.3522
1953.91	13.1872
1956.87	13.5784
1959.83	13.6762
1962.79	13.6805
1965.75	13.2335
1968.71	12.7815
1971.67	12.8242
1974.62	12.8737
1977.58	13.5665
1980.53	13.7065
1983.48	13.1927
1986.43	13.5229
1989.38	13.5138
1992.33	13.6064
1995.28	14.2536
1998.23	14.1164
2001.18	14.2633
2004.12	14.3071
2007.06	14.4254
2010.01	14.3887
2012.95	14.7662
2015.89	15.0232
2018.83	15.0641
2021.77	14.9628
2024.71	15.075
2027.64	16.3601
2030.58	18.0403
2033.51	18.4323
2036.45	19.1022
2039.38	19.669
2042.31	19.9627
2045.24	20.7054
2048.17	20.6287
2051.1	21.2855
2054.02	20.4352
2056.95	21.1596
2059.87	20.9953
2062.8	21.1092
2065.72	21.6523
2068.64	22.5216
2071.56	23.0523
2074.48	23.1843
2077.4	23.8336
2080.31	24.0217
2083.23	25.235
2086.14	25.8588
2089.06	25.5355
2091.97	26.2612
2094.88	27.6818
2097.79	29.2282
2100.7	30.158
2103.61	31.8208
2106.52	33.9105
2109.43	35.9789
2112.33	38.3486
2115.24	40.6475
2118.14	43.4562
2121.04	46.4794
2123.94	50.9047
2126.84	54.4951
2129.74	58.6279
2132.64	62.5825
2135.54	67.7988
2138.43	72.7362
2141.33	77.2203
2144.22	81.4235
2147.11	85.9558
2150.01	89.9448
2152.9	93.7818
2155.79	98.2368
2158.67	101.097
2161.56	103.607
2164.45	106.03
2167.33	107.952
2170.22	108.667
2173.1	110.081
2175.98	109.582
2178.86	109.63
2181.74	108.27
2184.62	106.682
2187.5	104.976
2190.38	102.611
2193.25	99.5938
2196.13	95.9583
2199	92.0778
2201.88	86.8785
2204.75	83.0708
2207.62	78.543
2210.49	74.2036
2213.36	68.829
2216.22	64.8616
2219.09	61.3099
2221.96	58.4336
2224.82	55.3388
2227.68	52.8275
2230.55	49.7376
2233.41	46.5998
2236.27	45.0607
2239.12	43.4408
2241.98	41.4938
2244.84	39.3156
2247.7	37.3639
2250.55	36.942
2253.41	35.1678
2256.26	33.5999
2259.11	32.469
2261.96	31.375
2264.81	30.0908
2267.66	28.6837
2270.51	27.076
2273.35	25.4705
2276.2	24.7622
2279.04	23.2924
2281.89	22.5884
2284.73	21.8301
2287.57	21.7035
2290.41	19.5303
2293.25	18.4703
2296.09	17.9501
2298.93	18.183
2301.76	17.7405
2304.6	18.4185
2307.44	18.0297
2310.27	17.8076
2313.1	17.5095
2315.93	17.4655
2318.76	16.8566
2321.59	16.2779
2324.42	15.8734
2327.25	14.5259
2330.07	13.7102
2332.9	12.9247
2335.72	12.5218
2338.55	11.4123
2341.37	10.6519
2344.19	9.98524
2347.01	9.71517
2349.83	9.05108
2352.65	7.45593
2355.46	5.86431
2358.28	5.48275
2361.09	5.00716
2363.91	5.40254
2366.72	6.15656
2369.53	5.79512
2372.34	6.12981
2375.15	6.82135
2377.96	6.88322
2380.77	6.19441
2383.58	5.97356
2386.38	6.10046
2389.19	5.05932
2391.99	5.36422
2394.8	4.51793
2397.6	3.48294
2400.4	4.261
2403.2	4.20034
2406	3.73802
2408.79	3.84261
2411.59	4.03394
2414.39	4.60641
2417.18	4.65138
2419.98	4.90964
2422.77	6.1148
2425.56	6.93449
2428.35	7.64024
2431.14	7.84487
2433.93	7.89498
2436.72	8.05415
2439.5	7.99069
2442.29	8.43285
2445.07	7.52306
2447.86	6.79488
2450.64	6.38955
2453.42	5.92251
2456.2	5.02534
2458.98	4.21293
2461.76	3.87554
2464.54	3.0324
2467.32	3.18385
2470.09	3.09531
2472.87	2.38067
2475.64	2.8744
2478.41	2.65979
2481.18	2.78523
2483.95	2.67761
2486.72	2.6047
2489.49	3.43545
2492.26	3.6995
2495.03	3.84689
2497.79	3.35093
2500.56	3.83843
2503.32	3.20494
2506.09	2.83532
2508.85	2.31373
2511.61	1.80485
2514.37	1.19846
2517.13	0.961541
2519.89	1.14476
2522.64	1.9306
2525.4	3.06628
2528.15	2.85611
2530.91	2.93845
2533.66	2.86926
2536.41	2.97578
2539.16	2.55109
2541.91	2.54072
2544.66	1.87683
2547.41	1.52473
2550.16	1.165
2552.9	1.22938
2555.65	1.47152
2558.39	1.33552
2561.13	1.25837
2563.88	0.313531
2566.62	0.421073
2569.36	-0.331361
2572.1	-1.40746
2574.84	-1.37605
2577.57	-1.18789
2580.31	-0.89718
2583.05	-0.212008
2585.78	0.655892
2588.51	0.997479
2591.24	1.11961
2593.98	1.42764
2596.71	0.415503
2599.44	0.802019
2602.16	1.14911
2604.89	1.23746
2607.62	0.825016
2610.34	0.641283
2613.07	0.62096
2615.79	0.252209
2618.52	0.835041
2621.24	0.896378
2623.96	1.15494
2626.68	0.935999
2629.4	0.451008
2632.11	0.137552
2634.83	0.121216
2637.55	0.551066
2640.26	0.248615
2642.98	1.20532
2645.69	1.24473
2648.4	1.46728
2651.11	1.73533
2653.82	1.36755
2656.53	1.36577
2659.24	1.86983
2661.95	1.03913
2664.65	1.17991
2667.36	1.45474
2670.06	1.80006
2672.76	1.23942
2675.47	0.370769
2678.17	0.762204
2680.87	2.24818
2683.57	2.29177
2686.27	2.60952
2688.97	2.56052
2691.66	2.95193
2694.36	3.35951
2697.05	4.1712
2699.75	4.9578
2702.44	6.08562
2705.13	6.57173
2707.82	7.96973
2710.51	9.2278
2713.2	10.3285
2715.89	11.0509
2718.57	11.9793
2721.26	11.8074
2723.95	13.2278
2726.63	13.241
2729.31	13.3355
2732	14.3069
2734.68	14.1594
2737.36	13.8054
2740.04	13.4222
2742.72	13.1894
2745.39	13.6539
2748.07	12.8763
2750.75	11.2987
2753.42	10.9239
2756.09	10.2683
2758.77	9.13941
2761.44	8.58234
2764.11	7.37686
2766.78	7.88914
2769.45	6.84659
2772.12	5.93375
2774.78	5.46058
2777.45	5.2347
2780.12	4.19172
2782.78	4.13508
2785.44	4.4492
2788.11	4.24844
2790.77	4.20676
2793.43	4.04897
2796.09	4.94441
2798.75	5.70869
2801.4	5.75981
2804.06	6.45752
2806.72	6.75536
2809.37	7.63262
2812.03	7.35197
2814.68	7.53502
2817.33	8.06514
2819.98	10.7138
2822.63	13.3742
2825.28	17.5428
2827.93	22.483
2830.58	27.9031
2833.23	32.4392
2835.87	37.3773
2838.52	44.1123
2841.16	51.3463
2843.8	59.3356
2846.44	67.7716
2849.08	78.7365
2851.73	90.3446
2854.36	102.024
2857	114.053
2859.64	125.613
2862.28	137.675
2864.91	148.087
2867.55	157.133
2870.18	166.389
2872.81	173.769
2875.44	180.015
2878.07	185.076
2880.7	191.113
2883.33	196.642
2885.96	202.578
2888.59	208.352
2891.21	212.615
2893.84	217.292
2896.46	222.498
2899.09	229.485
2901.71	238.144
2904.33	247.351
2906.95	260.034
2909.57	274.278
2912.19	289.508
2914.81	305.457
2917.43	320.739
2920.04	334.601
2922.66	347.127
2925.27	357.023
2927.88	362.87
2930.5	367.254
2933.11	368.741
2935.72	366.56
2938.33	362.332
2940.94	354.696
2943.54	345.543
2946.15	334.377
2948.76	321.828
2951.36	308.133
2953.97	293.498
2956.57	279.729
2959.17	265.324
2961.77	252.283
2964.37	239.148
2966.97	226.562
2969.57	214.934
2972.17	204.558
2974.77	194.064
2977.36	184.595
2979.96	174.334
2982.55	164.012
2985.15	153.145
2987.74	141.688
2990.33	130.418
2992.92	119.507
2995.51	110.131
2998.1	98.6311
3000.69	88.9263
3003.27	79.8222
3005.86	71.0405
3008.44	63.0944
3011.03	56.2194
3013.61	50.1869
3016.19	46.2802
3018.78	43.1214
3021.36	39.274
3023.94	36.656
3026.51	35.1068
3029.09	33.9628
3031.67	33.4874
3034.24	34.5103
3036.82	35.3884
3039.39	37.1063
3041.97	38.5659
3044.54	39.9878
3047.11	41.3147
3049.68	41.9655
3052.25	42.9683
3054.82	42.7637
3057.39	41.7731
3059.96	40.0503
3062.52	38.3747
3065.09	36.5569
3067.65	33.307
3070.22	29.6712
3072.78	26.3882
3075.34	23.5169
3077.9	20.4717
3080.46	18.0701
3083.02	15.1579
3085.58	12.4108
3088.14	9.8477
3090.69	8.21895
3093.25	6.99514
3095.8	6.30918
3098.36	5.44823
3100.91	4.47797
3103.46	4.25089
3106.01	3.79141
3108.56	3.23393
3111.11	2.59163
3113.66	2.02782
3116.21	1.75727
3118.76	1.53487
3121.3	1.21281
3123.85	0.961027
3126.39	0.423711
3128.93	-0.000293399
3131.48	-0.626444
3134.02	-0.544691
3136.56	-0.401598
3139.1	-0.532804
3141.64	-0.661458
3144.17	-0.925908
3146.71	-1.00478
3149.25	-1.02804