File: data/Raman/poly_smoothed/Thy_10_08_47_1x_45s_532 nm_x100_100%_600 gr_mm_01.txt
#Acq. time (s)=	45
#Accumulations=	2
#Range (cm-¹)=	200...3150
#Windows=	2
#Auto scanning=	Off
#Autofocus=	Off
#Macrospot=	Off
#AutoExposure=	Off
#Spike filter=	Multiple accum.
#Delay time (s)=	0
#Binning=	1
#Readout mode=	Signal
#DeNoise=	Off
#ICS correction=	On
#Dark correction=	Off
#Inst. Process=	Off
#Detector Gain=	Best Dynamic Range
#Detector ADC=	20 kHz
#Detector temperature (°C)=	-69.85
#Instrument=	LabRAM HR Evol
#Detector=	Synapse
#Objective=	x100
#Grating=	600 gr/mm
#ND Filter=	100%
#Laser (nm)=	532
#Hole=	100.021
#Range=	Auto
#Laser Pol.=	No
#Raman. Pol.=	No
#Laser Pol. (°)=	-0.0007625
#Raman Pol. (°)=	89.9995
#Collection=	Microscope
#StageXY=	Marzhauser
#StageZ=	Marzhauser
#X (µm)=	-2354.8
#Y (µm)=	245.2
#Z (µm)=	521.65
#Full time(mm:ss)=	3:18
#Project=
#Sample=
#Site=
#Title=	Thy_10_08_47_2x_45s_532 nm_x100_100%_600 gr_mm
#Remark=
#Date=	06.07.2022 15:14
#Acquired=	06.07.2022 15:14:55
#Base:Fit=	10.08.2022 09:46:25
#Base:Sub=	10.08.2022 09:46:49
#Filter:Polynom=	16.08.2022 10:24:56
#AxisType[0]=Intens
#AxisUnit[0]=Cnt
#AxisType[1]=Spectr
#AxisUnit[1]=1/cm
200.398	-1.83008
204.027	-0.410754
207.657	1.36686
211.283	1.74997
214.909	2.5004
218.533	3.72282
222.157	3.79902
225.777	4.24085
229.396	4.01324
233.016	4.17781
236.632	4.53631
240.247	3.89155
243.86	3.88419
247.474	4.24148
251.085	3.17097
254.694	2.81566
258.301	1.91323
261.908	1.49871
265.513	1.11781
269.116	1.54968
272.718	2.06333
276.319	1.39067
279.918	1.78153
283.516	3.24132
287.113	3.01966
290.708	3.15409
294.302	3.40502
297.894	3.70178
301.485	7.2194
305.073	8.97242
308.661	10.0897
312.247	11.4029
315.833	13.4035
319.415	13.4577
322.997	14.7329
326.579	14.3632
330.156	14.7903
333.735	15.3755
337.31	15.2169
340.885	14.0905
344.458	14.1912
348.03	13.8451
351.6	13.6043
355.17	12.5057
358.737	11.8799
362.304	9.55476
365.868	8.34236
369.431	7.61321
372.994	5.7351
376.554	5.10364
380.112	3.74664
383.669	3.9634
387.225	3.41044
390.781	2.86847
394.334	1.84046
397.885	2.017
401.436	1.49774
404.984	0.610331
408.532	-0.069124
412.078	0.459787
415.623	0.64544
419.166	0.793585
422.708	1.91787
426.248	2.39747
429.788	3.29555
433.326	3.48909
436.86	4.09325
440.395	5.56387
443.929	6.61772
447.461	7.8966
450.99	9.05433
454.52	10.5496
458.048	10.6405
461.573	12.0572
465.099	13.4613
468.623	13.5133
472.144	14.3407
475.666	14.1035
479.184	15.3769
482.703	16.4702
486.218	16.9212
489.734	17.8401
493.247	18.337
496.759	18.4887
500.271	18.5735
503.779	18.8906
507.287	19.1303
510.795	19.0159
514.299	19.2578
517.803	18.3839
521.305	19.6269
524.805	19.5188
528.307	20.047
531.805	20.2598
535.301	19.165
538.797	18.0779
542.291	17.1615
545.783	16.5188
549.275	15.9537
552.765	15.362
556.253	13.6645
559.738	14.1542
563.224	13.0763
566.709	12.4438
570.192	11.5451
573.674	11.4436
577.153	11.5894
580.632	10.7379
584.11	9.17457
587.587	7.72126
591.06	7.53467
594.534	6.21462
598.005	6.0629
601.476	6.56371
604.944	7.03304
608.413	7.07724
611.878	7.59454
615.344	8.14241
618.807	7.75168
622.27	8.61908
625.73	8.99744
629.189	11.0759
632.648	11.9435
636.105	12.622
639.559	13.6928
643.013	16.0045
646.467	17.1143
649.918	18.8654
653.368	21.5608
656.816	24.1692
660.263	26.8586
663.708	27.1744
667.153	27.553
670.596	27.8101
674.037	28.2083
677.478	29.8472
680.917	31.0181
684.355	33.1538
687.791	34.441
691.224	34.8684
694.658	36.5097
698.091	36.5171
701.522	36.5633
704.95	37.0619
708.379	38.8068
711.806	39.8765
715.23	42.3207
718.655	43.5496
722.078	46.9554
725.498	50.0027
728.919	53.109
732.337	54.3668
735.755	57.2163
739.17	59.432
742.584	62.2208
745.998	64.7867
749.409	66.651
752.819	70.9124
756.23	72.9157
759.637	74.9635
763.043	77.6052
766.448	79.8179
769.853	81.0362
773.255	81.9302
776.656	82.4538
780.056	84.374
783.454	84.8678
786.851	86.016
790.247	88.5771
793.641	90.7131
797.034	91.6486
800.426	93.8469
803.817	94.8253
807.206	96.0661
810.592	96.0275
813.979	95.5592
817.364	95.8109
820.748	96.0106
824.129	95.7648
827.511	96.3389
830.891	95.0392
834.269	94.4284
837.646	92.8507
841.023	90.2846
844.396	87.3562
847.77	85.3609
851.141	82.2144
854.513	79.2459
857.881	76.6272
861.248	73.8557
864.616	72.3301
867.98	69.9072
871.343	70.4793
874.707	70.1372
878.068	68.0573
881.428	67.8277
884.786	67.1922
888.143	67.2728
891.498	67.3809
894.855	66.7133
898.208	66.0264
901.56	65.7217
904.91	64.9767
908.26	65.1564
911.608	64.0248
914.955	64.0381
918.298	63.5904
921.643	62.0413
924.986	61.6813
928.328	60.4707
931.668	60.4504
935.006	59.782
938.344	58.3869
941.681	57.8411
945.014	58.2336
948.349	59.3001
951.682	59.2145
955.012	58.0422
958.343	55.1564
961.67	54.8322
964.998	56.2694
968.323	57.6906
971.649	57.5809
974.971	57.0439
978.293	56.9385
981.615	56.2552
984.933	55.3999
988.251	54.7861
991.567	53.6341
994.884	52.2777
998.198	50.4169
1001.51	49.6135
1004.82	49.885
1008.13	48.5909
1011.44	47.4306
1014.75	47.7586
1018.06	46.5726
1021.36	45.584
1024.66	44.9027
1027.97	44.1996
1031.27	42.3747
1034.57	40.5382
1037.87	37.9527
1041.16	37.154
1044.46	39.8914
1047.76	40.0954
1051.05	39.6111
1054.34	38.4085
1057.63	37.8282
1060.92	36.0668
1064.21	34.7693
1067.5	33.1318
1070.78	32.2529
1074.07	31.0101
1077.35	30.6278
1080.63	29.4217
1083.91	29.171
1087.19	29.5955
1090.47	29.8997
1093.75	31.483
1097.03	31.0307
1100.3	30.3453
1103.57	30.4852
1106.84	31.3734
1110.11	30.8145
1113.38	30.4899
1116.65	29.4339
1119.92	28.7467
1123.19	28.3386
1126.45	29.0931
1129.71	27.2272
1132.97	25.3806
1136.23	24.5944
1139.49	23.3936
1142.75	23.4791
1146.01	22.1547
1149.26	20.0478
1152.52	18.4103
1155.77	16.7093
1159.02	15.503
1162.27	14.8312
1165.52	15.0947
1168.77	15.2267
1172.02	15.5001
1175.26	17.0275
1178.51	18.6259
1181.75	19.7413
1184.99	20.0702
1188.23	21.3331
1191.47	20.9947
1194.71	22.6957
1197.94	25.1684
1201.18	27.6477
1204.41	30.9589
1207.65	33.825
1210.88	36.2958
1214.11	39.0147
1217.34	43.4302
1220.57	45.9787
1223.79	48.2068
1227.02	50.0484
1230.24	50.9563
1233.47	52.8291
1236.69	55.0539
1239.91	56.4277
1243.13	57.3267
1246.34	57.921
1249.56	59.5189
1252.78	59.5622
1255.99	58.6439
1259.2	57.0201
1262.42	56.6138
1265.63	56.6769
1268.84	55.9553
1272.04	56.1947
1275.25	56.9564
1278.46	57.3546
1281.66	57.8687
1284.86	59.0559
1288.07	61.1639
1291.27	62.5796
1294.47	63.7613
1297.66	66.6306
1300.86	69.0188
1304.06	72.0028
1307.25	74.5732
1310.44	77.4663
1313.64	77.8713
1316.83	78.8445
1320.02	79.2305
1323.2	78.7665
1326.39	78.24
1329.58	77.4387
1332.76	75.26
1335.95	74.6087
1339.13	73.4974
1342.31	71.7991
1345.49	68.916
1348.67	66.061
1351.85	63.2696
1355.02	61.44
1358.2	59.0275
1361.37	56.547
1364.54	54.9697
1367.71	53.454
1370.88	51.5825
1374.05	50.3482
1377.22	49.8832
1380.39	49.0751
1383.55	47.9443
1386.72	46.3881
1389.88	44.5569
1393.04	43.4453
1396.2	41.1565
1399.36	39.97
1402.52	39.6816
1405.68	40.2236
1408.83	40.5347
1411.98	43.1839
1415.14	45.0421
1418.29	47.2031
1421.44	50.4276
1424.59	53.6062
1427.74	57.5908
1430.89	62.9201
1434.03	67.0946
1437.18	70.3614
1440.32	72.6901
1443.46	75.3599
1446.6	77.1568
1449.74	76.6327
1452.88	75.023
1456.02	73.6258
1459.16	71.6295
1462.29	67.3832
1465.43	62.5119
1468.56	57.7901
1471.69	52.7719
1474.82	46.8153
1477.95	42.3831
1481.08	37.3636
1484.2	34.2814
1487.33	30.6953
1490.46	28.3191
1493.58	25.538
1496.7	23.7563
1499.82	21.8576
1502.94	21.4745
1506.06	21.1723
1509.18	21.713
1512.29	22.0214
1515.41	21.5537
1518.52	22.9009
1521.63	23.3544
1524.75	23.7713
1527.85	24.8593
1530.96	26.0341
1534.07	28.9821
1537.18	30.2902
1540.28	31.1892
1543.39	32.7309
1546.49	34.8807
1549.59	38.0558
1552.69	40.8913
1555.79	44.0339
1558.89	47.3701
1561.99	50.1413
1565.08	51.59
1568.18	53.2156
1571.27	54.8549
1574.37	56.3008
1577.46	56.8497
1580.55	58.7055
1583.64	60.1899
1586.73	61.047
1589.81	61.3169
1592.9	62.6069
1595.98	61.5425
1599.06	60.701
1602.15	59.4263
1605.23	58.3284
1608.31	58.295
1611.39	58.2112
1614.46	57.6781
1617.54	56.5008
1620.61	57.134
1623.69	59.3141
1626.76	60.1597
1629.83	61.3458
1632.9	63.6945
1635.97	65.379
1639.04	66.5951
1642.11	68.5211
1645.17	70.8887
1648.24	72.8028
1651.3	74.513
1654.36	75.9657
1657.42	77.4267
1660.48	77.2123
1663.54	76.8398
1666.6	75.2606
1669.66	73.3342
1672.71	69.0061
1675.77	64.6621
1678.82	59.4112
1681.87	55.5843
1684.92	50.8305
1687.97	45.8607
1691.02	40.706
1694.07	35.4014
1697.11	32.2394
1700.16	27.1503
1703.2	23.4583
1706.25	20.5655
1709.29	17.1036
1712.33	15.2053
1715.37	13.8242
1718.41	12.8423
1721.44	12.3393
1724.48	11.6792
1727.51	10.9928
1730.55	11.2556
1733.58	10.6982
1736.61	9.43858
1739.64	8.9244
1742.67	8.35095
1745.7	7.51389
1748.72	6.40239
1751.75	5.08843
1754.77	4.02345
1757.8	4.06718
1760.82	3.62833
1763.84	2.57265
1766.86	1.673
1769.88	0.947648
1772.9	1.06607
1775.91	0.315726
1778.93	0.96241
1781.94	1.05342
1784.96	0.849509
1787.97	1.8289
1790.98	2.19009
1793.99	2.07897
1797	1.92278
1800.01	0.960819
1803.01	1.4237
1806.02	0.419776
1809.02	0.254063
1812.02	0.858122
1815.02	0.926967
1818.03	1.31851
1821.02	1.46531
1824.02	0.998359
1827.02	0.918396
1830.02	0.816302
1833.01	1.13868
1836.01	1.23813
1839	1.03291
1841.99	0.981405
1844.98	0.659563
1847.97	1.22637
1850.96	2.41837
1853.95	2.28686
1856.93	1.96171
1859.92	1.59793
1862.9	2.0623
1865.88	1.71022
1868.87	1.49617
1871.85	0.827326
1874.83	0.728111
1877.81	1.15579
1880.78	0.740121
1882.53	1.83389
1885.52	1.70874
1888.51	1.65077
1891.5	2.23255
1894.48	2.90055
1897.47	2.5469
1900.45	2.87299
1903.43	3.81724
1906.41	4.30171
1909.39	4.5369
1912.37	5.01741
1915.35	4.96398
1918.33	4.62108
1921.3	5.43541
1924.28	5.30098
1927.25	4.4536
1930.22	4.16386
1933.19	3.67692
1936.16	3.75977
1939.13	4.06057
1942.1	3.50956
1945.07	3.73735
1948.03	3.79234
1951	4.29938
1953.96	4.7092
1956.92	4.98007
1959.88	4.5983
1962.84	3.5858
1965.8	3.8623
1968.76	3.74588
1971.72	3.91633
1974.67	4.71481
1977.63	4.82044
1980.58	5.28787
1983.54	5.77434
1986.49	5.59718
1989.44	5.30804
1992.39	5.38983
1995.33	5.55932
1998.28	4.18153
2001.23	4.53179
2004.17	4.74534
2007.12	5.41286
2010.06	6.28481
2013	6.16886
2015.94	7.01238
2018.88	6.93017
2021.82	6.97918
2024.76	6.9166
2027.69	6.70061
2030.63	5.77929
2033.56	5.42035
2036.5	6.7657
2039.43	6.85606
2042.36	7.37735
2045.29	8.13716
2048.22	8.15321
2051.15	8.56823
2054.07	9.0187
2057	9.15704
2059.92	9.0456
2062.85	9.72387
2065.77	9.7623
2068.69	9.5415
2071.61	10.2269
2074.53	10.3054
2077.45	9.79824
2080.37	10.397
2083.28	10.9554
2086.2	11.1365
2089.11	11.015
2092.02	10.2558
2094.94	9.92411
2097.85	11.0181
2100.76	12.1552
2103.66	12.9104
2106.57	13.9307
2109.48	14.9311
2112.38	15.1938
2115.29	14.9458
2118.19	16.2095
2121.09	16.2183
2123.99	17.4054
2126.89	18.0286
2129.79	19.0031
2132.69	20.2704
2135.59	20.9018
2138.48	21.4485
2141.38	21.5265
2144.27	22.2289
2147.17	22.6278
2150.06	23.9776
2152.95	25.2543
2155.84	26.071
2158.73	26.7267
2161.61	27.1157
2164.5	27.1946
2167.38	28.9155
2170.27	30.2635
2173.15	29.445
2176.03	29.2906
2178.91	29.3118
2181.8	29.0376
2184.67	28.2518
2187.55	27.4088
2190.43	27.4741
2193.3	26.6767
2196.18	26.1815
2199.05	24.7535
2201.93	23.9756
2204.8	22.7408
2207.67	21.0879
2210.54	19.6995
2213.41	18.6991
2216.27	18.0934
2219.14	17.1882
2222.01	16.5417
2224.87	15.6098
2227.73	15.5466
2230.6	14.7366
2233.46	13.228
2236.32	13.166
2239.18	13.3236
2242.03	11.2954
2244.89	10.2433
2247.75	10.6834
2250.6	10.4219
2253.46	9.48973
2256.31	9.80001
2259.16	9.45583
2262.01	9.47187
2264.86	8.48588
2267.71	8.48241
2270.56	8.03095
2273.4	8.06333
2276.25	7.78168
2279.09	6.9444
2281.94	6.8613
2284.78	7.18954
2287.62	6.87526
2290.46	5.78703
2293.3	5.65818
2296.14	6.96587
2298.98	8.27193
2301.82	8.59437
2304.65	8.98325
2307.49	9.10555
2310.32	9.48575
2313.15	8.54839
2315.98	9.33718
2318.81	9.16248
2321.64	8.46663
2324.47	8.89906
2327.3	8.89195
2330.12	8.75343
2332.95	8.22438
2335.77	8.14346
2338.6	7.52486
2341.42	6.6022
2344.24	6.25314
2347.06	5.90889
2349.88	5.32475
2352.7	4.38408
2355.51	3.45066
2358.33	2.7206
2361.14	3.2849
2363.96	4.17324
2366.77	4.55985
2369.58	4.21743
2372.39	3.83171
2375.2	2.76245
2378.01	2.93694
2380.82	2.70322
2383.63	2.42384
2386.43	2.47941
2389.24	2.1863
2392.04	1.11556
2394.84	2.25489
2397.65	2.03864
2400.45	2.53823
2403.25	2.66842
2406.05	3.2924
2408.84	3.09408
2411.64	3.71814
2414.44	4.23408
2417.23	4.93418
2420.02	5.25791
2422.82	5.74778
2425.61	6.93435
2428.4	7.15753
2431.19	7.81765
2433.98	7.29861
2436.77	7.74634
2439.55	8.27598
2442.34	8.34012
2445.12	8.59336
2447.91	9.12966
2450.69	8.60316
2453.47	7.55876
2456.25	6.43366
2459.03	6.09977
2461.81	5.81144
2464.59	5.51333
2467.36	4.14477
2470.14	3.65601
2472.92	2.18314
2475.69	1.50655
2478.46	1.07307
2481.23	0.586598
2484	0.612807
2486.77	1.31165
2489.54	1.33576
2492.31	1.56353
2495.08	1.43135
2497.84	1.59498
2500.61	1.28604
2503.37	1.52398
2506.13	2.05753
2508.9	2.17846
2511.66	2.99712
2514.42	2.72753
2517.18	2.54155
2519.93	2.55076
2522.69	2.41451
2525.45	2.66045
2528.2	2.67739
2530.95	2.22329
2533.71	2.01682
2536.46	2.08764
2539.21	2.75738
2541.96	2.87111
2544.71	3.10966
2547.46	2.87974
2550.2	3.23428
2552.95	3.19187
2555.7	3.18798
2558.44	3.35358
2561.18	3.20853
2563.93	2.82279
2566.67	3.27967
2569.41	2.9208
2572.15	2.14177
2574.88	1.38577
2577.62	1.13761
2580.36	-0.270052
2583.09	-0.116219
2585.83	0.0734247
2588.56	-0.0125582
2591.29	0.326737
2594.02	-0.303995
2596.75	-0.139327
2599.48	-0.0259732
2602.21	-0.0402939
2604.94	-0.00845486
2607.67	0.243375
2610.39	0.320496
2613.12	0.0931287
2615.84	0.470886
2618.56	0.528276
2621.28	0.871301
2624.01	1.71761
2626.72	2.05142
2629.44	2.26311
2632.16	2.87672
2634.88	2.62973
2637.59	1.88685
2640.31	1.70328
2643.02	2.1605
2645.74	2.63834
2648.45	2.86207
2651.16	3.61326
2653.87	3.17152
2656.58	2.73023
2659.29	2.72145
2661.99	2.63839
2664.7	2.49852
2667.41	2.60041
2670.11	2.84551
2672.81	2.87655
2675.51	3.39919
2678.22	3.56078
2680.92	3.50159
2683.62	3.99196
2686.31	4.91058
2689.01	6.11873
2691.71	6.35475
2694.4	6.88663
2697.1	7.38189
2699.79	7.82138
2702.49	8.64475
2705.18	9.86138
2707.87	11.0931
2710.56	11.0625
2713.25	11.396
2715.94	12.2229
2718.62	12.6064
2721.31	12.2227
2723.99	12.6402
2726.68	12.9607
2729.36	12.5307
2732.04	12.1813
2734.73	11.7573
2737.41	10.9124
2740.08	10.3113
2742.76	10.3016
2745.44	9.54855
2748.12	9.10081
2750.79	8.86638
2753.47	8.45477
2756.14	7.39423
2758.81	6.86616
2761.49	6.3553
2764.16	6.64438
2766.83	6.41906
2769.5	6.44585
2772.16	7.10869
2774.83	6.76211
2777.5	7.33553
2780.16	8.66066
2782.83	9.55775
2785.49	8.94225
2788.15	8.77651
2790.82	9.47472
2793.48	9.80089
2796.14	9.86777
2798.79	10.169
2801.45	9.73459
2804.11	9.93417
2806.76	9.31927
2809.42	9.23088
2812.07	8.7259
2814.73	9.3105
2817.38	9.99244
2820.03	11.3525
2822.68	14.2656
2825.33	18.197
2827.98	22.2109
2830.63	26.1831
2833.27	30.7243
2835.92	35.3787
2838.56	41.1797
2841.21	48.904
2843.85	56.8875
2846.49	64.6884
2849.13	73.2968
2851.77	82.7044
2854.41	93.2187
2857.05	103.781
2859.69	112.275
2862.32	120.756
2864.96	128.757
2867.59	135.424
2870.23	141.392
2872.86	146.755
2875.49	151.759
2878.12	155.751
2880.75	159.552
2883.38	164.042
2886.01	167.956
2888.63	172.032
2891.26	175.464
2893.89	178.243
2896.51	182.415
2899.13	186.892
2901.76	193.922
2904.38	201.918
2907	210.625
2909.62	219.66
2912.24	230.007
2914.85	240.651
2917.47	249.868
2920.09	259.596
2922.7	265.068
2925.32	269.401
2927.93	272.264
2930.54	272.732
2933.15	270.608
2935.76	267.281
2938.37	263.102
2940.98	255.883
2943.59	248.518
2946.2	239.518
2948.8	229.992
2951.41	219.826
2954.01	209.866
2956.62	200.07
2959.22	190.324
2961.82	181.257
2964.42	173.137
2967.02	165.513
2969.62	157.234
2972.22	150.051
2974.81	144.327
2977.41	137.273
2980	129.873
2982.6	122.19
2985.19	113.812
2987.78	105.713
2990.38	97.0452
2992.97	88.4753
2995.56	81.1866
2998.14	73.5612
3000.73	67.0323
3003.32	60.3544
3005.91	53.499
3008.49	47.7171
3011.07	42.2268
3013.66	38.6846
3016.24	34.7358
3018.82	32.1816
3021.4	28.7845
3023.98	27.7398
3026.56	25.9986
3029.14	24.7536
3031.71	23.9124
3034.29	23.7811
3036.87	24.7387
3039.44	25.3284
3042.01	25.5412
3044.59	26.5521
3047.16	27.6735
3049.73	28.4871
3052.3	28.2296
3054.87	28.2014
3057.43	28.5669
3060	29.041
3062.57	28.1451
3065.13	27.1628
3067.7	25.4378
3070.26	23.8344
3072.82	22.377
3075.39	20.8931
3077.95	19.1828
3080.51	16.0428
3083.07	13.3521
3085.63	11.7544
3088.18	9.28819
3090.74	8.12878
3093.29	6.63155
3095.85	5.84253
3098.4	5.27588
3100.95	4.72202
3103.51	3.92004
3106.06	3.81925
3108.61	4.02678
3111.16	3.62277
3113.71	2.96003
3116.25	2.90433
3118.8	2.99286
3121.35	3.19377
3123.89	3.21151
3126.44	3.12329
3128.98	2.72472
3131.52	2.28607
3134.06	2.75478
3136.6	1.87242
3139.14	0.837117
3141.68	-0.0392253
3144.22	-0.278084
3146.76	-0.181824
3149.29	0.270428