File: data/Raman/poly_smoothed/Thy_50_12_1_1x_45s_532 nm_x100_100%_600 gr_mm_01.txt
#Acq. time (s)=	45
#Accumulations=	2
#Range (cm-¹)=	200...3150
#Windows=	2
#Auto scanning=	Off
#Autofocus=	Off
#Macrospot=	Off
#AutoExposure=	Off
#Spike filter=	Multiple accum.
#Delay time (s)=	0
#Binning=	1
#Readout mode=	Signal
#DeNoise=	Off
#ICS correction=	On
#Dark correction=	Off
#Inst. Process=	Off
#Detector Gain=	Best Dynamic Range
#Detector ADC=	20 kHz
#Detector temperature (°C)=	-69.85
#Instrument=	LabRAM HR Evol
#Detector=	Synapse
#Objective=	x100
#Grating=	600 gr/mm
#ND Filter=	100%
#Laser (nm)=	532
#Hole=	100.021
#Range=	Auto
#Laser Pol.=	No
#Raman. Pol.=	No
#Laser Pol. (°)=	-0.0007625
#Raman Pol. (°)=	89.9995
#Collection=	Microscope
#StageXY=	Marzhauser
#StageZ=	Marzhauser
#X (µm)=	-5087.5
#Y (µm)=	1509.6
#Z (µm)=	62.85
#Full time(mm:ss)=	3:18
#Project=
#Sample=
#Site=
#Title=	Thy_50_12_1_2x_45s_532 nm_x100_100%_600 gr_mm
#Remark=
#Date=	07.07.2022 09:09
#Acquired=	07.07.2022 09:09:55
#Base:Fit=	10.08.2022 10:04:29
#Base:Sub=	10.08.2022 10:04:45
#Filter:Polynom=	16.08.2022 10:20:24
#AxisType[0]=Intens
#AxisUnit[0]=Cnt
#AxisType[1]=Spectr
#AxisUnit[1]=1/cm
200.43	58.7417
204.061	51.0737
207.688	46.2279
211.316	42.0468
214.941	39.9674
218.566	36.4815
222.188	33.4321
225.809	29.7566
229.43	27.5657
233.047	24.6179
236.663	22.3701
240.278	21.2745
243.894	18.3486
247.506	15.1879
251.116	12.3169
254.725	11.8617
258.333	11.4305
261.939	10.5283
265.546	9.68845
269.15	8.82067
272.752	7.1876
276.353	6.18598
279.952	2.53013
283.55	0.973093
287.146	1.27492
290.739	0.219889
294.333	3.05529
297.925	2.73169
301.516	4.48741
305.106	4.10238
308.694	3.7545
312.279	4.20346
315.864	4.69897
319.448	5.09923
323.029	5.42805
326.61	6.34248
330.19	7.12588
333.766	7.07559
337.343	8.31788
340.917	9.06114
344.491	9.7597
348.062	9.03116
351.633	8.17473
355.201	7.22787
358.77	8.68076
362.335	6.42542
365.899	5.04701
369.464	4.99278
373.025	4.52309
376.585	5.37947
380.143	4.68796
383.702	3.39055
387.258	2.5525
390.812	2.92259
394.365	3.04874
397.916	2.56167
401.467	2.98127
405.015	3.57853
408.565	2.47025
412.111	4.22802
415.656	6.23867
419.197	6.54706
422.739	4.92169
426.279	4.38832
429.819	4.67117
433.356	4.71085
436.893	3.60939
440.428	4.91389
443.96	5.84326
447.492	5.77782
451.023	5.69611
454.553	4.93615
458.079	4.61456
461.606	5.20307
465.132	5.20359
468.654	5.82272
472.177	7.52012
475.696	8.88837
479.217	8.75052
482.733	9.46191
486.251	10.3585
489.765	12.0927
493.278	12.2936
496.791	13.9228
500.301	16.486
503.81	17.8855
507.319	18.6647
510.825	20.8082
514.33	22.2798
517.833	22.4438
521.337	23.3545
524.838	24.9974
528.337	25.4717
531.835	24.332
535.332	24.5592
538.827	23.0695
542.321	22.5747
545.814	22.0139
549.305	20.5552
552.795	18.7984
556.284	16.9354
559.771	12.9803
563.257	9.50825
566.742	6.95867
570.223	5.63976
573.705	5.93948
577.185	4.37422
580.665	3.52322
584.141	3.99363
587.617	2.86913
591.092	3.30812
594.564	2.87522
598.037	2.72489
601.506	3.41634
604.976	4.93907
608.443	6.6231
611.91	7.1513
615.374	9.30959
618.839	12
622.3	14.5659
625.761	16.9653
629.221	18.2247
632.679	20.2195
636.135	21.1754
639.592	22.9104
643.045	24.5345
646.497	25.3619
649.948	26.434
653.398	30.5728
656.846	31.0319
660.293	31.9042
663.738	32.9348
667.185	34.0317
670.628	34.2616
674.067	34.9175
677.508	37.0979
680.947	38.1107
684.385	40.616
687.821	41.8694
691.256	44.2097
694.69	43.8049
698.121	46.2018
701.552	48.6797
704.982	50.1962
708.41	52.594
711.836	54.1471
715.262	54.475
718.685	54.3311
722.108	55.5111
725.53	58.2806
728.949	57.6576
732.369	58.0975
735.785	59.6494
739.2	60.24
742.616	61.7232
746.028	62.1894
749.441	63.4937
752.851	65.0506
756.26	66.514
759.667	69.3871
763.075	71.7536
766.479	74.1782
769.883	74.9811
773.285	77.2344
776.686	79.1761
780.085	81.2956
783.484	83.8238
786.881	85.4889
790.276	87.6033
793.671	89.9153
797.064	90.2145
800.456	91.7118
803.846	93.3519
807.236	93.5648
810.624	93.9302
814.01	93.2373
817.394	95.0088
820.778	94.7167
824.161	93.8862
827.543	93.9989
830.921	92.9372
834.3	89.9663
837.676	89.364
841.053	88.344
844.426	86.6324
847.8	84.6862
851.171	83.384
854.542	80.4212
857.911	79.5645
861.279	77.4628
864.645	74.7687
868.01	72.0513
871.375	69.7141
874.737	69.698
878.097	67.9991
881.457	65.6981
884.817	64.7125
888.174	62.0824
891.53	60.0859
894.884	58.9937
898.237	59.9104
901.589	61.4147
904.94	60.2393
908.289	59.5227
911.637	58.4466
914.984	56.692
918.33	56.6524
921.674	56.0495
925.015	55.1329
928.357	53.3723
931.698	51.3382
935.037	50.8285
938.373	49.6701
941.71	51.171
945.046	49.4634
948.378	47.1006
951.711	47.98
955.043	48.2121
958.372	46.3775
961.701	45.8614
965.027	44.4908
968.354	45.6733
971.678	43.1744
975	44.0462
978.324	43.7005
981.644	41.6272
984.962	39.8045
988.282	38.0957
991.598	37.2559
994.913	35.2231
998.227	35.7205
1001.54	32.393
1004.85	29.2089
1008.16	28.0868
1011.47	28.2163
1014.78	28.5687
1018.08	28.4987
1021.39	30.7338
1024.69	29.9185
1028	30.8723
1031.3	32.7636
1034.6	34.4464
1037.9	34.2215
1041.19	36.5813
1044.49	37.8996
1047.79	38.6026
1051.08	37.2119
1054.37	36.7583
1057.66	35.879
1060.95	34.3794
1064.24	31.7891
1067.53	31.7456
1070.81	31.7316
1074.1	28.7499
1077.38	27.6156
1080.66	24.4715
1083.94	21.5412
1087.22	20.0977
1090.5	19.6141
1093.78	19.0213
1097.05	17.6879
1100.33	18.8726
1103.6	18.8263
1106.87	17.3134
1110.15	18.5732
1113.41	17.9644
1116.68	16.691
1119.95	18.5962
1123.21	18.806
1126.48	17.7914
1129.74	17.8328
1133	17.9804
1136.26	16.4884
1139.52	16.1499
1142.78	15.1537
1146.04	16.0146
1149.29	15.7152
1152.55	13.8506
1155.8	10.7314
1159.05	8.96165
1162.3	8.95261
1165.55	8.69932
1168.8	8.31298
1172.05	7.71745
1175.29	7.81461
1178.54	6.39079
1181.78	4.93764
1185.02	3.1115
1188.26	4.3825
1191.5	5.99696
1194.74	5.42281
1197.97	5.07111
1201.21	6.51268
1204.44	7.63225
1207.68	8.59981
1210.91	10.1382
1214.14	11.2337
1217.37	13.1835
1220.6	15.2417
1223.82	16.986
1227.05	20.0782
1230.27	20.0313
1233.49	21.8501
1236.72	23.7981
1239.94	27.3129
1243.16	30.6058
1246.37	30.9377
1249.59	32.7386
1252.8	34.3645
1256.02	37.0982
1259.23	38.7699
1262.44	40.2418
1265.66	44.7465
1268.87	49.3947
1272.07	51.5489
1275.28	52.4825
1278.48	54.0796
1281.69	54.2742
1284.89	54.6184
1288.09	55.052
1291.3	53.3621
1294.49	54.0101
1297.69	54.4858
1300.89	53.0398
1304.09	51.4382
1307.28	50.2628
1310.47	49.3586
1313.66	48.4605
1316.86	46.8131
1320.05	46.1459
1323.23	43.7926
1326.42	42.6582
1329.61	41.2251
1332.79	39.5396
1335.98	38.6521
1339.16	37.5485
1342.34	39.7748
1345.52	40.3239
1348.7	40.7087
1351.87	39.5386
1355.05	38.2885
1358.23	37.1458
1361.4	36.7203
1364.57	34.0714
1367.74	32.4925
1370.91	32.1259
1374.08	32.6654
1377.25	31.4192
1380.42	28.913
1383.58	29.3137
1386.75	28.2529
1389.91	27.6527
1393.07	27.026
1396.23	25.8521
1399.39	26.0187
1402.55	25.999
1405.7	27.397
1408.86	28.1113
1412.01	31.1647
1415.17	32.44
1418.32	35.0498
1421.47	38.1925
1424.62	42.27
1427.77	45.7337
1430.92	47.6012
1434.06	48.9334
1437.2	52.7125
1440.35	53.7802
1443.49	55.5067
1446.63	59.1631
1449.77	60.1465
1452.91	58.8153
1456.05	56.0609
1459.18	55.0486
1462.32	52.4991
1465.45	48.374
1468.59	45.0277
1471.72	43.3804
1474.85	40.73
1477.98	38.9459
1481.11	35.1292
1484.23	31.1895
1487.36	26.7321
1490.48	24.7649
1493.61	22.4072
1496.73	21.5805
1499.85	18.8818
1502.97	18.3584
1506.09	14.9213
1509.2	15.7362
1512.32	16.2898
1515.44	17.5412
1518.55	18.471
1521.66	18.9668
1524.77	18.9898
1527.88	18.8933
1530.99	17.9494
1534.1	20.1919
1537.21	23.0909
1540.31	23.1394
1543.42	27.6636
1546.52	30.7355
1549.62	34.7201
1552.72	36.8596
1555.82	39.0667
1558.92	40.6209
1562.02	43.779
1565.11	46.954
1568.21	48.533
1571.3	50.3957
1574.39	52.1799
1577.49	52.7239
1580.58	54.697
1583.67	55.5462
1586.75	56.9457
1589.84	57.2353
1592.93	56.703
1596.01	55.3361
1599.09	53.6377
1602.18	50.874
1605.26	50.1746
1608.34	48.7031
1611.41	47.3667
1614.49	47.8864
1617.57	48.3656
1620.64	49.8443
1623.72	49.0573
1626.79	49.3538
1629.86	49.7824
1632.93	49.7251
1636	49.5881
1639.07	50.4278
1642.14	50.5827
1645.2	51.2812
1648.27	51.8707
1651.33	52.3941
1654.39	52.2802
1657.45	51.6734
1660.51	51.0065
1663.57	50.0481
1666.63	47.0635
1669.69	44.4086
1672.74	42.0992
1675.79	37.7872
1678.85	35.2538
1681.9	33.2196
1684.95	30.1957
1688	30.6969
1691.05	28.7954
1694.1	26.1691
1697.14	23.8189
1700.19	23.1087
1703.23	21.9941
1706.27	21.2456
1709.32	19.513
1712.35	17.7232
1715.39	15.9689
1718.43	16.393
1721.47	14.7
1724.5	14.9053
1727.54	14.2829
1730.57	13.8953
1733.61	13.141
1736.64	11.1646
1739.67	10.7456
1742.7	9.538
1745.72	9.57308
1748.75	9.35105
1751.78	7.63213
1754.8	7.50202
1757.82	6.43322
1760.85	6.48987
1763.87	6.00139
1766.89	4.65976
1769.91	4.86342
1772.92	4.22462
1775.94	3.71913
1778.96	2.51504
1781.97	1.62687
1784.98	1.68651
1788	1.71367
1791.01	2.48868
1794.01	3.28764
1797.02	4.75939
1800.03	5.5676
1803.04	5.47203
1806.04	7.13662
1809.05	7.62651
1812.05	7.79501
1815.05	7.69832
1818.05	7.28939
1821.05	6.61658
1824.05	6.6657
1827.05	7.45127
1830.04	6.42845
1833.04	5.7676
1836.03	5.8149
1839.03	4.2028
1842.02	3.95588
1845.01	3.14282
1848	2.45567
1850.99	2.68014
1853.97	2.08307
1856.96	3.06992
1859.94	2.78225
1862.93	3.33232
1865.91	4.68161
1868.89	5.74427
1871.87	5.72676
1874.85	5.71536
1877.83	6.23803
1880.81	6.4468
1882.56	5.91801
1885.55	6.931
1888.54	6.74755
1891.52	6.5758
1894.51	7.10991
1897.49	7.33363
1900.48	6.59446
1903.46	5.7251
1906.44	5.65315
1909.42	5.59171
1912.4	4.4983
1915.38	5.40195
1918.35	5.43377
1921.33	6.98304
1924.3	6.35834
1927.28	5.56836
1930.25	5.40132
1933.22	6.32881
1936.19	4.87226
1939.16	4.06217
1942.13	3.35843
1945.09	3.5037
1948.06	2.72784
1951.03	2.5367
1953.99	2.68882
1956.95	1.99988
1959.91	1.09397
1962.87	-0.111036
1965.83	-1.10396
1968.79	-0.412348
1971.75	-0.898463
1974.7	-0.99528
1977.66	-1.24677
1980.61	-0.151361
1983.56	0.55331
1986.52	2.08834
1989.47	3.43726
1992.41	3.83786
1995.36	4.60693
1998.31	4.55637
2001.26	4.59214
2004.2	4.91468
2007.15	4.93364
2010.09	5.302
2013.03	6.54542
2015.97	7.52871
2018.91	7.47437
2021.85	6.55798
2024.79	8.27488
2027.72	8.86767
2030.66	8.5721
2033.59	9.81053
2036.53	9.84089
2039.46	10.0739
2042.39	10.1973
2045.32	11.1756
2048.25	12.1469
2051.18	12.4439
2054.1	13.7255
2057.03	14.6851
2059.95	15.3022
2062.88	14.8837
2065.8	14.9113
2068.72	15.2136
2071.64	15.9903
2074.56	15.612
2077.48	17.1236
2080.39	19.0369
2083.31	19.721
2086.22	21.2442
2089.14	22.6919
2092.05	22.8704
2094.96	23.7653
2097.87	25.0104
2100.78	26.4158
2103.69	28.2708
2106.6	30.1325
2109.51	30.4266
2112.41	32.7092
2115.32	34.5573
2118.22	38.4688
2121.12	39.7858
2124.02	42.5187
2126.92	44.7935
2129.82	47.8359
2132.72	50.9344
2135.62	53.7889
2138.51	57.9205
2141.41	60.7313
2144.3	63.2611
2147.19	65.6904
2150.09	69.5681
2152.97	71.8222
2155.86	75.4669
2158.75	77.7714
2161.64	78.9639
2164.53	80.5498
2167.41	80.8996
2170.3	82.4946
2173.18	83.6999
2176.06	83.6209
2178.94	82.007
2181.82	80.2319
2184.7	79.7643
2187.58	77.7968
2190.46	76.1478
2193.33	73.7425
2196.21	72.0105
2199.08	70.1923
2201.95	67.1306
2204.83	65.7336
2207.7	62.7382
2210.57	58.285
2213.43	56.4508
2216.3	54.0478
2219.17	52.0482
2222.03	50.858
2224.9	47.5515
2227.76	46.5989
2230.62	43.6162
2233.49	41.5904
2236.34	38.8424
2239.2	37.6068
2242.06	35.5529
2244.92	33.1761
2247.78	31.4482
2250.63	29.9421
2253.48	28.0191
2256.34	26.8976
2259.19	25.7538
2262.04	24.7927
2264.89	23.3759
2267.74	22.8888
2270.59	20.7738
2273.43	20.1243
2276.28	17.0328
2279.12	16.3177
2281.97	15.6606
2284.81	13.6367
2287.65	12.2374
2290.49	11.2743
2293.33	10.5859
2296.17	9.45034
2299.01	9.62062
2301.84	9.06426
2304.68	9.87103
2307.51	10.8456
2310.35	11.3741
2313.18	10.2582
2316.01	10.7763
2318.84	10.803
2321.67	9.99049
2324.5	10.6854
2327.33	10.6677
2330.15	10.9485
2332.98	11.0242
2335.8	8.98015
2338.62	7.75564
2341.45	6.23497
2344.27	4.88228
2347.09	4.41531
2349.91	4.08001
2352.72	2.29875
2355.54	1.37476
2358.36	0.516882
2361.17	0.677296
2363.98	0.62229
2366.8	0.90542
2369.61	1.09475
2372.42	1.02038
2375.23	1.83007
2378.04	2.28614
2380.85	3.62796
2383.66	4.33741
2386.46	5.26343
2389.26	5.00282
2392.07	6.65939
2394.87	6.89997
2397.67	6.17653
2400.47	6.59753
2403.27	6.24951
2406.07	7.36867
2408.87	8.64483
2411.67	10.6273
2414.46	10.4394
2417.26	11.4007
2420.05	12.0211
2422.84	12.472
2425.64	12.021
2428.43	11.7457
2431.22	10.9937
2434.01	10.3211
2436.79	10.2033
2439.58	10.4901
2442.37	10.9704
2445.15	10.5763
2447.93	10.5906
2450.72	10.3359
2453.5	10.6655
2456.28	10.2984
2459.06	9.81944
2461.84	10.5987
2464.62	10.1284
2467.39	10.6479
2470.17	11.2173
2472.94	12.6745
2475.72	13.281
2478.49	12.9693
2481.26	12.1798
2484.03	12.2199
2486.8	12.8205
2489.57	12.863
2492.34	10.8052
2495.1	9.5948
2497.87	8.62321
2500.63	7.66814
2503.4	7.41452
2506.16	7.16313
2508.92	6.38311
2511.68	6.36866
2514.44	5.38882
2517.2	5.44647
2519.96	7.15451
2522.72	8.36837
2525.47	9.35872
2528.23	10.5377
2530.98	10.1409
2533.74	9.33256
2536.49	9.38457
2539.24	8.98168
2541.99	8.17808
2544.74	7.7143
2547.49	6.94653
2550.23	5.6759
2552.98	6.10576
2555.72	5.86214
2558.47	5.01798
2561.21	4.6211
2563.95	4.76259
2566.69	3.68758
2569.43	3.15229
2572.17	2.92837
2574.91	3.29989
2577.65	4.00785
2580.39	4.60158
2583.12	5.04371
2585.85	6.19253
2588.59	6.80006
2591.32	7.48727
2594.05	8.2024
2596.78	7.97058
2599.51	7.37351
2602.24	8.70013
2604.97	9.71959
2607.69	8.78641
2610.42	8.75465
2613.14	8.54356
2615.87	7.7427
2618.59	7.17994
2621.31	6.94823
2624.03	6.39576
2626.75	5.77758
2629.47	5.04303
2632.19	5.58337
2634.91	4.66878
2637.62	6.23573
2640.34	6.74434
2643.05	7.68991
2645.76	7.9602
2648.48	8.23536
2651.19	8.51236
2653.9	8.88876
2656.6	10.6276
2659.31	11.8147
2662.02	12.8576
2664.73	13.3665
2667.43	13.4892
2670.14	14.2702
2672.84	13.2393
2675.54	13.3974
2678.24	12.1194
2680.94	11.5707
2683.64	10.9579
2686.34	10.3051
2689.04	11.2274
2691.74	11.2117
2694.43	10.5707
2697.13	11.4267
2699.82	11.2773
2702.51	11.9316
2705.21	12.6884
2707.9	12.6291
2710.58	11.9395
2713.27	12.8126
2715.96	13.3643
2718.65	14.3729
2721.33	14.9394
2724.02	15.582
2726.71	14.3749
2729.39	14.7061
2732.07	15.3277
2734.75	15.3857
2737.43	15.2061
2740.11	13.8573
2742.79	13.4529
2745.47	12.0892
2748.14	12.1612
2750.82	13.4587
2753.49	13.1673
2756.17	12.0435
2758.84	11.2344
2761.51	10.876
2764.18	10.719
2766.85	10.7324
2769.52	9.8077
2772.19	9.14444
2774.86	8.2901
2777.52	7.10221
2780.19	7.09605
2782.85	6.12655
2785.52	5.07709
2788.18	3.49695
2790.84	3.18824
2793.5	3.02543
2796.16	3.17017
2798.82	3.21937
2801.48	2.56348
2804.13	1.89591
2806.79	1.28579
2809.45	1.2386
2812.1	1.61788
2814.75	1.97871
2817.41	3.07665
2820.06	4.2231
2822.71	6.20645
2825.36	9.34875
2828	13.8849
2830.65	18.7881
2833.3	22.3604
2835.94	26.3894
2838.59	30.0136
2841.23	33.3743
2843.87	36.6548
2846.52	41.1963
2849.16	46.552
2851.8	51.4271
2854.44	57.0083
2857.08	63.9899
2859.71	70.0217
2862.35	74.2885
2864.98	78.8039
2867.62	82.127
2870.25	85.0377
2872.88	87.4159
2875.52	90.2459
2878.15	93.7744
2880.78	95.4915
2883.41	97.8357
2886.03	100.533
2888.66	103.805
2891.29	106.807
2893.91	111.73
2896.54	114.103
2899.16	116.608
2901.78	121.099
2904.4	125.108
2907.02	131.011
2909.64	136.634
2912.26	143.73
2914.88	149.523
2917.5	155.678
2920.11	161.046
2922.73	166.586
2925.34	168.997
2927.96	170.874
2930.57	172.239
2933.18	171.446
2935.79	170.329
2938.4	167.502
2941.01	164.531
2943.62	159.477
2946.22	152.882
2948.83	147.992
2951.43	141.822
2954.04	136.297
2956.64	128.295
2959.24	121.111
2961.84	114.654
2964.45	108.886
2967.05	104.024
2969.64	98.9111
2972.24	92.4874
2974.84	87.5355
2977.43	81.7721
2980.03	75.6897
2982.62	70.7178
2985.22	65.0334
2987.81	59.0113
2990.4	53.0801
2992.99	47.2356
2995.58	41.7216
2998.17	35.8831
3000.76	30.596
3003.34	25.3961
3005.93	21.0483
3008.52	16.9325
3011.1	13.6831
3013.68	9.41519
3016.27	7.40637
3018.85	4.21715
3021.43	1.96039
3024.01	0.553299
3026.59	0.209103
3029.16	-0.458235
3031.74	-1.69812
3034.32	-2.06608
3036.89	-1.47667
3039.47	-0.532825
3042.04	-0.155133
3044.61	0.663852
3047.18	1.07163
3049.75	0.772827
3052.32	1.42519
3054.89	1.61411
3057.46	2.15848
3060.03	0.830077
3062.59	0.916251
3065.16	2.39318
3067.72	2.6962
3070.29	3.63928
3072.85	3.85347
3075.41	4.32339
3077.97	5.12895
3080.53	4.98045
3083.09	3.89433
3085.65	3.91557
3088.21	2.99098
3090.76	2.21922
3093.32	1.78022
3095.87	2.51051
3098.43	3.26591
3100.98	3.07704
3103.53	2.36666
3106.08	3.44261
3108.63	3.23304
3111.18	3.44558
3113.73	4.6226
3116.28	5.78865
3118.83	7.11214
3121.37	7.32802
3123.92	8.23862
3126.46	11.2702
3129	12.3901
3131.55	14.0531
3134.09	15.3754
3136.63	15.7362
3139.17	17.2111
3141.71	16.7916
3144.24	16.0793
3146.78	14.5018
3149.32	14.4585