File: data/Raman/poly_smoothed/Thy_20_09_32_1x_45s_532 nm_x100_100%_600 gr_mm_01.txt
#Acq. time (s)=	45
#Accumulations=	2
#Range (cm-¹)=	200...3150
#Windows=	2
#Auto scanning=	Off
#Autofocus=	Off
#Macrospot=	Off
#AutoExposure=	Off
#Spike filter=	Multiple accum.
#Delay time (s)=	0
#Binning=	1
#Readout mode=	Signal
#DeNoise=	Off
#ICS correction=	On
#Dark correction=	Off
#Inst. Process=	Off
#Detector Gain=	Best Dynamic Range
#Detector ADC=	20 kHz
#Detector temperature (°C)=	-69.85
#Instrument=	LabRAM HR Evol
#Detector=	Synapse
#Objective=	x100
#Grating=	600 gr/mm
#ND Filter=	100%
#Laser (nm)=	532
#Hole=	100.021
#Range=	Auto
#Laser Pol.=	No
#Raman. Pol.=	No
#Laser Pol. (°)=	-0.0007625
#Raman Pol. (°)=	89.9995
#Collection=	Microscope
#StageXY=	Marzhauser
#StageZ=	Marzhauser
#X (µm)=	-5919.2
#Y (µm)=	2878.7
#Z (µm)=	-223.45
#Full time(mm:ss)=	3:18
#Project=
#Sample=
#Site=
#Title=	Thy_20_09_32_2x_45s_532 nm_x100_100%_600 gr_mm
#Remark=
#Date=	29.06.2022 12:52
#Acquired=	29.06.2022 12:52:55
#Base:Fit=	10.08.2022 09:52:02
#Base:Fit=	10.08.2022 09:52:12
#Base:Sub=	10.08.2022 09:54:21
#Filter:Polynom=	16.08.2022 10:24:04
#AxisType[0]=Intens
#AxisUnit[0]=Cnt
#AxisType[1]=Spectr
#AxisUnit[1]=1/cm
200.523	9.40632
204.154	10.406
207.781	8.52706
211.409	7.11787
215.034	6.0224
218.659	6.32483
222.281	7.27871
225.903	7.69492
229.522	8.06655
233.14	7.78592
236.756	7.31494
240.373	7.05681
243.986	7.06947
247.598	6.17585
251.208	5.44041
254.818	4.31391
258.427	3.52841
262.034	3.94139
265.638	3.9561
269.242	3.39758
272.844	3.96985
276.445	4.31112
280.044	4.32637
283.642	4.0755
287.238	3.7623
290.833	5.28255
294.425	6.16498
298.017	7.85895
301.608	10.7437
305.198	11.7135
308.786	14.0756
312.371	15.6747
315.956	17.2408
319.54	17.7418
323.122	17.9131
326.701	17.4882
330.281	16.2954
333.857	14.806
337.434	14.0466
341.008	12.754
344.582	12.1152
348.153	12.4276
351.724	10.7724
355.292	9.72052
358.861	8.64113
362.426	6.99159
365.99	6.05959
369.555	4.81504
373.116	5.21039
376.676	6.1866
380.236	6.16092
383.793	8.24281
387.349	8.62456
390.903	8.99551
394.456	9.00568
398.007	9.67835
401.56	7.8129
405.108	7.89299
408.656	7.90117
412.202	7.90869
415.746	8.66921
419.29	8.86698
422.831	9.94566
426.37	11.2411
429.909	10.9746
433.447	10.5071
436.983	10.6482
440.519	9.91975
444.052	9.58713
447.583	9.91644
451.114	10.4751
454.643	10.7379
458.169	12.4759
461.696	14.3365
465.222	15.9528
468.744	17.757
472.267	17.1409
475.787	16.106
479.307	15.5369
482.823	14.9388
486.341	16.5915
489.855	18.0141
493.37	19.4334
496.881	21.9698
500.391	24.5005
503.902	24.0391
507.409	23.9502
510.915	26.2618
514.42	25.0785
517.925	24.5567
521.427	24.7473
524.928	24.5996
528.427	22.9388
531.925	21.4384
535.422	20.6267
538.917	20.5919
542.411	19.3818
545.903	19.4631
549.395	17.3981
552.884	16.5688
556.373	13.4015
559.86	11.1494
563.346	9.88489
566.831	10.2898
570.314	10.1431
573.794	10.9769
577.274	10.401
580.754	9.69949
584.23	10.202
587.706	7.77439
591.181	6.34076
594.653	6.48053
598.126	6.05067
601.595	5.31972
605.065	5.43058
608.532	5.45039
611.999	6.86236
615.463	7.15979
618.928	7.55169
622.389	8.08299
625.851	9.57807
629.31	10.8757
632.767	12.8094
636.223	13.83
639.68	13.9637
643.134	16.7072
646.586	18.8049
650.037	20.1494
653.486	21.4051
656.936	22.3125
660.383	22.1681
663.829	23.9245
667.273	23.7815
670.716	23.1777
674.158	22.1339
677.598	22.879
681.035	24.2749
684.473	25.3636
687.909	26.089
691.344	27.1981
694.778	27.9679
698.211	30.1228
701.64	30.7768
705.07	31.6176
708.498	35.5157
711.924	40.2107
715.35	42.1133
718.774	44.4345
722.196	47.2313
725.618	49.5224
729.037	51.6128
732.456	53.5963
735.873	54.1858
739.289	55.4962
742.703	55.8069
746.116	55.9269
749.529	56.9326
752.938	58.0538
756.347	60.1119
759.756	60.3583
763.162	63.0625
766.567	63.6911
769.97	64.3381
773.372	64.2407
776.773	66.1734
780.174	66.9253
783.573	68.2304
786.97	69.2265
790.365	70.6283
793.76	72.4286
797.153	72.3767
800.543	74.6983
803.933	74.7773
807.322	76.5034
810.71	75.881
814.097	75.8855
817.483	76.2265
820.865	77.4192
824.248	77.0821
827.629	75.4798
831.008	75.0347
834.387	75.5905
837.765	74.4178
841.139	72.8891
844.514	73.6602
847.886	72.2112
851.259	69.4268
854.629	68.5518
857.997	65.6306
861.366	63.8801
864.732	62.1711
868.098	58.4018
871.461	55.5295
874.823	54.0046
878.184	53.7845
881.545	53.0248
884.903	53.2218
888.26	53.1156
891.616	52.9441
894.97	52.3453
898.323	51.0173
901.675	50.899
905.026	50.0659
908.375	47.647
911.723	46.6497
915.07	46.4768
918.415	45.9505
921.76	45.7913
925.103	44.9163
928.443	42.2112
931.783	40.2627
935.123	39.7405
938.461	38.2599
941.796	36.0613
945.131	34.9396
948.465	33.7451
951.797	34.1767
955.128	34.5295
958.457	34.1119
961.786	32.0699
965.113	34.2784
968.44	35.9167
971.763	37.5251
975.086	38.9483
978.409	40.7048
981.729	41.9996
985.048	41.7053
988.367	42.555
991.683	42.1813
994.998	41.8191
998.312	41.3984
1001.62	40.9581
1004.94	39.3964
1008.25	37.2238
1011.56	34.7575
1014.86	34.592
1018.17	32.1307
1021.48	29.0737
1024.78	26.5641
1028.08	25.9778
1031.38	25.0207
1034.68	22.3204
1037.98	20.4335
1041.28	20.1751
1044.57	22.0908
1047.87	22.7759
1051.16	22.8674
1054.45	22.9936
1057.75	23.6349
1061.04	22.6253
1064.32	22.4336
1067.61	21.3725
1070.9	21.4577
1074.18	22.3948
1077.47	22.4183
1080.75	22.5131
1084.03	22.105
1087.31	21.195
1090.59	20.5918
1093.86	20.8841
1097.14	21.3006
1100.41	21.3649
1103.69	21.5065
1106.96	22.6899
1110.23	21.7281
1113.5	20.8923
1116.77	21.5051
1120.03	21.5226
1123.3	20.8119
1126.56	20.0812
1129.83	18.1355
1133.09	16.5525
1136.35	15.6593
1139.61	15.0464
1142.86	14.2886
1146.12	13.0065
1149.38	12.1346
1152.63	10.149
1155.88	7.83905
1159.14	5.9631
1162.39	4.32046
1165.63	3.5553
1168.88	3.30404
1172.13	4.45879
1175.38	5.44956
1178.62	5.90969
1181.86	5.66573
1185.1	6.75519
1188.34	7.49928
1191.58	8.75979
1194.82	10.1742
1198.06	14.3927
1201.29	17.0074
1204.53	18.97
1207.76	21.5145
1210.99	25.5026
1214.22	29.8528
1217.45	35.7325
1220.68	39.7372
1223.91	44.0832
1227.13	49.0109
1230.36	53.7831
1233.58	56.5688
1236.8	59.3891
1240.02	62.3706
1243.24	65.0606
1246.46	66.7525
1249.67	69.6989
1252.89	72.0629
1256.1	73.2577
1259.32	74.3819
1262.53	75.6913
1265.74	78.0043
1268.95	78.8459
1272.15	81.1547
1275.36	82.1685
1278.57	84.6071
1281.77	85.4534
1284.97	87.8637
1288.18	90.2444
1291.38	92.9592
1294.58	96.4472
1297.78	99.4256
1300.97	101.734
1304.17	104.907
1307.36	107.439
1310.55	107.76
1313.75	108.662
1316.94	107.13
1320.13	108.827
1323.32	108.046
1326.5	106.098
1329.69	104.884
1332.87	101.786
1336.06	99.4132
1339.24	97.2488
1342.42	94.6847
1345.6	91.1338
1348.78	87.0999
1351.96	84.5896
1355.13	81.5651
1358.31	76.9193
1361.48	73.8794
1364.65	72.124
1367.82	70.0872
1370.99	69.3954
1374.16	67.968
1377.33	66.8833
1380.5	67.2197
1383.66	66.3238
1386.83	64.287
1389.99	64.6366
1393.15	63.2956
1396.31	62.0376
1399.47	60.4098
1402.63	58.7514
1405.78	56.9727
1408.94	58.118
1412.1	60.0942
1415.25	63.1653
1418.4	68.7022
1421.55	73.07
1424.7	78.9598
1427.85	86.1459
1431	93.2641
1434.14	97.7413
1437.29	103.919
1440.43	109.806
1443.57	114.396
1446.71	116.927
1449.85	116.974
1452.99	114.78
1456.13	114.006
1459.26	109.882
1462.4	103.314
1465.54	94.5761
1468.67	86.2507
1471.8	77.7092
1474.93	68.6355
1478.06	59.7976
1481.19	51.9192
1484.31	43.8538
1487.44	38.2035
1490.56	34.2867
1493.69	31.5315
1496.81	29.9347
1499.93	28.4837
1503.05	28.9457
1506.17	28.9599
1509.28	27.3412
1512.4	27.7817
1515.52	30.5657
1518.63	32.1953
1521.74	33.3653
1524.85	33.3739
1527.96	30.7016
1531.07	32.2178
1534.18	36.2363
1537.29	41.43
1540.39	45.0491
1543.5	50.1263
1546.6	57.9172
1549.7	65.6175
1552.8	71.1013
1555.9	75.2857
1559	80.1022
1562.1	83.816
1565.19	89.8969
1568.29	95.5016
1571.38	99.8028
1574.47	103.347
1577.56	106.462
1580.66	108.639
1583.74	110.704
1586.83	111.532
1589.92	111.801
1593.01	110.757
1596.09	106.402
1599.17	102.654
1602.25	98.2047
1605.34	97.165
1608.41	98.6315
1611.49	97.9916
1614.57	95.7592
1617.65	93.4866
1620.72	94.705
1623.79	94.5131
1626.87	93.6001
1629.94	94.4107
1633.01	96.4611
1636.08	98.905
1639.15	100.34
1642.21	102.919
1645.28	104.77
1648.34	106.614
1651.41	108.454
1654.47	110.69
1657.53	111.507
1660.59	110.346
1663.65	107.833
1666.71	103.978
1669.76	99.6849
1672.82	94.6755
1675.87	90.7872
1678.93	84.2746
1681.98	76.6288
1685.03	69.6115
1688.08	62.379
1691.13	54.0101
1694.17	47.1999
1697.22	42.8676
1700.27	38.1048
1703.31	34.7349
1706.35	32.9457
1709.39	29.1346
1712.43	25.7498
1715.47	22.3702
1718.51	20.9125
1721.55	19.0516
1724.58	18.4761
1727.62	18.1125
1730.65	18.1076
1733.68	16.2361
1736.72	16.7126
1739.74	15.404
1742.77	14.2027
1745.8	12.777
1748.83	12.0554
1751.85	10.0367
1754.88	8.56809
1757.9	7.15036
1760.92	4.98462
1763.95	4.23806
1766.96	2.99323
1769.98	2.50067
1773	1.83683
1776.02	1.45602
1779.03	1.57149
1782.05	1.3383
1785.06	0.225653
1788.07	-0.470409
1791.08	0.261903
1794.09	1.17164
1797.1	1.74452
1800.11	1.7165
1803.12	2.88471
1806.12	3.43981
1809.12	4.19426
1812.13	4.49182
1815.13	4.16536
1818.13	4.41612
1821.13	4.392
1824.13	4.31074
1827.13	3.79737
1830.12	3.71376
1833.12	3.38895
1836.11	3.55133
1839.1	4.09591
1842.09	3.68045
1845.09	3.00715
1848.08	3.15644
1851.06	2.86666
1854.05	3.21157
1857.04	2.70122
1860.02	2.94309
1863.01	3.54816
1865.99	3.20888
1868.97	3.48277
1871.95	2.89916
1874.93	2.71876
1877.91	3.77
1880.89	4.23062
1882.46	3.21334
1885.45	2.84658
1888.43	2.18836
1891.42	2.61919
1894.41	1.39047
1897.39	0.862063
1900.37	1.75166
1903.36	1.20742
1906.34	1.84589
1909.32	1.90993
1912.29	0.98049
1915.27	0.370947
1918.25	0.661872
1921.23	1.05708
1924.2	1.83286
1927.17	2.17328
1930.15	2.78654
1933.12	3.21993
1936.09	3.64531
1939.06	4.1142
1942.02	3.49779
1944.99	2.72618
1947.96	3.48158
1950.92	3.33475
1953.88	2.72315
1956.85	3.318
1959.81	3.17799
1962.77	3.48344
1965.73	3.7807
1968.69	3.1901
1971.64	3.8035
1974.6	3.59037
1977.55	3.4422
1980.51	4.29037
1983.46	4.55725
1986.41	3.52285
1989.36	4.81081
1992.31	4.51502
1995.26	4.41895
1998.21	5.42646
2001.15	5.67449
2004.1	6.07197
2007.04	5.29758
2009.99	4.92964
2012.93	5.88734
2015.87	5.69214
2018.81	6.18563
2021.75	6.81939
2024.68	7.61958
2027.62	7.33596
2030.56	7.33113
2033.49	6.75381
2036.42	7.27942
2039.36	7.11529
2042.29	7.60677
2045.22	8.44485
2048.14	8.90025
2051.07	10.1418
2054	10.1805
2056.93	10.3152
2059.85	10.2756
2062.77	10.367
2065.7	10.5011
2068.62	11.6048
2071.54	13.2306
2074.46	13.4855
2077.38	13.7177
2080.29	14.3815
2083.21	16.9053
2086.12	18.6885
2089.04	19.1114
2091.95	19.7074
2094.86	20.397
2097.77	20.0841
2100.68	21.1756
2103.59	22.8628
2106.5	24.5221
2109.41	25.9426
2112.31	28.1074
2115.21	29.9175
2118.12	31.9785
2121.02	34.7209
2123.92	35.9389
2126.82	37.37
2129.72	40.3351
2132.62	42.8382
2135.51	45.9362
2138.41	49.2601
2141.31	52.6576
2144.2	54.743
2147.09	58.2967
2149.98	60.8522
2152.87	64.0445
2155.76	65.602
2158.65	68.2244
2161.54	69.3971
2164.43	70.6475
2167.31	71.2991
2170.2	71.5252
2173.08	72.5286
2175.96	72.837
2178.84	72.4089
2181.72	72.0339
2184.6	70.5529
2187.48	68.5341
2190.36	67.0759
2193.23	64.0841
2196.11	61.4451
2198.98	58.4167
2201.85	56.1306
2204.72	53.1575
2207.59	50.3986
2210.46	46.8518
2213.33	43.1603
2216.2	40.3837
2219.07	37.0726
2221.93	33.6362
2224.8	31.6225
2227.66	29.6498
2230.52	28.0628
2233.39	25.7798
2236.25	24.0784
2239.1	23.3274
2241.96	22.9324
2244.82	22.3569
2247.68	22.3188
2250.53	20.4038
2253.38	19.6224
2256.24	18.2768
2259.09	17.4338
2261.94	16.0418
2264.79	15.3611
2267.64	14.5647
2270.49	13.4569
2273.33	12.8205
2276.18	11.5008
2279.02	10.822
2281.87	9.16677
2284.71	8.98774
2287.55	8.56809
2290.39	7.73967
2293.23	6.74809
2296.07	7.08483
2298.91	8.33074
2301.74	9.03641
2304.58	10.0486
2307.41	10.2436
2310.25	10.4327
2313.08	11.0534
2315.91	11.6135
2318.74	11.1102
2321.57	10.4227
2324.4	10.6334
2327.23	10.9664
2330.05	11.0783
2332.88	10.3143
2335.7	9.13292
2338.52	8.61181
2341.35	8.04613
2344.17	7.37759
2346.99	7.49343
2349.81	6.84991
2352.62	6.55126
2355.44	6.48881
2358.26	5.07528
2361.07	3.61806
2363.89	3.67432
2366.7	3.98964
2369.51	4.11579
2372.32	3.46645
2375.13	3.0771
2377.94	3.27722
2380.75	4.14335
2383.56	4.53795
2386.36	4.3711
2389.17	3.94798
2391.97	4.0046
2394.77	5.12659
2397.58	5.15002
2400.38	4.65864
2403.18	4.85743
2405.97	5.75463
2408.77	7.01669
2411.57	7.55493
2414.37	8.00917
2417.16	8.25191
2419.95	8.19444
2422.75	8.84429
2425.54	8.8607
2428.33	7.4953
2431.12	7.1557
2433.91	5.82634
2436.7	5.16699
2439.48	5.08975
2442.27	4.17164
2445.05	3.51649
2447.84	3.55613
2450.62	2.59381
2453.4	2.33588
2456.18	1.30089
2458.96	1.36343
2461.74	0.860814
2464.52	0.802222
2467.29	0.690672
2470.07	0.414403
2472.85	0.427428
2475.62	0.265694
2478.39	-0.132356
2481.16	-1.28152
2483.93	-0.12705
2486.7	0.0813426
2489.47	0.483627
2492.24	0.67807
2495.01	0.483055
2497.77	0.084945
2500.54	0.276347
2503.3	0.539464
2506.06	0.766588
2508.83	1.44253
2511.59	1.37696
2514.35	2.26442
2517.11	3.31261
2519.86	3.81709
2522.62	5.07028
2525.38	5.29578
2528.13	6.42476
2530.89	6.22454
2533.64	6.49598
2536.39	6.82761
2539.14	6.30995
2541.89	6.88965
2544.64	6.71037
2547.39	6.85719
2550.14	7.36606
2552.88	6.84551
2555.63	6.61735
2558.37	6.60478
2561.11	6.15901
2563.86	4.78434
2566.6	4.38598
2569.34	3.99035
2572.08	3.18083
2574.82	3.12015
2577.55	3.80486
2580.29	4.34869
2583.02	4.92244
2585.76	5.29695
2588.49	5.18848
2591.22	3.99459
2593.96	3.1202
2596.69	4.16311
2599.42	4.46631
2602.14	5.14724
2604.87	5.91387
2607.6	6.18392
2610.32	6.10052
2613.05	5.64721
2615.77	5.88971
2618.49	5.9553
2621.22	5.81295
2623.94	6.02442
2626.66	5.07954
2629.37	3.97002
2632.09	2.98088
2634.81	2.96914
2637.53	2.23174
2640.24	1.62035
2642.96	2.03116
2645.67	2.16747
2648.38	1.68333
2651.09	2.45632
2653.8	2.03041
2656.51	3.39917
2659.22	3.91994
2661.93	5.51254
2664.63	7.16401
2667.34	7.72257
2670.04	8.62464
2672.75	9.31987
2675.45	10.1846
2678.15	10.6447
2680.85	11.0368
2683.55	11.9806
2686.25	11.4312
2688.94	11.6433
2691.64	11.4383
2694.34	11.7506
2697.03	10.7605
2699.73	10.5917
2702.42	10.6045
2705.11	9.28716
2707.8	9.07885
2710.49	9.6281
2713.18	9.73726
2715.87	10.6608
2718.55	11.3178
2721.24	11.0004
2723.93	11.8349
2726.61	11.3581
2729.29	12.0335
2731.98	12.2871
2734.66	12.3127
2737.34	12.2312
2740.02	12.5892
2742.7	13.0767
2745.37	13.3272
2748.05	12.1189
2750.72	11.6264
2753.4	10.8063
2756.07	10.9797
2758.75	10.6014
2761.42	10.0158
2764.09	9.00072
2766.76	8.12671
2769.43	6.25234
2772.1	6.15815
2774.76	5.0355
2777.43	4.87008
2780.1	4.07645
2782.76	3.7009
2785.42	2.88224
2788.09	2.43598
2790.75	2.59982
2793.41	2.61943
2796.07	2.17072
2798.73	2.88933
2801.39	3.51336
2804.04	4.23292
2806.7	4.51304
2809.35	3.88605
2812.01	3.70167
2814.66	3.23534
2817.31	5.61912
2819.96	8.50022
2822.61	12.4878
2825.26	18.3166
2827.91	25.9279
2830.56	32.0905
2833.21	39.5638
2835.85	46.7719
2838.5	55.2386
2841.14	64.2378
2843.78	74.9937
2846.42	87.6454
2849.06	101.143
2851.71	114.451
2854.34	130.217
2856.98	145.532
2859.62	159.377
2862.26	172.92
2864.89	185.661
2867.53	196.26
2870.16	205.426
2872.79	212.606
2875.42	218.757
2878.05	225.233
2880.68	229.948
2883.31	234.504
2885.94	239.923
2888.57	244.686
2891.19	250.568
2893.82	255.349
2896.44	259.5
2899.07	266.402
2901.69	273.392
2904.31	283.419
2906.93	295.268
2909.55	309.879
2912.17	326.363
2914.79	341.314
2917.41	357.965
2920.02	370.876
2922.64	379.641
2925.25	388.321
2927.86	392.95
2930.48	394.896
2933.09	393.497
2935.7	388.78
2938.31	381.331
2940.92	372.589
2943.53	361.973
2946.13	348.429
2948.74	335.148
2951.34	321.196
2953.95	306.472
2956.55	292.073
2959.15	277.316
2961.75	262.242
2964.35	248.417
2966.95	235.01
2969.55	223.342
2972.15	212.209
2974.75	202.031
2977.34	190.396
2979.94	178.752
2982.53	166.128
2985.13	152.011
2987.72	139.633
2990.31	126.595
2992.9	113.916
2995.49	102.035
2998.08	90.2902
3000.67	79.5047
3003.25	70.3398
3005.84	61.5847
3008.42	53.5003
3011.01	46.6245
3013.59	40.5741
3016.17	35.7261
3018.76	31.4704
3021.34	27.2031
3023.92	23.5794
3026.49	20.8018
3029.07	18.9902
3031.65	18.9141
3034.23	18.9687
3036.8	19.4858
3039.38	20.3879
3041.95	22.091
3044.52	24.0349
3047.09	25.2075
3049.66	26.4521
3052.23	27.3831
3054.8	28.6347
3057.37	29.8327
3059.94	30.0517
3062.5	30.3303
3065.07	28.7077
3067.63	27.5445
3070.2	25.2092
3072.76	23.1864
3075.32	20.7968
3077.88	18.2827
3080.44	15.9129
3083	11.7603
3085.56	9.06741
3088.12	6.42855
3090.67	4.01303
3093.23	2.28694
3095.78	1.60401
3098.34	0.68684
3100.89	1.17381
3103.44	1.09262
3105.99	0.772024
3108.54	1.12989
3111.09	1.76386
3113.64	3.52896
3116.19	4.80596
3118.74	5.68252
3121.28	6.67365
3123.83	7.55186
3126.37	7.63327
3128.91	8.34186
3131.46	8.94852
3134	9.25841
3136.54	9.82012
3139.08	10.2521
3141.62	10.0879
3144.16	9.84706
3146.69	10.0041
3149.23	10.7415