File: data/Raman/poly_smoothed/Thy_40_11_49_1x_45s_532 nm_x100_100%_600 gr_mm_01.txt
#Acq. time (s)=	45
#Accumulations=	2
#Range (cm-¹)=	200...3150
#Windows=	2
#Auto scanning=	Off
#Autofocus=	Off
#Macrospot=	Off
#AutoExposure=	Off
#Spike filter=	Multiple accum.
#Delay time (s)=	0
#Binning=	1
#Readout mode=	Signal
#DeNoise=	Off
#ICS correction=	On
#Dark correction=	Off
#Inst. Process=	Off
#Detector Gain=	Best Dynamic Range
#Detector ADC=	20 kHz
#Detector temperature (°C)=	-69.85
#Instrument=	LabRAM HR Evol
#Detector=	Synapse
#Objective=	x100
#Grating=	600 gr/mm
#ND Filter=	100%
#Laser (nm)=	532
#Hole=	100.021
#Range=	Auto
#Laser Pol.=	No
#Raman. Pol.=	No
#Laser Pol. (°)=	-0.0007625
#Raman Pol. (°)=	89.9995
#Collection=	Microscope
#StageXY=	Marzhauser
#StageZ=	Marzhauser
#X (µm)=	260
#Y (µm)=	1693.1
#Z (µm)=	427.6
#Full time(mm:ss)=	3:19
#Project=
#Sample=
#Site=
#Title=	Thy_40_11_49_2x_45s_532 nm_x100_100%_600 gr_mm
#Remark=
#Date=	05.07.2022 13:29
#Acquired=	05.07.2022 13:29:33
#Base:Fit=	10.08.2022 10:01:35
#Base:Sub=	10.08.2022 10:01:52
#Filter:Polynom=	16.08.2022 10:21:53
#AxisType[0]=Intens
#AxisUnit[0]=Cnt
#AxisType[1]=Spectr
#AxisUnit[1]=1/cm
200.43	16.6266
204.059	16.6543
207.688	15.3163
211.314	14.3406
214.941	12.725
218.564	11.7147
222.186	10.5058
225.809	10.6437
229.428	9.95722
233.045	7.71399
236.663	6.38681
240.278	5.46787
243.891	4.63319
247.503	4.38667
251.116	3.29306
254.725	1.88633
258.333	1.19767
261.939	0.96863
265.544	0.466341
269.148	0.79773
272.75	-0.379715
276.351	1.02848
279.95	1.01211
283.548	1.94486
287.144	0.57596
290.739	1.54124
294.333	1.90929
297.925	3.89939
301.514	4.19996
305.104	4.75175
308.692	6.18584
312.279	7.00879
315.862	7.81058
319.446	7.3994
323.029	6.92535
326.608	6.47336
330.188	6.91606
333.766	7.98504
337.341	8.1794
340.917	7.90554
344.489	7.51019
348.062	6.39238
351.631	6.94892
355.201	5.70543
358.768	5.70148
362.333	4.99097
365.899	5.42085
369.462	5.55537
373.023	6.65398
376.585	7.61466
380.143	7.61117
383.7	8.20037
387.256	9.55365
390.812	8.52665
394.365	7.70439
397.916	7.6989
401.467	8.08393
405.015	7.9536
408.563	6.79993
412.109	7.39812
415.654	8.39337
419.197	9.31547
422.739	9.08124
426.279	8.7107
429.819	7.25845
433.356	6.70551
436.891	6.95454
440.426	8.35645
443.96	7.79386
447.492	8.38391
451.021	8.95182
454.551	11.1158
458.079	12.5463
461.604	13.5602
465.13	12.1665
468.654	12.2351
472.175	13.7518
475.696	13.1667
479.215	12.7389
482.733	13.302
486.249	12.9488
489.765	13.0913
493.278	13.2292
496.789	14.5906
500.301	16.2199
503.81	15.9406
507.317	16.6324
510.825	16.5383
514.33	17.2711
517.833	17.3611
521.335	17.4933
524.836	18.0909
528.335	16.7233
531.835	15.6801
535.332	14.3678
538.827	12.7068
542.321	10.9247
545.814	10.3301
549.305	8.17477
552.795	7.31036
556.282	5.51395
559.769	4.51
563.255	2.81169
566.739	2.77204
570.223	2.02262
573.705	2.42882
577.183	2.24632
580.663	2.85521
584.141	3.66809
587.615	6.0341
591.09	5.96716
594.564	6.39146
598.035	6.1242
601.506	8.28958
604.974	8.30371
608.443	9.72591
611.908	11.3052
615.374	11.8029
618.837	11.2487
622.3	11.2533
625.761	11.4128
629.219	12.427
632.677	12.8013
636.135	11.373
639.59	10.228
643.043	8.69669
646.495	10.6359
649.948	12.303
653.398	12.7475
656.846	12.9736
660.293	13.3232
663.738	12.7085
667.183	13.7187
670.626	15.2088
674.067	17.1308
677.508	18.1567
680.947	19.5907
684.385	21.9084
687.821	24.1635
691.254	26.4117
694.688	30.051
698.121	31.3631
701.552	32.6901
704.98	34.0982
708.409	34.4413
711.836	34.9326
715.26	35.0118
718.685	36.0066
722.108	35.7241
725.528	37.4234
728.949	40.408
732.367	41.472
735.785	43.32
739.2	44.9992
742.614	47.168
746.028	49.6284
749.439	52.3772
752.849	55.0044
756.26	57.1997
759.667	59.6121
763.073	61.8865
766.477	63.2446
769.883	65.2735
773.285	67.3937
776.686	68.4418
780.085	70.4964
783.484	70.3685
786.881	70.865
790.276	70.8335
793.671	72.9356
797.064	73.3685
800.456	75.3295
803.846	75.4472
807.234	76.1757
810.622	76.8307
814.008	75.2185
817.394	75.334
820.778	75.0295
824.159	73.5024
827.541	72.9747
830.921	71.7022
834.298	68.9688
837.676	67.7914
841.051	65.1596
844.426	62.5743
847.798	59.5068
851.171	56.1014
854.54	53.9071
857.911	51.4605
861.278	48.4645
864.645	46.2736
868.01	45.2093
871.373	45.9262
874.735	46.269
878.097	45.6365
881.457	45.502
884.815	44.846
888.172	44.2079
891.528	44.6663
894.882	41.9067
898.237	40.9249
901.589	40.6998
904.94	38.9447
908.289	38.0136
911.635	38.4401
914.982	37.7935
918.328	38.4362
921.672	37.9025
925.015	37.0815
928.357	37.3615
931.698	36.8794
935.035	34.947
938.373	33.1524
941.71	32.9191
945.044	31.9162
948.378	32.6655
951.709	34.1343
955.041	34.8304
958.372	34.9524
961.699	33.9741
965.027	34.458
968.352	36.0028
971.676	34.7428
975	33.4171
978.322	32.3578
981.642	33.5972
984.962	34.0305
988.28	33.9722
991.596	33.9628
994.911	32.0467
998.227	32.0939
1001.54	32.0236
1004.85	31.5759
1008.16	30.0396
1011.47	28.2456
1014.78	27.1756
1018.08	26.0315
1021.39	25.6578
1024.69	26.3366
1028	26.3483
1031.3	26.9381
1034.6	26.5061
1037.9	26.2418
1041.19	25.5656
1044.49	25.001
1047.78	25.2535
1051.08	24.2373
1054.37	23.9772
1057.66	22.9808
1060.95	22.4
1064.24	22.372
1067.53	21.742
1070.81	19.8456
1074.1	18.8664
1077.38	19.5878
1080.66	19.807
1083.94	20.082
1087.22	20.416
1090.5	19.338
1093.78	21.0959
1097.05	21.4818
1100.33	21.4785
1103.6	21.5144
1106.87	21.8701
1110.14	20.8246
1113.41	20.3058
1116.68	19.2399
1119.95	17.8059
1123.21	15.8153
1126.48	13.9995
1129.74	13.2183
1133	11.7231
1136.26	10.1837
1139.52	8.48551
1142.78	9.6018
1146.04	8.56618
1149.29	7.32548
1152.55	5.77499
1155.8	6.36902
1159.05	4.45555
1162.3	3.03572
1165.55	2.16209
1168.8	1.86946
1172.05	3.15149
1175.29	4.05977
1178.54	2.8438
1181.78	1.93145
1185.02	2.5926
1188.26	2.71909
1191.5	4.34716
1194.74	5.69545
1197.97	7.06998
1201.21	7.17648
1204.44	10.0198
1207.68	14.4127
1210.91	17.2699
1214.14	20.6808
1217.37	24.3405
1220.59	28.8124
1223.82	31.7039
1227.05	34.5832
1230.27	37.9525
1233.49	41.239
1236.72	42.6406
1239.94	45.1209
1243.16	46.0433
1246.37	47.5635
1249.59	48.7851
1252.8	50.6672
1256.02	49.8198
1259.23	49.4078
1262.44	50.1794
1265.66	50.6917
1268.86	52.0629
1272.07	52.4542
1275.28	53.267
1278.48	54.3219
1281.69	56.5079
1284.89	57.8753
1288.09	59.3755
1291.29	61.0943
1294.49	64.2069
1297.69	65.4696
1300.89	67.8067
1304.08	68.7512
1307.28	71.227
1310.47	70.9728
1313.66	70.235
1316.85	71.0636
1320.04	70.2769
1323.23	69.9336
1326.42	69.6909
1329.61	67.6673
1332.79	65.2533
1335.97	62.5974
1339.16	60.6387
1342.34	58.3553
1345.52	56.7524
1348.7	54.9415
1351.87	52.7176
1355.05	51.1159
1358.22	48.7236
1361.4	47.0023
1364.57	45.1219
1367.74	43.2792
1370.91	41.8215
1374.08	42.0049
1377.25	41.9193
1380.41	40.2379
1383.58	39.0625
1386.74	38.2718
1389.91	38.6746
1393.07	37.4229
1396.23	36.9332
1399.39	36.8436
1402.55	34.0802
1405.7	33.1443
1408.86	32.8225
1412.01	33.4712
1415.17	35.2674
1418.32	37.757
1421.47	40.7526
1424.62	44.2717
1427.77	48.8123
1430.91	52.7361
1434.06	56.3375
1437.2	60.2214
1440.35	63.68
1443.49	66.3855
1446.63	68.1687
1449.77	70.249
1452.91	70.396
1456.05	69.7478
1459.18	67.8803
1462.32	64.826
1465.45	62.1604
1468.59	58.1139
1471.72	53.8345
1474.85	48.7655
1477.98	43.6839
1481.1	38.1012
1484.23	33.2522
1487.36	29.6666
1490.48	28.558
1493.61	26.1139
1496.73	26.0451
1499.85	25.2588
1502.97	24.3735
1506.09	23.6821
1509.2	23.3108
1512.32	22.9024
1515.43	24.4486
1518.55	25.4959
1521.66	25.5595
1524.77	25.9228
1527.88	27.1436
1530.99	27.2473
1534.1	28.882
1537.21	29.757
1540.31	31.0881
1543.42	33.5277
1546.52	35.3774
1549.62	37.4994
1552.72	39.8874
1555.82	42.9879
1558.92	44.7452
1562.02	47.7888
1565.11	51.5763
1568.21	54.8464
1571.3	56.7871
1574.39	59.3732
1577.49	62.1834
1580.57	63.0406
1583.66	63.5612
1586.75	65.3208
1589.84	66.1025
1592.92	66.5379
1596.01	66.218
1599.09	64.8968
1602.17	64.7566
1605.25	64.1703
1608.33	64.2442
1611.41	64.1121
1614.49	63.3369
1617.57	64.1549
1620.64	64.8609
1623.72	65.1162
1626.79	66.3294
1629.86	68.4801
1632.93	71.2936
1636	72.6394
1639.07	74.0484
1642.13	78.1373
1645.2	80.076
1648.26	82.4204
1651.33	84.7883
1654.39	84.8122
1657.45	85.5508
1660.51	85.754
1663.57	83.0969
1666.63	80.9756
1669.68	78.3394
1672.74	74.7497
1675.79	71.3175
1678.85	67.1875
1681.9	62.2918
1684.95	57.486
1688	51.9878
1691.05	46.7783
1694.09	40.7114
1697.14	35.1973
1700.18	31.0452
1703.23	27.6433
1706.27	24.8159
1709.31	23.0157
1712.35	21.5071
1715.39	20.1955
1718.43	19.5887
1721.47	18.9059
1724.5	18.8173
1727.54	17.7313
1730.57	17.075
1733.61	17.0139
1736.64	15.57
1739.67	14.4962
1742.7	14.4186
1745.72	12.9811
1748.75	11.7965
1751.77	11.0407
1754.8	9.76374
1757.82	8.76394
1760.84	8.33044
1763.87	7.09654
1766.89	5.8563
1769.91	5.53008
1772.92	5.23828
1775.94	5.30557
1778.95	5.70302
1781.97	6.27263
1784.98	6.56939
1787.99	5.70708
1791.01	5.16897
1794.01	5.08561
1797.02	4.19331
1800.03	2.79771
1803.04	1.80834
1806.04	1.15938
1809.05	1.19069
1812.05	0.335159
1815.05	0.547069
1818.05	0.295532
1821.05	-0.0860279
1824.05	0.927443
1827.05	1.42614
1830.04	1.9128
1833.04	3.2854
1836.03	4.19351
1839.03	5.00593
1842.02	5.79294
1845.01	7.03458
1848	7.32893
1850.99	7.66961
1853.97	8.79312
1856.96	9.23948
1859.94	9.23214
1862.93	9.48871
1865.91	9.37919
1868.89	8.84774
1871.87	7.74698
1874.85	7.25023
1877.83	7.03916
1880.81	7.24832
1882.57	7.34804
1885.56	7.20617
1888.55	6.95259
1891.54	7.56214
1894.52	7.63462
1897.51	8.39907
1900.49	9.31946
1903.47	9.21321
1906.45	8.92628
1909.43	8.80256
1912.41	9.64253
1915.39	8.94633
1918.37	8.91649
1921.34	8.26763
1924.32	8.17477
1927.29	7.60506
1930.26	7.60038
1933.23	6.84289
1936.2	5.93407
1939.17	5.05614
1942.14	4.28457
1945.11	4.0646
1948.07	4.54757
1951.04	4.14912
1954	3.47797
1956.96	3.99193
1959.93	2.9008
1962.89	3.90594
1965.85	3.94051
1968.8	4.10103
1971.76	4.84835
1974.72	5.11386
1977.67	3.6036
1980.63	4.24305
1983.58	4.52476
1986.53	3.32686
1989.48	2.63019
1992.43	1.64382
1995.38	1.44584
1998.32	1.15123
2001.27	1.67511
2004.22	1.09997
2007.16	1.22392
2010.1	0.62693
2013.04	0.441264
2015.98	0.909727
2018.92	1.27492
2021.86	0.962072
2024.8	1.13471
2027.74	2.07864
2030.67	2.69601
2033.61	2.87875
2036.54	4.37708
2039.47	5.12351
2042.4	6.79474
2045.33	6.24642
2048.26	6.72273
2051.19	6.79251
2054.12	7.89584
2057.04	8.12657
2059.97	8.75972
2062.89	9.9622
2065.81	10.6705
2068.73	11.1387
2071.65	11.6054
2074.57	13.116
2077.49	13.5504
2080.41	14.1525
2083.32	14.3723
2086.24	16.2554
2089.15	17.3838
2092.07	17.5731
2094.98	17.4422
2097.89	19.2839
2100.8	20.3758
2103.71	21.5366
2106.61	21.1542
2109.52	22.7061
2112.43	24.2013
2115.33	27.1393
2118.23	30.3024
2121.13	33.8072
2124.04	38.0776
2126.94	41.1151
2129.83	46.8457
2132.73	50.3965
2135.63	54.5406
2138.53	58.182
2141.42	62.5583
2144.31	67.3928
2147.21	71.3966
2150.1	73.9797
2152.99	77.3669
2155.88	81.2317
2158.77	82.8776
2161.65	83.393
2164.54	85.2409
2167.43	86.1368
2170.31	85.8569
2173.19	84.7218
2176.07	82.4883
2178.96	82.0668
2181.84	80.6301
2184.72	78.6934
2187.59	78.2062
2190.47	75.7885
2193.35	73.6003
2196.22	71.5033
2199.09	69.0616
2201.97	65.8342
2204.84	61.9881
2207.71	58.1224
2210.58	55.0242
2213.45	51.6657
2216.31	49.1142
2219.18	45.6158
2222.05	42.4347
2224.91	39.7287
2227.78	36.571
2230.64	34.6079
2233.5	32.1056
2236.36	29.7172
2239.22	27.8769
2242.08	26.1348
2244.93	24.9492
2247.79	23.5168
2250.64	22.1834
2253.5	21.1672
2256.35	20.6254
2259.2	20.3254
2262.05	19.6758
2264.9	20.0653
2267.75	18.9527
2270.6	18.4161
2273.45	17.6616
2276.29	17.5685
2279.14	17.322
2281.98	16.6413
2284.82	15.8766
2287.66	15.2986
2290.5	14.1295
2293.34	10.9995
2296.18	10.2516
2299.02	10.4937
2301.86	10.91
2304.69	10.7623
2307.53	10.8253
2310.36	11.0791
2313.19	9.8315
2316.02	9.46313
2318.85	9.33232
2321.68	8.8078
2324.51	8.0719
2327.34	7.22817
2330.16	7.44365
2332.99	7.03161
2335.81	6.0309
2338.64	6.03046
2341.46	5.0281
2344.28	3.52462
2347.1	2.58249
2349.92	1.66295
2352.74	0.298122
2355.55	-0.0412504
2358.37	-0.802227
2361.19	-1.99234
2364	-1.34778
2366.81	-0.0326227
2369.62	0.143949
2372.44	-0.103779
2375.24	-0.149531
2378.05	0.183671
2380.86	0.671715
2383.67	1.2874
2386.47	2.17878
2389.28	2.98418
2392.08	3.0513
2394.89	3.90543
2397.69	4.24474
2400.49	4.31002
2403.29	4.74997
2406.09	5.41675
2408.88	5.56291
2411.68	5.96028
2414.48	6.50234
2417.27	6.50943
2420.06	6.93099
2422.86	8.06348
2425.65	9.19996
2428.44	8.46453
2431.23	8.36647
2434.02	8.2711
2436.81	7.56349
2439.59	6.55642
2442.38	6.46171
2445.16	5.31086
2447.95	4.79367
2450.73	4.3088
2453.51	4.82126
2456.29	4.60405
2459.07	4.42592
2461.85	3.46313
2464.63	3.34548
2467.4	4.07363
2470.18	4.10765
2472.95	4.65909
2475.73	4.90027
2478.5	5.52341
2481.27	5.89417
2484.04	5.83484
2486.81	5.83798
2489.58	6.04564
2492.35	6.04893
2495.12	5.23819
2497.88	3.35039
2500.65	2.65099
2503.41	2.11509
2506.17	1.17991
2508.94	0.253763
2511.7	0.770765
2514.46	0.838808
2517.22	1.33061
2519.97	2.00717
2522.73	2.96685
2525.49	3.08288
2528.24	3.57887
2530.99	4.62244
2533.75	5.38647
2536.5	6.11885
2539.25	6.61422
2542	7.24682
2544.75	7.54054
2547.5	8.19639
2550.24	8.64016
2552.99	8.93836
2555.74	8.32681
2558.48	7.84713
2561.22	7.57531
2563.96	6.57683
2566.71	5.73999
2569.45	5.9593
2572.18	6.61285
2574.92	7.13671
2577.66	8.29869
2580.4	8.80619
2583.13	8.74794
2585.87	8.62881
2588.6	8.80416
2591.33	8.53172
2594.06	8.0853
2596.79	8.28318
2599.52	7.86622
2602.25	7.15638
2604.98	7.04209
2607.71	7.01112
2610.43	6.42897
2613.16	6.28387
2615.88	7.10257
2618.6	7.29333
2621.32	6.81671
2624.04	6.63347
2626.76	6.55277
2629.48	6.41658
2632.2	6.70487
2634.92	6.9252
2637.63	8.31573
2640.35	8.86212
2643.06	10.2497
2645.77	10.2681
2648.49	10.5329
2651.2	9.82257
2653.91	8.64486
2656.62	8.29211
2659.33	8.37723
2662.03	7.65508
2664.74	8.0815
2667.44	7.40522
2670.15	7.9002
2672.85	7.41344
2675.55	7.83467
2678.26	6.17936
2680.96	7.10349
2683.66	6.50544
2686.35	6.56719
2689.05	7.34815
2691.75	6.77241
2694.44	5.56898
2697.14	5.7111
2699.83	6.19229
2702.52	6.78289
2705.22	7.19091
2707.91	6.86692
2710.6	6.54283
2713.29	7.12661
2715.97	5.96937
2718.66	6.06369
2721.35	6.66308
2724.03	7.4522
2726.72	8.70231
2729.4	8.65794
2732.08	9.60719
2734.76	9.15009
2737.44	8.99718
2740.12	8.75341
2742.8	8.15061
2745.48	8.63765
2748.16	8.81395
2750.83	7.65665
2753.51	6.85271
2756.18	6.2676
2758.85	4.48789
2761.53	4.02976
2764.2	3.12091
2766.87	3.40288
2769.54	2.53452
2772.2	1.03434
2774.87	0.589028
2777.54	0.613998
2780.2	-0.338558
2782.87	-0.81229
2785.53	0.200758
2788.19	-0.244544
2790.85	0.0798603
2793.51	-0.422819
2796.17	-0.606651
2798.83	-0.940956
2801.49	-0.516763
2804.15	-0.462659
2806.8	0.621432
2809.46	0.902671
2812.11	0.295283
2814.76	0.622766
2817.42	1.12508
2820.07	1.96737
2822.72	4.24927
2825.37	6.82568
2828.02	10.0554
2830.66	13.8043
2833.31	17.1399
2835.96	20.6512
2838.6	23.8886
2841.24	28.0497
2843.89	32.4742
2846.53	38.6387
2849.17	44.7533
2851.81	51.9003
2854.45	57.9912
2857.09	64.148
2859.72	71.1367
2862.36	77.3999
2865	82.0512
2867.63	87.3183
2870.26	92.2457
2872.9	95.6552
2875.53	99.1253
2878.16	102.414
2880.79	105.727
2883.42	108.737
2886.05	113.145
2888.67	116.585
2891.3	119.843
2893.92	123.119
2896.55	126.898
2899.17	131.192
2901.79	137.058
2904.42	143.209
2907.04	151.225
2909.66	160.318
2912.27	170.54
2914.89	179.809
2917.51	190.102
2920.13	197.789
2922.74	204.205
2925.35	209.858
2927.97	213.274
2930.58	215.257
2933.19	216.293
2935.8	214.801
2938.41	212.455
2941.02	208.808
2943.63	202.943
2946.24	196.1
2948.84	189.318
2951.45	181.274
2954.05	172.184
2956.65	163.241
2959.26	154.205
2961.86	145.569
2964.46	136.378
2967.06	128.36
2969.66	120.932
2972.25	114.379
2974.85	106.81
2977.45	100.621
2980.04	93.1473
2982.64	85.4053
2985.23	78.0008
2987.82	70.4206
2990.41	62.9452
2993	55.4625
2995.59	48.8995
2998.18	42.2218
3000.77	35.8181
3003.36	30.2071
3005.94	24.5649
3008.53	19.7709
3011.11	16.8056
3013.69	13.7036
3016.28	10.7008
3018.86	7.67675
3021.44	5.72822
3024.02	3.65089
3026.6	2.60683
3029.18	2.29701
3031.75	2.40582
3034.33	3.52269
3036.9	4.79723
3039.48	5.15029
3042.05	6.55713
3044.62	7.22853
3047.19	8.99784
3049.77	10.0857
3052.34	11.1413
3054.9	11.4128
3057.47	12.4433
3060.04	13.0883
3062.61	13.1508
3065.17	12.8892
3067.74	12.9937
3070.3	11.503
3072.86	10.4341
3075.42	9.31645
3077.99	6.8752
3080.54	5.73282
3083.1	4.4445
3085.66	3.73018
3088.22	3.18217
3090.78	3.03726
3093.33	3.40786
3095.89	3.55776
3098.44	5.10143
3100.99	5.23563
3103.54	6.39712
3106.1	8.09103
3108.65	10.2136
3111.2	11.8243
3113.74	14.2889
3116.29	15.4488
3118.84	17.0938
3121.38	18.9836
3123.93	21.2532
3126.47	23.4611
3129.01	24.254
3131.56	26.3104
3134.1	26.6428
3136.64	28.6593
3139.18	30.1778
3141.72	31.9968
3144.26	34.1488
3146.79	36.3771
3149.33	39.6178