File: data/Raman/poly_smoothed/Thy_40_11_02_1x_45s_532 nm_x100_100%_600 gr_mm_01.txt
#Acq. time (s)=	45
#Accumulations=	2
#Range (cm-¹)=	200...3150
#Windows=	2
#Auto scanning=	Off
#Autofocus=	Off
#Macrospot=	Off
#AutoExposure=	Off
#Spike filter=	Multiple accum.
#Delay time (s)=	0
#Binning=	1
#Readout mode=	Signal
#DeNoise=	Off
#ICS correction=	On
#Dark correction=	Off
#Inst. Process=	Off
#Detector Gain=	Best Dynamic Range
#Detector ADC=	20 kHz
#Detector temperature (°C)=	-69.85
#Instrument=	LabRAM HR Evol
#Detector=	Synapse
#Objective=	x100
#Grating=	600 gr/mm
#ND Filter=	100%
#Laser (nm)=	532
#Hole=	100.021
#Range=	Auto
#Laser Pol.=	No
#Raman. Pol.=	No
#Laser Pol. (°)=	-0.0007625
#Raman Pol. (°)=	89.9995
#Collection=	Microscope
#StageXY=	Marzhauser
#StageZ=	Marzhauser
#X (µm)=	1967.3
#Y (µm)=	-92.6
#Z (µm)=	425.3
#Full time(mm:ss)=	3:18
#Project=
#Sample=
#Site=
#Title=	Thy_40_11_02_2x_45s_532 nm_x100_100%_600 gr_mm
#Remark=
#Date=	05.07.2022 09:56
#Acquired=	05.07.2022 09:56:09
#Base:Fit=	10.08.2022 10:00:48
#Base:Fit=	10.08.2022 10:01:07
#Base:Fit=	10.08.2022 10:01:15
#Base:Fit=	10.08.2022 10:01:35
#Base:Sub=	10.08.2022 10:01:52
#Filter:Polynom=	16.08.2022 10:21:53
#AxisType[0]=Intens
#AxisUnit[0]=Cnt
#AxisType[1]=Spectr
#AxisUnit[1]=1/cm
200.43	17.5741
204.059	17.8569
207.688	17.561
211.314	17.0483
214.941	15.3709
218.564	12.5935
222.186	11.5335
225.809	10.5635
229.428	8.40133
233.045	7.25506
236.663	6.53697
240.278	6.86412
243.891	5.89438
247.503	4.07546
251.116	1.1714
254.725	2.10105
258.333	1.04677
261.939	1.86527
265.544	3.45548
269.148	4.4966
272.75	4.16946
276.351	4.32513
279.95	4.04841
283.548	5.3919
287.144	7.42031
290.739	9.63348
294.333	9.93758
297.925	10.0709
301.514	10.2161
305.104	10.2199
308.692	12.4393
312.279	12.3785
315.862	11.0137
319.446	11.7821
323.029	11.0308
326.608	10.0038
330.188	9.80618
333.766	9.79086
337.341	8.84251
340.917	7.9546
344.489	6.02869
348.062	4.39235
351.631	6.15863
355.201	6.26019
358.768	5.77885
362.333	4.87974
365.899	5.09839
369.462	5.92204
373.023	9.06516
376.585	8.51992
380.143	8.56345
383.7	8.5443
387.256	8.35501
390.812	9.11121
394.365	9.2321
397.916	9.28963
401.467	8.98215
405.015	10.5188
408.563	11.0428
412.109	11.9363
415.654	12.3996
419.197	14.0244
422.739	14.1719
426.279	14.5455
429.819	15.6953
433.356	16.1799
436.891	17.0256
440.426	17.7271
443.96	15.8287
447.492	16.1631
451.021	18.0199
454.551	19.683
458.079	21.1964
461.604	22.473
465.13	21.4688
468.654	22.6637
472.175	22.737
475.696	23.3868
479.215	24.6898
482.733	27.1977
486.249	27.5912
489.765	28.4961
493.278	29.8818
496.789	29.9311
500.301	31.3539
503.81	32.0003
507.317	31.5955
510.825	31.0701
514.33	30.7211
517.833	29.051
521.335	28.519
524.836	28.3133
528.335	26.9258
531.835	26.3466
535.332	27.4449
538.827	27.0547
542.321	26.7928
545.814	26.1945
549.305	24.8519
552.795	25.0183
556.282	25.2163
559.769	25.2418
563.255	23.3459
566.739	21.9641
570.223	19.0036
573.705	16.3404
577.183	17.4467
580.663	16.4363
584.141	16.8212
587.615	15.539
591.09	12.1638
594.564	11.1079
598.035	10.3155
601.506	10.0543
604.974	11.2408
608.443	12.9602
611.908	12.0276
615.374	12.6658
618.837	14.8436
622.3	16.473
625.761	18.6288
629.219	20.3602
632.677	23.7333
636.135	25.2492
639.59	26.9691
643.043	27.9664
646.495	28.3184
649.948	28.2476
653.398	29.7299
656.846	29.4099
660.293	31.5909
663.738	32.9822
667.183	32.8449
670.626	32.7857
674.067	33.0471
677.508	33.5351
680.947	33.9372
684.385	35.9584
687.821	37.912
691.254	40.7909
694.688	41.619
698.121	44.2608
701.552	47.1034
704.98	50.3031
708.409	52.4725
711.836	54.2585
715.26	56.6416
718.685	60.0282
722.108	60.7452
725.528	63.3268
728.949	64.9387
732.367	63.9943
735.785	64.5656
739.2	65.919
742.614	68.838
746.028	70.9425
749.439	71.6398
752.849	73.4218
756.26	75.6921
759.667	78.8478
763.073	79.0497
766.477	81.2957
769.883	82.1006
773.285	84.5628
776.686	87.733
780.085	89.3028
783.484	90.0422
786.881	90.7326
790.276	90.7622
793.671	91.685
797.064	92.4604
800.456	91.7554
803.846	92.0816
807.234	90.9237
810.622	90.585
814.008	90.3575
817.394	91.2109
820.778	93.1667
824.159	94.1426
827.541	93.228
830.921	92.1125
834.298	89.3085
837.676	87.4926
841.051	85.0494
844.426	80.7633
847.798	80.3469
851.171	78.2702
854.54	76.0003
857.911	73.7007
861.278	71.1574
864.645	66.0449
868.01	62.8152
871.373	60.3894
874.735	58.3567
878.097	55.3489
881.457	54.5692
884.815	54.1214
888.172	54.1895
891.528	52.9115
894.882	53.9946
898.237	54.9294
901.589	55.8777
904.94	54.8696
908.289	54.8597
911.635	54.0158
914.982	53.5396
918.328	53.0337
921.672	52.9832
925.015	51.1581
928.357	49.0908
931.698	47.9198
935.035	45.1663
938.373	41.2913
941.71	36.3166
945.044	32.9517
948.378	31.1211
951.709	31.6098
955.041	32.1812
958.372	31.9518
961.699	33.2496
965.027	34.2213
968.352	34.5051
971.676	34.939
975	36.8955
978.322	39.1786
981.642	41.3834
984.962	43.9757
988.28	44.9777
991.596	47.1202
994.911	47.866
998.227	48.8658
1001.54	48.1917
1004.85	46.3631
1008.16	44.5395
1011.47	43.737
1014.78	41.2021
1018.08	37.9044
1021.39	35.7496
1024.69	33.2796
1028	33.2109
1031.3	34.2281
1034.6	35.3066
1037.9	33.2844
1041.19	33.4048
1044.49	33.2712
1047.78	32.062
1051.08	30.3723
1054.37	30.9431
1057.66	30.4319
1060.95	27.8775
1064.24	27.6345
1067.53	27.2132
1070.81	27.6904
1074.1	28.8877
1077.38	26.5784
1080.66	27.8498
1083.94	25.4232
1087.22	23.936
1090.5	23.0815
1093.78	21.5917
1097.05	20.8336
1100.33	19.0139
1103.6	19.0254
1106.87	18.9123
1110.14	19.1972
1113.41	18.1926
1116.68	17.1279
1119.95	15.3026
1123.21	12.7119
1126.48	10.3717
1129.74	10.2538
1133	9.74887
1136.26	8.9949
1139.52	8.28558
1142.78	7.6516
1146.04	8.8632
1149.29	9.74524
1152.55	8.99479
1155.8	8.86321
1159.05	7.48042
1162.3	6.35594
1165.55	5.79143
1168.8	6.08873
1172.05	5.60326
1175.29	5.22153
1178.54	5.12053
1181.78	6.80082
1185.02	5.98586
1188.26	5.99929
1191.5	5.68066
1194.74	5.62679
1197.97	5.82202
1201.21	7.28998
1204.44	10.5219
1207.68	14.0096
1210.91	18.7365
1214.14	21.2392
1217.37	26.5524
1220.59	31.3941
1223.82	35.9865
1227.05	41.4108
1230.27	46.0647
1233.49	49.862
1236.72	54.5864
1239.94	59.7076
1243.16	63.825
1246.37	68.7344
1249.59	73.0418
1252.8	76.2865
1256.02	80.0082
1259.23	83.1477
1262.44	87.3916
1265.66	88.6418
1268.86	92.9871
1272.07	94.8299
1275.28	96.7003
1278.48	101.206
1281.69	102.259
1284.89	103.543
1288.09	105.269
1291.29	106.842
1294.49	107.939
1297.69	109.535
1300.89	109.403
1304.08	109.629
1307.28	111.807
1310.47	112.769
1313.66	113.34
1316.85	114.045
1320.04	113.846
1323.23	112.832
1326.42	111.278
1329.61	109.612
1332.79	107.325
1335.97	105.462
1339.16	103.038
1342.34	100.118
1345.52	95.6771
1348.7	93.7988
1351.87	87.3821
1355.05	84.0114
1358.22	82.2266
1361.4	77.7439
1364.57	74.2465
1367.74	72.4455
1370.91	70.915
1374.08	68.1236
1377.25	65.6957
1380.41	62.757
1383.58	61.7696
1386.74	62.8186
1389.91	62.1272
1393.07	61.9195
1396.23	61.7356
1399.39	60.5317
1402.55	59.7208
1405.7	60.7085
1408.86	59.3143
1412.01	61.1543
1415.17	61.8152
1418.32	64.5635
1421.47	66.8627
1424.62	72.4362
1427.77	77.4284
1430.91	83.9404
1434.06	91.2674
1437.2	97.7827
1440.35	101.189
1443.49	104.85
1446.63	107.185
1449.77	108.815
1452.91	107.591
1456.05	107.816
1459.18	105.206
1462.32	103.489
1465.45	98.1629
1468.59	92.3536
1471.72	85.4468
1474.85	77.0289
1477.98	69.9604
1481.1	62.2387
1484.23	53.3335
1487.36	46.4314
1490.48	40.6675
1493.61	37.1808
1496.73	33.3881
1499.85	31.7564
1502.97	31.5879
1506.09	30.9918
1509.2	30.4856
1512.32	32.0956
1515.43	33.5086
1518.55	35.1463
1521.66	39.2614
1524.77	42.7442
1527.88	44.8693
1530.99	47.8295
1534.1	52.8461
1537.21	57.2967
1540.31	61.1087
1543.42	65.6264
1546.52	72.8306
1549.62	78.1908
1552.72	85.0049
1555.82	91.5557
1558.92	98.0401
1562.02	101.737
1565.11	107.005
1568.21	112.45
1571.3	116.817
1574.39	120.44
1577.49	124.042
1580.57	126.075
1583.66	127.879
1586.75	129.397
1589.84	129.495
1592.92	129.957
1596.01	130.101
1599.09	127.026
1602.17	124.132
1605.25	121.644
1608.33	118.394
1611.41	116.425
1614.49	114.41
1617.57	114.171
1620.64	114.553
1623.72	115.96
1626.79	118.637
1629.86	121.288
1632.93	123.717
1636	125.743
1639.07	129.144
1642.13	134.565
1645.2	137.48
1648.26	140.588
1651.33	144.442
1654.39	146.203
1657.45	146.378
1660.51	145.897
1663.57	142.942
1666.63	139.101
1669.68	134.969
1672.74	128.374
1675.79	120.649
1678.85	113.428
1681.9	105.7
1684.95	96.8355
1688	88.9913
1691.05	81.072
1694.09	73.1279
1697.14	66.6329
1700.18	59.7381
1703.23	52.7448
1706.27	46.771
1709.31	43.3947
1712.35	41.3701
1715.39	38.3902
1718.43	36.3386
1721.47	33.4885
1724.5	32.4966
1727.54	30.8355
1730.57	29.0692
1733.61	27.8344
1736.64	25.6998
1739.67	24.5837
1742.7	24.2952
1745.72	21.9484
1748.75	21.7251
1751.77	20.5683
1754.8	20.3808
1757.82	19.6632
1760.84	18.6082
1763.87	18.4647
1766.89	17.7787
1769.91	16.9104
1772.92	16.4686
1775.94	15.2645
1778.95	14.9089
1781.97	14.9228
1784.98	14.9081
1787.99	15.221
1791.01	13.3583
1794.01	12.7953
1797.02	11.1959
1800.03	10.331
1803.04	9.74846
1806.04	9.76554
1809.05	9.53964
1812.05	9.05052
1815.05	8.0257
1818.05	8.47682
1821.05	7.79546
1824.05	6.85945
1827.05	5.53026
1830.04	4.99771
1833.04	4.3332
1836.03	4.9386
1839.03	5.87421
1842.02	6.20833
1845.01	5.9554
1848	5.40564
1850.99	5.57127
1853.97	5.53188
1856.96	5.42632
1859.94	4.98784
1862.93	3.85617
1865.91	3.48716
1868.89	2.47421
1871.87	2.13734
1874.85	3.08477
1877.83	2.78365
1880.81	2.89356
1882.57	3.95592
1885.56	3.34947
1888.55	2.24497
1891.54	1.84508
1894.52	1.4151
1897.51	0.951366
1900.49	0.526395
1903.47	0.934873
1906.45	2.90117
1909.43	4.66533
1912.41	6.23564
1915.39	5.71068
1918.37	5.38884
1921.34	5.67517
1924.32	5.71586
1927.29	5.76086
1930.26	5.45041
1933.23	5.04538
1936.2	4.87959
1939.17	4.79194
1942.14	5.29906
1945.11	4.7846
1948.07	6.11848
1951.04	6.50557
1954	6.01145
1956.96	6.03349
1959.93	5.76603
1962.89	7.7199
1965.85	9.14468
1968.8	9.61138
1971.76	8.96954
1974.72	10.5676
1977.67	11.1724
1980.63	11.2408
1983.58	10.9895
1986.53	10.0925
1989.48	8.38161
1992.43	7.26083
1995.38	6.49637
1998.32	5.4028
2001.27	5.64698
2004.22	5.97519
2007.16	6.01657
2010.1	6.76088
2013.04	6.29329
2015.98	6.12944
2018.92	6.91651
2021.86	7.56575
2024.8	8.33791
2027.74	9.10345
2030.67	11.2322
2033.61	12.448
2036.54	15.107
2039.47	15.2539
2042.4	15.1371
2045.33	16.1628
2048.26	16.8078
2051.19	17.6271
2054.12	17.911
2057.04	18.3718
2059.97	17.8873
2062.89	17.7183
2065.81	19.1495
2068.73	20.5214
2071.65	22.2667
2074.57	23.7893
2077.49	25.8913
2080.41	26.8855
2083.32	27.7153
2086.24	29.1361
2089.15	31.3105
2092.07	34.1574
2094.98	36.4781
2097.89	39.7717
2100.8	42.3949
2103.71	46.1501
2106.61	48.7735
2109.52	51.3583
2112.43	54.7537
2115.33	59.3385
2118.23	65.0204
2121.13	70.6073
2124.04	75.81
2126.94	80.3417
2129.83	85.5032
2132.73	92.0945
2135.63	98.2848
2138.53	104.967
2141.42	110.902
2144.31	116.358
2147.21	122.12
2150.1	126.962
2152.99	131.335
2155.88	135.613
2158.77	140.729
2161.65	144.147
2164.54	146.72
2167.43	147.741
2170.31	147.657
2173.19	147.153
2176.07	145.405
2178.96	142.878
2181.84	140.914
2184.72	139.414
2187.59	136.525
2190.47	132.392
2193.35	127.818
2196.22	121.802
2199.09	115.826
2201.97	111.1
2204.84	105.3
2207.71	99.0251
2210.58	93.1458
2213.45	87.1638
2216.31	81.452
2219.18	78.4057
2222.05	73.9037
2224.91	69.1638
2227.78	65.3157
2230.64	61.9351
2233.5	57.8185
2236.36	52.706
2239.22	48.8793
2242.08	46.0678
2244.93	43.536
2247.79	40.5341
2250.64	38.2127
2253.5	36.2638
2256.35	34.7354
2259.2	33.0035
2262.05	31.393
2264.9	29.1217
2267.75	27.3926
2270.6	25.5797
2273.45	24.4908
2276.29	23.306
2279.14	22.574
2281.98	22.4842
2284.82	22.5508
2287.66	21.9352
2290.5	22.333
2293.34	19.7886
2296.18	18.2739
2299.02	18.5114
2301.86	17.7463
2304.69	16.3941
2307.53	15.4042
2310.36	15.6227
2313.19	14.8029
2316.02	13.3942
2318.85	13.0107
2321.68	12.6108
2324.51	11.949
2327.34	11.144
2330.16	10.7401
2332.99	9.69775
2335.81	9.84652
2338.64	8.84371
2341.46	7.86935
2344.28	7.09381
2347.1	7.30424
2349.92	5.7749
2352.74	4.72006
2355.55	3.29572
2358.37	2.57404
2361.19	1.68075
2364	2.18487
2366.81	3.73757
2369.62	4.14134
2372.44	4.5349
2375.24	5.35365
2378.05	4.6679
2380.86	4.8441
2383.67	4.16504
2386.47	4.58416
2389.28	4.73052
2392.08	4.23598
2394.89	4.30769
2397.69	5.54673
2400.49	6.54411
2403.29	7.21928
2406.09	7.79047
2408.88	7.62255
2411.68	7.91672
2414.48	8.62834
2417.27	8.96927
2420.06	7.91203
2422.86	7.3449
2425.65	8.18536
2428.44	9.15997
2431.23	8.93897
2434.02	9.72762
2436.81	10.3409
2439.59	10.1944
2442.38	10.7247
2445.16	8.92502
2447.95	7.97858
2450.73	7.06411
2453.51	6.87718
2456.29	7.21071
2459.07	6.92825
2461.85	6.75166
2464.63	6.62647
2467.4	6.18399
2470.18	6.13827
2472.95	5.04571
2475.73	4.85765
2478.5	4.42617
2481.27	3.72038
2484.04	2.85427
2486.81	1.61552
2489.58	0.524471
2492.35	0.414276
2495.12	0.355604
2497.88	-0.248316
2500.65	-0.725619
2503.41	-0.0847693
2506.17	0.309682
2508.94	-0.939717
2511.7	-0.842561
2514.46	-0.47147
2517.22	-0.434511
2519.97	0.232851
2522.73	1.45815
2525.49	1.49049
2528.24	0.857302
2530.99	0.995681
2533.75	1.11603
2536.5	1.52758
2539.25	2.98468
2542	3.91697
2544.75	3.98242
2547.5	5.0279
2550.24	5.22209
2552.99	5.66309
2555.74	6.2993
2558.48	7.34761
2561.22	7.86402
2563.96	7.49456
2566.71	7.13252
2569.45	6.95357
2572.18	6.56731
2574.92	5.91472
2577.66	5.60015
2580.4	5.7191
2583.13	5.15718
2585.87	4.22819
2588.6	3.46436
2591.33	2.7818
2594.06	2.54157
2596.79	1.5529
2599.52	0.792427
2602.25	0.894322
2604.98	0.704755
2607.71	0.853974
2610.43	0.435465
2613.16	0.698504
2615.88	1.20474
2618.6	1.43431
2621.32	2.14462
2624.04	2.01452
2626.76	1.44846
2629.48	1.32235
2632.2	1.43647
2634.92	1.63539
2637.63	1.55683
2640.35	1.80951
2643.06	1.98726
2645.77	2.17382
2648.49	1.80093
2651.2	3.14673
2653.91	2.69246
2656.62	3.43364
2659.33	4.21526
2662.03	4.52661
2664.74	4.64844
2667.44	5.33939
2670.15	5.50567
2672.85	6.78992
2675.55	7.75624
2678.26	7.81257
2680.96	6.91022
2683.66	6.71965
2686.35	5.6371
2689.05	5.34687
2691.75	4.61477
2694.44	4.80053
2697.14	5.35885
2699.83	4.44539
2702.52	4.91725
2705.22	6.21169
2707.91	6.08419
2710.6	6.67804
2713.29	8.30007
2715.97	9.72373
2718.66	10.6082
2721.35	11.3759
2724.03	13.0133
2726.72	13.4305
2729.4	13.5554
2732.08	13.4157
2734.76	13.536
2737.44	13.2826
2740.12	12.6504
2742.8	12.034
2745.48	10.0528
2748.16	8.56142
2750.83	6.86851
2753.51	5.98923
2756.18	5.17219
2758.85	4.55285
2761.53	2.45175
2764.2	2.25084
2766.87	0.95192
2769.54	1.76082
2772.2	1.07792
2774.87	0.822802
2777.54	0.236693
2780.2	0.699317
2782.87	0.311918
2785.53	-0.48673
2788.19	-0.107465
2790.85	0.346938
2793.51	-0.466876
2796.17	0.301116
2798.83	0.223788
2801.49	0.306934
2804.15	0.417776
2806.8	0.853623
2809.46	0.342425
2812.11	0.134846
2814.76	-0.616452
2817.42	0.374044
2820.07	2.72291
2822.72	7.23449
2825.37	11.5921
2828.02	16.1114
2830.66	23.3811
2833.31	29.9568
2835.96	37.1012
2838.6	45.0526
2841.24	53.4863
2843.89	62.7491
2846.53	74.171
2849.17	86.8533
2851.81	99.1958
2854.45	113.044
2857.09	124.591
2859.72	136.367
2862.36	147.197
2865	157.459
2867.63	166.592
2870.26	174.228
2872.9	181.279
2875.53	187.164
2878.16	192.737
2880.79	198.748
2883.42	203.598
2886.05	210.107
2888.67	215.724
2891.3	220.319
2893.92	226.459
2896.55	232.942
2899.17	241.918
2901.79	251.287
2904.42	262.76
2907.04	276.383
2909.66	292.193
2912.27	309.976
2914.89	326.692
2917.51	343.697
2920.13	357.764
2922.74	369.441
2925.35	378.625
2927.97	385.025
2930.58	388.826
2933.19	389.984
2935.8	389.099
2938.41	384.768
2941.02	377.439
2943.63	367.474
2946.24	355.928
2948.84	342.284
2951.45	328.035
2954.05	313.487
2956.65	297.173
2959.26	281.615
2961.86	267.409
2964.46	251.994
2967.06	237.696
2969.66	224.882
2972.25	211.98
2974.85	199.703
2977.45	186.742
2980.04	173.985
2982.64	159.841
2985.23	145.5
2987.82	130.358
2990.41	116.787
2993	104.12
2995.59	92.8615
2998.18	81.9676
3000.77	71.4153
3003.36	61.6716
3005.94	52.9064
3008.53	45.1184
3011.11	38.5034
3013.69	33.1361
3016.28	29.6952
3018.86	26.3622
3021.44	23.2811
3024.02	20.6146
3026.6	19.2146
3029.18	17.7913
3031.75	17.5402
3034.33	17.5975
3036.9	17.5678
3039.48	18.4752
3042.05	20.2213
3044.62	20.5324
3047.19	21.8386
3049.77	23.7501
3052.34	24.8374
3054.9	25.3612
3057.47	24.7369
3060.04	25.1239
3062.61	24.1028
3065.17	23.5036
3067.74	22.7115
3070.3	20.632
3072.86	18.454
3075.42	15.9079
3077.99	13.2143
3080.54	11.8106
3083.1	9.3729
3085.66	7.25261
3088.22	6.43685
3090.78	5.24169
3093.33	4.61728
3095.89	4.33266
3098.44	3.98476
3100.99	4.37669
3103.54	5.38004
3106.1	6.12942
3108.65	7.08985
3111.2	8.64014
3113.74	9.88868
3116.29	10.7071
3118.84	11.9174
3121.38	13.7507
3123.93	16.0707
3126.47	18.2089
3129.01	21.1952
3131.56	22.0255
3134.1	23.6187
3136.64	26.3965
3139.18	28.9476
3141.72	32.9878
3144.26	36.3785
3146.79	40.1428
3149.33	44.5207