File: data/Raman/poly_smoothed/Thy_20_09_42_1x_45s_532 nm_x100_100%_600 gr_mm_01.txt
#Acq. time (s)=	45
#Accumulations=	2
#Range (cm-¹)=	200...3150
#Windows=	2
#Auto scanning=	Off
#Autofocus=	Off
#Macrospot=	Off
#AutoExposure=	Off
#Spike filter=	Multiple accum.
#Delay time (s)=	0
#Binning=	1
#Readout mode=	Signal
#DeNoise=	Off
#ICS correction=	On
#Dark correction=	Off
#Inst. Process=	Off
#Detector Gain=	Best Dynamic Range
#Detector ADC=	20 kHz
#Detector temperature (°C)=	-69.85
#Instrument=	LabRAM HR Evol
#Detector=	Synapse
#Objective=	x100
#Grating=	600 gr/mm
#ND Filter=	100%
#Laser (nm)=	532
#Hole=	100.021
#Range=	Auto
#Laser Pol.=	No
#Raman. Pol.=	No
#Laser Pol. (°)=	-0.0007625
#Raman Pol. (°)=	89.9995
#Collection=	Microscope
#StageXY=	Marzhauser
#StageZ=	Marzhauser
#X (µm)=	-5919
#Y (µm)=	2858.6
#Z (µm)=	-224.15
#Full time(mm:ss)=	3:18
#Project=
#Sample=
#Site=
#Title=	Thy_20_09_42_2x_45s_532 nm_x100_100%_600 gr_mm
#Remark=
#Date=	29.06.2022 13:37
#Acquired=	29.06.2022 13:37:33
#Base:Fit=	10.08.2022 09:52:02
#Base:Fit=	10.08.2022 09:52:12
#Base:Sub=	10.08.2022 09:54:21
#Filter:Polynom=	16.08.2022 10:24:04
#AxisType[0]=Intens
#AxisUnit[0]=Cnt
#AxisType[1]=Spectr
#AxisUnit[1]=1/cm
200.523	-3.18708
204.154	-0.287022
207.781	2.09695
211.409	4.17653
215.034	5.23766
218.659	7.51398
222.281	7.96181
225.903	9.95914
229.522	12.6041
233.14	14.2022
236.756	15.3006
240.373	13.9128
243.986	14.0247
247.598	14.0226
251.208	13.0736
254.818	13.3469
258.427	12.4392
262.034	12.2133
265.638	11.5082
269.242	11.3015
272.844	10.5006
276.445	8.53999
280.044	8.62052
283.642	9.46908
287.238	9.44887
290.833	7.85955
294.425	7.96623
298.017	8.50699
301.608	10.2505
305.198	12.0717
308.786	13.7163
312.371	14.9282
315.956	17.8222
319.54	19.9724
323.122	19.7371
326.701	19.9623
330.281	19.7298
333.857	21.2804
337.434	22.3633
341.008	21.8813
344.582	22.3831
348.153	21.9668
351.724	22.4178
355.292	22.8958
358.861	20.7549
362.426	21.0244
365.99	19.7279
369.555	18.442
373.116	17.5475
376.676	16.9222
380.236	16.2172
383.793	16.9584
387.349	16.7924
390.903	17.3732
394.456	14.8992
398.007	14.6576
401.56	13.3321
405.108	12.7983
408.656	12.6604
412.202	12.4743
415.746	11.4995
419.29	11.3619
422.831	11.0412
426.37	10.8481
429.909	11.4093
433.447	12.1191
436.983	12.3976
440.519	12.8149
444.052	12.9366
447.583	15.0152
451.114	16.5303
454.643	18.1133
458.169	19.5506
461.696	22.5626
465.222	23.8098
468.744	24.6401
472.267	24.7154
475.787	25.3876
479.307	25.9544
482.823	25.808
486.341	27.2823
489.855	29.3711
493.37	30.633
496.881	30.8857
500.391	29.118
503.902	28.4647
507.409	27.6828
510.915	27.055
514.42	27.1413
517.925	25.9774
521.427	23.9113
524.928	23.7637
528.427	22.6298
531.925	21.4
535.422	20.2464
538.917	20.4085
542.411	18.2999
545.903	18.2523
549.395	16.2102
552.884	15.1165
556.373	12.4859
559.86	11.9736
563.346	12.5345
566.831	11.1759
570.314	9.78102
573.794	8.70775
577.274	8.71867
580.754	7.97362
584.23	8.13663
587.706	8.03156
591.181	6.07728
594.653	4.80519
598.126	4.32473
601.595	5.26624
605.065	6.08192
608.532	5.11204
611.999	6.08718
615.463	6.77764
618.928	7.61897
622.389	8.98148
625.851	8.83442
629.31	10.4353
632.767	10.7089
636.223	10.4819
639.68	11.5311
643.134	11.2568
646.586	10.6664
650.037	10.8238
653.486	10.4126
656.936	11.3039
660.383	13.8547
663.829	14.3883
667.273	15.0471
670.716	14.9558
674.158	14.9292
677.598	16.0803
681.035	18.4526
684.473	20.2014
687.909	22.542
691.344	24.9374
694.778	25.6588
698.211	29.0137
701.64	29.6199
705.07	30.2927
708.498	31.5667
711.924	32.18
715.35	32.0271
718.774	32.3365
722.196	32.76
725.618	33.4369
729.037	34.5005
732.456	36.3166
735.873	37.7803
739.289	38.9976
742.703	38.7981
746.116	41.1905
749.529	40.6773
752.938	43.5989
756.347	44.6782
759.756	48.592
763.162	49.9463
766.567	51.5607
769.97	53.5765
773.372	55.5879
776.773	57.3963
780.174	58.1027
783.573	57.7496
786.97	59.3349
790.365	60.7065
793.76	60.9833
797.153	62.2485
800.543	65.0495
803.933	67.1728
807.322	68.201
810.71	69.6355
814.097	70.2098
817.483	71.5297
820.865	71.3546
824.248	70.5265
827.629	70.7881
831.008	71.0176
834.387	71.6673
837.765	70.972
841.139	70.6403
844.514	67.6653
847.886	65.8965
851.259	64.5122
854.629	63.7564
857.997	62.6789
861.366	58.8284
864.732	56.015
868.098	54.317
871.461	52.4402
874.823	51.385
878.184	49.9971
881.545	49.626
884.903	48.0537
888.26	45.9067
891.616	42.7292
894.97	41.2265
898.323	39.8821
901.675	37.1544
905.026	36.471
908.375	35.9413
911.723	36.1509
915.07	35.7768
918.415	35.5542
921.76	35.241
925.103	35.6999
928.443	35.0563
931.783	36.1733
935.123	37.826
938.461	35.7475
941.796	33.7789
945.131	32.327
948.465	30.8186
951.797	30.4309
955.128	30.0331
958.457	29.9037
961.786	28.0672
965.113	28.0942
968.44	27.9591
971.763	27.8518
975.086	27.0669
978.409	26.3946
981.729	27.8297
985.048	29.3468
988.367	30.117
991.683	31.1085
994.998	32.6035
998.312	32.8271
1001.62	34.2714
1004.94	34.0959
1008.25	34.334
1011.56	34.8579
1014.86	34.7883
1018.17	33.034
1021.48	31.3391
1024.78	29.9483
1028.08	28.2148
1031.38	25.6376
1034.68	22.8905
1037.98	21.4363
1041.28	19.8634
1044.57	18.8477
1047.87	18.4221
1051.16	16.7347
1054.45	15.0923
1057.75	13.3337
1061.04	13.0155
1064.32	13.7333
1067.61	14.059
1070.9	14.857
1074.18	15.0218
1077.47	15.2853
1080.75	15.2463
1084.03	16.2641
1087.31	16.24
1090.59	17.2085
1093.86	18.9721
1097.14	18.9837
1100.41	19.7931
1103.69	21.0077
1106.96	19.7626
1110.23	19.5531
1113.5	18.6592
1116.77	18.0039
1120.03	16.3775
1123.3	13.6316
1126.56	12.6324
1129.83	11.0701
1133.09	10.3931
1136.35	9.5931
1139.61	9.46771
1142.86	9.05067
1146.12	9.72671
1149.38	7.62597
1152.63	8.79249
1155.88	7.75454
1159.14	7.66057
1162.39	6.23468
1165.63	6.17976
1168.88	7.67202
1172.13	9.39515
1175.38	10.9701
1178.62	12.8848
1181.86	14.8891
1185.1	16.1683
1188.34	17.1603
1191.58	20.6441
1194.82	20.816
1198.06	22.6609
1201.29	25.4256
1204.53	29.4148
1207.76	33.0093
1210.99	35.1802
1214.22	38.5612
1217.45	41.9169
1220.68	44.3468
1223.91	48.7648
1227.13	52.1558
1230.36	55.2246
1233.58	58.1439
1236.8	58.8835
1240.02	60.6758
1243.24	63.6462
1246.46	66.2624
1249.67	68.4423
1252.89	70.2588
1256.1	71.0894
1259.32	71.3421
1262.53	71.3913
1265.74	73.5871
1268.95	74.3643
1272.15	74.581
1275.36	75.7003
1278.57	77.9659
1281.77	79.659
1284.97	80.371
1288.18	82.2212
1291.38	84.2349
1294.58	85.2735
1297.78	88.0877
1300.97	89.9106
1304.17	93.2328
1307.36	94.3942
1310.55	95.4993
1313.75	96.4224
1316.94	97.1299
1320.13	98.9296
1323.32	99.648
1326.5	100.156
1329.69	98.8839
1332.87	97.3161
1336.06	94.7597
1339.24	93.7913
1342.42	92.6338
1345.6	89.9664
1348.78	87.378
1351.96	86.4581
1355.13	83.6829
1358.31	82.6177
1361.48	78.8548
1364.65	76.8693
1367.82	73.9763
1370.99	71.0439
1374.16	68.3582
1377.33	66.066
1380.5	64.1091
1383.66	62.5719
1386.83	61.8168
1389.99	59.6998
1393.15	56.5731
1396.31	55.5328
1399.47	53.1136
1402.63	51.6193
1405.78	49.7964
1408.94	51.5762
1412.1	53.899
1415.25	56.3726
1418.4	58.5737
1421.55	61.6459
1424.7	68.7552
1427.85	74.1989
1431	80.6069
1434.14	85.4504
1437.29	89.4217
1440.43	92.2041
1443.57	94.2627
1446.71	96.0524
1449.85	97.0615
1452.99	96.1738
1456.13	94.015
1459.26	91.8435
1462.4	87.5948
1465.54	82.3884
1468.67	75.0282
1471.8	69.5387
1474.93	62.2494
1478.06	55.9687
1481.19	50.1122
1484.31	44.965
1487.44	40.9451
1490.56	36.67
1493.69	33.9899
1496.81	30.4416
1499.93	30.1466
1503.05	29.7014
1506.17	29.6486
1509.28	29.3351
1512.4	29.7396
1515.52	29.4917
1518.63	29.9393
1521.74	32.3714
1524.85	33.8586
1527.96	35.4457
1531.07	37.8293
1534.18	40.5824
1537.29	44.1199
1540.39	46.5574
1543.5	50.0677
1546.6	53.1026
1549.7	58.2572
1552.8	62.6748
1555.9	67.0462
1559	69.2255
1562.1	72.7036
1565.19	74.7803
1568.29	78.3769
1571.38	80.6748
1574.47	81.6153
1577.56	84.7003
1580.66	86.0229
1583.74	86.9421
1586.83	88.2549
1589.92	88.7805
1593.01	89.7981
1596.09	91.0003
1599.17	89.781
1602.25	89.1471
1605.34	89.6484
1608.41	87.8113
1611.49	86.5277
1614.57	85.9672
1617.65	83.7659
1620.72	82.7165
1623.79	83.1131
1626.87	83.1547
1629.94	82.6926
1633.01	82.1426
1636.08	82.7443
1639.15	85.3642
1642.21	86.9753
1645.28	89.6446
1648.34	89.3552
1651.41	89.989
1654.47	90.6932
1657.53	90.2503
1660.59	91.7909
1663.65	90.5452
1666.71	89.6781
1669.76	88.6795
1672.82	84.5928
1675.87	80.8525
1678.93	76.7134
1681.98	70.0488
1685.03	63.0843
1688.08	55.8792
1691.13	48.3549
1694.17	41.0933
1697.22	35.3461
1700.27	30.3298
1703.31	25.2052
1706.35	19.9537
1709.39	17.6695
1712.43	14.579
1715.47	11.904
1718.51	10.28
1721.55	7.77781
1724.58	5.37489
1727.62	5.27987
1730.65	6.23706
1733.68	6.61308
1736.72	6.7371
1739.74	6.43183
1742.77	7.07107
1745.8	7.45045
1748.83	7.29182
1751.85	6.92793
1754.88	6.31342
1757.9	5.47406
1760.92	4.74062
1763.95	4.86599
1766.96	4.43623
1769.98	4.74312
1773	3.73552
1776.02	2.59242
1779.03	1.66402
1782.05	1.93613
1785.06	1.53104
1788.07	1.74399
1791.08	1.28169
1794.09	1.28759
1797.1	0.793516
1800.11	1.1111
1803.12	1.99031
1806.12	2.22747
1809.12	2.17263
1812.13	1.79935
1815.13	2.57862
1818.13	2.71284
1821.13	3.01034
1824.13	2.31044
1827.13	2.6466
1830.12	2.81298
1833.12	3.56957
1836.11	3.12097
1839.1	3.87066
1842.09	3.28643
1845.09	3.11394
1848.08	3.04537
1851.06	3.41798
1854.05	3.58843
1857.04	3.06427
1860.02	2.56614
1863.01	2.05419
1865.99	2.2957
1868.97	2.57205
1871.95	3.46111
1874.93	2.90877
1877.91	2.90943
1880.89	3.13987
1882.46	3.05351
1885.45	3.4503
1888.43	3.80812
1891.42	4.59843
1894.41	5.31044
1897.39	6.10945
1900.37	7.4603
1903.36	8.05044
1906.34	8.09996
1909.32	7.67793
1912.29	8.31263
1915.27	8.7364
1918.25	8.14471
1921.23	7.41523
1924.2	6.36241
1927.17	5.29486
1930.15	5.09251
1933.12	5.12801
1936.09	5.5796
1939.06	5.08891
1942.02	4.05422
1944.99	4.74736
1947.96	4.30649
1950.92	4.54109
1953.88	4.30226
1956.85	4.7599
1959.81	5.58204
1962.77	5.92602
1965.73	5.93156
1968.69	6.72327
1971.64	6.83828
1974.6	6.53039
1977.55	6.28148
1980.51	6.60805
1983.46	6.08789
1986.41	6.91699
1989.36	6.56178
1992.31	6.27733
1995.26	6.8406
1998.21	6.33358
2001.15	6.96145
2004.1	8.03335
2007.04	8.15195
2009.99	8.76845
2012.93	8.54042
2015.87	8.83743
2018.81	8.77007
2021.75	7.92681
2024.68	8.58426
2027.62	8.85144
2030.56	9.80595
2033.49	10.7366
2036.42	10.3343
2039.36	10.1551
2042.29	11.6954
2045.22	11.329
2048.14	12.6763
2051.07	13.2543
2054	13.6327
2056.93	13.5417
2059.85	14.0208
2062.77	13.6134
2065.7	13.8179
2068.62	14.3176
2071.54	14.2325
2074.46	14.9355
2077.38	16.2151
2080.29	16.869
2083.21	17.341
2086.12	16.9871
2089.04	17.5078
2091.95	18.628
2094.86	18.6882
2097.77	19.4964
2100.68	20.4532
2103.59	21.7707
2106.5	22.3694
2109.41	23.0477
2112.31	24.3928
2115.21	26.1587
2118.12	27.5498
2121.02	29.0496
2123.92	30.3094
2126.82	31.2044
2129.72	33.2056
2132.62	34.6356
2135.51	37.1091
2138.41	39.0984
2141.31	42.2845
2144.2	44.8561
2147.09	47.2351
2149.98	50.243
2152.87	52.8336
2155.76	55.2776
2158.65	57.0397
2161.54	59.4182
2164.43	59.8294
2167.31	60.1889
2170.2	62.0765
2173.08	62.9497
2175.96	62.8568
2178.84	62.1139
2181.72	60.789
2184.6	60.1729
2187.48	58.1602
2190.36	56.0382
2193.23	54.2308
2196.11	53.2123
2198.98	51.2466
2201.85	49.2474
2204.72	47.7103
2207.59	45.5507
2210.46	44.1406
2213.33	42.4929
2216.2	40.1813
2219.07	38.8554
2221.93	38.1497
2224.8	35.5672
2227.66	33.7041
2230.52	32.2595
2233.39	29.7294
2236.25	28.3854
2239.1	28.8546
2241.96	27.2013
2244.82	25.0901
2247.68	23.3075
2250.53	21.7242
2253.38	20.659
2256.24	19.6171
2259.09	18.3991
2261.94	18.7855
2264.79	17.9928
2267.64	17.9442
2270.49	17.6205
2273.33	17.0094
2276.18	16.6898
2279.02	15.418
2281.87	15.126
2284.71	15.3665
2287.55	14.3025
2290.39	14.1429
2293.23	12.1476
2296.07	12.1585
2298.91	13.0351
2301.74	13.3472
2304.58	13.5951
2307.41	13.6111
2310.25	13.4733
2313.08	13.1448
2315.91	13.6684
2318.74	13.2971
2321.57	12.9324
2324.4	13.4999
2327.23	13.9729
2330.05	12.4121
2332.88	11.865
2335.7	11.168
2338.52	9.31732
2341.35	8.76385
2344.17	6.66196
2346.99	4.90824
2349.81	4.9194
2352.62	4.75242
2355.44	3.33447
2358.26	2.0293
2361.07	0.687794
2363.89	0.972643
2366.7	1.56126
2369.51	2.02828
2372.32	2.52819
2375.13	1.99696
2377.94	2.31724
2380.75	3.16514
2383.56	3.87848
2386.36	4.57811
2389.17	5.05491
2391.97	7.0073
2394.77	6.74868
2397.58	6.49762
2400.38	5.62878
2403.18	5.79033
2405.97	4.21926
2408.77	4.27692
2411.57	4.24787
2414.37	4.96048
2417.16	5.1305
2419.95	5.01052
2422.75	4.39209
2425.54	4.90225
2428.33	4.13468
2431.12	4.10539
2433.91	5.11004
2436.7	4.85325
2439.48	4.95343
2442.27	4.7088
2445.05	4.40824
2447.84	4.28509
2450.62	4.27424
2453.4	5.57886
2456.18	5.11275
2458.96	4.831
2461.74	4.35426
2464.52	3.10845
2467.29	2.8471
2470.07	2.16399
2472.85	2.23486
2475.62	2.98371
2478.39	3.52023
2481.16	2.72037
2483.93	2.62478
2486.7	2.1872
2489.47	2.05605
2492.24	2.61633
2495.01	1.82853
2497.77	1.61793
2500.54	1.82019
2503.3	1.24047
2506.06	1.34262
2508.83	1.75279
2511.59	0.543838
2514.35	0.215324
2517.11	0.298264
2519.86	0.826179
2522.62	1.30784
2525.38	0.772852
2528.13	0.110566
2530.89	0.195679
2533.64	0.855778
2536.39	0.985762
2539.14	1.59587
2541.89	2.38609
2544.64	1.39997
2547.39	1.61523
2550.14	1.63141
2552.88	1.88338
2555.63	2.16829
2558.37	1.88784
2561.11	1.49486
2563.86	1.68872
2566.6	1.23607
2569.34	1.468
2572.08	1.46879
2574.82	1.37697
2577.55	1.6572
2580.29	1.28854
2583.02	1.94143
2585.76	2.21417
2588.49	1.75222
2591.22	2.67591
2593.96	2.00614
2596.69	1.22179
2599.42	1.57279
2602.14	2.71396
2604.87	2.47778
2607.6	2.80064
2610.32	3.1409
2613.05	2.59263
2615.77	2.80281
2618.49	2.16732
2621.22	1.82296
2623.94	1.65354
2626.66	1.59665
2629.37	1.9526
2632.09	1.21767
2634.81	2.20541
2637.53	1.67831
2640.24	2.09996
2642.96	2.70752
2645.67	2.49537
2648.38	2.02082
2651.09	1.60962
2653.8	2.04694
2656.51	2.0026
2659.22	2.65294
2661.93	2.45772
2664.63	3.69921
2667.34	4.0752
2670.04	3.6384
2672.75	2.78896
2675.45	2.9493
2678.15	2.27668
2680.85	2.04404
2683.55	1.83442
2686.25	2.57634
2688.94	2.63289
2691.64	2.88709
2694.34	2.71492
2697.03	2.93769
2699.73	3.19028
2702.42	3.49835
2705.11	3.91294
2707.8	4.52753
2710.49	5.29109
2713.18	5.86704
2715.87	6.88632
2718.55	8.57307
2721.24	8.52729
2723.93	9.02167
2726.61	9.30246
2729.29	8.83964
2731.98	8.6673
2734.66	7.42207
2737.34	6.14207
2740.02	6.07709
2742.7	6.38275
2745.37	5.70032
2748.05	5.35834
2750.72	5.51312
2753.4	5.04676
2756.07	3.34456
2758.75	2.87934
2761.42	2.89333
2764.09	2.20529
2766.76	1.94395
2769.43	2.65802
2772.1	2.97806
2774.76	3.01166
2777.43	2.71193
2780.1	2.6603
2782.76	2.25979
2785.42	1.68322
2788.09	1.37316
2790.75	1.31135
2793.41	0.15429
2796.07	0.781291
2798.73	1.41673
2801.39	2.02858
2804.04	2.47972
2806.7	2.7371
2809.35	2.45187
2812.01	3.03403
2814.66	2.69019
2817.31	3.28462
2819.96	4.08551
2822.61	6.05502
2825.26	9.56488
2827.91	11.7745
2830.56	15.5256
2833.21	18.7354
2835.85	21.9835
2838.5	27.0507
2841.14	31.468
2843.78	37.1
2846.42	44.3942
2849.06	51.7104
2851.71	60.0075
2854.34	68.5243
2856.98	76.8419
2859.62	85.5364
2862.26	93.868
2864.89	101.566
2867.53	108.716
2870.16	114.709
2872.79	120.096
2875.42	125.283
2878.05	130.276
2880.68	134.639
2883.31	139.385
2885.94	145.125
2888.57	150.541
2891.19	155.717
2893.82	160.804
2896.44	166.981
2899.07	173.756
2901.69	181.603
2904.31	191.335
2906.93	201.22
2909.55	212.369
2912.17	224.922
2914.79	237.658
2917.41	249.155
2920.02	259.705
2922.64	267.663
2925.25	273.886
2927.86	277.947
2930.48	280.159
2933.09	279.874
2935.7	277.455
2938.31	273.426
2940.92	268.054
2943.53	262.005
2946.13	252.8
2948.74	244.202
2951.34	234.495
2953.95	224.918
2956.55	213.889
2959.15	204.454
2961.75	194.796
2964.35	184.974
2966.95	175.42
2969.55	167.236
2972.15	160.05
2974.75	152.221
2977.34	144.939
2979.94	136.493
2982.53	127.851
2985.13	118.97
2987.72	110.099
2990.31	100.271
2992.9	91.4604
2995.49	83.5848
2998.08	74.9258
3000.67	67.1307
3003.25	60.4744
3005.84	53.4429
3008.42	47.7816
3011.01	42.6476
3013.59	38.1455
3016.17	34.6594
3018.76	31.1254
3021.34	28.3135
3023.92	25.7149
3026.49	23.8771
3029.07	22.7302
3031.65	21.5875
3034.23	21.8308
3036.8	22.8092
3039.38	23.4028
3041.95	24.4594
3044.52	26.1592
3047.09	27.1276
3049.66	28.4324
3052.23	29.0296
3054.8	30.529
3057.37	31.6389
3059.94	31.5863
3062.5	31.0504
3065.07	30.361
3067.63	29.1281
3070.2	27.7881
3072.76	26.9798
3075.32	24.8042
3077.88	22.6924
3080.44	19.0815
3083	16.0697
3085.56	13.4745
3088.12	11.3033
3090.67	8.91885
3093.23	7.35212
3095.78	5.65797
3098.34	4.20499
3100.89	2.95981
3103.44	1.39543
3105.99	1.24832
3108.54	0.706032
3111.09	0.45748
3113.64	0.36407
3116.19	0.718107
3118.74	0.81572
3121.28	0.76518
3123.83	1.74572
3126.37	2.62677
3128.91	3.28861
3131.46	4.59489
3134	5.9883
3136.54	7.46078
3139.08	8.52713
3141.62	10.0137
3144.16	11.877
3146.69	14.4337
3149.23	15.6554