File: data/Raman/poly_smoothed/Thy_30_10_11_1x_45s_532 nm_x100_100%_600 gr_mm_01.txt
#Acq. time (s)=	45
#Accumulations=	2
#Range (cm-¹)=	200...3150
#Windows=	2
#Auto scanning=	Off
#Autofocus=	Off
#Macrospot=	Off
#AutoExposure=	Off
#Spike filter=	Multiple accum.
#Delay time (s)=	0
#Binning=	1
#Readout mode=	Signal
#DeNoise=	Off
#ICS correction=	On
#Dark correction=	Off
#Inst. Process=	Off
#Detector Gain=	Best Dynamic Range
#Detector ADC=	20 kHz
#Detector temperature (°C)=	-69.85
#Instrument=	LabRAM HR Evol
#Detector=	Synapse
#Objective=	x100
#Grating=	600 gr/mm
#ND Filter=	100%
#Laser (nm)=	532
#Hole=	100.021
#Range=	Auto
#Laser Pol.=	No
#Raman. Pol.=	No
#Laser Pol. (°)=	-0.0007625
#Raman Pol. (°)=	89.9995
#Collection=	Microscope
#StageXY=	Marzhauser
#StageZ=	Marzhauser
#X (µm)=	4730.9
#Y (µm)=	-7742.5
#Z (µm)=	584.6
#Full time(mm:ss)=	3:18
#Project=
#Sample=
#Site=
#Title=	Thy_30_10_11_2x_45s_532 nm_x100_100%_600 gr_mm
#Remark=
#Date=	30.06.2022 12:07
#Acquired=	30.06.2022 12:07:40
#Base:Fit=	10.08.2022 09:58:11
#Base:Sub=	10.08.2022 09:58:44
#Filter:Polynom=	16.08.2022 10:22:53
#AxisType[0]=Intens
#AxisUnit[0]=Cnt
#AxisType[1]=Spectr
#AxisUnit[1]=1/cm
200.533	4.23566
204.162	5.06551
207.792	5.69748
211.418	5.04053
215.044	4.24438
218.667	4.2037
222.289	3.79856
225.912	1.73584
229.531	2.37985
233.148	2.49483
236.766	2.65308
240.381	3.04112
243.994	3.05726
247.606	3.01281
251.217	3.19726
254.828	3.84035
258.436	3.5121
262.042	2.83445
265.647	3.17927
269.25	3.47666
272.852	4.18062
276.453	5.0596
280.052	5.66125
283.65	7.69253
287.247	9.77631
290.842	10.9693
294.436	12.4243
298.028	13.5982
301.617	14.2986
305.206	15.6204
308.794	15.5224
312.381	14.9918
315.964	15.1479
319.548	15.6903
323.131	16.0063
326.71	15.7413
330.29	14.6007
333.868	12.0742
337.443	10.9162
341.018	8.91163
344.591	7.5165
348.163	6.64745
351.733	5.12397
355.303	4.67418
358.869	4.43964
362.435	4.54515
366.001	5.60826
369.563	8.17093
373.124	8.99986
376.686	7.99319
380.244	8.078
383.801	8.80716
387.357	7.50393
390.911	8.85053
394.466	8.66619
398.018	8.02662
401.568	8.68883
405.117	8.56058
408.664	8.31167
412.21	7.33727
415.755	5.60572
419.298	4.22509
422.84	3.68644
426.38	3.93551
429.919	4.07091
433.455	5.51115
436.992	4.14954
440.527	4.86251
444.06	6.24489
447.593	7.9875
451.122	7.84151
454.651	9.24095
458.18	9.3714
461.705	7.82533
465.23	7.97033
468.752	10.1615
472.275	10.1301
475.797	11.2053
479.315	11.4522
482.834	10.6483
486.349	11.0769
489.863	10.8785
493.378	10.1787
496.889	9.89777
500.401	10.7209
503.91	11.3934
507.417	11.4463
510.923	12.0617
514.43	12.3241
517.933	11.7022
521.435	12.1992
524.936	11.3273
528.435	11.7975
531.933	11.5504
535.43	10.3725
538.927	9.20155
542.421	9.86445
545.913	9.41383
549.403	9.31965
552.893	9.26209
556.381	8.62031
559.868	7.15462
563.354	7.47128
566.839	6.76651
570.322	6.86842
573.802	7.05323
577.283	7.33211
580.762	7.44357
584.24	8.00448
587.714	8.40377
591.19	7.4502
594.663	5.93715
598.134	4.24977
601.605	3.09146
605.073	4.39928
608.542	3.95999
612.007	3.27979
615.473	3.86386
618.936	3.68749
622.397	2.80706
625.859	5.21128
629.318	5.25752
632.775	6.50794
636.233	7.68455
639.688	8.74933
643.142	9.19947
646.594	10.746
650.045	11.9446
653.496	13.7775
656.944	14.2419
660.391	14.3591
663.837	13.1923
667.281	12.5968
670.724	13.5077
674.166	13.5299
677.606	13.9635
681.045	14.4307
684.483	15.8146
687.917	17.612
691.352	20.4254
694.786	22.3524
698.219	23.0155
701.65	24.02
705.078	25.2699
708.506	28.4861
711.934	31.427
715.358	34.5009
718.782	37.2415
722.204	37.9695
725.626	38.8995
729.045	40.6846
732.464	42.2301
735.881	43.0733
739.297	42.7521
742.711	43.5534
746.125	44.4548
749.537	46.8141
752.946	50.4764
756.357	51.6066
759.764	53.3413
763.17	55.214
766.575	56.0324
769.978	57.9732
773.382	60.0349
776.783	62.0406
780.182	62.8246
783.581	63.6216
786.978	65.5988
790.373	67.5927
793.768	70.1926
797.161	70.1671
800.552	71.8419
803.941	70.771
807.33	70.8704
810.718	71.7101
814.105	72.2135
817.49	71.888
820.873	71.9211
824.256	71.6973
827.637	71.7051
831.016	70.5754
834.395	69.2744
837.772	68.4045
841.147	68.1298
844.522	66.1052
847.894	64.4082
851.267	63.0244
854.637	60.7061
858.007	59.0185
861.374	56.9475
864.739	56.8425
868.106	55.3485
871.469	54.7989
874.831	52.836
878.193	51.7518
881.553	49.9794
884.911	48.8263
888.268	48.4222
891.623	47.8439
894.978	47.0356
898.331	45.8152
901.683	45.4544
905.033	44.1143
908.383	42.3721
911.731	42.1712
915.078	42.2994
918.423	41.8678
921.768	41.3486
925.111	41.0507
928.452	39.7974
931.791	39.2843
935.13	37.4845
938.468	37.7718
941.803	36.569
945.139	35.313
948.473	33.3515
951.804	32.8056
955.136	32.6021
958.465	32.4446
961.794	31.5391
965.12	30.5701
968.447	32.7695
971.771	34.3857
975.095	34.9184
978.417	35.4497
981.737	36.6672
985.057	37.5111
988.375	37.9392
991.691	38.3901
995.006	38.1954
998.32	37.622
1001.63	35.7678
1004.95	36.7713
1008.26	35.0536
1011.56	33.6981
1014.87	31.4028
1018.18	29.2605
1021.48	28.01
1024.79	26.7831
1028.09	25.4712
1031.39	26.1376
1034.69	25.4696
1037.99	24.7838
1041.29	23.6072
1044.58	23.5528
1047.88	26.2253
1051.17	26.6174
1054.46	26.1458
1057.75	24.8106
1061.04	23.0701
1064.33	23.9654
1067.62	22.9251
1070.9	22.8748
1074.19	22.8064
1077.47	23.8913
1080.76	23.6307
1084.04	23.0591
1087.32	21.5948
1090.59	21.1929
1093.87	20.1378
1097.15	19.0817
1100.42	19.2809
1103.69	19.8156
1106.97	20.1501
1110.24	20.4305
1113.51	19.5961
1116.77	18.8507
1120.04	17.8543
1123.31	16.4489
1126.57	15.3366
1129.83	14.2048
1133.1	11.7785
1136.36	10.9671
1139.62	9.09156
1142.87	8.43734
1146.13	7.40529
1149.38	6.86196
1152.64	6.8186
1155.89	6.89207
1159.14	7.24574
1162.39	6.5689
1165.64	6.16833
1168.89	5.72742
1172.14	7.36079
1175.38	7.11444
1178.63	9.25469
1181.87	11.475
1185.11	12.8695
1188.35	14.3071
1191.59	14.2927
1194.83	16.2798
1198.07	16.7995
1201.3	17.9551
1204.53	20.1766
1207.77	21.8032
1211	24.2581
1214.23	26.7297
1217.46	29.2302
1220.69	30.713
1223.91	31.458
1227.14	34.4054
1230.36	35.4944
1233.59	38.5174
1236.81	40.368
1240.03	42.6867
1243.25	43.8342
1246.46	45.0472
1249.68	47.4291
1252.9	48.4345
1256.11	49.7728
1259.32	51.6083
1262.54	52.6936
1265.75	52.4779
1268.96	53.9026
1272.16	53.3201
1275.37	54.5976
1278.57	55.2303
1281.78	55.8056
1284.98	55.1668
1288.18	55.8298
1291.38	55.8618
1294.58	56.909
1297.78	57.1319
1300.98	56.8832
1304.17	56.4211
1307.37	57.6477
1310.56	55.8775
1313.76	55.4917
1316.95	54.2926
1320.14	54.77
1323.32	54.6671
1326.51	54.1299
1329.7	53.554
1332.88	52.7963
1336.07	52.4024
1339.25	52.1291
1342.43	51.0357
1345.61	50.7417
1348.79	49.2403
1351.96	49.2615
1355.14	46.8973
1358.31	44.68
1361.49	42.7658
1364.66	41.5472
1367.83	40.2724
1371	39.6618
1374.17	39.9644
1377.34	38.2805
1380.5	36.6661
1383.67	35.4222
1386.83	33.7348
1390	31.3911
1393.16	29.7456
1396.32	28.7374
1399.48	28.0726
1402.64	26.2841
1405.79	25.5917
1408.95	25.0604
1412.1	25.2772
1415.26	26.3815
1418.41	29.8559
1421.56	33.1857
1424.71	36.256
1427.86	39.3962
1431	43.2984
1434.15	47.4521
1437.29	51.8647
1440.44	55.9927
1443.58	58.4355
1446.72	60.349
1449.86	61.8335
1453	62.0178
1456.14	62.0358
1459.27	60.2846
1462.41	58.3555
1465.54	55.3418
1468.67	51.4673
1471.81	47.3235
1474.94	42.507
1478.07	37.0484
1481.19	30.8684
1484.32	26.3023
1487.45	21.722
1490.57	18.2351
1493.69	17.0578
1496.82	15.2615
1499.94	14.1293
1503.06	13.7919
1506.17	14.2753
1509.29	14.8961
1512.41	14.1573
1515.52	13.8527
1518.64	14.5515
1521.75	15.7754
1524.86	17.1986
1527.97	19.4184
1531.08	21.2822
1534.19	23.8372
1537.29	27.0394
1540.4	27.6545
1543.5	29.6548
1546.61	33.2044
1549.71	35.7287
1552.81	37.7255
1555.91	39.5131
1559.01	41.0507
1562.11	43.0394
1565.2	44.8491
1568.29	48.6043
1571.39	50.5981
1574.48	52.0348
1577.57	53.3605
1580.66	54.1313
1583.75	55.17
1586.84	55.1621
1589.93	55.8587
1593.01	56.6833
1596.1	57.8946
1599.18	58.2453
1602.26	57.8736
1605.34	57.4607
1608.42	56.6182
1611.5	56.203
1614.58	56.1524
1617.65	55.3043
1620.73	56.7928
1623.8	57.6733
1626.87	59.4097
1629.95	61.8567
1633.02	63.8789
1636.09	66.0701
1639.15	69.4827
1642.22	71.6352
1645.29	73.1158
1648.35	73.0755
1651.42	74.9978
1654.48	75.8599
1657.54	76.9576
1660.6	77.8553
1663.66	77.2074
1666.72	76.6204
1669.77	73.6869
1672.83	70.8479
1675.88	65.692
1678.93	61.9559
1681.99	57.1738
1685.04	53.0536
1688.09	48.3411
1691.13	42.7563
1694.18	39.0989
1697.23	36.3484
1700.27	32.3471
1703.32	28.3429
1706.36	25.3974
1709.4	21.6816
1712.44	19.3141
1715.48	16.6852
1718.52	13.6357
1721.56	12.9095
1724.59	11.7435
1727.63	11.5312
1730.66	11.9985
1733.69	12.1832
1736.72	12.2498
1739.75	12.4094
1742.78	12.4518
1745.81	11.6426
1748.84	11.84
1751.86	11.3207
1754.89	11.5278
1757.91	11.615
1760.93	11.6851
1763.95	11.3903
1766.97	11.1348
1769.99	10.9897
1773.01	9.32119
1776.03	8.38697
1779.04	6.85407
1782.06	5.71915
1785.07	4.45511
1788.08	3.7534
1791.09	2.89795
1794.1	2.62831
1797.11	3.07293
1800.12	3.48787
1803.12	3.73847
1806.13	4.96196
1809.13	5.69291
1812.14	6.19559
1815.14	6.84713
1818.14	7.71532
1821.14	8.45
1824.14	8.02719
1827.13	8.26919
1830.13	8.07807
1833.12	7.47476
1836.12	7.47597
1839.11	7.89858
1842.1	6.97509
1845.09	7.03634
1848.08	5.90725
1851.07	5.05027
1854.06	4.42976
1857.04	2.96131
1860.03	2.18364
1863.01	1.33562
1866	1.04132
1868.98	0.317624
1871.96	1.09871
1874.94	1.37677
1877.92	1.49623
1880.89	1.87951
1882.48	2.24861
1885.47	2.63633
1888.46	2.58458
1891.44	2.72627
1894.43	2.12145
1897.41	2.4451
1900.4	3.1343
1903.38	3.35498
1906.36	4.03405
1909.34	5.70717
1912.32	7.18898
1915.29	8.61601
1918.27	10.3367
1921.25	9.8631
1924.22	10.9121
1927.2	10.6285
1930.17	10.5836
1933.14	10.2583
1936.11	9.58505
1939.08	9.50727
1942.05	9.20756
1945.01	10.1491
1947.98	9.31415
1950.94	9.05457
1953.91	8.46793
1956.87	7.32417
1959.83	7.19881
1962.79	5.96512
1965.75	6.35826
1968.71	6.08379
1971.67	6.61013
1974.62	7.02368
1977.58	6.9844
1980.53	8.16496
1983.48	9.38618
1986.43	10.2089
1989.38	11.0701
1992.33	10.849
1995.28	12.421
1998.23	12.3879
2001.18	11.8196
2004.12	11.3528
2007.06	11.8572
2010.01	11.2321
2012.95	11.8316
2015.89	12.0845
2018.83	12.5209
2021.77	13.3583
2024.71	13.2198
2027.64	14.7862
2030.58	15.2088
2033.51	14.9555
2036.45	16.071
2039.38	16.169
2042.31	16.4406
2045.24	17.6221
2048.17	18.3082
2051.1	18.8952
2054.02	20.0495
2056.95	20.5433
2059.87	20.9497
2062.8	21.213
2065.72	21.5137
2068.64	20.8706
2071.56	20.662
2074.48	19.4493
2077.4	19.6844
2080.31	20.0372
2083.23	20.6293
2086.14	21.0608
2089.06	21.2237
2091.97	22.185
2094.88	23.0837
2097.79	23.7901
2100.7	25.7143
2103.61	26.7598
2106.52	28.8597
2109.43	31.2786
2112.33	33.0391
2115.24	35.5724
2118.14	38.2496
2121.04	41.0663
2123.94	43.2177
2126.84	45.9189
2129.74	47.9031
2132.64	49.9645
2135.54	52.7392
2138.43	54.3625
2141.33	57.0929
2144.22	58.8
2147.11	60.631
2150.01	62.5772
2152.9	64.1919
2155.79	65.5053
2158.67	67.2765
2161.56	67.2981
2164.45	68.4842
2167.33	69.541
2170.22	70.7705
2173.1	71.8835
2175.98	72.2296
2178.86	71.203
2181.74	70.6897
2184.62	69.4434
2187.5	68.5438
2190.38	66.9201
2193.25	64.9034
2196.13	62.9989
2199	60.7586
2201.88	59.1223
2204.75	57.2308
2207.62	53.609
2210.49	50.69
2213.36	48.3582
2216.22	45.8619
2219.09	44.0816
2221.96	42.542
2224.82	40.5688
2227.68	39.488
2230.55	37.8352
2233.41	36.3858
2236.27	35.9186
2239.12	34.0569
2241.98	33.1484
2244.84	31.9818
2247.7	30.4686
2250.55	28.8722
2253.41	28.9619
2256.26	27.334
2259.11	25.8859
2261.96	24.6452
2264.81	24.4609
2267.66	23.5671
2270.51	22.837
2273.35	21.8573
2276.2	20.1968
2279.04	18.3137
2281.89	17.8479
2284.73	16.8468
2287.57	16.5059
2290.41	15.9483
2293.25	15.1106
2296.09	15.0205
2298.93	15.2402
2301.76	15.9777
2304.6	15.594
2307.44	15.4554
2310.27	15.9293
2313.1	15.6726
2315.93	15.9766
2318.76	15.9103
2321.59	15.7498
2324.42	16.3282
2327.25	15.8654
2330.07	15.1172
2332.9	15.6065
2335.72	15.0777
2338.55	15.2331
2341.37	13.785
2344.19	13.4076
2347.01	12.1624
2349.83	10.846
2352.65	10.0722
2355.46	9.5425
2358.28	8.27384
2361.09	7.32773
2363.91	7.35748
2366.72	8.47528
2369.53	8.38635
2372.34	7.93707
2375.15	7.14708
2377.96	7.25198
2380.77	7.14216
2383.58	7.31437
2386.38	7.54983
2389.19	8.09592
2391.99	8.55922
2394.8	9.63028
2397.6	9.97522
2400.4	10.5358
2403.2	11.1389
2406	11.944
2408.79	12.2083
2411.59	12.2611
2414.39	13.0413
2417.18	12.9491
2419.98	14.4389
2422.77	14.1417
2425.56	13.8774
2428.35	13.3646
2431.14	13.487
2433.93	13.3781
2436.72	12.521
2439.5	11.3956
2442.29	11.2883
2445.07	9.92631
2447.86	8.68102
2450.64	8.28806
2453.42	7.98814
2456.2	7.74761
2458.98	7.2495
2461.76	7.23258
2464.54	7.36472
2467.32	5.9191
2470.09	5.60439
2472.87	4.21769
2475.64	4.38054
2478.41	4.60339
2481.18	4.65869
2483.95	4.41917
2486.72	4.60469
2489.49	4.92784
2492.26	4.37222
2495.03	3.86643
2497.79	3.99613
2500.56	4.28106
2503.32	3.74846
2506.09	3.67113
2508.85	3.37296
2511.61	2.42038
2514.37	2.41098
2517.13	2.84778
2519.89	2.82229
2522.64	2.42392
2525.4	1.84905
2528.15	1.38052
2530.91	0.560377
2533.66	0.541751
2536.41	0.351446
2539.16	0.638198
2541.91	1.06718
2544.66	2.24399
2547.41	3.07034
2550.16	3.46502
2552.9	4.29223
2555.65	4.60812
2558.39	4.17712
2561.13	4.85502
2563.88	3.85334
2566.62	4.15946
2569.36	4.18811
2572.1	3.79425
2574.84	3.35696
2577.57	2.71571
2580.31	2.53053
2583.05	3.06285
2585.78	2.25979
2588.51	1.25646
2591.24	0.45597
2593.98	-0.302555
2596.71	-0.724266
2599.44	-0.311238
2602.16	0.278208
2604.89	0.752754
2607.62	0.939155
2610.34	1.38485
2613.07	2.4495
2615.79	2.3577
2618.52	2.73332
2621.24	2.82018
2623.96	2.86155
2626.68	2.42218
2629.4	2.63656
2632.11	3.32097
2634.83	4.69757
2637.55	5.45119
2640.26	4.99869
2642.98	4.65672
2645.69	4.85923
2648.4	4.58314
2651.11	3.87838
2653.82	2.46176
2656.53	1.45189
2659.24	1.49387
2661.95	1.14839
2664.65	1.03521
2667.36	0.963243
2670.06	0.877567
2672.76	1.13588
2675.47	2.04426
2678.17	1.54464
2680.87	1.92992
2683.57	1.79663
2686.27	2.13935
2688.97	2.53313
2691.66	2.99149
2694.36	2.8871
2697.05	3.69745
2699.75	4.60481
2702.44	4.85967
2705.13	3.92338
2707.82	2.90992
2710.51	3.70087
2713.2	3.08638
2715.89	3.15896
2718.57	3.50365
2721.26	2.95376
2723.95	2.82412
2726.63	2.97927
2729.31	3.14259
2732	3.42216
2734.68	3.61888
2737.36	3.93959
2740.04	4.19312
2742.72	3.85141
2745.39	3.7333
2748.07	3.70975
2750.75	3.20294
2753.42	4.03483
2756.09	4.04834
2758.77	4.01213
2761.44	4.40844
2764.11	4.4685
2766.78	3.95732
2769.45	3.74338
2772.12	4.04627
2774.78	4.44999
2777.45	4.58156
2780.12	3.90004
2782.78	3.85631
2785.44	2.39559
2788.11	1.99417
2790.77	1.98933
2793.43	2.34379
2796.09	1.80706
2798.75	0.283967
2801.4	-0.0131958
2804.06	0.0569248
2806.72	0.54831
2809.37	0.333014
2812.03	0.185906
2814.68	0.170522
2817.33	0.392808
2819.98	2.42031
2822.63	5.10463
2825.28	7.45159
2827.93	10.4225
2830.58	13.7375
2833.23	17.2643
2835.87	21.091
2838.52	25.5161
2841.16	30.3043
2843.8	35.1875
2846.44	41.6419
2849.08	48.0588
2851.73	54.5886
2854.36	62.7244
2857	70.6665
2859.64	77.5078
2862.28	83.5883
2864.91	90.6398
2867.55	96.7665
2870.18	102.579
2872.81	107.86
2875.44	111.518
2878.07	114.472
2880.7	118.741
2883.33	122.584
2885.96	126.741
2888.59	130.614
2891.21	132.863
2893.84	136.565
2896.46	140.68
2899.09	145.319
2901.71	151.111
2904.33	158.106
2906.95	165.796
2909.57	175.539
2912.19	185.308
2914.81	194.778
2917.43	204.345
2920.04	212.649
2922.66	219.981
2925.27	224.551
2927.88	230.22
2930.5	232.686
2933.11	233.668
2935.72	233.709
2938.33	231.329
2940.94	226.799
2943.54	221.887
2946.15	216.148
2948.76	207.512
2951.36	199.433
2953.97	190.1
2956.57	181.468
2959.17	173.528
2961.77	165.142
2964.37	156.111
2966.97	148.147
2969.57	140.432
2972.17	133.23
2974.77	126.489
2977.36	118.854
2979.96	111.454
2982.55	104.173
2985.15	97.124
2987.74	89.5265
2990.33	83.0825
2992.92	76.6122
2995.51	69.4505
2998.1	63.464
3000.69	58.3365
3003.27	51.9128
3005.86	46.7992
3008.44	41.7619
3011.03	36.9114
3013.61	33.3709
3016.19	30.5132
3018.78	27.8672
3021.36	25.113
3023.94	22.8584
3026.51	21.0585
3029.09	20.2676
3031.67	20.294
3034.24	20.7181
3036.82	21.6038
3039.39	22.1999
3041.97	23.9241
3044.54	24.8719
3047.11	26.256
3049.68	27.5423
3052.25	28.0856
3054.82	28.5299
3057.39	28.4411
3059.96	28.5565
3062.52	27.6549
3065.09	26.7278
3067.65	25.5647
3070.22	22.8514
3072.78	20.5312
3075.34	18.0905
3077.9	15.8882
3080.46	14.2264
3083.02	11.1847
3085.58	8.84348
3088.14	6.92402
3090.69	4.63219
3093.25	3.39145
3095.8	2.89053
3098.36	2.27492
3100.91	1.43467
3103.46	0.642116
3106.01	0.842054
3108.56	1.21388
3111.11	0.75495
3113.66	0.613811
3116.21	0.773869
3118.76	0.756979
3121.3	0.873127
3123.85	1.15095
3126.39	1.32969
3128.93	1.21307
3131.48	0.443377
3134.02	0.431636
3136.56	0.831402
3139.1	1.49534
3141.64	1.25534
3144.17	0.612754
3146.71	0.386183
3149.25	1.16684