File: data/Raman/poly_smoothed/Thy_40_11_30_1x_45s_532 nm_x100_100%_600 gr_mm_01.txt
#Acq. time (s)=	45
#Accumulations=	2
#Range (cm-¹)=	200...3150
#Windows=	2
#Auto scanning=	Off
#Autofocus=	Off
#Macrospot=	Off
#AutoExposure=	Off
#Spike filter=	Multiple accum.
#Delay time (s)=	0
#Binning=	1
#Readout mode=	Signal
#DeNoise=	Off
#ICS correction=	On
#Dark correction=	Off
#Inst. Process=	Off
#Detector Gain=	Best Dynamic Range
#Detector ADC=	20 kHz
#Detector temperature (°C)=	-69.85
#Instrument=	LabRAM HR Evol
#Detector=	Synapse
#Objective=	x100
#Grating=	600 gr/mm
#ND Filter=	100%
#Laser (nm)=	532
#Hole=	100.021
#Range=	Auto
#Laser Pol.=	No
#Raman. Pol.=	No
#Laser Pol. (°)=	-0.0007625
#Raman Pol. (°)=	89.9995
#Collection=	Microscope
#StageXY=	Marzhauser
#StageZ=	Marzhauser
#X (µm)=	254
#Y (µm)=	1670.5
#Z (µm)=	427.2
#Full time(mm:ss)=	3:19
#Project=
#Sample=
#Site=
#Title=	Thy_40_11_30_2x_45s_532 nm_x100_100%_600 gr_mm
#Remark=
#Date=	05.07.2022 12:10
#Acquired=	05.07.2022 12:10:00
#Base:Fit=	10.08.2022 10:01:35
#Base:Sub=	10.08.2022 10:01:52
#Filter:Polynom=	16.08.2022 10:21:53
#AxisType[0]=Intens
#AxisUnit[0]=Cnt
#AxisType[1]=Spectr
#AxisUnit[1]=1/cm
200.43	4.22963
204.059	6.06321
207.688	4.96336
211.314	4.12048
214.941	3.46208
218.564	3.67545
222.186	3.03658
225.809	3.52203
229.428	3.53484
233.045	5.52826
236.663	5.62811
240.278	4.87338
243.891	6.63954
247.503	7.63507
251.116	8.46328
254.725	10.0199
258.333	10.5494
261.939	11.1111
265.544	12.8351
269.148	13.2985
272.75	13.4255
276.351	12.6695
279.95	13.8969
283.548	12.6473
287.144	11.8136
290.739	10.8767
294.333	9.9454
297.925	9.79465
301.514	9.22154
305.104	9.71979
308.692	9.43508
312.279	9.24641
315.862	9.15754
319.446	9.29016
323.029	8.90765
326.608	8.73405
330.188	9.93199
333.766	11.1203
337.341	12.7115
340.917	13.149
344.489	13.8095
348.062	14.2345
351.631	14.4887
355.201	14.6269
358.768	13.6631
362.333	14.5678
365.899	13.7602
369.462	13.4423
373.023	11.2901
376.585	11.1773
380.143	10.4936
383.7	10.0375
387.256	10.0741
390.812	9.22734
394.365	8.12547
397.916	7.48682
401.467	5.97349
405.015	5.36484
408.563	5.27738
412.109	5.32417
415.654	5.1536
419.197	5.14448
422.739	4.90413
426.279	4.43139
429.819	4.35888
433.356	4.57008
436.891	3.95161
440.426	3.21926
443.96	1.94892
447.492	1.70442
451.021	1.07786
454.551	-0.292576
458.079	-1.2964
461.604	-1.16295
465.13	1.18195
468.654	1.45684
472.175	1.84029
475.696	2.68657
479.215	4.08127
482.733	6.94801
486.249	8.7604
489.765	9.52626
493.278	11.5434
496.789	12.5875
500.301	13.0867
503.81	12.7655
507.317	13.3344
510.825	13.8748
514.33	14.8397
517.833	15.1459
521.335	14.2559
524.836	13.8675
528.335	12.425
531.835	11.5608
535.332	10.4562
538.827	9.59202
542.321	8.90553
545.814	7.90242
549.305	8.54632
552.795	8.39907
556.282	7.87882
559.769	6.84602
563.255	7.25119
566.739	7.63725
570.223	6.00797
573.705	5.01757
577.183	5.38753
580.663	4.05438
584.141	2.97773
587.615	2.40345
591.09	2.45128
594.564	2.17011
598.035	2.13956
601.506	2.07434
604.974	1.58326
608.443	1.31317
611.908	2.0576
615.374	3.11514
618.837	4.02232
622.3	4.32391
625.761	5.07853
629.219	5.04598
632.677	5.90791
636.135	6.42352
639.59	7.76558
643.043	8.06909
646.495	8.49281
649.948	9.45619
653.398	10.6559
656.846	11.1056
660.293	12.6107
663.738	14.1892
667.183	15.4059
670.626	15.9283
674.067	15.5215
677.508	16.1282
680.947	18.1659
684.385	19.8699
687.821	20.6874
691.254	22.0083
694.688	24.9623
698.121	26.1038
701.552	27.1557
704.98	27.5119
708.409	29.6282
711.836	29.3802
715.26	30.6848
718.685	31.7774
722.108	34.4332
725.528	34.4166
728.949	36.5334
732.367	36.9616
735.785	39.7467
739.2	41.1786
742.614	43.2522
746.028	45.1553
749.439	46.6454
752.849	48.8943
756.26	50.8416
759.667	53.6529
763.073	57.2809
766.477	60.7655
769.883	63.3115
773.285	65.0886
776.686	67.7351
780.085	69.3133
783.484	70.4532
786.881	71.2924
790.276	73.3525
793.671	74.2589
797.064	74.4642
800.456	75.5143
803.846	77.1981
807.234	76.7302
810.622	76.131
814.008	76.0104
817.394	75.9072
820.778	75.7313
824.159	75.3958
827.541	73.6713
830.921	72.3844
834.298	70.5851
837.676	70.8092
841.051	69.9431
844.426	67.9644
847.798	67.0565
851.171	66.2829
854.54	63.818
857.911	60.6469
861.278	58.4116
864.645	57.7366
868.01	56.8688
871.373	56.6261
874.735	53.9791
878.097	51.7233
881.457	50.6268
884.815	48.0049
888.172	46.1848
891.528	44.8762
894.882	45.3306
898.237	44.5717
901.589	44.6554
904.94	44.1156
908.289	42.3698
911.635	41.3945
914.982	41.3613
918.328	41.3773
921.672	40.7172
925.015	39.8704
928.357	39.5259
931.698	39.173
935.035	38.3957
938.373	38.2228
941.71	37.4669
945.044	37.2
948.378	37.6563
951.709	38.4703
955.041	36.784
958.372	36.0237
961.699	35.2273
965.027	34.9129
968.352	35.2399
971.676	37.2722
975	37.062
978.322	37.5498
981.642	37.204
984.962	36.6953
988.28	35.6878
991.596	34.8309
994.911	35.8053
998.227	34.2085
1001.54	33.6613
1004.85	33.6181
1008.16	31.9517
1011.47	30.1515
1014.78	30.2981
1018.08	30.7501
1021.39	30.0387
1024.69	29.2826
1028	29.3673
1031.3	28.7407
1034.6	28.3131
1037.9	26.5863
1041.19	25.5006
1044.49	22.8846
1047.78	22.5449
1051.08	22.8477
1054.37	21.7643
1057.66	20.8383
1060.95	18.4058
1064.24	17.995
1067.53	17.1805
1070.81	17.4
1074.1	17.4617
1077.38	17.3868
1080.66	16.5543
1083.94	16.92
1087.22	15.4198
1090.5	15.3444
1093.78	16.1945
1097.05	16.8589
1100.33	16.4474
1103.6	16.0472
1106.87	15.7348
1110.14	14.7787
1113.41	13.8901
1116.68	13.3934
1119.95	12.353
1123.21	10.9516
1126.48	10.3451
1129.74	10.4845
1133	10.2466
1136.26	8.12228
1139.52	7.72189
1142.78	7.99138
1146.04	8.38997
1149.29	7.44914
1152.55	6.4194
1155.8	5.21219
1159.05	4.65365
1162.3	3.91665
1165.55	4.16505
1168.8	4.13739
1172.05	5.5586
1175.29	5.6195
1178.54	5.7257
1181.78	6.55527
1185.02	6.89057
1188.26	8.94976
1191.5	10.1762
1194.74	11.7652
1197.97	13.8067
1201.21	14.0402
1204.44	16.8615
1207.68	20.0065
1210.91	21.8148
1214.14	23.9154
1217.37	27.3182
1220.59	29.0817
1223.82	31.8479
1227.05	33.5324
1230.27	34.511
1233.49	36.7491
1236.72	39.5888
1239.94	42.2157
1243.16	43.3978
1246.37	45.8389
1249.59	47.0498
1252.8	48.2779
1256.02	50.2668
1259.23	51.0374
1262.44	52.5868
1265.66	53.649
1268.86	54.7637
1272.07	55.6638
1275.28	57.0646
1278.48	58.829
1281.69	58.6267
1284.89	59.3357
1288.09	60.5611
1291.29	59.9333
1294.49	61.1496
1297.69	60.6795
1300.89	60.2126
1304.08	61.1206
1307.28	61.6178
1310.47	62.3842
1313.66	63.1675
1316.85	61.5938
1320.04	61.8318
1323.23	60.9288
1326.42	61.0036
1329.61	60.1747
1332.79	59.6064
1335.97	57.7661
1339.16	57.145
1342.34	55.6942
1345.52	53.2683
1348.7	51.1589
1351.87	49.2266
1355.05	47.3939
1358.22	46.0873
1361.4	43.0515
1364.57	41.207
1367.74	38.7384
1370.91	35.9339
1374.08	34.215
1377.25	32.4919
1380.41	32.3767
1383.58	31.3739
1386.74	30.4144
1389.91	29.9853
1393.07	30.023
1396.23	30.4265
1399.39	30.7899
1402.55	31.5576
1405.7	32.0901
1408.86	34.1953
1412.01	36.1237
1415.17	37.1965
1418.32	39.4724
1421.47	40.7455
1424.62	42.2339
1427.77	45.0723
1430.91	49.3782
1434.06	52.4193
1437.2	54.8927
1440.35	56.2491
1443.49	56.4388
1446.63	57.9677
1449.77	57.8844
1452.91	58.5192
1456.05	57.8767
1459.18	56.1057
1462.32	54.4873
1465.45	52.27
1468.59	49.3317
1471.72	46.9999
1474.85	43.7892
1477.98	39.9044
1481.1	35.3876
1484.23	33.2169
1487.36	30.6857
1490.48	28.3275
1493.61	26.3803
1496.73	24.2585
1499.85	21.9979
1502.97	21.4631
1506.09	20.9276
1509.2	21.2593
1512.32	20.377
1515.43	18.9743
1518.55	18.7461
1521.66	19.0047
1524.77	20.4234
1527.88	21.5847
1530.99	22.7982
1534.1	24.0782
1537.21	25.3529
1540.31	27.1154
1543.42	28.067
1546.52	29.2108
1549.62	31.6042
1552.72	33.5041
1555.82	35.0091
1558.92	38.5118
1562.02	40.4884
1565.11	42.6556
1568.21	44.7915
1571.3	46.3266
1574.39	48.3369
1577.49	49.6062
1580.57	51.3095
1583.66	52.2702
1586.75	53.5442
1589.84	53.8288
1592.92	54.7845
1596.01	55.1286
1599.09	56.2292
1602.17	55.3106
1605.25	54.6517
1608.33	53.9007
1611.41	52.6024
1614.49	52.2186
1617.57	50.6091
1620.64	50.403
1623.72	50.389
1626.79	50.7735
1629.86	49.7936
1632.93	52.5729
1636	52.5718
1639.07	53.3107
1642.13	55.6137
1645.2	57.478
1648.26	58.0025
1651.33	59.265
1654.39	59.5133
1657.45	61.5857
1660.51	61.3745
1663.57	61.4652
1666.63	60.175
1669.68	57.3515
1672.74	54.9347
1675.79	50.6601
1678.85	47.1204
1681.9	42.982
1684.95	39.6178
1688	36.5354
1691.05	32.4215
1694.09	28.0262
1697.14	23.7086
1700.18	19.8847
1703.23	16.937
1706.27	13.8777
1709.31	12.5895
1712.35	9.79572
1715.39	8.2074
1718.43	6.35935
1721.47	4.61608
1724.5	3.87071
1727.54	3.76215
1730.57	3.37838
1733.61	3.62584
1736.64	3.15136
1739.67	2.34459
1742.7	1.72293
1745.72	1.63761
1748.75	1.02277
1751.77	0.88544
1754.8	1.07883
1757.82	1.56458
1760.84	1.94872
1763.87	1.75742
1766.89	1.27608
1769.91	0.948705
1772.92	0.141559
1775.94	0.560142
1778.95	0.965371
1781.97	0.945411
1784.98	0.968398
1787.99	0.942038
1791.01	1.05244
1794.01	1.67053
1797.02	2.1676
1800.03	2.36139
1803.04	2.25766
1806.04	2.71016
1809.05	3.02746
1812.05	1.92849
1815.05	2.38117
1818.05	2.62411
1821.05	2.59129
1824.05	2.20037
1827.05	2.15244
1830.04	3.25004
1833.04	3.75654
1836.03	3.22936
1839.03	3.13405
1842.02	3.39675
1845.01	3.75946
1848	3.35113
1850.99	3.0047
1853.97	2.21823
1856.96	2.13164
1859.94	2.77317
1862.93	2.77
1865.91	3.99295
1868.89	3.95751
1871.87	3.63388
1874.85	4.15405
1877.83	4.34437
1880.81	4.69965
1882.57	5.41002
1885.56	5.33085
1888.55	5.4691
1891.54	5.81349
1894.52	5.95839
1897.51	5.96917
1900.49	6.75992
1903.47	6.84578
1906.45	6.66202
1909.43	6.87335
1912.41	6.82941
1915.39	5.68203
1918.37	4.99139
1921.34	4.73052
1924.32	4.71673
1927.29	3.91566
1930.26	4.79236
1933.23	4.40016
1936.2	4.64307
1939.17	4.09314
1942.14	3.91492
1945.11	3.28681
1948.07	3.64887
1951.04	3.15724
1954	3.3141
1956.96	2.5873
1959.93	1.96432
1962.89	1.61945
1965.85	1.42785
1968.8	1.7388
1971.76	1.72112
1974.72	1.42278
1977.67	1.67834
1980.63	1.27051
1983.58	0.831542
1986.53	0.564434
1989.48	-0.282415
1992.43	1.35064
1995.38	2.00035
1998.32	1.37158
2001.27	1.56872
2004.22	1.7556
2007.16	0.983176
2010.1	0.7898
2013.04	1.21442
2015.98	0.268954
2018.92	-0.399716
2021.86	0.448911
2024.8	1.25763
2027.74	1.82585
2030.67	0.567098
2033.61	1.26499
2036.54	1.06144
2039.47	1.05891
2042.4	0.94554
2045.33	1.55305
2048.26	1.80975
2051.19	2.49266
2054.12	3.30723
2057.04	4.20274
2059.97	4.3827
2062.89	5.43655
2065.81	5.79663
2068.73	6.06283
2071.65	6.22252
2074.57	7.61753
2077.49	7.70605
2080.41	8.06047
2083.32	9.46752
2086.24	9.92399
2089.15	11.1361
2092.07	12.3398
2094.98	14.2661
2097.89	14.8177
2100.8	15.2727
2103.71	15.8852
2106.61	17.0603
2109.52	18.6144
2112.43	20.1358
2115.33	21.9926
2118.23	24.8004
2121.13	26.9784
2124.04	29.2364
2126.94	30.7469
2129.83	33.6344
2132.73	34.8619
2135.63	37.563
2138.53	40.1699
2141.42	42.6281
2144.31	45.9628
2147.21	48.8477
2150.1	51.5664
2152.99	55.1956
2155.88	57.382
2158.77	59.121
2161.65	60.7465
2164.54	62.0137
2167.43	62.8186
2170.31	63.4172
2173.19	62.3797
2176.07	63.541
2178.96	63.2887
2181.84	63.3348
2184.72	61.8121
2187.59	60.619
2190.47	59.0241
2193.35	56.8032
2196.22	54.6687
2199.09	52.8839
2201.97	50.5613
2204.84	48.338
2207.71	46.4058
2210.58	44.0114
2213.45	41.4608
2216.31	39.7675
2219.18	37.5328
2222.05	35.4053
2224.91	32.9855
2227.78	31.1153
2230.64	29.2159
2233.5	27.0749
2236.36	26.1513
2239.22	24.1643
2242.08	22.169
2244.93	21.155
2247.79	19.8715
2250.64	19.2487
2253.5	18.8155
2256.35	18.0593
2259.2	16.8247
2262.05	16.3434
2264.9	16.1499
2267.75	15.3846
2270.6	14.7481
2273.45	14.0907
2276.29	13.2009
2279.14	12.0951
2281.98	11.4809
2284.82	10.3674
2287.66	10.4753
2290.5	9.51487
2293.34	8.13284
2296.18	8.36392
2299.02	8.99923
2301.86	9.29559
2304.69	10.2949
2307.53	10.4697
2310.36	9.80489
2313.19	9.60101
2316.02	10.5434
2318.85	11.442
2321.68	11.9428
2324.51	11.6629
2327.34	11.7034
2330.16	10.3341
2332.99	9.67387
2335.81	8.44016
2338.64	7.6765
2341.46	7.06015
2344.28	5.47495
2347.1	4.63581
2349.92	2.84279
2352.74	2.19218
2355.55	1.35316
2358.37	-0.165442
2361.19	-0.97385
2364	-0.901242
2366.81	0.402161
2369.62	0.673066
2372.44	1.01566
2375.24	1.36672
2378.05	1.29368
2380.86	0.840316
2383.67	2.43894
2386.47	2.92106
2389.28	4.41033
2392.08	4.44988
2394.89	5.90609
2397.69	5.62451
2400.49	5.99858
2403.29	6.57008
2406.09	7.47448
2408.88	8.62345
2411.68	8.7647
2414.48	9.34731
2417.27	9.53618
2420.06	9.80463
2422.86	10.3044
2425.65	9.91829
2428.44	9.42562
2431.23	8.63013
2434.02	8.97878
2436.81	8.78865
2439.59	8.37333
2442.38	8.01238
2445.16	6.40674
2447.95	6.23746
2450.73	6.16499
2453.51	5.56868
2456.29	4.76769
2459.07	4.13317
2461.85	3.6936
2464.63	3.87154
2467.4	4.03359
2470.18	3.87734
2472.95	4.51903
2475.73	5.25233
2478.5	5.8114
2481.27	6.48387
2484.04	6.82266
2486.81	7.07854
2489.58	7.54349
2492.35	7.22099
2495.12	6.91254
2497.88	7.08715
2500.65	6.35713
2503.41	5.77518
2506.17	5.49916
2508.94	5.30773
2511.7	5.66784
2514.46	5.55205
2517.22	6.23124
2519.97	5.31991
2522.73	4.98364
2525.49	5.09728
2528.24	4.62935
2530.99	4.2959
2533.75	4.27041
2536.5	4.19977
2539.25	4.77607
2542	4.90694
2544.75	4.94787
2547.5	5.5333
2550.24	6.33376
2552.99	6.89342
2555.74	6.34872
2558.48	6.51162
2561.22	7.08163
2563.96	7.7097
2566.71	6.68805
2569.45	6.79468
2572.18	7.20513
2574.92	6.54695
2577.66	6.92769
2580.4	6.35227
2583.13	5.74102
2585.87	5.33928
2588.6	3.97892
2591.33	3.50043
2594.06	4.34811
2596.79	3.45018
2599.52	3.42646
2602.25	3.83797
2604.98	3.77556
2607.71	4.22246
2610.43	4.85624
2613.16	6.08416
2615.88	6.43463
2618.6	7.02698
2621.32	7.67881
2624.04	8.22262
2626.76	9.05727
2629.48	9.76805
2632.2	9.26533
2634.92	9.60394
2637.63	9.46215
2640.35	8.96443
2643.06	8.42391
2645.77	7.96781
2648.49	7.32135
2651.2	7.1713
2653.91	7.48007
2656.62	7.73266
2659.33	8.27437
2662.03	8.13303
2664.74	8.05107
2667.44	8.22167
2670.15	8.1271
2672.85	8.94983
2675.55	9.45479
2678.26	9.98542
2680.96	10.3216
2683.66	10.5288
2686.35	10.4802
2689.05	10.458
2691.75	10.401
2694.44	10.2227
2697.14	9.96072
2699.83	9.87956
2702.52	9.58826
2705.22	9.00945
2707.91	8.93885
2710.6	9.01355
2713.29	9.44804
2715.97	9.76749
2718.66	9.90736
2721.35	9.59182
2724.03	9.23346
2726.72	9.01596
2729.4	8.41567
2732.08	8.42535
2734.76	8.65853
2737.44	9.58423
2740.12	9.63411
2742.8	9.14787
2745.48	9.37634
2748.16	8.68655
2750.83	7.5541
2753.51	6.87347
2756.18	6.8548
2758.85	5.45818
2761.53	4.58535
2764.2	3.88514
2766.87	2.85487
2769.54	2.13496
2772.2	1.48397
2774.87	1.68209
2777.54	1.76081
2780.2	2.0018
2782.87	1.5931
2785.53	1.02636
2788.19	1.38416
2790.85	0.848304
2793.51	0.960197
2796.17	1.29059
2798.83	2.05022
2801.49	2.72243
2804.15	2.98036
2806.8	3.00274
2809.46	2.74844
2812.11	2.95214
2814.76	2.90131
2817.42	2.89738
2820.07	3.6345
2822.72	4.31916
2825.37	4.63941
2828.02	6.41869
2830.66	7.32108
2833.31	8.63663
2835.96	10.175
2838.6	12.4228
2841.24	16.0159
2843.89	19.3572
2846.53	23.6781
2849.17	27.9498
2851.81	31.8006
2854.45	36.7311
2857.09	41.1514
2859.72	46.1729
2862.36	49.0244
2865	54.4928
2867.63	58.0917
2870.26	61.5802
2872.9	65.0816
2875.53	67.8567
2878.16	70.3678
2880.79	73.5518
2883.42	75.8166
2886.05	78.8608
2888.67	81.0438
2891.3	83.9692
2893.92	86.9903
2896.55	90.1652
2899.17	93.8032
2901.79	98.1303
2904.42	104.019
2907.04	110.014
2909.66	116.864
2912.27	123.866
2914.89	130.714
2917.51	136.573
2920.13	142.118
2922.74	146.749
2925.35	151.242
2927.97	154.006
2930.58	156.131
2933.19	156.379
2935.8	155.289
2938.41	154.358
2941.02	152.247
2943.63	148.997
2946.24	144.973
2948.84	140.006
2951.45	134.479
2954.05	128.944
2956.65	123.114
2959.26	117.011
2961.86	110.23
2964.46	103.94
2967.06	98.3029
2969.66	92.2433
2972.25	86.55
2974.85	81.4596
2977.45	74.9848
2980.04	68.86
2982.64	62.7502
2985.23	56.8433
2987.82	50.9061
2990.41	44.4723
2993	39.4525
2995.59	33.9929
2998.18	29.6533
3000.77	25.6548
3003.36	21.9505
3005.94	18.4953
3008.53	14.7791
3011.11	12.2124
3013.69	10.1649
3016.28	8.98907
3018.86	7.63136
3021.44	6.44181
3024.02	5.47317
3026.6	5.13204
3029.18	4.63033
3031.75	5.14728
3034.33	5.1576
3036.9	5.55372
3039.48	5.66394
3042.05	5.63402
3044.62	5.56712
3047.19	5.32549
3049.77	4.9177
3052.34	4.54399
3054.9	5.3839
3057.47	5.42316
3060.04	5.12386
3062.61	5.66281
3065.17	5.18087
3067.74	5.9014
3070.3	5.95251
3072.86	6.02024
3075.42	5.77707
3077.99	5.81256
3080.54	4.40869
3083.1	3.88137
3085.66	3.42362
3088.22	3.89819
3090.78	4.438
3093.33	4.07416
3095.89	4.03153
3098.44	3.57345
3100.99	3.5294
3103.54	3.18132
3106.1	3.17296
3108.65	3.41058
3111.2	3.51904
3113.74	4.18028
3116.29	4.99993
3118.84	5.726
3121.38	6.46582
3123.93	8.27448
3126.47	10.3883
3129.01	11.0743
3131.56	12.7563
3134.1	13.8869
3136.64	15.3398
3139.18	16.2565
3141.72	18.7596
3144.26	21.1772
3146.79	24.1715
3149.33	24.945