File: data/Raman/poly_smoothed/Thy_10_08_45_1x_45s_532 nm_x100_100%_600 gr_mm_01.txt
#Acq. time (s)=	45
#Accumulations=	2
#Range (cm-¹)=	200...3150
#Windows=	2
#Auto scanning=	Off
#Autofocus=	Off
#Macrospot=	Off
#AutoExposure=	Off
#Spike filter=	Multiple accum.
#Delay time (s)=	0
#Binning=	1
#Readout mode=	Signal
#DeNoise=	Off
#ICS correction=	On
#Dark correction=	Off
#Inst. Process=	Off
#Detector Gain=	Best Dynamic Range
#Detector ADC=	20 kHz
#Detector temperature (°C)=	-69.85
#Instrument=	LabRAM HR Evol
#Detector=	Synapse
#Objective=	x100
#Grating=	600 gr/mm
#ND Filter=	100%
#Laser (nm)=	532
#Hole=	100.021
#Range=	Auto
#Laser Pol.=	No
#Raman. Pol.=	No
#Laser Pol. (°)=	-0.0007625
#Raman Pol. (°)=	89.9995
#Collection=	Microscope
#StageXY=	Marzhauser
#StageZ=	Marzhauser
#X (µm)=	-2358.5
#Y (µm)=	242.2
#Z (µm)=	521.7
#Full time(mm:ss)=	3:18
#Project=
#Sample=
#Site=
#Title=	Thy_10_08_45_2x_45s_532 nm_x100_100%_600 gr_mm
#Remark=
#Date=	06.07.2022 15:01
#Acquired=	06.07.2022 15:01:59
#Base:Fit=	10.08.2022 09:46:25
#Base:Sub=	10.08.2022 09:46:49
#Filter:Polynom=	16.08.2022 10:24:56
#AxisType[0]=Intens
#AxisUnit[0]=Cnt
#AxisType[1]=Spectr
#AxisUnit[1]=1/cm
200.398	32.1954
204.027	28.3068
207.657	22.9343
211.283	19.1291
214.909	15.7376
218.533	12.8303
222.157	12.0481
225.777	10.7546
229.396	9.18754
233.016	7.20333
236.632	6.00112
240.247	4.9345
243.86	3.90948
247.474	3.44079
251.085	2.53312
254.694	1.97267
258.301	1.49266
261.908	2.03927
265.513	2.49529
269.116	2.23037
272.718	2.13481
276.319	0.843979
279.918	1.00441
283.516	2.02444
287.113	2.93063
290.708	3.7422
294.302	4.81311
297.894	7.92732
301.485	9.38847
305.073	10.059
308.661	11.9137
312.247	13.5498
315.833	13.5116
319.415	13.6837
322.997	13.328
326.579	14.2514
330.156	13.7407
333.735	14.0341
337.31	14.3537
340.885	14.2137
344.458	12.8284
348.03	10.9556
351.6	8.04225
355.17	5.44141
358.737	4.47495
362.304	4.79031
365.868	4.6176
369.431	5.7916
372.994	5.67085
376.554	7.22736
380.112	6.33172
383.669	7.00608
387.225	7.97678
390.781	8.11858
394.334	9.3526
397.885	10.9052
401.436	10.3424
404.984	10.2471
408.532	11.1504
412.078	11.6306
415.623	12.6973
419.166	13.6254
422.708	14.2176
426.248	12.6497
429.788	11.0868
433.326	9.3376
436.86	9.87434
440.395	8.62579
443.929	8.61111
447.461	8.6201
450.99	9.99797
454.52	8.98589
458.048	7.35417
461.573	7.21586
465.099	7.66586
468.623	8.60898
472.144	11.0236
475.666	12.7228
479.184	13.6597
482.703	15.4204
486.218	15.5965
489.734	16.0657
493.247	18.0911
496.759	18.6491
500.271	19.5555
503.779	20.4462
507.287	21.0728
510.795	19.9888
514.299	19.6122
517.803	19.4574
521.305	19.1447
524.805	18.4039
528.307	16.2245
531.805	15.8406
535.301	15.4308
538.797	14.0538
542.291	12.0791
545.783	11.5887
549.275	13.0717
552.765	13.3913
556.253	11.9188
559.738	11.4322
563.224	12.0217
566.709	10.5815
570.192	7.59009
573.674	7.48325
577.153	7.22221
580.632	5.71688
584.11	6.82994
587.587	6.55515
591.06	4.52582
594.534	3.41958
598.005	2.57575
601.476	4.11101
604.944	3.694
608.413	4.20429
611.878	4.97387
615.344	5.55619
618.807	5.46981
622.27	6.27028
625.73	6.08538
629.189	7.78246
632.648	8.55345
636.105	9.62694
639.559	10.4365
643.013	12.6971
646.467	14.8699
649.918	15.5299
653.368	16.4364
656.816	16.7725
660.263	18.1963
663.708	18.9954
667.153	20.3754
670.596	21.2422
674.037	20.4333
677.478	21.3044
680.917	22.6948
684.355	25.1252
687.791	27.3811
691.224	27.1331
694.658	27.9949
698.091	27.8501
701.522	28.2329
704.95	28.7577
708.379	30.0771
711.806	32.1889
715.23	34.0992
718.655	37.3004
722.078	39.8199
725.498	42.7845
728.919	46.4609
732.337	47.6389
735.755	51.0689
739.17	53.8159
742.584	54.6225
745.998	56.3723
749.409	58.3098
752.819	60.6706
756.23	63.967
759.637	65.8827
763.043	69.3701
766.448	72.601
769.853	75.2795
773.255	77.1965
776.656	79.1092
780.056	79.543
783.454	81.8991
786.851	82.7018
790.247	85.2167
793.641	87.8011
797.034	89.6763
800.426	89.3909
803.817	91.1446
807.206	90.79
810.592	90.9707
813.979	90.5132
817.364	90.496
820.748	89.6513
824.129	86.698
827.511	84.4384
830.891	82.8328
834.269	81.0388
837.646	79.2861
841.023	77.5393
844.396	76.3694
847.77	74.5145
851.141	72.7067
854.513	69.492
857.881	66.448
861.248	64.652
864.616	63.9851
867.98	61.8018
871.343	60.131
874.707	61.1095
878.068	60.3757
881.428	58.4853
884.786	56.3858
888.143	55.759
891.498	55.1901
894.855	54.7821
898.208	55.3369
901.56	53.7828
904.91	53.029
908.26	52.0877
911.608	51.2094
914.955	49.7709
918.298	49.4965
921.643	49.253
924.986	49.3219
928.328	51.178
931.668	50.1025
935.006	51.7044
938.344	51.2575
941.681	50.898
945.014	51.1975
948.349	51.5865
951.682	51.0937
955.012	52.2195
958.343	48.9231
961.67	47.2206
964.998	48.4594
968.323	50.5665
971.649	51.6077
974.971	51.6131
978.293	50.6612
981.615	48.3192
984.933	45.4555
988.251	43.0647
991.567	41.0107
994.884	39.1348
998.198	38.1281
1001.51	37.7249
1004.82	37.3809
1008.13	37.9018
1011.44	37.1582
1014.75	36.3769
1018.06	36.1456
1021.36	33.3961
1024.66	33.4749
1027.97	32.6932
1031.27	31.7595
1034.57	29.4838
1037.87	27.1562
1041.16	26.9752
1044.46	28.8894
1047.76	28.2354
1051.05	26.5546
1054.34	25.8101
1057.63	24.2412
1060.92	23.3344
1064.21	22.6267
1067.5	22.1776
1070.78	21.3564
1074.07	21.0689
1077.35	21.5148
1080.63	22.1196
1083.91	21.8531
1087.19	21.2215
1090.47	22.6348
1093.75	22.9665
1097.03	23.1953
1100.3	23.1168
1103.57	22.8861
1106.84	24.1113
1110.11	22.1919
1113.38	20.7342
1116.65	17.6151
1119.92	17.25
1123.19	16.1869
1126.45	16.1677
1129.71	15.2704
1132.97	14.9644
1136.23	14.3893
1139.49	14.4889
1142.75	12.8961
1146.01	12.3239
1149.26	11.3727
1152.52	10.4767
1155.77	8.20482
1159.02	8.14249
1162.27	5.7258
1165.52	5.49535
1168.77	6.01025
1172.02	6.53109
1175.26	8.2847
1178.51	10.2412
1181.75	11.941
1184.99	12.9029
1188.23	14.438
1191.47	15.1335
1194.71	17.8298
1197.94	20.4296
1201.18	24.4615
1204.41	28.2582
1207.65	30.2401
1210.88	33.5921
1214.11	37.0286
1217.34	40.5053
1220.57	43.1642
1223.79	46.0166
1227.02	48.6429
1230.24	49.2081
1233.47	49.8967
1236.69	50.1188
1239.91	51.2888
1243.13	51.7936
1246.34	52.4976
1249.56	53.7299
1252.78	54.1808
1255.99	53.7276
1259.2	54.8562
1262.42	55.1131
1265.63	55.1728
1268.84	57.2198
1272.04	57.0339
1275.25	58.0038
1278.46	60.0445
1281.66	61.2093
1284.86	63.6453
1288.07	65.1642
1291.27	67.2433
1294.47	68.0701
1297.66	68.8141
1300.86	69.3161
1304.06	69.6073
1307.25	70.9868
1310.44	72.8332
1313.64	74.2866
1316.83	73.9689
1320.02	73.7816
1323.2	73.1003
1326.39	71.423
1329.58	71.197
1332.76	69.3741
1335.95	68.5432
1339.13	67.9435
1342.31	67.5999
1345.49	64.9738
1348.67	63.5339
1351.85	60.478
1355.02	59.4197
1358.2	55.969
1361.37	52.3061
1364.54	49.3549
1367.71	45.5149
1370.88	42.8808
1374.05	39.8264
1377.22	37.4406
1380.39	35.1479
1383.55	36.023
1386.72	35.3322
1389.88	33.3094
1393.04	31.3087
1396.2	30.2118
1399.36	29.4349
1402.52	30.114
1405.68	30.9335
1408.83	33.2861
1411.98	37.5637
1415.14	41.6795
1418.29	46.1425
1421.44	50.1587
1424.59	55.5327
1427.74	61.658
1430.89	66.9123
1434.03	71.942
1437.18	76.0926
1440.32	79.4568
1443.46	81.5252
1446.6	84.0834
1449.74	84.9492
1452.88	83.829
1456.02	81.605
1459.16	78.327
1462.29	73.5086
1465.43	66.7463
1468.56	60.7407
1471.69	53.3444
1474.82	46.9604
1477.95	41.1313
1481.08	35.0974
1484.2	28.6601
1487.33	24.3193
1490.46	19.4953
1493.58	15.5883
1496.7	12.6247
1499.82	10.4368
1502.94	9.33121
1506.06	8.17425
1509.18	7.48055
1512.29	7.15934
1515.41	8.29345
1518.52	10.2629
1521.63	11.7951
1524.75	13.6051
1527.85	14.6799
1530.96	14.9204
1534.07	15.6193
1537.18	15.9489
1540.28	17.4769
1543.39	19.6319
1546.49	21.9353
1549.59	25.7961
1552.69	29.0092
1555.79	31.858
1558.89	35.1845
1561.99	37.2945
1565.08	39.7971
1568.18	42.8479
1571.27	45.5243
1574.37	47.5312
1577.46	49.9468
1580.55	51.5863
1583.64	54.8112
1586.73	57.0592
1589.81	59.3282
1592.9	61.6727
1595.98	61.7938
1599.06	62.0867
1602.15	60.9799
1605.23	59.9609
1608.31	58.1177
1611.39	56.6916
1614.46	55.79
1617.54	54.9286
1620.61	54.4025
1623.69	55.5444
1626.76	57.8892
1629.83	58.5112
1632.9	59.8626
1635.97	61.9478
1639.04	64.6486
1642.11	67.6515
1645.17	68.0628
1648.24	69.9214
1651.3	70.5332
1654.36	72.186
1657.42	73.1947
1660.48	72.9716
1663.54	71.8904
1666.6	70.9721
1669.66	68.6147
1672.71	65.0917
1675.77	60.9562
1678.82	56.7101
1681.87	50.6574
1684.92	45.0598
1687.97	41.1053
1691.02	35.7485
1694.07	31.6325
1697.11	28.1157
1700.16	24.9049
1703.2	20.8151
1706.25	17.6792
1709.29	15.9067
1712.33	14.4612
1715.37	12.1682
1718.41	11.4061
1721.44	11.3432
1724.48	11.087
1727.51	10.337
1730.55	9.87231
1733.58	9.72728
1736.61	9.92531
1739.64	9.59973
1742.67	9.56658
1745.7	8.89986
1748.72	7.84194
1751.75	6.82836
1754.77	5.89246
1757.8	4.81502
1760.82	3.56402
1763.84	3.20395
1766.86	1.53724
1769.88	0.580988
1772.9	-0.527001
1775.91	-1.91439
1778.93	-2.11007
1781.94	-1.81985
1784.96	-1.36337
1787.97	-0.982202
1790.98	-0.333025
1793.99	0.619172
1797	1.09529
1800.01	1.02099
1803.01	1.19801
1806.02	1.88713
1809.02	1.66408
1812.02	1.72073
1815.02	2.03637
1818.03	2.33736
1821.02	2.08418
1824.02	2.53112
1827.02	2.90568
1830.02	2.62801
1833.01	1.75911
1836.01	1.68461
1839	2.53551
1841.99	1.43829
1844.98	1.28884
1847.97	1.1705
1850.96	1.61616
1853.95	2.44353
1856.93	3.6435
1859.92	3.24712
1862.9	3.76486
1865.88	4.95003
1868.87	6.2957
1871.85	6.99201
1874.83	7.22502
1877.81	7.29313
1880.78	7.43898
1882.53	7.77799
1885.52	8.85295
1888.51	9.3226
1891.5	9.05289
1894.48	9.6484
1897.47	9.95439
1900.45	10.306
1903.43	9.72604
1906.41	9.59666
1909.39	9.59996
1912.37	9.04482
1915.35	9.05249
1918.33	8.88286
1921.3	8.07428
1924.28	8.33878
1927.25	7.89805
1930.22	6.70491
1933.19	6.79263
1936.16	6.94002
1939.13	7.30436
1942.1	7.51067
1945.07	6.93706
1948.03	5.94802
1951	5.75596
1953.96	6.22575
1956.92	5.76753
1959.88	5.16442
1962.84	5.16584
1965.8	5.91899
1968.76	5.88063
1971.72	6.91646
1974.67	7.35269
1977.63	7.75807
1980.58	8.91738
1983.54	9.64237
1986.49	10.4284
1989.44	11.3249
1992.39	10.8408
1995.33	11.3785
1998.28	12.5055
2001.23	12.8832
2004.17	13.6941
2007.12	14.8143
2010.06	14.8768
2013	14.5766
2015.94	15.1031
2018.88	16.0638
2021.82	16.0129
2024.76	16.0163
2027.69	14.9646
2030.63	14.692
2033.56	15.5108
2036.5	15.8547
2039.43	15.6891
2042.36	15.2406
2045.29	15.5948
2048.22	15.4384
2051.15	15.2163
2054.07	15.766
2057	15.2033
2059.92	15.62
2062.85	15.5913
2065.77	16.2112
2068.69	16.8969
2071.61	17.5235
2074.53	17.3299
2077.45	17.6422
2080.37	17.8757
2083.28	17.6376
2086.2	18.5279
2089.11	19.321
2092.02	19.0173
2094.94	18.9299
2097.85	19.3652
2100.76	19.0314
2103.66	19.8661
2106.57	19.9075
2109.48	20.2901
2112.38	20.6256
2115.29	20.9148
2118.19	21.3335
2121.09	21.5392
2123.99	22.6199
2126.89	23.6389
2129.79	24.4461
2132.69	25.4407
2135.59	25.9648
2138.48	26.8697
2141.38	27.476
2144.27	28.1411
2147.17	28.8471
2150.06	28.9944
2152.95	30.4137
2155.84	30.8949
2158.73	32.0119
2161.61	32.198
2164.5	32.4674
2167.38	32.4429
2170.27	32.4076
2173.15	32.2171
2176.03	32.7937
2178.91	33.3867
2181.8	34.1853
2184.67	33.8129
2187.55	33.152
2190.43	32.9383
2193.3	32.8974
2196.18	32.0452
2199.05	31.5709
2201.93	30.3711
2204.8	29.129
2207.67	27.8992
2210.54	26.5639
2213.41	25.1488
2216.27	22.7406
2219.14	22.7962
2222.01	22.6626
2224.87	21.027
2227.73	19.6951
2230.6	18.6804
2233.46	17.2838
2236.32	17.7232
2239.18	17.4075
2242.03	17.491
2244.89	17.3322
2247.75	17.9524
2250.6	17.9016
2253.46	17.9149
2256.31	17.4962
2259.16	17.8191
2262.01	17.834
2264.86	18.1729
2267.71	18.919
2270.56	18.8052
2273.4	18.469
2276.25	17.5048
2279.09	15.8646
2281.94	15.7404
2284.78	14.7788
2287.62	14.2688
2290.46	14.052
2293.3	12.5205
2296.14	12.5179
2298.98	13.0466
2301.82	14.1421
2304.65	15.186
2307.49	15.5919
2310.32	15.8579
2313.15	15.3572
2315.98	15.3874
2318.81	14.9525
2321.64	14.8743
2324.47	14.6713
2327.3	14.0631
2330.12	12.7683
2332.95	12.4436
2335.77	12.8636
2338.6	13.3788
2341.42	12.2761
2344.24	11.9985
2347.06	11.1533
2349.88	9.72651
2352.7	8.16497
2355.51	7.13316
2358.33	6.85293
2361.14	5.5351
2363.96	6.34745
2366.77	7.77666
2369.58	7.49586
2372.39	7.97706
2375.2	7.80989
2378.01	8.08039
2380.82	7.67843
2383.63	6.24278
2386.43	6.27221
2389.24	6.57719
2392.04	5.55866
2394.84	4.87066
2397.65	4.04718
2400.45	3.59276
2403.25	4.13554
2406.05	4.8494
2408.84	4.60926
2411.64	4.59354
2414.44	5.08441
2417.23	5.24018
2420.02	4.87994
2422.82	4.98473
2425.61	5.90481
2428.4	5.64836
2431.19	5.97133
2433.98	6.81181
2436.77	7.29968
2439.55	7.20468
2442.34	7.5386
2445.12	8.11389
2447.91	8.19553
2450.69	7.53493
2453.47	8.10221
2456.25	7.42683
2459.03	7.04836
2461.81	6.36139
2464.59	6.10423
2467.36	5.91945
2470.14	5.42917
2472.92	4.6705
2475.69	4.74233
2478.46	4.83258
2481.23	4.2674
2484	4.66123
2486.77	3.88643
2489.54	3.44486
2492.31	2.82577
2495.08	2.39814
2497.84	1.68466
2500.61	1.84972
2503.37	1.4509
2506.13	0.407236
2508.9	0.180462
2511.66	0.891207
2514.42	0.438282
2517.18	0.484931
2519.93	0.629384
2522.69	0.45473
2525.45	1.09404
2528.2	2.1104
2530.95	2.26907
2533.71	3.53855
2536.46	3.94921
2539.21	4.2152
2541.96	4.20948
2544.71	4.68165
2547.46	3.75347
2550.2	4.43799
2552.95	4.95062
2555.7	5.66919
2558.44	5.52234
2561.18	4.98225
2563.93	5.14749
2566.67	4.95908
2569.41	5.09623
2572.15	4.0906
2574.88	3.29759
2577.62	3.97846
2580.36	3.04708
2583.09	3.15471
2585.83	3.57325
2588.56	3.27222
2591.29	3.28832
2594.02	3.00868
2596.75	3.28431
2599.48	2.96371
2602.21	1.50556
2604.94	0.716432
2607.67	-0.326683
2610.39	-0.549376
2613.12	-1.54021
2615.84	-0.974463
2618.56	-0.304477
2621.28	0.476046
2624.01	-0.372148
2626.72	-1.13575
2629.44	-0.675675
2632.16	-0.872158
2634.88	-1.17651
2637.59	0.298248
2640.31	0.969328
2643.02	1.59703
2645.74	2.29537
2648.45	2.05127
2651.16	3.46214
2653.87	3.40351
2656.58	3.63786
2659.29	4.50928
2661.99	4.63844
2664.7	5.32489
2667.41	5.02913
2670.11	4.99693
2672.81	5.47313
2675.51	4.82263
2678.22	5.21024
2680.92	5.8358
2683.62	5.8841
2686.31	5.29068
2689.01	3.99084
2691.71	3.31827
2694.4	2.94342
2697.1	3.17602
2699.79	3.13382
2702.49	3.50782
2705.18	4.29412
2707.87	4.82004
2710.56	5.67843
2713.25	6.73883
2715.94	7.79907
2718.62	7.80259
2721.31	8.59375
2723.99	8.7923
2726.68	9.53769
2729.36	9.2839
2732.04	9.48109
2734.73	9.34389
2737.41	8.45898
2740.08	7.99287
2742.76	7.24193
2745.44	6.61374
2748.12	5.30168
2750.79	3.44123
2753.47	2.48537
2756.14	2.67792
2758.81	2.56354
2761.49	2.17394
2764.16	1.57957
2766.83	2.15777
2769.5	2.49081
2772.16	3.28877
2774.83	3.637
2777.5	4.06673
2780.16	3.19539
2782.83	3.21246
2785.49	3.18897
2788.15	3.24571
2790.82	2.9511
2793.48	3.17718
2796.14	2.95621
2798.79	2.68112
2801.45	2.47097
2804.11	1.63766
2806.76	2.06756
2809.42	1.63931
2812.07	1.19742
2814.73	0.975439
2817.38	1.79065
2820.03	3.81378
2822.68	5.38956
2825.33	7.43836
2827.98	11.3578
2830.63	14.4327
2833.27	18.5411
2835.92	22.0563
2838.56	26.3722
2841.21	31.8307
2843.85	37.3075
2846.49	44.0919
2849.13	51.146
2851.77	58.675
2854.41	65.5934
2857.05	72.2342
2859.69	78.9803
2862.32	86.4277
2864.96	92.4788
2867.59	98.1847
2870.23	103.676
2872.86	107.54
2875.49	110.11
2878.12	113.482
2880.75	115.667
2883.38	119.157
2886.01	123.556
2888.63	127.256
2891.26	132.668
2893.89	135.942
2896.51	140.934
2899.13	145.898
2901.76	152.127
2904.38	158.923
2907	167.295
2909.62	175.59
2912.24	184.254
2914.85	193.407
2917.47	202.405
2920.09	209.923
2922.7	215.956
2925.32	221.493
2927.93	224.362
2930.54	225.387
2933.15	225.413
2935.76	222.633
2938.37	217.334
2940.98	212.346
2943.59	205.738
2946.2	199.265
2948.8	193.772
2951.41	187.455
2954.01	179.423
2956.62	172.012
2959.22	165.219
2961.82	157.438
2964.42	149.422
2967.02	142.004
2969.62	135.216
2972.22	128.91
2974.81	122.613
2977.41	116.807
2980	110.866
2982.6	104.616
2985.19	97.5956
2987.78	90.6063
2990.38	83.4998
2992.97	75.6299
2995.56	68.2623
2998.14	60.888
3000.73	53.6848
3003.32	47.1214
3005.91	41.9262
3008.49	36.5428
3011.07	33.4108
3013.66	29.924
3016.24	27.0464
3018.82	24.1951
3021.4	23.1774
3023.98	20.7755
3026.56	18.9829
3029.14	16.9613
3031.71	16.9582
3034.29	16.2803
3036.87	16.8387
3039.44	17.7203
3042.01	18.3953
3044.59	19.7138
3047.16	20.9372
3049.73	21.5591
3052.3	22.4709
3054.87	22.7049
3057.43	22.2818
3060	21.979
3062.57	21.2278
3065.13	20.1422
3067.7	19.6725
3070.26	18.1519
3072.82	17.4449
3075.39	16.4405
3077.95	15.3665
3080.51	13.7533
3083.07	11.3268
3085.63	9.92799
3088.18	6.81549
3090.74	5.1091
3093.29	3.84088
3095.85	3.0201
3098.4	2.15311
3100.95	2.02032
3103.51	1.79919
3106.06	1.95312
3108.61	2.68523
3111.16	2.64217
3113.71	3.19993
3116.25	2.65408
3118.8	2.5384
3121.35	2.41833
3123.89	2.85102
3126.44	3.49896
3128.98	4.09515
3131.52	4.60927
3134.06	3.58084
3136.6	3.48368
3139.14	2.75202
3141.68	1.72743
3144.22	0.875899
3146.76	0.635934
3149.29	0.634695