File: data/Raman/poly_smoothed/Thy_40_11_22_1x_45s_532 nm_x100_100%_600 gr_mm_01.txt
#Acq. time (s)=	45
#Accumulations=	2
#Range (cm-¹)=	200...3150
#Windows=	2
#Auto scanning=	Off
#Autofocus=	Off
#Macrospot=	Off
#AutoExposure=	Off
#Spike filter=	Multiple accum.
#Delay time (s)=	0
#Binning=	1
#Readout mode=	Signal
#DeNoise=	Off
#ICS correction=	On
#Dark correction=	Off
#Inst. Process=	Off
#Detector Gain=	Best Dynamic Range
#Detector ADC=	20 kHz
#Detector temperature (°C)=	-69.85
#Instrument=	LabRAM HR Evol
#Detector=	Synapse
#Objective=	x100
#Grating=	600 gr/mm
#ND Filter=	100%
#Laser (nm)=	532
#Hole=	100.021
#Range=	Auto
#Laser Pol.=	No
#Raman. Pol.=	No
#Laser Pol. (°)=	-0.0007625
#Raman Pol. (°)=	89.9995
#Collection=	Microscope
#StageXY=	Marzhauser
#StageZ=	Marzhauser
#X (µm)=	1961.4
#Y (µm)=	-44.4
#Z (µm)=	425.15
#Full time(mm:ss)=	3:18
#Project=
#Sample=
#Site=
#Title=	Thy_40_11_22_2x_45s_532 nm_x100_100%_600 gr_mm
#Remark=
#Date=	05.07.2022 11:25
#Acquired=	05.07.2022 11:25:23
#Base:Fit=	10.08.2022 10:01:35
#Base:Sub=	10.08.2022 10:01:52
#Filter:Polynom=	16.08.2022 10:21:53
#AxisType[0]=Intens
#AxisUnit[0]=Cnt
#AxisType[1]=Spectr
#AxisUnit[1]=1/cm
200.43	23.7842
204.059	17.4911
207.688	14.127
211.314	10.6803
214.941	8.2196
218.564	6.84867
222.186	6.14579
225.809	6.39839
229.428	5.69785
233.045	4.04104
236.663	4.63604
240.278	4.77383
243.891	4.13995
247.503	3.00169
251.116	3.4271
254.725	4.48511
258.333	4.29612
261.939	5.39473
265.544	4.93444
269.148	5.53546
272.75	6.57381
276.351	5.20103
279.95	6.00756
283.548	7.2958
287.144	7.83515
290.739	7.98308
294.333	8.26675
297.925	6.797
301.514	6.32316
305.104	7.13804
308.692	7.59882
312.279	8.15568
315.862	6.01108
319.446	5.74808
323.029	5.97143
326.608	6.2239
330.188	4.85698
333.766	4.33889
337.341	6.25556
340.917	6.25428
344.489	6.93361
348.062	6.48142
351.631	6.80661
355.201	7.03684
358.768	7.15265
362.333	7.70946
365.899	7.76045
369.462	7.64339
373.023	8.75893
376.585	9.64138
380.143	10.5489
383.7	9.62272
387.256	11.4255
390.812	11.4044
394.365	11.8102
397.916	11.9332
401.467	11.267
405.015	10.9135
408.563	11.181
412.109	11.1837
415.654	10.5818
419.197	10.268
422.739	9.91294
426.279	9.33621
429.819	7.9515
433.356	5.24818
436.891	4.49211
440.426	1.8283
443.96	0.790241
447.492	0.632014
451.021	0.676354
454.551	0.0370979
458.079	0.167716
461.604	2.68757
465.13	3.35817
468.654	4.80012
472.175	7.03321
475.696	8.44522
479.215	10.5181
482.733	12.6766
486.249	14.5825
489.765	17.1586
493.278	20.2423
496.789	22.8076
500.301	25.9236
503.81	26.7955
507.317	27.2274
510.825	28.2923
514.33	28.4583
517.833	27.051
521.335	26.7211
524.836	25.2255
528.335	22.9545
531.835	20.6395
535.332	19.1942
538.827	17.3135
542.321	13.0775
545.814	12.4041
549.305	10.4065
552.795	8.26659
556.282	7.64764
559.769	7.64513
563.255	7.39466
566.739	8.37715
570.223	8.77906
573.705	9.39746
577.183	9.74233
580.663	11.3193
584.141	12.2484
587.615	10.9756
591.09	10.3426
594.564	10.0737
598.035	9.96384
601.506	9.53773
604.974	8.61551
608.443	8.35805
611.908	7.35236
615.374	6.17076
618.837	7.43653
622.3	7.22115
625.761	5.79353
629.219	6.7189
632.677	7.7425
636.135	8.93491
639.59	11.5573
643.043	14.3612
646.495	16.9757
649.948	19.0297
653.398	20.2318
656.846	21.3188
660.293	21.7418
663.738	22.1159
667.183	22.3554
670.626	21.9842
674.067	22.389
677.508	23.0205
680.947	23.605
684.385	23.4509
687.821	23.1976
691.254	23.6545
694.688	24.6872
698.121	23.5043
701.552	25.7805
704.98	27.3798
708.409	29.6111
711.836	31.5831
715.26	35.5954
718.685	38.1322
722.108	41.8934
725.528	43.8305
728.949	46.0528
732.367	47.2288
735.785	49.9812
739.2	51.4418
742.614	52.8017
746.028	56.0137
749.439	57.6045
752.849	59.2213
756.26	61.4346
759.667	63.131
763.073	63.6245
766.477	63.9777
769.883	63.9796
773.285	65.4008
776.686	67.1515
780.085	67.4227
783.484	69.2646
786.881	73.4704
790.276	76.6019
793.671	79.0806
797.064	80.7227
800.456	83.6501
803.846	84.3103
807.234	83.7049
810.622	82.6656
814.008	83.3977
817.394	84.204
820.778	83.3589
824.159	84.1845
827.541	82.2264
830.921	81.1791
834.298	79.1602
837.676	78.1174
841.051	74.8038
844.426	70.7434
847.798	66.7382
851.171	64.7178
854.54	61.1894
857.911	58.6178
861.278	56.4315
864.645	54.203
868.01	53.6145
871.373	52.6049
874.735	50.5115
878.097	49.9365
881.457	48.5719
884.815	47.7196
888.172	46.8976
891.528	45.395
894.882	44.8257
898.237	47.543
901.589	48.7703
904.94	48.081
908.289	49.2402
911.635	48.2823
914.982	48.2291
918.328	46.7607
921.672	46.3319
925.015	44.9831
928.357	45.0189
931.698	44.0016
935.035	42.3563
938.373	39.724
941.71	37.7571
945.044	34.662
948.378	33.4095
951.709	32.0213
955.041	31.388
958.372	31.1754
961.699	31.1453
965.027	30.741
968.352	30.5756
971.676	31.7253
975	32.6485
978.322	34.2796
981.642	35.6697
984.962	35.2265
988.28	35.1973
991.596	35.3744
994.911	35.505
998.227	35.5229
1001.54	34.3374
1004.85	33.1778
1008.16	33.1016
1011.47	32.3329
1014.78	30.9579
1018.08	30.6681
1021.39	30.9738
1024.69	28.7689
1028	28.5253
1031.3	28.2148
1034.6	27.5647
1037.9	26.8505
1041.19	24.8367
1044.49	24.6497
1047.78	22.7975
1051.08	23.607
1054.37	23.2984
1057.66	23.495
1060.95	22.7815
1064.24	21.222
1067.53	19.1658
1070.81	18.8312
1074.1	17.9628
1077.38	17.0218
1080.66	16.125
1083.94	15.8439
1087.22	15.8083
1090.5	15.7876
1093.78	16.0608
1097.05	16.8179
1100.33	18.325
1103.6	17.176
1106.87	16.0665
1110.14	14.0959
1113.41	14.395
1116.68	11.3698
1119.95	11.09
1123.21	11.4869
1126.48	12.1161
1129.74	12.4841
1133	12.8455
1136.26	11.7313
1139.52	10.5543
1142.78	9.51471
1146.04	8.61933
1149.29	8.03482
1152.55	6.9353
1155.8	7.07342
1159.05	6.89131
1162.3	5.64381
1165.55	4.64192
1168.8	2.14442
1172.05	3.04309
1175.29	3.18157
1178.54	3.19642
1181.78	2.6641
1185.02	1.85753
1188.26	1.42472
1191.5	1.12591
1194.74	1.12506
1197.97	3.17349
1201.21	6.89058
1204.44	9.04729
1207.68	12.2942
1210.91	14.0742
1214.14	17.3457
1217.37	21.0353
1220.59	24.3015
1223.82	28.2657
1227.05	31.3004
1230.27	33.5288
1233.49	36.2732
1236.72	38.4625
1239.94	39.7674
1243.16	43.0134
1246.37	45.4258
1249.59	47.26
1252.8	49.501
1256.02	50.32
1259.23	50.9983
1262.44	52.0084
1265.66	54.1018
1268.86	55.3351
1272.07	56.7488
1275.28	58.6581
1278.48	61.2587
1281.69	61.6945
1284.89	64.6336
1288.09	66.4034
1291.29	66.5557
1294.49	68.2676
1297.69	68.4003
1300.89	68.4169
1304.08	67.9548
1307.28	68.1245
1310.47	68.2001
1313.66	68.62
1316.85	68.2619
1320.04	66.7209
1323.23	66.3689
1326.42	62.9638
1329.61	61.0773
1332.79	59.4375
1335.97	58.4714
1339.16	56.5883
1342.34	55.0102
1345.52	53.9102
1348.7	50.8053
1351.87	47.9163
1355.05	46.2219
1358.22	42.9946
1361.4	42.6043
1364.57	41.4406
1367.74	39.2608
1370.91	37.1654
1374.08	35.4169
1377.25	34.5171
1380.41	34.6387
1383.58	35.2946
1386.74	35.3989
1389.91	34.7223
1393.07	32.0991
1396.23	30.7067
1399.39	29.7801
1402.55	29.7003
1405.7	29.3476
1408.86	30.8242
1412.01	30.4358
1415.17	31.1337
1418.32	34.0293
1421.47	38.1382
1424.62	42.8293
1427.77	46.192
1430.91	49.8144
1434.06	53.4408
1437.2	57.6602
1440.35	61.1161
1443.49	63.2058
1446.63	64.1295
1449.77	65.7008
1452.91	65.8883
1456.05	63.8875
1459.18	63.4266
1462.32	59.5629
1465.45	55.6186
1468.59	49.8815
1471.72	44.7272
1474.85	41.0538
1477.98	36.4106
1481.1	30.1499
1484.23	24.9429
1487.36	21.9813
1490.48	17.9378
1493.61	16.5662
1496.73	15.8805
1499.85	15.4856
1502.97	14.6304
1506.09	13.0217
1509.2	13.5208
1512.32	13.12
1515.43	12.0436
1518.55	12.9864
1521.66	14.3879
1524.77	16.6869
1527.88	19.1438
1530.99	21.256
1534.1	24.3651
1537.21	25.0159
1540.31	26.9331
1543.42	29.4779
1546.52	32.7439
1549.62	35.9158
1552.72	37.875
1555.82	41.2749
1558.92	42.4874
1562.02	43.6543
1565.11	45.3116
1568.21	46.9364
1571.3	49.7276
1574.39	50.54
1577.49	52.0291
1580.57	53.1117
1583.66	53.7392
1586.75	55.645
1589.84	55.8051
1592.92	57.0418
1596.01	58.9469
1599.09	59.4862
1602.17	61.1955
1605.25	60.4647
1608.33	59.6278
1611.41	60.3111
1614.49	60.1024
1617.57	61.5137
1620.64	61.8658
1623.72	61.6287
1626.79	62.526
1629.86	63.8099
1632.93	64.9051
1636	65.1391
1639.07	66.2522
1642.13	68.5629
1645.2	71.018
1648.26	70.7329
1651.33	71.9718
1654.39	72.4436
1657.45	72.2944
1660.51	73.3412
1663.57	72.9746
1666.63	71.2733
1669.68	69.2158
1672.74	65.0857
1675.79	59.8366
1678.85	55.7313
1681.9	50.2628
1684.95	46.1
1688	40.5106
1691.05	34.8229
1694.09	30.045
1697.14	26.015
1700.18	22.4505
1703.23	18.4466
1706.27	15.3444
1709.31	13.0445
1712.35	10.3072
1715.39	8.67457
1718.43	8.04785
1721.47	6.70407
1724.5	6.36108
1727.54	7.29791
1730.57	7.22972
1733.61	8.0218
1736.64	8.62243
1739.67	7.21596
1742.7	6.43449
1745.72	6.13171
1748.75	4.65261
1751.77	5.66813
1754.8	5.71601
1757.82	4.4051
1760.84	3.57391
1763.87	2.41544
1766.89	2.40278
1769.91	1.50454
1772.92	1.16787
1775.94	1.29603
1778.95	0.661263
1781.97	0.617538
1784.98	1.44501
1787.99	2.00272
1791.01	2.18238
1794.01	2.82301
1797.02	2.67283
1800.03	3.25574
1803.04	3.03877
1806.04	2.62914
1809.05	3.53901
1812.05	4.44868
1815.05	4.46267
1818.05	5.0336
1821.05	5.69101
1824.05	5.71086
1827.05	5.30606
1830.04	4.90186
1833.04	4.37891
1836.03	4.21074
1839.03	4.56382
1842.02	4.17282
1845.01	3.66375
1848	4.24127
1850.99	3.83866
1853.97	3.67436
1856.96	3.48535
1859.94	3.0152
1862.93	2.66926
1865.91	1.9071
1868.89	0.845071
1871.87	0.563514
1874.85	1.08981
1877.83	1.12636
1880.81	1.6992
1882.57	2.26726
1885.56	3.2053
1888.55	4.68764
1891.54	4.95323
1894.52	5.9574
1897.51	5.3025
1900.49	4.77907
1903.47	5.12025
1906.45	6.03107
1909.43	6.30523
1912.41	6.37274
1915.39	7.17932
1918.37	7.58051
1921.34	8.0385
1924.32	7.76714
1927.29	7.57719
1930.26	6.09028
1933.23	5.8797
1936.2	4.9615
1939.17	4.68959
1942.14	4.56726
1945.11	4.7474
1948.07	5.15108
1951.04	5.50932
1954	5.15641
1956.96	6.73711
1959.93	6.84297
1962.89	5.65274
1965.85	5.84034
1968.8	5.38291
1971.76	5.0451
1974.72	5.45277
1977.67	5.8375
1980.63	5.40247
1983.58	6.35111
1986.53	7.30579
1989.48	7.86366
1992.43	8.63359
1995.38	7.97967
1998.32	8.67227
2001.27	8.22827
2004.22	7.67841
2007.16	7.22536
2010.1	6.15936
2013.04	7.19026
2015.98	7.2146
2018.92	7.53678
2021.86	8.06129
2024.8	8.87918
2027.74	8.67984
2030.67	8.02269
2033.61	7.2616
2036.54	7.98795
2039.47	8.39205
2042.4	8.762
2045.33	8.93797
2048.26	9.37725
2051.19	10.3235
2054.12	11.0988
2057.04	11.6591
2059.97	12.2551
2062.89	13.0205
2065.81	14.5215
2068.73	15.7975
2071.65	15.5597
2074.57	16.1215
2077.49	16.7969
2080.41	18.6956
2083.32	20.8895
2086.24	22.6064
2089.15	23.7311
2092.07	24.3668
2094.98	24.9302
2097.89	26.1003
2100.8	26.5615
2103.71	27.9525
2106.61	28.7308
2109.52	30.9686
2112.43	32.2428
2115.33	33.0573
2118.23	35.0166
2121.13	37.5086
2124.04	39.6728
2126.94	42.7014
2129.83	46.3994
2132.73	50.3827
2135.63	54.134
2138.53	57.1809
2141.42	60.6461
2144.31	63.9569
2147.21	68.0697
2150.1	71.4423
2152.99	75.0199
2155.88	76.7798
2158.77	79.2747
2161.65	81.5259
2164.54	82.3471
2167.43	83.7821
2170.31	84.3803
2173.19	85.1073
2176.07	83.7526
2178.96	83.4886
2181.84	82.2445
2184.72	80.7788
2187.59	79.2153
2190.47	78.5632
2193.35	76.8066
2196.22	75.2387
2199.09	73.3751
2201.97	71.2458
2204.84	67.7392
2207.71	65.0486
2210.58	61.9842
2213.45	59.6176
2216.31	56.6557
2219.18	53.4794
2222.05	50.0107
2224.91	46.4411
2227.78	43.8263
2230.64	41.1575
2233.5	37.5598
2236.36	35.22
2239.22	32.7211
2242.08	30.2882
2244.93	28.4573
2247.79	26.8625
2250.64	26.2487
2253.5	23.9877
2256.35	22.8011
2259.2	21.5817
2262.05	21.0033
2264.9	20.5872
2267.75	20.1863
2270.6	20.3978
2273.45	19.437
2276.29	19.686
2279.14	19.6721
2281.98	17.7147
2284.82	16.098
2287.66	15.2025
2290.5	13.3665
2293.34	12.1424
2296.18	11.8335
2299.02	13.2357
2301.86	12.7226
2304.69	12.1247
2307.53	12.505
2310.36	11.8575
2313.19	13.18
2316.02	13.4452
2318.85	13.9682
2321.68	13.7375
2324.51	13.1571
2327.34	13.2233
2330.16	12.4175
2332.99	12.4667
2335.81	10.8484
2338.64	9.91735
2341.46	8.87259
2344.28	8.4548
2347.1	6.99808
2349.92	5.17952
2352.74	3.79432
2355.55	3.26808
2358.37	2.99383
2361.19	1.30736
2364	1.77919
2366.81	2.48105
2369.62	2.14702
2372.44	0.586325
2375.24	1.09282
2378.05	1.86498
2380.86	2.83569
2383.67	3.51921
2386.47	4.43807
2389.28	4.12408
2392.08	3.61932
2394.89	3.2625
2397.69	3.1083
2400.49	3.03486
2403.29	2.50768
2406.09	2.80034
2408.88	3.5776
2411.68	5.34496
2414.48	5.49766
2417.27	5.22757
2420.06	6.06429
2422.86	6.31326
2425.65	5.95093
2428.44	6.67529
2431.23	6.66573
2434.02	6.2145
2436.81	5.74057
2439.59	5.38609
2442.38	5.84014
2445.16	7.17569
2447.95	6.98508
2450.73	7.55685
2453.51	7.21755
2456.29	6.42613
2459.07	5.61552
2461.85	4.87731
2464.63	5.42284
2467.4	4.96196
2470.18	5.58119
2472.95	5.86641
2475.73	4.23175
2478.5	4.29046
2481.27	3.73261
2484.04	3.28054
2486.81	3.44555
2489.58	3.31891
2492.35	3.42632
2495.12	4.02863
2497.88	4.09645
2500.65	3.89124
2503.41	3.31811
2506.17	3.42044
2508.94	4.09827
2511.7	4.91958
2514.46	5.36661
2517.22	5.2049
2519.97	5.32195
2522.73	5.26357
2525.49	5.14501
2528.24	4.88585
2530.99	5.17743
2533.75	4.90013
2536.5	5.33151
2539.25	5.90281
2542	5.06377
2544.75	5.53085
2547.5	6.28874
2550.24	6.54077
2552.99	6.47549
2555.74	6.73126
2558.48	7.61801
2561.22	8.14361
2563.96	7.59373
2566.71	7.7134
2569.45	7.7194
2572.18	7.25922
2574.92	6.36499
2577.66	5.90229
2580.4	4.89958
2583.13	4.28283
2585.87	2.88295
2588.6	2.30396
2591.33	1.56234
2594.06	1.48204
2596.79	0.838259
2599.52	0.749974
2602.25	1.5066
2604.98	1.2597
2607.71	1.78677
2610.43	1.71065
2613.16	1.51583
2615.88	0.828484
2618.6	0.959084
2621.32	1.2549
2624.04	2.86202
2626.76	2.99279
2629.48	3.0176
2632.2	2.80672
2634.92	2.71267
2637.63	2.57611
2640.35	1.41826
2643.06	2.14743
2645.77	2.68468
2648.49	2.28203
2651.2	2.34449
2653.91	2.80329
2656.62	2.93024
2659.33	3.74164
2662.03	3.68362
2664.74	3.8377
2667.44	3.77722
2670.15	2.78291
2672.85	2.6621
2675.55	3.30332
2678.26	1.99858
2680.96	2.00332
2683.66	2.76732
2686.35	3.26038
2689.05	3.55697
2691.75	3.59657
2694.44	3.14647
2697.14	3.58116
2699.83	3.06743
2702.52	3.54174
2705.22	3.24824
2707.91	4.11409
2710.6	5.12496
2713.29	4.99736
2715.97	5.91199
2718.66	6.82449
2721.35	8.22243
2724.03	9.11484
2726.72	9.25771
2729.4	9.63761
2732.08	10.249
2734.76	9.13711
2737.44	8.92836
2740.12	9.38363
2742.8	8.59528
2745.48	8.00111
2748.16	8.53583
2750.83	8.15978
2753.51	6.32908
2756.18	6.33271
2758.85	5.24021
2761.53	4.11037
2764.2	3.03926
2766.87	2.00748
2769.54	1.88915
2772.2	0.760333
2774.87	0.498603
2777.54	0.521191
2780.2	0.247744
2782.87	0.87232
2785.53	0.767565
2788.19	0.806335
2790.85	0.859378
2793.51	1.30718
2796.17	0.67752
2798.83	0.377662
2801.49	-0.136598
2804.15	-0.405667
2806.8	-0.537003
2809.46	-0.773788
2812.11	-0.474319
2814.76	0.227485
2817.42	0.202562
2820.07	1.56184
2822.72	2.32619
2825.37	4.24532
2828.02	6.43014
2830.66	9.19415
2833.31	11.6171
2835.96	14.2403
2838.6	17.041
2841.24	21.3774
2843.89	25.7103
2846.53	31.0625
2849.17	36.994
2851.81	43.2093
2854.45	49.6539
2857.09	56.9535
2859.72	64.2813
2862.36	71.2614
2865	77.8088
2867.63	83.4625
2870.26	89.431
2872.9	95.2466
2875.53	98.9969
2878.16	102.957
2880.79	106.934
2883.42	110.851
2886.05	114.859
2888.67	118.542
2891.3	121.845
2893.92	123.989
2896.55	126.595
2899.17	130.491
2901.79	134.985
2904.42	141.139
2907.04	149.04
2909.66	158.133
2912.27	166.977
2914.89	176.858
2917.51	185.951
2920.13	194.143
2922.74	201.554
2925.35	207.52
2927.97	211.532
2930.58	214.292
2933.19	214.951
2935.8	213.952
2938.41	212.316
2941.02	208.101
2943.63	203.48
2946.24	198.387
2948.84	190.873
2951.45	183.202
2954.05	174.989
2956.65	166.228
2959.26	157.134
2961.86	150.232
2964.46	142.407
2967.06	134.174
2969.66	127.562
2972.25	120.83
2974.85	115.092
2977.45	107.958
2980.04	101.385
2982.64	92.66
2985.23	84.5424
2987.82	77.7269
2990.41	69.2539
2993	61.8848
2995.59	53.586
2998.18	46.3705
3000.77	39.7144
3003.36	33.8384
3005.94	28.3828
3008.53	23.5967
3011.11	18.8441
3013.69	15.0983
3016.28	12.9676
3018.86	10.8098
3021.44	8.93751
3024.02	7.77685
3026.6	7.15016
3029.18	5.79546
3031.75	5.94749
3034.33	6.7578
3036.9	7.42207
3039.48	8.78353
3042.05	9.57552
3044.62	10.0372
3047.19	11.4904
3049.77	12.3665
3052.34	12.8258
3054.9	13.9851
3057.47	13.5249
3060.04	13.396
3062.61	13.2411
3065.17	12.7784
3067.74	11.4802
3070.3	10.7184
3072.86	9.92556
3075.42	8.78006
3077.99	7.61906
3080.54	5.9144
3083.1	4.71045
3085.66	3.70003
3088.22	2.81904
3090.78	1.2805
3093.33	-0.414994
3095.89	-0.392251
3098.44	-1.114
3100.99	-0.966143
3103.54	-0.509194
3106.1	-0.727829
3108.65	0.168061
3111.2	1.90748
3113.74	2.67673
3116.29	3.57271
3118.84	4.72077
3121.38	5.22571
3123.93	6.72105
3126.47	8.70431
3129.01	9.10175
3131.56	10.6813
3134.1	12.7725
3136.64	13.794
3139.18	15.5595
3141.72	17.4711
3144.26	18.8596
3146.79	19.4457
3149.33	21.2794