File: data/Raman/poly_smoothed/Thy_50_12_07_1x_45s_532 nm_x100_100%_600 gr_mm_01.txt
#Acq. time (s)=	45
#Accumulations=	2
#Range (cm-¹)=	200...3150
#Windows=	2
#Auto scanning=	Off
#Autofocus=	Off
#Macrospot=	Off
#AutoExposure=	Off
#Spike filter=	Multiple accum.
#Delay time (s)=	0
#Binning=	1
#Readout mode=	Signal
#DeNoise=	Off
#ICS correction=	On
#Dark correction=	Off
#Inst. Process=	Off
#Detector Gain=	Best Dynamic Range
#Detector ADC=	20 kHz
#Detector temperature (°C)=	-69.85
#Instrument=	LabRAM HR Evol
#Detector=	Synapse
#Objective=	x100
#Grating=	600 gr/mm
#ND Filter=	100%
#Laser (nm)=	532
#Hole=	100.021
#Range=	Auto
#Laser Pol.=	No
#Raman. Pol.=	No
#Laser Pol. (°)=	-0.0007625
#Raman Pol. (°)=	89.9995
#Collection=	Microscope
#StageXY=	Marzhauser
#StageZ=	Marzhauser
#X (µm)=	-5108.9
#Y (µm)=	1501.7
#Z (µm)=	63.1
#Full time(mm:ss)=	3:18
#Project=
#Sample=
#Site=
#Title=	Thy_50_12_07_2x_45s_532 nm_x100_100%_600 gr_mm
#Remark=
#Date=	07.07.2022 09:44
#Acquired=	07.07.2022 09:44:53
#Base:Fit=	10.08.2022 10:03:08
#Base:Fit=	10.08.2022 10:03:15
#Base:Fit=	10.08.2022 10:03:19
#Base:Fit=	10.08.2022 10:04:29
#Base:Sub=	10.08.2022 10:04:45
#Filter:Polynom=	16.08.2022 10:20:24
#AxisType[0]=Intens
#AxisUnit[0]=Cnt
#AxisType[1]=Spectr
#AxisUnit[1]=1/cm
200.43	68.3583
204.061	59.3483
207.688	48.9726
211.316	39.4244
214.941	32.148
218.566	25.6547
222.188	22.2789
225.809	15.7865
229.43	12.6044
233.047	9.4371
236.663	7.08671
240.278	6.82436
243.894	7.2429
247.506	6.81729
251.116	5.81573
254.725	5.0349
258.333	7.93924
261.939	11.0047
265.546	11.1279
269.15	10.435
272.752	9.72873
276.353	11.6002
279.952	13.202
283.55	12.565
287.146	11.9897
290.739	12.8374
294.333	13.1808
297.925	14.3702
301.516	16.0619
305.106	17.2144
308.694	17.7308
312.279	17.6939
315.864	14.3537
319.448	15.2699
323.029	16.8028
326.61	17.8257
330.19	16.3372
333.766	16.0049
337.343	14.477
340.917	13.9435
344.491	13.8634
348.062	14.4694
351.633	13.4511
355.201	12.0778
358.77	10.3966
362.335	9.78989
365.899	8.86203
369.464	7.24291
373.025	6.5851
376.585	8.91608
380.143	10.0286
383.702	9.03519
387.258	8.60206
390.812	7.34112
394.365	6.90772
397.916	6.50939
401.467	5.83148
405.015	6.71089
408.565	8.34234
412.111	7.94577
415.656	8.36394
419.197	8.44281
422.739	9.59314
426.279	11.0898
429.819	13.1218
433.356	14.3148
436.893	14.5281
440.428	14.5242
443.96	15.511
447.492	16.9705
451.023	18.0801
454.553	19.3219
458.079	20.7978
461.606	21.1813
465.132	22.1313
468.654	23.7725
472.177	23.6961
475.696	26.1476
479.217	27.6867
482.733	30.1416
486.251	30.5716
489.765	30.8806
493.278	32.203
496.791	31.3146
500.301	31.0673
503.81	32.1291
507.319	32.059
510.825	34.3993
514.33	35.1691
517.833	35.5701
521.337	36.7869
524.838	36.8154
528.337	39.1999
531.835	37.9474
535.332	37.2893
538.827	37.2912
542.321	36.3911
545.814	35.8006
549.305	36.0318
552.795	35.0507
556.284	34.3113
559.771	32.5779
563.257	30.7503
566.742	27.0901
570.223	22.2298
573.705	18.5079
577.185	15.8512
580.665	13.6874
584.141	9.86426
587.617	9.19259
591.092	8.36212
594.564	6.51994
598.037	5.78632
601.506	6.99035
604.976	7.93882
608.443	9.18051
611.91	9.14052
615.374	8.98069
618.839	9.05339
622.3	8.23964
625.761	8.47373
629.221	10.4742
632.679	10.5576
636.135	11.3616
639.592	10.6302
643.045	12.4117
646.497	12.385
649.948	11.8754
653.398	11.464
656.846	11.4016
660.293	12.3378
663.738	11.818
667.185	12.021
670.628	11.8616
674.067	12.8404
677.508	14.2167
680.947	14.069
684.385	17.01
687.821	19.8589
691.256	21.7072
694.69	23.27
698.121	24.0522
701.552	26.319
704.982	29.3007
708.41	31.5915
711.836	35.0243
715.262	37.5402
718.685	39.377
722.108	42.1352
725.53	43.9373
728.949	46.4813
732.369	47.9828
735.785	48.7533
739.2	48.1976
742.616	49.7211
746.028	50.4402
749.441	50.8346
752.851	51.7359
756.26	53.3006
759.667	55.368
763.075	54.2859
766.479	56.4755
769.883	57.5372
773.285	59.7862
776.686	59.4488
780.085	60.2733
783.484	60.8619
786.881	62.4237
790.276	64.0752
793.671	64.7883
797.064	68.4943
800.456	70.9361
803.846	73.6957
807.236	74.3683
810.624	78.0598
814.01	79.943
817.394	81.6283
820.778	83.8155
824.161	85.8868
827.543	87.7947
830.921	87.465
834.3	87.3652
837.676	87.5651
841.053	87.0721
844.426	84.4751
847.8	83.7105
851.171	81.7818
854.542	79.0538
857.911	77.6579
861.279	76.6433
864.645	75.2897
868.01	73.2912
871.375	74.8766
874.737	73.1862
878.097	71.7838
881.457	70.3018
884.817	67.6195
888.174	66.3195
891.53	62.9042
894.884	61.5773
898.237	60.3087
901.589	58.5315
904.94	56.4049
908.289	53.3771
911.637	49.1325
914.984	46.2924
918.33	45.4163
921.674	42.4053
925.015	40.1167
928.357	37.5785
931.698	34.2855
935.037	30.2986
938.373	31.3894
941.71	31.6406
945.046	29.0753
948.378	28.8833
951.711	29.1386
955.043	30.9648
958.372	30.3609
961.701	29.6211
965.027	33.5977
968.354	38.3962
971.678	42.9062
975	44.9586
978.324	51.3148
981.644	54.8797
984.962	57.3981
988.282	60.3084
991.598	62.3214
994.913	65.5774
998.227	68.1276
1001.54	68.6623
1004.85	68.5477
1008.16	68.3684
1011.47	69.6734
1014.78	70.9847
1018.08	73.6335
1021.39	76.9701
1024.69	77.4366
1028	77.6903
1031.3	80.3301
1034.6	81.1354
1037.9	81.7098
1041.19	80.4663
1044.49	83.1006
1047.79	84.1019
1051.08	82.9903
1054.37	78.9232
1057.66	74.3517
1060.95	71.6308
1064.24	67.1399
1067.53	60.5821
1070.81	56.9373
1074.1	52.9073
1077.38	47.2922
1080.66	42.2369
1083.94	38.5128
1087.22	35.823
1090.5	35.4643
1093.78	35.1062
1097.05	36.9816
1100.33	38.083
1103.6	39.2855
1106.87	40.7894
1110.15	41.357
1113.41	41.148
1116.68	40.8691
1119.95	39.5325
1123.21	40.2878
1126.48	38.1145
1129.74	35.0698
1133	33.799
1136.26	31.4321
1139.52	28.508
1142.78	25.4736
1146.04	22.5936
1149.29	19.2924
1152.55	15.1278
1155.8	10.8341
1159.05	6.39513
1162.3	3.07647
1165.55	0.48351
1168.8	1.10751
1172.05	0.882781
1175.29	1.4156
1178.54	3.30331
1181.78	2.81169
1185.02	3.30297
1188.26	3.6831
1191.5	6.01298
1194.74	5.90898
1197.97	8.25426
1201.21	10.0976
1204.44	14.2992
1207.68	18.9648
1210.91	23.8534
1214.14	31.0754
1217.37	37.2096
1220.6	42.0823
1223.82	48.3531
1227.05	54.6954
1230.27	59.6074
1233.49	66.9864
1236.72	73.7212
1239.94	81.6343
1243.16	88.1288
1246.37	96.1431
1249.59	102.921
1252.8	108.509
1256.02	114.145
1259.23	120.794
1262.44	126.176
1265.66	132.972
1268.87	140.586
1272.07	145.493
1275.28	151.248
1278.48	156.777
1281.69	162.249
1284.89	167.321
1288.09	168.785
1291.3	170.823
1294.49	172.18
1297.69	170.616
1300.89	168.149
1304.09	167.033
1307.28	162.964
1310.47	160.915
1313.66	157.706
1316.86	154.112
1320.05	149.286
1323.23	144.451
1326.42	139.151
1329.61	132.283
1332.79	125.319
1335.98	119.807
1339.16	116.012
1342.34	110.267
1345.52	104.253
1348.7	99.2566
1351.87	93.3515
1355.05	89.3339
1358.23	83.2202
1361.4	78.753
1364.57	75.8432
1367.74	71.8718
1370.91	68.9265
1374.08	66.5258
1377.25	64.9689
1380.42	63.0211
1383.58	61.9344
1386.75	61.6705
1389.91	64.0315
1393.07	65.8396
1396.23	65.3594
1399.39	65.7465
1402.55	68.817
1405.7	72.2449
1408.86	77.113
1412.01	83.9491
1415.17	93.2569
1418.32	102.825
1421.47	113.885
1424.62	126.913
1427.77	142.181
1430.92	155.198
1434.06	167.53
1437.2	180.159
1440.35	191.166
1443.49	198.613
1446.63	202.907
1449.77	203.216
1452.91	201.663
1456.05	195.002
1459.18	186.695
1462.32	174.929
1465.45	161.803
1468.59	146.557
1471.72	130.729
1474.85	112.559
1477.98	97.2557
1481.11	82.0863
1484.23	66.7569
1487.36	56.2162
1490.48	46.8325
1493.61	39.179
1496.73	34.0782
1499.85	31.6234
1502.97	30.7059
1506.09	29.5018
1509.2	29.5312
1512.32	31.509
1515.44	33.9671
1518.55	37.4272
1521.66	40.2875
1524.77	44.6786
1527.88	48.1196
1530.99	51.4013
1534.1	54.2219
1537.21	57.5805
1540.31	61.433
1543.42	65.9763
1546.52	70.622
1549.62	73.9142
1552.72	77.0986
1555.82	80.8776
1558.92	83.9512
1562.02	86.8479
1565.11	90.35
1568.21	97.4654
1571.3	102.44
1574.39	106.901
1577.49	112.436
1580.58	116.866
1583.67	119.433
1586.75	124.502
1589.84	128.666
1592.93	132.041
1596.01	134.865
1599.09	135.662
1602.18	136.58
1605.26	134.965
1608.34	136.539
1611.41	136.069
1614.49	139.235
1617.57	140.468
1620.64	142.688
1623.72	144.758
1626.79	147.669
1629.86	151.536
1632.93	154.54
1636	160.26
1639.07	167.19
1642.14	176.089
1645.2	181.883
1648.27	186.718
1651.33	189.39
1654.39	191.92
1657.45	192.274
1660.51	191.187
1663.57	186.797
1666.63	181.468
1669.69	173.532
1672.74	162.454
1675.79	152.4
1678.85	139.819
1681.9	126.775
1684.95	114.265
1688	101.978
1691.05	90.0626
1694.1	79.2463
1697.14	68.7409
1700.19	58.6181
1703.23	50.9667
1706.27	44.1072
1709.32	39.24
1712.35	35.3405
1715.39	31.4628
1718.43	30.0539
1721.47	27.9468
1724.5	25.8301
1727.54	25.4711
1730.57	25.2226
1733.61	23.9732
1736.64	21.9055
1739.67	20.0387
1742.7	19.2364
1745.72	16.6985
1748.75	14.1111
1751.78	12.3815
1754.8	10.3099
1757.82	7.88797
1760.85	7.17812
1763.87	5.66527
1766.89	5.09625
1769.91	4.38624
1772.92	3.03165
1775.94	2.46608
1778.96	3.02239
1781.97	2.45156
1784.98	2.62722
1788	2.93939
1791.01	3.75454
1794.01	4.21816
1797.02	3.97901
1800.03	3.68311
1803.04	3.40523
1806.04	3.19975
1809.05	2.5814
1812.05	1.97023
1815.05	1.20929
1818.05	1.22208
1821.05	0.587521
1824.05	0.528763
1827.05	0.0309893
1830.04	-0.192397
1833.04	-0.016374
1836.03	-0.740251
1839.03	-0.0936406
1842.02	0.732593
1845.01	0.360885
1848	0.929278
1850.99	0.861862
1853.97	1.38813
1856.96	0.955722
1859.94	0.911814
1862.93	0.309509
1865.91	1.16644
1868.89	1.93754
1871.87	0.735812
1874.85	0.765819
1877.83	0.704058
1880.81	0.378536
1882.56	1.2334
1885.55	0.577445
1888.54	0.895994
1891.52	-0.349969
1894.51	0.263371
1897.49	0.277835
1900.48	0.332446
1903.46	1.2218
1906.44	1.85854
1909.42	2.1396
1912.4	1.93557
1915.38	1.81965
1918.35	1.48553
1921.33	1.60401
1924.3	0.958124
1927.28	1.82156
1930.25	1.47318
1933.22	2.40042
1936.19	2.4315
1939.16	3.08498
1942.13	2.50417
1945.09	1.64987
1948.06	1.7662
1951.03	2.59792
1953.99	2.50186
1956.95	1.05994
1959.91	0.532538
1962.87	0.162485
1965.83	0.600336
1968.79	0.279739
1971.75	-0.0809307
1974.7	0.290543
1977.66	1.44167
1980.61	1.14635
1983.56	0.39109
1986.52	1.03461
1989.47	1.48677
1992.41	0.755842
1995.36	0.839662
1998.31	2.16033
2001.26	3.47069
2004.2	4.09891
2007.15	4.89028
2010.09	5.38997
2013.03	5.74011
2015.97	4.12371
2018.91	3.26054
2021.85	3.9185
2024.79	4.7352
2027.72	3.84376
2030.66	4.45195
2033.59	5.60106
2036.53	6.51638
2039.46	6.45081
2042.39	8.16982
2045.32	9.67391
2048.25	11.5535
2051.18	12.8493
2054.1	14.7129
2057.03	16.4855
2059.95	17.6276
2062.88	20.1804
2065.8	22.8705
2068.72	26.6504
2071.64	30.6199
2074.56	33.5386
2077.48	36.592
2080.39	38.8148
2083.31	41.6142
2086.22	45.1203
2089.14	49.0287
2092.05	55.0238
2094.96	60.5857
2097.87	66.6045
2100.78	70.6623
2103.69	77.7513
2106.6	84.9867
2109.51	91.1572
2112.41	97.8325
2115.32	105.664
2118.22	112.629
2121.12	120.524
2124.02	127.44
2126.92	135.22
2129.82	144.59
2132.72	153.091
2135.62	159.869
2138.51	166.727
2141.41	173.177
2144.3	180.448
2147.19	185.507
2150.09	191.682
2152.97	197.414
2155.86	202.722
2158.75	208.235
2161.64	210.849
2164.53	214.748
2167.41	215.137
2170.3	215.758
2173.18	214.613
2176.06	213.152
2178.94	210.75
2181.82	207.259
2184.7	204.054
2187.58	199.412
2190.46	193.776
2193.33	187.104
2196.21	179.178
2199.08	171.468
2201.95	164.386
2204.83	156.158
2207.7	148.525
2210.57	140.653
2213.43	133.636
2216.3	125.224
2219.17	117.744
2222.03	110.918
2224.9	104.041
2227.76	98.5857
2230.62	92.5386
2233.49	86.1049
2236.34	82.0301
2239.2	76.9651
2242.06	72.7096
2244.92	69.5355
2247.78	65.9423
2250.63	63.0997
2253.48	59.4778
2256.34	56.4841
2259.19	53.7697
2262.04	50.8566
2264.89	48.7542
2267.74	46.2507
2270.59	44.0256
2273.43	43.1811
2276.28	40.8527
2279.12	37.586
2281.97	36.0669
2284.81	32.4151
2287.65	29.6661
2290.49	26.436
2293.33	23.7994
2296.17	22.2652
2299.01	20.9752
2301.84	19.6047
2304.68	18.0076
2307.51	17.2174
2310.35	15.3926
2313.18	15.3712
2316.01	13.5055
2318.84	12.1491
2321.67	10.9274
2324.5	10.5628
2327.33	9.44825
2330.15	8.8549
2332.98	8.74487
2335.8	7.49836
2338.62	6.99141
2341.45	6.60073
2344.27	5.57185
2347.09	5.15206
2349.91	4.77417
2352.72	3.25014
2355.54	3.10166
2358.36	1.87316
2361.17	1.63065
2363.98	2.19122
2366.8	3.15664
2369.61	3.46051
2372.42	3.48346
2375.23	2.93163
2378.04	3.65368
2380.85	4.5455
2383.66	3.99242
2386.46	3.61613
2389.26	3.0792
2392.07	3.65653
2394.87	4.62163
2397.67	4.69782
2400.47	5.24291
2403.27	5.24668
2406.07	5.89607
2408.87	6.2244
2411.67	6.99069
2414.46	6.99047
2417.26	8.04265
2420.05	8.33362
2422.84	8.87303
2425.64	9.62539
2428.43	10.4192
2431.22	12.2308
2434.01	13.3585
2436.79	13.2866
2439.58	14.2464
2442.37	14.0162
2445.15	14.2676
2447.93	14.2789
2450.72	13.7312
2453.5	13.9284
2456.28	12.7809
2459.06	12.5968
2461.84	12.1939
2464.62	11.3892
2467.39	10.2321
2470.17	9.03542
2472.94	7.02727
2475.72	5.94356
2478.49	5.08013
2481.26	4.16246
2484.03	4.39561
2486.8	2.98561
2489.57	2.16107
2492.34	0.997157
2495.1	1.01717
2497.87	1.88946
2500.63	0.250383
2503.4	-1.42754
2506.16	-1.26112
2508.92	-1.71538
2511.68	-2.91889
2514.44	-2.3798
2517.2	-2.21793
2519.96	-1.89624
2522.72	-2.51376
2525.47	-0.764465
2528.23	0.774677
2530.98	1.90787
2533.74	0.999713
2536.49	1.17629
2539.24	2.2411
2541.99	3.87407
2544.74	5.34649
2547.49	7.30817
2550.23	7.53753
2552.98	7.22279
2555.72	7.46136
2558.47	7.5533
2561.21	7.78561
2563.95	7.94269
2566.69	6.86799
2569.43	7.03128
2572.17	7.67091
2574.91	8.09353
2577.65	6.52285
2580.39	6.68461
2583.12	6.37374
2585.85	6.64929
2588.59	6.13063
2591.32	7.2206
2594.05	6.92927
2596.78	7.07791
2599.51	6.23846
2602.24	5.65441
2604.97	6.87673
2607.69	6.39787
2610.42	6.12284
2613.14	5.06057
2615.87	4.06629
2618.59	3.70599
2621.31	3.73459
2624.03	3.34049
2626.75	3.57233
2629.47	3.46245
2632.19	3.59375
2634.91	3.77572
2637.62	4.19959
2640.34	4.83422
2643.05	5.01897
2645.76	4.60181
2648.48	4.68855
2651.19	4.59202
2653.9	4.75538
2656.6	4.1698
2659.31	4.45579
2662.02	4.97416
2664.73	4.83663
2667.43	4.24239
2670.14	4.32813
2672.84	4.72064
2675.54	4.85453
2678.24	4.72012
2680.94	4.89505
2683.64	5.37305
2686.34	6.09964
2689.04	6.3513
2691.74	7.96507
2694.43	9.08738
2697.13	10.1903
2699.82	11.1422
2702.51	11.6439
2705.21	13.2977
2707.9	14.6448
2710.58	15.8065
2713.27	17.0004
2715.96	18.1028
2718.65	18.4912
2721.33	20.0988
2724.02	20.6343
2726.71	21.6253
2729.39	21.6935
2732.07	21.6492
2734.75	20.2539
2737.43	20.9049
2740.11	19.6424
2742.79	18.7931
2745.47	17.7312
2748.14	17.1133
2750.82	17.0854
2753.49	17.5174
2756.17	15.7666
2758.84	15.3892
2761.51	12.5469
2764.18	10.1167
2766.85	9.78389
2769.52	8.71666
2772.19	7.39276
2774.86	6.69504
2777.52	6.01106
2780.19	5.83943
2782.85	4.3029
2785.52	4.27171
2788.18	3.55409
2790.84	2.97036
2793.5	1.98779
2796.16	1.42302
2798.82	0.132505
2801.48	0.640785
2804.13	0.825538
2806.79	0.764257
2809.45	0.152859
2812.1	0.953582
2814.75	1.4824
2817.41	4.24668
2820.06	8.10852
2822.71	15.8718
2825.36	25.9987
2828	36.3463
2830.65	49.0237
2833.3	62.0595
2835.94	74.4721
2838.59	88.6213
2841.23	104.144
2843.87	121.434
2846.52	139.596
2849.16	159.5
2851.8	180.615
2854.44	202.002
2857.08	223.521
2859.71	243.485
2862.35	262.527
2864.98	279.15
2867.62	293.134
2870.25	304.851
2872.88	313.731
2875.52	321.94
2878.15	330.779
2880.78	338.922
2883.41	349.469
2886.03	358.477
2888.66	366.35
2891.29	374.188
2893.91	380.933
2896.54	389.487
2899.16	398.166
2901.78	410.257
2904.4	424.172
2907.02	440.591
2909.64	459.841
2912.26	479.744
2914.88	501.022
2917.5	519.934
2920.11	537.766
2922.73	550.706
2925.34	559.307
2927.96	565.098
2930.57	565.16
2933.18	562.89
2935.79	556.674
2938.4	545.482
2941.01	532.639
2943.62	516.869
2946.22	499.204
2948.83	479.059
2951.43	457.544
2954.04	435.247
2956.64	412.996
2959.24	391.251
2961.84	369.25
2964.45	350.504
2967.05	331.903
2969.64	313.391
2972.24	296.792
2974.84	279.647
2977.43	261.887
2980.03	243.541
2982.62	225.488
2985.22	207.06
2987.81	188.548
2990.4	169.827
2992.99	151.193
2995.58	134.371
2998.17	118.509
3000.76	103.293
3003.34	89.6432
3005.93	77.5908
3008.52	66.0465
3011.1	56.2877
3013.68	46.6226
3016.27	39.7724
3018.85	34.6949
3021.43	29.7051
3024.01	26.1011
3026.59	24.1164
3029.16	23.1479
3031.74	22.1285
3034.32	22.0951
3036.89	22.498
3039.47	23.3592
3042.04	25.5194
3044.61	27.2605
3047.18	29.9007
3049.75	31.0103
3052.32	31.0658
3054.89	31.5312
3057.46	32.2855
3060.03	32.7178
3062.59	30.9193
3065.16	29.0551
3067.72	26.4057
3070.29	23.4534
3072.85	20.9351
3075.41	18.0266
3077.97	14.9961
3080.53	11.679
3083.09	8.83868
3085.65	6.88123
3088.21	4.83431
3090.76	4.10659
3093.32	3.17655
3095.87	3.02974
3098.43	3.6896
3100.98	5.10576
3103.53	6.28059
3106.08	9.07091
3108.63	10.9925
3111.18	12.7543
3113.73	14.79
3116.28	18.4116
3118.83	21.8154
3121.37	24.3871
3123.92	26.3379
3126.46	28.349
3129	31.32
3131.55	34.0169
3134.09	36.4635
3136.63	38.4782
3139.17	40.1985
3141.71	42.4515
3144.24	44.3636
3146.78	43.8307
3149.32	43.9687