File: data/Raman/poly_smoothed/Thy_40_11_41_1x_45s_532 nm_x100_100%_600 gr_mm_01.txt
#Acq. time (s)=	45
#Accumulations=	2
#Range (cm-¹)=	200...3150
#Windows=	2
#Auto scanning=	Off
#Autofocus=	Off
#Macrospot=	Off
#AutoExposure=	Off
#Spike filter=	Multiple accum.
#Delay time (s)=	0
#Binning=	1
#Readout mode=	Signal
#DeNoise=	Off
#ICS correction=	On
#Dark correction=	Off
#Inst. Process=	Off
#Detector Gain=	Best Dynamic Range
#Detector ADC=	20 kHz
#Detector temperature (°C)=	-69.85
#Instrument=	LabRAM HR Evol
#Detector=	Synapse
#Objective=	x100
#Grating=	600 gr/mm
#ND Filter=	100%
#Laser (nm)=	532
#Hole=	100.021
#Range=	Auto
#Laser Pol.=	No
#Raman. Pol.=	No
#Laser Pol. (°)=	-0.0007625
#Raman Pol. (°)=	89.9995
#Collection=	Microscope
#StageXY=	Marzhauser
#StageZ=	Marzhauser
#X (µm)=	251.8
#Y (µm)=	1687.8
#Z (µm)=	426.85
#Full time(mm:ss)=	3:18
#Project=
#Sample=
#Site=
#Title=	Thy_40_11_41_2x_45s_532 nm_x100_100%_600 gr_mm
#Remark=
#Date=	05.07.2022 12:54
#Acquired=	05.07.2022 12:54:42
#Base:Fit=	10.08.2022 10:01:35
#Base:Sub=	10.08.2022 10:01:52
#Filter:Polynom=	16.08.2022 10:21:53
#AxisType[0]=Intens
#AxisUnit[0]=Cnt
#AxisType[1]=Spectr
#AxisUnit[1]=1/cm
200.43	45.2911
204.059	41.7915
207.688	36.1835
211.314	30.4658
214.941	25.6237
218.564	21.4186
222.186	16.6826
225.809	13.2112
229.428	11.2498
233.045	9.66104
236.663	8.05289
240.278	5.72808
243.891	4.9727
247.503	4.2931
251.116	4.68918
254.725	3.10764
258.333	1.10797
261.939	1.41002
265.544	2.42613
269.148	2.3506
272.75	4.99738
276.351	6.10343
279.95	6.24703
283.548	5.71276
287.144	6.09047
290.739	5.57383
294.333	5.78119
297.925	6.62003
301.514	7.90032
305.104	7.69293
308.692	7.10805
312.279	8.04345
315.862	10.8068
319.446	13.3348
323.029	14.7492
326.608	13.509
330.188	13.2737
333.766	13.3508
337.341	12.9554
340.917	12.7675
344.489	13.1247
348.062	12.5689
351.631	14.6467
355.201	13.4351
358.768	12.6906
362.333	12.4389
365.899	11.961
369.462	11.1998
373.023	11.6546
376.585	11.3895
380.143	10.5327
383.7	10.2469
387.256	10.2716
390.812	7.78847
394.365	7.964
397.916	8.30574
401.467	8.66287
405.015	7.90918
408.563	7.97115
412.109	5.72466
415.654	5.70917
419.197	5.3051
422.739	4.55072
426.279	5.1699
429.819	4.29655
433.356	4.61969
436.891	2.47874
440.426	1.48694
443.96	1.32579
447.492	3.18501
451.021	5.09046
454.551	8.29236
458.079	10.2527
461.604	11.3768
465.13	13.1707
468.654	14.3782
472.175	14.2722
475.696	16.0153
479.215	15.6762
482.733	17.1131
486.249	17.5851
489.765	19.303
493.278	20.8058
496.789	21.8919
500.301	21.5438
503.81	23.0767
507.317	23.4884
510.825	23.8522
514.33	22.275
517.833	22.5774
521.335	21.2703
524.836	20.3466
528.335	20.9992
531.835	20.6623
535.332	21.1735
538.827	20.9833
542.321	20.6586
545.814	19.6584
549.305	19.0084
552.795	18.5311
556.282	15.0888
559.769	14.1255
563.255	11.7223
566.739	10.222
570.223	9.15099
573.705	8.93719
577.183	8.11462
580.663	7.00123
584.141	7.29915
587.615	8.65752
591.09	9.53858
594.564	8.80555
598.035	6.48418
601.506	6.14123
604.974	5.83858
608.443	7.18014
611.908	9.57015
615.374	12.3854
618.837	13.125
622.3	14.5886
625.761	16.1199
629.219	16.9445
632.677	19.0381
636.135	19.1334
639.59	18.568
643.043	19.4544
646.495	18.8706
649.948	18.374
653.398	19.0085
656.846	19.0082
660.293	19.8138
663.738	21.2912
667.183	20.6525
670.626	22.1011
674.067	23.0606
677.508	22.6986
680.947	22.2655
684.385	23.1729
687.821	25.738
691.254	29.6924
694.688	32.0091
698.121	34.8151
701.552	35.4115
704.98	36.0044
708.409	35.8162
711.836	37.2797
715.26	38.9046
718.685	40.4711
722.108	41.4449
725.528	42.3316
728.949	41.9393
732.367	42.3452
735.785	43.8878
739.2	43.7361
742.614	46.1393
746.028	49.1577
749.439	52.4058
752.849	53.7222
756.26	56.4892
759.667	58.8895
763.073	60.6856
766.477	62.9826
769.883	65.3245
773.285	69.6749
776.686	72.1177
780.085	74.0158
783.484	75.6658
786.881	76.225
790.276	76.8142
793.671	78.6533
797.064	80.5009
800.456	82.1603
803.846	83.3435
807.234	84.2108
810.622	83.2845
814.008	84.314
817.394	85.2196
820.778	87.2448
824.159	87.9854
827.541	90.1217
830.921	88.6968
834.298	87.6124
837.676	86.7135
841.051	84.8469
844.426	81.5493
847.798	77.5608
851.171	77.0557
854.54	73.0839
857.911	70.5579
861.278	66.3158
864.645	62.8355
868.01	58.5622
871.373	56.0971
874.735	53.9027
878.097	52.7521
881.457	50.7206
884.815	49.2826
888.172	48.0232
891.528	45.7633
894.882	44.8911
898.237	45.1111
901.589	43.7999
904.94	44.3649
908.289	44.1569
911.635	41.6724
914.982	42.2142
918.328	40.7141
921.672	40.2044
925.015	38.1759
928.357	36.8246
931.698	35.6655
935.035	35.0798
938.373	33.6971
941.71	32.2679
945.044	31.1297
948.378	28.5278
951.709	31.2194
955.041	31.6571
958.372	32.1537
961.699	31.4135
965.027	33.3416
968.352	32.9408
971.676	33.4507
975	33.6649
978.322	34.5176
981.642	35.6094
984.962	37.3263
988.28	37.3313
991.596	36.4406
994.911	36.1975
998.227	36.4081
1001.54	35.9353
1004.85	36.4849
1008.16	37.0064
1011.47	35.7713
1014.78	36.5804
1018.08	37.2088
1021.39	36.9308
1024.69	36.9827
1028	36.0653
1031.3	38.334
1034.6	39.1499
1037.9	38.4139
1041.19	36.806
1044.49	35.2266
1047.78	33.9281
1051.08	31.2696
1054.37	30.7093
1057.66	27.8832
1060.95	25.1927
1064.24	23.3477
1067.53	19.5699
1070.81	16.174
1074.1	14.6125
1077.38	14.5959
1080.66	14.3052
1083.94	13.5928
1087.22	15.7348
1090.5	14.7743
1093.78	16.2527
1097.05	17.407
1100.33	19.4052
1103.6	20.9388
1106.87	21.0385
1110.14	22.8185
1113.41	25.1187
1116.68	22.852
1119.95	22.3589
1123.21	21.1619
1126.48	19.9472
1129.74	17.4409
1133	15.9207
1136.26	13.3378
1139.52	12.9716
1142.78	10.4922
1146.04	10.1596
1149.29	9.47525
1152.55	8.80151
1155.8	8.64653
1159.05	8.55186
1162.3	8.29105
1165.55	9.34507
1168.8	8.86071
1172.05	10.4347
1175.29	10.7341
1178.54	10.7478
1181.78	11.7019
1185.02	12.4107
1188.26	13.1762
1191.5	14.2629
1194.74	15.0478
1197.97	15.8415
1201.21	18.4008
1204.44	19.2259
1207.68	22.9844
1210.91	24.6291
1214.14	27.5612
1217.37	31.389
1220.59	35.0879
1223.82	39.9652
1227.05	44.0095
1230.27	47.0151
1233.49	51.8446
1236.72	57.3026
1239.94	59.9801
1243.16	62.18
1246.37	64.9991
1249.59	68.6158
1252.8	70.5574
1256.02	72.3714
1259.23	74.0531
1262.44	75.9378
1265.66	77.4542
1268.86	79.7482
1272.07	82.7008
1275.28	84.1536
1278.48	85.3568
1281.69	87.8674
1284.89	90.0189
1288.09	91.9108
1291.29	94.6789
1294.49	97.6326
1297.69	98.2861
1300.89	98.7224
1304.08	99.907
1307.28	100.257
1310.47	102.972
1313.66	105.154
1316.85	104.215
1320.04	102.245
1323.23	101.858
1326.42	101.39
1329.61	99.9046
1332.79	96.6816
1335.97	93.9532
1339.16	91.4248
1342.34	88.9657
1345.52	87.1384
1348.7	85.5704
1351.87	82.3984
1355.05	78.4628
1358.22	74.8665
1361.4	73.2172
1364.57	70.6039
1367.74	67.832
1370.91	65.4163
1374.08	63.1564
1377.25	61.6019
1380.41	60.5068
1383.58	59.3711
1386.74	57.43
1389.91	54.8346
1393.07	53.7075
1396.23	49.1318
1399.39	48.4122
1402.55	47.7119
1405.7	46.6328
1408.86	44.402
1412.01	45.6675
1415.17	47.8784
1418.32	51.2099
1421.47	55.0202
1424.62	61.4843
1427.77	67.917
1430.91	72.4923
1434.06	77.5224
1437.2	83.9961
1440.35	89.8436
1443.49	94.7896
1446.63	98.6525
1449.77	101.185
1452.91	101.866
1456.05	99.5455
1459.18	95.2047
1462.32	91.3816
1465.45	86.0981
1468.59	81.9839
1471.72	75.402
1474.85	68.339
1477.98	61.466
1481.1	52.2719
1484.23	44.0604
1487.36	38.0272
1490.48	33.3021
1493.61	29.4337
1496.73	28.3555
1499.85	28.0478
1502.97	27.9606
1506.09	29.2852
1509.2	29.6456
1512.32	31.4881
1515.43	31.8861
1518.55	33.0865
1521.66	35.3899
1524.77	36.7381
1527.88	37.8196
1530.99	38.3726
1534.1	40.616
1537.21	43.2851
1540.31	45.8978
1543.42	50.0128
1546.52	53.4069
1549.62	57.8876
1552.72	61.2791
1555.82	65.1908
1558.92	69.182
1562.02	72.9172
1565.11	77.004
1568.21	82.0157
1571.3	87.6852
1574.39	93.4005
1577.49	97.3557
1580.57	100.676
1583.66	102.781
1586.75	105.298
1589.84	105.93
1592.92	106.955
1596.01	105.962
1599.09	105.398
1602.17	102.064
1605.25	99.3002
1608.33	95.9958
1611.41	95.6897
1614.49	93.6587
1617.57	93.0338
1620.64	94.0396
1623.72	95.6761
1626.79	95.5358
1629.86	94.8923
1632.93	96.0072
1636	97.2976
1639.07	98.892
1642.13	101.459
1645.2	104.812
1648.26	108.962
1651.33	112.116
1654.39	113.498
1657.45	112.747
1660.51	112.906
1663.57	111.334
1666.63	107.863
1669.68	103.215
1672.74	97.7139
1675.79	91.5826
1678.85	84.4048
1681.9	79.0664
1684.95	72.5961
1688	65.9383
1691.05	58.8539
1694.09	52.1256
1697.14	45.5262
1700.18	38.7233
1703.23	32.0391
1706.27	27.8118
1709.31	24.9516
1712.35	21.0033
1715.39	17.3654
1718.43	15.7238
1721.47	15.1486
1724.5	13.6532
1727.54	11.4867
1730.57	10.0441
1733.61	8.51545
1736.64	8.05028
1739.67	5.48242
1742.7	4.03536
1745.72	2.70837
1748.75	2.66195
1751.77	3.07858
1754.8	3.33552
1757.82	3.21502
1760.84	2.47894
1763.87	2.07797
1766.89	2.09302
1769.91	0.969432
1772.92	1.2316
1775.94	1.81173
1778.95	2.47551
1781.97	2.13007
1784.98	1.43147
1787.99	0.554873
1791.01	0.142052
1794.01	0.38441
1797.02	0.142178
1800.03	0.571409
1803.04	0.260723
1806.04	0.0736916
1809.05	0.531613
1812.05	0.913703
1815.05	0.910985
1818.05	1.98036
1821.05	2.10225
1824.05	3.83112
1827.05	3.99213
1830.04	3.8944
1833.04	4.39967
1836.03	3.91775
1839.03	4.26509
1842.02	4.0016
1845.01	3.89153
1848	3.87779
1850.99	2.86154
1853.97	2.42162
1856.96	1.40862
1859.94	0.797036
1862.93	-0.308516
1865.91	-0.241747
1868.89	0.449127
1871.87	0.658483
1874.85	0.732301
1877.83	0.831645
1880.81	1.09038
1882.57	2.81698
1885.56	2.57713
1888.55	2.93876
1891.54	3.54099
1894.52	4.41674
1897.51	5.38265
1900.49	5.0428
1903.47	5.41122
1906.45	5.0284
1909.43	5.46945
1912.41	5.11193
1915.39	4.85109
1918.37	5.06992
1921.34	4.13304
1924.32	3.59466
1927.29	2.96758
1930.26	2.27985
1933.23	1.02173
1936.2	1.25313
1939.17	1.82681
1942.14	2.6848
1945.11	2.01607
1948.07	2.7868
1951.04	3.54762
1954	3.76835
1956.96	3.57719
1959.93	3.86332
1962.89	4.40274
1965.85	4.42455
1968.8	6.0551
1971.76	5.5261
1974.72	5.42166
1977.67	5.6302
1980.63	6.11022
1983.58	5.04976
1986.53	4.48738
1989.48	4.84814
1992.43	4.77544
1995.38	3.95523
1998.32	3.56813
2001.27	3.51465
2004.22	4.8183
2007.16	5.81626
2010.1	6.38676
2013.04	6.82553
2015.98	6.02147
2018.92	6.81717
2021.86	7.51491
2024.8	7.73562
2027.74	6.87864
2030.67	6.86136
2033.61	7.34233
2036.54	6.78467
2039.47	7.81703
2042.4	8.23968
2045.33	8.2217
2048.26	8.77958
2051.19	8.42303
2054.12	7.7366
2057.04	8.50243
2059.97	9.73005
2062.89	11.3656
2065.81	12.4097
2068.73	13.7805
2071.65	16.0711
2074.57	17.8947
2077.49	20.2907
2080.41	20.1299
2083.32	20.7324
2086.24	22.0351
2089.15	23.7268
2092.07	25.5676
2094.98	27.1584
2097.89	27.9608
2100.8	30.4089
2103.71	33.6721
2106.61	37.7317
2109.52	40.4458
2112.43	43.3197
2115.33	46.4148
2118.23	50.4501
2121.13	54.0378
2124.04	58.4233
2126.94	63.9236
2129.83	69.8444
2132.73	75.1075
2135.63	81.1597
2138.53	86.6859
2141.42	91.5485
2144.31	95.883
2147.21	100.41
2150.1	103.877
2152.99	106.023
2155.88	108.503
2158.77	111.8
2161.65	113.685
2164.54	115.965
2167.43	117.29
2170.31	118.817
2173.19	119.303
2176.07	119.262
2178.96	117.561
2181.84	115.081
2184.72	112.873
2187.59	109.391
2190.47	105.964
2193.35	102.241
2196.22	98.6827
2199.09	94.8951
2201.97	90.7498
2204.84	86.718
2207.71	82.3731
2210.58	76.9623
2213.45	72.6725
2216.31	67.2457
2219.18	61.9306
2222.05	56.9655
2224.91	52.8243
2227.78	48.8089
2230.64	46.6331
2233.5	42.7817
2236.36	39.6314
2239.22	37.1901
2242.08	35.3737
2244.93	33.8303
2247.79	32.5824
2250.64	30.3866
2253.5	28.8174
2256.35	27.2701
2259.2	24.7824
2262.05	24.0862
2264.9	23.1966
2267.75	23.0207
2270.6	21.47
2273.45	20.5773
2276.29	20.3732
2279.14	19.7582
2281.98	18.5455
2284.82	17.4126
2287.66	16.3044
2290.5	14.5868
2293.34	11.9942
2296.18	10.7598
2299.02	10.842
2301.86	10.8758
2304.69	10.1393
2307.53	10.3164
2310.36	9.87097
2313.19	9.27011
2316.02	9.41103
2318.85	9.13069
2321.68	7.86286
2324.51	8.10476
2327.34	6.90789
2330.16	5.44226
2332.99	4.56485
2335.81	4.19477
2338.64	3.36031
2341.46	2.61025
2344.28	1.47266
2347.1	1.47685
2349.92	0.925828
2352.74	0.0313167
2355.55	-1.20864
2358.37	-2.37879
2361.19	-3.26496
2364	-2.93962
2366.81	-1.44719
2369.62	-0.257251
2372.44	-0.427312
2375.24	-0.454075
2378.05	0.720706
2380.86	0.793484
2383.67	1.48618
2386.47	1.80049
2389.28	1.44442
2392.08	2.05224
2394.89	2.21807
2397.69	0.961946
2400.49	1.17343
2403.29	1.28088
2406.09	2.00515
2408.88	2.39678
2411.68	3.86108
2414.48	4.58731
2417.27	5.60672
2420.06	5.93833
2422.86	6.05911
2425.65	6.70815
2428.44	7.05639
2431.23	7.65304
2434.02	8.56661
2436.81	7.51317
2439.59	8.08129
2442.38	7.86596
2445.16	8.61642
2447.95	8.69916
2450.73	7.93206
2453.51	8.06377
2456.29	8.24405
2459.07	7.46993
2461.85	6.74289
2464.63	5.96183
2467.4	5.88542
2470.18	6.39192
2472.95	5.5972
2475.73	5.21922
2478.5	5.8521
2481.27	6.4085
2484.04	6.16778
2486.81	6.66518
2489.58	6.96274
2492.35	7.42183
2495.12	7.26146
2497.88	7.43546
2500.65	6.99122
2503.41	7.12283
2506.17	7.0862
2508.94	7.32801
2511.7	6.8615
2514.46	7.30224
2517.22	7.21957
2519.97	7.83301
2522.73	7.42999
2525.49	6.74974
2528.24	5.55942
2530.99	5.0828
2533.75	4.88767
2536.5	3.86687
2539.25	1.97982
2542	1.21842
2544.75	0.590296
2547.5	0.468957
2550.24	0.530871
2552.99	0.756846
2555.74	0.935481
2558.48	0.0161869
2561.22	-0.435594
2563.96	0.5806
2566.71	1.09309
2569.45	1.35001
2572.18	2.28329
2574.92	1.8448
2577.66	2.17716
2580.4	4.13653
2583.13	3.77052
2585.87	4.01879
2588.6	4.45769
2591.33	4.51182
2594.06	4.68747
2596.79	3.83144
2599.52	4.30713
2602.25	4.11047
2604.98	4.26586
2607.71	3.23294
2610.43	3.93863
2613.16	3.86383
2615.88	4.6903
2618.6	5.46593
2621.32	5.42933
2624.04	5.55622
2626.76	6.70615
2629.48	8.38492
2632.2	8.82113
2634.92	9.15242
2637.63	8.72499
2640.35	8.91634
2643.06	8.96989
2645.77	9.85417
2648.49	10.2828
2651.2	9.58645
2653.91	10.0071
2656.62	9.48487
2659.33	8.66094
2662.03	8.53554
2664.74	8.29726
2667.44	8.41014
2670.15	8.85316
2672.85	8.90508
2675.55	8.39462
2678.26	8.72645
2680.96	9.16796
2683.66	9.22584
2686.35	10.5523
2689.05	11.1499
2691.75	11.3081
2694.44	11.7357
2697.14	11.5115
2699.83	11.7816
2702.52	12.1838
2705.22	11.3967
2707.91	12.1039
2710.6	12.2167
2713.29	13.7095
2715.97	13.8072
2718.66	14.6172
2721.35	14.2032
2724.03	14.0016
2726.72	15.2255
2729.4	14.7827
2732.08	14.5032
2734.76	14.4092
2737.44	13.8404
2740.12	13.5073
2742.8	13.2767
2745.48	12.9277
2748.16	13.4123
2750.83	12.9992
2753.51	13.1505
2756.18	12.0443
2758.85	11.6916
2761.53	10.2788
2764.2	10.5839
2766.87	8.89423
2769.54	8.39668
2772.2	8.03107
2774.87	7.92328
2777.54	6.95258
2780.2	6.87612
2782.87	6.23211
2785.53	5.70683
2788.19	5.0696
2790.85	3.7066
2793.51	1.89314
2796.17	1.45291
2798.83	-0.0253757
2801.49	-0.707822
2804.15	-0.560346
2806.8	-0.582391
2809.46	-0.572339
2812.11	-0.462368
2814.76	-0.651094
2817.42	-0.297901
2820.07	1.37311
2822.72	4.07843
2825.37	7.84969
2828.02	12.9058
2830.66	19.3288
2833.31	24.502
2835.96	31.1001
2838.6	38.5655
2841.24	45.0066
2843.89	53.233
2846.53	62.3861
2849.17	72.8818
2851.81	82.818
2854.45	94.0191
2857.09	104.064
2859.72	115.262
2862.36	125.447
2865	134.636
2867.63	142.746
2870.26	151.01
2872.9	158.028
2875.53	163.06
2878.16	167.938
2880.79	172.006
2883.42	176.791
2886.05	181.432
2888.67	186.324
2891.3	191.365
2893.92	196.691
2896.55	201.848
2899.17	208.347
2901.79	216.647
2904.42	225.621
2907.04	236.061
2909.66	248.967
2912.27	263.036
2914.89	276.554
2917.51	290.053
2920.13	301.495
2922.74	312.587
2925.35	320.828
2927.97	326.63
2930.58	330.673
2933.19	332.548
2935.8	333.014
2938.41	330.017
2941.02	323.85
2943.63	315.902
2946.24	307.159
2948.84	297.786
2951.45	286.481
2954.05	275.103
2956.65	263.016
2959.26	250.068
2961.86	237.663
2964.46	225.677
2967.06	213.42
2969.66	201.694
2972.25	190.199
2974.85	179.186
2977.45	167.932
2980.04	156.902
2982.64	144.484
2985.23	132.559
2987.82	119.999
2990.41	107.93
2993	97.1206
2995.59	86.5589
2998.18	76.738
3000.77	67.2427
3003.36	57.9255
3005.94	49.7603
3008.53	42.8516
3011.11	38.2165
3013.69	33.1008
3016.28	28.7068
3018.86	23.9296
3021.44	20.6399
3024.02	17.4064
3026.6	14.3531
3029.18	12.5774
3031.75	11.7987
3034.33	11.5575
3036.9	12.1855
3039.48	12.5307
3042.05	12.701
3044.62	12.9555
3047.19	13.2172
3049.77	13.8606
3052.34	14.8468
3054.9	15.4155
3057.47	15.8852
3060.04	16.188
3062.61	15.9466
3065.17	15.0322
3067.74	13.9429
3070.3	13.2128
3072.86	12.1548
3075.42	11.6182
3077.99	9.4841
3080.54	6.23833
3083.1	4.74197
3085.66	2.8951
3088.22	1.6075
3090.78	0.445497
3093.33	0.209554
3095.89	-0.280674
3098.44	-0.279678
3100.99	-0.214236
3103.54	-0.481056
3106.1	-0.625214
3108.65	0.38049
3111.2	1.01869
3113.74	1.70677
3116.29	1.61925
3118.84	2.43081
3121.38	3.47212
3123.93	3.6162
3126.47	4.29804
3129.01	5.13591
3131.56	5.70572
3134.1	6.79806
3136.64	8.19298
3139.18	9.10306
3141.72	9.74635
3144.26	11.4864
3146.79	13.019
3149.33	15.5562