File: data/Raman/poly_smoothed/Thy_30_10_41_1x_45s_532 nm_x100_100%_600 gr_mm_01.txt
#Acq. time (s)=	45
#Accumulations=	2
#Range (cm-¹)=	200...3150
#Windows=	2
#Auto scanning=	Off
#Autofocus=	Off
#Macrospot=	Off
#AutoExposure=	Off
#Spike filter=	Multiple accum.
#Delay time (s)=	0
#Binning=	1
#Readout mode=	Signal
#DeNoise=	Off
#ICS correction=	On
#Dark correction=	Off
#Inst. Process=	Off
#Detector Gain=	Best Dynamic Range
#Detector ADC=	20 kHz
#Detector temperature (°C)=	-69.85
#Instrument=	LabRAM HR Evol
#Detector=	Synapse
#Objective=	x100
#Grating=	600 gr/mm
#ND Filter=	100%
#Laser (nm)=	532
#Hole=	100.021
#Range=	Auto
#Laser Pol.=	No
#Raman. Pol.=	No
#Laser Pol. (°)=	-0.0007625
#Raman Pol. (°)=	89.9995
#Collection=	Microscope
#StageXY=	Marzhauser
#StageZ=	Marzhauser
#X (µm)=	4718.2
#Y (µm)=	-7715.8
#Z (µm)=	584.45
#Full time(mm:ss)=	3:19
#Project=
#Sample=
#Site=
#Title=	Thy_30_10_41_2x_45s_532 nm_x100_100%_600 gr_mm
#Remark=
#Date=	30.06.2022 14:22
#Acquired=	30.06.2022 14:22:17
#Base:Fit=	10.08.2022 09:58:11
#Base:Sub=	10.08.2022 09:58:44
#Filter:Polynom=	16.08.2022 10:22:53
#AxisType[0]=Intens
#AxisUnit[0]=Cnt
#AxisType[1]=Spectr
#AxisUnit[1]=1/cm
200.533	0.337663
204.162	4.39525
207.792	7.15941
211.418	10.0354
215.044	12.7946
218.667	15.2845
222.289	14.1896
225.912	13.3541
229.531	12.996
233.148	13.2509
236.766	13.0346
240.381	12.6646
243.994	10.9447
247.606	10.8641
251.217	10.0033
254.828	9.2009
258.436	10.1117
262.042	9.62994
265.647	9.16338
269.25	9.20916
272.852	8.16951
276.453	7.28953
280.052	7.11476
283.65	8.44963
287.247	9.35322
290.842	9.73328
294.436	12.52
298.028	12.7448
301.617	12.6966
305.206	13.9261
308.794	13.4647
312.381	13.6221
315.964	14.1371
319.548	13.7319
323.131	13.6712
326.71	11.7743
330.29	11.7097
333.868	12.2111
337.443	12.9953
341.018	12.7657
344.591	11.4066
348.163	11.1661
351.733	9.08789
355.303	7.82517
358.869	6.54761
362.435	4.67745
366.001	6.09491
369.563	5.05731
373.124	4.7843
376.686	6.32572
380.244	5.86448
383.801	5.84862
387.357	5.77909
390.911	6.08499
394.466	6.48749
398.018	7.26866
401.568	6.84685
405.117	6.62828
408.664	7.66915
412.21	8.62747
415.755	10.5908
419.298	10.7187
422.84	11.0489
426.38	11.6879
429.919	10.5691
433.455	8.90345
436.992	7.91343
440.527	6.83933
444.06	6.57386
447.593	6.75934
451.122	5.82514
454.651	5.12896
458.18	3.72184
461.705	3.83346
465.23	2.45609
468.752	2.24708
472.275	1.23322
475.797	2.62218
479.315	2.98585
482.834	4.00088
486.349	4.50415
489.863	6.55967
493.378	7.88399
496.889	10.1486
500.401	11.6363
503.91	12.598
507.417	13.3076
510.923	13.6061
514.43	13.4809
517.933	12.8772
521.435	12.8086
524.936	12.6926
528.435	12.7987
531.933	12.7705
535.43	11.2391
538.927	9.2465
542.421	8.67935
545.913	8.35731
549.403	7.39286
552.893	6.24021
556.381	6.39419
559.868	6.53174
563.354	7.29386
566.839	5.75645
570.322	4.99284
573.802	4.7233
577.283	4.91826
580.762	4.69794
584.24	5.63812
587.714	5.5591
591.19	4.92393
594.663	5.04562
598.134	5.36117
601.605	5.95478
605.073	5.36527
608.542	5.43719
612.007	6.01074
615.473	6.55113
618.936	6.58504
622.397	5.89225
625.859	5.77731
629.318	7.66224
632.775	9.37649
636.233	11.0106
639.688	11.642
643.142	13.5151
646.594	14.1084
650.045	14.3247
653.496	14.859
656.944	16.2623
660.391	18.4446
663.837	21.0125
667.281	22.1561
670.724	23.5539
674.166	25.8413
677.606	28.1065
681.045	28.3853
684.483	30.3124
687.917	30.8733
691.352	31.473
694.786	32.7444
698.219	31.9062
701.65	32.5649
705.078	33.1942
708.506	33.3012
711.934	34.551
715.358	35.2027
718.782	35.1615
722.204	36.0674
725.626	35.4784
729.045	37.8202
732.464	39.2468
735.881	40.1251
739.297	43.1062
742.711	45.0736
746.125	48.621
749.537	49.5885
752.946	53.5036
756.357	56.3426
759.764	58.4944
763.17	61.1098
766.575	63.1806
769.978	67.6877
773.382	68.9648
776.783	70.6388
780.182	71.8408
783.581	73.6625
786.978	76.7162
790.373	77.0194
793.768	78.6444
797.161	79.7362
800.552	81.5378
803.941	83.5636
807.33	84.5823
810.718	86.125
814.105	87.4475
817.49	88.4284
820.873	88.5157
824.256	89.7888
827.637	89.2048
831.016	88.339
834.395	87.003
837.772	85.905
841.147	83.0135
844.522	80.7795
847.894	78.3882
851.267	75.2642
854.637	72.496
858.007	68.5544
861.374	66.7725
864.739	64.9913
868.106	61.0295
871.469	59.073
874.831	58.3398
878.193	57.2982
881.553	57.4763
884.911	56.8876
888.268	57.4369
891.623	56.859
894.978	57.4355
898.331	56.1176
901.683	57.0713
905.033	57.1443
908.383	56.8341
911.731	55.9051
915.078	55.184
918.423	53.7024
921.768	52.7956
925.111	49.9881
928.452	48.2554
931.791	47.0643
935.13	44.8435
938.468	43.514
941.803	40.9272
945.139	38.5421
948.473	36.6891
951.804	35.8365
955.136	35.7333
958.465	33.6131
961.794	32.9495
965.12	33.8668
968.447	34.396
971.771	35.2408
975.095	36.6057
978.417	37.5783
981.737	38.3703
985.057	40.4226
988.375	41.9264
991.691	43.115
995.006	45.3304
998.32	45.5435
1001.63	45.4694
1004.95	45.4025
1008.26	45.1102
1011.56	44.8974
1014.87	43.9965
1018.18	42.5919
1021.48	40.1178
1024.79	38.3798
1028.09	38.9415
1031.39	37.252
1034.69	34.6583
1037.99	32.7464
1041.29	30.7447
1044.58	30.6162
1047.88	31.2688
1051.17	30.3189
1054.46	29.7074
1057.75	29.7871
1061.04	28.9438
1064.33	29.1403
1067.62	29.3465
1070.9	29.7015
1074.19	29.7758
1077.47	29.4267
1080.76	28.6982
1084.04	27.7485
1087.32	27.86
1090.59	26.8523
1093.87	27.6366
1097.15	27.3327
1100.42	27.6778
1103.69	28.4751
1106.97	28.5658
1110.24	28.737
1113.51	27.533
1116.77	25.4151
1120.04	23.694
1123.31	22.5644
1126.57	22.2746
1129.83	20.1059
1133.1	18.3136
1136.36	16.9177
1139.62	16.5595
1142.87	14.3051
1146.13	13.8614
1149.38	12.4093
1152.64	10.7305
1155.89	9.29663
1159.14	8.34488
1162.39	6.96714
1165.64	6.54159
1168.89	7.17319
1172.14	7.74627
1175.38	7.66598
1178.63	9.04222
1181.87	10.4864
1185.11	11.861
1188.35	11.7183
1191.59	12.5907
1194.83	12.7063
1198.07	13.647
1201.3	16.5395
1204.53	18.9668
1207.77	20.2834
1211	21.9517
1214.23	25.873
1217.46	28.1262
1220.69	29.7817
1223.91	32.927
1227.14	37.0333
1230.36	38.3742
1233.59	41.2858
1236.81	42.272
1240.03	44.6215
1243.25	45.7215
1246.46	48.2591
1249.68	49.9109
1252.9	50.9094
1256.11	52.2155
1259.32	54.402
1262.54	54.7083
1265.75	56.6424
1268.96	58.3277
1272.16	60.2643
1275.37	61.8203
1278.57	62.7777
1281.78	65.2188
1284.98	66.1954
1288.18	68.6219
1291.38	70.0129
1294.58	69.6428
1297.78	69.0748
1300.98	69.7683
1304.17	69.7525
1307.37	69.9675
1310.56	69.7107
1313.76	70.2106
1316.95	69.8978
1320.14	68.8939
1323.32	67.7209
1326.51	67.0874
1329.7	65.6707
1332.88	64.449
1336.07	63.5162
1339.25	62.6218
1342.43	62.59
1345.61	60.7503
1348.79	58.3667
1351.96	57.2945
1355.14	55.7227
1358.31	54.3079
1361.49	50.3784
1364.66	48.1442
1367.83	45.3459
1371	42.3289
1374.17	39.2588
1377.34	38.8935
1380.5	37.0453
1383.67	36.7893
1386.83	35.57
1390	34.2458
1393.16	32.0594
1396.32	31.4755
1399.48	29.9516
1402.64	30.0151
1405.79	29.9718
1408.95	31.8331
1412.1	33.8876
1415.26	35.7678
1418.41	38.7728
1421.56	41.8509
1424.71	45.1133
1427.86	49.887
1431	54.4533
1434.15	57.6684
1437.29	59.5891
1440.44	62.1895
1443.58	65.3112
1446.72	67.6686
1449.86	67.4126
1453	67.2474
1456.14	66.2327
1459.27	63.2288
1462.41	60.3979
1465.54	55.696
1468.67	50.3036
1471.81	46.3923
1474.94	40.177
1478.07	34.0796
1481.19	29.1598
1484.32	24.9839
1487.45	21.2257
1490.57	17.7597
1493.69	14.0929
1496.82	12.6108
1499.94	12.1992
1503.06	11.4208
1506.17	11.6185
1509.29	10.0918
1512.41	11.173
1515.52	11.8758
1518.64	13.6551
1521.75	15.56
1524.86	16.4981
1527.97	17.8352
1531.08	19.4498
1534.19	21.7667
1537.29	25.2096
1540.4	28.1943
1543.5	30.5414
1546.61	32.9636
1549.71	35.7018
1552.81	37.8926
1555.91	41.0542
1559.01	43.6835
1562.11	45.8632
1565.2	47.9441
1568.29	50.4293
1571.39	52.8135
1574.48	54.7614
1577.57	55.65
1580.66	57.2201
1583.75	58.1452
1586.84	58.1845
1589.93	58.9567
1593.01	58.7001
1596.1	58.3335
1599.18	57.2534
1602.26	55.7028
1605.34	54.2781
1608.42	54.2916
1611.5	54.6261
1614.58	54.4544
1617.65	55.0546
1620.73	54.6564
1623.8	56.2759
1626.87	57.9197
1629.95	59.6172
1633.02	63.0742
1636.09	66.2536
1639.15	69.0921
1642.22	71.7419
1645.29	74.7643
1648.35	76.9485
1651.42	77.8986
1654.48	79.4679
1657.54	80.686
1660.6	80.6527
1663.66	79.8479
1666.72	77.8764
1669.77	75.0635
1672.83	71.0006
1675.88	66.0908
1678.93	60.46
1681.99	55.6146
1685.04	51.1189
1688.09	45.9636
1691.13	40.1828
1694.18	35.5151
1697.23	30.5934
1700.27	26.1233
1703.32	21.3992
1706.36	17.885
1709.4	15.1072
1712.44	11.4405
1715.48	8.4719
1718.52	6.33942
1721.56	4.99528
1724.59	3.58279
1727.63	2.92425
1730.66	3.02746
1733.69	3.27997
1736.72	2.92708
1739.75	2.0775
1742.78	2.7844
1745.81	2.05983
1748.84	1.12806
1751.86	1.50123
1754.89	2.38024
1757.91	2.68486
1760.93	2.74057
1763.95	2.27625
1766.97	2.51706
1769.99	1.99378
1773.01	0.951635
1776.03	0.430258
1779.04	0.0307609
1782.06	0.567141
1785.07	0.96235
1788.08	0.929698
1791.09	0.614251
1794.1	0.814702
1797.11	1.11249
1800.12	1.80256
1803.12	2.5436
1806.13	3.75556
1809.13	4.1121
1812.14	4.54854
1815.14	5.45642
1818.14	5.35442
1821.14	6.38936
1824.14	7.13617
1827.13	7.70109
1830.13	7.7826
1833.12	7.584
1836.12	7.91771
1839.11	8.23553
1842.1	7.88296
1845.09	8.41727
1848.08	8.40478
1851.07	8.66565
1854.06	8.50157
1857.04	8.79453
1860.03	9.71115
1863.01	9.33967
1866	9.49263
1868.98	9.83954
1871.96	10.0586
1874.94	10.6599
1877.92	11.671
1880.89	11.8616
1882.48	12.2142
1885.47	12.6562
1888.46	13.5811
1891.44	14.553
1894.43	14.608
1897.41	13.9982
1900.4	14.2011
1903.38	12.9046
1906.36	12.7294
1909.34	13.2951
1912.32	12.086
1915.29	12.2854
1918.27	12.5806
1921.25	11.8569
1924.22	11.5996
1927.2	11.2827
1930.17	11.8862
1933.14	12.4268
1936.11	11.9395
1939.08	11.8124
1942.05	12.0574
1945.01	11.907
1947.98	11.9383
1950.94	12.4846
1953.91	13.0243
1956.87	13.5145
1959.83	13.4763
1962.79	13.5339
1965.75	14.0488
1968.71	14.2692
1971.67	14.8434
1974.62	14.9562
1977.58	14.9087
1980.53	14.8097
1983.48	14.4188
1986.43	14.7918
1989.38	14.9366
1992.33	15.3001
1995.28	14.6066
1998.23	15.2259
2001.18	16.35
2004.12	16.4722
2007.06	17.2562
2010.01	17.5268
2012.95	17.3806
2015.89	18.1234
2018.83	18.8266
2021.77	18.5901
2024.71	18.4817
2027.64	18.7012
2030.58	18.5159
2033.51	18.8086
2036.45	19.658
2039.38	20.1808
2042.31	19.3932
2045.24	19.1887
2048.17	19.0577
2051.1	18.6642
2054.02	18.2017
2056.95	19.2319
2059.87	19.357
2062.8	18.8423
2065.72	18.7817
2068.64	19.3605
2071.56	20.311
2074.48	20.4545
2077.4	21.1324
2080.31	21.0946
2083.23	22.4847
2086.14	23.8902
2089.06	24.4394
2091.97	24.5349
2094.88	24.8794
2097.79	26.1183
2100.7	27.5483
2103.61	28.4432
2106.52	30.2939
2109.43	30.8212
2112.33	31.8418
2115.24	34.1969
2118.14	37.3888
2121.04	39.1497
2123.94	41.5944
2126.84	43.8897
2129.74	46.4256
2132.64	48.6995
2135.54	52.2176
2138.43	54.6662
2141.33	57.8034
2144.22	60.1871
2147.11	63.0881
2150.01	65.3278
2152.9	68.6224
2155.79	71.4878
2158.67	73.7078
2161.56	75.6524
2164.45	78.1117
2167.33	79.5505
2170.22	81.3227
2173.1	82.7811
2175.98	83.6115
2178.86	83.0288
2181.74	82.8244
2184.62	82.771
2187.5	81.9677
2190.38	80.8209
2193.25	77.5377
2196.13	74.7474
2199	72.0493
2201.88	69.7192
2204.75	66.0383
2207.62	62.3225
2210.49	57.8137
2213.36	54.579
2216.22	50.6548
2219.09	47.3049
2221.96	43.3754
2224.82	40.3945
2227.68	37.7826
2230.55	35.674
2233.41	33.5775
2236.27	32.0019
2239.12	30.1731
2241.98	29.2733
2244.84	27.9859
2247.7	27.6514
2250.55	26.4132
2253.41	25.7848
2256.26	25.7946
2259.11	24.579
2261.96	23.0001
2264.81	22.8804
2267.66	22.471
2270.51	22.1707
2273.35	21.4094
2276.2	20.2012
2279.04	19.1314
2281.89	17.6961
2284.73	16.763
2287.57	16.5351
2290.41	16.2164
2293.25	15.0959
2296.09	15.9398
2298.93	16.8494
2301.76	17.3215
2304.6	17.6931
2307.44	18.1075
2310.27	18.2451
2313.1	19.4326
2315.93	19.8224
2318.76	19.6342
2321.59	19.3143
2324.42	18.8482
2327.25	18.7811
2330.07	17.9782
2332.9	18.1085
2335.72	17.2359
2338.55	15.6164
2341.37	14.5119
2344.19	13.0141
2347.01	11.4964
2349.83	9.90135
2352.65	9.10555
2355.46	8.16163
2358.28	7.85704
2361.09	7.65824
2363.91	8.12867
2366.72	8.93725
2369.53	7.66114
2372.34	7.70115
2375.15	7.91556
2377.96	7.31296
2380.77	6.54519
2383.58	6.90593
2386.38	6.93046
2389.19	7.37942
2391.99	6.68632
2394.8	6.4918
2397.6	5.76648
2400.4	6.06876
2403.2	5.55784
2406	5.17932
2408.79	4.87041
2411.59	4.94664
2414.39	5.58581
2417.18	5.25727
2419.98	5.07977
2422.77	5.03689
2425.56	5.11743
2428.35	4.89418
2431.14	5.34753
2433.93	5.4267
2436.72	4.65239
2439.5	4.30753
2442.29	4.00921
2445.07	3.87471
2447.86	4.0113
2450.64	4.35144
2453.42	4.05248
2456.2	3.42001
2458.98	3.01234
2461.76	2.29146
2464.54	1.77583
2467.32	1.54787
2470.09	1.94965
2472.87	1.79741
2475.64	2.21994
2478.41	1.45609
2481.18	2.14993
2483.95	1.87737
2486.72	1.86008
2489.49	2.0573
2492.26	1.80038
2495.03	1.87831
2497.79	1.62734
2500.56	1.87875
2503.32	2.10393
2506.09	1.89662
2508.85	1.67197
2511.61	1.36237
2514.37	1.69037
2517.13	0.873341
2519.89	-0.174641
2522.64	-0.121735
2525.4	0.165641
2528.15	-0.419639
2530.91	-0.733031
2533.66	-0.231106
2536.41	0.0348266
2539.16	0.318708
2541.91	0.0721761
2544.66	0.482062
2547.41	0.945086
2550.16	1.94379
2552.9	1.99433
2555.65	2.81604
2558.39	3.09596
2561.13	3.06529
2563.88	2.99919
2566.62	2.95689
2569.36	3.56841
2572.1	2.62174
2574.84	2.01317
2577.57	1.38022
2580.31	1.00972
2583.05	0.0940959
2585.78	0.550786
2588.51	0.402117
2591.24	0.644281
2593.98	0.323168
2596.71	1.00538
2599.44	0.633994
2602.16	0.724634
2604.89	0.451732
2607.62	0.168875
2610.34	0.290897
2613.07	0.903688
2615.79	1.60448
2618.52	1.0967
2621.24	0.695518
2623.96	0.684121
2626.68	-0.00557736
2629.4	0.382315
2632.11	0.635074
2634.83	1.04341
2637.55	0.304995
2640.26	0.0690129
2642.98	0.514942
2645.69	-0.124819
2648.4	0.322639
2651.11	1.11726
2653.82	1.32514
2656.53	1.39908
2659.24	1.90534
2661.95	1.68159
2664.65	1.30112
2667.36	0.524128
2670.06	0.751255
2672.76	0.801253
2675.47	0.511357
2678.17	1.38431
2680.87	1.07143
2683.57	1.38485
2686.27	1.09355
2688.97	0.945866
2691.66	0.734232
2694.36	1.09089
2697.05	1.60921
2699.75	1.39266
2702.44	1.19945
2705.13	1.80292
2707.82	2.70923
2710.51	2.69611
2713.2	2.76716
2715.89	3.25533
2718.57	3.49873
2721.26	3.69991
2723.95	3.61684
2726.63	3.54638
2729.31	3.16981
2732	3.08265
2734.68	4.27978
2737.36	3.89497
2740.04	3.46841
2742.72	3.17309
2745.39	3.00062
2748.07	2.85458
2750.75	2.57218
2753.42	2.23925
2756.09	1.52414
2758.77	1.57666
2761.44	1.74062
2764.11	1.54333
2766.78	1.322
2769.45	1.35443
2772.12	1.04702
2774.78	0.739054
2777.45	0.832422
2780.12	0.856375
2782.78	0.81492
2785.44	1.45866
2788.11	1.06381
2790.77	1.20282
2793.43	1.2052
2796.09	1.43355
2798.75	1.69789
2801.4	1.7202
2804.06	0.834956
2806.72	1.05307
2809.37	0.778329
2812.03	0.729727
2814.68	0.836479
2817.33	1.30818
2819.98	1.46611
2822.63	3.26743
2825.28	5.57064
2827.93	7.48785
2830.58	10.7085
2833.23	13.5146
2835.87	16.7025
2838.52	21.4117
2841.16	25.3414
2843.8	30.8662
2846.44	36.6618
2849.08	43.9286
2851.73	52.3562
2854.36	60.4679
2857	68.725
2859.64	77.8453
2862.28	86.0276
2864.91	93.7253
2867.55	100.128
2870.18	105.493
2872.81	110.459
2875.44	115.346
2878.07	120.513
2880.7	124.619
2883.33	128.758
2885.96	133.185
2888.59	136.433
2891.21	140.571
2893.84	144.286
2896.46	149.139
2899.09	154.636
2901.71	160.902
2904.33	168.554
2906.95	176.888
2909.57	187.046
2912.19	198.065
2914.81	209.769
2917.43	220.791
2920.04	230.623
2922.66	239.873
2925.27	247.209
2927.88	251.845
2930.5	254.115
2933.11	255.902
2935.72	254.383
2938.33	252.77
2940.94	248.468
2943.54	242.81
2946.15	235.509
2948.76	226.959
2951.36	217.555
2953.97	207.963
2956.57	198.636
2959.17	188.603
2961.77	180.072
2964.37	170.194
2966.97	161.784
2969.57	153.053
2972.17	144.848
2974.77	137.511
2977.36	130.694
2979.96	122.808
2982.55	115.475
2985.15	107.033
2987.74	99.1776
2990.33	90.8086
2992.92	82.6116
2995.51	75.6621
2998.1	69.1969
3000.69	62.4529
3003.27	56.0015
3005.86	49.8125
3008.44	44.6543
3011.03	40.0306
3013.61	34.8353
3016.19	31.0161
3018.78	28.9205
3021.36	26.2285
3023.94	24.6305
3026.51	22.3783
3029.09	21.0217
3031.67	20.9266
3034.24	20.2168
3036.82	20.3995
3039.39	20.7123
3041.97	21.74
3044.54	22.5506
3047.11	23.2098
3049.68	23.3552
3052.25	23.8541
3054.82	24.4175
3057.39	24.3095
3059.96	24.5018
3062.52	23.225
3065.09	21.5243
3067.65	20.1052
3070.22	18.613
3072.78	16.8706
3075.34	15.0266
3077.9	13.0821
3080.46	11.5654
3083.02	9.54188
3085.58	7.5574
3088.14	5.51583
3090.69	4.58099
3093.25	4.1566
3095.8	3.32964
3098.36	3.02953
3100.91	3.87794
3103.46	3.98429
3106.01	3.44375
3108.56	3.23345
3111.11	3.81313
3113.66	3.65697
3116.21	3.96999
3118.76	3.38449
3121.3	3.37051
3123.85	3.25425
3126.39	2.79563
3128.93	1.99943
3131.48	2.21032
3134.02	1.78108
3136.56	1.23496
3139.1	0.108448
3141.64	-0.64051
3144.17	-0.964992
3146.71	-0.811969
3149.25	-0.386241