File: data/Raman/poly_smoothed/Thy_00_07_39_1x_45s_532 nm_x100_100%_600 gr_mm_01.txt
#Acq. time (s)=	45
#Accumulations=	2
#Range (cm-¹)=	200...3150
#Windows=	2
#Auto scanning=	Off
#Autofocus=	Off
#Macrospot=	Off
#AutoExposure=	Off
#Spike filter=	Multiple accum.
#Delay time (s)=	0
#Binning=	1
#Readout mode=	Signal
#DeNoise=	Off
#ICS correction=	On
#Dark correction=	Off
#Inst. Process=	Off
#Detector Gain=	Best Dynamic Range
#Detector ADC=	20 kHz
#Detector temperature (°C)=	-69.85
#Instrument=	LabRAM HR Evol
#Detector=	Synapse
#Objective=	x100
#Grating=	600 gr/mm
#ND Filter=	100%
#Laser (nm)=	532
#Hole=	100.021
#Range=	Auto
#Laser Pol.=	No
#Raman. Pol.=	No
#Laser Pol. (°)=	-0.0007625
#Raman Pol. (°)=	89.9995
#Collection=	Microscope
#StageXY=	Marzhauser
#StageZ=	Marzhauser
#X (µm)=	8965.9
#Y (µm)=	-3052.9
#Z (µm)=	-54.85
#Full time(mm:ss)=	3:18
#Project=
#Sample=
#Site=
#Title=	Thy_00_07_39_2x_45s_532 nm_x100_100%_600 gr_mm
#Remark=
#Date=	28.06.2022 12:57
#Acquired=	28.06.2022 12:57:37
#Base:Fit=	10.08.2022 10:07:56
#Base:Sub=	10.08.2022 10:08:40
#Filter:Polynom=	16.08.2022 10:26:06
#AxisType[0]=Intens
#AxisUnit[0]=Cnt
#AxisType[1]=Spectr
#AxisUnit[1]=1/cm
200.407	3.89268
204.035	2.11689
207.665	2.14823
211.291	2.30839
214.916	2.22055
218.541	1.39968
222.163	2.42968
225.785	2.77629
229.404	2.98677
233.022	3.75714
236.638	3.18311
240.255	2.851
243.868	3.37973
247.48	3.05065
251.091	2.5027
254.702	1.62069
258.31	2.46448
261.916	3.09007
265.521	2.67019
269.125	2.7319
272.727	2.76652
276.328	3.39681
279.927	4.68364
283.525	4.49698
287.121	5.76761
290.716	6.46552
294.31	7.09435
297.9	6.65201
301.491	8.81925
305.081	8.35338
308.669	10.0617
312.256	11.5111
315.839	11.9932
319.423	12.5047
323.006	12.8485
326.585	13.7091
330.165	13.7335
333.741	11.5559
337.318	11.6225
340.894	10.7271
344.466	11.885
348.039	11.8149
351.608	11.301
355.176	10.9927
358.745	10.7935
362.31	11.4209
365.876	12.4221
369.439	11.3674
373	10.0813
376.56	10.4292
380.12	11.0516
383.677	9.6552
387.233	9.66226
390.787	11.2874
394.34	9.5399
397.894	10.1527
401.444	9.23288
404.993	7.86367
408.54	7.70145
412.086	8.32736
415.631	8.21668
419.174	5.77585
422.716	7.29557
426.257	7.77397
429.794	7.29155
433.332	6.98851
436.868	5.52533
440.403	5.43168
443.937	5.03468
447.468	6.07056
450.999	6.19319
454.528	6.43294
458.057	7.12788
461.582	8.08149
465.107	9.20678
468.629	9.66445
472.152	11.5119
475.672	12.6726
479.192	12.5534
482.709	12.6378
486.226	14.8483
489.74	15.8228
493.255	18.0385
496.767	19.6073
500.277	20.5793
503.788	19.5901
507.295	20.7292
510.801	20.0039
514.308	18.1131
517.811	18.0042
521.313	16.473
524.814	16.7866
528.313	18.0171
531.811	17.1701
535.308	15.9707
538.803	15.8735
542.297	13.1888
545.789	12.7368
549.281	13.6113
552.771	13.2112
556.259	12.6254
559.747	11.7383
563.233	9.2449
566.717	10.5412
570.2	10.7674
573.68	11.1366
577.161	11.0643
580.64	10.9526
584.118	10.1534
587.593	8.17423
591.068	8.53688
594.54	7.8682
598.013	7.60901
601.484	6.01704
604.952	5.47765
608.421	4.80934
611.886	5.1005
615.35	4.24989
618.815	2.46665
622.276	2.2711
625.738	3.04206
629.197	4.16953
632.655	7.61857
636.113	8.97161
639.568	8.95596
643.021	10.5785
646.473	12.1596
649.924	14.6244
653.376	17.3152
656.824	19.0084
660.271	19.2039
663.716	19.4715
667.161	21.3034
670.604	22.4157
674.045	22.8122
677.486	23.8517
680.925	22.7918
684.361	23.4647
687.797	25.7929
691.232	28.3034
694.666	29.6986
698.099	29.6005
701.528	31.475
704.958	33.471
708.387	36.4875
711.814	40.7661
715.238	42.9039
718.663	44.9443
722.084	45.5228
725.506	48.2742
728.925	48.8701
732.345	50.7624
735.761	51.401
739.178	53.2088
742.592	54.8644
746.006	55.2349
749.417	58.1646
752.827	59.884
756.236	61.7731
759.645	63.3062
763.051	63.1171
766.456	65.5528
769.859	68.7725
773.261	71.0549
776.664	72.3824
780.064	73.5412
783.462	74.5241
786.859	74.5558
790.255	75.2726
793.649	76.1479
797.042	75.4033
800.434	73.7631
803.823	73.6253
807.212	72.8261
810.6	74.4666
813.987	75.4727
817.372	75.983
820.754	75.6615
824.137	77.0575
827.519	77.8705
830.897	78.1424
834.276	77.5601
837.654	76.1353
841.029	75.14
844.404	73.7599
847.776	72.994
851.149	71.246
854.519	69.7569
857.889	67.521
861.256	64.8969
864.622	60.5037
867.988	56.6805
871.351	53.2186
874.713	49.7003
878.074	44.7143
881.435	42.8033
884.794	42.0645
888.15	41.5766
891.506	42.0162
894.861	41.586
898.214	42.0391
901.566	42.9207
904.916	43.7044
908.266	45.4073
911.614	47.706
914.961	48.2391
918.306	50.1735
921.651	52.2684
924.994	54.1901
928.336	54.9442
931.674	55.0151
935.014	54.1481
938.352	54.1362
941.687	53.3429
945.022	52.3835
948.357	49.0352
951.688	46.2862
955.02	42.9666
958.348	40.295
961.678	37.453
965.004	36.4361
968.331	36.5693
971.655	36.5588
974.979	36.286
978.3	36.0124
981.62	36.1272
984.941	36.1959
988.259	36.1578
991.575	35.5138
994.89	35.7993
998.204	34.6912
1001.52	33.3314
1004.83	33.2149
1008.14	31.9667
1011.45	30.5535
1014.76	28.693
1018.06	27.6815
1021.37	25.7798
1024.67	24.7046
1027.97	22.0302
1031.27	18.7999
1034.57	19.1768
1037.87	18.6686
1041.17	18.7911
1044.47	19.3604
1047.76	22.1368
1051.06	22.5293
1054.35	22.829
1057.64	23.9461
1060.93	22.855
1064.22	22.4433
1067.5	23.1116
1070.79	22.1198
1074.08	22.8757
1077.36	21.8277
1080.64	19.8258
1083.92	18.4829
1087.2	17.9761
1090.48	17.9765
1093.76	18.1596
1097.03	20.6725
1100.31	23.0728
1103.58	24.7332
1106.85	24.2633
1110.12	23.8906
1113.39	24.3566
1116.66	24.8532
1119.93	24.3605
1123.19	22.9744
1126.46	21.8595
1129.72	21.4254
1132.98	20.826
1136.24	20.5621
1139.5	19.4354
1142.76	18.6749
1146.01	16.1923
1149.27	16.4087
1152.53	16.4054
1155.78	14.3914
1159.03	12.0359
1162.28	9.8886
1165.53	8.41689
1168.78	8.28146
1172.02	10.7207
1175.27	11.236
1178.51	12.5682
1181.76	13.0307
1185	11.4449
1188.24	11.4123
1191.48	12.4584
1194.71	11.668
1197.95	13.081
1201.19	13.9615
1204.42	15.7204
1207.65	16.3013
1210.88	18.3192
1214.12	21.0693
1217.35	23.5212
1220.57	25.6473
1223.8	29.3247
1227.03	32.8295
1230.25	35.4003
1233.47	35.7386
1236.69	36.357
1239.92	37.9262
1243.13	38.6392
1246.35	38.3757
1249.57	40.2312
1252.78	40.2814
1256	39.9256
1259.21	40.9106
1262.42	39.2913
1265.63	40.9277
1268.84	41.005
1272.05	42.4756
1275.26	42.6351
1278.46	43.2886
1281.67	44.8067
1284.87	46.7444
1288.07	47.7152
1291.27	50.4163
1294.47	53.3646
1297.67	55.2638
1300.87	58.2403
1304.06	59.2381
1307.26	60.137
1310.45	61.5048
1313.64	62.165
1316.83	63.6035
1320.02	62.9376
1323.21	62.0015
1326.4	61.9172
1329.59	60.3861
1332.77	58.5579
1335.95	58.6744
1339.14	56.2286
1342.32	56.184
1345.5	55.5005
1348.67	53.2985
1351.85	51.464
1355.03	50.937
1358.2	51.6237
1361.38	49.9092
1364.55	47.9575
1367.72	46.6539
1370.89	46.4963
1374.06	44.8237
1377.23	43.7997
1380.39	40.8546
1383.56	39.2518
1386.72	38.7274
1389.89	37.7742
1393.05	37.124
1396.21	34.8582
1399.37	32.6821
1402.52	32.2755
1405.68	31.8557
1408.84	32.5435
1411.99	34.5415
1415.15	35.3463
1418.3	38.4517
1421.45	40.7092
1424.6	43.4985
1427.75	47.8401
1430.89	51.9336
1434.04	57.0387
1437.18	60.609
1440.33	64.2219
1443.47	67.2612
1446.61	69.2536
1449.75	70.7682
1452.89	71.4394
1456.03	70.4085
1459.16	69.615
1462.3	67.0855
1465.43	64.1339
1468.56	59.5658
1471.7	55.7461
1474.83	50.3838
1477.96	46.6224
1481.08	41.872
1484.21	38.9806
1487.34	34.72
1490.46	30.5798
1493.58	27.7974
1496.71	24.9386
1499.83	23.3385
1502.95	21.3611
1506.07	20.9328
1509.18	21.2505
1512.3	20.3521
1515.41	20.8284
1518.53	21.4257
1521.64	22.5593
1524.75	24.4042
1527.86	25.3616
1530.97	27.2857
1534.08	28.1776
1537.19	27.9985
1540.29	29.2717
1543.4	31.6913
1546.5	33.0607
1549.6	34.6773
1552.7	35.238
1555.8	36.3444
1558.9	38.2216
1562	40.4119
1565.09	40.9224
1568.19	42.0247
1571.28	42.9322
1574.37	43.0488
1577.47	43.7465
1580.56	45.1714
1583.64	46.7277
1586.73	47.6366
1589.82	47.0926
1592.9	48.7647
1595.99	49.023
1599.07	49.6875
1602.15	49.8148
1605.23	49.3731
1608.31	48.751
1611.39	46.9363
1614.47	45.8208
1617.55	45.82
1620.62	45.549
1623.7	45.1115
1626.77	44.3253
1629.84	43.8823
1632.91	44.7075
1635.98	45.2627
1639.05	45.2749
1642.11	46.7256
1645.18	48.2179
1648.24	48.7188
1651.31	50.4411
1654.37	51.774
1657.43	51.7731
1660.49	51.2638
1663.55	51.8809
1666.61	51.2626
1669.66	51.1221
1672.72	50.7218
1675.77	49.4098
1678.83	47.602
1681.88	44.1607
1684.93	42.2454
1687.98	38.7207
1691.03	35.8015
1694.07	33.7557
1697.12	31.496
1700.17	27.214
1703.21	23.6923
1706.25	21.8986
1709.29	19.9195
1712.33	18.4675
1715.37	17.0044
1718.41	17.4495
1721.45	13.8779
1724.49	11.9702
1727.52	11.435
1730.55	10.371
1733.59	9.53468
1736.62	8.91712
1739.65	7.95036
1742.68	7.22983
1745.7	6.73632
1748.73	5.9961
1751.76	5.89842
1754.78	5.32262
1757.8	5.22124
1760.83	5.41384
1763.85	4.92282
1766.87	4.91885
1769.89	3.57321
1772.9	3.09149
1775.92	3.31419
1778.94	4.52137
1781.95	4.04148
1784.96	4.65585
1787.97	4.98805
1790.99	5.10005
1794	5.3185
1797	5.02286
1800.01	6.61327
1803.02	6.15391
1806.02	5.69133
1809.03	5.83546
1812.03	5.37533
1815.03	5.32676
1818.03	5.97573
1821.03	6.55619
1824.03	6.64077
1827.03	6.42083
1830.02	6.38039
1833.02	6.05181
1836.01	5.4621
1839.01	5.08604
1842	4.66818
1844.99	5.7368
1847.98	6.79439
1850.97	6.70295
1853.95	6.5126
1856.94	5.76422
1859.93	5.56148
1862.91	6.15475
1865.89	5.53503
1868.87	4.7947
1871.85	4.04457
1874.83	3.62821
1877.81	3.17176
1880.79	3.44588
1882.52	3.27352
1885.51	2.71635
1888.5	2.16988
1891.49	2.37831
1894.47	2.80408
1897.46	1.83403
1900.44	2.88313
1903.42	3.93911
1906.4	4.34856
1909.38	4.12974
1912.36	4.98904
1915.34	5.36202
1918.32	5.78446
1921.29	4.909
1924.27	5.17564
1927.24	4.38999
1930.21	3.45782
1933.18	3.12047
1936.15	3.01921
1939.12	2.56483
1942.09	2.12546
1945.06	2.45032
1948.02	1.76467
1950.99	2.06466
1953.95	1.34208
1956.91	1.08456
1959.88	1.08518
1962.84	1.31293
1965.8	2.29305
1968.75	2.08648
1971.71	2.7507
1974.67	3.35511
1977.62	3.61963
1980.58	3.90799
1983.53	4.938
1986.48	4.23068
1989.43	4.63359
1992.38	4.6373
1995.33	4.759
1998.27	4.60815
2001.22	4.59712
2004.16	5.45102
2007.11	6.04997
2010.05	6.75527
2012.99	6.81217
2015.93	7.54766
2018.87	8.04953
2021.81	8.71868
2024.75	8.28913
2027.69	8.41867
2030.62	8.44831
2033.56	8.12166
2036.49	6.85108
2039.42	6.29347
2042.35	5.69706
2045.28	5.88001
2048.21	6.31948
2051.14	6.14809
2054.07	5.64454
2056.99	5.25021
2059.92	5.35635
2062.84	5.72318
2065.76	5.07945
2068.68	5.68193
2071.6	6.6423
2074.52	6.6258
2077.44	6.90108
2080.36	7.57615
2083.27	6.96996
2086.19	7.35788
2089.1	7.09169
2092.02	6.70518
2094.93	6.55522
2097.84	5.858
2100.75	5.11004
2103.66	5.2748
2106.56	5.01055
2109.47	5.20021
2112.38	5.20517
2115.28	5.99678
2118.18	7.51186
2121.09	6.86666
2123.99	6.42354
2126.89	5.52075
2129.79	5.55502
2132.68	6.06236
2135.58	6.66995
2138.48	6.17995
2141.37	6.74024
2144.27	7.61471
2147.16	7.39023
2150.05	6.91613
2152.94	6.72399
2155.83	6.3742
2158.72	6.08931
2161.6	4.92298
2164.49	5.31255
2167.38	4.84523
2170.26	5.54466
2173.14	5.89334
2176.03	6.74749
2178.91	6.83383
2181.79	6.42323
2184.67	6.39792
2187.54	5.56669
2190.42	4.66038
2193.3	4.28817
2196.17	3.44213
2199.05	3.89407
2201.92	4.82711
2204.79	5.52168
2207.66	5.63991
2210.53	6.20064
2213.4	7.09278
2216.27	7.01981
2219.13	6.78496
2222	6.81827
2224.86	6.83587
2227.72	5.9142
2230.59	5.92615
2233.45	5.25307
2236.31	5.39462
2239.17	5.53054
2242.03	5.98616
2244.88	5.8946
2247.74	5.57512
2250.59	5.19163
2253.45	5.42024
2256.3	4.25181
2259.15	4.8286
2262	3.88983
2264.85	3.82453
2267.7	4.81044
2270.55	5.27759
2273.4	4.76502
2276.24	4.02399
2279.09	3.76795
2281.93	3.9399
2284.77	4.09401
2287.62	4.00508
2290.46	3.6998
2293.3	3.33665
2296.13	3.50937
2298.97	5.04392
2301.81	6.15737
2304.64	7.44274
2307.48	8.81675
2310.31	9.78595
2313.14	10.4587
2315.98	10.7123
2318.81	9.86267
2321.64	10.2162
2324.46	9.60568
2327.29	9.58522
2330.12	8.98872
2332.94	9.37918
2335.77	9.56542
2338.59	7.85387
2341.41	6.39152
2344.23	5.42881
2347.05	5.07011
2349.87	5.21955
2352.69	4.63418
2355.51	4.42311
2358.32	3.28304
2361.14	3.10894
2363.95	3.14871
2366.76	4.08037
2369.58	3.92527
2372.39	3.9983
2375.2	4.28741
2378	3.70214
2380.81	3.36594
2383.62	3.70398
2386.43	3.01473
2389.23	3.33984
2392.03	4.03487
2394.84	4.98364
2397.64	4.59746
2400.44	4.07323
2403.24	4.80725
2406.04	4.3382
2408.84	5.29054
2411.63	5.22093
2414.43	5.83908
2417.22	5.62762
2420.02	5.67559
2422.81	5.57437
2425.6	6.13802
2428.39	5.37728
2431.18	5.39484
2433.97	5.90852
2436.76	6.26214
2439.54	6.45547
2442.33	6.14652
2445.12	6.68772
2447.9	5.438
2450.68	5.59032
2453.46	4.33251
2456.24	4.3621
2459.02	4.00822
2461.8	3.79712
2464.58	3.53889
2467.36	3.22861
2470.13	2.86739
2472.91	3.7782
2475.68	2.96241
2478.45	2.54473
2481.23	1.79333
2484	1.51128
2486.77	1.57637
2489.54	1.95955
2492.3	2.22961
2495.07	2.52512
2497.84	3.24027
2500.6	3.46273
2503.36	4.13441
2506.13	4.19094
2508.89	3.36942
2511.65	3.49778
2514.41	3.71821
2517.17	3.8683
2519.93	4.45542
2522.68	5.41794
2525.44	6.9699
2528.19	7.37125
2530.95	7.68898
2533.7	8.01862
2536.45	8.65058
2539.2	8.79786
2541.95	8.77908
2544.7	8.68844
2547.45	7.38988
2550.2	6.49554
2552.94	6.04872
2555.69	5.6556
2558.43	4.47398
2561.18	4.66424
2563.92	3.80329
2566.66	2.50833
2569.4	1.59629
2572.14	0.451392
2574.88	0.245835
2577.61	-0.29849
2580.35	-0.238517
2583.09	0.108896
2585.82	0.730842
2588.55	1.32743
2591.29	2.36758
2594.02	3.69801
2596.75	3.29435
2599.48	3.65461
2602.21	4.48807
2604.93	4.11788
2607.66	3.96855
2610.39	4.15248
2613.11	3.88361
2615.83	3.62542
2618.56	3.6617
2621.28	4.04073
2624	4.34365
2626.72	4.77243
2629.44	4.8223
2632.15	4.98521
2634.87	5.1725
2637.59	5.56797
2640.3	5.54096
2643.02	5.95464
2645.73	6.2198
2648.44	6.85111
2651.15	7.0695
2653.86	7.21782
2656.57	6.6876
2659.28	6.63239
2661.99	6.91003
2664.69	6.60204
2667.4	6.19444
2670.1	5.54657
2672.81	5.07149
2675.51	4.60407
2678.21	4.02054
2680.91	3.7797
2683.61	4.29907
2686.31	4.80716
2689	4.83243
2691.7	4.55838
2694.4	4.27341
2697.09	4.00455
2699.79	4.41583
2702.48	4.41745
2705.17	4.49514
2707.86	4.57251
2710.55	5.74121
2713.24	5.81221
2715.93	6.48393
2718.62	6.64843
2721.3	6.7244
2723.99	7.08202
2726.67	7.99546
2729.35	7.98887
2732.04	7.84403
2734.72	7.29172
2737.4	7.15721
2740.08	6.88392
2742.76	6.60398
2745.43	6.4854
2748.11	6.03066
2750.79	5.52021
2753.46	5.14437
2756.14	3.77886
2758.81	3.44271
2761.48	2.89809
2764.15	2.27606
2766.82	1.69745
2769.49	1.8055
2772.16	2.14101
2774.82	2.66753
2777.49	2.31213
2780.16	2.3272
2782.82	1.80806
2785.48	1.96645
2788.15	1.62072
2790.81	0.985552
2793.47	0.30838
2796.13	0.290096
2798.79	0.77299
2801.44	0.895716
2804.1	0.0213963
2806.76	-0.241015
2809.41	-0.512337
2812.07	-1.0588
2814.72	-0.737407
2817.37	-0.935587
2820.02	-1.18086
2822.67	-0.0629593
2825.32	1.4978
2827.97	3.73373
2830.62	5.78565
2833.26	8.04083
2835.91	10.6684
2838.56	12.8734
2841.2	15.8445
2843.84	19.7112
2846.48	24.0919
2849.12	30.0615
2851.77	35.7251
2854.4	42.2807
2857.04	47.9218
2859.68	55.7968
2862.32	61.9809
2864.95	68.5866
2867.59	74.9537
2870.22	79.7659
2872.85	85.3635
2875.48	90.2683
2878.11	95.0491
2880.74	99.387
2883.37	103.035
2886	106.641
2888.63	110.54
2891.25	113.813
2893.88	116.767
2896.5	119.086
2899.13	122.927
2901.75	127.046
2904.37	130.902
2906.99	136.566
2909.61	142.335
2912.23	149.38
2914.85	156.015
2917.46	162.026
2920.08	167.173
2922.7	170.395
2925.31	173.769
2927.92	175.045
2930.54	175.888
2933.15	174.706
2935.76	173.599
2938.37	170.111
2940.98	166.814
2943.58	162.101
2946.19	156.17
2948.8	150.41
2951.4	143.735
2954.01	137.972
2956.61	131.892
2959.21	125.598
2961.81	120.05
2964.41	114.261
2967.01	108.792
2969.61	103.461
2972.21	99.1474
2974.81	94.1323
2977.4	89.6369
2980	83.5473
2982.59	78.1446
2985.18	71.1798
2987.78	64.902
2990.37	58.4899
2992.96	52.6886
2995.55	46.3365
2998.14	39.714
3000.73	33.9935
3003.31	28.2746
3005.9	23.4515
3008.48	19.1834
3011.07	14.9974
3013.65	11.2129
3016.23	8.12662
3018.81	6.19667
3021.4	3.79267
3023.97	2.11509
3026.55	1.56691
3029.13	0.671556
3031.71	0.594491
3034.28	0.994101
3036.86	1.82638
3039.43	3.01783
3042.01	4.78505
3044.58	6.3527
3047.15	7.44286
3049.72	8.09479
3052.29	8.73605
3054.86	9.41602
3057.43	9.23361
3060	8.828
3062.56	8.79745
3065.13	9.66838
3067.69	9.60424
3070.26	8.96749
3072.82	8.45924
3075.38	6.98517
3077.94	5.62035
3080.5	4.54353
3083.06	3.56472
3085.62	2.41299
3088.18	2.00705
3090.73	2.59931
3093.29	1.96444
3095.84	2.33468
3098.4	2.30783
3100.95	3.32399
3103.5	3.3212
3106.05	3.5263
3108.6	3.57895
3111.15	4.13205
3113.7	4.35301
3116.25	5.21764
3118.79	6.23598
3121.34	7.47561
3123.88	9.19094
3126.43	10.4995
3128.97	12.1454
3131.51	13.0755
3134.06	13.9553
3136.6	15.5011
3139.14	17.1112
3141.67	18.9146
3144.21	21.1715
3146.75	23.8476
3149.29	25.0996