File: data/Raman/poly_smoothed/Thy_00_07_19_1x_45s_532 nm_x100_100%_600 gr_mm_01.txt
#Acq. time (s)=	45
#Accumulations=	2
#Range (cm-¹)=	200...3150
#Windows=	2
#Auto scanning=	Off
#Autofocus=	Off
#Macrospot=	Off
#AutoExposure=	Off
#Spike filter=	Multiple accum.
#Delay time (s)=	0
#Binning=	1
#Readout mode=	Signal
#DeNoise=	Off
#ICS correction=	On
#Dark correction=	Off
#Inst. Process=	Off
#Detector Gain=	Best Dynamic Range
#Detector ADC=	20 kHz
#Detector temperature (°C)=	-69.85
#Instrument=	LabRAM HR Evol
#Detector=	Synapse
#Objective=	x100
#Grating=	600 gr/mm
#ND Filter=	100%
#Laser (nm)=	532
#Hole=	100.021
#Range=	Auto
#Laser Pol.=	No
#Raman. Pol.=	No
#Laser Pol. (°)=	-0.0007625
#Raman Pol. (°)=	89.9995
#Collection=	Microscope
#StageXY=	Marzhauser
#StageZ=	Marzhauser
#X (µm)=	9026.2
#Y (µm)=	-3077.8
#Z (µm)=	-54.7
#Full time(mm:ss)=	3:19
#Project=
#Sample=
#Site=
#Title=	Thy_00_07_19_2x_45s_532 nm_x100_100%_600 gr_mm
#Remark=
#Date=	28.06.2022 11:26
#Acquired=	28.06.2022 11:26:51
#Base:Fit=	10.08.2022 10:07:56
#Base:Sub=	10.08.2022 10:08:40
#Filter:Polynom=	16.08.2022 10:26:06
#AxisType[0]=Intens
#AxisUnit[0]=Cnt
#AxisType[1]=Spectr
#AxisUnit[1]=1/cm
200.407	10.7659
204.035	6.75394
207.665	5.68968
211.291	5.55547
214.916	5.09207
218.541	4.71791
222.163	5.05036
225.785	4.67809
229.404	6.69769
233.022	6.58737
236.638	6.88672
240.255	6.13087
243.868	5.86121
247.48	6.70851
251.091	7.89624
254.702	7.80281
258.31	6.29559
261.916	6.12666
265.521	6.13065
269.125	6.62211
272.727	6.99053
276.328	6.90724
279.927	7.42733
283.525	8.09592
287.121	8.8829
290.716	10.6885
294.31	12.4041
297.9	14.3925
301.491	16.7196
305.081	16.743
308.669	16.963
312.256	18.9996
315.839	20.3373
319.423	19.08
323.006	19.0262
326.585	18.9879
330.165	18.0752
333.741	16.593
337.318	16.0344
340.894	15.1687
344.466	14.458
348.039	13.6742
351.608	12.9032
355.176	11.6957
358.745	9.95778
362.31	8.65772
365.876	7.18273
369.439	8.45462
373	8.01836
376.56	9.04775
380.12	9.90527
383.677	10.8503
387.233	12.4986
390.787	11.6341
394.34	11.0942
397.894	12.0621
401.444	11.6838
404.993	11.2672
408.54	10.6028
412.086	10.0971
415.631	10.9236
419.174	10.4422
422.716	10.001
426.257	11.4124
429.794	12.4785
433.332	11.6728
436.868	10.8568
440.403	10.6201
443.937	9.90568
447.468	10.902
450.999	12.4538
454.528	13.5878
458.057	14.9119
461.582	15.7009
465.107	16.9134
468.629	18.1868
472.152	20.0705
475.672	21.1382
479.192	21.4695
482.709	21.7789
486.226	23.1987
489.74	23.2567
493.255	22.4074
496.767	22.7882
500.277	22.5714
503.788	22.1574
507.295	19.4196
510.801	19.9071
514.308	19.9427
517.811	20.44
521.313	18.5554
524.814	18.0137
528.313	18.6265
531.811	17.4988
535.308	17.0274
538.803	16.5838
542.297	14.7204
545.789	12.5688
549.281	11.1976
552.771	11.1117
556.259	10.9976
559.747	10.711
563.233	9.62011
566.717	9.17594
570.2	8.26374
573.68	7.04097
577.161	5.28947
580.64	5.8952
584.118	5.64562
587.593	7.03674
591.068	6.57297
594.54	7.0934
598.013	7.68422
601.484	7.28539
604.952	7.65703
608.421	7.29549
611.886	8.48294
615.35	9.31246
618.815	10.0049
622.276	10.882
625.738	10.1579
629.197	10.3818
632.655	9.7901
636.113	10.0221
639.568	12.441
643.021	10.6856
646.473	8.90603
649.924	8.27519
653.376	8.34474
656.824	8.40099
660.271	8.97767
663.716	10.2126
667.161	10.3953
670.604	10.9295
674.045	11.8444
677.486	10.6051
680.925	9.42698
684.361	9.66215
687.797	10.2738
691.232	11.0862
694.666	12.191
698.099	13.7817
701.528	15.5166
704.958	17.0634
708.387	18.727
711.814	19.2534
715.238	19.9494
718.663	19.8887
722.084	21.8954
725.506	23.6886
728.925	23.9554
732.345	27.0098
735.761	29.4785
739.178	32.448
742.592	33.5005
746.006	36.0908
749.417	39.2901
752.827	43.4413
756.236	47.3885
759.645	49.9616
763.051	50.8571
766.456	53.8435
769.859	55.5773
773.261	58.7885
776.664	60.4599
780.064	63.2803
783.462	65.444
786.859	67.4394
790.255	68.5418
793.649	70.1616
797.042	70.8835
800.434	71.6071
803.823	72.0568
807.212	72.4497
810.6	70.4839
813.987	69.6577
817.372	69.1543
820.754	67.2844
824.137	66.788
827.519	65.6487
830.897	64.275
834.276	63.7034
837.654	63.2637
841.029	62.0117
844.404	59.7277
847.776	57.2485
851.149	54.9556
854.519	52.9892
857.889	53.1828
861.256	50.5931
864.622	50.7487
867.988	49.5234
871.351	48.8889
874.713	48.2076
878.074	48.3656
881.435	46.7317
884.794	44.7184
888.15	43.7973
891.506	43.4268
894.861	42.2448
898.214	42.7441
901.566	42.6779
904.916	42.4588
908.266	43.2449
911.614	43.5191
914.961	44.1668
918.306	44.168
921.651	42.5129
924.994	42.0149
928.336	41.8462
931.674	39.9689
935.014	39.8372
938.352	38.8037
941.687	39.1099
945.022	38.7276
948.357	38.5168
951.688	38.2894
955.02	37.8002
958.348	35.164
961.678	31.532
965.004	31.0429
968.331	32.2574
971.655	34.3293
974.979	36.4275
978.3	38.1626
981.62	39.278
984.941	39.778
988.259	39.4775
991.575	38.2721
994.89	36.531
998.204	35.1403
1001.52	34.5829
1004.83	33.5609
1008.14	34.7655
1011.45	33.7668
1014.76	32.8223
1018.06	31.0813
1021.37	29.292
1024.67	27.9188
1027.97	25.2789
1031.27	24.0034
1034.57	20.5259
1037.87	15.4297
1041.17	12.5456
1044.47	13.5682
1047.76	16.1968
1051.06	16.3454
1054.35	16.9991
1057.64	15.853
1060.93	17.0126
1064.22	16.6578
1067.5	14.8712
1070.79	13.915
1074.08	13.9277
1077.36	15.4436
1080.64	16.5903
1083.92	17.8547
1087.2	18.7401
1090.48	20.2943
1093.76	21.2454
1097.03	23.1745
1100.31	23.0757
1103.58	22.3941
1106.85	22.1188
1110.12	22.2128
1113.39	20.7775
1116.66	17.2836
1119.93	17.5253
1123.19	16.5878
1126.46	15.2586
1129.72	12.8449
1132.98	11.2265
1136.24	10.1198
1139.5	8.9818
1142.76	8.60498
1146.01	6.672
1149.27	5.66918
1152.53	5.60871
1155.78	4.63077
1159.03	4.46062
1162.28	2.89526
1165.53	3.65279
1168.78	3.79883
1172.02	5.99823
1175.27	7.93484
1178.51	8.11264
1181.76	8.98291
1185	10.5656
1188.24	13.8044
1191.48	15.4097
1194.71	16.2984
1197.95	18.4616
1201.19	21.7529
1204.42	23.0101
1207.65	23.8225
1210.88	27.3936
1214.12	30.884
1217.35	33.7229
1220.57	36.6489
1223.8	40.6484
1227.03	42.1725
1230.25	44.156
1233.47	43.6236
1236.69	44.4982
1239.92	45.3421
1243.13	45.3939
1246.35	45.4314
1249.57	45.7789
1252.78	45.6545
1256	44.5986
1259.21	43.8839
1262.42	43.018
1265.63	42.5475
1268.84	41.0859
1272.05	40.6061
1275.26	39.8579
1278.46	41.322
1281.67	41.3292
1284.87	42.6943
1288.07	44.1159
1291.27	46.5308
1294.47	47.8722
1297.67	50.222
1300.87	53.4709
1304.06	55.6592
1307.26	59.458
1310.45	62.1592
1313.64	66.2307
1316.83	69.5196
1320.02	70.7612
1323.21	71.3702
1326.4	72.1176
1329.59	69.8739
1332.77	69.8768
1335.95	68.0391
1339.14	64.9536
1342.32	61.8586
1345.5	60.2078
1348.67	57.7338
1351.85	55.9952
1355.03	54.6996
1358.2	52.2656
1361.38	50.1098
1364.55	47.7806
1367.72	45.2535
1370.89	44.0004
1374.06	42.8897
1377.23	43.2125
1380.39	42.1218
1383.56	42.8432
1386.72	42.4423
1389.89	42.5561
1393.05	41.9647
1396.21	39.4241
1399.37	39.0208
1402.52	37.4168
1405.68	36.5251
1408.84	37.0098
1411.99	38.7072
1415.15	40.5961
1418.3	44.7621
1421.45	49.084
1424.6	55.0191
1427.75	59.0669
1430.89	62.5902
1434.04	67.3637
1437.18	73.213
1440.33	77.8243
1443.47	80.8216
1446.61	82.6237
1449.75	82.9626
1452.89	82.867
1456.03	82.7712
1459.16	79.8236
1462.3	76.1339
1465.43	72.5825
1468.56	67.9248
1471.7	59.9246
1474.83	53.617
1477.96	48.4973
1481.08	42.6968
1484.21	37.7719
1487.34	33.3368
1490.46	28.3709
1493.58	26.4213
1496.71	22.7304
1499.83	20.4183
1502.95	18.2603
1506.07	17.8253
1509.18	18.2401
1512.3	19.4739
1515.41	20.1378
1518.53	21.0524
1521.64	22.1574
1524.75	23.6269
1527.86	24.9329
1530.97	27.4984
1534.08	28.3831
1537.19	30.7222
1540.29	35.2149
1543.4	36.5609
1546.5	36.6229
1549.6	39.0866
1552.7	41.3608
1555.8	42.6071
1558.9	43.7323
1562	46.1882
1565.09	47.1777
1568.19	48.1593
1571.28	50.8107
1574.37	52.6026
1577.47	55.1596
1580.56	56.2015
1583.64	57.4873
1586.73	58.3699
1589.82	59.5557
1592.9	60.3907
1595.99	60.9237
1599.07	60.8416
1602.15	59.0286
1605.23	59.1203
1608.31	58.0664
1611.39	56.8402
1614.47	55.9575
1617.55	55.9134
1620.62	55.8763
1623.7	56.3107
1626.77	57.4688
1629.84	58.3509
1632.91	59.4713
1635.98	61.23
1639.05	63.5665
1642.11	65.8744
1645.18	69.2023
1648.24	71.7413
1651.31	73.4173
1654.37	75.2308
1657.43	76.2056
1660.49	76.1251
1663.55	75.7247
1666.61	75.6997
1669.66	73.5802
1672.72	71.928
1675.77	68.7768
1678.83	65.0607
1681.88	60.2867
1684.93	56.1518
1687.98	51.422
1691.03	47.8615
1694.07	43.9958
1697.12	38.7424
1700.17	34.2955
1703.21	29.498
1706.25	24.6219
1709.29	22.2261
1712.33	19.2706
1715.37	17.9347
1718.41	14.4772
1721.45	12.7376
1724.49	10.7417
1727.52	10.1088
1730.55	11.0451
1733.59	9.80597
1736.62	10.3968
1739.65	10.2825
1742.68	11.1803
1745.7	10.2488
1748.73	10.5148
1751.76	10.0474
1754.78	10.214
1757.8	10.178
1760.83	11.0836
1763.85	10.2139
1766.87	10.0552
1769.89	9.574
1772.9	9.09268
1775.92	8.2245
1778.94	9.12548
1781.95	9.44584
1784.96	9.04066
1787.97	8.98824
1790.99	8.96157
1794	8.17009
1797	8.98831
1800.01	8.93674
1803.02	8.16731
1806.02	7.49651
1809.03	6.30947
1812.03	5.49923
1815.03	4.24278
1818.03	3.73219
1821.03	3.1581
1824.03	3.69334
1827.03	2.5664
1830.02	2.78824
1833.02	2.76573
1836.01	1.91299
1839.01	1.14518
1842	1.24715
1844.99	1.31556
1847.98	2.10245
1850.97	3.99156
1853.95	4.57646
1856.94	4.89124
1859.93	5.63003
1862.91	5.37539
1865.89	5.29919
1868.87	5.41166
1871.85	5.31631
1874.83	4.51795
1877.81	4.58081
1880.79	5.12155
1882.52	4.86254
1885.51	5.36001
1888.5	4.8042
1891.49	6.37239
1894.47	5.84226
1897.46	5.06195
1900.44	5.02393
1903.42	4.40271
1906.4	3.80709
1909.38	4.16611
1912.36	5.05959
1915.34	5.78216
1918.32	5.98978
1921.29	6.89587
1924.27	6.06926
1927.24	5.16746
1930.21	4.73319
1933.18	4.02949
1936.15	2.61729
1939.12	3.10744
1942.09	3.7475
1945.06	4.1467
1948.02	3.26775
1950.99	3.80036
1953.95	3.89699
1956.91	4.47276
1959.88	3.74099
1962.84	3.91954
1965.8	3.28282
1968.75	3.23348
1971.71	3.02495
1974.67	3.46811
1977.62	3.66028
1980.58	3.53954
1983.53	4.40244
1986.48	4.18956
1989.43	5.52783
1992.38	5.70602
1995.33	5.61271
1998.27	5.15871
2001.22	4.93227
2004.16	5.15049
2007.11	4.9454
2010.05	5.23242
2012.99	5.46945
2015.93	5.39622
2018.87	6.20239
2021.81	6.1994
2024.75	6.12653
2027.69	6.2527
2030.62	6.6132
2033.56	5.6215
2036.49	6.01174
2039.42	5.21268
2042.35	5.38937
2045.28	4.99203
2048.21	4.15061
2051.14	3.1173
2054.07	3.60514
2056.99	2.88834
2059.92	3.57068
2062.84	3.75678
2065.76	3.16024
2068.68	2.52317
2071.6	1.86448
2074.52	1.55456
2077.44	1.43802
2080.36	1.98589
2083.27	1.74363
2086.19	2.52618
2089.1	3.31903
2092.02	3.88897
2094.93	4.1069
2097.84	4.77851
2100.75	3.9176
2103.66	3.67405
2106.56	3.64799
2109.47	3.30976
2112.38	3.76875
2115.28	2.97075
2118.18	3.12883
2121.09	2.38247
2123.99	2.88618
2126.89	4.07551
2129.79	4.43008
2132.68	4.39677
2135.58	5.01364
2138.48	4.84702
2141.37	4.74065
2144.27	4.29775
2147.16	4.7251
2150.05	5.37471
2152.94	5.18115
2155.83	5.14069
2158.72	5.25697
2161.6	4.71161
2164.49	4.34661
2167.38	3.92565
2170.26	3.37737
2173.14	3.05028
2176.03	3.43941
2178.91	4.08307
2181.79	4.02839
2184.67	4.16331
2187.54	4.7037
2190.42	5.29903
2193.3	5.81188
2196.17	6.66782
2199.05	6.91542
2201.92	5.95514
2204.79	6.72373
2207.66	7.82015
2210.53	7.22677
2213.4	5.57796
2216.27	5.07489
2219.13	4.26206
2222	4.24102
2224.86	3.66672
2227.72	3.4153
2230.59	3.04636
2233.45	3.8425
2236.31	3.90471
2239.17	4.12046
2242.03	4.08027
2244.88	4.14335
2247.74	4.39816
2250.59	3.66629
2253.45	4.4781
2256.3	4.37226
2259.15	4.64909
2262	5.35237
2264.85	5.74123
2267.7	6.17003
2270.55	5.89169
2273.4	6.90548
2276.24	7.91955
2279.09	6.87054
2281.93	6.23926
2284.77	6.23919
2287.62	7.07379
2290.46	6.40168
2293.3	6.02186
2296.13	6.9234
2298.97	7.84568
2301.81	9.68383
2304.64	9.99988
2307.48	9.95909
2310.31	9.45169
2313.14	9.87762
2315.98	9.56529
2318.81	9.36844
2321.64	9.61027
2324.46	9.09152
2327.29	7.64002
2330.12	6.88833
2332.94	6.98196
2335.77	6.02367
2338.59	4.64452
2341.41	4.10034
2344.23	3.435
2347.05	2.78142
2349.87	2.25847
2352.69	1.56013
2355.51	0.128911
2358.32	-0.134064
2361.14	-0.129074
2363.95	0.661938
2366.76	1.22444
2369.58	1.75959
2372.39	1.5156
2375.2	1.77927
2378	1.94345
2380.81	2.42362
2383.62	2.08081
2386.43	2.56926
2389.23	4.2252
2392.03	4.28758
2394.84	4.22056
2397.64	4.15904
2400.44	4.44972
2403.24	4.91222
2406.04	4.62171
2408.84	5.56613
2411.63	6.14653
2414.43	7.58689
2417.22	8.56226
2420.02	9.19239
2422.81	8.44601
2425.6	9.26206
2428.39	10.5762
2431.18	10.6804
2433.97	10.0334
2436.76	9.50063
2439.54	9.54097
2442.33	9.18898
2445.12	8.49269
2447.9	7.34154
2450.68	7.45901
2453.46	7.02303
2456.24	7.00715
2459.02	6.3315
2461.8	5.50617
2464.58	4.98354
2467.36	4.15995
2470.13	3.46495
2472.91	2.85954
2475.68	3.43229
2478.45	4.02617
2481.23	4.55992
2484	3.93715
2486.77	3.93483
2489.54	4.19445
2492.3	4.51873
2495.07	4.64347
2497.84	4.32366
2500.6	4.05586
2503.36	3.93281
2506.13	4.33875
2508.89	4.30596
2511.65	3.67269
2514.41	3.82966
2517.17	3.46046
2519.93	3.99772
2522.68	4.46938
2525.44	4.96679
2528.19	5.11715
2530.95	4.22861
2533.7	3.09553
2536.45	3.01073
2539.2	2.43545
2541.95	4.03576
2544.7	3.26815
2547.45	3.1506
2550.2	2.65492
2552.94	2.00296
2555.69	1.6483
2558.43	1.75731
2561.18	0.512607
2563.92	-0.268815
2566.66	-0.214215
2569.4	-0.0805836
2572.14	0.847111
2574.88	1.52995
2577.61	2.17781
2580.35	2.51752
2583.09	2.63707
2585.82	2.78758
2588.55	2.83742
2591.29	3.23822
2594.02	4.32506
2596.75	3.98709
2599.48	4.29914
2602.21	4.75561
2604.93	5.34585
2607.66	6.04821
2610.39	7.4703
2613.11	6.36997
2615.83	6.5324
2618.56	5.96824
2621.28	6.50148
2624	6.47213
2626.72	6.51862
2629.44	6.40069
2632.15	6.51101
2634.87	7.21168
2637.59	7.3098
2640.3	6.91794
2643.02	7.53359
2645.73	7.65525
2648.44	6.7609
2651.15	6.99161
2653.86	6.56595
2656.57	6.83674
2659.28	7.13001
2661.99	8.08507
2664.69	7.32845
2667.4	7.37144
2670.1	6.87774
2672.81	7.8834
2675.51	7.62158
2678.21	7.74107
2680.91	7.0973
2683.61	6.68732
2686.31	7.81296
2689	7.86107
2691.7	7.79921
2694.4	7.9008
2697.09	8.36229
2699.79	8.42613
2702.48	8.90144
2705.17	8.58494
2707.86	9.54769
2710.55	9.26168
2713.24	9.34687
2715.93	8.38374
2718.62	7.8536
2721.3	7.52335
2723.99	7.13586
2726.67	6.19484
2729.35	5.71625
2732.04	4.64901
2734.72	4.54891
2737.4	3.84646
2740.08	3.08128
2742.76	2.94852
2745.43	2.44791
2748.11	1.80168
2750.79	1.3677
2753.46	2.47056
2756.14	1.46945
2758.81	2.11517
2761.48	1.86883
2764.15	2.91227
2766.82	2.78957
2769.49	2.62594
2772.16	2.45108
2774.82	2.00631
2777.49	1.10057
2780.16	1.18916
2782.82	1.79559
2785.48	1.67194
2788.15	1.79137
2790.81	1.53743
2793.47	1.99134
2796.13	2.1065
2798.79	2.17801
2801.44	1.94341
2804.1	1.15952
2806.76	1.40547
2809.41	0.313011
2812.07	-0.375811
2814.72	-1.11276
2817.37	-0.81087
2820.02	0.163957
2822.67	2.20014
2825.32	5.41437
2827.97	8.25241
2830.62	12.7067
2833.26	15.4759
2835.91	20.0693
2838.56	23.8968
2841.2	29.4633
2843.84	36.2451
2846.48	44.2222
2849.12	52.4005
2851.77	60.5667
2854.4	69.5302
2857.04	77.9152
2859.68	85.348
2862.32	92.8514
2864.95	99.8396
2867.59	105.945
2870.22	111.085
2872.85	115.025
2875.48	118.387
2878.11	121.682
2880.74	126.108
2883.37	130.279
2886	133.02
2888.63	137.255
2891.25	140.065
2893.88	143.896
2896.5	147.575
2899.13	151.444
2901.75	156.39
2904.37	161.232
2906.99	168.178
2909.61	176.579
2912.23	185.554
2914.85	193.894
2917.46	201.917
2920.08	208.076
2922.7	214.26
2925.31	218.558
2927.92	222.313
2930.54	222.38
2933.15	220.757
2935.76	217.678
2938.37	213.817
2940.98	207.926
2943.58	201.874
2946.19	194.418
2948.8	185.209
2951.4	176.685
2954.01	168.566
2956.61	158.682
2959.21	149.864
2961.81	141.367
2964.41	133.264
2967.01	125.201
2969.61	118.983
2972.21	112.759
2974.81	106.351
2977.4	100.73
2980	94.7717
2982.59	86.7092
2985.18	80.3377
2987.78	73.7277
2990.37	65.7572
2992.96	58.318
2995.55	51.2434
2998.14	44.8592
3000.73	37.6877
3003.31	32.2944
3005.9	26.1067
3008.48	21.3282
3011.07	16.8383
3013.65	12.5862
3016.23	9.29233
3018.81	5.94404
3021.4	3.66999
3023.97	2.26031
3026.55	0.721995
3029.13	0.194761
3031.71	-0.196482
3034.28	0.0725149
3036.86	0.827128
3039.43	1.28453
3042.01	2.56462
3044.58	3.78939
3047.15	4.9957
3049.72	6.29118
3052.29	7.57143
3054.86	8.32285
3057.43	9.29156
3060	10.0037
3062.56	10.0309
3065.13	10.0424
3067.69	10.1999
3070.26	9.52979
3072.82	9.05969
3075.38	7.99516
3077.94	6.31437
3080.5	4.99052
3083.06	3.39785
3085.62	2.61194
3088.18	1.7599
3090.73	1.153
3093.29	1.68605
3095.84	1.79124
3098.4	2.7707
3100.95	2.80827
3103.5	3.72707
3106.05	5.06234
3108.6	6.02922
3111.15	6.46838
3113.7	7.40693
3116.25	8.74233
3118.79	9.75877
3121.34	10.6542
3123.88	12.0555
3126.43	12.6895
3128.97	14.0947
3131.51	16.3828
3134.06	17.3771
3136.6	19.2536
3139.14	20.0852
3141.67	22.3789
3144.21	24.8124
3146.75	27.6048
3149.29	31.6835