File: data/Raman/poly_smoothed/Thy_30_10_28_1x_45s_532 nm_x100_100%_600 gr_mm_01.txt
#Acq. time (s)=	45
#Accumulations=	2
#Range (cm-¹)=	200...3150
#Windows=	2
#Auto scanning=	Off
#Autofocus=	Off
#Macrospot=	Off
#AutoExposure=	Off
#Spike filter=	Multiple accum.
#Delay time (s)=	0
#Binning=	1
#Readout mode=	Signal
#DeNoise=	Off
#ICS correction=	On
#Dark correction=	Off
#Inst. Process=	Off
#Detector Gain=	Best Dynamic Range
#Detector ADC=	20 kHz
#Detector temperature (°C)=	-69.85
#Instrument=	LabRAM HR Evol
#Detector=	Synapse
#Objective=	x100
#Grating=	600 gr/mm
#ND Filter=	100%
#Laser (nm)=	532
#Hole=	100.021
#Range=	Auto
#Laser Pol.=	No
#Raman. Pol.=	No
#Laser Pol. (°)=	-0.0007625
#Raman Pol. (°)=	89.9995
#Collection=	Microscope
#StageXY=	Marzhauser
#StageZ=	Marzhauser
#X (µm)=	4766.5
#Y (µm)=	-7711
#Z (µm)=	584.65
#Full time(mm:ss)=	3:19
#Project=
#Sample=
#Site=
#Title=	Thy_30_10_28_2x_45s_532 nm_x100_100%_600 gr_mm
#Remark=
#Date=	30.06.2022 13:29
#Acquired=	30.06.2022 13:29:11
#Base:Fit=	10.08.2022 09:58:11
#Base:Sub=	10.08.2022 09:58:44
#Filter:Polynom=	16.08.2022 10:22:53
#AxisType[0]=Intens
#AxisUnit[0]=Cnt
#AxisType[1]=Spectr
#AxisUnit[1]=1/cm
200.533	0.534101
204.162	2.34004
207.792	2.87693
211.418	3.66627
215.044	4.95812
218.667	5.8201
222.289	6.99596
225.912	9.0214
229.531	9.11973
233.148	9.30412
236.766	12.0529
240.381	13.1395
243.994	13.517
247.606	12.4845
251.217	12.7542
254.828	13.3929
258.436	11.907
262.042	10.6151
265.647	11.3067
269.25	12.2657
272.852	10.3242
276.453	9.47404
280.052	8.93375
283.65	9.02357
287.247	9.3876
290.842	9.77296
294.436	10.351
298.028	10.3713
301.617	11.3216
305.206	12.7719
308.794	15.0374
312.381	16.2915
315.964	17.5816
319.548	18.6875
323.131	20.8243
326.71	21.9796
330.29	21.4484
333.868	20.9715
337.443	20.3353
341.018	20.2946
344.591	20.3313
348.163	18.3421
351.733	17.9932
355.303	18.3853
358.869	16.5341
362.435	15.4672
366.001	16.7877
369.563	16.8253
373.124	16.8314
376.686	16.3857
380.244	15.0154
383.801	15.5288
387.357	15.4727
390.911	15.2905
394.466	15.5705
398.018	15.2393
401.568	13.5324
405.117	14.3005
408.664	13.6195
412.21	14.2024
415.755	13.3206
419.298	14.5302
422.84	13.0912
426.38	11.8246
429.919	12.6207
433.455	12.1654
436.992	11.5758
440.527	10.9112
444.06	11.5008
447.593	10.9062
451.122	10.4356
454.651	9.69678
458.18	9.81402
461.705	9.3999
465.23	8.81569
468.752	8.709
472.275	8.89241
475.797	9.06575
479.315	9.90697
482.834	11.1344
486.349	11.7325
489.863	13.6983
493.378	15.494
496.889	18.8892
500.401	20.021
503.91	21.4535
507.417	21.9523
510.923	23.3633
514.43	23.8059
517.933	23.9446
521.435	22.332
524.936	22.9921
528.435	22.9597
531.933	22.1128
535.43	21.0345
538.927	18.2656
542.421	15.9526
545.913	14.1245
549.403	11.3716
552.893	10.1501
556.381	9.1366
559.868	7.68933
563.354	6.76131
566.839	4.72465
570.322	5.1516
573.802	5.59945
577.283	4.92291
580.762	6.34934
584.24	7.3393
587.714	8.39808
591.19	9.05052
594.663	9.52437
598.134	10.173
601.605	10.4881
605.073	11.3591
608.542	11.4953
612.007	11.9112
615.473	11.1013
618.936	10.7758
622.397	10.3146
625.859	9.64334
629.318	10.7236
632.775	11.9923
636.233	13.165
639.688	13.6681
643.142	14.5252
646.594	14.9571
650.045	16.2662
653.496	17.8485
656.944	19.5842
660.391	21.2847
663.837	23.0747
667.281	25.5128
670.724	27.9912
674.166	28.7085
677.606	30.4727
681.045	31.6729
684.483	32.3302
687.917	32.41
691.352	32.3787
694.786	32.3062
698.219	33.7713
701.65	34.0988
705.078	34.028
708.506	35.7455
711.934	36.0155
715.358	38.7752
718.782	40.3402
722.204	42.7319
725.626	45.4254
729.045	46.9571
732.464	50.0002
735.881	52.7751
739.297	54.4424
742.711	57.6325
746.125	59.5799
749.537	62.7193
752.946	66.5999
756.357	69.8722
759.764	71.8719
763.17	72.4974
766.575	73.7202
769.978	76.9073
773.382	78.5201
776.783	79.3591
780.182	79.0303
783.581	78.5401
786.978	78.2704
790.373	79.3988
793.768	80.7469
797.161	82.6072
800.552	83.1978
803.941	83.728
807.33	83.2765
810.718	83.0112
814.105	81.8767
817.49	81.1569
820.873	79.6278
824.256	78.7741
827.637	79.462
831.016	78.0843
834.395	77.4604
837.772	76.6203
841.147	75.7175
844.522	74.049
847.894	73.308
851.267	72.2866
854.637	69.1413
858.007	67.1028
861.374	64.7308
864.739	62.6476
868.106	60.2455
871.469	59.4754
874.831	58.3718
878.193	56.72
881.553	54.777
884.911	53.0891
888.268	53.0253
891.623	51.4658
894.978	49.0695
898.331	48.1164
901.683	48.2143
905.033	47.8376
908.383	48.5681
911.731	49.8084
915.078	50.3844
918.423	50.5877
921.768	50.8254
925.111	50.4615
928.452	51.9339
931.791	50.0502
935.13	48.2181
938.468	47.6657
941.803	47.1107
945.139	45.0137
948.473	42.7176
951.804	41.9753
955.136	41.0532
958.465	39.3815
961.794	39.0593
965.12	39.3402
968.447	40.3555
971.771	40.5502
975.095	39.5258
978.417	40.6015
981.737	41.4153
985.057	42.0438
988.375	41.3284
991.691	41.3944
995.006	41.5649
998.32	40.5676
1001.63	42.3462
1004.95	43.1972
1008.26	43.7955
1011.56	43.2064
1014.87	42.1836
1018.18	41.6621
1021.48	42.303
1024.79	41.7102
1028.09	42.7501
1031.39	42.9045
1034.69	42.1202
1037.99	41.7476
1041.29	40.3686
1044.58	38.8094
1047.88	37.847
1051.17	36.7486
1054.46	35.6649
1057.75	33.3462
1061.04	31.6145
1064.33	28.2695
1067.62	26.7053
1070.9	24.312
1074.19	23.9389
1077.47	23.3784
1080.76	24.0081
1084.04	23.6873
1087.32	23.3267
1090.59	22.8455
1093.87	23.4252
1097.15	25.135
1100.42	26.7507
1103.69	27.4875
1106.97	27.8585
1110.24	28.6435
1113.51	27.2245
1116.77	27.3658
1120.04	26.9218
1123.31	25.471
1126.57	24.6532
1129.83	24.2789
1133.1	22.3024
1136.36	19.4183
1139.62	17.0056
1142.87	15.1562
1146.13	13.8523
1149.38	12.9651
1152.64	10.7218
1155.89	10.9557
1159.14	8.70809
1162.39	6.29949
1165.64	4.5095
1168.89	4.11387
1172.14	4.65514
1175.38	5.13997
1178.63	5.95265
1181.87	7.22348
1185.11	7.53305
1188.35	8.21114
1191.59	10.1411
1194.83	12.8321
1198.07	16.1441
1201.3	17.9857
1204.53	19.8366
1207.77	22.5613
1211	24.5469
1214.23	26.7139
1217.46	29.4405
1220.69	32.8921
1223.91	36.1186
1227.14	38.6815
1230.36	40.7707
1233.59	43.0242
1236.81	42.2616
1240.03	42.2079
1243.25	42.8745
1246.46	44.4609
1249.68	45.2731
1252.9	46.3657
1256.11	45.6708
1259.32	47.0636
1262.54	46.063
1265.75	46.2604
1268.96	48.1968
1272.16	50.8659
1275.37	51.3981
1278.57	53.3768
1281.78	57.1154
1284.98	59.5492
1288.18	59.6695
1291.38	60.0062
1294.58	61.8083
1297.78	65.9174
1300.98	70.7211
1304.17	72.2627
1307.37	74.8941
1310.56	76.9875
1313.76	78.2934
1316.95	79.2907
1320.14	80.6998
1323.32	80.4347
1326.51	81.3225
1329.7	80.1483
1332.88	77.2447
1336.07	76.1613
1339.25	74.4905
1342.43	71.2656
1345.61	69.3929
1348.79	66.1186
1351.96	63.6571
1355.14	60.8551
1358.31	59.8683
1361.49	54.7688
1364.66	50.1975
1367.83	46.0512
1371	45.7831
1374.17	47.1385
1377.34	44.311
1380.5	42.2825
1383.67	40.1935
1386.83	38.825
1390	36.6354
1393.16	36.0887
1396.32	34.5353
1399.48	32.6906
1402.64	31.7778
1405.79	31.6664
1408.95	32.2829
1412.1	33.1229
1415.26	36.3539
1418.41	38.7262
1421.56	41.8373
1424.71	45.9517
1427.86	50.9156
1431	55.5261
1434.15	60.0986
1437.29	62.3288
1440.44	65.2677
1443.58	68.3827
1446.72	70.012
1449.86	70.3271
1453	70.0174
1456.14	68.2863
1459.27	65.62
1462.41	62.7445
1465.54	59.0308
1468.67	54.2289
1471.81	49.175
1474.94	43.6794
1478.07	38.4405
1481.19	34.3333
1484.32	30.4434
1487.45	26.8737
1490.57	23.6387
1493.69	22.5774
1496.82	20.4025
1499.94	19.2442
1503.06	18.1765
1506.17	17.033
1509.29	16.0355
1512.41	15.2567
1515.52	15.7182
1518.64	17.5504
1521.75	18.42
1524.86	19.2289
1527.97	20.7636
1531.08	22.0355
1534.19	24.9646
1537.29	27.5319
1540.4	30.2642
1543.5	33.8673
1546.61	38.3762
1549.71	41.9387
1552.81	46.0717
1555.91	51.1953
1559.01	55.0501
1562.11	59.7345
1565.2	62.757
1568.29	66.3239
1571.39	69.8349
1574.48	71.9413
1577.57	74.1474
1580.66	75.6723
1583.75	75.0161
1586.84	73.876
1589.93	73.1672
1593.01	71.7022
1596.1	69.2397
1599.18	66.8481
1602.26	63.8552
1605.34	61.3221
1608.42	59.4155
1611.5	58.0484
1614.58	55.8251
1617.65	55.309
1620.73	56.7401
1623.8	56.6997
1626.87	58.0637
1629.95	60.185
1633.02	61.6177
1636.09	62.9018
1639.15	64.7491
1642.22	67.3943
1645.29	68.7196
1648.35	69.8553
1651.42	71.3283
1654.48	72.0705
1657.54	70.1099
1660.6	67.6161
1663.66	64.2857
1666.72	61.4151
1669.77	58.1066
1672.83	53.6463
1675.88	48.5373
1678.93	43.8613
1681.99	38.8037
1685.04	34.1676
1688.09	29.0931
1691.13	25.2897
1694.18	22.1339
1697.23	19.1963
1700.27	16.6304
1703.32	14.9563
1706.36	13.9838
1709.4	11.525
1712.44	10.18
1715.48	9.69618
1718.52	8.28349
1721.56	6.63233
1724.59	6.52368
1727.63	6.0328
1730.66	4.61066
1733.69	3.47582
1736.72	2.65891
1739.75	3.10782
1742.78	3.11828
1745.81	2.04289
1748.84	0.804343
1751.86	0.171562
1754.89	-0.0316409
1757.91	0.0816258
1760.93	0.170551
1763.95	0.108597
1766.97	0.107996
1769.99	1.12102
1773.01	2.73859
1776.03	2.57301
1779.04	4.07213
1782.06	3.95336
1785.07	3.18152
1788.08	3.29759
1791.09	3.11532
1794.1	2.62542
1797.11	2.40605
1800.12	2.57301
1803.12	2.44433
1806.13	2.99907
1809.13	3.27185
1812.14	4.6169
1815.14	4.93293
1818.14	4.88537
1821.14	4.97545
1824.14	4.68469
1827.13	5.69784
1830.13	6.13995
1833.12	6.16288
1836.12	5.6708
1839.11	6.03058
1842.1	5.9086
1845.09	6.72478
1848.08	6.86662
1851.07	7.11431
1854.06	6.07975
1857.04	5.4477
1860.03	5.08331
1863.01	4.95914
1866	4.78518
1868.98	5.17584
1871.96	4.51206
1874.94	4.79467
1877.92	5.39704
1880.89	5.97129
1882.48	6.13378
1885.47	6.19551
1888.46	6.45507
1891.44	6.45458
1894.43	6.83926
1897.41	7.44756
1900.4	7.77676
1903.38	7.61222
1906.36	7.82715
1909.34	7.92356
1912.32	8.77749
1915.29	9.08463
1918.27	9.12553
1921.25	9.80066
1924.22	9.9497
1927.2	11.066
1930.17	10.9587
1933.14	11.1335
1936.11	11.6625
1939.08	11.3625
1942.05	12.0209
1945.01	12.4093
1947.98	12.5161
1950.94	12.4413
1953.91	12.1016
1956.87	11.1521
1959.83	11.3897
1962.79	10.3605
1965.75	10.0715
1968.71	9.88443
1971.67	9.96201
1974.62	9.91036
1977.58	9.32664
1980.53	8.96437
1983.48	8.7026
1986.43	8.95645
1989.38	9.10752
1992.33	9.29959
1995.28	10.4049
1998.23	10.4685
2001.18	11.247
2004.12	10.7617
2007.06	10.4307
2010.01	10.9856
2012.95	12.3933
2015.89	12.5726
2018.83	12.3584
2021.77	11.8462
2024.71	11.8233
2027.64	11.7495
2030.58	11.1351
2033.51	11.8765
2036.45	11.832
2039.38	13.0111
2042.31	14.0117
2045.24	13.6469
2048.17	14.6359
2051.1	14.6952
2054.02	15.5914
2056.95	16.5676
2059.87	17.397
2062.8	17.8239
2065.72	18.6565
2068.64	19.8173
2071.56	20.6797
2074.48	21.8646
2077.4	23.5739
2080.31	24.1718
2083.23	25.001
2086.14	24.7639
2089.06	24.7489
2091.97	24.3065
2094.88	25.2937
2097.79	25.7566
2100.7	27.138
2103.61	28.687
2106.52	30.0187
2109.43	31.0277
2112.33	31.4569
2115.24	32.6031
2118.14	34.6183
2121.04	36.2243
2123.94	38.6088
2126.84	41.6464
2129.74	44.3741
2132.64	46.3804
2135.54	49.2121
2138.43	51.6343
2141.33	54.7882
2144.22	57.2257
2147.11	59.5229
2150.01	62.755
2152.9	63.5978
2155.79	66.0744
2158.67	67.4031
2161.56	68.2483
2164.45	70.4729
2167.33	71.8454
2170.22	72.2965
2173.1	72.6895
2175.98	72.5532
2178.86	71.9667
2181.74	70.8094
2184.62	70.047
2187.5	69.8558
2190.38	69.2604
2193.25	66.8186
2196.13	65.9769
2199	63.9902
2201.88	62.0557
2204.75	59.135
2207.62	57.0219
2210.49	54.1555
2213.36	52.1307
2216.22	49.9531
2219.09	47.428
2221.96	45.4942
2224.82	42.8737
2227.68	40.6615
2230.55	38.2627
2233.41	37.0089
2236.27	35.9946
2239.12	34.8264
2241.98	33.2843
2244.84	33.3357
2247.7	32.372
2250.55	31.2522
2253.41	30.6044
2256.26	30.1259
2259.11	29.085
2261.96	28.1939
2264.81	27.6792
2267.66	27.2879
2270.51	27.3243
2273.35	26.6679
2276.2	26.1637
2279.04	25.2203
2281.89	23.5851
2284.73	22.6911
2287.57	21.6165
2290.41	20.8215
2293.25	18.8716
2296.09	18.348
2298.93	18.0586
2301.76	17.5548
2304.6	18.3132
2307.44	18.1147
2310.27	18.7446
2313.1	18.7807
2315.93	18.5778
2318.76	17.8588
2321.59	18.0104
2324.42	17.8615
2327.25	17.8883
2330.07	17.4829
2332.9	17.0681
2335.72	16.6739
2338.55	16.6433
2341.37	15.3574
2344.19	14.9219
2347.01	14.1932
2349.83	12.7527
2352.65	11.0787
2355.46	10.4559
2358.28	9.41508
2361.09	8.84374
2363.91	8.81781
2366.72	8.55352
2369.53	8.03456
2372.34	8.6341
2375.15	9.35767
2377.96	8.55603
2380.77	8.54331
2383.58	8.37579
2386.38	8.8796
2389.19	9.63383
2391.99	9.52735
2394.8	9.10402
2397.6	9.7852
2400.4	9.85846
2403.2	10.1472
2406	9.59849
2408.79	9.43458
2411.59	8.55503
2414.39	9.14675
2417.18	8.68916
2419.98	9.26209
2422.77	9.07351
2425.56	8.78295
2428.35	8.22727
2431.14	7.78965
2433.93	7.10927
2436.72	7.53431
2439.5	6.94922
2442.29	7.69289
2445.07	6.35483
2447.86	5.97967
2450.64	4.83991
2453.42	4.01824
2456.2	3.18678
2458.98	1.70973
2461.76	0.758675
2464.54	0.726963
2467.32	0.445056
2470.09	0.877969
2472.87	0.450007
2475.64	0.827296
2478.41	0.549371
2481.18	1.77282
2483.95	1.88404
2486.72	1.77492
2489.49	2.1194
2492.26	2.77597
2495.03	2.70602
2497.79	2.67592
2500.56	3.75104
2503.32	4.94736
2506.09	5.26377
2508.85	5.62816
2511.61	5.12119
2514.37	5.08065
2517.13	4.8103
2519.89	4.31855
2522.64	4.60299
2525.4	4.1295
2528.15	3.94027
2530.91	3.38657
2533.66	3.42746
2536.41	3.42283
2539.16	3.79724
2541.91	3.30696
2544.66	3.09199
2547.41	2.85632
2550.16	2.568
2552.9	1.36057
2555.65	1.22877
2558.39	0.635404
2561.13	-0.200815
2563.88	-0.511271
2566.62	0.430767
2569.36	0.676673
2572.1	1.54777
2574.84	1.08846
2577.57	0.938703
2580.31	0.956691
2583.05	1.21315
2585.78	0.885913
2588.51	1.22206
2591.24	0.866862
2593.98	0.37326
2596.71	0.19136
2599.44	0.761033
2602.16	1.67036
2604.89	2.24857
2607.62	2.31074
2610.34	2.48687
2613.07	3.37654
2615.79	3.21067
2618.52	2.88974
2621.24	2.55832
2623.96	3.08914
2626.68	2.99222
2629.4	3.35741
2632.11	3.5091
2634.83	3.31118
2637.55	2.86111
2640.26	3.31209
2642.98	2.40696
2645.69	2.85087
2648.4	2.43686
2651.11	2.31482
2653.82	2.27608
2656.53	2.52477
2659.24	2.43675
2661.95	2.40183
2664.65	3.44045
2667.36	4.57066
2670.06	5.78021
2672.76	6.01932
2675.47	6.6023
2678.17	6.37949
2680.87	6.42935
2683.57	5.69427
2686.27	5.20566
2688.97	5.08999
2691.66	5.08091
2694.36	4.85495
2697.05	4.30947
2699.75	3.76823
2702.44	3.62308
2705.13	4.18055
2707.82	4.66871
2710.51	4.28452
2713.2	4.013
2715.89	4.25187
2718.57	4.17991
2721.26	4.45112
2723.95	4.37377
2726.63	4.32755
2729.31	4.2032
2732	4.92419
2734.68	4.90093
2737.36	5.09358
2740.04	4.7353
2742.72	4.16557
2745.39	3.71206
2748.07	4.03713
2750.75	3.88778
2753.42	4.23821
2756.09	3.72036
2758.77	3.39982
2761.44	4.33558
2764.11	3.94874
2766.78	3.84273
2769.45	3.00631
2772.12	3.7014
2774.78	3.55635
2777.45	3.71574
2780.12	3.53604
2782.78	2.65706
2785.44	1.96633
2788.11	1.98142
2790.77	1.39736
2793.43	0.785729
2796.09	0.636289
2798.75	0.34618
2801.4	-0.890219
2804.06	-0.467575
2806.72	-0.580324
2809.37	-1.24057
2812.03	-1.72282
2814.68	-2.04172
2817.33	-1.5651
2819.98	-0.62886
2822.63	1.05995
2825.28	2.99234
2827.93	5.48537
2830.58	7.98893
2833.23	12.2582
2835.87	15.747
2838.52	21.1908
2841.16	26.5277
2843.8	31.0256
2846.44	36.5206
2849.08	43.0807
2851.73	50.8148
2854.36	57.9607
2857	66.2124
2859.64	74.3195
2862.28	82.4843
2864.91	89.2006
2867.55	95.095
2870.18	100.54
2872.81	105.408
2875.44	109.071
2878.07	113.057
2880.7	116.873
2883.33	120.424
2885.96	123.109
2888.59	125.928
2891.21	129.997
2893.84	135.501
2896.46	140.34
2899.09	145.07
2901.71	151.319
2904.33	158.479
2906.95	166.506
2909.57	175.669
2912.19	186.799
2914.81	196.967
2917.43	207.431
2920.04	217.631
2922.66	224.874
2925.27	230.755
2927.88	234.963
2930.5	236.741
2933.11	237.115
2935.72	236.286
2938.33	234.478
2940.94	230.593
2943.54	225.819
2946.15	219.745
2948.76	212.654
2951.36	204.956
2953.97	198.582
2956.57	190.762
2959.17	182.731
2961.77	174.553
2964.37	167.777
2966.97	160.617
2969.57	153.38
2972.17	147.195
2974.77	139.745
2977.36	132.709
2979.96	124.816
2982.55	116.94
2985.15	108.415
2987.74	99.8949
2990.33	91.3211
2992.92	82.738
2995.51	75.0032
2998.1	66.7324
3000.69	60.5302
3003.27	53.6005
3005.86	47.3177
3008.44	42.5821
3011.03	37.9333
3013.61	33.5421
3016.19	30.5249
3018.78	27.8684
3021.36	25.5847
3023.94	23.6204
3026.51	21.7133
3029.09	20.8839
3031.67	19.516
3034.24	19.7743
3036.82	19.0352
3039.39	20.316
3041.97	21.3689
3044.54	21.9653
3047.11	23.0036
3049.68	23.673
3052.25	23.673
3054.82	23.4938
3057.39	23.2069
3059.96	22.2983
3062.52	21.7851
3065.09	21.1299
3067.65	18.9324
3070.22	17.9785
3072.78	16.3733
3075.34	14.4806
3077.9	12.6069
3080.46	10.4437
3083.02	8.15397
3085.58	5.7654
3088.14	4.25143
3090.69	2.50898
3093.25	1.50657
3095.8	0.308317
3098.36	-0.693815
3100.91	-0.938842
3103.46	-1.45694
3106.01	-0.857343
3108.56	-1.37055
3111.11	-1.0454
3113.66	-0.576641
3116.21	-0.719886
3118.76	-0.594743
3121.3	-0.660907
3123.85	-0.575206
3126.39	-0.237547
3128.93	-0.221344
3131.48	-0.21826
3134.02	0.312519
3136.56	0.816065
3139.1	1.35743
3141.64	1.9073
3144.17	2.04324
3146.71	3.36569
3149.25	3.7074