File: data/Raman/poly_smoothed/Thy_00_07_1_1x_45s_532 nm_x100_100%_600 gr_mm_01.txt
#Acq. time (s)=	45
#Accumulations=	2
#Range (cm-¹)=	200...3150
#Windows=	2
#Auto scanning=	Off
#Autofocus=	Off
#Macrospot=	Off
#AutoExposure=	Off
#Spike filter=	Multiple accum.
#Delay time (s)=	0
#Binning=	1
#Readout mode=	Signal
#DeNoise=	Off
#ICS correction=	On
#Dark correction=	Off
#Inst. Process=	Off
#Detector Gain=	Best Dynamic Range
#Detector ADC=	20 kHz
#Detector temperature (°C)=	-69.85
#Instrument=	LabRAM HR Evol
#Detector=	Synapse
#Objective=	x100
#Grating=	600 gr/mm
#ND Filter=	100%
#Laser (nm)=	532
#Hole=	100.021
#Range=	Auto
#Laser Pol.=	No
#Raman. Pol.=	No
#Laser Pol. (°)=	-0.0007625
#Raman Pol. (°)=	89.9995
#Collection=	Microscope
#StageXY=	Marzhauser
#StageZ=	Marzhauser
#X (µm)=	8999.8
#Y (µm)=	-3087.6
#Z (µm)=	-55.8
#Full time(mm:ss)=	3:05
#Project=
#Sample=
#Site=
#Title=	Thy_00_07_1_2x_45s_532 nm_x100_100%_600 gr_mm
#Remark=
#Date=	28.06.2022 09:53
#Acquired=	28.06.2022 09:53:41
#Edit:Spike=	28.06.2022 09:54:32
#Base:Fit=	10.08.2022 10:07:56
#Base:Sub=	10.08.2022 10:08:40
#Filter:Polynom=	16.08.2022 10:26:06
#AxisType[0]=Intens
#AxisUnit[0]=Cnt
#AxisType[1]=Spectr
#AxisUnit[1]=1/cm
200.407	77.9174
204.035	59.9827
207.665	47.2471
211.291	39.2726
214.916	34.1748
218.541	28.7774
222.163	24.961
225.785	21.3736
229.404	16.8897
233.022	15.7433
236.638	12.7747
240.255	10.567
243.868	9.58175
247.48	8.66757
251.091	8.19846
254.702	7.59837
258.31	7.51658
261.916	8.10468
265.521	8.99324
269.125	7.20623
272.727	4.65298
276.328	3.78546
279.927	1.43598
283.525	1.14866
287.121	1.66359
290.716	1.67352
294.31	3.61665
297.9	5.0071
301.491	4.59641
305.081	5.69155
308.669	5.14215
312.256	4.93913
315.839	4.68041
319.423	5.03965
323.006	7.23418
326.585	7.13193
330.165	6.88525
333.741	7.09897
337.318	6.61189
340.894	6.01425
344.466	5.74477
348.039	6.72191
351.608	6.83463
355.176	4.80359
358.745	2.87675
362.31	2.40249
365.876	1.93518
369.439	3.20958
373	3.36466
376.56	3.65059
380.12	2.14167
383.677	3.14836
387.233	2.52745
390.787	3.49947
394.34	3.22652
397.894	1.68184
401.444	3.106
404.993	3.09556
408.54	4.20645
412.086	4.51214
415.631	3.21727
419.174	3.39924
422.716	3.89828
426.257	2.40264
429.794	1.44034
433.332	-0.0787409
436.868	-1.42285
440.403	-1.80874
443.937	-1.06581
447.468	1.97411
450.999	5.64488
454.528	10.2643
458.057	14.3588
461.582	17.9059
465.107	21.8346
468.629	25.3199
472.152	29.3186
475.672	32.254
479.192	36.8954
482.709	39.4373
486.226	42.2231
489.74	45.4107
493.255	46.0524
496.767	47.1621
500.277	45.8011
503.788	44.3554
507.295	41.9416
510.801	38.7119
514.308	35.5784
517.811	31.5678
521.313	28.2899
524.814	26.7725
528.313	25.2398
531.811	24.8187
535.308	24.3094
538.803	23.5027
542.297	20.594
545.789	20.2222
549.281	19.6449
552.771	19.5033
556.259	17.9315
559.747	18.6163
563.233	18.7056
566.717	18.9519
570.2	16.8501
573.68	15.9397
577.161	13.9787
580.64	12.4493
584.118	10.8888
587.593	9.10456
591.068	7.19689
594.54	7.17969
598.013	5.87602
601.484	5.60667
604.952	5.36675
608.421	5.88972
611.886	4.71809
615.35	4.18533
618.815	3.07117
622.276	3.50984
625.738	5.19734
629.197	4.97916
632.655	7.61901
636.113	8.32482
639.568	11.2148
643.021	12.8132
646.473	14.2551
649.924	15.1302
653.376	17.0472
656.824	18.2524
660.271	19.338
663.716	19.8254
667.161	20.9612
670.604	22.551
674.045	24.6107
677.486	27.6379
680.925	28.6998
684.361	31.1813
687.797	33.4209
691.232	35.7713
694.666	37.6497
698.099	36.283
701.528	37.992
704.958	38.431
708.387	40.5543
711.814	40.4999
715.238	42.8238
718.663	44.8959
722.084	45.9036
725.506	48.594
728.925	49.6003
732.345	50.6331
735.761	54.0773
739.178	56.9608
742.592	60.2808
746.006	63.9922
749.417	69.6059
752.827	74.1302
756.236	78.3341
759.645	82.3202
763.051	85.7736
766.456	87.1223
769.859	88.2374
773.261	91.4066
776.664	93.2732
780.064	93.3995
783.462	92.8647
786.859	93.5541
790.255	92.5457
793.649	92.906
797.042	92.5129
800.434	92.3817
803.823	90.348
807.212	90.4977
810.6	88.8706
813.987	88.4613
817.372	90.7349
820.754	92.8645
824.137	96.9354
827.519	99.4694
830.897	102.948
834.276	105.507
837.654	106.274
841.029	107.907
844.404	107.896
847.776	106.489
851.149	104.327
854.519	101.326
857.889	98.087
861.256	94.5954
864.622	91.4474
867.988	87.1296
871.351	83.2892
874.713	80.9192
878.074	77.9224
881.435	75.0593
884.794	69.9873
888.15	67.5918
891.506	65.2075
894.861	63.8148
898.214	65.8912
901.566	66.2785
904.916	68.2747
908.266	70.0173
911.614	73.9335
914.961	76.9843
918.306	80.4398
921.651	82.255
924.994	82.6904
928.336	82.3242
931.674	80.8513
935.014	78.5116
938.352	77.1831
941.687	75.6607
945.022	72.9088
948.357	69.3626
951.688	66.6732
955.02	64.6622
958.348	60.1622
961.678	54.5539
965.004	52.6989
968.331	52.0634
971.655	51.9217
974.979	52.1914
978.3	53.5576
981.62	54.3582
984.941	54.9231
988.259	56.7734
991.575	58.038
994.89	58.7222
998.204	60.4063
1001.52	61.6384
1004.83	61.9698
1008.14	63.1811
1011.45	64.8929
1014.76	66.6754
1018.06	67.5874
1021.37	68.3728
1024.67	66.6466
1027.97	66.0801
1031.27	64.5477
1034.57	61.4344
1037.87	57.4271
1041.17	55.3424
1044.47	57.2862
1047.76	59.9493
1051.06	60.1704
1054.35	60.0412
1057.64	59.8103
1060.93	58.7551
1064.22	57.3638
1067.5	55.9756
1070.79	56.7333
1074.08	58.4293
1077.36	58.3525
1080.64	58.4477
1083.92	60.4509
1087.2	62.4322
1090.48	64.5027
1093.76	66.1876
1097.03	69.7027
1100.31	71.0339
1103.58	70.5576
1106.85	70.2891
1110.12	70.2884
1113.39	67.5891
1116.66	64.1272
1119.93	63.8108
1123.19	63.2773
1126.46	60.0238
1129.72	57.1447
1132.98	53.4348
1136.24	49.8287
1139.5	47.0744
1142.76	43.9044
1146.01	40.6719
1149.27	36.8492
1152.53	32.6374
1155.78	27.8587
1159.03	22.4254
1162.28	18.3943
1165.53	16.0847
1168.78	14.6289
1172.02	15.5302
1175.27	16.8719
1178.51	17.7409
1181.76	17.5057
1185	19.4815
1188.24	20.187
1191.48	21.3964
1194.71	23.3967
1197.95	24.9552
1201.19	29.7074
1204.42	32.9037
1207.65	37.6265
1210.88	42.9899
1214.12	48.9506
1217.35	54.7293
1220.57	62.1885
1223.8	67.8334
1227.03	73.1608
1230.25	76.6286
1233.47	80.4253
1236.69	84.716
1239.92	87.9383
1243.13	90.6597
1246.35	91.826
1249.57	93.1697
1252.78	92.1833
1256	90.7678
1259.21	89.5711
1262.42	85.8962
1265.63	83.5226
1268.84	80.9457
1272.05	78.4733
1275.26	75.2777
1278.46	73.6875
1281.67	73.3959
1284.87	74.0588
1288.07	74.5824
1291.27	76.9333
1294.47	80.6855
1297.67	85.103
1300.87	90.0701
1304.06	95.9067
1307.26	100.781
1310.45	105.585
1313.64	112.999
1316.83	118.532
1320.02	122.984
1323.21	125.616
1326.4	127.769
1329.59	128.716
1332.77	129.305
1335.95	129.971
1339.14	127.908
1342.32	127.354
1345.5	125.644
1348.67	121.865
1351.85	118.276
1355.03	114.346
1358.2	109.941
1361.38	107.22
1364.55	102.825
1367.72	98.5162
1370.89	95.5954
1374.06	91.2335
1377.23	87.8833
1380.39	84.8706
1383.56	83.7726
1386.72	83.2945
1389.89	81.8362
1393.05	79.9873
1396.21	77.5606
1399.37	74.4003
1402.52	71.9152
1405.68	69.0552
1408.84	69.116
1411.99	69.8803
1415.15	71.4642
1418.3	73.2129
1421.45	78.4163
1424.6	84.4168
1427.75	91.7306
1430.89	97.7792
1434.04	105.138
1437.18	112.457
1440.33	119.059
1443.47	123.289
1446.61	128.206
1449.75	128.541
1452.89	129.353
1456.03	128.451
1459.16	125.133
1462.3	121.752
1465.43	114.79
1468.56	105.136
1471.7	96.7587
1474.83	87.6677
1477.96	77.6898
1481.08	66.958
1484.21	57.0655
1487.34	48.5121
1490.46	40.373
1493.58	33.9266
1496.71	29.931
1499.83	29.026
1502.95	26.2268
1506.07	25.5188
1509.18	24.9099
1512.3	23.8819
1515.41	23.6665
1518.53	25.5412
1521.64	25.2874
1524.75	26.3463
1527.86	27.7521
1530.97	29.3135
1534.08	30.5383
1537.19	33.4966
1540.29	36.0756
1543.4	40.2429
1546.5	42.9038
1549.6	47.2704
1552.7	50.5699
1555.8	54.4744
1558.9	58.8437
1562	64.8264
1565.09	68.2774
1568.19	72.2471
1571.28	77.1289
1574.37	79.9034
1577.47	82.4201
1580.56	83.2439
1583.64	85.842
1586.73	87.3845
1589.82	87.5554
1592.9	89.409
1595.99	88.0852
1599.07	88.0204
1602.15	86.5031
1605.23	84.6874
1608.31	83.4346
1611.39	79.2426
1614.47	78.7909
1617.55	77.9827
1620.62	77.9886
1623.7	78.5762
1626.77	78.4558
1629.84	80.4651
1632.91	82.9773
1635.98	85.1025
1639.05	87.7423
1642.11	88.9769
1645.18	91.6238
1648.24	93.3328
1651.31	94.1926
1654.37	97.041
1657.43	99.6568
1660.49	100.174
1663.55	99.7348
1666.61	97.9227
1669.66	94.2029
1672.72	89.94
1675.77	85.422
1678.83	80.5004
1681.88	74.4587
1684.93	67.6184
1687.98	59.8654
1691.03	55.7153
1694.07	50.3285
1697.12	43.5558
1700.17	36.6918
1703.21	32.8921
1706.25	27.5202
1709.29	23.1616
1712.33	20.7759
1715.37	17.742
1718.41	15.5379
1721.45	14.1319
1724.49	13.016
1727.52	12.6883
1730.55	12.5704
1733.59	11.1662
1736.62	10.2173
1739.65	9.10241
1742.68	8.64727
1745.7	8.54978
1748.73	7.25835
1751.76	6.79149
1754.78	4.93897
1757.8	3.42277
1760.83	2.91418
1763.85	2.31879
1766.87	2.42855
1769.89	2.37038
1772.9	2.03482
1775.92	1.86189
1778.94	2.16445
1781.95	2.63863
1784.96	3.72925
1787.97	4.08879
1790.99	4.97962
1794	5.25932
1797	5.96719
1800.01	6.00671
1803.02	6.12866
1806.02	5.71211
1809.03	6.5625
1812.03	6.73808
1815.03	6.88385
1818.03	5.95845
1821.03	4.79866
1824.03	4.9645
1827.03	4.08834
1830.02	2.90987
1833.02	3.18128
1836.01	2.96628
1839.01	3.43531
1842	4.03361
1844.99	4.44466
1847.98	3.97076
1850.97	4.45991
1853.95	4.88094
1856.94	5.57467
1859.93	5.42223
1862.91	4.57608
1865.89	4.14743
1868.87	3.38458
1871.85	3.15184
1874.83	3.1564
1877.81	4.1697
1880.79	3.44416
1882.52	3.19385
1885.51	3.65345
1888.5	3.29184
1891.49	3.07683
1894.47	2.60514
1897.46	3.35201
1900.44	3.75409
1903.42	4.54944
1906.4	5.85141
1909.38	5.90723
1912.36	6.78838
1915.34	5.7155
1918.32	5.97246
1921.29	5.51157
1924.27	6.53994
1927.24	6.0818
1930.21	6.94693
1933.18	5.24419
1936.15	4.14071
1939.12	4.26943
1942.09	4.13063
1945.06	5.07305
1948.02	5.05423
1950.99	4.16958
1953.95	3.49509
1956.91	3.33563
1959.88	2.79302
1962.84	1.62368
1965.8	1.52991
1968.75	1.90645
1971.71	1.89826
1974.67	2.4686
1977.62	2.69997
1980.58	2.65245
1983.53	2.36061
1986.48	2.6106
1989.43	3.23862
1992.38	5.09444
1995.33	5.17247
1998.27	5.27396
2001.22	5.75249
2004.16	5.47747
2007.11	6.61301
2010.05	6.82037
2012.99	7.539
2015.93	7.75169
2018.87	8.75833
2021.81	8.38068
2024.75	8.00656
2027.69	8.70541
2030.62	9.31485
2033.56	8.74733
2036.49	9.95933
2039.42	9.92897
2042.35	9.66206
2045.28	10.2676
2048.21	10.0961
2051.14	9.50122
2054.07	9.03807
2056.99	9.93475
2059.92	9.95602
2062.84	10.4901
2065.76	9.47805
2068.68	8.5761
2071.6	8.08917
2074.52	8.73498
2077.44	10.5439
2080.36	10.869
2083.27	10.3718
2086.19	8.91569
2089.1	9.27721
2092.02	8.35843
2094.93	8.13745
2097.84	8.204
2100.75	7.31619
2103.66	7.21664
2106.56	6.68738
2109.47	7.07102
2112.38	7.12273
2115.28	6.75752
2118.18	5.97661
2121.09	6.22979
2123.99	6.717
2126.89	8.49606
2129.79	8.39245
2132.68	8.38084
2135.58	9.90805
2138.48	8.30889
2141.37	8.31674
2144.27	8.60446
2147.16	11.4401
2150.05	10.7471
2152.94	9.63668
2155.83	8.65208
2158.72	7.2383
2161.6	7.36911
2164.49	7.51965
2167.38	6.46904
2170.26	5.71217
2173.14	5.59369
2176.03	5.66745
2178.91	6.08216
2181.79	6.39651
2184.67	6.00718
2187.54	7.06027
2190.42	6.28365
2193.3	6.52095
2196.17	6.03678
2199.05	5.74827
2201.92	6.02382
2204.79	5.49399
2207.66	4.74994
2210.53	4.16957
2213.4	3.80437
2216.27	4.2073
2219.13	3.90984
2222	4.03472
2224.86	4.37687
2227.72	4.88793
2230.59	5.22107
2233.45	6.56357
2236.31	7.42448
2239.17	7.81234
2242.03	9.14001
2244.88	9.18351
2247.74	9.87097
2250.59	9.98837
2253.45	9.72499
2256.3	9.07222
2259.15	8.52574
2262	7.41129
2264.85	7.41531
2267.7	7.87989
2270.55	7.86152
2273.4	8.12094
2276.24	7.36389
2279.09	7.28713
2281.93	6.56893
2284.77	6.15704
2287.62	6.84888
2290.46	5.60487
2293.3	5.69858
2296.13	5.14172
2298.97	6.22467
2301.81	5.8935
2304.64	6.32157
2307.48	6.37043
2310.31	6.41334
2313.14	5.79065
2315.98	4.47015
2318.81	3.91316
2321.64	3.27454
2324.46	2.86884
2327.29	2.6456
2330.12	2.97937
2332.94	3.80047
2335.77	3.83077
2338.59	4.33284
2341.41	4.38
2344.23	3.90628
2347.05	3.57218
2349.87	3.60331
2352.69	3.89535
2355.51	3.71911
2358.32	3.1601
2361.14	2.73871
2363.95	3.80505
2366.76	4.16719
2369.58	4.64792
2372.39	3.74292
2375.2	3.4387
2378	3.28359
2380.81	2.76831
2383.62	1.71501
2386.43	0.916713
2389.23	0.691668
2392.03	0.266167
2394.84	-0.34368
2397.64	0.267506
2400.44	0.447001
2403.24	0.184513
2406.04	0.164695
2408.84	0.891794
2411.63	1.32966
2414.43	1.60136
2417.22	4.39375
2420.02	5.5131
2422.81	6.21589
2425.6	7.56533
2428.39	8.36348
2431.18	8.23329
2433.97	9.21502
2436.76	9.41042
2439.54	10.5626
2442.33	9.99919
2445.12	9.39379
2447.9	9.58198
2450.68	9.29973
2453.46	8.22154
2456.24	7.2571
2459.02	5.79565
2461.8	6.27664
2464.58	4.92012
2467.36	5.03858
2470.13	4.94725
2472.91	5.14417
2475.68	4.42936
2478.45	4.07595
2481.23	3.20705
2484	3.19047
2486.77	3.66023
2489.54	1.94133
2492.3	1.99688
2495.07	1.43447
2497.84	1.18785
2500.6	1.17361
2503.36	0.800446
2506.13	2.60061
2508.89	2.40222
2511.65	2.48669
2514.41	2.56081
2517.17	3.22098
2519.93	2.87209
2522.68	2.38608
2525.44	2.90954
2528.19	2.87699
2530.95	2.54212
2533.7	2.50919
2536.45	3.66217
2539.2	4.03989
2541.95	3.74384
2544.7	3.18861
2547.45	3.38581
2550.2	2.61547
2552.94	3.29366
2555.69	3.81837
2558.43	4.63949
2561.18	5.36944
2563.92	5.48684
2566.66	6.52104
2569.4	7.02322
2572.14	7.6536
2574.88	7.32072
2577.61	6.82143
2580.35	6.56096
2583.09	6.93999
2585.82	6.25268
2588.55	5.80628
2591.29	4.66003
2594.02	4.87642
2596.75	3.69161
2599.48	3.12685
2602.21	3.19593
2604.93	2.72895
2607.66	2.98746
2610.39	4.04066
2613.11	3.89881
2615.83	4.94443
2618.56	6.04687
2621.28	6.96928
2624	7.38665
2626.72	7.86082
2629.44	8.97811
2632.15	9.1628
2634.87	10.7765
2637.59	10.6244
2640.3	10.2755
2643.02	10.0272
2645.73	10.3502
2648.44	10.0115
2651.15	10.9567
2653.86	10.7352
2656.57	11.0597
2659.28	10.8739
2661.99	10.445
2664.69	9.19042
2667.4	9.0826
2670.1	8.00824
2672.81	7.90011
2675.51	7.1805
2678.21	7.78198
2680.91	7.43872
2683.61	6.51897
2686.31	5.68735
2689	5.84175
2691.7	6.21511
2694.4	6.57329
2697.09	6.75621
2699.79	6.91232
2702.48	7.93226
2705.17	8.10253
2707.86	8.47889
2710.55	9.52957
2713.24	11.644
2715.93	13.9431
2718.62	15.6773
2721.3	16.7238
2723.99	18.3975
2726.67	19.5895
2729.35	19.8808
2732.04	19.804
2734.72	20.0939
2737.4	19.7535
2740.08	20.7409
2742.76	21.0297
2745.43	21.1664
2748.11	20.3299
2750.79	20.2887
2753.46	19.3649
2756.14	17.5874
2758.81	15.7177
2761.48	13.8865
2764.15	11.5146
2766.82	9.85127
2769.49	9.48198
2772.16	8.08033
2774.82	7.12833
2777.49	5.18207
2780.16	4.80581
2782.82	3.65402
2785.48	2.52796
2788.15	2.14384
2790.81	1.4002
2793.47	1.6945
2796.13	0.845445
2798.79	0.260394
2801.44	0.577421
2804.1	1.24308
2806.76	1.86545
2809.41	1.66185
2812.07	2.2714
2814.72	4.11371
2817.37	6.55773
2820.02	8.3297
2822.67	12.6467
2825.32	17.757
2827.97	24.9666
2830.62	31.0635
2833.26	37.6697
2835.91	45.0366
2838.56	52.6593
2841.2	62.459
2843.84	72.6488
2846.48	85.8158
2849.12	100.728
2851.77	116.729
2854.4	133.402
2857.04	149.457
2859.68	166.44
2862.32	183.126
2864.95	199.71
2867.59	216.392
2870.22	231.976
2872.85	248.91
2875.48	265.115
2878.11	281.867
2880.74	297.133
2883.37	311.89
2886	325.436
2888.63	338.939
2891.25	352.036
2893.88	363.176
2896.5	373.679
2899.13	385.895
2901.75	397.777
2904.37	410.7
2906.99	424.498
2909.61	437.98
2912.23	452.699
2914.85	466.543
2917.46	478.28
2920.08	487.164
2922.7	494.085
2925.31	498.356
2927.92	499.791
2930.54	499.512
2933.15	496.08
2935.76	491.517
2938.37	483.887
2940.98	472.221
2943.58	458.448
2946.19	443.915
2948.8	426.654
2951.4	409.734
2954.01	393.139
2956.61	375.141
2959.21	357.966
2961.81	340.898
2964.41	323.775
2967.01	305.85
2969.61	289.212
2972.21	272.396
2974.81	255.951
2977.4	238.46
2980	221.418
2982.59	204.115
2985.18	186.948
2987.78	169.131
2990.37	152.474
2992.96	136.114
2995.55	119.414
2998.14	103.787
3000.73	89.8333
3003.31	75.8065
3005.9	63.0228
3008.48	51.568
3011.07	41.8145
3013.65	33.1132
3016.23	26.7794
3018.81	21.249
3021.4	16.106
3023.97	12.0964
3026.55	7.81652
3029.13	4.70261
3031.71	2.85977
3034.28	0.831799
3036.86	1.02053
3039.43	1.3655
3042.01	2.66569
3044.58	4.38784
3047.15	6.30514
3049.72	8.2313
3052.29	8.68326
3054.86	10.0342
3057.43	10.5866
3060	10.8099
3062.56	10.7488
3065.13	10.7238
3067.69	9.56095
3070.26	8.70748
3072.82	7.9595
3075.38	7.30295
3077.94	5.57197
3080.5	3.79816
3083.06	2.05019
3085.62	0.826688
3088.18	-0.168334
3090.73	-0.972897
3093.29	-0.713607
3095.84	0.271743
3098.4	1.69071
3100.95	2.86632
3103.5	4.06526
3106.05	5.50287
3108.6	7.35649
3111.15	9.05535
3113.7	10.1802
3116.25	11.8334
3118.79	14.3717
3121.34	15.3928
3123.88	17.1472
3126.43	18.988
3128.97	20.2621
3131.51	22.599
3134.06	24.2571
3136.6	25.3947
3139.14	26.19
3141.67	27.8539
3144.21	29.6958
3146.75	31.3414
3149.29	33.4954