File: data/Raman/poly_smoothed/Thy_10_08_09_1x_45s_532 nm_x100_100%_600 gr_mm_01.txt
#Acq. time (s)=	45
#Accumulations=	2
#Range (cm-¹)=	200...3150
#Windows=	2
#Auto scanning=	Off
#Autofocus=	Off
#Macrospot=	Off
#AutoExposure=	Off
#Spike filter=	Multiple accum.
#Delay time (s)=	0
#Binning=	1
#Readout mode=	Signal
#DeNoise=	Off
#ICS correction=	On
#Dark correction=	Off
#Inst. Process=	Off
#Detector Gain=	Best Dynamic Range
#Detector ADC=	20 kHz
#Detector temperature (°C)=	-69.85
#Instrument=	LabRAM HR Evol
#Detector=	Synapse
#Objective=	x100
#Grating=	600 gr/mm
#ND Filter=	100%
#Laser (nm)=	532
#Hole=	100.021
#Range=	Auto
#Laser Pol.=	No
#Raman. Pol.=	No
#Laser Pol. (°)=	-0.0007625
#Raman Pol. (°)=	89.9995
#Collection=	Microscope
#StageXY=	Marzhauser
#StageZ=	Marzhauser
#X (µm)=	2161.3
#Y (µm)=	1263.8
#Z (µm)=	442.95
#Full time(mm:ss)=	3:18
#Project=
#Sample=
#Site=
#Title=	Thy_10_08_09_2x_45s_532 nm_x100_100%_600 gr_mm
#Remark=
#Date=	05.07.2022 14:49
#Acquired=	05.07.2022 14:49:56
#Base:Fit=	10.08.2022 09:45:33
#Base:Fit=	10.08.2022 09:46:03
#Base:Fit=	10.08.2022 09:46:25
#Base:Sub=	10.08.2022 09:46:49
#Filter:Polynom=	16.08.2022 10:24:56
#AxisType[0]=Intens
#AxisUnit[0]=Cnt
#AxisType[1]=Spectr
#AxisUnit[1]=1/cm
200.43	-0.487749
204.059	4.31407
207.688	9.67542
211.314	13.2917
214.941	15.4684
218.564	16.6515
222.186	16.6411
225.809	16.688
229.428	15.9334
233.045	15.1163
236.663	14.4929
240.278	13.9799
243.891	13.7511
247.503	13.9188
251.116	13.9493
254.725	12.339
258.333	11.3243
261.939	11.6833
265.544	10.974
269.148	11.4693
272.75	12.6506
276.351	12.7314
279.95	11.7225
283.548	12.4961
287.144	15.3274
290.739	14.9543
294.333	16.0066
297.925	16.8513
301.514	17.4982
305.104	18.1735
308.692	17.8146
312.279	19.4217
315.862	19.8472
319.446	19.4827
323.029	20.2395
326.608	20.8213
330.188	21.9157
333.766	22.8242
337.341	23.2379
340.917	21.8238
344.489	20.3733
348.062	20.4104
351.631	20.2334
355.201	18.8156
358.768	19.0683
362.333	17.8462
365.899	16.8077
369.462	16.5088
373.023	17.0511
376.585	16.6233
380.143	16.5067
383.7	17.4914
387.256	17.2434
390.812	15.8605
394.365	15.0965
397.916	14.8185
401.467	12.7117
405.015	11.8605
408.563	10.8631
412.109	9.45339
415.654	8.78824
419.197	7.49309
422.739	6.64236
426.279	6.20328
429.819	4.87917
433.356	3.87235
436.891	3.69572
440.426	2.49731
443.96	1.99785
447.492	2.67871
451.021	1.9444
454.551	2.79153
458.079	3.0586
461.604	3.96154
465.13	4.66557
468.654	5.61035
472.175	6.60143
475.696	6.94211
479.215	7.68095
482.733	9.03664
486.249	10.509
489.765	10.967
493.278	11.7888
496.789	12.8162
500.301	14.0764
503.81	15.2042
507.317	16.9413
510.825	18.2836
514.33	18.6961
517.833	18.5835
521.335	18.6982
524.836	18.4102
528.335	18.6033
531.835	18.2196
535.332	16.9651
538.827	16.0883
542.321	15.1299
545.814	13.3606
549.305	12.0111
552.795	10.1777
556.282	9.58347
559.769	7.83689
563.255	6.06128
566.739	5.76254
570.223	4.09601
573.705	2.13251
577.183	-0.136181
580.663	0.179155
584.141	0.605357
587.615	0.829202
591.09	1.84243
594.564	2.83292
598.035	3.76449
601.506	4.31464
604.974	6.03513
608.443	6.40948
611.908	7.02281
615.374	7.87739
618.837	9.62875
622.3	11.2544
625.761	11.7223
629.219	12.1349
632.677	13.9933
636.135	14.6698
639.59	14.7909
643.043	14.5012
646.495	13.7596
649.948	12.7687
653.398	14.5638
656.846	14.057
660.293	13.8184
663.738	14.6438
667.183	16.032
670.626	16.8177
674.067	17.9609
677.508	19.583
680.947	19.4297
684.385	19.227
687.821	20.0495
691.254	20.5127
694.688	21.1998
698.121	22.3817
701.552	26.5777
704.98	28.8563
708.409	31.0886
711.836	33.1393
715.26	35.6815
718.685	37.4934
722.108	37.3076
725.528	38.7464
728.949	40.577
732.367	42.8777
735.785	44.4615
739.2	44.4368
742.614	44.6838
746.028	45.5411
749.439	48.9604
752.849	53.1425
756.26	56.3074
759.667	58.5451
763.073	61.5179
766.477	61.7115
769.883	64.5111
773.285	66.4728
776.686	69.122
780.085	71.4881
783.484	74.549
786.881	77.7208
790.276	78.723
793.671	79.2974
797.064	82.4152
800.456	84.902
803.846	86.2261
807.234	86.2041
810.622	86.4705
814.008	86.6633
817.394	84.9773
820.778	84.1343
824.159	83.467
827.541	82.8209
830.921	81.908
834.298	81.2892
837.676	78.8134
841.051	75.1435
844.426	72.7843
847.798	69.8443
851.171	66.2666
854.54	64.2367
857.911	60.9597
861.278	57.8312
864.645	56.4161
868.01	54.0293
871.373	51.1692
874.735	50.491
878.097	51.3982
881.457	51.6163
884.815	51.0537
888.172	51.7464
891.528	53.2329
894.882	54.3226
898.237	55.1797
901.589	55.5564
904.94	56.9346
908.289	56.903
911.635	55.7216
914.982	56.7116
918.328	55.9462
921.672	53.9012
925.015	52.9705
928.357	52.9056
931.698	51.4091
935.035	50.2054
938.373	48.6479
941.71	46.9389
945.044	45.5243
948.378	44.9131
951.709	43.6183
955.041	41.8591
958.372	38.6004
961.699	36.3363
965.027	35.9694
968.352	36.4136
971.676	38.5283
975	40.1486
978.322	40.4937
981.642	40.3636
984.962	41.0041
988.28	41.409
991.596	39.7148
994.911	38.801
998.227	38.5748
1001.54	37.1434
1004.85	36.7011
1008.16	36.7706
1011.47	36.9376
1014.78	36.4316
1018.08	35.5624
1021.39	34.3338
1024.69	32.4507
1028	32.3268
1031.3	30.8902
1034.6	26.426
1037.9	22.3572
1041.19	20.7812
1044.49	21.3513
1047.78	21.3783
1051.08	20.4584
1054.37	20.0814
1057.66	19.3152
1060.95	16.9787
1064.24	15.2315
1067.53	13.7226
1070.81	13.2338
1074.1	12.089
1077.38	12.2118
1080.66	12.5327
1083.94	12.004
1087.22	12.8744
1090.5	13.8122
1093.78	14.3626
1097.05	13.2321
1100.33	14.1322
1103.6	14.485
1106.87	14.4836
1110.14	13.807
1113.41	11.9878
1116.68	12.0158
1119.95	12.4512
1123.21	10.8685
1126.48	10.7804
1129.74	9.71628
1133	8.16106
1136.26	8.19334
1139.52	6.88444
1142.78	6.4642
1146.04	6.14067
1149.29	5.68484
1152.55	6.05452
1155.8	4.74158
1159.05	2.9195
1162.3	3.59966
1165.55	2.44608
1168.8	2.79238
1172.05	2.35564
1175.29	3.15047
1178.54	4.06475
1181.78	5.5219
1185.02	6.3639
1188.26	7.17378
1191.5	8.5168
1194.74	8.76752
1197.97	10.1274
1201.21	11.9156
1204.44	13.3133
1207.68	14.7181
1210.91	16.9943
1214.14	20.103
1217.37	21.6164
1220.59	22.9974
1223.82	25.5591
1227.05	26.9584
1230.27	27.7537
1233.49	28.5092
1236.72	29.0351
1239.94	30.7477
1243.16	33.0815
1246.37	33.0109
1249.59	34.8918
1252.8	37.7886
1256.02	39.4485
1259.23	40.6156
1262.44	40.8193
1265.66	42.9085
1268.86	43.6759
1272.07	43.3604
1275.28	43.6361
1278.48	45.3698
1281.69	46.467
1284.89	48.6573
1288.09	49.714
1291.29	49.9146
1294.49	50.3147
1297.69	49.8088
1300.89	50.6248
1304.08	50.9571
1307.28	51.679
1310.47	52.2681
1313.66	52.7752
1316.85	53.6519
1320.04	54.6524
1323.23	54.761
1326.42	54.9469
1329.61	56.3392
1332.79	55.7327
1335.97	53.9518
1339.16	53.1803
1342.34	50.8742
1345.52	49.6772
1348.7	47.591
1351.87	44.3117
1355.05	42.3084
1358.22	39.9189
1361.4	37.7687
1364.57	35.9315
1367.74	32.4102
1370.91	30.4237
1374.08	27.66
1377.25	24.1881
1380.41	22.6676
1383.58	21.7437
1386.74	20.3115
1389.91	19.7872
1393.07	18.4345
1396.23	17.7344
1399.39	17.4739
1402.55	17.979
1405.7	18.858
1408.86	20.0352
1412.01	20.475
1415.17	23.583
1418.32	26.4378
1421.47	28.3736
1424.62	32.0906
1427.77	36.9743
1430.91	40.9659
1434.06	45.3013
1437.2	49.9308
1440.35	52.1824
1443.49	53.8861
1446.63	54.3296
1449.77	54.5006
1452.91	53.6215
1456.05	51.2126
1459.18	51.5191
1462.32	47.7698
1465.45	44.6832
1468.59	40.4981
1471.72	35.3707
1474.85	30.8239
1477.98	25.9744
1481.1	22.202
1484.23	18.7912
1487.36	15.6394
1490.48	13.4398
1493.61	12.3129
1496.73	10.1931
1499.85	9.03028
1502.97	8.52651
1506.09	8.35834
1509.2	7.77417
1512.32	7.6541
1515.43	7.20002
1518.55	7.25151
1521.66	7.98756
1524.77	7.5781
1527.88	8.88022
1530.99	9.75011
1534.1	12.1913
1537.21	13.2646
1540.31	14.5813
1543.42	15.2978
1546.52	16.7077
1549.62	18.5271
1552.72	20.1424
1555.82	21.1949
1558.92	23.8663
1562.02	25.136
1565.11	27.1855
1568.21	29.3207
1571.3	30.5164
1574.39	30.4159
1577.49	30.9185
1580.57	31.8331
1583.66	32.5147
1586.75	34.7704
1589.84	36.2704
1592.92	37.8827
1596.01	37.4691
1599.09	37.7146
1602.17	38.5577
1605.25	38.8453
1608.33	39.5076
1611.41	38.742
1614.49	38.6789
1617.57	39.2
1620.64	39.43
1623.72	40.5717
1626.79	40.1686
1629.86	40.5519
1632.93	41.5633
1636	44.0361
1639.07	45.4289
1642.13	46.7301
1645.2	48.3606
1648.26	49.2688
1651.33	50.7918
1654.39	52.5733
1657.45	53.3306
1660.51	53.5175
1663.57	52.5579
1666.63	51.3274
1669.68	48.6879
1672.74	45.5527
1675.79	42.7682
1678.85	40.5705
1681.9	36.0791
1684.95	32.3666
1688	27.7164
1691.05	24.3605
1694.09	21.3652
1697.14	19.0828
1700.18	15.1527
1703.23	14.094
1706.27	12.8972
1709.31	11.881
1712.35	11.4749
1715.39	9.91077
1718.43	9.18264
1721.47	9.08642
1724.5	9.05502
1727.54	9.07855
1730.57	9.08993
1733.61	8.27606
1736.64	7.36749
1739.67	7.12411
1742.7	5.84593
1745.72	4.79114
1748.75	3.78107
1751.77	3.53303
1754.8	2.0716
1757.82	0.589012
1760.84	-0.06736
1763.87	-0.501234
1766.89	-0.974099
1769.91	-0.489271
1772.92	-0.526873
1775.94	-0.988438
1778.95	-0.416165
1781.97	-1.54036
1784.98	-1.09833
1787.99	-1.47052
1791.01	-2.23921
1794.01	-0.937673
1797.02	-0.231791
1800.03	0.23524
1803.04	0.195422
1806.04	1.59287
1809.05	2.01426
1812.05	3.18205
1815.05	3.1812
1818.05	3.65069
1821.05	4.55838
1824.05	5.95955
1827.05	6.80769
1830.04	6.47893
1833.04	6.77049
1836.03	6.89825
1839.03	7.41226
1842.02	7.61785
1845.01	7.65311
1848	7.60374
1850.99	7.53024
1853.97	7.73289
1856.96	6.77319
1859.94	6.30229
1862.93	5.82001
1865.91	6.23691
1868.89	6.14477
1871.87	5.89868
1874.85	4.84326
1877.83	5.26059
1880.81	6.84651
1882.57	7.08101
1885.56	7.00589
1888.55	6.132
1891.54	6.96747
1894.52	7.33544
1897.51	6.51007
1900.49	6.71964
1903.47	6.26398
1906.45	7.04437
1909.43	7.50494
1912.41	7.50352
1915.39	8.18294
1918.37	8.58067
1921.34	8.81958
1924.32	9.40164
1927.29	8.85891
1930.26	8.7418
1933.23	8.59437
1936.2	8.87443
1939.17	8.75334
1942.14	7.89392
1945.11	7.45769
1948.07	7.79801
1951.04	8.15433
1954	8.25925
1956.96	6.49328
1959.93	5.58034
1962.89	4.37836
1965.85	4.46844
1968.8	3.6934
1971.76	3.7675
1974.72	4.28085
1977.67	4.50867
1980.63	4.59073
1983.58	4.87197
1986.53	5.1033
1989.48	5.82034
1992.43	6.03192
1995.38	7.66189
1998.32	8.65704
2001.27	8.85884
2004.22	8.16805
2007.16	8.4417
2010.1	8.64002
2013.04	8.80225
2015.98	9.13015
2018.92	10.0217
2021.86	11.24
2024.8	11.295
2027.74	10.6894
2030.67	10.3971
2033.61	11.2398
2036.54	11.9497
2039.47	12.986
2042.4	12.8291
2045.33	13.5094
2048.26	13.6536
2051.19	13.9855
2054.12	14.2729
2057.04	15.163
2059.97	15.4604
2062.89	15.7855
2065.81	15.5532
2068.73	16.1122
2071.65	14.4601
2074.57	14.0546
2077.49	13.7431
2080.41	13.7033
2083.32	13.285
2086.24	13.4366
2089.15	13.2711
2092.07	13.8698
2094.98	14.4298
2097.89	14.5228
2100.8	14.8981
2103.71	15.5792
2106.61	16.1876
2109.52	16.1481
2112.43	15.4791
2115.33	15.8036
2118.23	16.6324
2121.13	17.2701
2124.04	17.3629
2126.94	17.4308
2129.83	18.3401
2132.73	18.2159
2135.63	18.3721
2138.53	18.9409
2141.42	19.4339
2144.31	19.6669
2147.21	20.0223
2150.1	20.6968
2152.99	21.148
2155.88	22.0943
2158.77	23.8291
2161.65	25.0064
2164.54	27.0864
2167.43	27.7747
2170.31	28.0719
2173.19	28.9037
2176.07	29.5457
2178.96	30.3206
2181.84	29.8172
2184.72	29.5712
2187.59	29.7209
2190.47	29.6651
2193.35	28.6654
2196.22	27.5481
2199.09	26.745
2201.97	26.2636
2204.84	25.3893
2207.71	23.8847
2210.58	22.2605
2213.45	20.7258
2216.31	19.5922
2219.18	19.1637
2222.05	18.6659
2224.91	18.8516
2227.78	19.2313
2230.64	19.0576
2233.5	19.1249
2236.36	18.4998
2239.22	18.7398
2242.08	18.3278
2244.93	17.7311
2247.79	17.7931
2250.64	16.7293
2253.5	15.4785
2256.35	14.8825
2259.2	13.5989
2262.05	13.2988
2264.9	12.6288
2267.75	12.3806
2270.6	11.8153
2273.45	10.7979
2276.29	9.90471
2279.14	8.43745
2281.98	7.96361
2284.82	7.78292
2287.66	7.56726
2290.5	7.13725
2293.34	6.09548
2296.18	7.32075
2299.02	8.72854
2301.86	10.3295
2304.69	11.681
2307.53	12.5609
2310.36	13.812
2313.19	13.4072
2316.02	13.618
2318.85	13.5452
2321.68	13.4486
2324.51	13.9896
2327.34	14.4941
2330.16	14.9486
2332.99	15.3727
2335.81	14.7642
2338.64	13.5065
2341.46	11.7388
2344.28	9.66239
2347.1	8.81057
2349.92	7.37883
2352.74	7.07486
2355.55	6.09014
2358.37	4.64729
2361.19	3.94617
2364	4.37553
2366.81	6.64766
2369.62	6.04575
2372.44	5.68974
2375.24	5.45679
2378.05	5.36461
2380.86	5.8051
2383.67	5.32224
2386.47	5.14346
2389.28	6.06774
2392.08	6.09495
2394.89	7.19413
2397.69	7.22263
2400.49	7.50549
2403.29	7.17833
2406.09	6.8284
2408.88	6.19043
2411.68	5.40792
2414.48	6.42564
2417.27	6.2755
2420.06	5.47197
2422.86	5.84449
2425.65	5.10299
2428.44	5.31397
2431.23	5.49155
2434.02	5.99179
2436.81	5.21424
2439.59	5.08555
2442.38	4.48932
2445.16	4.08978
2447.95	4.86402
2450.73	4.25831
2453.51	3.81343
2456.29	4.48913
2459.07	5.08456
2461.85	5.12973
2464.63	5.48982
2467.4	5.08723
2470.18	5.35469
2472.95	4.20741
2475.73	3.17773
2478.5	3.17227
2481.27	2.58041
2484.04	2.09186
2486.81	1.30185
2489.58	0.648326
2492.35	0.391496
2495.12	0.0108263
2497.88	-0.395385
2500.65	-1.09669
2503.41	-1.60445
2506.17	-1.98502
2508.94	-2.76669
2511.7	-2.6552
2514.46	-1.88362
2517.22	-1.25256
2519.97	-0.795455
2522.73	0.779182
2525.49	2.49126
2528.24	2.9589
2530.99	2.73544
2533.75	2.92601
2536.5	2.93123
2539.25	3.66425
2542	4.18248
2544.75	5.71115
2547.5	5.59721
2550.24	4.84642
2552.99	5.35112
2555.74	4.36315
2558.48	3.89454
2561.22	4.44372
2563.96	4.48493
2566.71	4.48379
2569.45	4.86697
2572.18	5.16502
2574.92	6.45108
2577.66	7.08065
2580.4	7.21723
2583.13	7.21279
2585.87	6.76609
2588.6	6.85294
2591.33	6.33656
2594.06	5.43785
2596.79	4.60669
2599.52	3.78049
2602.25	3.12837
2604.98	3.55642
2607.71	2.91305
2610.43	2.51777
2613.16	1.73359
2615.88	0.997403
2618.6	0.587926
2621.32	0.160836
2624.04	0.0426337
2626.76	0.83868
2629.48	1.05527
2632.2	1.71755
2634.92	2.65363
2637.63	3.56308
2640.35	4.28655
2643.06	4.26574
2645.77	4.09469
2648.49	4.21868
2651.2	4.45347
2653.91	5.30653
2656.62	4.48271
2659.33	4.53452
2662.03	4.54711
2664.74	3.71588
2667.44	3.63703
2670.15	2.94482
2672.85	2.45394
2675.55	2.04349
2678.26	2.12098
2680.96	2.09272
2683.66	2.1365
2686.35	2.64866
2689.05	2.89183
2691.75	3.27854
2694.44	3.71516
2697.14	4.68745
2699.83	5.78471
2702.52	7.09964
2705.22	8.01358
2707.91	9.09365
2710.6	9.62552
2713.29	11.4012
2715.97	12.6931
2718.66	13.9939
2721.35	13.6898
2724.03	14.2513
2726.72	14.6762
2729.4	14.2809
2732.08	14.5449
2734.76	14.1474
2737.44	13.5409
2740.12	13.3661
2742.8	13.3141
2745.48	12.6829
2748.16	12.4426
2750.83	12.6581
2753.51	12.267
2756.18	11.8727
2758.85	11.1129
2761.53	10.2378
2764.2	9.55287
2766.87	8.99428
2769.54	8.04324
2772.2	7.47596
2774.87	6.84846
2777.54	6.144
2780.2	6.6039
2782.87	6.25651
2785.53	6.1146
2788.19	5.84085
2790.85	5.42722
2793.51	5.79482
2796.17	5.74679
2798.83	5.60589
2801.49	6.07458
2804.15	6.75613
2806.8	6.99767
2809.46	8.23578
2812.11	8.19173
2814.76	9.17579
2817.42	10.5915
2820.07	11.1826
2822.72	12.7265
2825.37	13.9056
2828.02	15.9869
2830.66	18.6397
2833.31	21.4658
2835.96	23.9601
2838.6	27.0935
2841.24	31.1482
2843.89	36.2575
2846.53	41.7883
2849.17	47.4082
2851.81	52.7938
2854.45	58.6479
2857.09	65.4609
2859.72	71.1112
2862.36	76.7062
2865	82.9522
2867.63	88.4778
2870.26	94.3908
2872.9	98.1206
2875.53	101.924
2878.16	105.926
2880.79	109.692
2883.42	112.629
2886.05	115.219
2888.67	118.977
2891.3	121.9
2893.92	124.66
2896.55	127.391
2899.17	130.416
2901.79	134.63
2904.42	139.842
2907.04	146.137
2909.66	152.934
2912.27	160.978
2914.89	168.168
2917.51	174.446
2920.13	180.744
2922.74	185.5
2925.35	188.997
2927.97	191.042
2930.58	191.867
2933.19	192.118
2935.8	190.09
2938.41	187.363
2941.02	184.174
2943.63	179.732
2946.24	174.633
2948.84	168.436
2951.45	162.142
2954.05	155.668
2956.65	148.28
2959.26	140.747
2961.86	133.529
2964.46	127.921
2967.06	122.391
2969.66	117.753
2972.25	113.951
2974.85	111.044
2977.45	106.613
2980.04	101.413
2982.64	95.3533
2985.23	90.015
2987.82	84.2605
2990.41	77.4073
2993	71.954
2995.59	66.6707
2998.18	61.5426
3000.77	56.7179
3003.36	51.7463
3005.94	46.753
3008.53	43.4523
3011.11	39.3722
3013.69	35.7495
3016.28	32.1712
3018.86	29.1261
3021.44	26.9205
3024.02	25.0836
3026.6	23.5363
3029.18	21.8001
3031.75	21.6905
3034.33	21.4831
3036.9	22.4953
3039.48	23.0067
3042.05	23.7549
3044.62	23.9369
3047.19	24.7297
3049.77	25.4285
3052.34	25.5134
3054.9	25.6696
3057.47	25.8615
3060.04	25.4213
3062.61	25.3947
3065.17	24.8756
3067.74	24.2292
3070.3	23.5457
3072.86	21.9151
3075.42	20.9425
3077.99	19.2804
3080.54	17.6734
3083.1	15.6345
3085.66	13.549
3088.22	11.5802
3090.78	9.46158
3093.33	8.54313
3095.89	7.55157
3098.44	7.0908
3100.99	6.386
3103.54	6.10659
3106.1	5.22434
3108.65	3.91567
3111.2	3.10192
3113.74	2.16944
3116.29	1.65618
3118.84	1.5924
3121.38	1.17711
3123.93	1.29963
3126.47	1.35415
3129.01	0.582979
3131.56	0.644516
3134.1	0.578206
3136.64	0.443429
3139.18	0.160134
3141.72	-0.704263
3144.26	-0.761749
3146.79	-0.33284
3149.33	1.29769