File: data/Raman/poly_smoothed/Thy_00_07_15_1x_45s_532 nm_x100_100%_600 gr_mm_01.txt
#Acq. time (s)=	45
#Accumulations=	2
#Range (cm-¹)=	200...3150
#Windows=	2
#Auto scanning=	Off
#Autofocus=	Off
#Macrospot=	Off
#AutoExposure=	Off
#Spike filter=	Multiple accum.
#Delay time (s)=	0
#Binning=	1
#Readout mode=	Signal
#DeNoise=	Off
#ICS correction=	On
#Dark correction=	Off
#Inst. Process=	Off
#Detector Gain=	Best Dynamic Range
#Detector ADC=	20 kHz
#Detector temperature (°C)=	-69.85
#Instrument=	LabRAM HR Evol
#Detector=	Synapse
#Objective=	x100
#Grating=	600 gr/mm
#ND Filter=	100%
#Laser (nm)=	532
#Hole=	100.021
#Range=	Auto
#Laser Pol.=	No
#Raman. Pol.=	No
#Laser Pol. (°)=	-0.0007625
#Raman Pol. (°)=	89.9995
#Collection=	Microscope
#StageXY=	Marzhauser
#StageZ=	Marzhauser
#X (µm)=	9019.2
#Y (µm)=	-3084.6
#Z (µm)=	-54.6
#Full time(mm:ss)=	3:15
#Project=
#Sample=
#Site=
#Title=	Thy_00_07_15_2x_45s_532 nm_x100_100%_600 gr_mm
#Remark=
#Date=	28.06.2022 11:11
#Acquired=	28.06.2022 11:11:02
#Base:Fit=	10.08.2022 10:06:44
#Base:Fit=	10.08.2022 10:07:16
#Base:Fit=	10.08.2022 10:07:25
#Base:Fit=	10.08.2022 10:07:44
#Base:Fit=	10.08.2022 10:07:56
#Base:Sub=	10.08.2022 10:08:40
#Filter:Polynom=	16.08.2022 10:26:06
#AxisType[0]=Intens
#AxisUnit[0]=Cnt
#AxisType[1]=Spectr
#AxisUnit[1]=1/cm
200.407	45.033
204.035	42.3977
207.665	38.6863
211.291	35.6797
214.916	32.4319
218.541	29.1865
222.163	26.4874
225.785	24.3214
229.404	20.4221
233.022	18.3599
236.638	17.2523
240.255	15.7267
243.868	13.739
247.48	12.2884
251.091	11.887
254.702	9.31849
258.31	8.37673
261.916	5.60554
265.521	4.0511
269.125	3.55928
272.727	4.53479
276.328	5.502
279.927	5.08929
283.525	3.57677
287.121	3.39331
290.716	2.2593
294.31	4.01551
297.9	4.32435
301.491	3.9805
305.081	6.16634
308.669	6.30405
312.256	6.4812
315.839	6.20048
319.423	7.20971
323.006	6.96815
326.585	7.5381
330.165	8.29031
333.741	8.51367
337.318	7.7567
340.894	7.19952
344.466	7.06395
348.039	6.20352
351.608	5.22119
355.176	6.05564
358.745	6.01456
362.31	6.69224
365.876	6.46455
369.439	3.39524
373	3.54
376.56	3.26896
380.12	3.61134
383.677	3.87122
387.233	3.00271
390.787	3.79623
394.34	3.95668
397.894	2.90758
401.444	3.61436
404.993	2.76879
408.54	3.30883
412.086	4.275
415.631	5.17386
419.174	4.35152
422.716	3.91554
426.257	4.78643
429.794	4.44121
433.332	3.42342
436.868	1.07213
440.403	1.46621
443.937	3.32583
447.468	4.17922
450.999	5.62262
454.528	7.53334
458.057	9.38387
461.582	11.5547
465.107	12.2084
468.629	13.9197
472.152	16.1293
475.672	17.5174
479.192	20.1241
482.709	22.6818
486.226	23.8745
489.74	25.4161
493.255	26.136
496.767	28.085
500.277	28.1765
503.788	27.4663
507.295	28.4621
510.801	28.7876
514.308	26.2957
517.811	24.066
521.313	22.1187
524.814	21.3154
528.313	21.704
531.811	20.5018
535.308	18.8272
538.803	17.7322
542.297	16.408
545.789	15.8403
549.281	14.485
552.771	12.5417
556.259	10.4312
559.747	9.66394
563.233	9.29236
566.717	9.00676
570.2	8.22796
573.68	6.67397
577.161	6.12448
580.64	7.30853
584.118	8.24068
587.593	8.54673
591.068	8.66429
594.54	9.30777
598.013	7.5884
601.484	7.04857
604.952	6.70195
608.421	6.08419
611.886	6.69295
615.35	5.9797
618.815	6.08909
622.276	5.33848
625.738	5.71906
629.197	6.45106
632.655	5.87956
636.113	6.9179
639.568	6.81726
643.021	8.24979
646.473	10.69
649.924	11.9469
653.376	14.2175
656.824	15.1215
660.271	16.7076
663.716	20.5613
667.161	22.2572
670.604	24.3537
674.045	24.5577
677.486	25.9767
680.925	28.9399
684.361	30.6957
687.797	32.7052
691.232	34.5972
694.666	35.7648
698.099	36.6752
701.528	37.5258
704.958	38.2471
708.387	39.8079
711.814	40.9969
715.238	42.5853
718.663	44.7654
722.084	46.5448
725.506	48.8282
728.925	50.1608
732.345	52.3035
735.761	53.7661
739.178	56.5001
742.592	59.3207
746.006	64.6566
749.417	66.8839
752.827	67.5579
756.236	70.7443
759.645	73.1515
763.051	74.965
766.456	76.8507
769.859	78.3419
773.261	78.1467
776.664	78.2684
780.064	77.9936
783.462	77.8652
786.859	77.9821
790.255	77.7302
793.649	77.5718
797.042	77.7399
800.434	78.9063
803.823	79.4007
807.212	77.586
810.6	78.1857
813.987	78.8542
817.372	79.7221
820.754	81.4696
824.137	84.8719
827.519	86.8471
830.897	87.714
834.276	86.6808
837.654	88.5436
841.029	87.9396
844.404	85.8752
847.776	84.7503
851.149	82.8142
854.519	79.5563
857.889	77.4853
861.256	74.4455
864.622	71.0772
867.988	66.5303
871.351	65.1951
874.713	62.7247
878.074	62.5611
881.435	60.1135
884.794	58.2923
888.15	56.75
891.506	55.4833
894.861	55.1465
898.214	55.7877
901.566	56.1187
904.916	57.7595
908.266	58.7744
911.614	59.9212
914.961	61.8332
918.306	62.8018
921.651	63.3351
924.994	64.017
928.336	63.495
931.674	62.0951
935.014	60.6562
938.352	58.0297
941.687	55.7528
945.022	54.7327
948.357	52.8653
951.688	50.9946
955.02	49.157
958.348	46.8071
961.678	43.7236
965.004	43.5305
968.331	44.6287
971.655	45.3298
974.979	46.0217
978.3	47.2349
981.62	49.2388
984.941	48.5016
988.259	48.5409
991.575	49.0195
994.89	51.1472
998.204	51.0055
1001.52	51.8873
1004.83	52.0649
1008.14	52.979
1011.45	50.0171
1014.76	49.7703
1018.06	47.3593
1021.37	45.7347
1024.67	44.8816
1027.97	43.8033
1031.27	40.4692
1034.57	37.006
1037.87	32.2797
1041.17	30.2052
1044.47	32.7455
1047.76	33.9201
1051.06	33.7474
1054.35	34.3157
1057.64	32.8613
1060.93	33.3337
1064.22	32.5387
1067.5	31.9368
1070.79	32.3389
1074.08	33.1896
1077.36	32.4834
1080.64	33.5503
1083.92	33.5227
1087.2	33.674
1090.48	34.6152
1093.76	37.0378
1097.03	38.1548
1100.31	38.4828
1103.58	40.6497
1106.85	40.5003
1110.12	40.381
1113.39	38.1715
1116.66	37.7471
1119.93	36.5706
1123.19	36.3028
1126.46	35.8481
1129.72	35.2582
1132.98	34.3281
1136.24	33.7548
1139.5	33.5623
1142.76	31.524
1146.01	29.7436
1149.27	25.3347
1152.53	22.075
1155.78	19.5473
1159.03	16.767
1162.28	14.379
1165.53	12.8623
1168.78	11.8573
1172.02	12.3611
1175.27	11.853
1178.51	12.4002
1181.76	11.3263
1185	11.2226
1188.24	11.4651
1191.48	12.1024
1194.71	12.3562
1197.95	14.8543
1201.19	16.6894
1204.42	19.6
1207.65	21.9068
1210.88	26.3561
1214.12	30.8736
1217.35	34.7808
1220.57	38.0067
1223.8	39.711
1227.03	42.262
1230.25	45.3202
1233.47	47.4218
1236.69	49.8131
1239.92	52.008
1243.13	54.1657
1246.35	55.1009
1249.57	55.6623
1252.78	56.9166
1256	56.6132
1259.21	54.2052
1262.42	52.8379
1265.63	52.1759
1268.84	50.5637
1272.05	49.5588
1275.26	50.1025
1278.46	49.7085
1281.67	50.2967
1284.87	50.4758
1288.07	51.5586
1291.27	55.4492
1294.47	57.3324
1297.67	58.5602
1300.87	61.8916
1304.06	65.877
1307.26	70.2615
1310.45	75.1077
1313.64	78.2169
1316.83	82.4291
1320.02	84.6435
1323.21	86.6994
1326.4	87.0089
1329.59	86.6297
1332.77	86.9459
1335.95	84.4656
1339.14	83.7687
1342.32	82.5039
1345.5	80.4625
1348.67	78.4279
1351.85	76.7799
1355.03	74.0245
1358.2	70.6999
1361.38	69.0838
1364.55	66.4464
1367.72	64.3098
1370.89	61.8371
1374.06	60.0813
1377.23	58.7297
1380.39	58.9701
1383.56	58.3552
1386.72	57.659
1389.89	56.3747
1393.05	55.0249
1396.21	52.6371
1399.37	50.1733
1402.52	49.2217
1405.68	48.4861
1408.84	48.7161
1411.99	50.8985
1415.15	54.866
1418.3	56.7839
1421.45	60.7511
1424.6	64.6536
1427.75	68.5927
1430.89	73.2099
1434.04	77.533
1437.18	81.2178
1440.33	84.8317
1443.47	86.5216
1446.61	88.7093
1449.75	88.8323
1452.89	89.117
1456.03	87.5766
1459.16	85.3102
1462.3	81.3214
1465.43	75.9949
1468.56	69.8625
1471.7	64.8018
1474.83	56.7947
1477.96	51.0979
1481.08	44.6669
1484.21	39.7143
1487.34	36.2319
1490.46	31.9606
1493.58	27.6097
1496.71	24.4166
1499.83	22.9105
1502.95	21.0528
1506.07	18.904
1509.18	18.177
1512.3	17.8004
1515.41	18.4751
1518.53	19.4261
1521.64	19.9061
1524.75	20.9514
1527.86	22.0814
1530.97	23.4038
1534.08	27.0794
1537.19	28.6491
1540.29	30.601
1543.4	32.8199
1546.5	37.6298
1549.6	40.8353
1552.7	45.4348
1555.8	48.8131
1558.9	52.379
1562	54.9192
1565.09	56.5975
1568.19	59.1633
1571.28	62.562
1574.37	64.588
1577.47	65.879
1580.56	66.7798
1583.64	68.1165
1586.73	68.5578
1589.82	69.3306
1592.9	69.0663
1595.99	68.525
1599.07	67.0332
1602.15	65.8074
1605.23	64.9683
1608.31	64.3489
1611.39	64.393
1614.47	64.1998
1617.55	63.0924
1620.62	65.5472
1623.7	67.6433
1626.77	67.866
1629.84	68.905
1632.91	69.7562
1635.98	71.161
1639.05	73.981
1642.11	75.7214
1645.18	77.6154
1648.24	78.7763
1651.31	80.5118
1654.37	81.3088
1657.43	81.0274
1660.49	80.8242
1663.55	80.0459
1666.61	78.0571
1669.66	76.2386
1672.72	71.9114
1675.77	69.2006
1678.83	64.5425
1681.88	58.2287
1684.93	53.125
1687.98	47.7479
1691.03	43.3832
1694.07	37.4017
1697.12	33.3283
1700.17	28.76
1703.21	24.3656
1706.25	20.4173
1709.29	17.3065
1712.33	15.1799
1715.37	12.5379
1718.41	11.619
1721.45	9.53813
1724.49	10.1227
1727.52	9.28478
1730.55	8.46252
1733.59	8.46721
1736.62	9.36915
1739.65	8.63218
1742.68	8.48182
1745.7	8.91895
1748.73	8.812
1751.76	8.01574
1754.78	6.48229
1757.8	7.31988
1760.83	8.00641
1763.85	8.0565
1766.87	7.76142
1769.89	7.18338
1772.9	6.60914
1775.92	6.9193
1778.94	5.97397
1781.95	5.2571
1784.96	5.18652
1787.97	4.1206
1790.99	3.92296
1794	3.27461
1797	2.78714
1800.01	2.58454
1803.02	1.91111
1806.02	1.02286
1809.03	1.21164
1812.03	1.48398
1815.03	2.16819
1818.03	2.9245
1821.03	2.96402
1824.03	2.9356
1827.03	2.28654
1830.02	2.63039
1833.02	3.40153
1836.01	3.53312
1839.01	3.90814
1842	3.80476
1844.99	4.45336
1847.98	4.82962
1850.97	5.03817
1853.95	4.70865
1856.94	4.47853
1859.93	4.47112
1862.91	3.4331
1865.89	2.90784
1868.87	2.89672
1871.85	2.83348
1874.83	2.92811
1877.81	2.65554
1880.79	3.6983
1882.52	3.79972
1885.51	4.97516
1888.5	5.16192
1891.49	5.19469
1894.47	5.22264
1897.46	3.97524
1900.44	4.25727
1903.42	5.28483
1906.4	5.45983
1909.38	6.94298
1912.36	7.3864
1915.34	7.67059
1918.32	8.57867
1921.29	9.11551
1924.27	9.00599
1927.24	8.40597
1930.21	8.00099
1933.18	7.10161
1936.15	6.65731
1939.12	7.42493
1942.09	7.5428
1945.06	7.76705
1948.02	7.22379
1950.99	6.49116
1953.95	6.46615
1956.91	7.24737
1959.88	7.4694
1962.84	6.13074
1965.8	4.60335
1968.75	3.64025
1971.71	3.23159
1974.67	3.83786
1977.62	4.58038
1980.58	3.88419
1983.53	4.37558
1986.48	5.07893
1989.43	5.39751
1992.38	6.31079
1995.33	5.93537
1998.27	6.15695
2001.22	6.78761
2004.16	7.65168
2007.11	8.80221
2010.05	9.2903
2012.99	9.84463
2015.93	8.83958
2018.87	8.86638
2021.81	8.69828
2024.75	9.1694
2027.69	9.30382
2030.62	9.15757
2033.56	9.01453
2036.49	8.04001
2039.42	8.17818
2042.35	8.64536
2045.28	8.85076
2048.21	8.96619
2051.14	9.8121
2054.07	9.78288
2056.99	10.9011
2059.92	10.8802
2062.84	11.7961
2065.76	12.9065
2068.68	12.9717
2071.6	12.4964
2074.52	11.1982
2077.44	10.7992
2080.36	10.5103
2083.27	9.79446
2086.19	8.59908
2089.1	8.0524
2092.02	8.08278
2094.93	7.55311
2097.84	7.17774
2100.75	7.3448
2103.66	7.70735
2106.56	7.67991
2109.47	7.1871
2112.38	7.72735
2115.28	8.22933
2118.18	8.39914
2121.09	8.33548
2123.99	8.99142
2126.89	9.48322
2129.79	9.62089
2132.68	10.598
2135.58	10.4278
2138.48	8.35947
2141.37	7.44318
2144.27	5.86296
2147.16	5.63379
2150.05	5.17531
2152.94	4.5698
2155.83	4.05522
2158.72	3.91628
2161.6	3.81272
2164.49	3.1674
2167.38	4.16067
2170.26	3.43851
2173.14	3.35225
2176.03	3.30552
2178.91	3.28321
2181.79	4.35463
2184.67	4.73536
2187.54	5.58013
2190.42	5.93407
2193.3	6.66758
2196.17	8.38995
2199.05	9.52936
2201.92	9.87705
2204.79	10.3551
2207.66	9.83922
2210.53	9.3671
2213.4	8.51987
2216.27	8.9332
2219.13	9.00843
2222	9.65529
2224.86	9.34145
2227.72	8.91482
2230.59	9.1347
2233.45	8.28666
2236.31	6.72126
2239.17	5.83057
2242.03	5.60851
2244.88	5.85791
2247.74	4.92435
2250.59	4.37925
2253.45	4.80138
2256.3	5.77224
2259.15	6.12023
2262	6.21534
2264.85	6.74657
2267.7	7.52707
2270.55	6.70897
2273.4	6.24739
2276.24	6.4987
2279.09	6.02389
2281.93	4.77875
2284.77	4.58256
2287.62	4.25582
2290.46	3.9557
2293.3	3.50856
2296.13	3.78654
2298.97	4.90017
2301.81	6.15247
2304.64	6.63685
2307.48	7.84586
2310.31	9.26126
2313.14	9.12114
2315.98	9.72625
2318.81	10.0885
2321.64	10.6927
2324.46	10.7686
2327.29	11.1564
2330.12	10.8571
2332.94	10.683
2335.77	9.56221
2338.59	9.28848
2341.41	7.86385
2344.23	6.87523
2347.05	5.45143
2349.87	3.82499
2352.69	2.60868
2355.51	0.815688
2358.32	0.954201
2361.14	0.887459
2363.95	1.25741
2366.76	1.47523
2369.58	1.5389
2372.39	0.513669
2375.2	-0.461146
2378	-0.414698
2380.81	-0.49047
2383.62	-0.682382
2386.43	0.224025
2389.23	-0.118692
2392.03	0.229263
2394.84	0.540738
2397.64	0.251718
2400.44	1.03131
2403.24	1.22685
2406.04	1.39852
2408.84	2.28457
2411.63	3.50076
2414.43	5.21169
2417.22	5.9474
2420.02	6.79433
2422.81	7.69043
2425.6	8.1169
2428.39	8.40682
2431.18	8.31636
2433.97	8.48705
2436.76	8.38804
2439.54	7.97094
2442.33	7.67973
2445.12	7.47662
2447.9	7.23858
2450.68	5.99968
2453.46	5.47787
2456.24	5.4801
2459.02	4.72401
2461.8	3.33699
2464.58	2.03245
2467.36	0.965547
2470.13	0.757329
2472.91	0.343528
2475.68	0.774048
2478.45	0.885849
2481.23	0.529287
2484	0.592399
2486.77	-0.219891
2489.54	0.394615
2492.3	1.25827
2495.07	2.10467
2497.84	2.63529
2500.6	3.35097
2503.36	3.81312
2506.13	3.41312
2508.89	3.29672
2511.65	4.73943
2514.41	3.9345
2517.17	3.61697
2519.93	3.97843
2522.68	4.13483
2525.44	3.88244
2528.19	3.24218
2530.95	2.99829
2533.7	3.48914
2536.45	3.2059
2539.2	3.86849
2541.95	3.34666
2544.7	2.93806
2547.45	2.19661
2550.2	2.07397
2552.94	2.10158
2555.69	2.39057
2558.43	3.37129
2561.18	2.98279
2563.92	2.18696
2566.66	1.50792
2569.4	1.98449
2572.14	2.88616
2574.88	3.34751
2577.61	3.75036
2580.35	3.82212
2583.09	3.68501
2585.82	3.55247
2588.55	3.44326
2591.29	3.87315
2594.02	4.58481
2596.75	5.35977
2599.48	6.12058
2602.21	6.5043
2604.93	6.47134
2607.66	6.72988
2610.39	5.66653
2613.11	5.50018
2615.83	4.59144
2618.56	4.0937
2621.28	3.6012
2624	3.60417
2626.72	2.90897
2629.44	2.08477
2632.15	2.55596
2634.87	4.25723
2637.59	5.41325
2640.3	5.73487
2643.02	6.47365
2645.73	7.20508
2648.44	7.37628
2651.15	7.48876
2653.86	7.79852
2656.57	8.82065
2659.28	10.0429
2661.99	10.6353
2664.69	11.8087
2667.4	11.6398
2670.1	11.8537
2672.81	11.8192
2675.51	11.9163
2678.21	11.3325
2680.91	11.1546
2683.61	10.0355
2686.31	9.10404
2689	9.63217
2691.7	9.4067
2694.4	9.53179
2697.09	10.7034
2699.79	12.6034
2702.48	13.7053
2705.17	14.3722
2707.86	14.9514
2710.55	14.8586
2713.24	15.1174
2715.93	15.0075
2718.62	15.4986
2721.3	16.1618
2723.99	17.1086
2726.67	17.1186
2729.35	18.103
2732.04	17.6206
2734.72	17.1858
2737.4	16.373
2740.08	15.758
2742.76	14.9828
2745.43	13.109
2748.11	12.0537
2750.79	11.2807
2753.46	10.5397
2756.14	10.0147
2758.81	10.0763
2761.48	10.7535
2764.15	10.4761
2766.82	9.68985
2769.49	8.76541
2772.16	7.36253
2774.82	6.8998
2777.49	6.38735
2780.16	6.29392
2782.82	6.15115
2785.48	5.40458
2788.15	4.20417
2790.81	3.73856
2793.47	2.99691
2796.13	2.86549
2798.79	1.45472
2801.44	1.28683
2804.1	2.33577
2806.76	1.63884
2809.41	0.701611
2812.07	0.383394
2814.72	1.93268
2817.37	4.25883
2820.02	7.06995
2822.67	11.299
2825.32	15.695
2827.97	19.563
2830.62	24.4078
2833.26	29.0764
2835.91	34.3226
2838.56	41.2157
2841.2	48.7086
2843.84	57.2434
2846.48	65.7433
2849.12	75.6215
2851.77	85.5483
2854.4	96.6134
2857.04	108.308
2859.68	119.913
2862.32	130.294
2864.95	141.55
2867.59	151.881
2870.22	160.677
2872.85	169.2
2875.48	176.981
2878.11	184.711
2880.74	192.421
2883.37	200.15
2886	206.487
2888.63	212.476
2891.25	217.57
2893.88	223.035
2896.5	228.902
2899.13	234.98
2901.75	242.348
2904.37	251.211
2906.99	260.444
2909.61	269.88
2912.23	281.323
2914.85	291.99
2917.46	302.001
2920.08	310.593
2922.7	318.583
2925.31	322.677
2927.92	325.336
2930.54	326.201
2933.15	324.551
2935.76	319.653
2938.37	313.813
2940.98	306.854
2943.58	296.678
2946.19	286.871
2948.8	276.819
2951.4	264.234
2954.01	252.445
2956.61	240.132
2959.21	228.67
2961.81	217.548
2964.41	207.014
2967.01	197.047
2969.61	186.2
2972.21	176.899
2974.81	167.745
2977.4	159.349
2980	149.883
2982.59	139.955
2985.18	130.069
2987.78	118.921
2990.37	107.077
2992.96	97.3078
2995.55	86.4322
2998.14	75.9837
3000.73	66.1559
3003.31	57.3135
3005.9	48.6965
3008.48	40.9054
3011.07	33.9999
3013.65	27.9145
3016.23	22.6912
3018.81	17.868
3021.4	14.1086
3023.97	11.2382
3026.55	9.63907
3029.13	7.43854
3031.71	5.41803
3034.28	4.79549
3036.86	5.9446
3039.43	6.72657
3042.01	8.92522
3044.58	10.7318
3047.15	11.5417
3049.72	13.2631
3052.29	14.6765
3054.86	15.7256
3057.43	16.3292
3060	16.6264
3062.56	15.8345
3065.13	15.5919
3067.69	14.4057
3070.26	13.6376
3072.82	12.5992
3075.38	10.9096
3077.94	9.53843
3080.5	7.5446
3083.06	5.85638
3085.62	4.14203
3088.18	2.92766
3090.73	1.15934
3093.29	0.0499211
3095.84	0.455209
3098.4	0.0064249
3100.95	-0.146624
3103.5	0.0198376
3106.05	0.879388
3108.6	1.55101
3111.15	3.0736
3113.7	4.12556
3116.25	4.64991
3118.79	5.51101
3121.34	6.08472
3123.88	6.79991
3126.43	7.22679
3128.97	8.79418
3131.51	10.6912
3134.06	11.6002
3136.6	12.6102
3139.14	13.623
3141.67	14.0498
3144.21	13.9306
3146.75	13.9131
3149.29	13.929