File: data/Raman/poly_smoothed/Thy_20_09_17_1x_45s_532 nm_x100_100%_600 gr_mm_01.txt
#Acq. time (s)=	45
#Accumulations=	2
#Range (cm-¹)=	200...3150
#Windows=	2
#Auto scanning=	Off
#Autofocus=	Off
#Macrospot=	Off
#AutoExposure=	Off
#Spike filter=	Multiple accum.
#Delay time (s)=	0
#Binning=	1
#Readout mode=	Signal
#DeNoise=	Off
#ICS correction=	On
#Dark correction=	Off
#Inst. Process=	Off
#Detector Gain=	Best Dynamic Range
#Detector ADC=	20 kHz
#Detector temperature (°C)=	-69.85
#Instrument=	LabRAM HR Evol
#Detector=	Synapse
#Objective=	x100
#Grating=	600 gr/mm
#ND Filter=	100%
#Laser (nm)=	532
#Hole=	100.021
#Range=	Auto
#Laser Pol.=	No
#Raman. Pol.=	No
#Laser Pol. (°)=	-0.0007625
#Raman Pol. (°)=	89.9995
#Collection=	Microscope
#StageXY=	Marzhauser
#StageZ=	Marzhauser
#X (µm)=	-5887.4
#Y (µm)=	2883.3
#Z (µm)=	-223.85
#Full time(mm:ss)=	3:18
#Project=
#Sample=
#Site=
#Title=	Thy_20_09_17_2x_45s_532 nm_x100_100%_600 gr_mm
#Remark=
#Date=	29.06.2022 11:53
#Acquired=	29.06.2022 11:53:29
#Base:Fit=	10.08.2022 09:52:02
#Base:Fit=	10.08.2022 09:52:12
#Base:Sub=	10.08.2022 09:54:21
#Filter:Polynom=	16.08.2022 10:24:04
#AxisType[0]=Intens
#AxisUnit[0]=Cnt
#AxisType[1]=Spectr
#AxisUnit[1]=1/cm
200.523	24.6754
204.154	19.4608
207.781	14.9726
211.409	11.7166
215.034	9.27624
218.659	7.17748
222.281	5.5657
225.903	3.6563
229.522	1.97882
233.14	2.42957
236.756	1.65146
240.373	2.52572
243.986	2.13552
247.598	2.61063
251.208	3.4152
254.818	3.30187
258.427	3.32526
262.034	4.23075
265.638	4.99469
269.242	3.25146
272.844	2.37204
276.445	2.22032
280.044	2.87964
283.642	3.79485
287.238	5.81796
290.833	6.7752
294.425	7.73348
298.017	8.98736
301.608	9.71376
305.198	9.01894
308.786	10.6033
312.371	10.353
315.956	10.3408
319.54	10.8908
323.122	12.8528
326.701	13.9979
330.281	15.6098
333.857	15.5112
337.434	15.5137
341.008	14.5598
344.582	14.7272
348.153	15.2139
351.724	15.4049
355.292	16.4683
358.861	15.2223
362.426	14.8682
365.99	13.9861
369.555	13.8995
373.116	15.5157
376.676	14.6099
380.236	15.4922
383.793	15.8513
387.349	16.0748
390.903	14.2639
394.456	13.0963
398.007	11.8157
401.56	10.2139
405.108	9.03388
408.656	10.6856
412.202	10.6437
415.746	9.55874
419.29	7.8341
422.831	6.36277
426.37	6.61155
429.909	7.64336
433.447	7.62702
436.983	7.44328
440.519	7.03703
444.052	5.74349
447.583	5.44943
451.114	5.41066
454.643	6.70169
458.169	9.69948
461.696	12.0144
465.222	14.1389
468.744	16.0965
472.267	17.6252
475.787	19.3914
479.307	19.8694
482.823	20.1208
486.341	22.0194
489.855	22.661
493.37	23.5952
496.881	23.282
500.391	24.5516
503.902	24.0388
507.409	25.4777
510.915	26.0248
514.42	25.3486
517.925	23.0296
521.427	21.3525
524.928	19.6528
528.427	18.3901
531.925	17.1867
535.422	16.8516
538.917	15.5057
542.411	13.3699
545.903	11.9077
549.395	10.069
552.884	9.18374
556.373	8.26446
559.86	8.44552
563.346	8.66587
566.831	6.72946
570.314	7.56052
573.794	7.22391
577.274	6.84862
580.754	6.54732
584.23	8.35221
587.706	9.09708
591.181	8.89566
594.653	9.22236
598.126	7.97884
601.595	9.29525
605.065	10.0498
608.532	10.4119
611.999	11.3581
615.463	12.6112
618.928	14.616
622.389	15.0572
625.851	13.6327
629.31	15.0143
632.767	17.7617
636.223	20.1381
639.68	23.6766
643.134	24.4845
646.586	25.0086
650.037	24.5513
653.486	23.9719
656.936	24.4997
660.383	23.852
663.829	23.5837
667.273	23.6932
670.716	22.76
674.158	22.0218
677.598	22.8536
681.035	24.4942
684.473	26.1576
687.909	26.8159
691.344	28.39
694.778	29.9689
698.211	32.9998
701.64	35.1087
705.07	36.3887
708.498	37.3623
711.924	40.3252
715.35	41.4689
718.774	42.2686
722.196	45.3384
725.618	44.4223
729.037	43.1751
732.456	43.1893
735.873	43.505
739.289	43.7535
742.703	43.6987
746.116	45.4428
749.529	47.5856
752.938	49.6615
756.347	51.4213
759.756	54.0105
763.162	57.7968
766.567	58.9937
769.97	61.4986
773.372	64.7817
776.773	65.1844
780.174	67.3682
783.573	69.5307
786.97	71.744
790.365	74.0905
793.76	74.8839
797.153	74.3946
800.543	74.7169
803.933	77.1177
807.322	77.7328
810.71	77.5528
814.097	77.6501
817.483	78.6822
820.865	78.626
824.248	78.7255
827.629	78.8495
831.008	78.3189
834.387	76.6886
837.765	73.9393
841.139	70.9851
844.514	68.2334
847.886	66.3101
851.259	63.3485
854.629	60.2353
857.997	55.7131
861.366	54.2138
864.732	52.4887
868.098	50.454
871.461	49.8174
874.823	47.6276
878.184	47.21
881.545	46.5407
884.903	46.0245
888.26	46.3519
891.616	46.1558
894.97	47.1942
898.323	47.2553
901.675	46.3273
905.026	46.2561
908.375	46.1402
911.723	44.0424
915.07	42.7107
918.415	41.1041
921.76	39.3197
925.103	38.6378
928.443	37.1674
931.783	35.7667
935.123	33.5071
938.461	33.1531
941.796	32.2223
945.131	29.9152
948.465	28.3846
951.797	29.7406
955.128	29.0891
958.457	26.871
961.786	25.3924
965.113	25.7243
968.44	27.4017
971.763	28.9072
975.086	29.0842
978.409	30.4141
981.729	29.2744
985.048	28.9608
988.367	28.454
991.683	27.2412
994.998	26.524
998.312	25.6899
1001.62	25.3202
1004.94	23.7492
1008.25	24.1658
1011.56	24.159
1014.86	23.4995
1018.17	22.7156
1021.48	22.2437
1024.78	19.7315
1028.08	18.9317
1031.38	18.2348
1034.68	17.254
1037.98	16.2225
1041.28	16.1531
1044.57	16.5108
1047.87	16.7818
1051.16	16.7069
1054.45	15.5294
1057.75	14.8821
1061.04	14.4653
1064.32	12.8635
1067.61	11.9879
1070.9	11.1223
1074.18	11.1777
1077.47	10.7217
1080.75	10.495
1084.03	9.74456
1087.31	9.88969
1090.59	11.8488
1093.86	11.778
1097.14	12.8911
1100.41	13.7991
1103.69	13.0736
1106.96	13.5123
1110.23	13.4546
1113.5	12.9577
1116.77	12.371
1120.03	11.8082
1123.3	11.2883
1126.56	11.2022
1129.83	10.2624
1133.09	9.60538
1136.35	8.27186
1139.61	7.05891
1142.86	5.77535
1146.12	5.093
1149.38	3.26511
1152.63	2.7202
1155.88	1.83376
1159.14	1.11377
1162.39	0.275929
1165.63	0.283521
1168.88	0.0706701
1172.13	1.46744
1175.38	1.83104
1178.62	2.18654
1181.86	2.87665
1185.1	4.382
1188.34	6.26138
1191.58	7.6296
1194.82	10.2127
1198.06	11.4135
1201.29	16.016
1204.53	18.2659
1207.76	19.8981
1210.99	21.6728
1214.22	23.5798
1217.45	25.9204
1220.68	28.3379
1223.91	32.0344
1227.13	33.6208
1230.36	35.8614
1233.58	37.9791
1236.8	38.3614
1240.02	40.0789
1243.24	42.6597
1246.46	43.9022
1249.67	44.7488
1252.89	46.8046
1256.1	48.5835
1259.32	49.8756
1262.53	51.5717
1265.74	52.6639
1268.95	54.9849
1272.15	55.6085
1275.36	56.6314
1278.57	57.7039
1281.77	59.3926
1284.97	58.8157
1288.18	59.6264
1291.38	60.9497
1294.58	60.8339
1297.78	62.9776
1300.97	64.131
1304.17	64.8308
1307.36	65.1162
1310.55	67.581
1313.75	68.6981
1316.94	70.5988
1320.13	71.2659
1323.32	71.4921
1326.5	70.9107
1329.69	71.7457
1332.87	71.967
1336.06	69.1418
1339.24	67.8821
1342.42	68.0715
1345.6	65.3362
1348.78	64.4026
1351.96	62.4724
1355.13	60.3876
1358.31	58.4487
1361.48	55.2113
1364.65	53.5825
1367.82	51.8217
1370.99	49.3938
1374.16	46.8631
1377.33	44.8401
1380.5	43.3057
1383.66	41.8882
1386.83	41.0052
1389.99	39.5849
1393.15	38.292
1396.31	35.9075
1399.47	36.1812
1402.63	36.8891
1405.78	36.9011
1408.94	37.3111
1412.1	38.6786
1415.25	41.3658
1418.4	45.5247
1421.55	49.4068
1424.7	53.9847
1427.85	60.1788
1431	65.4509
1434.14	70.7397
1437.29	73.9202
1440.43	78.3262
1443.57	80.9337
1446.71	81.8423
1449.85	81.4842
1452.99	80.1156
1456.13	78.28
1459.26	75.1432
1462.4	71.7171
1465.54	66.1164
1468.67	60.7786
1471.8	56.2448
1474.93	50.182
1478.06	44.852
1481.19	39.2126
1484.31	33.0993
1487.44	28.5662
1490.56	23.9037
1493.69	21.4359
1496.81	19.3085
1499.93	18.9832
1503.05	19.2793
1506.17	19.5853
1509.28	19.5488
1512.4	19.3381
1515.52	18.5485
1518.63	20.344
1521.74	21.0021
1524.85	22.2146
1527.96	24.5001
1531.07	27.2408
1534.18	28.8765
1537.29	31.0271
1540.39	32.6504
1543.5	34.623
1546.6	37.7722
1549.7	40.1012
1552.8	43.9105
1555.9	48.0439
1559	51.0852
1562.1	53.4843
1565.19	55.5181
1568.29	56.4862
1571.38	59.469
1574.47	60.9089
1577.56	62.2216
1580.66	64.4997
1583.74	66.4437
1586.83	68.0362
1589.92	69.4398
1593.01	70.0677
1596.09	71.0188
1599.17	70.6657
1602.25	69.5989
1605.34	67.8084
1608.41	66.6525
1611.49	63.5464
1614.57	61.8575
1617.65	60.3851
1620.72	59.0181
1623.79	57.9834
1626.87	58.1372
1629.94	58.7033
1633.01	58.9786
1636.08	58.0579
1639.15	58.0848
1642.21	59.0331
1645.28	60.5049
1648.34	62.5322
1651.41	63.5528
1654.47	66.0743
1657.53	66.9404
1660.59	67.7167
1663.65	67.6709
1666.71	66.9995
1669.76	65.7938
1672.82	63.3582
1675.87	59.909
1678.93	55.1796
1681.98	51.6714
1685.03	47.3862
1688.08	42.8736
1691.13	36.4935
1694.17	31.3919
1697.22	26.1763
1700.27	22.2113
1703.31	18.687
1706.35	15.6058
1709.39	13.658
1712.43	10.3681
1715.47	9.29253
1718.51	9.41146
1721.55	9.38854
1724.58	8.81547
1727.62	8.88927
1730.65	9.28013
1733.68	9.2204
1736.72	9.9359
1739.74	10.7861
1742.77	9.95519
1745.8	10.222
1748.83	10.3669
1751.85	9.95041
1754.88	8.66745
1757.9	8.80314
1760.92	7.29839
1763.95	5.53079
1766.96	3.85773
1769.98	3.15712
1773	1.92529
1776.02	1.04889
1779.03	0.303859
1782.05	-0.613307
1785.06	-1.04988
1788.07	-1.0528
1791.08	-0.168442
1794.09	-0.0700461
1797.1	-0.134404
1800.11	0.00744508
1803.12	0.400562
1806.12	-0.26168
1809.12	-0.119181
1812.13	0.194339
1815.13	0.607857
1818.13	1.49797
1821.13	2.09921
1824.13	2.08163
1827.13	2.87007
1830.12	3.7284
1833.12	3.849
1836.11	3.77991
1839.1	3.95769
1842.09	3.24214
1845.09	2.8825
1848.08	2.08961
1851.06	2.55787
1854.05	2.78806
1857.04	2.69342
1860.02	3.13469
1863.01	3.01966
1865.99	2.21311
1868.97	2.30088
1871.95	2.01979
1874.93	1.72015
1877.91	1.02252
1880.89	1.41214
1882.46	1.35498
1885.45	1.74435
1888.43	2.56548
1891.42	2.05973
1894.41	2.69302
1897.39	3.69115
1900.37	4.49682
1903.36	4.54103
1906.34	4.48996
1909.32	4.94843
1912.29	5.61055
1915.27	5.92769
1918.25	6.79714
1921.23	6.43142
1924.2	7.51537
1927.17	7.68917
1930.15	8.01842
1933.12	7.34499
1936.09	7.13072
1939.06	6.5913
1942.02	5.39286
1944.99	4.51291
1947.96	4.39963
1950.92	3.97431
1953.88	3.91879
1956.85	4.14461
1959.81	4.1896
1962.77	3.9837
1965.73	3.80945
1968.69	3.84784
1971.64	2.7757
1974.6	3.04007
1977.55	2.9581
1980.51	4.47842
1983.46	4.45658
1986.41	4.53552
1989.36	4.78195
1992.31	5.46563
1995.26	5.42145
1998.21	5.01153
2001.15	4.57419
2004.1	2.81138
2007.04	2.21653
2009.99	1.47606
2012.93	1.56079
2015.87	1.48955
2018.81	1.97667
2021.75	1.94771
2024.68	2.44744
2027.62	2.86795
2030.56	3.24616
2033.49	3.49896
2036.42	4.78657
2039.36	5.01035
2042.29	5.28452
2045.22	6.40618
2048.14	7.79968
2051.07	8.375
2054	8.31657
2056.93	7.544
2059.85	9.17295
2062.77	9.87805
2065.7	9.34428
2068.62	8.64647
2071.54	9.05628
2074.46	7.93554
2077.38	7.88048
2080.29	8.69272
2083.21	9.64876
2086.12	10.5575
2089.04	9.85477
2091.95	9.64419
2094.86	9.90446
2097.77	11.0673
2100.68	12.0957
2103.59	14.4351
2106.5	15.998
2109.41	17.1809
2112.31	18.2717
2115.21	19.9664
2118.12	21.5306
2121.02	22.7124
2123.92	23.8183
2126.82	25.2918
2129.72	26.6982
2132.62	28.0815
2135.51	29.0227
2138.41	29.9231
2141.31	32.2806
2144.2	34.3193
2147.09	35.5008
2149.98	37.965
2152.87	39.9884
2155.76	40.9136
2158.65	41.8577
2161.54	42.8875
2164.43	44.1104
2167.31	46.4545
2170.2	48.7026
2173.08	50.0452
2175.96	50.1013
2178.84	50.1856
2181.72	50.0802
2184.6	49.9559
2187.48	49.7273
2190.36	48.2276
2193.23	46.2303
2196.11	43.5744
2198.98	40.9456
2201.85	38.8318
2204.72	36.4439
2207.59	34.1227
2210.46	31.937
2213.33	29.3321
2216.2	27.0804
2219.07	24.6903
2221.93	23.488
2224.8	20.3579
2227.66	18.0548
2230.52	16.4056
2233.39	15.5292
2236.25	15.614
2239.1	15.0287
2241.96	13.9224
2244.82	12.9186
2247.68	13.9266
2250.53	14.8203
2253.38	15.0193
2256.24	15.3395
2259.09	15.4514
2261.94	14.8526
2264.79	13.9743
2267.64	13.2748
2270.49	12.9401
2273.33	12.5724
2276.18	12.2637
2279.02	11.6684
2281.87	10.7889
2284.71	10.3759
2287.55	9.67419
2290.39	7.73689
2293.23	6.29802
2296.07	5.35525
2298.91	5.53777
2301.74	5.77602
2304.58	5.85012
2307.41	6.17231
2310.25	6.32857
2313.08	7.06931
2315.91	8.26741
2318.74	9.82262
2321.57	9.80846
2324.4	10.7097
2327.23	9.88996
2330.05	9.00581
2332.88	7.65935
2335.7	7.63952
2338.52	7.07661
2341.35	7.53333
2344.17	7.46201
2346.99	6.95196
2349.81	6.71183
2352.62	5.86257
2355.44	4.57013
2358.26	2.28028
2361.07	2.37465
2363.89	2.28616
2366.7	2.09955
2369.51	1.37892
2372.32	1.46972
2375.13	1.35903
2377.94	1.55471
2380.75	1.63408
2383.56	2.55659
2386.36	3.27221
2389.17	3.14805
2391.97	3.28636
2394.77	3.20819
2397.58	3.47544
2400.38	3.98587
2403.18	3.78174
2405.97	4.2428
2408.77	5.16954
2411.57	6.06574
2414.37	6.90986
2417.16	7.53989
2419.95	8.66175
2422.75	8.94124
2425.54	8.75352
2428.33	9.09683
2431.12	9.33262
2433.91	9.95971
2436.7	10.1752
2439.48	9.38088
2442.27	8.89886
2445.05	8.66417
2447.84	8.04955
2450.62	8.34229
2453.4	8.33816
2456.18	7.55469
2458.96	6.79882
2461.74	6.66043
2464.52	6.17731
2467.29	6.14165
2470.07	5.46179
2472.85	5.64685
2475.62	6.0023
2478.39	6.08891
2481.16	6.45677
2483.93	7.34036
2486.7	6.77154
2489.47	6.49773
2492.24	5.9308
2495.01	4.86389
2497.77	4.9949
2500.54	4.96305
2503.3	4.31418
2506.06	4.2279
2508.83	3.71215
2511.59	3.03025
2514.35	3.43805
2517.11	4.60146
2519.86	4.97488
2522.62	5.12059
2525.38	5.07236
2528.13	4.77354
2530.89	5.46538
2533.64	5.10999
2536.39	5.60675
2539.14	5.81243
2541.89	6.77387
2544.64	6.89241
2547.39	6.87106
2550.14	6.98887
2552.88	6.12115
2555.63	5.55057
2558.37	4.47544
2561.11	4.61522
2563.86	4.37899
2566.6	4.57449
2569.34	4.17336
2572.08	3.59001
2574.82	2.59814
2577.55	2.16993
2580.29	1.79805
2583.02	1.93068
2585.76	2.0748
2588.49	1.82167
2591.22	1.64602
2593.96	1.46001
2596.69	0.898116
2599.42	0.79612
2602.14	1.27226
2604.87	1.54203
2607.6	2.60003
2610.32	2.24214
2613.05	1.74546
2615.77	2.01242
2618.49	1.99562
2621.22	2.25489
2623.94	2.7204
2626.66	2.62237
2629.37	2.87364
2632.09	3.0251
2634.81	3.14366
2637.53	2.36524
2640.24	2.64221
2642.96	2.96599
2645.67	3.23514
2648.38	3.42962
2651.09	4.37676
2653.8	4.615
2656.51	4.58547
2659.22	5.37154
2661.93	6.17341
2664.63	6.15709
2667.34	7.41824
2670.04	7.16542
2672.75	7.43251
2675.45	7.22129
2678.15	7.19354
2680.85	7.97214
2683.55	8.38395
2686.25	8.31779
2688.94	9.29874
2691.64	8.77053
2694.34	9.25838
2697.03	9.46928
2699.73	9.58944
2702.42	10.3444
2705.11	10.4887
2707.8	11.3596
2710.49	11.0871
2713.18	11.1897
2715.87	11.4814
2718.55	11.3543
2721.24	10.7151
2723.93	11.3105
2726.61	10.6181
2729.29	10.2609
2731.98	9.38288
2734.66	8.39187
2737.34	8.02446
2740.02	7.04607
2742.7	5.82037
2745.37	6.19093
2748.05	4.72852
2750.72	4.05749
2753.4	2.97115
2756.07	2.69057
2758.75	2.18866
2761.42	1.5281
2764.09	1.96574
2766.76	2.42335
2769.43	2.421
2772.1	2.49724
2774.76	2.45748
2777.43	1.83443
2780.1	1.73436
2782.76	2.43426
2785.42	2.27398
2788.09	2.53892
2790.75	2.15822
2793.41	1.90661
2796.07	2.09763
2798.73	1.57144
2801.39	1.59646
2804.04	1.70585
2806.7	0.736486
2809.35	0.179518
2812.01	-0.248875
2814.66	-1.16962
2817.31	-0.387636
2819.96	1.44417
2822.61	2.34783
2825.26	4.5865
2827.91	7.62996
2830.56	10.2978
2833.21	14.236
2835.85	17.1383
2838.5	21.1543
2841.14	26.5904
2843.78	31.9373
2846.42	38.5244
2849.06	46.4478
2851.71	53.9372
2854.34	61.5476
2856.98	69.0651
2859.62	77.6403
2862.26	84.5866
2864.89	91.429
2867.53	97.6427
2870.16	102.78
2872.79	106.585
2875.42	109.577
2878.05	113.191
2880.68	117.078
2883.31	120.096
2885.94	122.856
2888.57	126.278
2891.19	129.054
2893.82	132.316
2896.44	136.348
2899.07	140.792
2901.69	146.267
2904.31	153.031
2906.93	160.265
2909.55	169.123
2912.17	177.847
2914.79	186.728
2917.41	195.557
2920.02	203.677
2922.64	210.465
2925.25	216.689
2927.86	220.169
2930.48	221.996
2933.09	221.854
2935.7	220.483
2938.31	217.199
2940.92	213.184
2943.53	208.218
2946.13	201.793
2948.74	195.832
2951.34	188.422
2953.95	181.261
2956.55	173.038
2959.15	165.407
2961.75	158.269
2964.35	151.045
2966.95	143.411
2969.55	136.25
2972.15	128.193
2974.75	121.229
2977.34	113.748
2979.94	105.307
2982.53	97.3654
2985.13	90.0346
2987.72	82.2022
2990.31	73.4424
2992.9	65.1134
2995.49	57.1651
2998.08	49.3652
3000.67	42.2472
3003.25	35.155
3005.84	29.622
3008.42	24.8145
3011.01	20.672
3013.59	17.4532
3016.17	14.9066
3018.76	11.3556
3021.34	9.79817
3023.92	9.0202
3026.49	7.43857
3029.07	6.26183
3031.65	6.39529
3034.23	6.84743
3036.8	7.46207
3039.38	8.5071
3041.95	9.16856
3044.52	10.9946
3047.09	13.3422
3049.66	14.004
3052.23	14.873
3054.8	16.3709
3057.37	16.4008
3059.94	16.2404
3062.5	16.3531
3065.07	15.2964
3067.63	14.9612
3070.2	15.1503
3072.76	13.994
3075.32	12.6308
3077.88	10.6818
3080.44	8.89184
3083	7.66322
3085.56	6.69157
3088.12	4.17005
3090.67	2.13734
3093.23	1.12378
3095.78	0.143761
3098.34	-0.256577
3100.89	0.219968
3103.44	0.600965
3105.99	1.0559
3108.54	1.62299
3111.09	1.25401
3113.64	2.20562
3116.19	3.69156
3118.74	3.87609
3121.28	4.14589
3123.83	4.9432
3126.37	5.8202
3128.91	6.5181
3131.46	8.21524
3134	9.13419
3136.54	8.94143
3139.08	10.3478
3141.62	11.1003
3144.16	11.3542
3146.69	10.9991
3149.23	12.1243