File: data/Raman/poly_smoothed/Thy_50_12_04_1x_45s_532 nm_x100_100%_600 gr_mm_01.txt
#Acq. time (s)=	45
#Accumulations=	2
#Range (cm-¹)=	200...3150
#Windows=	2
#Auto scanning=	Off
#Autofocus=	Off
#Macrospot=	Off
#AutoExposure=	Off
#Spike filter=	Multiple accum.
#Delay time (s)=	0
#Binning=	1
#Readout mode=	Signal
#DeNoise=	Off
#ICS correction=	On
#Dark correction=	Off
#Inst. Process=	Off
#Detector Gain=	Best Dynamic Range
#Detector ADC=	20 kHz
#Detector temperature (°C)=	-69.85
#Instrument=	LabRAM HR Evol
#Detector=	Synapse
#Objective=	x100
#Grating=	600 gr/mm
#ND Filter=	100%
#Laser (nm)=	532
#Hole=	100.021
#Range=	Auto
#Laser Pol.=	No
#Raman. Pol.=	No
#Laser Pol. (°)=	-0.0007625
#Raman Pol. (°)=	89.9995
#Collection=	Microscope
#StageXY=	Marzhauser
#StageZ=	Marzhauser
#X (µm)=	-5086.5
#Y (µm)=	1500.5
#Z (µm)=	62.65
#Full time(mm:ss)=	3:18
#Project=
#Sample=
#Site=
#Title=	Thy_50_12_04_2x_45s_532 nm_x100_100%_600 gr_mm
#Remark=
#Date=	07.07.2022 09:26
#Acquired=	07.07.2022 09:26:26
#Base:Fit=	10.08.2022 10:03:08
#Base:Fit=	10.08.2022 10:03:15
#Base:Fit=	10.08.2022 10:03:19
#Base:Fit=	10.08.2022 10:04:29
#Base:Sub=	10.08.2022 10:04:45
#Filter:Polynom=	16.08.2022 10:20:24
#AxisType[0]=Intens
#AxisUnit[0]=Cnt
#AxisType[1]=Spectr
#AxisUnit[1]=1/cm
200.43	52.415
204.061	46.5129
207.688	42.3139
211.316	37.1137
214.941	30.9408
218.566	25.8224
222.188	21.5922
225.809	18.0242
229.43	15.1779
233.047	12.8537
236.663	10.1389
240.278	7.57814
243.894	6.45293
247.506	5.27559
251.116	3.61807
254.725	3.76114
258.333	3.58643
261.939	2.8289
265.546	2.89904
269.15	2.17608
272.752	1.99944
276.353	2.35092
279.952	4.71031
283.55	4.80476
287.146	4.61259
290.739	5.27498
294.333	5.61506
297.925	4.2479
301.516	2.14447
305.106	3.03452
308.694	3.70676
312.279	5.29074
315.864	6.04903
319.448	5.95153
323.029	6.36648
326.61	6.08316
330.19	7.12053
333.766	8.38762
337.343	8.62985
340.917	9.4361
344.491	9.0497
348.062	8.45033
351.633	8.83499
355.201	8.02664
358.77	8.8546
362.335	8.48629
365.899	7.86792
369.464	7.67092
373.025	6.54451
376.585	7.81403
380.143	8.66071
383.702	7.78351
387.258	6.68213
390.812	7.27602
394.365	7.74484
397.916	7.36284
401.467	5.61609
405.015	5.80581
408.565	7.00544
412.111	5.75152
415.656	6.21347
419.197	5.35369
422.739	4.71256
426.279	3.8277
429.819	1.81656
433.356	-0.506208
436.893	0.242909
440.428	0.0307773
443.96	1.227
447.492	0.666341
451.023	0.340228
454.553	0.962959
458.079	3.21359
461.606	4.23923
465.132	5.72558
468.654	6.35867
472.177	8.85661
475.696	9.01353
479.217	10.4056
482.733	11.4854
486.251	13.6001
489.765	16.8059
493.278	18.0776
496.791	19.782
500.301	21.1625
503.81	22.7463
507.319	22.7127
510.825	23.9048
514.33	23.2018
517.833	23.237
521.337	24.6283
524.838	26.4775
528.337	26.2529
531.835	27.1257
535.332	26.6462
538.827	26.4431
542.321	23.0292
545.814	21.5627
549.305	19.7875
552.795	17.7578
556.284	16.1379
559.771	14.7185
563.257	12.8613
566.742	12.5763
570.223	11.2266
573.705	11.5632
577.185	11.5102
580.665	10.9733
584.141	11.6378
587.617	9.85681
591.092	9.99224
594.564	9.59568
598.037	9.31988
601.506	8.60008
604.976	11.0157
608.443	11.4908
611.91	11.8552
615.374	11.0601
618.839	11.2798
622.3	10.7173
625.761	10.1491
629.221	10.4252
632.679	10.768
636.135	11.7268
639.592	12.373
643.045	14.509
646.497	16.4984
649.948	18.6806
653.398	20.4386
656.846	22.4065
660.293	27.3308
663.738	27.8799
667.185	29.3328
670.628	31.7027
674.067	33.5739
677.508	34.9483
680.947	36.5167
684.385	37.4478
687.821	39.5484
691.256	40.106
694.69	41.6525
698.121	42.5693
701.552	42.2889
704.982	42.3595
708.41	43.9012
711.836	43.9964
715.262	43.9334
718.685	44.5791
722.108	44.3219
725.53	46.9032
728.949	47.6891
732.369	48.8666
735.785	51.3291
739.2	54.0947
742.616	55.8693
746.028	57.8608
749.441	59.3191
752.851	65.0452
756.26	69.2339
759.667	70.4381
763.075	74.8999
766.479	78.9201
769.883	81.4612
773.285	85.3158
776.686	87.6316
780.085	88.6934
783.484	89.297
786.881	90.8747
790.276	92.187
793.671	93.2353
797.064	94.5288
800.456	94.1341
803.846	94.6644
807.236	94.4581
810.624	94.2932
814.01	92.017
817.394	92.1027
820.778	93.9682
824.161	92.3439
827.543	91.916
830.921	91.5538
834.3	91.4796
837.676	89.3232
841.053	87.8541
844.426	87.3423
847.8	85.9335
851.171	82.5718
854.542	80.1545
857.911	79.2665
861.279	76.4747
864.645	75.2851
868.01	74.0264
871.375	73.2165
874.737	71.7399
878.097	70.1929
881.457	68.9049
884.817	68.4936
888.174	66.7583
891.53	64.7124
894.884	63.7785
898.237	63.4432
901.589	63.7299
904.94	62.9689
908.289	62.0456
911.637	59.9988
914.984	58.3084
918.33	58.9681
921.674	57.8648
925.015	55.0995
928.357	54.8387
931.698	53.023
935.037	51.3603
938.373	49.4242
941.71	48.065
945.046	46.9492
948.378	45.3147
951.711	45.8822
955.043	45.3242
958.372	44.581
961.701	45.79
965.027	45.0508
968.354	45.6452
971.678	46.1155
975	46.895
978.324	46.9833
981.644	47.4151
984.962	48.3956
988.282	47.7256
991.598	46.2777
994.913	46.345
998.227	46.9395
1001.54	46.336
1004.85	43.2709
1008.16	44.0331
1011.47	43.0008
1014.78	41.4169
1018.08	41.3075
1021.39	41.3131
1024.69	42.0858
1028	41.9054
1031.3	41.2229
1034.6	40.8379
1037.9	39.839
1041.19	38.3797
1044.49	38.0665
1047.79	36.772
1051.08	36.3665
1054.37	34.6158
1057.66	33.7093
1060.95	33.8229
1064.24	32.9958
1067.53	30.4553
1070.81	29.2559
1074.1	27.2653
1077.38	26.9589
1080.66	26.212
1083.94	26.6838
1087.22	27.3454
1090.5	25.3775
1093.78	22.5617
1097.05	27.1413
1100.33	31.5972
1103.6	34.9785
1106.87	37.724
1110.15	38.4079
1113.41	41.5342
1116.68	42.0854
1119.95	41.296
1123.21	39.2693
1126.48	38.2852
1129.74	36.3602
1133	35.2005
1136.26	34.5899
1139.52	32.052
1142.78	29.8663
1146.04	26.4198
1149.29	23.186
1152.55	21.4017
1155.8	17.8391
1159.05	16.2933
1162.3	14.5066
1165.55	11.385
1168.8	8.02167
1172.05	3.8691
1175.29	8.34661
1178.54	12.2335
1181.78	13.1498
1185.02	11.4777
1188.26	12.7245
1191.5	15.7146
1194.74	15.8598
1197.97	16.1523
1201.21	16.668
1204.44	18.4277
1207.68	20.2257
1210.91	22.5872
1214.14	23.9267
1217.37	27.1733
1220.6	29.4808
1223.82	31.859
1227.05	32.959
1230.27	33.9909
1233.49	36.9685
1236.72	39.7178
1239.94	42.3215
1243.16	44.5679
1246.37	46.2571
1249.59	47.5061
1252.8	47.1777
1256.02	50.6005
1259.23	52.1673
1262.44	52.9708
1265.66	56.0445
1268.87	59.9531
1272.07	61.0385
1275.28	63.0342
1278.48	65.9284
1281.69	68.2636
1284.89	69.5746
1288.09	71.1206
1291.3	72.5389
1294.49	73.1288
1297.69	73.2049
1300.89	72.1986
1304.09	70.4759
1307.28	68.871
1310.47	69.4457
1313.66	69.0183
1316.86	69.4911
1320.05	68.115
1323.23	67.7253
1326.42	65.8194
1329.61	62.7747
1332.79	61.3571
1335.98	61.2532
1339.16	60.0198
1342.34	58.5594
1345.52	58.0675
1348.7	55.4987
1351.87	54.4634
1355.05	54.646
1358.23	52.857
1361.4	51.7229
1364.57	50.5134
1367.74	48.9108
1370.91	46.5272
1374.08	46.0729
1377.25	44.303
1380.42	44.2455
1383.58	44.7822
1386.75	43.1508
1389.91	43.385
1393.07	41.9277
1396.23	41.9208
1399.39	40.7822
1402.55	39.7282
1405.7	40.7604
1408.86	41.5747
1412.01	42.7781
1415.17	45.6037
1418.32	48.3223
1421.47	51.3474
1424.62	54.3379
1427.77	57.0349
1430.92	62.2878
1434.06	66.9796
1437.2	71.6444
1440.35	75.0056
1443.49	77.3111
1446.63	80.5047
1449.77	82.0435
1452.91	81.1395
1456.05	81.2478
1459.18	78.2643
1462.32	73.0265
1465.45	67.7775
1468.59	63.17
1471.72	57.4273
1474.85	52.508
1477.98	46.1466
1481.11	41.7754
1484.23	37.4034
1487.36	31.7773
1490.48	29.5065
1493.61	27.3012
1496.73	24.6233
1499.85	23.0693
1502.97	20.5243
1506.09	21.8406
1509.2	21.8
1512.32	22.8472
1515.44	22.5568
1518.55	23.2997
1521.66	24.2704
1524.77	24.7514
1527.88	25.0451
1530.99	25.1214
1534.1	26.2025
1537.21	26.3866
1540.31	29.9366
1543.42	33.6208
1546.52	35.9558
1549.62	39.5881
1552.72	43.262
1555.82	46.0647
1558.92	49.6644
1562.02	52.3596
1565.11	55.9023
1568.21	58.797
1571.3	59.6459
1574.39	62.0972
1577.49	63.8804
1580.58	64.5071
1583.67	65.8737
1586.75	66.5811
1589.84	66.3056
1592.93	65.7004
1596.01	65.072
1599.09	64.5201
1602.18	62.8641
1605.26	61.2193
1608.34	61.2786
1611.41	61.2795
1614.49	62.3677
1617.57	61.4291
1620.64	61.4587
1623.72	64.0423
1626.79	65.4637
1629.86	67.253
1632.93	68.8228
1636	70.8786
1639.07	72.2363
1642.14	72.2688
1645.2	73.317
1648.27	74.8781
1651.33	75.2661
1654.39	75.2808
1657.45	74.7047
1660.51	74.3388
1663.57	71.6876
1666.63	68.1484
1669.69	65.1881
1672.74	60.227
1675.79	56.1576
1678.85	50.762
1681.9	46.9547
1684.95	41.5338
1688	36.69
1691.05	31.2106
1694.1	26.2173
1697.14	23.9848
1700.19	21.9273
1703.23	19.0776
1706.27	16.839
1709.32	14.02
1712.35	12.558
1715.39	10.2489
1718.43	9.17301
1721.47	9.12084
1724.5	9.23968
1727.54	9.12885
1730.57	10.2714
1733.61	11.057
1736.64	9.26636
1739.67	8.42037
1742.7	7.18312
1745.72	7.01228
1748.75	7.35117
1751.78	7.29476
1754.8	6.0139
1757.82	4.77314
1760.85	4.2344
1763.87	3.33188
1766.89	2.18754
1769.91	2.7749
1772.92	2.04206
1775.94	1.01581
1778.96	1.16927
1781.97	-0.0961117
1784.98	0.273216
1788	-0.356749
1791.01	-0.259745
1794.01	-0.0424784
1797.02	0.504311
1800.03	1.15005
1803.04	2.60637
1806.04	3.05486
1809.05	2.23912
1812.05	3.13781
1815.05	3.20697
1818.05	2.73513
1821.05	2.58246
1824.05	2.92658
1827.05	2.40257
1830.04	2.94125
1833.04	2.93775
1836.03	2.42977
1839.03	2.88189
1842.02	3.39747
1845.01	3.10224
1848	3.22665
1850.99	3.2232
1853.97	4.23438
1856.96	4.45024
1859.94	4.97923
1862.93	4.78307
1865.91	5.13728
1868.89	6.30974
1871.87	6.86373
1874.85	7.38141
1877.83	8.22226
1880.81	8.23276
1882.56	8.26039
1885.55	7.71051
1888.54	6.66765
1891.52	6.94543
1894.51	6.07077
1897.49	5.59994
1900.48	4.91798
1903.46	4.12864
1906.44	4.56222
1909.42	4.02917
1912.4	4.52402
1915.38	4.39784
1918.35	4.70203
1921.33	4.64972
1924.3	5.66524
1927.28	4.73278
1930.25	4.48245
1933.22	3.98731
1936.19	4.1093
1939.16	4.13395
1942.13	3.96473
1945.09	4.9871
1948.06	4.33477
1951.03	4.26394
1953.99	3.72364
1956.95	3.70458
1959.91	2.93769
1962.87	3.85642
1965.83	4.06441
1968.79	3.55239
1971.75	3.94544
1974.7	4.54789
1977.66	5.73075
1980.61	6.32104
1983.56	7.03862
1986.52	7.84711
1989.47	8.65661
1992.41	8.57582
1995.36	9.39247
1998.31	9.74986
2001.26	10.5921
2004.2	11.6305
2007.15	12.4434
2010.09	12.2195
2013.03	10.9411
2015.97	11.2429
2018.91	10.9939
2021.85	10.2852
2024.79	10.1325
2027.72	9.85178
2030.66	10.7594
2033.59	10.4755
2036.53	10.9781
2039.46	10.2193
2042.39	9.73193
2045.32	11.1436
2048.25	10.9332
2051.18	10.8875
2054.1	10.5852
2057.03	10.9232
2059.95	11.9046
2062.88	12.1597
2065.8	13.5169
2068.72	15.1917
2071.64	17.0608
2074.56	17.961
2077.48	20.7373
2080.39	20.9319
2083.31	21.2099
2086.22	23.1315
2089.14	24.1887
2092.05	25.1343
2094.96	26.4477
2097.87	28.6012
2100.78	30.3633
2103.69	32.2909
2106.6	33.1876
2109.51	36.9721
2112.41	38.3504
2115.32	41.0958
2118.22	44.0934
2121.12	46.9808
2124.02	49.8264
2126.92	52.7065
2129.82	56.7584
2132.72	60.1528
2135.62	64.2026
2138.51	68.7121
2141.41	71.8082
2144.3	74.1424
2147.19	79.0739
2150.09	81.6043
2152.97	84.7612
2155.86	86.8482
2158.75	88.9007
2161.64	88.8766
2164.53	89.2471
2167.41	88.5884
2170.3	87.851
2173.18	87.2697
2176.06	85.5422
2178.94	84.1769
2181.82	83.5601
2184.7	81.8587
2187.58	80.2764
2190.46	78.9693
2193.33	77.1098
2196.21	75.6801
2199.08	73.6533
2201.95	72.5609
2204.83	70.0655
2207.7	66.5798
2210.57	64.7379
2213.43	62.476
2216.3	60.7317
2219.17	58.773
2222.03	56.1906
2224.9	53.2792
2227.76	49.4447
2230.62	46.3202
2233.49	43.4557
2236.34	40.6026
2239.2	38.1541
2242.06	36.5089
2244.92	33.3168
2247.78	32.5
2250.63	31.9991
2253.48	31.3682
2256.34	31.3135
2259.19	31.1054
2262.04	30.4641
2264.89	29.8593
2267.74	29.273
2270.59	29.0743
2273.43	28.3742
2276.28	26.5141
2279.12	26.4028
2281.97	25.5029
2284.81	24.2158
2287.65	23.2946
2290.49	21.7934
2293.33	19.965
2296.17	18.3921
2299.01	19.412
2301.84	19.7513
2304.68	19.5229
2307.51	19.7663
2310.35	19.4252
2313.18	18.6653
2316.01	19.4303
2318.84	19.7573
2321.67	19.3581
2324.5	18.9122
2327.33	18.5866
2330.15	17.0634
2332.98	15.9411
2335.8	15.2521
2338.62	14.3947
2341.45	13.3629
2344.27	11.1204
2347.09	8.50151
2349.91	7.02699
2352.72	4.82636
2355.54	3.32043
2358.36	2.60297
2361.17	2.11916
2363.98	1.24031
2366.8	2.10839
2369.61	2.16578
2372.42	0.773313
2375.23	0.962885
2378.04	0.239847
2380.85	0.166323
2383.66	0.129747
2386.46	0.620054
2389.26	1.03457
2392.07	1.1915
2394.87	0.941162
2397.67	1.30657
2400.47	2.37059
2403.27	3.21395
2406.07	2.71139
2408.87	3.52532
2411.67	3.12975
2414.46	3.26879
2417.26	3.97451
2420.05	4.60722
2422.84	5.14718
2425.64	5.91577
2428.43	6.84425
2431.22	6.46497
2434.01	6.27384
2436.79	6.51363
2439.58	5.69282
2442.37	5.55096
2445.15	6.26818
2447.93	5.58958
2450.72	5.89743
2453.5	5.97118
2456.28	5.53681
2459.06	4.35485
2461.84	4.39004
2464.62	4.63223
2467.39	4.93205
2470.17	4.84635
2472.94	4.9065
2475.72	4.77538
2478.49	4.5664
2481.26	4.47725
2484.03	4.62317
2486.8	3.6575
2489.57	3.10935
2492.34	3.89326
2495.1	3.8161
2497.87	2.64989
2500.63	2.88917
2503.4	2.93529
2506.16	2.65706
2508.92	2.36473
2511.68	3.31622
2514.44	2.82171
2517.2	2.6307
2519.96	1.9659
2522.72	2.72176
2525.47	2.98512
2528.23	3.2285
2530.98	3.43688
2533.74	2.91431
2536.49	3.16482
2539.24	3.55286
2541.99	2.90835
2544.74	3.70731
2547.49	4.38464
2550.23	4.54369
2552.98	4.37506
2555.72	4.33095
2558.47	5.16802
2561.21	5.47762
2563.95	5.66598
2566.69	5.52635
2569.43	5.60046
2572.17	4.66082
2574.91	4.67176
2577.65	4.61591
2580.39	4.17625
2583.12	3.39713
2585.85	2.79241
2588.59	2.93145
2591.32	2.22646
2594.05	1.87765
2596.78	1.35608
2599.51	0.618077
2602.24	1.16728
2604.97	1.3789
2607.69	1.75508
2610.42	2.33536
2613.14	3.42845
2615.87	3.4663
2618.59	3.15714
2621.31	2.93163
2624.03	3.1307
2626.75	3.19606
2629.47	3.00566
2632.19	3.11497
2634.91	2.87014
2637.62	1.4187
2640.34	1.19858
2643.05	0.837766
2645.76	0.933094
2648.48	0.754193
2651.19	-0.319148
2653.9	-0.220726
2656.6	0.0596142
2659.31	0.289968
2662.02	0.330014
2664.73	0.522801
2667.43	1.77392
2670.14	2.00887
2672.84	2.19152
2675.54	3.16745
2678.24	3.15307
2680.94	3.37834
2683.64	3.00298
2686.34	3.89274
2689.04	4.36391
2691.74	5.1515
2694.43	5.08646
2697.13	5.33361
2699.82	6.02464
2702.51	6.74876
2705.21	8.15269
2707.9	9.36476
2710.58	10.2733
2713.27	11.1366
2715.96	10.5921
2718.65	10.4165
2721.33	11.7328
2724.02	10.3511
2726.71	10.6912
2729.39	10.4973
2732.07	10.7571
2734.75	11.2714
2737.43	9.36036
2740.11	9.05762
2742.79	8.18965
2745.47	7.18706
2748.14	7.50673
2750.82	8.22576
2753.49	7.27665
2756.17	6.54624
2758.84	5.18514
2761.51	5.89364
2764.18	7.12754
2766.85	7.52351
2769.52	8.2922
2772.19	8.08617
2774.86	7.68904
2777.52	7.98258
2780.19	8.31674
2782.85	8.29825
2785.52	7.73793
2788.18	7.16781
2790.84	6.34783
2793.5	6.00713
2796.16	5.70564
2798.82	5.32762
2801.48	5.14644
2804.13	4.85989
2806.79	4.69972
2809.45	4.35822
2812.1	3.98616
2814.75	3.73478
2817.41	4.7625
2820.06	5.3422
2822.71	7.45624
2825.36	10.8559
2828	15.3198
2830.65	19.6935
2833.3	23.0376
2835.94	27.6045
2838.59	30.5972
2841.23	36.207
2843.87	41.798
2846.52	47.4722
2849.16	52.2094
2851.8	58.016
2854.44	64.7354
2857.08	71.1798
2859.71	78.192
2862.35	84.8662
2864.98	90.7756
2867.62	95.2537
2870.25	100.01
2872.88	102.448
2875.52	105.867
2878.15	109.023
2880.78	111.986
2883.41	114.951
2886.03	117.759
2888.66	121.258
2891.29	124.401
2893.91	127.448
2896.54	129.453
2899.16	132.418
2901.78	135.98
2904.4	140.541
2907.02	147.963
2909.64	155.444
2912.26	163.649
2914.88	171.697
2917.5	178.213
2920.11	184.872
2922.73	191.1
2925.34	195.482
2927.96	197.98
2930.57	200.251
2933.18	201.11
2935.79	201.355
2938.4	200.129
2941.01	197.082
2943.62	192.76
2946.22	188.144
2948.83	182.433
2951.43	175.958
2954.04	169.191
2956.64	161.048
2959.24	154.36
2961.84	147.529
2964.45	141.145
2967.05	134.386
2969.64	129.277
2972.24	122.857
2974.84	116.594
2977.43	109.675
2980.03	101.583
2982.62	94.9121
2985.22	88.6764
2987.81	81.456
2990.4	74.3135
2992.99	68.7334
2995.58	63.2343
2998.17	57.726
3000.76	52.1255
3003.34	46.892
3005.93	42.5057
3008.52	39.1971
3011.1	35.6089
3013.68	32.0402
3016.27	29.4545
3018.85	27.3563
3021.43	25.1031
3024.01	23.7257
3026.59	21.9348
3029.16	20.197
3031.74	19.7682
3034.32	19.2742
3036.89	19.4801
3039.47	19.7403
3042.04	19.5305
3044.61	19.6938
3047.18	19.0254
3049.75	18.4765
3052.32	18.3121
3054.89	18.1313
3057.46	18.4024
3060.03	17.5153
3062.59	16.7301
3065.16	15.4001
3067.72	14.8149
3070.29	13.7759
3072.85	12.079
3075.41	10.114
3077.97	8.92603
3080.53	8.14896
3083.09	7.10527
3085.65	6.00949
3088.21	5.37856
3090.76	4.28214
3093.32	3.86442
3095.87	2.97643
3098.43	2.18928
3100.98	2.85279
3103.53	2.52749
3106.08	1.87799
3108.63	1.84275
3111.18	2.02083
3113.73	2.56133
3116.28	4.49007
3118.83	4.36246
3121.37	5.07116
3123.92	5.33096
3126.46	4.58022
3129	6.02547
3131.55	6.73021
3134.09	7.48518
3136.63	8.67716
3139.17	10.5509
3141.71	12.0042
3144.24	12.798
3146.78	13.3637
3149.32	12.6927