File: data/Raman/poly_smoothed/Thy_20_09_12_1x_45s_532 nm_x100_100%_600 gr_mm_01.txt
#Acq. time (s)=	45
#Accumulations=	2
#Range (cm-¹)=	200...3150
#Windows=	2
#Auto scanning=	Off
#Autofocus=	Off
#Macrospot=	Off
#AutoExposure=	Off
#Spike filter=	Multiple accum.
#Delay time (s)=	0
#Binning=	1
#Readout mode=	Signal
#DeNoise=	Off
#ICS correction=	On
#Dark correction=	Off
#Inst. Process=	Off
#Detector Gain=	Best Dynamic Range
#Detector ADC=	20 kHz
#Detector temperature (°C)=	-69.85
#Instrument=	LabRAM HR Evol
#Detector=	Synapse
#Objective=	x100
#Grating=	600 gr/mm
#ND Filter=	100%
#Laser (nm)=	532
#Hole=	100.021
#Range=	Auto
#Laser Pol.=	No
#Raman. Pol.=	No
#Laser Pol. (°)=	-0.0007625
#Raman Pol. (°)=	89.9995
#Collection=	Microscope
#StageXY=	Marzhauser
#StageZ=	Marzhauser
#X (µm)=	-5891.4
#Y (µm)=	2848.3
#Z (µm)=	-223.65
#Full time(mm:ss)=	3:18
#Project=
#Sample=
#Site=
#Title=	Thy_20_09_12_2x_45s_532 nm_x100_100%_600 gr_mm
#Remark=
#Date=	29.06.2022 11:33
#Acquired=	29.06.2022 11:33:17
#Base:Fit=	10.08.2022 09:52:02
#Base:Fit=	10.08.2022 09:52:12
#Base:Sub=	10.08.2022 09:54:21
#Filter:Polynom=	16.08.2022 10:24:04
#AxisType[0]=Intens
#AxisUnit[0]=Cnt
#AxisType[1]=Spectr
#AxisUnit[1]=1/cm
200.523	17.9526
204.154	18.8363
207.781	17.8649
211.409	16.3437
215.034	15.151
218.659	12.8011
222.281	10.2333
225.903	8.45134
229.522	7.53843
233.14	8.0541
236.756	7.50641
240.373	7.56449
243.986	7.07366
247.598	7.16465
251.208	7.49797
254.818	6.3697
258.427	4.17666
262.034	5.73931
265.638	5.95825
269.242	5.59474
272.844	5.20779
276.445	6.35837
280.044	7.83467
283.642	8.05247
287.238	7.25091
290.833	7.33781
294.425	7.64055
298.017	7.22268
301.608	7.19911
305.198	7.79715
308.786	5.776
312.371	6.406
315.956	4.89612
319.54	6.06972
323.122	7.42495
326.701	8.96537
330.281	8.95203
333.857	9.46273
337.434	11.0851
341.008	9.97871
344.582	8.97089
348.153	8.42239
351.724	8.13374
355.292	6.92689
358.861	8.31334
362.426	8.23622
365.99	8.30377
369.555	7.99734
373.116	6.98516
376.676	6.62285
380.236	6.35308
383.793	5.76207
387.349	5.05263
390.903	4.65837
394.456	4.01726
398.007	2.58143
401.56	1.64901
405.108	2.08595
408.656	4.94218
412.202	4.72359
415.746	4.97605
419.29	5.07696
422.831	5.13237
426.37	5.47761
429.909	6.05719
433.447	5.57514
436.983	4.46762
440.519	4.076
444.052	5.94685
447.583	7.03799
451.114	7.283
454.643	7.00138
458.169	9.03934
461.696	9.78571
465.222	10.6036
468.744	11.2174
472.267	12.4501
475.787	12.8692
479.307	13.7733
482.823	13.2461
486.341	13.6581
489.855	14.6873
493.37	15.506
496.881	17.0679
500.391	16.6973
503.902	18.3341
507.409	19.0861
510.915	19.515
514.42	19.6452
517.925	18.0546
521.427	16.8485
524.928	17.8201
528.427	18.176
531.925	18.5248
535.422	18.0851
538.917	17.599
542.411	18.071
545.903	17.2952
549.395	16.1971
552.884	14.7904
556.373	13.4564
559.86	11.9334
563.346	11.265
566.831	9.82276
570.314	8.93093
573.794	8.04954
577.274	6.70176
580.754	5.84153
584.23	5.90662
587.706	4.76652
591.181	3.27636
594.653	1.95775
598.126	1.41992
601.595	0.35926
605.065	1.30183
608.532	1.56922
611.999	1.71473
615.463	2.36773
618.928	1.66655
622.389	2.3056
625.851	3.59774
629.31	4.87512
632.767	5.66685
636.223	6.54352
639.68	7.75869
643.134	9.31888
646.586	11.4865
650.037	12.6181
653.486	14.7396
656.936	15.9745
660.383	18.1507
663.829	20.5809
667.273	22.4109
670.716	24.2775
674.158	25.6852
677.598	28.2337
681.035	29.5984
684.473	31.141
687.909	33.7469
691.344	34.4678
694.778	34.6401
698.211	35.466
701.64	37.6695
705.07	38.4128
708.498	40.7805
711.924	42.2432
715.35	42.4415
718.774	43.2902
722.196	45.4473
725.618	46.5028
729.037	46.9374
732.456	47.0852
735.873	49.1592
739.289	50.8849
742.703	52.2809
746.116	54.0212
749.529	54.6049
752.938	55.6844
756.347	58.1144
759.756	60.5444
763.162	62.3291
766.567	64.5379
769.97	66.2827
773.372	67.6318
776.773	69.8815
780.174	73.3593
783.573	75.3934
786.97	77.5605
790.365	78.226
793.76	79.968
797.153	80.5526
800.543	82.0919
803.933	83.6555
807.322	83.1365
810.71	82.0509
814.097	81.1042
817.483	81.1114
820.865	80.9306
824.248	80.2055
827.629	78.0044
831.008	75.7859
834.387	73.8405
837.765	73.5308
841.139	71.2581
844.514	69.0455
847.886	66.4103
851.259	63.5762
854.629	61.4801
857.997	59.6992
861.366	57.5419
864.732	55.759
868.098	53.8846
871.461	51.1123
874.823	50.2779
878.184	50.615
881.545	49.9924
884.903	49.245
888.26	48.3512
891.616	48.3608
894.97	47.2135
898.323	45.9152
901.675	45.6788
905.026	45.8072
908.375	45.5952
911.723	44.9623
915.07	45.3239
918.415	44.2676
921.76	43.4567
925.103	42.8454
928.443	41.1041
931.783	40.6806
935.123	41.1161
938.461	40.7144
941.796	39.8172
945.131	39.2242
948.465	38.052
951.797	36.9909
955.128	37.764
958.457	35.2268
961.786	34.1538
965.113	33.9431
968.44	35.8509
971.763	37.1968
975.086	36.1014
978.409	34.9407
981.729	34.7673
985.048	35.3316
988.367	34.8567
991.683	32.1756
994.998	31.2485
998.312	30.0914
1001.62	29.936
1004.94	28.6318
1008.25	27.9942
1011.56	25.4459
1014.86	23.6462
1018.17	21.0597
1021.48	20.4512
1024.78	18.5194
1028.08	17.1596
1031.38	16.3066
1034.68	14.9829
1037.98	14.1976
1041.28	13.3173
1044.57	15.1815
1047.87	15.6866
1051.16	16.4045
1054.45	15.2723
1057.75	15.4876
1061.04	16.2913
1064.32	14.9431
1067.61	14.2193
1070.9	14.5589
1074.18	15.1619
1077.47	17.0797
1080.75	16.0371
1084.03	15.2813
1087.31	14.6405
1090.59	14.295
1093.86	13.0978
1097.14	14.246
1100.41	15.76
1103.69	17.9864
1106.96	18.6002
1110.23	18.5216
1113.5	17.3071
1116.77	17.8515
1120.03	15.9156
1123.3	15.1999
1126.56	13.7913
1129.83	13.0423
1133.09	12.1156
1136.35	12.2734
1139.61	11.7087
1142.86	9.35743
1146.12	9.04484
1149.38	9.91907
1152.63	8.70427
1155.88	7.13144
1159.14	6.89251
1162.39	5.90104
1165.63	5.47402
1168.88	6.3549
1172.13	6.82344
1175.38	8.64396
1178.62	11.5733
1181.86	14.2672
1185.1	14.2031
1188.34	15.0492
1191.58	16.2601
1194.82	17.5389
1198.06	20.2934
1201.29	23.074
1204.53	25.6367
1207.76	29.0257
1210.99	32.8157
1214.22	36.5309
1217.45	40.4027
1220.68	43.0348
1223.91	45.9102
1227.13	50.4611
1230.36	54.241
1233.58	56.2421
1236.8	60.1587
1240.02	61.9072
1243.24	63.1055
1246.46	66.745
1249.67	69.0562
1252.89	69.8105
1256.1	71.3503
1259.32	72.1414
1262.53	72.3626
1265.74	72.8478
1268.95	74.0773
1272.15	74.283
1275.36	77.6392
1278.57	81.2736
1281.77	82.2932
1284.97	84.26
1288.18	85.5175
1291.38	87.7129
1294.58	90.0818
1297.78	92.6912
1300.97	96.302
1304.17	99.0197
1307.36	102.539
1310.55	106.699
1313.75	109.323
1316.94	111.884
1320.13	114.408
1323.32	115.847
1326.5	116.722
1329.69	116.683
1332.87	117.319
1336.06	116.192
1339.24	117.342
1342.42	115.691
1345.6	113.442
1348.78	110.982
1351.96	110.1
1355.13	106.99
1358.31	102.696
1361.48	97.5294
1364.65	91.8269
1367.82	87.7969
1370.99	83.7476
1374.16	80.7156
1377.33	77.2821
1380.5	73.6855
1383.66	72.8179
1386.83	70.3035
1389.99	67.6934
1393.15	65.559
1396.31	62.8572
1399.47	61.0056
1402.63	59.972
1405.78	60.0908
1408.94	60.6406
1412.1	61.2631
1415.25	64.7124
1418.4	67.7516
1421.55	69.1037
1424.7	72.5885
1427.85	75.8143
1431	78.4178
1434.14	81.1573
1437.29	82.4719
1440.43	82.3301
1443.57	84.9043
1446.71	85.9265
1449.85	86.7617
1452.99	86.0322
1456.13	84.9873
1459.26	83.5951
1462.4	81.8624
1465.54	77.0557
1468.67	73.1592
1471.8	69.3538
1474.93	64.3602
1478.06	60.0558
1481.19	56.1613
1484.31	53.4433
1487.44	48.8544
1490.56	45.2876
1493.69	42.5365
1496.81	39.8815
1499.93	37.9333
1503.05	36.7553
1506.17	36.1057
1509.28	35.5776
1512.4	34.7753
1515.52	34.8348
1518.63	36.6753
1521.74	39.3391
1524.85	40.638
1527.96	41.334
1531.07	45.5915
1534.18	48.8973
1537.29	52.9704
1540.39	55.9166
1543.5	59.3926
1546.6	64.3038
1549.7	69.4868
1552.8	74.1273
1555.9	80.5928
1559	84.9134
1562.1	88.9639
1565.19	92.9849
1568.29	96.7036
1571.38	101.805
1574.47	107.634
1577.56	109.917
1580.66	113.072
1583.74	115.64
1586.83	116.148
1589.92	117.336
1593.01	118.423
1596.09	117.824
1599.17	115.817
1602.25	112.956
1605.34	110.549
1608.41	107.893
1611.49	103.836
1614.57	101.415
1617.65	97.5728
1620.72	95.4104
1623.79	94.2435
1626.87	91.5972
1629.94	90.2183
1633.01	89.6193
1636.08	87.6339
1639.15	87.7327
1642.21	86.5169
1645.28	87.0655
1648.34	87.6726
1651.41	86.1713
1654.47	83.994
1657.53	82.8665
1660.59	81.5084
1663.65	78.0191
1666.71	76.051
1669.76	73.3186
1672.82	68.914
1675.87	64.9969
1678.93	61.4157
1681.98	56.7966
1685.03	51.0538
1688.08	46.6105
1691.13	43.4177
1694.17	38.461
1697.22	34.2447
1700.27	29.9298
1703.31	25.402
1706.35	23.0278
1709.39	20.1308
1712.43	16.9358
1715.47	16.1065
1718.51	13.9983
1721.55	12.7281
1724.58	11.934
1727.62	10.4634
1730.65	9.55268
1733.68	8.23101
1736.72	7.12902
1739.74	6.48574
1742.77	5.86937
1745.8	4.41514
1748.83	4.14934
1751.85	4.10688
1754.88	3.40922
1757.9	2.70241
1760.92	2.1736
1763.95	1.53812
1766.96	1.45964
1769.98	0.440235
1773	-0.173789
1776.02	-0.93521
1779.03	-0.470816
1782.05	0.0930054
1785.06	0.299422
1788.07	0.482347
1791.08	1.23177
1794.09	0.345586
1797.1	1.05945
1800.11	1.3977
1803.12	1.46912
1806.12	1.42738
1809.12	1.30574
1812.13	1.47802
1815.13	1.38111
1818.13	1.34662
1821.13	1.66686
1824.13	2.15318
1827.13	2.54158
1830.12	2.22835
1833.12	2.58893
1836.11	2.60776
1839.1	2.01209
1842.09	1.8929
1845.09	2.96288
1848.08	3.85674
1851.06	4.35325
1854.05	4.37864
1857.04	5.41199
1860.02	5.49345
1863.01	5.19286
1865.99	6.12629
1868.97	7.0688
1871.95	7.95276
1874.93	8.28557
1877.91	9.34518
1880.89	10.4426
1882.46	9.97212
1885.45	9.50142
1888.43	10.014
1891.42	10.0879
1894.41	11.052
1897.39	11.6254
1900.37	10.8188
1903.36	10.4212
1906.34	8.98694
1909.32	6.95889
1912.29	6.31715
1915.27	6.52907
1918.25	6.30842
1921.23	5.43426
1924.2	4.45145
1927.17	3.48127
1930.15	4.36564
1933.12	3.25742
1936.09	4.40064
1939.06	5.11289
1942.02	4.28532
1944.99	4.96288
1947.96	4.89972
1950.92	5.44519
1953.88	6.2254
1956.85	5.95314
1959.81	8.56539
1962.77	9.60414
1965.73	10.7813
1968.69	10.9318
1971.64	10.0662
1974.6	8.17027
1977.55	8.62518
1980.51	7.75265
1983.46	9.30434
1986.41	9.16346
1989.36	7.91448
1992.31	8.059
1995.26	7.6107
1998.21	8.13329
2001.15	9.24738
2004.1	9.22643
2007.04	8.85156
2009.99	8.59764
2012.93	7.71134
2015.87	7.81014
2018.81	7.9568
2021.75	8.11903
2024.68	9.38576
2027.62	9.91195
2030.56	11.4068
2033.49	12.2609
2036.42	12.0934
2039.36	11.7257
2042.29	12.6506
2045.22	13.7577
2048.14	14.8638
2051.07	16.4328
2054	16.6927
2056.93	16.4185
2059.85	17.5464
2062.77	17.4693
2065.7	18.3011
2068.62	19.3325
2071.54	19.1475
2074.46	19.4413
2077.38	19.3673
2080.29	19.3392
2083.21	19.319
2086.12	19.4164
2089.04	20.2189
2091.95	20.1385
2094.86	20.8873
2097.77	21.3048
2100.68	21.3135
2103.59	21.781
2106.5	21.4681
2109.41	22.1142
2112.31	22.5543
2115.21	23.694
2118.12	24.3699
2121.02	25.1592
2123.92	25.004
2126.82	25.2553
2129.72	27.2832
2132.62	28.385
2135.51	29.7479
2138.41	31.1014
2141.31	33.1846
2144.2	35.5378
2147.09	38.0006
2149.98	39.1066
2152.87	41.2715
2155.76	42.5467
2158.65	44.0212
2161.54	45.5638
2164.43	46.8563
2167.31	48.585
2170.2	49.2832
2173.08	49.8925
2175.96	51.4707
2178.84	50.8521
2181.72	51.7019
2184.6	50.9707
2187.48	50.5866
2190.36	49.122
2193.23	47.4907
2196.11	45.2131
2198.98	44.6056
2201.85	42.7203
2204.72	40.9401
2207.59	38.576
2210.46	36.7224
2213.33	34.9732
2216.2	32.6593
2219.07	29.9825
2221.93	27.5044
2224.8	25.5791
2227.66	23.9186
2230.52	21.4414
2233.39	20.2562
2236.25	19.8065
2239.1	20.1636
2241.96	18.8498
2244.82	18.2479
2247.68	17.7351
2250.53	16.1204
2253.38	15.653
2256.24	14.5045
2259.09	14.9361
2261.94	14.1207
2264.79	13.38
2267.64	12.8891
2270.49	12.5161
2273.33	11.5806
2276.18	11.7557
2279.02	11.2128
2281.87	11.5257
2284.71	9.79883
2287.55	9.19806
2290.39	7.60978
2293.23	7.95649
2296.07	9.35357
2298.91	10.0559
2301.74	10.7709
2304.58	12.7332
2307.41	13.2153
2310.25	13.3684
2313.08	12.671
2315.91	12.9407
2318.74	13.3214
2321.57	13.7913
2324.4	12.9781
2327.23	12.952
2330.05	12.728
2332.88	11.2039
2335.7	10.3517
2338.52	9.27113
2341.35	8.50323
2344.17	7.1523
2346.99	5.95656
2349.81	5.01631
2352.62	2.83102
2355.44	2.35957
2358.26	2.50668
2361.07	3.057
2363.89	4.4506
2366.7	5.31377
2369.51	3.89057
2372.32	4.07566
2375.13	5.19269
2377.94	4.71463
2380.75	6.1521
2383.56	6.74662
2386.36	6.84045
2389.17	6.7548
2391.97	7.25252
2394.77	6.5878
2397.58	7.41653
2400.38	7.48288
2403.18	7.45371
2405.97	6.90983
2408.77	6.33523
2411.57	5.16034
2414.37	5.05876
2417.16	5.24531
2419.95	4.5939
2422.75	4.56445
2425.54	5.18557
2428.33	4.22371
2431.12	3.83657
2433.91	2.9275
2436.7	2.10441
2439.48	1.59257
2442.27	2.04803
2445.05	2.0771
2447.84	1.14551
2450.62	0.920336
2453.4	1.18941
2456.18	1.27034
2458.96	1.54348
2461.74	1.38018
2464.52	1.06244
2467.29	1.10837
2470.07	0.559924
2472.85	0.0615918
2475.62	-0.202265
2478.39	0.301942
2481.16	0.101671
2483.93	0.431269
2486.7	0.429614
2489.47	0.208402
2492.24	0.292185
2495.01	-0.268712
2497.77	-0.750232
2500.54	-0.625703
2503.3	-0.60561
2506.06	-0.78546
2508.83	-0.630413
2511.59	-0.434982
2514.35	-0.319506
2517.11	0.404681
2519.86	1.37572
2522.62	2.73274
2525.38	3.40577
2528.13	4.29442
2530.89	4.50798
2533.64	4.90635
2536.39	5.60371
2539.14	6.56552
2541.89	6.50067
2544.64	6.84401
2547.39	6.76404
2550.14	6.78387
2552.88	5.83766
2555.63	6.86229
2558.37	6.55403
2561.11	6.35355
2563.86	5.37596
2566.6	5.922
2569.34	5.39951
2572.08	4.28873
2574.82	3.8117
2577.55	3.45277
2580.29	3.19108
2583.02	2.77345
2585.76	2.5797
2588.49	3.73075
2591.22	4.27465
2593.96	4.02519
2596.69	3.97297
2599.42	3.99771
2602.14	4.39391
2604.87	4.13569
2607.6	3.82648
2610.32	3.24097
2613.05	3.10929
2615.77	3.68562
2618.49	3.56411
2621.22	3.66429
2623.94	4.42611
2626.66	4.07537
2629.37	4.75572
2632.09	4.53302
2634.81	4.41602
2637.53	4.41689
2640.24	3.75302
2642.96	3.68188
2645.67	3.58533
2648.38	4.62236
2651.09	4.4578
2653.8	4.89566
2656.51	4.79697
2659.22	4.24823
2661.93	3.9548
2664.63	4.8325
2667.34	4.88173
2670.04	4.68786
2672.75	3.85846
2675.45	4.4133
2678.15	4.23438
2680.85	5.42282
2683.55	6.41828
2686.25	5.86632
2688.94	6.72504
2691.64	7.20025
2694.34	7.79341
2697.03	8.70081
2699.73	8.39427
2702.42	9.37801
2705.11	9.15513
2707.8	9.5109
2710.49	10.2228
2713.18	10.6614
2715.87	10.1715
2718.55	10.6981
2721.24	9.92001
2723.93	9.06092
2726.61	9.54557
2729.29	9.09655
2731.98	8.53644
2734.66	7.90441
2737.34	7.85554
2740.02	8.11432
2742.7	7.36919
2745.37	6.64874
2748.05	6.31665
2750.72	5.13773
2753.4	4.1071
2756.07	4.32732
2758.75	3.87717
2761.42	2.95199
2764.09	1.99671
2766.76	1.47468
2769.43	0.906327
2772.1	0.590358
2774.76	1.02669
2777.43	0.660309
2780.1	0.13204
2782.76	-0.126683
2785.42	0.00785543
2788.09	-0.710723
2790.75	-0.536882
2793.41	-0.370795
2796.07	-0.377967
2798.73	0.147526
2801.39	0.169262
2804.04	0.130574
2806.7	0.0422442
2809.35	-0.235256
2812.01	-0.0686954
2814.66	0.40223
2817.31	1.01631
2819.96	2.81314
2822.61	3.86243
2825.26	5.77895
2827.91	7.94531
2830.56	10.6158
2833.21	14.4202
2835.85	17.3934
2838.5	20.8976
2841.14	25.5438
2843.78	30.1579
2846.42	36.1182
2849.06	43.6017
2851.71	50.9811
2854.34	58.8494
2856.98	67.223
2859.62	74.3855
2862.26	82.0637
2864.89	88.0624
2867.53	94.0868
2870.16	100.224
2872.79	105.375
2875.42	109.005
2878.05	113.539
2880.68	117.587
2883.31	120.828
2885.94	123.494
2888.57	126.545
2891.19	130.777
2893.82	133.584
2896.44	138.622
2899.07	143.525
2901.69	148.604
2904.31	155.632
2906.93	165.268
2909.55	174.103
2912.17	183.994
2914.79	194.255
2917.41	203.329
2920.02	211.131
2922.64	217.46
2925.25	222.932
2927.86	226.407
2930.48	228.386
2933.09	228.734
2935.7	227.566
2938.31	223.991
2940.92	220.196
2943.53	214.601
2946.13	207.741
2948.74	200.406
2951.34	192.611
2953.95	185.73
2956.55	179.11
2959.15	171.346
2961.75	163.113
2964.35	156.039
2966.95	150.219
2969.55	143.461
2972.15	137.214
2974.75	130.361
2977.34	124.829
2979.94	117.457
2982.53	109.95
2985.13	102.037
2987.72	94.9347
2990.31	87.9725
2992.9	79.7655
2995.49	71.8243
2998.08	64.9174
3000.67	57.505
3003.25	50.6175
3005.84	44.8314
3008.42	38.7255
3011.01	33.765
3013.59	30.1659
3016.17	27.1272
3018.76	25.1499
3021.34	23.0969
3023.92	20.6309
3026.49	18.865
3029.07	18.8506
3031.65	17.6436
3034.23	17.8841
3036.8	18.699
3039.38	18.7668
3041.95	19.7408
3044.52	20.4457
3047.09	21.6502
3049.66	22.8979
3052.23	23.0219
3054.8	21.6284
3057.37	21.3255
3059.94	20.1886
3062.5	19.482
3065.07	18.6029
3067.63	17.0575
3070.2	15.0004
3072.76	13.2626
3075.32	11.6739
3077.88	9.84292
3080.44	7.1373
3083	6.07191
3085.56	4.43617
3088.12	3.18784
3090.67	2.22644
3093.23	1.3533
3095.78	1.1463
3098.34	0.722159
3100.89	1.38266
3103.44	2.01015
3105.99	2.85149
3108.54	4.42643
3111.09	3.90661
3113.64	4.23225
3116.19	3.51162
3118.74	4.44685
3121.28	5.29973
3123.83	6.51606
3126.37	7.28677
3128.91	7.43821
3131.46	7.38575
3134	7.18629
3136.54	7.98505
3139.08	8.01803
3141.62	8.4745
3144.16	9.2483
3146.69	8.64293
3149.23	8.56419