File: data/Raman/poly_smoothed/Thy_50_12_25_1x_45s_532 nm_x100_100%_600 gr_mm_01.txt
#Acq. time (s)=	45
#Accumulations=	2
#Range (cm-¹)=	200...3150
#Windows=	2
#Auto scanning=	Off
#Autofocus=	Off
#Macrospot=	Off
#AutoExposure=	Off
#Spike filter=	Multiple accum.
#Delay time (s)=	0
#Binning=	1
#Readout mode=	Signal
#DeNoise=	Off
#ICS correction=	On
#Dark correction=	Off
#Inst. Process=	Off
#Detector Gain=	Best Dynamic Range
#Detector ADC=	20 kHz
#Detector temperature (°C)=	-69.85
#Instrument=	LabRAM HR Evol
#Detector=	Synapse
#Objective=	x100
#Grating=	600 gr/mm
#ND Filter=	100%
#Laser (nm)=	532
#Hole=	100.021
#Range=	Auto
#Laser Pol.=	No
#Raman. Pol.=	No
#Laser Pol. (°)=	-0.0007625
#Raman Pol. (°)=	89.9995
#Collection=	Microscope
#StageXY=	Marzhauser
#StageZ=	Marzhauser
#X (µm)=	-5135.5
#Y (µm)=	1493.7
#Z (µm)=	63.15
#Full time(mm:ss)=	3:18
#Project=
#Sample=
#Site=
#Title=	Thy_50_12_25_2x_45s_532 nm_x100_100%_600 gr_mm
#Remark=
#Date=	07.07.2022 11:04
#Acquired=	07.07.2022 11:04:32
#Base:Fit=	10.08.2022 10:04:29
#Base:Sub=	10.08.2022 10:04:45
#Filter:Polynom=	16.08.2022 10:20:24
#AxisType[0]=Intens
#AxisUnit[0]=Cnt
#AxisType[1]=Spectr
#AxisUnit[1]=1/cm
200.43	34.7187
204.061	24.8548
207.688	20.6258
211.316	17.5351
214.941	16.0421
218.566	14.8884
222.188	11.8706
225.809	10.3234
229.43	10.5083
233.047	8.37509
236.663	7.01062
240.278	6.70061
243.894	6.04811
247.506	7.08087
251.116	8.8772
254.725	8.78137
258.333	11.0845
261.939	12.5746
265.546	14.175
269.15	12.2049
272.752	11.1844
276.353	10.0613
279.952	10.7237
283.55	11.1588
287.146	12.2566
290.739	13.2151
294.333	12.4623
297.925	11.862
301.516	12.5167
305.106	10.5027
308.694	8.6471
312.279	9.59156
315.864	9.89968
319.448	9.50612
323.029	8.20399
326.61	8.12758
330.19	9.83161
333.766	9.70448
337.343	10.4992
340.917	10.3011
344.491	11.1046
348.062	10.5847
351.633	8.65332
355.201	7.02841
358.77	5.34059
362.335	6.87151
365.899	7.98273
369.464	7.78344
373.025	7.7516
376.585	7.47882
380.143	5.575
383.702	5.04079
387.258	4.43631
390.812	3.49831
394.365	3.18722
397.916	5.33016
401.467	5.00579
405.015	6.27405
408.565	7.1847
412.111	7.2376
415.656	10.1901
419.197	10.1711
422.739	8.33926
426.279	8.99349
429.819	8.82799
433.356	9.2132
436.893	9.30407
440.428	8.47115
443.96	7.7343
447.492	7.72936
451.023	7.49964
454.553	7.53049
458.079	6.85548
461.606	6.75775
465.132	5.68802
468.654	5.51613
472.177	6.11777
475.696	8.01452
479.217	9.55537
482.733	12.7198
486.251	14.6804
489.765	17.1272
493.278	20.4276
496.791	22.762
500.301	23.8833
503.81	23.9403
507.319	24.8772
510.825	23.4123
514.33	26.0108
517.833	26.3514
521.337	26.6125
524.838	26.0187
528.337	25.2459
531.835	23.7639
535.332	22.8763
538.827	20.8981
542.321	19.2942
545.814	18.0902
549.305	17.0434
552.795	15.5963
556.284	15.0713
559.771	14.5435
563.257	13.0722
566.742	12.0941
570.223	12.3331
573.705	11.7152
577.185	11.9369
580.665	11.0659
584.141	9.91403
587.617	8.00848
591.092	8.41074
594.564	6.04581
598.037	5.77594
601.506	5.42441
604.976	5.47452
608.443	6.52331
611.91	7.13767
615.374	6.82344
618.839	6.32634
622.3	7.56959
625.761	8.92998
629.221	8.62473
632.679	9.55595
636.135	10.0195
639.592	11.0324
643.045	11.9563
646.497	12.572
649.948	13.3212
653.398	15.5446
656.846	17.6689
660.293	19.2365
663.738	20.5586
667.185	19.7612
670.628	19.0907
674.067	19.1968
677.508	18.865
680.947	20.1715
684.385	21.9709
687.821	23.5128
691.256	26.3899
694.69	28.622
698.121	29.5022
701.552	30.212
704.982	32.3049
708.41	34.531
711.836	35.5205
715.262	37.6026
718.685	39.5664
722.108	42.065
725.53	42.1235
728.949	43.8972
732.369	44.8716
735.785	44.9811
739.2	46.9019
742.616	48.7198
746.028	51.2081
749.441	52.6974
752.851	54.0256
756.26	58.011
759.667	62.1528
763.075	65.9202
766.479	69.2022
769.883	71.1216
773.285	74.4275
776.686	77.0672
780.085	80.4512
783.484	81.2088
786.881	81.9714
790.276	83.1505
793.671	85.0037
797.064	86.0261
800.456	85.4513
803.846	84.2144
807.236	83.1226
810.624	81.9245
814.01	80.9418
817.394	79.2048
820.778	78.591
824.161	77.1577
827.543	75.1306
830.921	73.1513
834.3	71.2984
837.676	68.5948
841.053	67.4209
844.426	64.2902
847.8	62.7738
851.171	60.2394
854.542	57.9067
857.911	56.1046
861.279	54.5003
864.645	51.7108
868.01	50.5075
871.375	50.6732
874.737	49.4178
878.097	50.2163
881.457	48.0442
884.817	49.3263
888.174	48.6574
891.53	47.3415
894.884	46.304
898.237	44.1346
901.589	42.1134
904.94	38.2323
908.289	35.6327
911.637	32.7822
914.984	30.1335
918.33	29.3025
921.674	28.5172
925.015	28.6461
928.357	25.8901
931.698	23.5175
935.037	22.0129
938.373	21.331
941.71	20.2196
945.046	17.8276
948.378	19.5503
951.711	21.926
955.043	24.5185
958.372	24.9032
961.701	26.5034
965.027	30.2515
968.354	31.3159
971.678	32.4432
975	34.5565
978.324	34.7993
981.644	35.2046
984.962	36.498
988.282	34.7903
991.598	35.8592
994.913	38.3292
998.227	39.123
1001.54	41.1013
1004.85	41.4417
1008.16	41.1974
1011.47	41.9103
1014.78	43.2537
1018.08	43.7579
1021.39	43.1684
1024.69	42.6108
1028	43.9103
1031.3	45.2347
1034.6	46.4313
1037.9	47.0204
1041.19	46.7184
1044.49	48.124
1047.79	46.6777
1051.08	44.9307
1054.37	43.5138
1057.66	39.4738
1060.95	36.4388
1064.24	34.9345
1067.53	32.9263
1070.81	30.0368
1074.1	31.0187
1077.38	30.2168
1080.66	30.4907
1083.94	28.7018
1087.22	26.4862
1090.5	25.0394
1093.78	25.209
1097.05	24.2021
1100.33	22.7279
1103.6	20.733
1106.87	19.0905
1110.15	18.1113
1113.41	19.0174
1116.68	20.0336
1119.95	18.1511
1123.21	15.6863
1126.48	13.2531
1129.74	12.7866
1133	10.2407
1136.26	8.62053
1139.52	8.93058
1142.78	9.58879
1146.04	8.69392
1149.29	8.87907
1152.55	9.71963
1155.8	8.34338
1159.05	6.01967
1162.3	3.53282
1165.55	2.74517
1168.8	3.86975
1172.05	5.05851
1175.29	5.11365
1178.54	4.21881
1181.78	4.37262
1185.02	4.52844
1188.26	5.16285
1191.5	6.93355
1194.74	8.81046
1197.97	8.88501
1201.21	8.92721
1204.44	11.6851
1207.68	13.7268
1210.91	15.3388
1214.14	18.452
1217.37	24.4784
1220.6	28.2582
1223.82	32.9616
1227.05	36.9425
1230.27	41.4764
1233.49	44.8742
1236.72	48.723
1239.94	54.3403
1243.16	61.1723
1246.37	65.7101
1249.59	71.228
1252.8	74.1587
1256.02	78.5895
1259.23	83.2791
1262.44	86.3276
1265.66	89.831
1268.87	94.0601
1272.07	97.9025
1275.28	100.471
1278.48	102.682
1281.69	104.835
1284.89	108.189
1288.09	109.599
1291.3	110.801
1294.49	112.454
1297.69	113.001
1300.89	113.009
1304.09	113.411
1307.28	111.366
1310.47	111.15
1313.66	110.018
1316.86	108.516
1320.05	106.53
1323.23	104.547
1326.42	101.214
1329.61	98.6816
1332.79	96.5353
1335.98	94.5965
1339.16	90.4996
1342.34	87.8988
1345.52	85.842
1348.7	81.814
1351.87	77.6345
1355.05	73.3472
1358.23	70.5578
1361.4	66.7247
1364.57	62.4308
1367.74	58.2795
1370.91	56.0272
1374.08	53.2401
1377.25	51.1945
1380.42	47.7312
1383.58	46.6
1386.75	46.2593
1389.91	45.2506
1393.07	44.1736
1396.23	42.3265
1399.39	44.0099
1402.55	45.557
1405.7	48.0663
1408.86	50.2342
1412.01	55.6854
1415.17	59.0257
1418.32	64.8533
1421.47	72.2432
1424.62	77.956
1427.77	85.4381
1430.92	92.9748
1434.06	101.178
1437.2	108.668
1440.35	112.685
1443.49	116.222
1446.63	117.987
1449.77	119.483
1452.91	118.977
1456.05	116.375
1459.18	114.056
1462.32	108.716
1465.45	100.237
1468.59	91.1694
1471.72	81.8549
1474.85	72.7082
1477.98	65.2009
1481.11	54.8628
1484.23	46.9192
1487.36	40.5421
1490.48	33.3859
1493.61	29.1287
1496.73	26.8413
1499.85	25.2194
1502.97	22.9645
1506.09	22.6042
1509.2	22.8092
1512.32	25.91
1515.44	25.8804
1518.55	26.3622
1521.66	27.7461
1524.77	31.1666
1527.88	32.9285
1530.99	34.9837
1534.1	36.2789
1537.21	38.5215
1540.31	42.2926
1543.42	46.162
1546.52	52.1173
1549.62	58.3199
1552.72	62.5955
1555.82	66.4212
1558.92	71.4865
1562.02	77.2583
1565.11	81.6662
1568.21	86.9407
1571.3	91.4165
1574.39	96.445
1577.49	99.2213
1580.58	100.794
1583.67	104.222
1586.75	105.764
1589.84	107.295
1592.93	105.585
1596.01	105.275
1599.09	103.537
1602.18	102.304
1605.26	100.02
1608.34	97.3219
1611.41	98.2177
1614.49	98.566
1617.57	100.524
1620.64	101.818
1623.72	104.14
1626.79	105.44
1629.86	108.064
1632.93	112.27
1636	114.136
1639.07	118.673
1642.14	121.168
1645.2	124.043
1648.27	127.569
1651.33	129.278
1654.39	128.707
1657.45	127.848
1660.51	125.796
1663.57	122.381
1666.63	119.489
1669.69	114.704
1672.74	108.196
1675.79	101.521
1678.85	93.1664
1681.9	84.3101
1684.95	76.4886
1688	67.4088
1691.05	59.7845
1694.1	52.8682
1697.14	46.1302
1700.19	39.9337
1703.23	34.8718
1706.27	30.1299
1709.32	26.3381
1712.35	23.5482
1715.39	21.8063
1718.43	20.9514
1721.47	19.661
1724.5	18.5316
1727.54	17.2011
1730.57	15.6067
1733.61	14.9094
1736.64	14.8769
1739.67	14.5864
1742.7	13.9384
1745.72	12.4237
1748.75	11.9762
1751.78	11.1418
1754.8	8.42651
1757.82	7.0715
1760.85	4.93018
1763.87	4.19175
1766.89	2.53203
1769.91	1.99193
1772.92	1.00538
1775.94	0.780176
1778.96	0.215782
1781.97	1.07287
1784.98	2.77364
1788	2.99208
1791.01	2.43701
1794.01	2.87284
1797.02	3.78096
1800.03	3.49943
1803.04	2.8842
1806.04	3.7025
1809.05	3.2878
1812.05	3.27352
1815.05	3.84094
1818.05	3.72689
1821.05	3.30886
1824.05	3.81018
1827.05	3.31137
1830.04	2.73045
1833.04	2.99077
1836.03	2.25454
1839.03	1.76873
1842.02	1.75462
1845.01	2.04358
1848	1.8049
1850.99	1.4151
1853.97	1.35574
1856.96	1.26136
1859.94	0.861378
1862.93	0.569608
1865.91	0.0889163
1868.89	1.40199
1871.87	1.2942
1874.85	0.322081
1877.83	1.09636
1880.81	2.3447
1882.56	2.52993
1885.55	3.65273
1888.54	3.76486
1891.52	3.96067
1894.51	3.99392
1897.49	4.77023
1900.48	5.77274
1903.46	5.91545
1906.44	6.70364
1909.42	6.39096
1912.4	7.15428
1915.38	7.21905
1918.35	6.82669
1921.33	5.66265
1924.3	5.25855
1927.28	4.53513
1930.25	4.44821
1933.22	3.84597
1936.19	2.80912
1939.16	2.64527
1942.13	2.24672
1945.09	2.24797
1948.06	2.74355
1951.03	3.01528
1953.99	1.9155
1956.95	2.07621
1959.91	1.266
1962.87	1.25675
1965.83	2.43232
1968.79	3.30581
1971.75	3.40191
1974.7	3.74652
1977.66	4.37394
1980.61	4.48737
1983.56	3.87755
1986.52	3.43879
1989.47	3.09551
1992.41	4.65805
1995.36	4.27495
1998.31	4.29597
2001.26	3.66523
2004.2	4.06826
2007.15	3.81762
2010.09	4.34365
2013.03	4.6054
2015.97	4.71559
2018.91	6.03436
2021.85	6.39749
2024.79	6.7183
2027.72	8.34949
2030.66	11.1051
2033.59	11.8791
2036.53	13.9332
2039.46	15.4017
2042.39	16.4014
2045.32	16.5325
2048.25	16.3581
2051.18	17.2356
2054.1	16.9941
2057.03	18.4752
2059.95	20.2738
2062.88	23.1225
2065.8	25.0152
2068.72	26.9641
2071.64	29.2624
2074.56	31.3057
2077.48	34.3935
2080.39	37.0442
2083.31	39.5662
2086.22	42.0268
2089.14	45.3575
2092.05	48.2328
2094.96	52.8278
2097.87	57.4281
2100.78	63.8452
2103.69	67.6769
2106.6	72.204
2109.51	76.7271
2112.41	82.0732
2115.32	87.9691
2118.22	92.8992
2121.12	99.1653
2124.02	106.427
2126.92	112.677
2129.82	120.386
2132.72	127.571
2135.62	134.873
2138.51	140.833
2141.41	145.388
2144.3	152.825
2147.19	159.32
2150.09	165.641
2152.97	171.005
2155.86	173.948
2158.75	176.803
2161.64	179.387
2164.53	180.743
2167.41	181.8
2170.3	181.996
2173.18	181.404
2176.06	179.567
2178.94	176.59
2181.82	174.21
2184.7	171.602
2187.58	166.451
2190.46	160.825
2193.33	155.118
2196.21	148.919
2199.08	142.019
2201.95	136.319
2204.83	129.952
2207.7	122.336
2210.57	114.674
2213.43	108.976
2216.3	105.291
2219.17	98.8851
2222.03	93.1358
2224.9	85.6753
2227.76	79.5385
2230.62	74.4301
2233.49	69.2851
2236.34	63.898
2239.2	59.698
2242.06	56.3843
2244.92	52.0753
2247.78	49.2682
2250.63	45.5677
2253.48	43.0699
2256.34	40.7121
2259.19	38.0645
2262.04	35.8788
2264.89	33.475
2267.74	32.6164
2270.59	31.2632
2273.43	29.8645
2276.28	27.2585
2279.12	25.0224
2281.97	24.0627
2284.81	23.0161
2287.65	20.1207
2290.49	17.4317
2293.33	14.5133
2296.17	13.4812
2299.01	14.2725
2301.84	13.3866
2304.68	13.1197
2307.51	13.3781
2310.35	13.4713
2313.18	12.8645
2316.01	12.6297
2318.84	12.5849
2321.67	11.7028
2324.5	12.4333
2327.33	11.9611
2330.15	11.0871
2332.98	10.9596
2335.8	10.4726
2338.62	8.54765
2341.45	7.44829
2344.27	6.51974
2347.09	5.28358
2349.91	4.29135
2352.72	2.53519
2355.54	1.26378
2358.36	0.115591
2361.17	-0.711699
2363.98	-0.528205
2366.8	0.421913
2369.61	0.936138
2372.42	2.18835
2375.23	2.9676
2378.04	3.49873
2380.85	2.58671
2383.66	2.19158
2386.46	1.80303
2389.26	2.37034
2392.07	3.59519
2394.87	3.8421
2397.67	3.03671
2400.47	3.11485
2403.27	3.13662
2406.07	2.25345
2408.87	3.14777
2411.67	4.01463
2414.46	4.62428
2417.26	4.75592
2420.05	5.41714
2422.84	5.25515
2425.64	4.24228
2428.43	4.9246
2431.22	4.30045
2434.01	4.9197
2436.79	5.75475
2439.58	6.1398
2442.37	5.94904
2445.15	4.7932
2447.93	5.58357
2450.72	4.87871
2453.5	4.72514
2456.28	5.82942
2459.06	6.23183
2461.84	6.56212
2464.62	5.50713
2467.39	5.99393
2470.17	5.64204
2472.94	5.48353
2475.72	5.22167
2478.49	6.66784
2481.26	6.95633
2484.03	7.28922
2486.8	5.9227
2489.57	5.36313
2492.34	4.87773
2495.1	4.52896
2497.87	3.4699
2500.63	2.61522
2503.4	2.56412
2506.16	1.69332
2508.92	1.18994
2511.68	0.382186
2514.44	0.674136
2517.2	0.254502
2519.96	-0.62173
2522.72	-0.432746
2525.47	0.189224
2528.23	0.308356
2530.98	0.800488
2533.74	0.397686
2536.49	0.801969
2539.24	1.50729
2541.99	2.19927
2544.74	3.4069
2547.49	5.08589
2550.23	5.58997
2552.98	4.82453
2555.72	4.87742
2558.47	5.73833
2561.21	5.51874
2563.95	6.10138
2566.69	5.35172
2569.43	6.12644
2572.17	6.03691
2574.91	6.22967
2577.65	5.63893
2580.39	6.48226
2583.12	7.19917
2585.85	6.23493
2588.59	6.11732
2591.32	5.68479
2594.05	5.7982
2596.78	6.25321
2599.51	5.85822
2602.24	5.51654
2604.97	5.48002
2607.69	4.73614
2610.42	3.96603
2613.14	3.67815
2615.87	2.98969
2618.59	2.45257
2621.31	2.30909
2624.03	2.78012
2626.75	3.0616
2629.47	3.47954
2632.19	3.00187
2634.91	4.20907
2637.62	4.84324
2640.34	5.33211
2643.05	5.24748
2645.76	6.34655
2648.48	7.48901
2651.19	7.13716
2653.9	6.91226
2656.6	8.19088
2659.31	7.55988
2662.02	8.00152
2664.73	8.15567
2667.43	8.4086
2670.14	7.61201
2672.84	7.78474
2675.54	8.26324
2678.24	9.01957
2680.94	8.71811
2683.64	10.1182
2686.34	9.77029
2689.04	9.31389
2691.74	9.72318
2694.43	9.67245
2697.13	10.6594
2699.82	12.1645
2702.51	12.6395
2705.21	12.7854
2707.9	13.482
2710.58	14.1192
2713.27	14.8881
2715.96	14.2565
2718.65	13.9053
2721.33	15.4131
2724.02	15.1577
2726.71	15.5814
2729.39	16.1308
2732.07	16.07
2734.75	15.4829
2737.43	14.9226
2740.11	14.9049
2742.79	14.1702
2745.47	12.7109
2748.14	11.5731
2750.82	11.2584
2753.49	9.63137
2756.17	8.18856
2758.84	6.76333
2761.51	7.06301
2764.18	6.78049
2766.85	6.96095
2769.52	5.12365
2772.19	4.36034
2774.86	3.89618
2777.52	2.1231
2780.19	2.17631
2782.85	2.02767
2785.52	1.80515
2788.18	2.08948
2790.84	1.49854
2793.5	0.460409
2796.16	-0.18852
2798.82	-0.621425
2801.48	-0.551251
2804.13	-0.0635024
2806.79	-0.921204
2809.45	-1.76672
2812.1	-1.2412
2814.75	0.097514
2817.41	1.97273
2820.06	6.01673
2822.71	11.4005
2825.36	20.0486
2828	29.2073
2830.65	38.6213
2833.3	47.8478
2835.94	58.9309
2838.59	70.1067
2841.23	80.1789
2843.87	92.0083
2846.52	106.083
2849.16	119.966
2851.8	134.92
2854.44	151.366
2857.08	166.486
2859.71	180.917
2862.35	194.931
2864.98	207.207
2867.62	217.895
2870.25	225.685
2872.88	232.824
2875.52	239.276
2878.15	244.596
2880.78	250.082
2883.41	256.159
2886.03	262.173
2888.66	268.214
2891.29	273.561
2893.91	279.619
2896.54	284.875
2899.16	291.504
2901.78	299.387
2904.4	308.935
2907.02	321.269
2909.64	337.4
2912.26	354.759
2914.88	372.836
2917.5	389.815
2920.11	405.748
2922.73	417.641
2925.34	427.898
2927.96	434.479
2930.57	436.91
2933.18	436.061
2935.79	432.345
2938.4	425.616
2941.01	416.789
2943.62	404.972
2946.22	391.263
2948.83	374.958
2951.43	357.803
2954.04	338.922
2956.64	321.501
2959.24	302.888
2961.84	284.328
2964.45	266.713
2967.05	251.415
2969.64	236.741
2972.24	223.917
2974.84	209.627
2977.43	196.259
2980.03	182.783
2982.62	169.281
2985.22	154.751
2987.81	139.371
2990.4	125.462
2992.99	112.289
2995.58	100.438
2998.17	89.3237
3000.76	78.1224
3003.34	68.9016
3005.93	59.3596
3008.52	51.2486
3011.1	43.418
3013.68	36.3652
3016.27	32.4716
3018.85	27.6099
3021.43	24.286
3024.01	20.9142
3026.59	18.2329
3029.16	17.2695
3031.74	17.0615
3034.32	17.4777
3036.89	18.1649
3039.47	19.6878
3042.04	21.3035
3044.61	22.5978
3047.18	23.9568
3049.75	24.124
3052.32	24.9205
3054.89	25.0477
3057.46	25.5129
3060.03	25.4084
3062.59	24.7444
3065.16	22.1675
3067.72	20.4249
3070.29	18.7443
3072.85	16.338
3075.41	13.1418
3077.97	10.296
3080.53	8.55041
3083.09	4.87259
3085.65	2.65869
3088.21	1.40226
3090.76	0.535308
3093.32	0.188054
3095.87	0.0749816
3098.43	0.546185
3100.98	0.842259
3103.53	1.81766
3106.08	2.83543
3108.63	4.11074
3111.18	4.25236
3113.73	5.68612
3116.28	7.48896
3118.83	8.86191
3121.37	10.7543
3123.92	12.8603
3126.46	14.2745
3129	15.9483
3131.55	18.0759
3134.09	20.0953
3136.63	22.3342
3139.17	24.5247
3141.71	27.5597
3144.24	30.6913
3146.78	33.6299
3149.32	36.3109