File: data/Raman/poly_smoothed/Thy_40_11_21_1x_45s_532 nm_x100_100%_600 gr_mm_01.txt
#Acq. time (s)=	45
#Accumulations=	2
#Range (cm-¹)=	200...3150
#Windows=	2
#Auto scanning=	Off
#Autofocus=	Off
#Macrospot=	Off
#AutoExposure=	Off
#Spike filter=	Multiple accum.
#Delay time (s)=	0
#Binning=	1
#Readout mode=	Signal
#DeNoise=	Off
#ICS correction=	On
#Dark correction=	Off
#Inst. Process=	Off
#Detector Gain=	Best Dynamic Range
#Detector ADC=	20 kHz
#Detector temperature (°C)=	-69.85
#Instrument=	LabRAM HR Evol
#Detector=	Synapse
#Objective=	x100
#Grating=	600 gr/mm
#ND Filter=	100%
#Laser (nm)=	532
#Hole=	100.021
#Range=	Auto
#Laser Pol.=	No
#Raman. Pol.=	No
#Laser Pol. (°)=	-0.0007625
#Raman Pol. (°)=	89.9995
#Collection=	Microscope
#StageXY=	Marzhauser
#StageZ=	Marzhauser
#X (µm)=	1971.3
#Y (µm)=	-46.1
#Z (µm)=	425.55
#Full time(mm:ss)=	3:18
#Project=
#Sample=
#Site=
#Title=	Thy_40_11_21_2x_45s_532 nm_x100_100%_600 gr_mm
#Remark=
#Date=	05.07.2022 11:21
#Acquired=	05.07.2022 11:21:20
#Base:Fit=	10.08.2022 10:01:35
#Base:Sub=	10.08.2022 10:01:52
#Filter:Polynom=	16.08.2022 10:21:53
#AxisType[0]=Intens
#AxisUnit[0]=Cnt
#AxisType[1]=Spectr
#AxisUnit[1]=1/cm
200.43	46.4779
204.059	31.8831
207.688	22.7935
211.314	16.3208
214.941	12.6903
218.564	9.71026
222.186	7.66975
225.809	6.33143
229.428	6.08655
233.045	5.38984
236.663	5.2934
240.278	5.85712
243.891	5.16354
247.503	6.43157
251.116	8.43858
254.725	8.93413
258.333	9.21183
261.939	10.1065
265.544	9.44828
269.148	8.91065
272.75	7.98421
276.351	8.31495
279.95	7.13557
283.548	6.98307
287.144	4.85127
290.739	4.59169
294.333	5.82357
297.925	5.36162
301.514	4.66083
305.104	3.58132
308.692	3.02579
312.279	3.97705
315.862	4.18526
319.446	4.4843
323.029	4.94087
326.608	5.80117
330.188	5.79911
333.766	5.46872
337.341	5.85105
340.917	7.13149
344.489	7.0265
348.062	7.84389
351.631	6.96014
355.201	7.20433
358.768	6.76656
362.333	6.91687
365.899	6.45592
369.462	6.02597
373.023	5.84789
376.585	6.65874
380.143	7.00436
383.7	6.05881
387.256	4.20246
390.812	3.82398
394.365	4.69499
397.916	3.49884
401.467	3.9002
405.015	3.41114
408.563	4.0158
412.109	4.3085
415.654	4.18842
419.197	4.632
422.739	4.59117
426.279	5.33472
429.819	5.34457
433.356	4.80758
436.891	5.11742
440.426	4.57168
443.96	5.61027
447.492	6.08491
451.021	6.02112
454.551	5.95907
458.079	5.36345
461.604	6.27571
465.13	7.19887
468.654	6.7902
472.175	6.89658
475.696	7.42146
479.215	8.69755
482.733	8.22694
486.249	7.62049
489.765	8.62655
493.278	10.4023
496.789	11.1958
500.301	13.268
503.81	14.2239
507.317	15.7716
510.825	15.6922
514.33	15.3496
517.833	15.6707
521.335	15.3236
524.836	15.8438
528.335	16.4996
531.835	16.3525
535.332	15.9273
538.827	14.4019
542.321	14.1577
545.814	14.1831
549.305	13.7571
552.795	12.6431
556.282	11.5256
559.769	9.91556
563.255	8.51268
566.739	7.3843
570.223	6.86471
573.705	6.51454
577.183	7.11961
580.663	7.29284
584.141	7.78313
587.615	7.6112
591.09	6.10581
594.564	6.57422
598.035	6.82882
601.506	6.73414
604.974	7.84656
608.443	9.38684
611.908	11.9658
615.374	13.6301
618.837	14.3578
622.3	16.553
625.761	18.109
629.219	20.6939
632.677	20.8969
636.135	21.5221
639.59	22.2461
643.043	23.0632
646.495	23.2251
649.948	24.4284
653.398	24.7881
656.846	25.8339
660.293	25.1873
663.738	26.6411
667.183	26.7269
670.626	26.9827
674.067	29.3674
677.508	30.8366
680.947	32.1568
684.385	33.3659
687.821	34.5224
691.254	36.0009
694.688	37.7418
698.121	39.4749
701.552	41.0049
704.98	43.2194
708.409	46.0192
711.836	47.392
715.26	48.3961
718.685	48.6594
722.108	49.1375
725.528	49.417
728.949	50.9195
732.367	53.1132
735.785	54.9831
739.2	55.62
742.614	57.4815
746.028	58.1065
749.439	60.1278
752.849	62.1314
756.26	63.5494
759.667	66.1596
763.073	67.4189
766.477	69.4637
769.883	71.812
773.285	73.9237
776.686	75.788
780.085	78.6751
783.484	80.0046
786.881	80.9266
790.276	82.6665
793.671	83.7182
797.064	84.2072
800.456	85.9445
803.846	85.7925
807.234	86.3604
810.622	87.8817
814.008	88.8841
817.394	89.8375
820.778	90.3798
824.159	90.7344
827.541	90.6265
830.921	90.4942
834.298	90.6939
837.676	89.8064
841.051	88.0582
844.426	86.4039
847.798	84.6299
851.171	81.7991
854.54	79.0777
857.911	76.6936
861.278	72.9649
864.645	70.2353
868.01	66.9495
871.373	64.7887
874.735	63.318
878.097	61.5144
881.457	61.7407
884.815	59.2519
888.172	59.1371
891.528	59.0933
894.882	58.9038
898.237	58.8389
901.589	59.7898
904.94	59.6041
908.289	59.0491
911.635	58.006
914.982	58.1465
918.328	57.1244
921.672	55.8729
925.015	55.3534
928.357	54.2553
931.698	51.8398
935.035	49.8808
938.373	48.7873
941.71	47.7116
945.044	45.5562
948.378	44.1616
951.709	44.7381
955.041	45.4924
958.372	43.4611
961.699	42.5337
965.027	42.6459
968.352	42.2085
971.676	42.0297
975	41.0847
978.322	41.5364
981.642	42.6263
984.962	41.3986
988.28	40.2961
991.596	40.1781
994.911	40.3412
998.227	39.8419
1001.54	39.0151
1004.85	38.772
1008.16	37.4842
1011.47	35.421
1014.78	34.3637
1018.08	34.3509
1021.39	33.9067
1024.69	32.2499
1028	32.5534
1031.3	33.0515
1034.6	32.755
1037.9	30.4613
1041.19	29.2511
1044.49	30.2578
1047.78	30.902
1051.08	29.9879
1054.37	28.9031
1057.66	29.9729
1060.95	29.5484
1064.24	28.3291
1067.53	27.1513
1070.81	26.8286
1074.1	25.8458
1077.38	24.042
1080.66	23.7377
1083.94	22.3221
1087.22	20.4278
1090.5	19.7957
1093.78	18.8776
1097.05	18.5163
1100.33	17.6222
1103.6	16.5007
1106.87	15.9931
1110.14	15.6557
1113.41	14.1689
1116.68	13.8993
1119.95	13.8257
1123.21	13.746
1126.48	13.6562
1129.74	12.6432
1133	11.8152
1136.26	12.9376
1139.52	12.1839
1142.78	12.1465
1146.04	11.5456
1149.29	11.0915
1152.55	9.20921
1155.8	8.4789
1159.05	7.88665
1162.3	7.29572
1165.55	5.7633
1168.8	4.96667
1172.05	4.25115
1175.29	3.33263
1178.54	2.93701
1181.78	3.21839
1185.02	3.70602
1188.26	4.13945
1191.5	4.69003
1194.74	4.61848
1197.97	5.21548
1201.21	6.02325
1204.44	8.4376
1207.68	10.7271
1210.91	11.7536
1214.14	15.1602
1217.37	16.454
1220.59	18.3607
1223.82	21.5657
1227.05	23.9183
1230.27	25.9594
1233.49	27.9347
1236.72	29.1249
1239.94	29.8983
1243.16	30.674
1246.37	31.2735
1249.59	32.6467
1252.8	33.8678
1256.02	35.6466
1259.23	36.6692
1262.44	36.7073
1265.66	36.6177
1268.86	37.8344
1272.07	37.3847
1275.28	37.794
1278.48	39.7904
1281.69	41.5096
1284.89	41.49
1288.09	42.9976
1291.29	44.1674
1294.49	45.2502
1297.69	46.5386
1300.89	47.7737
1304.08	50.0964
1307.28	49.5448
1310.47	50.1828
1313.66	49.5892
1316.85	49.7159
1320.04	50.2294
1323.23	50.6819
1326.42	49.9732
1329.61	49.7669
1332.79	48.0827
1335.97	47.9654
1339.16	45.9706
1342.34	45.0503
1345.52	44.4537
1348.7	42.2259
1351.87	40.2896
1355.05	39.5261
1358.22	39.0177
1361.4	37.2076
1364.57	35.6044
1367.74	34.4863
1370.91	32.211
1374.08	29.9827
1377.25	28.4338
1380.41	26.9995
1383.58	25.2217
1386.74	23.6986
1389.91	22.8346
1393.07	22.5602
1396.23	22.0923
1399.39	21.6189
1402.55	21.1918
1405.7	20.7064
1408.86	22.8274
1412.01	24.0166
1415.17	24.9518
1418.32	26.7895
1421.47	30.1005
1424.62	32.7009
1427.77	35.4828
1430.91	39.8996
1434.06	43.5388
1437.2	46.7071
1440.35	47.9738
1443.49	48.4511
1446.63	49.0939
1449.77	49.8198
1452.91	50.7319
1456.05	50.0978
1459.18	48.3377
1462.32	46.2254
1465.45	44.4471
1468.59	42.1041
1471.72	39.0264
1474.85	35.072
1477.98	31.6787
1481.1	29.0827
1484.23	25.9791
1487.36	22.638
1490.48	20.5194
1493.61	18.1507
1496.73	16.5327
1499.85	15.9804
1502.97	14.5072
1506.09	14.2184
1509.2	13.8155
1512.32	13.168
1515.43	12.8087
1518.55	12.102
1521.66	12.306
1524.77	13.2473
1527.88	14.5764
1530.99	15.4966
1534.1	16.0802
1537.21	17.6956
1540.31	19.6283
1543.42	21.5472
1546.52	23.2025
1549.62	24.2276
1552.72	26.1441
1555.82	27.8865
1558.92	29.3119
1562.02	29.6108
1565.11	31.2735
1568.21	32.2045
1571.3	34.2664
1574.39	35.9967
1577.49	37.8038
1580.57	39.4191
1583.66	40.0921
1586.75	40.634
1589.84	39.487
1592.92	40.1948
1596.01	39.2549
1599.09	40.8967
1602.17	39.8626
1605.25	39.6395
1608.33	38.9354
1611.41	38.5713
1614.49	39.0307
1617.57	39.2897
1620.64	40.1086
1623.72	39.724
1626.79	38.7457
1629.86	40.0883
1632.93	40.7736
1636	42.0268
1639.07	43.4065
1642.13	44.9191
1645.2	46.8801
1648.26	48.9888
1651.33	49.7745
1654.39	51.142
1657.45	51.4817
1660.51	50.4842
1663.57	48.6548
1666.63	47.293
1669.68	44.8746
1672.74	42.1067
1675.79	39.8791
1678.85	36.5793
1681.9	33.1667
1684.95	30.3912
1688	27.9751
1691.05	25.2819
1694.09	22.263
1697.14	18.5397
1700.18	15.144
1703.23	12.6185
1706.27	10.6452
1709.31	9.18047
1712.35	8.21775
1715.39	6.56259
1718.43	5.77261
1721.47	4.86508
1724.5	4.04712
1727.54	3.60222
1730.57	2.99147
1733.61	2.2394
1736.64	1.45465
1739.67	0.936127
1742.7	0.740137
1745.72	0.784518
1748.75	1.63023
1751.77	1.9285
1754.8	1.37513
1757.82	1.8599
1760.84	1.95944
1763.87	1.71119
1766.89	1.62419
1769.91	0.517289
1772.92	0.523399
1775.94	1.68216
1778.95	2.3619
1781.97	2.91877
1784.98	3.30994
1787.99	3.08452
1791.01	3.10701
1794.01	3.65133
1797.02	3.89566
1800.03	4.30264
1803.04	4.81895
1806.04	5.25749
1809.05	5.64499
1812.05	6.3519
1815.05	6.64241
1818.05	7.35795
1821.05	6.54975
1824.05	6.69799
1827.05	6.36698
1830.04	6.62861
1833.04	7.08371
1836.03	6.78035
1839.03	6.07399
1842.02	6.01839
1845.01	5.9941
1848	6.48855
1850.99	5.79404
1853.97	4.87352
1856.96	4.23855
1859.94	4.30257
1862.93	4.20135
1865.91	5.33495
1868.89	5.2821
1871.87	5.52988
1874.85	5.85448
1877.83	5.92991
1880.81	5.94632
1882.57	6.39132
1885.56	6.95333
1888.55	7.34116
1891.54	7.32476
1894.52	7.82575
1897.51	9.50597
1900.49	9.5536
1903.47	9.72629
1906.45	8.80791
1909.43	8.27464
1912.41	7.94897
1915.39	7.91455
1918.37	8.52998
1921.34	7.63837
1924.32	6.1737
1927.29	5.84212
1930.26	5.90573
1933.23	6.552
1936.2	6.65434
1939.17	7.12639
1942.14	6.80239
1945.11	5.30534
1948.07	5.11323
1951.04	4.34583
1954	4.34036
1956.96	5.13452
1959.93	3.9011
1962.89	3.66387
1965.85	4.06921
1968.8	3.90808
1971.76	2.97937
1974.72	1.42324
1977.67	0.804401
1980.63	1.549
1983.58	1.27457
1986.53	1.89912
1989.48	2.21128
1992.43	1.9107
1995.38	1.67063
1998.32	2.88117
2001.27	2.96711
2004.22	3.25448
2007.16	3.46313
2010.1	4.64706
2013.04	5.24521
2015.98	4.65864
2018.92	4.57712
2021.86	4.16247
2024.8	4.88063
2027.74	5.13018
2030.67	4.59457
2033.61	4.48039
2036.54	4.89236
2039.47	4.77507
2042.4	3.88643
2045.33	4.46309
2048.26	4.77691
2051.19	6.04762
2054.12	6.87565
2057.04	7.12156
2059.97	7.99717
2062.89	9.24635
2065.81	9.45822
2068.73	9.79792
2071.65	10.5443
2074.57	11.132
2077.49	12.3583
2080.41	13.5181
2083.32	14.2849
2086.24	14.6498
2089.15	15.155
2092.07	15.3412
2094.98	15.4753
2097.89	16.1181
2100.8	15.9641
2103.71	16.4934
2106.61	17.2955
2109.52	17.4936
2112.43	18.547
2115.33	21.2368
2118.23	22.5882
2121.13	24.0104
2124.04	25.8034
2126.94	28.457
2129.83	31.1199
2132.73	33.8278
2135.63	35.9117
2138.53	37.7464
2141.42	40.7213
2144.31	43.2675
2147.21	44.8067
2150.1	48.2426
2152.99	49.9541
2155.88	51.3134
2158.77	53.2092
2161.65	54.3982
2164.54	54.6661
2167.43	55.6624
2170.31	56.2674
2173.19	56.8583
2176.07	56.9661
2178.96	56.5169
2181.84	56.1657
2184.72	56.2439
2187.59	54.7105
2190.47	53.0629
2193.35	50.8097
2196.22	49.4575
2199.09	47.9636
2201.97	45.6938
2204.84	42.4899
2207.71	38.5746
2210.58	36.0497
2213.45	33.6046
2216.31	31.6316
2219.18	29.8518
2222.05	28.1855
2224.91	25.9887
2227.78	23.5657
2230.64	22.3004
2233.5	20.8728
2236.36	19.2391
2239.22	17.849
2242.08	16.8332
2244.93	14.1819
2247.79	13.0322
2250.64	12.593
2253.5	12.1303
2256.35	11.2056
2259.2	10.1491
2262.05	10.1677
2264.9	9.97551
2267.75	9.55833
2270.6	9.00954
2273.45	8.93216
2276.29	8.74609
2279.14	9.15899
2281.98	9.77206
2284.82	9.95951
2287.66	9.66353
2290.5	9.9037
2293.34	8.93215
2296.18	9.31971
2299.02	10.321
2301.86	10.2233
2304.69	9.78172
2307.53	9.27429
2310.36	7.76705
2313.19	7.28129
2316.02	6.59242
2318.85	5.69156
2321.68	4.617
2324.51	4.42319
2327.34	3.26745
2330.16	3.65823
2332.99	3.08495
2335.81	3.14621
2338.64	2.35591
2341.46	2.51986
2344.28	1.78818
2347.1	1.77889
2349.92	1.93812
2352.74	1.44144
2355.55	1.33535
2358.37	1.37888
2361.19	1.95232
2364	2.59647
2366.81	2.81971
2369.62	2.18873
2372.44	2.38312
2375.24	2.73922
2378.05	2.16287
2380.86	1.73269
2383.67	1.7439
2386.47	1.53899
2389.28	0.77103
2392.08	0.930476
2394.89	0.437637
2397.69	0.605855
2400.49	0.655281
2403.29	0.783809
2406.09	1.59705
2408.88	2.00054
2411.68	2.81982
2414.48	3.38483
2417.27	4.33664
2420.06	4.56755
2422.86	4.7211
2425.65	6.03724
2428.44	6.50501
2431.23	6.57976
2434.02	5.98183
2436.81	6.78445
2439.59	7.18067
2442.38	7.71064
2445.16	7.61622
2447.95	7.62524
2450.73	6.92234
2453.51	7.18826
2456.29	6.90513
2459.07	6.23875
2461.85	5.961
2464.63	6.13333
2467.4	4.93072
2470.18	4.88455
2472.95	4.21765
2475.73	4.25997
2478.5	3.5962
2481.27	2.85406
2484.04	3.15719
2486.81	2.83712
2489.58	2.61386
2492.35	2.58893
2495.12	1.87157
2497.88	0.853199
2500.65	1.18986
2503.41	0.634003
2506.17	1.50311
2508.94	1.39196
2511.7	1.98194
2514.46	2.30486
2517.22	2.88533
2519.97	2.75981
2522.73	3.43895
2525.49	3.64507
2528.24	3.77648
2530.99	4.34151
2533.75	5.12257
2536.5	4.9147
2539.25	5.48814
2542	6.27764
2544.75	7.41208
2547.5	7.11038
2550.24	8.03642
2552.99	7.82448
2555.74	8.65448
2558.48	8.12935
2561.22	9.717
2563.96	9.83088
2566.71	10.1598
2569.45	10.5007
2572.18	9.83847
2574.92	9.75031
2577.66	9.49706
2580.4	9.26038
2583.13	9.30009
2585.87	8.72251
2588.6	8.09361
2591.33	7.67625
2594.06	7.04054
2596.79	6.7851
2599.52	7.25608
2602.25	6.88436
2604.98	7.66144
2607.71	7.83271
2610.43	7.94954
2613.16	7.57731
2615.88	7.38381
2618.6	8.10973
2621.32	8.33113
2624.04	8.79841
2626.76	9.58057
2629.48	9.40213
2632.2	8.74746
2634.92	7.73514
2637.63	7.37522
2640.35	6.84847
2643.06	6.3836
2645.77	6.57478
2648.49	7.16303
2651.2	6.71373
2653.91	5.93152
2656.62	6.02889
2659.33	6.11625
2662.03	6.0681
2664.74	6.40129
2667.44	6.91796
2670.15	7.45571
2672.85	8.09919
2675.55	8.35734
2678.26	8.40828
2680.96	7.96134
2683.66	7.46875
2686.35	7.91842
2689.05	7.3332
2691.75	7.70487
2694.44	7.70516
2697.14	7.78859
2699.83	7.18963
2702.52	7.55297
2705.22	7.73867
2707.91	7.29168
2710.6	7.96085
2713.29	8.22983
2715.97	7.48088
2718.66	6.9784
2721.35	6.96347
2724.03	6.83536
2726.72	6.60336
2729.4	6.24676
2732.08	6.57684
2734.76	6.78314
2737.44	6.71908
2740.12	6.91908
2742.8	6.69294
2745.48	6.33398
2748.16	6.21623
2750.83	5.26443
2753.51	4.94919
2756.18	3.87339
2758.85	4.26966
2761.53	4.53755
2764.2	4.7204
2766.87	4.45764
2769.54	4.08386
2772.2	3.71763
2774.87	3.03848
2777.54	2.96928
2780.2	2.14196
2782.87	2.48576
2785.53	2.64827
2788.19	2.05429
2790.85	2.21984
2793.51	1.72553
2796.17	1.69623
2798.83	1.44871
2801.49	0.708332
2804.15	0.67617
2806.8	0.333053
2809.46	0.0786898
2812.11	-0.291922
2814.76	-0.0294595
2817.42	-0.576789
2820.07	0.747805
2822.72	2.58012
2825.37	4.50478
2828.02	6.93791
2830.66	8.3818
2833.31	11.0811
2835.96	12.6617
2838.6	14.6586
2841.24	17.7661
2843.89	20.7471
2846.53	24.1188
2849.17	28.1596
2851.81	31.6564
2854.45	35.7465
2857.09	39.9305
2859.72	43.8869
2862.36	48.2516
2865	51.9459
2867.63	55.7422
2870.26	59.3139
2872.9	62.4782
2875.53	64.2033
2878.16	65.9717
2880.79	67.35
2883.42	69.3437
2886.05	71.0176
2888.67	73.2646
2891.3	76.1569
2893.92	79.323
2896.55	82.3411
2899.17	84.9493
2901.79	88.0955
2904.42	92.4891
2907.04	97.881
2909.66	103.343
2912.27	109.407
2914.89	116.241
2917.51	123.009
2920.13	129.645
2922.74	135.492
2925.35	139.707
2927.97	143.005
2930.58	145.399
2933.19	146.261
2935.8	145.185
2938.41	142.781
2941.02	139.543
2943.63	135.737
2946.24	131.758
2948.84	127.154
2951.45	122.505
2954.05	117.412
2956.65	111.124
2959.26	104.276
2961.86	98.0279
2964.46	91.6363
2967.06	86.5993
2969.66	81.4442
2972.25	76.7665
2974.85	71.3049
2977.45	66.3838
2980.04	61.531
2982.64	56.6555
2985.23	52.0166
2987.82	46.4346
2990.41	41.8395
2993	37.457
2995.59	31.8042
2998.18	26.9031
3000.77	21.9755
3003.36	18.3023
3005.94	15.0467
3008.53	11.9805
3011.11	9.23839
3013.69	6.87303
3016.28	4.55933
3018.86	3.03921
3021.44	1.56014
3024.02	0.425865
3026.6	0.430177
3029.18	0.365409
3031.75	1.12629
3034.33	0.793646
3036.9	0.931399
3039.48	0.677723
3042.05	1.3619
3044.62	2.71793
3047.19	3.74124
3049.77	3.93413
3052.34	4.23624
3054.9	4.84306
3057.47	3.85766
3060.04	3.75314
3062.61	4.02142
3065.17	3.61963
3067.74	3.82165
3070.3	3.48617
3072.86	3.17867
3075.42	3.6634
3077.99	3.68419
3080.54	3.46344
3083.1	2.62636
3085.66	2.02606
3088.22	1.74118
3090.78	1.69799
3093.33	0.961435
3095.89	0.707054
3098.44	0.260668
3100.99	-0.134612
3103.54	0.360512
3106.1	0.126524
3108.65	0.351897
3111.2	0.471098
3113.74	0.277314
3116.29	0.972668
3118.84	2.16204
3121.38	2.67781
3123.93	3.65056
3126.47	4.43482
3129.01	6.10735
3131.56	7.62335
3134.1	9.35985
3136.64	11.8081
3139.18	14.0649
3141.72	15.514
3144.26	17.0949
3146.79	18.728
3149.33	20.4676