File: data/Raman/poly_smoothed/Thy_20_09_24_1x_45s_532 nm_x100_100%_600 gr_mm_01.txt
#Acq. time (s)=	45
#Accumulations=	2
#Range (cm-¹)=	200...3150
#Windows=	2
#Auto scanning=	Off
#Autofocus=	Off
#Macrospot=	Off
#AutoExposure=	Off
#Spike filter=	Multiple accum.
#Delay time (s)=	0
#Binning=	1
#Readout mode=	Signal
#DeNoise=	Off
#ICS correction=	On
#Dark correction=	Off
#Inst. Process=	Off
#Detector Gain=	Best Dynamic Range
#Detector ADC=	20 kHz
#Detector temperature (°C)=	-69.85
#Instrument=	LabRAM HR Evol
#Detector=	Synapse
#Objective=	x100
#Grating=	600 gr/mm
#ND Filter=	100%
#Laser (nm)=	532
#Hole=	100.021
#Range=	Auto
#Laser Pol.=	No
#Raman. Pol.=	No
#Laser Pol. (°)=	-0.0007625
#Raman Pol. (°)=	89.9995
#Collection=	Microscope
#StageXY=	Marzhauser
#StageZ=	Marzhauser
#X (µm)=	-5910.6
#Y (µm)=	2880.2
#Z (µm)=	-223.55
#Full time(mm:ss)=	3:18
#Project=
#Sample=
#Site=
#Title=	Thy_20_09_24_2x_45s_532 nm_x100_100%_600 gr_mm
#Remark=
#Date=	29.06.2022 12:20
#Acquired=	29.06.2022 12:20:56
#Base:Fit=	10.08.2022 09:52:02
#Base:Fit=	10.08.2022 09:52:12
#Base:Sub=	10.08.2022 09:54:21
#Filter:Polynom=	16.08.2022 10:24:04
#AxisType[0]=Intens
#AxisUnit[0]=Cnt
#AxisType[1]=Spectr
#AxisUnit[1]=1/cm
200.523	-0.105492
204.154	12.8773
207.781	21.2348
211.409	25.0868
215.034	26.8448
218.659	27.2829
222.281	27.6864
225.903	25.9544
229.522	25.4757
233.14	23.6957
236.756	23.6854
240.373	23.2506
243.986	23.5433
247.598	23.3862
251.208	19.5739
254.818	18.1351
258.427	16.0878
262.034	15.2913
265.638	16.1869
269.242	16.8479
272.844	17.4683
276.445	16.0413
280.044	16.0621
283.642	17.3722
287.238	17.1752
290.833	17.3805
294.425	15.433
298.017	14.6406
301.608	15.4086
305.198	15.4108
308.786	16.2732
312.371	16.6128
315.956	16.5651
319.54	16.4608
323.122	18.3446
326.701	18.4768
330.281	19.7609
333.857	20.0201
337.434	18.3356
341.008	17.7417
344.582	16.3577
348.153	14.3199
351.724	14.638
355.292	12.7443
358.861	13.7306
362.426	14.077
365.99	12.9269
369.555	12.4372
373.116	11.5869
376.676	11.1247
380.236	11.1027
383.793	10.6528
387.349	11.1633
390.903	12.3882
394.456	11.1516
398.007	11.0413
401.56	11.5801
405.108	10.7654
408.656	11.6706
412.202	10.7016
415.746	10.171
419.29	11.8549
422.831	10.126
426.37	8.36906
429.909	6.91473
433.447	6.26768
436.983	6.44809
440.519	5.98767
444.052	4.47544
447.583	5.88382
451.114	3.79774
454.643	3.25513
458.169	5.08058
461.696	6.89723
465.222	8.45229
468.744	8.79842
472.267	10.0183
475.787	12.6935
479.307	12.8927
482.823	14.0212
486.341	15.999
489.855	18.7912
493.37	19.7277
496.881	21.8681
500.391	22.2244
503.902	23.7671
507.409	23.0062
510.915	23.4461
514.42	24.3645
517.925	23.6869
521.427	23.6935
524.928	24.0555
528.427	21.6271
531.925	22.3788
535.422	22.1077
538.917	21.065
542.411	21.6651
545.903	20.3999
549.395	19.6485
552.884	17.9406
556.373	17.257
559.86	17.3538
563.346	17.192
566.831	16.6691
570.314	16.7233
573.794	15.4995
577.274	14.409
580.754	13.742
584.23	12.3004
587.706	9.96869
591.181	10.7627
594.653	10.9632
598.126	10.5971
601.595	9.82268
605.065	11.1917
608.532	11.7466
611.999	11.5587
615.463	11.4257
618.928	11.9929
622.389	12.6257
625.851	11.3243
629.31	12.3194
632.767	13.3871
636.223	14.0922
639.68	14.5366
643.134	16.3118
646.586	18.1204
650.037	20.3754
653.486	21.4657
656.936	21.6846
660.383	21.9489
663.829	22.3891
667.273	21.3376
670.716	21.9053
674.158	23.1595
677.598	23.716
681.035	23.2461
684.473	24.7574
687.909	25.6867
691.344	26.7187
694.778	27.2035
698.211	28.5971
701.64	28.9103
705.07	30.5515
708.498	30.2672
711.924	32.3492
715.35	34.3839
718.774	34.8291
722.196	36.9818
725.618	39.2189
729.037	41.0013
732.456	43.2618
735.873	45.0154
739.289	47.2373
742.703	48.6474
746.116	52.3716
749.529	53.4541
752.938	56.2937
756.347	57.6937
759.756	59.1378
763.162	61.5505
766.567	62.715
769.97	64.9677
773.372	66.0356
776.773	65.8614
780.174	65.9873
783.573	66.143
786.97	66.9932
790.365	67.9648
793.76	69.1621
797.153	70.1382
800.543	72.1117
803.933	73.0427
807.322	73.7896
810.71	73.8849
814.097	74.5301
817.483	76.3355
820.865	77.1065
824.248	78.6327
827.629	78.931
831.008	79.4139
834.387	78.4228
837.765	78.4211
841.139	76.1373
844.514	75.1126
847.886	73.1002
851.259	69.8764
854.629	65.7749
857.997	61.1382
861.366	57.0791
864.732	54.5076
868.098	52.4648
871.461	50.3729
874.823	49.7
878.184	46.1196
881.545	46.0518
884.903	44.3511
888.26	42.8792
891.616	42.1756
894.97	40.9755
898.323	39.7467
901.675	39.0217
905.026	38.3671
908.375	38.2935
911.723	37.4796
915.07	37.6894
918.415	37.9756
921.76	36.7718
925.103	36.5364
928.443	37.4311
931.783	36.043
935.123	33.557
938.461	32.1826
941.796	31.0224
945.131	28.656
948.465	28.3224
951.797	29.1176
955.128	28.3442
958.457	25.8961
961.786	24.3031
965.113	24.6728
968.44	25.305
971.763	25.3659
975.086	26.057
978.409	26.0451
981.729	26.71
985.048	28.2562
988.367	28.5385
991.683	30.1512
994.998	30.9893
998.312	31.6401
1001.62	32.0987
1004.94	33.1893
1008.25	32.6967
1011.56	32.0398
1014.86	30.7114
1018.17	28.4363
1021.48	26.2697
1024.78	23.5283
1028.08	21.156
1031.38	20.8019
1034.68	17.5015
1037.98	13.539
1041.28	12.5298
1044.57	13.2049
1047.87	13.3447
1051.16	13.7633
1054.45	13.5172
1057.75	14.1746
1061.04	14.5771
1064.32	13.7429
1067.61	15.6054
1070.9	17.2474
1074.18	18.8789
1077.47	20.0584
1080.75	22.2814
1084.03	22.8289
1087.31	22.0565
1090.59	22.0486
1093.86	22.5221
1097.14	22.3441
1100.41	21.5362
1103.69	20.4946
1106.96	19.5531
1110.23	19.0871
1113.5	16.0762
1116.77	14.4871
1120.03	12.777
1123.3	11.1005
1126.56	10.4305
1129.83	9.35201
1133.09	8.41763
1136.35	8.6313
1139.61	9.6483
1142.86	8.30011
1146.12	8.14812
1149.38	9.48334
1152.63	7.88711
1155.88	7.66671
1159.14	8.03358
1162.39	5.79356
1165.63	5.13576
1168.88	4.33719
1172.13	4.66267
1175.38	7.12918
1178.62	6.72323
1181.86	5.1985
1185.1	5.24434
1188.34	6.65882
1191.58	7.65655
1194.82	7.34045
1198.06	9.5957
1201.29	12.9889
1204.53	17.3866
1207.76	22.6701
1210.99	27.562
1214.22	31.7824
1217.45	36.183
1220.68	40.2326
1223.91	44.0465
1227.13	47.8168
1230.36	50.8938
1233.58	53.1366
1236.8	56.7595
1240.02	59.0021
1243.24	60.5623
1246.46	61.9633
1249.67	61.8173
1252.89	62.7152
1256.1	63.7886
1259.32	64.28
1262.53	65.9931
1265.74	69.328
1268.95	69.9296
1272.15	70.5795
1275.36	74.5046
1278.57	77.713
1281.77	83.6667
1284.97	86.5801
1288.18	88.7941
1291.38	90.895
1294.58	93.3175
1297.78	95.6944
1300.97	97.7128
1304.17	98.9843
1307.36	101.849
1310.55	105.26
1313.75	106.397
1316.94	106.558
1320.13	106.123
1323.32	104.256
1326.5	101.827
1329.69	99.7693
1332.87	97.3643
1336.06	95.5687
1339.24	93.2379
1342.42	91.5402
1345.6	89.117
1348.78	86.0224
1351.96	83.9382
1355.13	81.4665
1358.31	78.5503
1361.48	76.3583
1364.65	72.9159
1367.82	71.9285
1370.99	69.5094
1374.16	67.7553
1377.33	65.9699
1380.5	65.2478
1383.66	64.859
1386.83	64.3295
1389.99	61.3017
1393.15	59.1243
1396.31	56.7915
1399.47	55.2195
1402.63	54.4528
1405.78	52.6693
1408.94	52.8883
1412.1	54.197
1415.25	56.9791
1418.4	58.9555
1421.55	63.364
1424.7	67.7049
1427.85	71.9376
1431	78.6644
1434.14	84.8603
1437.29	89.9747
1440.43	94.6226
1443.57	98.9156
1446.71	99.7751
1449.85	100.015
1452.99	100.895
1456.13	99.3423
1459.26	96.4413
1462.4	91.0661
1465.54	86.0434
1468.67	78.7372
1471.8	71.2019
1474.93	64.2209
1478.06	55.6559
1481.19	48.7578
1484.31	40.7692
1487.44	35.9546
1490.56	30.3482
1493.69	25.9811
1496.81	23.8986
1499.93	24.6857
1503.05	23.5126
1506.17	24.9699
1509.28	24.0758
1512.4	23.8966
1515.52	25.1959
1518.63	27.7615
1521.74	29.4746
1524.85	32.6097
1527.96	36.779
1531.07	40.2361
1534.18	43.1375
1537.29	45.5441
1540.39	47.8275
1543.5	51.5189
1546.6	54.2646
1549.7	57.0027
1552.8	60.7181
1555.9	64.2273
1559	67.3187
1562.1	70.5608
1565.19	74.332
1568.29	78.3686
1571.38	84.0645
1574.47	88.3827
1577.56	91.504
1580.66	95.2257
1583.74	97.125
1586.83	98.3109
1589.92	101.077
1593.01	102.903
1596.09	102.629
1599.17	102.623
1602.25	101.917
1605.34	99.6181
1608.41	97.1086
1611.49	94.5048
1614.57	91.5965
1617.65	89.0801
1620.72	86.0788
1623.79	83.0829
1626.87	81.1175
1629.94	81.7495
1633.01	81.5138
1636.08	81.1424
1639.15	81.4082
1642.21	83.0137
1645.28	85.2669
1648.34	87.524
1651.41	88.9866
1654.47	91.1337
1657.53	91.0923
1660.59	89.8325
1663.65	88.8262
1666.71	86.0048
1669.76	84.4981
1672.82	81.4881
1675.87	76.0047
1678.93	71.2836
1681.98	65.5829
1685.03	60.8273
1688.08	54.3999
1691.13	48.2481
1694.17	41.4964
1697.22	35.5047
1700.27	30.8269
1703.31	25.6145
1706.35	21.9513
1709.39	17.7822
1712.43	14.8445
1715.47	13.1099
1718.51	12.8943
1721.55	11.536
1724.58	10.1046
1727.62	9.33696
1730.65	8.63299
1733.68	6.68837
1736.72	5.78805
1739.74	6.25039
1742.77	7.20823
1745.8	6.35278
1748.83	5.80397
1751.85	6.72917
1754.88	6.16832
1757.9	6.24208
1760.92	5.56496
1763.95	3.87459
1766.96	3.20386
1769.98	3.09931
1773	2.45044
1776.02	1.86925
1779.03	2.0074
1782.05	2.67322
1785.06	2.35884
1788.07	1.82903
1791.08	1.8469
1794.09	1.30857
1797.1	0.370116
1800.11	0.868874
1803.12	-0.0727923
1806.12	0.0484866
1809.12	-0.0271427
1812.13	0.204255
1815.13	-0.737969
1818.13	0.400041
1821.13	0.339516
1824.13	0.660172
1827.13	1.43539
1830.12	0.494352
1833.12	0.796216
1836.11	0.15024
1839.1	0.464294
1842.09	0.295516
1845.09	-0.150579
1848.08	0.161722
1851.06	0.29802
1854.05	1.77796
1857.04	2.42554
1860.02	2.87938
1863.01	2.88804
1865.99	3.03358
1868.97	2.89287
1871.95	3.3027
1874.93	5.14999
1877.91	5.65672
1880.89	5.7833
1882.46	4.68786
1885.45	5.36733
1888.43	5.89295
1891.42	6.49393
1894.41	6.78596
1897.39	7.10882
1900.37	6.51193
1903.36	5.69425
1906.34	6.18191
1909.32	6.43966
1912.29	5.89527
1915.27	5.92292
1918.25	6.01761
1921.23	7.83833
1924.2	8.92989
1927.17	10.3035
1930.15	10.0209
1933.12	9.13656
1936.09	9.39626
1939.06	9.13387
1942.02	9.06362
1944.99	9.72004
1947.96	9.21639
1950.92	8.37422
1953.88	7.38611
1956.85	6.23504
1959.81	5.93781
1962.77	5.05431
1965.73	5.76836
1968.69	4.82915
1971.64	2.9863
1974.6	3.01672
1977.55	3.07588
1980.51	3.56314
1983.46	3.05932
1986.41	3.58244
1989.36	4.83022
1992.31	5.91696
1995.26	7.7891
1998.21	9.13029
2001.15	9.75978
2004.1	9.48873
2007.04	9.07042
2009.99	8.3811
2012.93	8.02191
2015.87	8.07202
2018.81	8.83948
2021.75	8.84496
2024.68	8.08784
2027.62	7.40657
2030.56	7.35763
2033.49	7.76671
2036.42	8.07263
2039.36	8.8522
2042.29	9.10927
2045.22	9.42051
2048.14	10.0087
2051.07	10.2176
2054	10.8282
2056.93	11.5458
2059.85	13.3209
2062.77	14.3323
2065.7	14.6381
2068.62	14.3971
2071.54	14.6413
2074.46	14.6168
2077.38	14.8428
2080.29	14.7043
2083.21	15.9273
2086.12	15.6315
2089.04	16.5545
2091.95	17.5889
2094.86	17.8166
2097.77	17.9523
2100.68	20.0779
2103.59	20.2067
2106.5	21.2774
2109.41	23.0398
2112.31	25.3868
2115.21	26.0872
2118.12	27.0294
2121.02	28.638
2123.92	31.0369
2126.82	33.8944
2129.72	35.7245
2132.62	38.02
2135.51	39.0624
2138.41	41.4966
2141.31	43.0693
2144.2	46.1246
2147.09	47.359
2149.98	49.2619
2152.87	50.9609
2155.76	53.1786
2158.65	54.756
2161.54	56.5093
2164.43	57.5984
2167.31	58.1146
2170.2	58.3626
2173.08	59.4249
2175.96	60.045
2178.84	59.728
2181.72	59.4424
2184.6	58.7023
2187.48	57.4285
2190.36	55.9428
2193.23	55.3973
2196.11	53.7857
2198.98	51.5487
2201.85	49.9137
2204.72	48.0761
2207.59	46.2735
2210.46	43.1842
2213.33	40.5896
2216.2	39.073
2219.07	36.4984
2221.93	34.392
2224.8	32.7126
2227.66	31.7365
2230.52	28.6735
2233.39	26.719
2236.25	25.5874
2239.1	24.8879
2241.96	23.612
2244.82	23.1513
2247.68	21.4452
2250.53	20.5231
2253.38	19.6608
2256.24	19.5981
2259.09	18.7657
2261.94	18.8772
2264.79	19.8155
2267.64	19.1064
2270.49	19.2761
2273.33	19.4426
2276.18	18.9749
2279.02	17.9059
2281.87	17.6081
2284.71	17.1659
2287.55	15.4323
2290.39	13.9369
2293.23	12.2567
2296.07	11.6311
2298.91	11.71
2301.74	11.163
2304.58	11.6112
2307.41	11.4089
2310.25	11.1579
2313.08	11.2196
2315.91	12.0213
2318.74	12.45
2321.57	12.5451
2324.4	12.37
2327.23	12.5
2330.05	11.9575
2332.88	12.1879
2335.7	11.9484
2338.52	11.5749
2341.35	12.0443
2344.17	10.6446
2346.99	9.53796
2349.81	9.65058
2352.62	8.83841
2355.44	7.2277
2358.26	6.18198
2361.07	4.97543
2363.89	5.90826
2366.7	7.0215
2369.51	6.02308
2372.32	5.27547
2375.13	4.64059
2377.94	4.72549
2380.75	4.79479
2383.56	4.73982
2386.36	4.41108
2389.17	4.15297
2391.97	2.75479
2394.77	2.20787
2397.58	2.10182
2400.38	2.16089
2403.18	2.66659
2405.97	2.65792
2408.77	3.36765
2411.57	4.2307
2414.37	5.52747
2417.16	6.18296
2419.95	7.8002
2422.75	7.9938
2425.54	7.94283
2428.33	8.56536
2431.12	9.68887
2433.91	9.84945
2436.7	8.70095
2439.48	8.30521
2442.27	8.81404
2445.05	8.5617
2447.84	8.72435
2450.62	7.67084
2453.4	7.59352
2456.18	6.80177
2458.96	5.81004
2461.74	4.1244
2464.52	3.22608
2467.29	3.02997
2470.07	2.45598
2472.85	1.81325
2475.62	0.90965
2478.39	1.8597
2481.16	2.67771
2483.93	2.69852
2486.7	2.00644
2489.47	1.91055
2492.24	1.05922
2495.01	0.481573
2497.77	0.28777
2500.54	0.701498
2503.3	-0.949116
2506.06	-1.65341
2508.83	-0.878423
2511.59	-0.35792
2514.35	-1.11128
2517.11	-0.215936
2519.86	-0.0237583
2522.62	0.244168
2525.38	-0.331132
2528.13	-0.191857
2530.89	0.545742
2533.64	1.45004
2536.39	2.28342
2539.14	2.95298
2541.89	3.94254
2544.64	4.81005
2547.39	5.88822
2550.14	6.54309
2552.88	6.83597
2555.63	6.08884
2558.37	6.36334
2561.11	5.76089
2563.86	5.31665
2566.6	4.89944
2569.34	4.30838
2572.08	4.0862
2574.82	4.26745
2577.55	3.53336
2580.29	3.50574
2583.02	3.73129
2585.76	3.2675
2588.49	1.95934
2591.22	2.27939
2593.96	2.69853
2596.69	3.59808
2599.42	4.27104
2602.14	4.65024
2604.87	4.71501
2607.6	4.67075
2610.32	4.7505
2613.05	5.9747
2615.77	6.76346
2618.49	6.41461
2621.22	7.02383
2623.94	5.6311
2626.66	6.06527
2629.37	5.94965
2632.09	6.02832
2634.81	5.39922
2637.53	5.87567
2640.24	5.58675
2642.96	5.61032
2645.67	5.22899
2648.38	4.79125
2651.09	4.84746
2653.8	3.89947
2656.51	3.9438
2659.22	5.06485
2661.93	4.18534
2664.63	3.33398
2667.34	2.84936
2670.04	3.01685
2672.75	3.67052
2675.45	3.02263
2678.15	3.72759
2680.85	5.07552
2683.55	4.54422
2686.25	4.47578
2688.94	4.32576
2691.64	4.43138
2694.34	5.3232
2697.03	6.33794
2699.73	6.7034
2702.42	7.98143
2705.11	8.48358
2707.8	8.83852
2710.49	9.56529
2713.18	10.7908
2715.87	11.787
2718.55	13.3907
2721.24	13.6538
2723.93	14.1559
2726.61	13.7493
2729.29	13.9464
2731.98	14.441
2734.66	14.6845
2737.34	13.7879
2740.02	13.0046
2742.7	12.2339
2745.37	10.6747
2748.05	9.89771
2750.72	8.95435
2753.4	8.14864
2756.07	6.9113
2758.75	5.51142
2761.42	5.64791
2764.09	5.23363
2766.76	3.97055
2769.43	3.53254
2772.1	2.6737
2774.76	3.46527
2777.43	4.32045
2780.1	5.23176
2782.76	4.62048
2785.42	5.11302
2788.09	4.88786
2790.75	5.17258
2793.41	5.51657
2796.07	5.56272
2798.73	4.94163
2801.39	3.60348
2804.04	2.42255
2806.7	1.02847
2809.35	-0.262864
2812.01	-0.837749
2814.66	-0.861629
2817.31	-0.859681
2819.96	-0.68806
2822.61	1.20445
2825.26	4.0664
2827.91	7.99951
2830.56	10.9565
2833.21	15.4074
2835.85	19.6994
2838.5	25.8427
2841.14	33.2652
2843.78	40.8421
2846.42	49.0505
2849.06	58.5935
2851.71	68.9617
2854.34	78.8189
2856.98	89.0231
2859.62	98.0449
2862.26	105.29
2864.89	112.916
2867.53	119.475
2870.16	126.95
2872.79	132.82
2875.42	138.017
2878.05	143.623
2880.68	147.863
2883.31	153.415
2885.94	158.279
2888.57	163.461
2891.19	168.389
2893.82	172.843
2896.44	178.173
2899.07	185.343
2901.69	194.144
2904.31	203.768
2906.93	215.657
2909.55	225.914
2912.17	237.256
2914.79	248.717
2917.41	260.423
2920.02	269.399
2922.64	275.647
2925.25	280.578
2927.86	283.684
2930.48	285.295
2933.09	285.311
2935.7	283.422
2938.31	277.754
2940.92	271.9
2943.53	265.523
2946.13	256.401
2948.74	247.373
2951.34	236.663
2953.95	226.532
2956.55	216.077
2959.15	205.265
2961.75	195.794
2964.35	186.308
2966.95	177.978
2969.55	170.018
2972.15	161.237
2974.75	151.702
2977.34	142.731
2979.94	132.816
2982.53	122.689
2985.13	111.415
2987.72	100.926
2990.31	90.1065
2992.9	80.2301
2995.49	70.795
2998.08	60.5889
3000.67	51.8361
3003.25	44.3127
3005.84	37.3024
3008.42	31.6003
3011.01	26.0502
3013.59	21.462
3016.17	18.2628
3018.76	15.2408
3021.34	12.9882
3023.92	10.594
3026.49	10.0058
3029.07	9.26977
3031.65	9.4563
3034.23	9.03519
3036.8	9.52988
3039.38	10.0279
3041.95	11.3164
3044.52	12.5015
3047.09	13.146
3049.66	14.2803
3052.23	15.4048
3054.8	15.4775
3057.37	14.7389
3059.94	14.94
3062.5	14.4641
3065.07	14.0983
3067.63	13.4901
3070.2	12.2078
3072.76	11.5436
3075.32	9.48748
3077.88	8.42168
3080.44	6.86699
3083	4.58829
3085.56	2.8307
3088.12	1.5456
3090.67	0.584663
3093.23	0.0356897
3095.78	-0.136175
3098.34	-0.770387
3100.89	-0.98394
3103.44	-0.720769
3105.99	-0.103719
3108.54	0.319343
3111.09	1.03317
3113.64	1.78156
3116.19	1.75035
3118.74	2.91454
3121.28	3.46417
3123.83	4.61089
3126.37	5.55884
3128.91	6.92285
3131.46	7.71094
3134	9.48523
3136.54	10.2892
3139.08	13.1082
3141.62	14.8633
3144.16	17.0859
3146.69	19.5746
3149.23	20.0825