File: data/Raman/poly_smoothed/Thy_10_08_43_1x_45s_532 nm_x100_100%_600 gr_mm_01.txt
#Acq. time (s)=	45
#Accumulations=	2
#Range (cm-¹)=	200...3150
#Windows=	2
#Auto scanning=	Off
#Autofocus=	Off
#Macrospot=	Off
#AutoExposure=	Off
#Spike filter=	Multiple accum.
#Delay time (s)=	0
#Binning=	1
#Readout mode=	Signal
#DeNoise=	Off
#ICS correction=	On
#Dark correction=	Off
#Inst. Process=	Off
#Detector Gain=	Best Dynamic Range
#Detector ADC=	20 kHz
#Detector temperature (°C)=	-69.85
#Instrument=	LabRAM HR Evol
#Detector=	Synapse
#Objective=	x100
#Grating=	600 gr/mm
#ND Filter=	100%
#Laser (nm)=	532
#Hole=	100.021
#Range=	Auto
#Laser Pol.=	No
#Raman. Pol.=	No
#Laser Pol. (°)=	-0.0007625
#Raman Pol. (°)=	89.9995
#Collection=	Microscope
#StageXY=	Marzhauser
#StageZ=	Marzhauser
#X (µm)=	-2356.3
#Y (µm)=	230
#Z (µm)=	521.25
#Full time(mm:ss)=	3:18
#Project=
#Sample=
#Site=
#Title=	Thy_10_08_43_2x_45s_532 nm_x100_100%_600 gr_mm
#Remark=
#Date=	06.07.2022 14:51
#Acquired=	06.07.2022 14:51:18
#Base:Fit=	10.08.2022 09:46:25
#Base:Sub=	10.08.2022 09:46:49
#Filter:Polynom=	16.08.2022 10:24:56
#AxisType[0]=Intens
#AxisUnit[0]=Cnt
#AxisType[1]=Spectr
#AxisUnit[1]=1/cm
200.398	3.19839
204.027	6.11447
207.657	6.75818
211.283	7.31088
214.909	8.39483
218.533	8.08858
222.157	7.10177
225.777	5.9483
229.396	4.49832
233.016	6.00776
236.632	5.50908
240.247	6.52432
243.86	7.47907
247.474	7.45242
251.085	6.60714
254.694	5.7393
258.301	5.52068
261.908	6.97671
265.513	8.4554
269.116	8.82244
272.718	8.98944
276.319	9.38681
279.918	10.5518
283.516	11.2569
287.113	12.7168
290.708	13.4914
294.302	13.5623
297.894	13.4329
301.485	13.3261
305.073	13.6007
308.661	13.371
312.247	13.0761
315.833	13.0024
319.415	14.0907
322.997	14.4902
326.579	14.6216
330.156	14.7805
333.735	15.2566
337.31	13.451
340.885	10.665
344.458	9.06131
348.03	8.67933
351.6	8.5583
355.17	7.37629
358.737	6.14435
362.304	5.9164
365.868	6.5646
369.431	7.21744
372.994	6.85337
376.554	6.24626
380.112	5.50583
383.669	4.69136
387.225	5.49555
390.781	6.11266
394.334	8.31884
397.885	9.31744
401.436	9.83441
404.984	10.4646
408.532	12.4827
412.078	12.8342
415.623	13.4415
419.166	14.3129
422.708	14.2228
426.248	13.4699
429.788	12.7919
433.326	12.9818
436.86	12.684
440.395	12.8893
443.929	13.2938
447.461	14.1291
450.99	15.0632
454.52	14.8996
458.048	13.8103
461.573	14.0616
465.099	13.3247
468.623	12.5801
472.144	13.672
475.666	14.3307
479.184	15.1757
482.703	16.2685
486.218	16.1756
489.734	16.2454
493.247	17.5736
496.759	19.0577
500.271	20.3155
503.779	20.8128
507.287	22.2119
510.795	23.0716
514.299	23.3668
517.803	23.0786
521.305	22.2666
524.805	23.444
528.307	22.8164
531.805	21.2803
535.301	21.0259
538.797	20.0768
542.291	18.5698
545.783	16.5278
549.275	14.2162
552.765	12.2047
556.253	11.5916
559.738	10.7537
563.224	9.47835
566.709	8.47279
570.192	7.64507
573.674	6.49477
577.153	6.62574
580.632	6.91603
584.11	6.08035
587.587	5.06029
591.06	5.17293
594.534	3.92585
598.005	3.43613
601.476	4.20749
604.944	4.97634
608.413	5.22927
611.878	5.80082
615.344	5.9665
618.807	8.16958
622.27	8.23442
625.73	7.73963
629.189	7.06169
632.648	8.4958
636.105	9.86609
639.559	11.2123
643.013	11.7283
646.467	12.5248
649.918	13.3442
653.368	13.3427
656.816	15.2369
660.263	16.2231
663.708	16.9613
667.153	18.0476
670.596	18.4959
674.037	19.2003
677.478	18.6474
680.917	19.7581
684.355	21.0307
687.791	22.5559
691.224	24.5012
694.658	25.9803
698.091	27.9608
701.522	28.4743
704.95	29.169
708.379	29.0602
711.806	30.8425
715.23	33.0639
718.655	34.8881
722.078	37.3071
725.498	39.3727
728.919	40.2282
732.337	43.9395
735.755	46.2117
739.17	49.9333
742.584	53.6887
745.998	55.7099
749.409	58.6911
752.819	61.783
756.23	62.8707
759.637	64.4248
763.043	66.1293
766.448	68.8441
769.853	70.3478
773.255	72.0246
776.656	73.52
780.056	74.7347
783.454	74.9962
786.851	77.0292
790.247	79.1233
793.641	81.1221
797.034	82.8517
800.426	84.6034
803.817	85.5078
807.206	85.305
810.592	85.5223
813.979	86.8499
817.364	87.5126
820.748	88.2638
824.129	88.9358
827.511	87.7245
830.891	86.9322
834.269	86.2065
837.646	83.5652
841.023	82.1978
844.396	80.4811
847.77	78.6375
851.141	75.3925
854.513	73.3328
857.881	71.1603
861.248	69.1191
864.616	67.1841
867.98	67.1585
871.343	67.2793
874.707	64.7819
878.068	63.1565
881.428	61.7377
884.786	61.7299
888.143	60.5126
891.498	59.757
894.855	60.4714
898.208	60.8417
901.56	61.1367
904.91	59.9051
908.26	57.965
911.608	58.3069
914.955	57.2016
918.298	57.6564
921.643	57.453
924.986	57.6856
928.328	57.795
931.668	56.9225
935.006	56.6342
938.344	56.2076
941.681	54.8591
945.014	53.2279
948.349	51.6943
951.682	50.0522
955.012	47.1976
958.343	42.8622
961.67	42.366
964.998	43.6371
968.323	43.3669
971.649	44.3525
974.971	44.5663
978.293	44.728
981.615	44.238
984.933	43.592
988.251	43.2761
991.567	42.9648
994.884	43.7422
998.198	43.9752
1001.51	43.2091
1004.82	42.5091
1008.13	42.6137
1011.44	42.2798
1014.75	40.9632
1018.06	39.0572
1021.36	37.2804
1024.66	33.7708
1027.97	31.5648
1031.27	29.7336
1034.57	28.8254
1037.87	26.907
1041.16	26.8598
1044.46	28.5041
1047.76	27.4117
1051.05	27.7177
1054.34	27.3527
1057.63	25.9789
1060.92	24.8725
1064.21	24.4428
1067.5	23.7436
1070.78	23.8062
1074.07	24.2091
1077.35	24.0834
1080.63	23.4107
1083.91	22.7421
1087.19	22.8856
1090.47	22.849
1093.75	21.9416
1097.03	21.1121
1100.3	20.3174
1103.57	20.1915
1106.84	19.0825
1110.11	18.6083
1113.38	18.7311
1116.65	17.4672
1119.92	14.8243
1123.19	12.5627
1126.45	10.8536
1129.71	7.51708
1132.97	7.00167
1136.23	5.35235
1139.49	4.64312
1142.75	4.75685
1146.01	4.7777
1149.26	4.40944
1152.52	4.41179
1155.77	4.93557
1159.02	4.06974
1162.27	5.04269
1165.52	5.44582
1168.77	5.90679
1172.02	6.73817
1175.26	8.82803
1178.51	10.006
1181.75	11.2609
1184.99	13.3288
1188.23	14.7324
1191.47	14.8617
1194.71	16.2396
1197.94	16.3102
1201.18	17.7134
1204.41	18.4559
1207.65	19.9953
1210.88	22.5689
1214.11	23.8673
1217.34	25.294
1220.57	27.7679
1223.79	28.6866
1227.02	31.1966
1230.24	32.6705
1233.47	35.6408
1236.69	37.8007
1239.91	40.029
1243.13	42.7739
1246.34	45.1392
1249.56	47.6668
1252.78	49.5387
1255.99	50.5302
1259.2	50.2854
1262.42	51.321
1265.63	51.9431
1268.84	51.9958
1272.04	53.3781
1275.25	54.6783
1278.46	54.9726
1281.66	54.9684
1284.86	55.47
1288.07	55.4872
1291.27	55.274
1294.47	56.3193
1297.66	57.0046
1300.86	58.31
1304.06	59.8648
1307.25	61.1702
1310.44	62.3988
1313.64	63.4893
1316.83	65.3555
1320.02	65.592
1323.2	65.6622
1326.39	64.9537
1329.58	63.7259
1332.76	62.5551
1335.95	60.728
1339.13	59.7106
1342.31	58.2067
1345.49	56.8966
1348.67	54.6398
1351.85	52.0017
1355.02	50.3159
1358.2	46.9446
1361.37	45.0908
1364.54	42.9195
1367.71	39.8121
1370.88	36.7118
1374.05	35.1817
1377.22	32.1677
1380.39	30.5254
1383.55	30.2766
1386.72	30.6775
1389.88	29.788
1393.04	27.9915
1396.2	26.9687
1399.36	25.3549
1402.52	25.7894
1405.68	28.085
1408.83	30.054
1411.98	32.9306
1415.14	36.1987
1418.29	41.5186
1421.44	45.1095
1424.59	49.7286
1427.74	55.556
1430.89	61.2225
1434.03	65.9346
1437.18	68.6929
1440.32	71.3124
1443.46	73.0291
1446.6	73.5165
1449.74	73.4254
1452.88	73.2111
1456.02	71.0633
1459.16	69.4272
1462.29	65.7272
1465.43	59.13
1468.56	51.0687
1471.69	44.7814
1474.82	37.5105
1477.95	31.6333
1481.08	27.8484
1484.2	24.3432
1487.33	20.9078
1490.46	17.4671
1493.58	15.3981
1496.7	14.5388
1499.82	12.1438
1502.94	12.5838
1506.06	12.4023
1509.18	11.3966
1512.29	11.449
1515.41	10.9024
1518.52	12.7616
1521.63	15.2211
1524.75	16.1228
1527.85	18.2189
1530.96	17.7666
1534.07	17.7351
1537.18	18.3256
1540.28	19.2748
1543.39	19.5651
1546.49	20.9169
1549.59	23.7246
1552.69	25.187
1555.79	28.5401
1558.89	29.4981
1561.99	31.9813
1565.08	34.0288
1568.18	34.8965
1571.27	38.6206
1574.37	40.3467
1577.46	42.3096
1580.55	45.2552
1583.64	47.4471
1586.73	49.6673
1589.81	50.6397
1592.9	51.396
1595.98	52.1845
1599.06	53.527
1602.15	52.402
1605.23	51.4035
1608.31	51.2735
1611.39	50.2933
1614.46	51.2659
1617.54	51.1217
1620.61	50.6323
1623.69	51.6745
1626.76	52.7337
1629.83	54.2708
1632.9	56.13
1635.97	59.2433
1639.04	62.6243
1642.11	64.3732
1645.17	69.1113
1648.24	73.2203
1651.3	77.0531
1654.36	79.8115
1657.42	80.8723
1660.48	81.021
1663.54	80.95
1666.6	78.8513
1669.66	76.9236
1672.71	74.3907
1675.77	70.7622
1678.82	65.889
1681.87	61.5501
1684.92	55.7495
1687.97	48.8925
1691.02	44.4296
1694.07	38.2133
1697.11	33.8723
1700.16	29.5036
1703.2	25.8958
1706.25	22.8334
1709.29	20.46
1712.33	17.7544
1715.37	15.9762
1718.41	14.418
1721.44	13.8176
1724.48	12.7932
1727.51	11.7971
1730.55	11.7066
1733.58	10.7944
1736.61	10.2367
1739.64	10.0562
1742.67	9.63375
1745.7	9.01262
1748.72	7.72499
1751.75	6.4502
1754.77	5.77665
1757.8	4.88492
1760.82	4.32437
1763.84	3.80167
1766.86	2.85996
1769.88	3.18633
1772.9	2.44497
1775.91	2.04854
1778.93	1.71767
1781.94	1.52615
1784.96	1.80826
1787.97	0.964576
1790.98	-0.075544
1793.99	-0.0594505
1797	0.429
1800.01	1.23823
1803.01	2.54887
1806.02	2.58194
1809.02	1.99216
1812.02	2.32236
1815.02	2.51692
1818.03	2.30662
1821.02	1.50216
1824.02	1.29319
1827.02	0.911855
1830.02	0.672814
1833.01	0.0404512
1836.01	0.369741
1839	0.70578
1841.99	2.03415
1844.98	2.13542
1847.97	2.2617
1850.96	3.03545
1853.95	3.26897
1856.93	4.19605
1859.92	3.89179
1862.9	3.75721
1865.88	4.38263
1868.87	4.71934
1871.85	4.39108
1874.83	4.70012
1877.81	5.17336
1880.78	5.05302
1882.53	4.62551
1885.52	3.69336
1888.51	3.69067
1891.5	2.96296
1894.48	2.62265
1897.47	2.584
1900.45	2.39765
1903.43	2.45316
1906.41	3.00482
1909.39	3.58511
1912.37	4.80868
1915.35	5.43114
1918.33	4.78152
1921.3	5.76703
1924.28	6.13743
1927.25	5.81503
1930.22	5.73369
1933.19	5.5253
1936.16	6.0624
1939.13	6.04545
1942.1	6.89735
1945.07	7.0386
1948.03	7.85417
1951	8.19853
1953.96	8.11236
1956.92	8.57053
1959.88	9.74249
1962.84	10.1877
1965.8	11.3391
1968.76	11.792
1971.72	12.474
1974.67	12.7543
1977.63	14.5144
1980.58	14.6605
1983.54	14.9345
1986.49	14.7702
1989.44	15.1917
1992.39	14.7227
1995.33	14.9135
1998.28	13.8486
2001.23	13.3787
2004.17	13.4679
2007.12	14.2462
2010.06	13.7139
2013	13.9525
2015.94	13.7823
2018.88	13.7919
2021.82	14.3147
2024.76	15.3166
2027.69	15.8217
2030.63	16.5354
2033.56	16.1891
2036.5	16.7254
2039.43	17.3483
2042.36	17.4591
2045.29	18.0838
2048.22	19.1536
2051.15	19.245
2054.07	19.2224
2057	19.4148
2059.92	19.0074
2062.85	18.8922
2065.77	17.3902
2068.69	16.7656
2071.61	15.5264
2074.53	15.6809
2077.45	15.7365
2080.37	15.6661
2083.28	14.7946
2086.2	14.7043
2089.11	15.0538
2092.02	15.0946
2094.94	15.6864
2097.85	16.0367
2100.76	15.6791
2103.66	16.5572
2106.57	18.1373
2109.48	20.4429
2112.38	20.5366
2115.29	21.9707
2118.19	23.2223
2121.09	23.7148
2123.99	25.11
2126.89	26.4544
2129.79	27.1863
2132.69	27.6389
2135.59	27.8101
2138.48	28.8289
2141.38	29.1115
2144.27	30.9385
2147.17	32.3208
2150.06	33.1236
2152.95	34.5997
2155.84	35.5545
2158.73	37.1135
2161.61	38.3997
2164.5	39.2552
2167.38	40.0898
2170.27	40.6648
2173.15	41.2981
2176.03	41.5264
2178.91	41.1736
2181.8	40.9703
2184.67	40.0122
2187.55	38.6245
2190.43	37.5014
2193.3	35.685
2196.18	34.6068
2199.05	33.657
2201.93	31.8747
2204.8	30.2636
2207.67	29.2582
2210.54	28.1538
2213.41	26.2761
2216.27	25.1546
2219.14	24.2184
2222.01	22.7789
2224.87	23.6347
2227.73	23.1294
2230.6	23.3362
2233.46	23.0559
2236.32	22.4457
2239.18	21.5999
2242.03	21.0404
2244.89	20.9909
2247.75	21.0634
2250.6	21.5311
2253.46	20.2004
2256.31	20.064
2259.16	19.6579
2262.01	19.4445
2264.86	19.7162
2267.71	19.7273
2270.56	19.6377
2273.4	19.2905
2276.25	18.385
2279.09	18.0976
2281.94	17.7118
2284.78	17.4128
2287.62	16.9978
2290.46	16.9139
2293.3	15.951
2296.14	16.0006
2298.98	16.0402
2301.82	16.1188
2304.65	16.2007
2307.49	15.4842
2310.32	15.1561
2313.15	15.5759
2315.98	15.2286
2318.81	14.2126
2321.64	13.3144
2324.47	13.0186
2327.3	13.1451
2330.12	12.7399
2332.95	12.0738
2335.77	10.9865
2338.6	10.5015
2341.42	10.1309
2344.24	9.86783
2347.06	10.3034
2349.88	10.7623
2352.7	9.97241
2355.51	8.91102
2358.33	8.39871
2361.14	7.58614
2363.96	8.24147
2366.77	8.88262
2369.58	9.13348
2372.39	8.5891
2375.2	8.77346
2378.01	7.4194
2380.82	6.53544
2383.63	5.60113
2386.43	5.38608
2389.24	5.09913
2392.04	5.13528
2394.84	4.60642
2397.65	5.26073
2400.45	4.79683
2403.25	5.60465
2406.05	6.3128
2408.84	6.43576
2411.64	7.88631
2414.44	9.42463
2417.23	10.5092
2420.02	10.6772
2422.82	10.2152
2425.61	10.715
2428.4	10.7417
2431.19	11.6572
2433.98	11.6037
2436.77	11.2612
2439.55	10.0293
2442.34	11.5207
2445.12	10.8987
2447.91	9.65541
2450.69	9.05384
2453.47	9.32147
2456.25	9.50957
2459.03	8.24359
2461.81	7.50702
2464.59	7.00547
2467.36	7.28762
2470.14	6.41479
2472.92	6.0724
2475.69	4.22052
2478.46	3.79625
2481.23	4.06512
2484	3.06689
2486.77	1.95271
2489.54	1.8286
2492.31	1.58583
2495.08	1.20757
2497.84	0.192858
2500.61	0.35874
2503.37	-0.526161
2506.13	-0.125608
2508.9	0.483744
2511.66	1.67121
2514.42	1.63495
2517.18	1.79272
2519.93	1.82785
2522.69	1.75955
2525.45	1.38148
2528.2	1.31916
2530.95	1.10656
2533.71	1.22744
2536.46	1.64779
2539.21	1.4949
2541.96	1.69799
2544.71	1.57815
2547.46	2.7311
2550.2	3.07835
2552.95	3.61692
2555.7	3.8431
2558.44	4.64351
2561.18	4.52682
2563.93	4.43715
2566.67	4.19805
2569.41	4.24142
2572.15	4.25258
2574.88	4.06899
2577.62	4.06898
2580.36	3.55831
2583.09	3.60236
2585.83	2.95692
2588.56	2.65063
2591.29	1.88127
2594.02	1.58791
2596.75	1.36573
2599.48	1.6654
2602.21	1.49344
2604.94	1.44151
2607.67	1.58482
2610.39	0.963243
2613.12	0.0876061
2615.84	0.25153
2618.56	-0.236876
2621.28	-0.438143
2624.01	0.329865
2626.72	-0.227253
2629.44	-0.0919791
2632.16	0.203984
2634.88	0.603659
2637.59	1.04445
2640.31	0.931608
2643.02	0.609722
2645.74	0.761613
2648.45	1.69138
2651.16	1.94482
2653.87	1.69449
2656.58	2.83778
2659.29	2.60942
2661.99	3.30411
2664.7	3.94959
2667.41	4.59154
2670.11	4.76914
2672.81	4.96143
2675.51	5.14223
2678.22	4.55224
2680.92	5.23466
2683.62	4.43074
2686.31	4.93779
2689.01	5.1113
2691.71	5.54779
2694.4	5.21672
2697.1	5.86991
2699.79	6.23539
2702.49	6.22367
2705.18	6.45372
2707.87	6.23519
2710.56	6.04461
2713.25	6.45355
2715.94	7.07263
2718.62	7.54038
2721.31	8.09592
2723.99	8.71763
2726.68	8.5729
2729.36	9.3068
2732.04	9.43249
2734.73	9.71635
2737.41	10.5164
2740.08	9.61297
2742.76	9.40336
2745.44	8.07346
2748.12	7.38991
2750.79	6.71534
2753.47	6.42913
2756.14	5.41288
2758.81	4.56157
2761.49	3.84704
2764.16	3.74765
2766.83	2.37664
2769.5	1.42561
2772.16	0.151498
2774.83	0.771627
2777.5	0.4891
2780.16	0.836388
2782.83	0.780917
2785.49	0.858873
2788.15	1.05342
2790.82	1.25085
2793.48	1.19446
2796.14	1.48998
2798.79	1.3524
2801.45	1.39065
2804.11	1.26263
2806.76	0.70892
2809.42	0.412849
2812.07	0.600571
2814.73	1.41289
2817.38	2.66407
2820.03	4.14114
2822.68	6.69785
2825.33	10.0033
2827.98	13.1866
2830.63	17.2553
2833.27	21.5972
2835.92	26.9722
2838.56	34.7133
2841.21	41.1864
2843.85	48.2139
2846.49	56.7942
2849.13	66.2942
2851.77	76.05
2854.41	86.0639
2857.05	95.067
2859.69	103.728
2862.32	112.453
2864.96	119.854
2867.59	127.767
2870.23	134.071
2872.86	139.708
2875.49	145.729
2878.12	150.317
2880.75	154.597
2883.38	158.735
2886.01	162.779
2888.63	167.082
2891.26	170.834
2893.89	174.961
2896.51	179.353
2899.13	185.895
2901.76	193.279
2904.38	201.876
2907	211.771
2909.62	223.091
2912.24	235.767
2914.85	248.037
2917.47	258.923
2920.09	268.462
2922.7	276.402
2925.32	282.045
2927.93	285.376
2930.54	287.351
2933.15	286.591
2935.76	283.645
2938.37	278.476
2940.98	271.299
2943.59	262.941
2946.2	253.536
2948.8	243.729
2951.41	233.089
2954.01	222.414
2956.62	211.643
2959.22	201.242
2961.82	191.567
2964.42	182.583
2967.02	173.937
2969.62	167.129
2972.22	159.837
2974.81	154.025
2977.41	145.757
2980	138.859
2982.6	130.835
2985.19	122.406
2987.78	113.048
2990.38	103.594
2992.97	94.6582
2995.56	85.2769
2998.14	76.9458
3000.73	69.0496
3003.32	61.5213
3005.91	54.8388
3008.49	49.4133
3011.07	44.066
3013.66	39.5837
3016.24	35.8619
3018.82	32.2584
3021.4	29.7209
3023.98	26.9487
3026.56	24.6397
3029.14	23.1012
3031.71	22.7163
3034.29	23.1859
3036.87	24.163
3039.44	24.3206
3042.01	24.2935
3044.59	25.78
3047.16	26.9624
3049.73	27.0415
3052.3	27.7164
3054.87	28.6833
3057.43	28.9068
3060	28.8825
3062.57	28.7833
3065.13	27.9948
3067.7	26.1698
3070.26	24.7436
3072.82	23.2831
3075.39	21.2625
3077.95	18.7328
3080.51	16.2959
3083.07	13.757
3085.63	10.4878
3088.18	8.03403
3090.74	5.72041
3093.29	4.50248
3095.85	2.85926
3098.4	2.27976
3100.95	1.2423
3103.51	0.160139
3106.06	-0.00141331
3108.61	0.462577
3111.16	0.287727
3113.71	0.707274
3116.25	0.0238125
3118.8	0.0775516
3121.35	-0.0913983
3123.89	0.155756
3126.44	0.842706
3128.98	0.0282493
3131.52	0.706189
3134.06	1.32836
3136.6	1.77037
3139.14	1.77569
3141.68	2.18785
3144.22	2.80046
3146.76	4.11286
3149.29	6.54541