File: data/Raman/poly_smoothed/Thy_20_09_27_1x_45s_532 nm_x100_100%_600 gr_mm_01.txt
#Acq. time (s)=	45
#Accumulations=	2
#Range (cm-¹)=	200...3150
#Windows=	2
#Auto scanning=	Off
#Autofocus=	Off
#Macrospot=	Off
#AutoExposure=	Off
#Spike filter=	Multiple accum.
#Delay time (s)=	0
#Binning=	1
#Readout mode=	Signal
#DeNoise=	Off
#ICS correction=	On
#Dark correction=	Off
#Inst. Process=	Off
#Detector Gain=	Best Dynamic Range
#Detector ADC=	20 kHz
#Detector temperature (°C)=	-69.85
#Instrument=	LabRAM HR Evol
#Detector=	Synapse
#Objective=	x100
#Grating=	600 gr/mm
#ND Filter=	100%
#Laser (nm)=	532
#Hole=	100.021
#Range=	Auto
#Laser Pol.=	No
#Raman. Pol.=	No
#Laser Pol. (°)=	-0.0007625
#Raman Pol. (°)=	89.9995
#Collection=	Microscope
#StageXY=	Marzhauser
#StageZ=	Marzhauser
#X (µm)=	-5917.9
#Y (µm)=	2885.6
#Z (µm)=	-222.9
#Full time(mm:ss)=	3:18
#Project=
#Sample=
#Site=
#Title=	Thy_20_09_27_2x_45s_532 nm_x100_100%_600 gr_mm
#Remark=
#Date=	29.06.2022 12:32
#Acquired=	29.06.2022 12:32:53
#Base:Fit=	10.08.2022 09:52:02
#Base:Fit=	10.08.2022 09:52:12
#Base:Sub=	10.08.2022 09:54:21
#Filter:Polynom=	16.08.2022 10:24:04
#AxisType[0]=Intens
#AxisUnit[0]=Cnt
#AxisType[1]=Spectr
#AxisUnit[1]=1/cm
200.523	5.18469
204.154	3.22078
207.781	1.72377
211.409	0.670275
215.034	-0.0431978
218.659	-0.32239
222.281	0.769018
225.903	2.78243
229.522	3.14493
233.14	3.7939
236.756	4.53599
240.373	5.04009
243.986	5.9707
247.598	6.77499
251.208	6.75719
254.818	8.17195
258.427	8.4735
262.034	8.43567
265.638	8.60666
269.242	8.97526
272.844	9.83976
276.445	9.74555
280.044	8.92083
283.642	9.17268
287.238	9.03374
290.833	9.18063
294.425	10.2435
298.017	10.7451
301.608	10.6565
305.198	12.3234
308.786	14.6892
312.371	15.7323
315.956	15.0228
319.54	15.3786
323.122	16.1531
326.701	15.6585
330.281	15.5431
333.857	15.3363
337.434	14.9639
341.008	14.1723
344.582	14.3226
348.153	12.9024
351.724	12.8091
355.292	13.0815
358.861	13.1879
362.426	12.123
365.99	11.4059
369.555	10.7085
373.116	10.5526
376.676	10.9813
380.236	10.7639
383.793	11.2483
387.349	11.7303
390.903	13.5357
394.456	12.9183
398.007	11.4803
401.56	9.96192
405.108	10.4654
408.656	10.7181
412.202	8.66482
415.746	8.28773
419.29	8.25937
422.831	7.68788
426.37	7.04278
429.909	6.49163
433.447	5.95719
436.983	5.55602
440.519	5.89747
444.052	6.4323
447.583	4.95852
451.114	3.65098
454.643	4.59542
458.169	4.38724
461.696	3.81707
465.222	4.11458
468.744	5.24347
472.267	6.47148
475.787	7.27859
479.307	7.98886
482.823	7.56391
486.341	9.71505
489.855	11.4872
493.37	13.4327
496.881	14.2598
500.391	14.4951
503.902	15.6044
507.409	15.0568
510.915	16.7331
514.42	17.1542
517.925	17.7909
521.427	19.6684
524.928	19.9935
528.427	21.5804
531.925	21.8735
535.422	21.1928
538.917	20.7895
542.411	19.7552
545.903	18.5071
549.395	17.6209
552.884	16.2958
556.373	15.3556
559.86	13.0428
563.346	11.6978
566.831	10.1076
570.314	9.31325
573.794	8.38035
577.274	6.51553
580.754	5.80969
584.23	3.38158
587.706	2.07299
591.181	2.29971
594.653	1.71657
598.126	2.48205
601.595	1.54743
605.065	3.85435
608.532	4.28723
611.999	4.96246
615.463	6.22521
618.928	5.11161
622.389	7.72053
625.851	9.20553
629.31	8.58893
632.767	7.92135
636.223	8.69711
639.68	8.32964
643.134	8.87208
646.586	9.89811
650.037	11.3055
653.486	11.2237
656.936	12.6967
660.383	14.0756
663.829	15.5506
667.273	16.6303
670.716	17.9324
674.158	19.1549
677.598	21.1728
681.035	23.7512
684.473	24.4676
687.909	25.0898
691.344	26.4948
694.778	27.7425
698.211	29.4937
701.64	31.2775
705.07	31.6222
708.498	32.6437
711.924	31.8368
715.35	32.7749
718.774	34.5274
722.196	34.2449
725.618	33.9282
729.037	35.0306
732.456	34.8717
735.873	34.9866
739.289	36.5831
742.703	39.2329
746.116	41.0187
749.529	42.5868
752.938	45.1052
756.347	47.9795
759.756	49.202
763.162	52.4783
766.567	54.8748
769.97	56.1399
773.372	58.9812
776.773	61.2545
780.174	63.4874
783.573	65.6385
786.97	67.0731
790.365	68.4436
793.76	70.5966
797.153	72.1333
800.543	71.3324
803.933	71.4099
807.322	71.5365
810.71	72.0618
814.097	72.5648
817.483	73.6654
820.865	73.8062
824.248	73.8622
827.629	73.0775
831.008	71.9498
834.387	71.3401
837.765	69.989
841.139	68.7558
844.514	66.8462
847.886	64.3476
851.259	61.2533
854.629	59.2849
857.997	56.3454
861.366	52.3914
864.732	49.9523
868.098	48.4459
871.461	46.0968
874.823	43.805
878.184	41.4913
881.545	39.4881
884.903	39.2139
888.26	39.2116
891.616	40.3602
894.97	39.7225
898.323	39.2516
901.675	39.4179
905.026	39.3544
908.375	39.2061
911.723	40.1527
915.07	39.3499
918.415	39.7586
921.76	40.178
925.103	39.4382
928.443	37.0744
931.783	35.5942
935.123	35.8166
938.461	36.7943
941.796	35.7317
945.131	34.6253
948.465	32.8813
951.797	32.6371
955.128	31.326
958.457	28.3853
961.786	26.937
965.113	26.1272
968.44	25.3436
971.763	24.6595
975.086	25.8948
978.409	26.7302
981.729	27.0844
985.048	27.7337
988.367	26.7829
991.683	26.2432
994.998	25.4418
998.312	24.0782
1001.62	24.5629
1004.94	22.8663
1008.25	21.8893
1011.56	21.9541
1014.86	22.826
1018.17	21.6766
1021.48	20.9704
1024.78	19.1841
1028.08	17.3207
1031.38	16.0614
1034.68	14.6549
1037.98	12.4689
1041.28	11.5335
1044.57	10.6353
1047.87	11.3776
1051.16	11.9289
1054.45	12.305
1057.75	12.7298
1061.04	13.026
1064.32	11.7261
1067.61	10.801
1070.9	9.62103
1074.18	9.75881
1077.47	10.0551
1080.75	9.32522
1084.03	9.79593
1087.31	11.0345
1090.59	12.6781
1093.86	13.4197
1097.14	13.5283
1100.41	14.7421
1103.69	14.1383
1106.96	13.6619
1110.23	12.7131
1113.5	12.9483
1116.77	12.0302
1120.03	12.256
1123.3	10.9982
1126.56	10.383
1129.83	10.3651
1133.09	9.14949
1136.35	7.58922
1139.61	6.3425
1142.86	5.06702
1146.12	4.15433
1149.38	3.40265
1152.63	2.2432
1155.88	3.77637
1159.14	3.46335
1162.39	3.89551
1165.63	3.92739
1168.88	4.72204
1172.13	3.87125
1175.38	3.41278
1178.62	4.14371
1181.86	4.03852
1185.1	2.79467
1188.34	4.32333
1191.58	4.74036
1194.82	5.06401
1198.06	5.94079
1201.29	6.30756
1204.53	7.04817
1207.76	9.14605
1210.99	10.5728
1214.22	11.6911
1217.45	13.8472
1220.68	16.4501
1223.91	19.9406
1227.13	22.9187
1230.36	25.7343
1233.58	27.1741
1236.8	29.2174
1240.02	29.9471
1243.24	30.5537
1246.46	31.2012
1249.67	31.5733
1252.89	31.7199
1256.1	31.8095
1259.32	32.6588
1262.53	32.5208
1265.74	30.9191
1268.95	31.6168
1272.15	30.4447
1275.36	30.2003
1278.57	31.3051
1281.77	31.865
1284.97	32.2907
1288.18	33.5552
1291.38	35.6848
1294.58	38.4368
1297.78	41.6325
1300.97	43.5316
1304.17	45.9647
1307.36	47.2713
1310.55	48.7943
1313.75	49.0605
1316.94	50.4973
1320.13	51.1481
1323.32	51.208
1326.5	51.9298
1329.69	51.26
1332.87	51.6507
1336.06	51.8471
1339.24	51.4105
1342.42	49.7109
1345.6	48.5653
1348.78	47.1742
1351.96	46.0036
1355.13	45.3176
1358.31	44.5783
1361.48	42.8201
1364.65	41.4668
1367.82	41.0207
1370.99	39.9881
1374.16	38.6559
1377.33	38.0264
1380.5	38.6011
1383.66	38.7007
1386.83	37.4973
1389.99	36.2733
1393.15	35.2651
1396.31	34.4915
1399.47	33.4489
1402.63	33.5222
1405.78	32.3423
1408.94	32.3741
1412.1	33.9463
1415.25	34.3746
1418.4	35.659
1421.55	36.6951
1424.7	39.6873
1427.85	40.6594
1431	43.5247
1434.14	44.7469
1437.29	45.5169
1440.43	46.8042
1443.57	47.9334
1446.71	48.8019
1449.85	48.4028
1452.99	49.192
1456.13	49.4245
1459.26	49.4843
1462.4	46.2488
1465.54	43.1828
1468.67	38.9095
1471.8	35.9429
1474.93	33.3058
1478.06	30.2085
1481.19	27.7162
1484.31	23.8584
1487.44	22.2579
1490.56	19.6085
1493.69	19.3926
1496.81	18.0342
1499.93	16.3533
1503.05	16.3533
1506.17	15.0515
1509.28	15.1754
1512.4	15.3611
1515.52	16.9094
1518.63	18.9964
1521.74	19.5381
1524.85	20.2566
1527.96	21.8141
1531.07	23.9624
1534.18	25.7796
1537.29	25.6521
1540.39	26.2017
1543.5	27.6156
1546.6	29.3752
1549.7	32.3257
1552.8	35.3811
1555.9	36.1795
1559	36.519
1562.1	37.4064
1565.19	39.4295
1568.29	40.7236
1571.38	43.2124
1574.47	44.4035
1577.56	46.3731
1580.66	47.6722
1583.74	49.944
1586.83	51.381
1589.92	52.1362
1593.01	52.7304
1596.09	51.9863
1599.17	52.96
1602.25	53.1226
1605.34	53.0102
1608.41	53.062
1611.49	51.0122
1614.57	48.7442
1617.65	48.837
1620.72	47.4291
1623.79	45.6725
1626.87	44.7957
1629.94	43.9876
1633.01	42.6771
1636.08	42.7703
1639.15	43.5062
1642.21	44.8064
1645.28	44.7724
1648.34	45.2272
1651.41	44.4471
1654.47	43.5159
1657.53	42.519
1660.59	42.2352
1663.65	41.1117
1666.71	40.4776
1669.76	40.325
1672.82	40.126
1675.87	37.1944
1678.93	35.8063
1681.98	32.4656
1685.03	29.0949
1688.08	26.3276
1691.13	23.7693
1694.17	20.0927
1697.22	17.1584
1700.27	14.3411
1703.31	11.369
1706.35	10.424
1709.39	9.56541
1712.43	9.63934
1715.47	8.0577
1718.51	5.42862
1721.55	4.45717
1724.58	4.23097
1727.62	3.27431
1730.65	3.59735
1733.68	4.20254
1736.72	4.70163
1739.74	4.17099
1742.77	4.78826
1745.8	3.72324
1748.83	3.53175
1751.85	3.06023
1754.88	4.23734
1757.9	3.95978
1760.92	3.30739
1763.95	3.45932
1766.96	2.7799
1769.98	2.29874
1773	2.70264
1776.02	2.79411
1779.03	3.31486
1782.05	4.1103
1785.06	5.03354
1788.07	4.06316
1791.08	4.3368
1794.09	4.43249
1797.1	5.77066
1800.11	5.804
1803.12	5.35559
1806.12	5.34306
1809.12	5.27289
1812.13	4.5111
1815.13	3.57994
1818.13	3.21948
1821.13	3.21124
1824.13	3.01729
1827.13	2.89136
1830.12	2.56843
1833.12	2.43581
1836.11	2.34093
1839.1	2.94527
1842.09	3.37109
1845.09	3.88883
1848.08	3.69568
1851.06	3.9547
1854.05	3.86196
1857.04	3.90317
1860.02	4.58669
1863.01	4.71553
1865.99	5.22501
1868.97	5.00808
1871.95	4.21623
1874.93	3.6948
1877.91	3.57133
1880.89	3.51679
1882.46	2.23913
1885.45	1.8958
1888.43	1.66407
1891.42	0.97541
1894.41	0.397339
1897.39	0.878763
1900.37	1.2269
1903.36	1.35669
1906.34	2.25889
1909.32	2.2051
1912.29	2.92019
1915.27	2.28299
1918.25	2.9246
1921.23	2.71528
1924.2	2.85052
1927.17	3.49715
1930.15	4.37362
1933.12	5.2629
1936.09	4.49604
1939.06	3.33774
1942.02	2.95909
1944.99	2.25697
1947.96	2.56771
1950.92	3.29769
1953.88	3.1331
1956.85	2.83085
1959.81	2.71075
1962.77	2.61896
1965.73	2.73984
1968.69	3.3005
1971.64	3.94484
1974.6	3.36469
1977.55	4.89424
1980.51	5.21565
1983.46	6.20015
1986.41	7.53185
1989.36	6.94507
1992.31	7.37332
1995.26	6.98437
1998.21	7.85949
2001.15	7.73831
2004.1	7.16352
2007.04	6.33729
2009.99	5.73875
2012.93	5.63168
2015.87	6.43877
2018.81	6.16843
2021.75	6.3406
2024.68	5.42584
2027.62	3.41453
2030.56	2.82964
2033.49	1.61802
2036.42	1.43702
2039.36	1.56506
2042.29	2.25648
2045.22	2.82891
2048.14	4.62687
2051.07	5.70565
2054	6.28148
2056.93	7.06375
2059.85	7.24981
2062.77	7.34545
2065.7	7.69593
2068.62	7.74163
2071.54	8.51655
2074.46	8.06569
2077.38	8.84589
2080.29	9.40376
2083.21	10.5737
2086.12	10.8111
2089.04	11.5946
2091.95	10.5492
2094.86	10.5839
2097.77	10.2668
2100.68	10.9804
2103.59	12.1026
2106.5	12.3535
2109.41	13.6905
2112.31	14.1647
2115.21	15.3991
2118.12	16.0389
2121.02	16.4365
2123.92	16.9476
2126.82	17.0882
2129.72	17.521
2132.62	18.3851
2135.51	19.4408
2138.41	21.0255
2141.31	21.7831
2144.2	22.4835
2147.09	23.855
2149.98	24.8186
2152.87	26.1546
2155.76	27.3649
2158.65	28.0176
2161.54	28.5863
2164.43	28.6239
2167.31	29.4843
2170.2	29.4624
2173.08	29.2087
2175.96	28.455
2178.84	27.5323
2181.72	27.6248
2184.6	26.5682
2187.48	26.4527
2190.36	26.0429
2193.23	25.4498
2196.11	25.021
2198.98	24.3396
2201.85	23.6233
2204.72	22.74
2207.59	22.1858
2210.46	20.6796
2213.33	19.2931
2216.2	17.7651
2219.07	16.6356
2221.93	16.1274
2224.8	15.05
2227.66	14.3628
2230.52	12.9482
2233.39	11.7778
2236.25	11.6063
2239.1	10.682
2241.96	9.1132
2244.82	9.19624
2247.68	9.11956
2250.53	9.21309
2253.38	9.63173
2256.24	9.85241
2259.09	10.2574
2261.94	11.0404
2264.79	11.5098
2267.64	11.0425
2270.49	10.2571
2273.33	9.69234
2276.18	9.1045
2279.02	8.71246
2281.87	8.36236
2284.71	8.67067
2287.55	7.50248
2290.39	6.9737
2293.23	5.76518
2296.07	5.62728
2298.91	6.05363
2301.74	5.88411
2304.58	6.10958
2307.41	5.65612
2310.25	5.02276
2313.08	4.503
2315.91	4.60477
2318.74	3.668
2321.57	3.31469
2324.4	3.45326
2327.23	4.01871
2330.05	3.89582
2332.88	4.65911
2335.7	5.15556
2338.52	3.8083
2341.35	3.85566
2344.17	4.38271
2346.99	4.55912
2349.81	5.65106
2352.62	5.99584
2355.44	5.37429
2358.26	4.50581
2361.07	4.54257
2363.89	5.37432
2366.7	6.32797
2369.51	6.52044
2372.32	7.31426
2375.13	6.13425
2377.94	5.35319
2380.75	4.38106
2383.56	3.32999
2386.36	3.1848
2389.17	3.23634
2391.97	3.35704
2394.77	3.56688
2397.58	3.67013
2400.38	4.11466
2403.18	3.70853
2405.97	3.51925
2408.77	4.02037
2411.57	4.88852
2414.37	4.72904
2417.16	4.93166
2419.95	4.95554
2422.75	4.63331
2425.54	5.23831
2428.33	6.72368
2431.12	7.80509
2433.91	8.59932
2436.7	9.27255
2439.48	10.4819
2442.27	10.1009
2445.05	9.15892
2447.84	8.76893
2450.62	8.94032
2453.4	9.53698
2456.18	9.47962
2458.96	9.11809
2461.74	8.04757
2464.52	8.09548
2467.29	7.01782
2470.07	6.08101
2472.85	5.68181
2475.62	5.45686
2478.39	5.35348
2481.16	4.68961
2483.93	3.86963
2486.7	3.1943
2489.47	3.02825
2492.24	2.93269
2495.01	3.18286
2497.77	2.60535
2500.54	2.3637
2503.3	2.8126
2506.06	1.98981
2508.83	1.59142
2511.59	1.38918
2514.35	0.889503
2517.11	1.78472
2519.86	2.20482
2522.62	1.58666
2525.38	1.46324
2528.13	1.46126
2530.89	1.95502
2533.64	2.43294
2536.39	2.74017
2539.14	3.42053
2541.89	4.618
2544.64	5.12319
2547.39	6.01995
2550.14	6.06746
2552.88	6.28602
2555.63	7.23251
2558.37	7.10843
2561.11	7.47979
2563.86	7.13853
2566.6	6.46614
2569.34	7.22052
2572.08	6.78939
2574.82	5.91166
2577.55	6.06591
2580.29	5.52743
2583.02	5.15624
2585.76	4.50078
2588.49	3.77869
2591.22	3.25024
2593.96	3.74233
2596.69	3.23517
2599.42	2.55009
2602.14	1.56863
2604.87	1.34658
2607.6	0.899679
2610.32	1.37658
2613.05	1.36724
2615.77	1.62929
2618.49	2.1297
2621.22	2.73502
2623.94	3.1177
2626.66	3.06948
2629.37	3.3122
2632.09	2.60934
2634.81	2.85097
2637.53	3.41879
2640.24	2.66203
2642.96	2.69533
2645.67	3.29867
2648.38	3.37474
2651.09	3.96649
2653.8	4.47165
2656.51	4.74673
2659.22	4.7963
2661.93	4.9132
2664.63	4.3903
2667.34	4.34942
2670.04	4.69404
2672.75	4.48737
2675.45	4.57843
2678.15	5.30701
2680.85	5.6184
2683.55	7.119
2686.25	7.98341
2688.94	7.96801
2691.64	7.71177
2694.34	7.53584
2697.03	7.58142
2699.73	6.91413
2702.42	7.62715
2705.11	7.16845
2707.8	7.24933
2710.49	7.26447
2713.18	7.2787
2715.87	6.40524
2718.55	7.22006
2721.24	6.51797
2723.93	6.82774
2726.61	6.14095
2729.29	6.79314
2731.98	6.29743
2734.66	6.09557
2737.34	5.64347
2740.02	5.98498
2742.7	6.03256
2745.37	6.49833
2748.05	6.96133
2750.72	7.37497
2753.4	7.06918
2756.07	6.50292
2758.75	6.27059
2761.42	5.99316
2764.09	5.44273
2766.76	5.94751
2769.43	5.547
2772.1	4.92732
2774.76	4.8595
2777.43	4.54965
2780.1	4.47798
2782.76	4.69782
2785.42	5.11428
2788.09	4.45727
2790.75	4.17168
2793.41	4.46826
2796.07	3.5057
2798.73	3.17104
2801.39	3.134
2804.04	3.09596
2806.7	3.28112
2809.35	3.83191
2812.01	3.25958
2814.66	3.67098
2817.31	3.48464
2819.96	3.81403
2822.61	4.21786
2825.26	5.7356
2827.91	8.17028
2830.56	9.97265
2833.21	12.7078
2835.85	14.9718
2838.5	17.2479
2841.14	20.7459
2843.78	24.018
2846.42	27.9169
2849.06	31.4615
2851.71	35.726
2854.34	39.5099
2856.98	44.2941
2859.62	48.0651
2862.26	51.9209
2864.89	56.7788
2867.53	60.7635
2870.16	64.2347
2872.79	67.0326
2875.42	69.2997
2878.05	71.7974
2880.68	74.6934
2883.31	77.1374
2885.94	79.1576
2888.57	81.2851
2891.19	83.1475
2893.82	85.9344
2896.44	88.0855
2899.07	90.1837
2901.69	93.1734
2904.31	96.3944
2906.93	100.412
2909.55	103.705
2912.17	107.207
2914.79	111.214
2917.41	114.866
2920.02	117.933
2922.64	121.269
2925.25	122.489
2927.86	123.806
2930.48	124.071
2933.09	123.337
2935.7	121.395
2938.31	119.43
2940.92	116.558
2943.53	113.547
2946.13	108.627
2948.74	104.05
2951.34	98.9603
2953.95	94.0011
2956.55	89.6046
2959.15	85.6626
2961.75	81.5986
2964.35	76.8456
2966.95	73.065
2969.55	69.3813
2972.15	65.379
2974.75	61.6898
2977.34	58.2407
2979.94	55.4411
2982.53	51.9133
2985.13	48.5205
2987.72	43.9312
2990.31	40.1782
2992.9	36.5876
2995.49	32.7872
2998.08	29.0501
3000.67	25.2334
3003.25	20.7996
3005.84	17.1154
3008.42	13.8705
3011.01	11.1483
3013.59	8.93286
3016.17	6.68799
3018.76	5.05962
3021.34	3.78847
3023.92	2.37693
3026.49	1.06332
3029.07	0.217968
3031.65	1.16818
3034.23	1.5387
3036.8	2.65308
3039.38	3.03692
3041.95	3.89005
3044.52	4.58957
3047.09	5.48717
3049.66	6.09735
3052.23	6.60846
3054.8	6.58824
3057.37	6.83352
3059.94	7.30875
3062.5	6.85054
3065.07	5.97188
3067.63	6.12239
3070.2	5.66907
3072.76	5.29669
3075.32	4.87707
3077.88	4.638
3080.44	3.76987
3083	3.65183
3085.56	2.89119
3088.12	2.13547
3090.67	1.52235
3093.23	0.958837
3095.78	1.69983
3098.34	2.11828
3100.89	2.07978
3103.44	2.17531
3105.99	2.90501
3108.54	3.75954
3111.09	4.01983
3113.64	4.50235
3116.19	4.62262
3118.74	5.65579
3121.28	6.94398
3123.83	7.29782
3126.37	7.70453
3128.91	8.26304
3131.46	8.82398
3134	10.2555
3136.54	11.284
3139.08	12.2348
3141.62	12.6226
3144.16	12.8889
3146.69	13.3593
3149.23	15.6266