File: data/Raman/poly_smoothed/Thy_50_12_26_1x_45s_532 nm_x100_100%_600 gr_mm_01.txt
#Acq. time (s)=	45
#Accumulations=	2
#Range (cm-¹)=	200...3150
#Windows=	2
#Auto scanning=	Off
#Autofocus=	Off
#Macrospot=	Off
#AutoExposure=	Off
#Spike filter=	Multiple accum.
#Delay time (s)=	0
#Binning=	1
#Readout mode=	Signal
#DeNoise=	Off
#ICS correction=	On
#Dark correction=	Off
#Inst. Process=	Off
#Detector Gain=	Best Dynamic Range
#Detector ADC=	20 kHz
#Detector temperature (°C)=	-69.85
#Instrument=	LabRAM HR Evol
#Detector=	Synapse
#Objective=	x100
#Grating=	600 gr/mm
#ND Filter=	100%
#Laser (nm)=	532
#Hole=	100.021
#Range=	Auto
#Laser Pol.=	No
#Raman. Pol.=	No
#Laser Pol. (°)=	-0.0007625
#Raman Pol. (°)=	89.9995
#Collection=	Microscope
#StageXY=	Marzhauser
#StageZ=	Marzhauser
#X (µm)=	-5139.2
#Y (µm)=	1495.3
#Z (µm)=	63.2
#Full time(mm:ss)=	3:18
#Project=
#Sample=
#Site=
#Title=	Thy_50_12_26_2x_45s_532 nm_x100_100%_600 gr_mm
#Remark=
#Date=	07.07.2022 11:08
#Acquired=	07.07.2022 11:08:50
#Base:Fit=	10.08.2022 10:04:29
#Base:Sub=	10.08.2022 10:04:45
#Filter:Polynom=	16.08.2022 10:20:24
#AxisType[0]=Intens
#AxisUnit[0]=Cnt
#AxisType[1]=Spectr
#AxisUnit[1]=1/cm
200.43	8.95046
204.061	12.0028
207.688	12.4602
211.316	11.899
214.941	11.3293
218.566	11.0794
222.188	11.2573
225.809	10.4458
229.43	12.1844
233.047	12.7061
236.663	12.0516
240.278	11.1687
243.894	10.5551
247.506	9.76768
251.116	9.64925
254.725	9.57466
258.333	8.5962
261.939	7.33744
265.546	4.75314
269.15	4.59143
272.752	5.25314
276.353	5.9705
279.952	7.5278
283.55	7.019
287.146	7.78351
290.739	8.33727
294.333	11.2719
297.925	10.5698
301.516	12.4811
305.106	13.6104
308.694	16.5774
312.279	18.1771
315.864	19.626
319.448	21.9509
323.029	22.4002
326.61	23.4948
330.19	25.4553
333.766	27.5933
337.343	28.5247
340.917	26.677
344.491	25.694
348.062	24.5398
351.633	23.4059
355.201	24.3241
358.77	24.3221
362.335	25.0491
365.899	24.0022
369.464	23.7365
373.025	24.4862
376.585	23.0794
380.143	23.0324
383.702	21.44
387.258	19.2463
390.812	17.6337
394.365	16.7256
397.916	15.4355
401.467	13.5337
405.015	14.2305
408.565	16.0521
412.111	16.0923
415.656	15.9776
419.197	14.9851
422.739	13.4876
426.279	12.2125
429.819	13.2277
433.356	15.3615
436.893	14.8445
440.428	16.3882
443.96	19.6684
447.492	20.0668
451.023	20.7855
454.553	22.0048
458.079	21.8369
461.606	25.8853
465.132	27.0339
468.654	28.5193
472.177	29.9399
475.696	33.5029
479.217	35.8829
482.733	37.3591
486.251	38.9004
489.765	40.3622
493.278	41.5706
496.791	40.0032
500.301	38.9724
503.81	38.6864
507.319	37.8415
510.825	39.2667
514.33	40.1847
517.833	41.1067
521.337	42.393
524.838	40.7044
528.337	39.8458
531.835	37.0121
535.332	34.3708
538.827	33.3555
542.321	30.9056
545.814	31.7684
549.305	29.9789
552.795	28.325
556.284	26.7256
559.771	25.7146
563.257	24.6493
566.742	20.0941
570.223	17.2728
573.705	13.7713
577.185	10.1428
580.665	7.17118
584.141	5.77536
587.617	4.31537
591.092	2.95843
594.564	3.97623
598.037	5.31762
601.506	6.9352
604.976	9.10559
608.443	8.89595
611.91	7.41387
615.374	8.75119
618.839	8.31588
622.3	8.92861
625.761	9.82528
629.221	9.38253
632.679	9.73077
636.135	10.3554
639.592	11.5575
643.045	10.177
646.497	11.1147
649.948	10.1393
653.398	7.7782
656.846	7.37411
660.293	5.81064
663.738	6.18905
667.185	6.26361
670.628	6.85231
674.067	6.39249
677.508	7.37059
680.947	11.1937
684.385	12.9249
687.821	15.0768
691.256	17.2699
694.69	18.7133
698.121	22.7019
701.552	24.3408
704.982	26.1457
708.41	29.9825
711.836	32.1044
715.262	35.0958
718.685	38.0439
722.108	41.4605
725.53	41.158
728.949	42.7229
732.369	45.9376
735.785	45.3792
739.2	47.8492
742.616	48.8403
746.028	49.6915
749.441	50.0463
752.851	50.9333
756.26	54.3178
759.667	55.3045
763.075	59.6758
766.479	62.2159
769.883	64.4569
773.285	65.6232
776.686	67.9673
780.085	68.9663
783.484	69.4018
786.881	67.8317
790.276	69.2604
793.671	70.4415
797.064	71.1824
800.456	71.9371
803.846	74.1273
807.236	73.9324
810.624	73.7734
814.01	74.871
817.394	74.1881
820.778	74.4258
824.161	72.6739
827.543	70.6875
830.921	69.5259
834.3	69.4592
837.676	68.2822
841.053	65.504
844.426	62.0616
847.8	59.955
851.171	56.1266
854.542	53.4473
857.911	51.644
861.279	47.2609
864.645	43.9709
868.01	42.653
871.375	41.3973
874.737	41.0843
878.097	39.6616
881.457	39.1802
884.817	38.5289
888.174	38.497
891.53	37.2287
894.884	34.6581
898.237	34.0998
901.589	32.5511
904.94	32.2917
908.289	30.5856
911.637	28.4215
914.984	25.8319
918.33	25.5827
921.674	24.8565
925.015	21.4448
928.357	21.7731
931.698	21.7268
935.037	20.8648
938.373	21.3135
941.71	19.8086
945.046	18.3267
948.378	18.7333
951.711	22.1285
955.043	22.2412
958.372	21.0109
961.701	20.7039
965.027	23.1341
968.354	25.7955
971.678	27.5363
975	27.8345
978.324	29.7966
981.644	28.4538
984.962	29.3032
988.282	30.2513
991.598	30.8408
994.913	31.0985
998.227	33.655
1001.54	33.4713
1004.85	34.4145
1008.16	37.0767
1011.47	39.0515
1014.78	40.4163
1018.08	42.6841
1021.39	42.9017
1024.69	43.3942
1028	44.5652
1031.3	47.2687
1034.6	46.1067
1037.9	43.6529
1041.19	43.9167
1044.49	46.3007
1047.79	45.973
1051.08	45.8145
1054.37	41.75
1057.66	39.3064
1060.95	35.422
1064.24	30.9977
1067.53	27.335
1070.81	25.5974
1074.1	24.1205
1077.38	21.522
1080.66	21.5985
1083.94	21.5351
1087.22	21.5046
1090.5	23.297
1093.78	24.8665
1097.05	26.3752
1100.33	29.2413
1103.6	31.4542
1106.87	31.6763
1110.15	31.8932
1113.41	31.4909
1116.68	29.2902
1119.95	29.8868
1123.21	30.2882
1126.48	28.7058
1129.74	25.9251
1133	24.0194
1136.26	22.5451
1139.52	20.9241
1142.78	19.7786
1146.04	18.6282
1149.29	17.5816
1152.55	17.0313
1155.8	14.1455
1159.05	13.6044
1162.3	11.0528
1165.55	9.84355
1168.8	9.07252
1172.05	11.4823
1175.29	11.5539
1178.54	11.4116
1181.78	11.2781
1185.02	9.66085
1188.26	9.45476
1191.5	9.22168
1194.74	7.97163
1197.97	9.70553
1201.21	11.6558
1204.44	14.4195
1207.68	16.5727
1210.91	21.9369
1214.14	29.0214
1217.37	35.6213
1220.6	41.2284
1223.82	47.9622
1227.05	52.7281
1230.27	58.5379
1233.49	65.3991
1236.72	71.8483
1239.94	79.5858
1243.16	84.7925
1246.37	90.0723
1249.59	96.4478
1252.8	100.945
1256.02	106.309
1259.23	109.1
1262.44	114.208
1265.66	118.695
1268.87	121.808
1272.07	124.174
1275.28	128.212
1278.48	129.709
1281.69	132.503
1284.89	136.352
1288.09	137.123
1291.3	137.907
1294.49	136.261
1297.69	135.749
1300.89	135.419
1304.09	134.807
1307.28	135.397
1310.47	138.666
1313.66	138.528
1316.86	138.83
1320.05	140.252
1323.23	137.253
1326.42	134.106
1329.61	131.57
1332.79	128.715
1335.98	125.522
1339.16	121.171
1342.34	117.688
1345.52	113.771
1348.7	110.46
1351.87	106.369
1355.05	101.956
1358.23	97.8228
1361.4	94.692
1364.57	90.0231
1367.74	84.1053
1370.91	80.1918
1374.08	77.0947
1377.25	76.7085
1380.42	76.5012
1383.58	76.3064
1386.75	76.0095
1389.91	75.4996
1393.07	74.7226
1396.23	76.1309
1399.39	74.5035
1402.55	71.2298
1405.7	70.7138
1408.86	73.0283
1412.01	75.0939
1415.17	78.1644
1418.32	83.5181
1421.47	91.0206
1424.62	98.9872
1427.77	107.97
1430.92	116.902
1434.06	126.794
1437.2	134.515
1440.35	140.741
1443.49	145.249
1446.63	149.212
1449.77	152.192
1452.91	152.169
1456.05	150.909
1459.18	147.408
1462.32	140.612
1465.45	133.324
1468.59	123.079
1471.72	113.203
1474.85	101.797
1477.98	88.0294
1481.11	77.1428
1484.23	65.9595
1487.36	57.6869
1490.48	50.6034
1493.61	45.7785
1496.73	41.1906
1499.85	39.5909
1502.97	37.4765
1506.09	36.8865
1509.2	36.1043
1512.32	36.7617
1515.44	37.8862
1518.55	40.8251
1521.66	43.7596
1524.77	47.8449
1527.88	51.9592
1530.99	56.1234
1534.1	61.5104
1537.21	66.8832
1540.31	74.0742
1543.42	82.8358
1546.52	90.5004
1549.62	99.866
1552.72	107.692
1555.82	114.813
1558.92	122.707
1562.02	128.547
1565.11	134.707
1568.21	140.832
1571.3	145.553
1574.39	149.067
1577.49	152.618
1580.58	154.05
1583.67	154.662
1586.75	152.244
1589.84	151
1592.93	147.148
1596.01	145.244
1599.09	141.328
1602.18	137.579
1605.26	133.019
1608.34	128.829
1611.41	127.316
1614.49	129.203
1617.57	128.992
1620.64	131.365
1623.72	134.192
1626.79	136.622
1629.86	139.582
1632.93	142.983
1636	147.072
1639.07	151.4
1642.14	156.207
1645.2	159.528
1648.27	162.331
1651.33	164.119
1654.39	164.461
1657.45	163.194
1660.51	160.494
1663.57	156.285
1666.63	150.128
1669.69	144.863
1672.74	136.954
1675.79	126.151
1678.85	115.537
1681.9	104.081
1684.95	94.5842
1688	84.846
1691.05	76.6213
1694.1	67.7698
1697.14	59.261
1700.19	52.4328
1703.23	46.1165
1706.27	39.8881
1709.32	35.775
1712.35	32.102
1715.39	28.8048
1718.43	25.8629
1721.47	23.2093
1724.5	22.5227
1727.54	21.8923
1730.57	21.6158
1733.61	21.0573
1736.64	19.3353
1739.67	17.0968
1742.7	15.495
1745.72	13.8345
1748.75	12.2726
1751.78	11.3451
1754.8	10.0454
1757.82	9.46244
1760.85	9.51521
1763.87	8.40757
1766.89	7.028
1769.91	5.74991
1772.92	5.88193
1775.94	5.37778
1778.96	5.22397
1781.97	3.81273
1784.98	4.8782
1788	5.17341
1791.01	4.05015
1794.01	4.07565
1797.02	4.99368
1800.03	5.42195
1803.04	5.04237
1806.04	5.65382
1809.05	5.19688
1812.05	4.75889
1815.05	4.67363
1818.05	4.86148
1821.05	4.68375
1824.05	4.39555
1827.05	3.40047
1830.04	3.57627
1833.04	4.03729
1836.03	3.68225
1839.03	2.84214
1842.02	3.26038
1845.01	3.83175
1848	3.11389
1850.99	2.61971
1853.97	3.50613
1856.96	3.32219
1859.94	2.44314
1862.93	2.28463
1865.91	1.44721
1868.89	1.71506
1871.87	2.13799
1874.85	1.72312
1877.83	1.91653
1880.81	1.993
1882.56	0.500153
1885.55	0.692456
1888.54	0.891798
1891.52	-0.656002
1894.51	-0.612579
1897.49	0.174794
1900.48	0.838064
1903.46	1.50487
1906.44	2.54449
1909.42	3.04502
1912.4	4.03655
1915.38	5.0189
1918.35	6.38031
1921.33	5.72884
1924.3	6.73064
1927.28	6.49983
1930.25	6.4891
1933.22	6.99558
1936.19	7.34073
1939.16	8.35009
1942.13	8.97834
1945.09	8.57606
1948.06	7.60184
1951.03	6.8119
1953.99	6.72019
1956.95	7.1526
1959.91	7.93502
1962.87	6.91644
1965.83	6.98518
1968.79	8.92686
1971.75	9.75415
1974.7	9.10267
1977.66	8.99777
1980.61	8.10765
1983.56	7.96345
1986.52	8.0909
1989.47	7.29779
1992.41	6.46728
1995.36	5.3342
1998.31	4.97062
2001.26	5.5647
2004.2	4.8459
2007.15	4.49427
2010.09	6.19723
2013.03	6.80877
2015.97	6.31756
2018.91	6.10334
2021.85	6.67992
2024.79	7.81824
2027.72	9.07713
2030.66	10.6553
2033.59	12.166
2036.53	13.6814
2039.46	16.2616
2042.39	18.9418
2045.32	19.9062
2048.25	20.4497
2051.18	22.4093
2054.1	23.922
2057.03	26.0996
2059.95	27.4839
2062.88	29.5995
2065.8	31.0023
2068.72	33.992
2071.64	36.9073
2074.56	39.2786
2077.48	42.1819
2080.39	45.9314
2083.31	48.4008
2086.22	50.3139
2089.14	53.2989
2092.05	58.1122
2094.96	61.4683
2097.87	66.1673
2100.78	71.8567
2103.69	78.4613
2106.6	83.809
2109.51	89.4662
2112.41	95.3426
2115.32	101.764
2118.22	108.208
2121.12	115.38
2124.02	122.781
2126.92	130.309
2129.82	138.129
2132.72	146.78
2135.62	154.841
2138.51	162.947
2141.41	169.196
2144.3	175.67
2147.19	181.295
2150.09	187.541
2152.97	192.496
2155.86	198.761
2158.75	202.882
2161.64	206.893
2164.53	209.384
2167.41	209.285
2170.3	209.724
2173.18	209.629
2176.06	206.588
2178.94	201.829
2181.82	196.459
2184.7	192.113
2187.58	186.664
2190.46	180.919
2193.33	174.901
2196.21	169.38
2199.08	162.203
2201.95	155.73
2204.83	147.585
2207.7	139.238
2210.57	131.373
2213.43	124.154
2216.3	117.888
2219.17	112.797
2222.03	108.539
2224.9	103.248
2227.76	97.5917
2230.62	90.9292
2233.49	86.0152
2236.34	78.5837
2239.2	73.1969
2242.06	68.2662
2244.92	64.0629
2247.78	59.5829
2250.63	54.5761
2253.48	52.0155
2256.34	49.7018
2259.19	46.5445
2262.04	44.4209
2264.89	41.8305
2267.74	38.6197
2270.59	36.507
2273.43	34.0848
2276.28	32.7345
2279.12	30.6793
2281.97	29.7093
2284.81	29.5448
2287.65	29.2539
2290.49	27.6927
2293.33	25.4806
2296.17	24.307
2299.01	22.8914
2301.84	21.7148
2304.68	20.9506
2307.51	20.5934
2310.35	19.8842
2313.18	19.1724
2316.01	18.0497
2318.84	16.7667
2321.67	16.6219
2324.5	15.7977
2327.33	13.1677
2330.15	12.4496
2332.98	11.7048
2335.8	10.5217
2338.62	9.87813
2341.45	8.96943
2344.27	8.57163
2347.09	7.47083
2349.91	5.56273
2352.72	4.41904
2355.54	2.77839
2358.36	1.91053
2361.17	1.08979
2363.98	1.63366
2366.8	1.60231
2369.61	0.393136
2372.42	0.759411
2375.23	0.145016
2378.04	0.34692
2380.85	0.251802
2383.66	0.466612
2386.46	1.52987
2389.26	2.61199
2392.07	2.60447
2394.87	2.79943
2397.67	4.66554
2400.47	5.48421
2403.27	5.77556
2406.07	6.54511
2408.87	6.75665
2411.67	7.71787
2414.46	8.92384
2417.26	9.42876
2420.05	8.88329
2422.84	9.30539
2425.64	8.40205
2428.43	9.21274
2431.22	8.88448
2434.01	7.666
2436.79	6.48188
2439.58	6.11268
2442.37	5.49868
2445.15	4.87405
2447.93	4.19377
2450.72	4.41795
2453.5	3.94281
2456.28	4.61373
2459.06	3.83245
2461.84	4.65642
2464.62	4.51152
2467.39	4.13723
2470.17	3.96055
2472.94	4.15048
2475.72	4.53021
2478.49	4.94616
2481.26	5.57061
2484.03	4.89069
2486.8	4.67536
2489.57	3.56117
2492.34	2.06184
2495.1	1.79906
2497.87	1.07378
2500.63	0.771319
2503.4	-0.608633
2506.16	0.0472291
2508.92	-0.699509
2511.68	-0.244226
2514.44	-0.178389
2517.2	0.458725
2519.96	0.618867
2522.72	0.42115
2525.47	0.7811
2528.23	0.71029
2530.98	1.3215
2533.74	2.03928
2536.49	1.94138
2539.24	3.34114
2541.99	3.37328
2544.74	3.69831
2547.49	4.07064
2550.23	4.53968
2552.98	4.76991
2555.72	4.032
2558.47	4.0329
2561.21	4.71848
2563.95	4.67534
2566.69	4.50136
2569.43	4.33275
2572.17	4.19169
2574.91	5.53051
2577.65	5.70979
2580.39	6.03478
2583.12	5.73285
2585.85	4.71867
2588.59	3.75782
2591.32	3.06245
2594.05	2.74527
2596.78	2.64061
2599.51	1.97372
2602.24	1.40109
2604.97	1.25785
2607.69	1.00643
2610.42	0.34046
2613.14	0.648073
2615.87	0.0689514
2618.59	1.09294
2621.31	1.33018
2624.03	1.14954
2626.75	2.08776
2629.47	2.65749
2632.19	2.46975
2634.91	3.99518
2637.62	4.58319
2640.34	5.1413
2643.05	4.83005
2645.76	4.61104
2648.48	5.00771
2651.19	4.86985
2653.9	4.20161
2656.6	3.85923
2659.31	3.69702
2662.02	3.59939
2664.73	4.33919
2667.43	4.16448
2670.14	4.84326
2672.84	5.28966
2675.54	5.04451
2678.24	4.89031
2680.94	6.63174
2683.64	7.61376
2686.34	7.80345
2689.04	8.00974
2691.74	8.71421
2694.43	8.50172
2697.13	9.64674
2699.82	10.2265
2702.51	10.7322
2705.21	10.8319
2707.9	11.2205
2710.58	11.7458
2713.27	12.1823
2715.96	12.4303
2718.65	11.9786
2721.33	12.2455
2724.02	13.6415
2726.71	14.9487
2729.39	16.122
2732.07	16.4127
2734.75	17.4845
2737.43	17.7224
2740.11	17.5061
2742.79	16.8625
2745.47	16.6845
2748.14	16.1373
2750.82	15.2026
2753.49	14.7236
2756.17	13.1529
2758.84	11.2397
2761.51	9.86705
2764.18	9.11393
2766.85	8.09846
2769.52	7.19511
2772.19	6.05074
2774.86	3.78802
2777.52	2.38732
2780.19	0.743431
2782.85	0.126043
2785.52	-1.23491
2788.18	-0.178186
2790.84	-0.157272
2793.5	-1.08583
2796.16	-1.03722
2798.82	0.0760561
2801.48	-0.0490999
2804.13	-0.90014
2806.79	-1.75274
2809.45	-1.78644
2812.1	-1.35578
2814.75	-0.56884
2817.41	1.89601
2820.06	6.60942
2822.71	11.8016
2825.36	19.7039
2828	28.9386
2830.65	38.0051
2833.3	46.2606
2835.94	56.0823
2838.59	65.813
2841.23	76.2919
2843.87	87.7625
2846.52	100.513
2849.16	113.36
2851.8	128.371
2854.44	144.261
2857.08	159.239
2859.71	174.117
2862.35	187.866
2864.98	199.012
2867.62	208.433
2870.25	218.965
2872.88	227.536
2875.52	234.683
2878.15	241.597
2880.78	249.574
2883.41	258.351
2886.03	266.847
2888.66	274.763
2891.29	282.598
2893.91	291.096
2896.54	298.347
2899.16	308.363
2901.78	320.034
2904.4	333.72
2907.02	349.597
2909.64	367.188
2912.26	385.303
2914.88	404.662
2917.5	424.479
2920.11	440.257
2922.73	453.557
2925.34	462.894
2927.96	470.331
2930.57	473.729
2933.18	474.546
2935.79	470.96
2938.4	462.999
2941.01	453.592
2943.62	441.938
2946.22	428.208
2948.83	411.93
2951.43	394.606
2954.04	375.086
2956.64	356.198
2959.24	338.047
2961.84	317.51
2964.45	301.038
2967.05	283.547
2969.64	267.391
2972.24	252.368
2974.84	237.677
2977.43	223.068
2980.03	207.998
2982.62	192.503
2985.22	175.877
2987.81	160.294
2990.4	145.832
2992.99	131.072
2995.58	116.754
2998.17	103.459
3000.76	90.4691
3003.34	78.4715
3005.93	68.1946
3008.52	57.8853
3011.1	48.7814
3013.68	41.2659
3016.27	34.6517
3018.85	29.4
3021.43	24.1204
3024.01	19.4484
3026.59	16.3953
3029.16	15.3204
3031.74	15.5813
3034.32	15.6947
3036.89	17.1134
3039.47	18.4357
3042.04	20.1923
3044.61	22.0961
3047.18	24.413
3049.75	25.8039
3052.32	26.9549
3054.89	28.5768
3057.46	28.1725
3060.03	28.3817
3062.59	28.1286
3065.16	27.3301
3067.72	25.2297
3070.29	23.4614
3072.85	21.5342
3075.41	19.3896
3077.97	16.1278
3080.53	13.7714
3083.09	10.3912
3085.65	6.92527
3088.21	3.65706
3090.76	2.28834
3093.32	0.927381
3095.87	-0.227591
3098.43	-1.09688
3100.98	-0.253265
3103.53	0.564698
3106.08	2.0818
3108.63	3.76969
3111.18	5.63474
3113.73	7.19786
3116.28	10.5509
3118.83	12.0394
3121.37	14.5828
3123.92	17.4049
3126.46	19.6053
3129	21.5194
3131.55	24.1745
3134.09	27.0344
3136.63	28.4622
3139.17	29.2956
3141.71	29.8765
3144.24	29.4863
3146.78	28.8939
3149.32	27.522