File: data/Raman/poly_smoothed/Thy_30_10_17_1x_45s_532 nm_x100_100%_600 gr_mm_01.txt
#Acq. time (s)=	45
#Accumulations=	2
#Range (cm-¹)=	200...3150
#Windows=	2
#Auto scanning=	Off
#Autofocus=	Off
#Macrospot=	Off
#AutoExposure=	Off
#Spike filter=	Multiple accum.
#Delay time (s)=	0
#Binning=	1
#Readout mode=	Signal
#DeNoise=	Off
#ICS correction=	On
#Dark correction=	Off
#Inst. Process=	Off
#Detector Gain=	Best Dynamic Range
#Detector ADC=	20 kHz
#Detector temperature (°C)=	-69.85
#Instrument=	LabRAM HR Evol
#Detector=	Synapse
#Objective=	x100
#Grating=	600 gr/mm
#ND Filter=	100%
#Laser (nm)=	532
#Hole=	100.021
#Range=	Auto
#Laser Pol.=	No
#Raman. Pol.=	No
#Laser Pol. (°)=	-0.0007625
#Raman Pol. (°)=	89.9995
#Collection=	Microscope
#StageXY=	Marzhauser
#StageZ=	Marzhauser
#X (µm)=	4755.3
#Y (µm)=	-7726.3
#Z (µm)=	584.35
#Full time(mm:ss)=	3:18
#Project=
#Sample=
#Site=
#Title=	Thy_30_10_17_2x_45s_532 nm_x100_100%_600 gr_mm
#Remark=
#Date=	30.06.2022 12:40
#Acquired=	30.06.2022 12:40:31
#Base:Fit=	10.08.2022 09:58:11
#Base:Sub=	10.08.2022 09:58:44
#Filter:Polynom=	16.08.2022 10:22:53
#AxisType[0]=Intens
#AxisUnit[0]=Cnt
#AxisType[1]=Spectr
#AxisUnit[1]=1/cm
200.533	5.20856
204.162	3.32353
207.792	3.2803
211.418	4.8474
215.044	5.81992
218.667	7.91248
222.289	7.4035
225.912	8.23331
229.531	9.16005
233.148	10.1222
236.766	10.6877
240.381	10.5687
243.994	11.6121
247.606	13.4152
251.217	14.6369
254.828	16.5241
258.436	16.6183
262.042	15.875
265.647	15.097
269.25	13.6068
272.852	13.1927
276.453	13.6678
280.052	13.1718
283.65	13.609
287.247	14.6871
290.842	15.5803
294.436	16.6932
298.028	18.311
301.617	18.0995
305.206	18.8268
308.794	19.8892
312.381	19.5621
315.964	21.3874
319.548	22.2144
323.131	22.9857
326.71	23.9818
330.29	24.4934
333.868	25.7913
337.443	25.5043
341.018	25.4749
344.591	24.4178
348.163	22.7111
351.733	22.29
355.303	21.7656
358.869	21.3256
362.435	21.6357
366.001	20.3992
369.563	19.4872
373.124	19.7725
376.686	20.3288
380.244	19.3396
383.801	18.4918
387.357	17.5494
390.911	16.4509
394.466	15.2651
398.018	13.3292
401.568	12.2783
405.117	12.9894
408.664	12.8113
412.21	12.8604
415.755	12.607
419.298	12.1644
422.84	12.5583
426.38	11.8682
429.919	11.7584
433.455	11.5894
436.992	12.1203
440.527	11.2747
444.06	11.6612
447.593	11.3834
451.122	11.3729
454.651	11.9285
458.18	13.7269
461.705	14.0025
465.23	14.5853
468.752	13.571
472.275	14.391
475.797	14.8036
479.315	13.9821
482.834	14.5448
486.349	17.7946
489.863	18.8164
493.378	18.8556
496.889	19.3871
500.401	20.7767
503.91	20.97
507.417	20.2125
510.923	20.8343
514.43	20.6445
517.933	20.2697
521.435	19.54
524.936	18.4174
528.435	18.869
531.933	17.8324
535.43	17.4252
538.927	17.0947
542.421	16.1254
545.913	15.5089
549.403	12.4546
552.893	11.771
556.381	10.0821
559.868	9.7875
563.354	7.63911
566.839	6.61111
570.322	5.8
573.802	3.35938
577.283	2.27115
580.762	1.19152
584.24	1.94314
587.714	1.38989
591.19	-0.384465
594.663	0.295236
598.134	1.2216
601.605	1.57679
605.073	2.30203
608.542	3.94712
612.007	5.20491
615.473	6.33957
618.936	6.72971
622.397	7.69187
625.859	8.72091
629.318	8.92442
632.775	9.80011
636.233	11.7272
639.688	13.4316
643.142	13.7754
646.594	15.4751
650.045	15.6146
653.496	16.8514
656.944	17.4955
660.391	19.5081
663.837	20.964
667.281	21.8785
670.724	22.7794
674.166	23.4745
677.606	24.6782
681.045	26.3017
684.483	28.0881
687.917	27.1323
691.352	28.9401
694.786	29.7898
698.219	30.089
701.65	30.9878
705.078	32.2156
708.506	34.2096
711.934	35.4247
715.358	36.5122
718.782	38.3069
722.204	38.9861
725.626	40.22
729.045	41.2964
732.464	42.3165
735.881	44.0082
739.297	47.5231
742.711	48.1465
746.125	49.5929
749.537	50.1065
752.946	51.499
756.357	53.114
759.764	55.0494
763.17	57.755
766.575	60.2653
769.978	59.8068
773.382	61.1343
776.783	64.0867
780.182	66.2207
783.581	68.6443
786.978	71.2238
790.373	72.6572
793.768	73.6109
797.161	75.3062
800.552	74.9082
803.941	74.9874
807.33	75.8718
810.718	75.0281
814.105	75.8607
817.49	75.8835
820.873	75.7839
824.256	74.3929
827.637	72.4489
831.016	70.6993
834.395	68.4706
837.772	67.5928
841.147	67.1877
844.522	65.2613
847.894	64.5279
851.267	61.6001
854.637	59.6477
858.007	59.3947
861.374	56.8774
864.739	56.0634
868.106	54.7649
871.469	52.3235
874.831	51.1523
878.193	50.5669
881.553	49.5829
884.911	46.9647
888.268	46.3978
891.623	45.344
894.978	45.2292
898.331	43.5387
901.683	42.7216
905.033	40.9566
908.383	41.507
911.731	40.1004
915.078	41.2484
918.423	41.7219
921.768	42.3275
925.111	40.1984
928.452	40.1682
931.791	38.3398
935.13	36.7707
938.468	36.5258
941.803	35.1119
945.139	33.6382
948.473	33.4866
951.804	33.4551
955.136	34.3735
958.465	33.0752
961.794	31.4661
965.12	31.4433
968.447	31.9737
971.771	30.9009
975.095	30.4484
978.417	30.6658
981.737	31.8187
985.057	32.5189
988.375	32.0584
991.691	31.8314
995.006	32.7658
998.32	33.2148
1001.63	31.8812
1004.95	29.6869
1008.26	30.5029
1011.56	30.5127
1014.87	29.6296
1018.18	28.8038
1021.48	27.6368
1024.79	27.4864
1028.09	26.9958
1031.39	27.1693
1034.69	26.553
1037.99	25.3579
1041.29	22.5679
1044.58	22.0309
1047.88	22.4566
1051.17	20.1176
1054.46	18.9725
1057.75	15.5531
1061.04	13.2884
1064.33	10.7484
1067.62	7.58095
1070.9	6.07259
1074.19	5.42576
1077.47	4.66342
1080.76	4.52074
1084.04	4.71625
1087.32	3.27122
1090.59	4.64906
1093.87	6.44256
1097.15	8.37615
1100.42	10.6412
1103.69	12.7829
1106.97	15.3776
1110.24	16.8554
1113.51	20.4305
1116.77	21.6702
1120.04	22.7198
1123.31	22.2198
1126.57	21.3096
1129.83	20.271
1133.1	18.8035
1136.36	17.693
1139.62	16.4468
1142.87	14.7181
1146.13	13.8659
1149.38	11.9001
1152.64	11.116
1155.89	10.436
1159.14	8.08905
1162.39	6.92202
1165.64	3.88348
1168.89	4.33743
1172.14	6.29091
1175.38	6.03648
1178.63	6.7899
1181.87	8.79442
1185.11	9.78344
1188.35	10.6627
1191.59	11.7322
1194.83	13.3972
1198.07	12.9556
1201.3	12.7082
1204.53	14.3179
1207.77	15.6661
1211	18.7675
1214.23	20.0972
1217.46	22.1867
1220.69	23.9898
1223.91	26.591
1227.14	28.6336
1230.36	28.2174
1233.59	30.3797
1236.81	31.2969
1240.03	30.8017
1243.25	31.3969
1246.46	31.9852
1249.68	34.2444
1252.9	37.2294
1256.11	38.6998
1259.32	40.2495
1262.54	41.497
1265.75	40.6676
1268.96	40.9928
1272.16	40.5436
1275.37	40.9037
1278.57	41.7751
1281.78	44.3522
1284.98	47.2095
1288.18	49.0018
1291.38	49.31
1294.58	50.3413
1297.78	50.95
1300.98	51.6462
1304.17	50.8905
1307.37	50.4404
1310.56	51.3413
1313.76	52.5979
1316.95	52.7917
1320.14	52.8611
1323.32	54.4214
1326.51	55.1608
1329.7	56.0896
1332.88	57.2958
1336.07	56.6569
1339.25	55.5594
1342.43	53.8371
1345.61	52.7134
1348.79	51.8799
1351.96	50.5736
1355.14	48.6483
1358.31	47.7581
1361.49	47.0253
1364.66	44.5051
1367.83	41.7964
1371	38.9973
1374.17	38.1988
1377.34	37.076
1380.5	35.3075
1383.67	32.7446
1386.83	31.4886
1390	28.7467
1393.16	26.7149
1396.32	24.1995
1399.48	23.7658
1402.64	22.5573
1405.79	21.7676
1408.95	23.0835
1412.1	23.8374
1415.26	25.0986
1418.41	25.8932
1421.56	29.3473
1424.71	33.5759
1427.86	36.6879
1431	41.0994
1434.15	44.5831
1437.29	49.5343
1440.44	53.2688
1443.58	54.8459
1446.72	57.3912
1449.86	59.6999
1453	61.0686
1456.14	59.3108
1459.27	57.1688
1462.41	53.6297
1465.54	49.688
1468.67	45.1744
1471.81	40.8423
1474.94	36.9725
1478.07	31.9359
1481.19	27.8351
1484.32	23.4751
1487.45	21.997
1490.57	18.0487
1493.69	16.0038
1496.82	14.8088
1499.94	15.1232
1503.06	15.6072
1506.17	16.0242
1509.29	15.979
1512.41	15.2246
1515.52	15.1009
1518.64	14.3316
1521.75	14.7259
1524.86	14.786
1527.97	15.5521
1531.08	16.0476
1534.19	17.7794
1537.29	20.0902
1540.4	22.6578
1543.5	24.9069
1546.61	28.6697
1549.71	32.5977
1552.81	36.7124
1555.91	39.6665
1559.01	42.9724
1562.11	46.6467
1565.2	49.212
1568.29	52.5377
1571.39	55.6751
1574.48	57.8651
1577.57	60.3447
1580.66	62.0409
1583.75	62.4875
1586.84	61.4061
1589.93	61.5424
1593.01	60.6584
1596.1	58.9024
1599.18	56.8533
1602.26	56.3418
1605.34	56.1916
1608.42	55.4723
1611.5	55.3776
1614.58	54.3587
1617.65	53.1626
1620.73	53.8522
1623.8	53.947
1626.87	55.2048
1629.95	56.6271
1633.02	57.5146
1636.09	59.3769
1639.15	62.3968
1642.22	65.1597
1645.29	67.0173
1648.35	68.7964
1651.42	69.1392
1654.48	70.2109
1657.54	70.4061
1660.6	69.9597
1663.66	68.2126
1666.72	67.1125
1669.77	63.705
1672.83	60.0718
1675.88	57.6052
1678.93	54.8535
1681.99	50.8197
1685.04	46.1973
1688.09	41.5641
1691.13	36.1923
1694.18	30.9122
1697.23	27.6164
1700.27	24.2038
1703.32	21.0679
1706.36	17.8064
1709.4	14.635
1712.44	13.6559
1715.48	13.1469
1718.52	11.7051
1721.56	10.8478
1724.59	9.65
1727.63	9.64036
1730.66	9.79522
1733.69	8.67895
1736.72	8.11344
1739.75	7.58202
1742.78	7.46343
1745.81	7.10717
1748.84	7.56685
1751.86	8.2289
1754.89	8.53265
1757.91	8.63061
1760.93	8.0963
1763.95	7.09011
1766.97	5.71561
1769.99	5.611
1773.01	4.9061
1776.03	3.95558
1779.04	3.82961
1782.06	4.30213
1785.07	4.61294
1788.08	5.92232
1791.09	6.02507
1794.1	5.49447
1797.11	5.01297
1800.12	5.20344
1803.12	4.65339
1806.13	3.63635
1809.13	2.41301
1812.14	2.42381
1815.14	2.21261
1818.14	1.90086
1821.14	1.23129
1824.14	1.70855
1827.13	2.04659
1830.13	2.15461
1833.12	0.682668
1836.12	0.221265
1839.11	0.158888
1842.1	0.157432
1845.09	0.121293
1848.08	0.00771851
1851.07	-0.0480419
1854.06	1.4051
1857.04	1.53058
1860.03	1.99666
1863.01	1.90886
1866	0.92048
1868.98	0.271353
1871.96	0.967839
1874.94	1.12477
1877.92	1.08683
1880.89	0.771518
1882.48	1.93714
1885.47	1.81856
1888.46	3.01062
1891.44	3.09662
1894.43	3.06913
1897.41	4.01629
1900.4	4.63488
1903.38	3.35652
1906.36	3.80102
1909.34	4.914
1912.32	6.46089
1915.29	6.3086
1918.27	6.48799
1921.25	7.34632
1924.22	7.15143
1927.2	6.95989
1930.17	6.13424
1933.14	6.82569
1936.11	6.4877
1939.08	5.98538
1942.05	6.87497
1945.01	7.47657
1947.98	7.8602
1950.94	7.88906
1953.91	8.56078
1956.87	8.80782
1959.83	8.19449
1962.79	7.72975
1965.75	7.16374
1968.71	6.83154
1971.67	6.26031
1974.62	5.78658
1977.58	5.98905
1980.53	6.21054
1983.48	6.60572
1986.43	6.35157
1989.38	6.74516
1992.33	7.16162
1995.28	6.28403
1998.23	5.29331
2001.18	5.69334
2004.12	7.43949
2007.06	8.46969
2010.01	8.51023
2012.95	8.96068
2015.89	10.1077
2018.83	10.3438
2021.77	11.8072
2024.71	12.2027
2027.64	12.1669
2030.58	12.6563
2033.51	12.4741
2036.45	12.8923
2039.38	13.6733
2042.31	14.8451
2045.24	15.6174
2048.17	17.0488
2051.1	17.6395
2054.02	18.3581
2056.95	17.987
2059.87	19.4244
2062.8	19.2558
2065.72	18.5241
2068.64	18.6355
2071.56	19.0737
2074.48	19.8485
2077.4	19.1371
2080.31	18.6977
2083.23	18.8272
2086.14	19.4969
2089.06	19.7387
2091.97	19.2319
2094.88	19.7033
2097.79	19.247
2100.7	19.9537
2103.61	21.5042
2106.52	22.524
2109.43	24.6281
2112.33	27.0872
2115.24	28.7186
2118.14	30.2767
2121.04	31.1191
2123.94	32.4384
2126.84	34.2299
2129.74	35.2119
2132.64	36.9969
2135.54	37.0989
2138.43	39.8805
2141.33	41.3292
2144.22	43.1798
2147.11	45.6561
2150.01	47.3807
2152.9	49.722
2155.79	52.0219
2158.67	53.1018
2161.56	54.1139
2164.45	56.6005
2167.33	57.6161
2170.22	59.5223
2173.1	60.4695
2175.98	61.6431
2178.86	62.1917
2181.74	62.7177
2184.62	62.9918
2187.5	62.2324
2190.38	60.6649
2193.25	59.6324
2196.13	58.434
2199	56.9458
2201.88	54.238
2204.75	52.9458
2207.62	51.9937
2210.49	49.8336
2213.36	47.5497
2216.22	44.7526
2219.09	43.3306
2221.96	41.4201
2224.82	39.3711
2227.68	37.331
2230.55	34.6773
2233.41	33.466
2236.27	31.8993
2239.12	30.2836
2241.98	29.4933
2244.84	28.1518
2247.7	26.7611
2250.55	25.5807
2253.41	25.2515
2256.26	24.8361
2259.11	24.9527
2261.96	25.2513
2264.81	24.8829
2267.66	24.8472
2270.51	24.6962
2273.35	25.4102
2276.2	24.6573
2279.04	23.6518
2281.89	22.5177
2284.73	21.7046
2287.57	21.5146
2290.41	21.2524
2293.25	19.9111
2296.09	19.5087
2298.93	18.6819
2301.76	17.778
2304.6	17.7798
2307.44	16.8576
2310.27	15.9459
2313.1	14.8374
2315.93	14.0877
2318.76	13.1125
2321.59	13.0453
2324.42	13.262
2327.25	15.1712
2330.07	15.3728
2332.9	14.8175
2335.72	14.5075
2338.55	14.4954
2341.37	14.2556
2344.19	13.1461
2347.01	12.4773
2349.83	12.5791
2352.65	11.8292
2355.46	12.2678
2358.28	11.8045
2361.09	12.0253
2363.91	12.3944
2366.72	12.3835
2369.53	11.9881
2372.34	11.6398
2375.15	11.5937
2377.96	11.0849
2380.77	10.2404
2383.58	9.40771
2386.38	8.91824
2389.19	9.37851
2391.99	9.45912
2394.8	9.67939
2397.6	10.2918
2400.4	10.8699
2403.2	10.374
2406	9.58492
2408.79	9.43692
2411.59	9.56066
2414.39	9.15874
2417.18	9.40758
2419.98	9.5557
2422.77	8.74429
2425.56	9.53548
2428.35	9.9753
2431.14	9.59466
2433.93	9.35666
2436.72	10.1034
2439.5	9.60519
2442.29	9.44299
2445.07	9.76565
2447.86	9.26997
2450.64	8.68761
2453.42	8.35017
2456.2	7.46398
2458.98	7.93693
2461.76	8.48727
2464.54	8.53929
2467.32	8.53913
2470.09	8.10062
2472.87	7.31259
2475.64	6.95873
2478.41	6.73031
2481.18	6.32501
2483.95	5.49103
2486.72	5.76026
2489.49	5.12611
2492.26	5.14623
2495.03	4.69968
2497.79	4.08834
2500.56	3.55335
2503.32	3.35679
2506.09	2.30125
2508.85	1.95585
2511.61	2.89402
2514.37	2.89108
2517.13	1.9152
2519.89	0.897489
2522.64	0.742705
2525.4	0.505136
2528.15	0.689438
2530.91	0.596067
2533.66	1.0163
2536.41	1.21572
2539.16	3.0509
2541.91	4.04019
2544.66	4.64534
2547.41	5.87208
2550.16	7.51194
2552.9	8.36454
2555.65	9.75772
2558.39	10.7302
2561.13	10.5824
2563.88	9.97917
2566.62	9.86554
2569.36	9.51499
2572.1	8.50799
2574.84	8.49905
2577.57	7.39399
2580.31	7.00231
2583.05	5.81174
2585.78	3.83396
2588.51	3.03586
2591.24	2.39447
2593.98	1.39374
2596.71	1.35012
2599.44	1.98823
2602.16	1.35375
2604.89	1.99461
2607.62	2.58663
2610.34	2.29254
2613.07	2.34379
2615.79	3.62101
2618.52	4.25144
2621.24	4.44039
2623.96	5.01638
2626.68	5.18684
2629.4	4.23825
2632.11	3.95716
2634.83	3.17447
2637.55	2.39283
2640.26	1.83827
2642.98	2.09451
2645.69	1.05111
2648.4	1.03503
2651.11	0.452333
2653.82	0.053459
2656.53	0.527747
2659.24	0.774414
2661.95	1.26233
2664.65	1.61943
2667.36	0.745707
2670.06	1.21747
2672.76	1.77171
2675.47	2.1091
2678.17	2.78378
2680.87	3.11214
2683.57	3.46807
2686.27	3.78706
2688.97	4.1332
2691.66	3.84774
2694.36	3.61982
2697.05	3.5988
2699.75	3.15865
2702.44	3.4412
2705.13	3.41757
2707.82	3.50896
2710.51	2.3118
2713.2	2.69664
2715.89	2.83144
2718.57	2.72668
2721.26	3.7743
2723.95	4.11416
2726.63	4.43997
2729.31	4.14954
2732	3.92733
2734.68	4.72767
2737.36	6.74244
2740.04	7.04946
2742.72	6.64755
2745.39	6.42635
2748.07	6.48532
2750.75	6.74879
2753.42	6.27102
2756.09	5.27499
2758.77	5.19012
2761.44	4.33979
2764.11	4.21877
2766.78	3.499
2769.45	3.31247
2772.12	2.62661
2774.78	1.87582
2777.45	1.79672
2780.12	2.351
2782.78	1.8302
2785.44	2.59336
2788.11	2.1331
2790.77	1.9662
2793.43	1.54229
2796.09	1.04592
2798.75	2.45759
2801.4	3.45409
2804.06	3.01555
2806.72	2.38434
2809.37	2.8651
2812.03	3.26093
2814.68	3.9626
2817.33	3.38764
2819.98	4.13165
2822.63	5.73819
2825.28	7.93386
2827.93	9.78234
2830.58	12.4584
2833.23	15.4136
2835.87	18.7495
2838.52	21.9257
2841.16	26.0449
2843.8	30.8651
2846.44	34.4894
2849.08	38.9627
2851.73	44.6214
2854.36	50.4386
2857	57.0178
2859.64	63.5869
2862.28	70.1613
2864.91	74.8325
2867.55	79.4301
2870.18	83.9862
2872.81	88.4998
2875.44	92.7438
2878.07	96.1586
2880.7	99.1534
2883.33	101.41
2885.96	103.922
2888.59	106.44
2891.21	109.891
2893.84	112.839
2896.46	116.198
2899.09	120.346
2901.71	124.149
2904.33	129.121
2906.95	136.132
2909.57	143.857
2912.19	151.967
2914.81	161.594
2917.43	170.663
2920.04	179.13
2922.66	185.675
2925.27	190.96
2927.88	194.131
2930.5	195.974
2933.11	196.253
2935.72	195.611
2938.33	193.635
2940.94	190.565
2943.54	185.125
2946.15	178.491
2948.76	171.094
2951.36	164.614
2953.97	158.73
2956.57	151.364
2959.17	143.331
2961.77	136.024
2964.37	130.231
2966.97	123.713
2969.57	117.895
2972.17	112.604
2974.77	107.408
2977.36	101.941
2979.96	96.4369
2982.55	90.5524
2985.15	83.7125
2987.74	78.1195
2990.33	72.1609
2992.92	65.2213
2995.51	58.409
2998.1	52.5925
3000.69	48.3442
3003.27	43.8251
3005.86	38.7398
3008.44	34.1786
3011.03	30.4939
3013.61	27.5608
3016.19	25.4299
3018.78	22.1108
3021.36	20.0084
3023.94	18.0774
3026.51	15.8691
3029.09	16.0713
3031.67	15.1598
3034.24	15.2451
3036.82	15.9389
3039.39	16.1231
3041.97	16.4446
3044.54	17.767
3047.11	17.9501
3049.68	19.2639
3052.25	19.9838
3054.82	20.7655
3057.39	20.3918
3059.96	20.2018
3062.52	20.8087
3065.09	20.239
3067.65	18.9264
3070.22	18.431
3072.78	17.1001
3075.34	14.2543
3077.9	12.447
3080.46	10.3945
3083.02	8.79422
3085.58	7.08751
3088.14	6.1821
3090.69	5.48054
3093.25	4.88191
3095.8	3.30838
3098.36	2.35376
3100.91	0.939518
3103.46	0.772916
3106.01	0.0287815
3108.56	-0.0826704
3111.11	-0.0992285
3113.66	0.215405
3116.21	0.574559
3118.76	0.664791
3121.3	0.443699
3123.85	0.688869
3126.39	0.306155
3128.93	0.30922
3131.48	0.897601
3134.02	0.600102
3136.56	0.3859
3139.1	0.859636
3141.64	1.61188
3144.17	1.60945
3146.71	1.3699
3149.25	-0.584907