File: data/Raman/poly_smoothed/Thy_00_07_16_1x_45s_532 nm_x100_100%_600 gr_mm_01.txt
#Acq. time (s)=	45
#Accumulations=	2
#Range (cm-¹)=	200...3150
#Windows=	2
#Auto scanning=	Off
#Autofocus=	Off
#Macrospot=	Off
#AutoExposure=	Off
#Spike filter=	Multiple accum.
#Delay time (s)=	0
#Binning=	1
#Readout mode=	Signal
#DeNoise=	Off
#ICS correction=	On
#Dark correction=	Off
#Inst. Process=	Off
#Detector Gain=	Best Dynamic Range
#Detector ADC=	20 kHz
#Detector temperature (°C)=	-69.85
#Instrument=	LabRAM HR Evol
#Detector=	Synapse
#Objective=	x100
#Grating=	600 gr/mm
#ND Filter=	100%
#Laser (nm)=	532
#Hole=	100.021
#Range=	Auto
#Laser Pol.=	No
#Raman. Pol.=	No
#Laser Pol. (°)=	-0.0007625
#Raman Pol. (°)=	89.9995
#Collection=	Microscope
#StageXY=	Marzhauser
#StageZ=	Marzhauser
#X (µm)=	9023.1
#Y (µm)=	-3084.6
#Z (µm)=	-54.6
#Full time(mm:ss)=	3:19
#Project=
#Sample=
#Site=
#Title=	Thy_00_07_16_2x_45s_532 nm_x100_100%_600 gr_mm
#Remark=
#Date=	28.06.2022 11:14
#Acquired=	28.06.2022 11:14:48
#Base:Fit=	10.08.2022 10:06:44
#Base:Fit=	10.08.2022 10:07:16
#Base:Fit=	10.08.2022 10:07:25
#Base:Fit=	10.08.2022 10:07:44
#Base:Fit=	10.08.2022 10:07:56
#Base:Sub=	10.08.2022 10:08:40
#Filter:Polynom=	16.08.2022 10:26:06
#AxisType[0]=Intens
#AxisUnit[0]=Cnt
#AxisType[1]=Spectr
#AxisUnit[1]=1/cm
200.407	66.9685
204.035	60.5563
207.665	52.3021
211.291	45.5289
214.916	40.6796
218.541	34.5333
222.163	28.9244
225.785	25.2441
229.404	22.7953
233.022	19.394
236.638	16.4291
240.255	14.4268
243.868	11.5593
247.48	10.4604
251.091	10.1737
254.702	7.93878
258.31	5.41375
261.916	3.05706
265.521	3.25924
269.125	3.19878
272.727	2.49295
276.328	2.47847
279.927	4.32268
283.525	4.51402
287.121	5.71754
290.716	5.19448
294.31	6.3037
297.9	9.45641
301.491	10.6052
305.081	11.4606
308.669	11.93
312.256	13.2275
315.839	15.4967
319.423	16.7601
323.006	16.9805
326.585	17.0421
330.165	17.4283
333.741	16.1494
337.318	16.4988
340.894	13.6922
344.466	13.8181
348.039	12.8534
351.608	13.0627
355.176	12.8622
358.745	12.4742
362.31	11.9595
365.876	10.8416
369.439	10.7479
373	8.75935
376.56	9.49671
380.12	8.73909
383.677	8.40576
387.233	6.69745
390.787	6.29097
394.34	5.8788
397.894	5.42305
401.444	5.67297
404.993	5.83101
408.54	5.55532
412.086	6.13089
415.631	6.96298
419.174	6.43883
422.716	6.77304
426.257	6.07611
429.794	5.16735
433.332	4.08524
436.868	3.46929
440.403	6.05304
443.937	9.08781
447.468	11.7404
450.999	15.2454
454.528	19.3654
458.057	22.7106
461.582	27.7945
465.107	30.3611
468.629	34.7811
472.152	37.0282
475.672	39.1947
479.192	42.0789
482.709	42.0632
486.226	43.071
489.74	44.0625
493.255	44.8052
496.767	44.2626
500.277	43.9708
503.788	41.7472
507.295	38.9498
510.801	34.9277
514.308	30.1948
517.811	24.3354
521.313	20.7932
524.814	20.3979
528.313	19.476
531.811	18.5461
535.308	16.7141
538.803	13.4115
542.297	12.7546
545.789	11.7251
549.281	12.4114
552.771	11
556.259	9.58964
559.747	8.0467
563.233	8.98274
566.717	8.97479
570.2	7.82525
573.68	8.23728
577.161	9.07839
580.64	8.97601
584.118	11.084
587.593	10.6831
591.068	11.0787
594.54	8.69929
598.013	7.52073
601.484	7.4185
604.952	7.78136
608.421	7.1089
611.886	7.86739
615.35	7.04446
618.815	7.9784
622.276	7.59979
625.738	8.55285
629.197	9.35819
632.655	11.2716
636.113	14.0212
639.568	15.6074
643.021	18.8415
646.473	20.7725
649.924	21.4892
653.376	21.6233
656.824	23.0583
660.271	23.6229
663.716	25.2354
667.161	25.1977
670.604	24.9396
674.045	23.957
677.486	24.2436
680.925	27.2451
684.361	27.8023
687.797	28.7588
691.232	28.8051
694.666	28.4411
698.099	30.2711
701.528	30.5133
704.958	30.2614
708.387	30.4653
711.814	33.0422
715.238	35.0338
718.663	36.5796
722.084	38.208
725.506	39.2898
728.925	41.6224
732.345	43.0526
735.761	45.727
739.178	48.5917
742.592	51.2027
746.006	55.3469
749.417	59.8623
752.827	61.9745
756.236	65.0359
759.645	68.8742
763.051	72.9426
766.456	74.1697
769.859	76.8429
773.261	78.2288
776.664	79.457
780.064	80.1925
783.462	79.7949
786.859	81.4366
790.255	82.2253
793.649	81.2797
797.042	81.298
800.434	80.0527
803.823	79.3771
807.212	81.1076
810.6	82.9949
813.987	85.0791
817.372	87.4666
820.754	91.3107
824.137	92.4128
827.519	96.7719
830.897	98.9652
834.276	100.078
837.654	100.773
841.029	101.256
844.404	100.954
847.776	99.153
851.149	97.7355
854.519	94.8254
857.889	91.6421
861.256	88.3238
864.622	84.5953
867.988	81.2279
871.351	77.703
874.713	74.1415
878.074	72.3636
881.435	70.5771
884.794	66.9862
888.15	67.1042
891.506	66.6628
894.861	66.8522
898.214	67.4582
901.566	68.9714
904.916	70.3194
908.266	74.86
911.614	78.078
914.961	81.4713
918.306	83.647
921.651	84.9737
924.994	84.5492
928.336	83.5691
931.674	82.5869
935.014	80.4715
938.352	76.4684
941.687	73.4865
945.022	71.391
948.357	67.2185
951.688	64.522
955.02	61.4883
958.348	56.6937
961.678	51.7962
965.004	47.3906
968.331	45.171
971.655	44.2176
974.979	42.8913
978.3	43.061
981.62	42.372
984.941	42.8002
988.259	43.8775
991.575	44.1917
994.89	44.9433
998.204	47.9392
1001.52	50.3973
1004.83	52.9165
1008.14	55.5067
1011.45	57.0169
1014.76	59.1514
1018.06	60.8334
1021.37	61.8842
1024.67	62.2382
1027.97	60.8631
1031.27	59.4225
1034.57	58.4795
1037.87	56.7881
1041.17	55.1001
1044.47	55.7853
1047.76	55.1126
1051.06	56.1722
1054.35	57.5297
1057.64	55.5228
1060.93	55.703
1064.22	54.5331
1067.5	55.4839
1070.79	56.2623
1074.08	57.8587
1077.36	60.8306
1080.64	62.0447
1083.92	64.8072
1087.2	66.036
1090.48	68.5678
1093.76	72.1094
1097.03	75.1669
1100.31	75.6214
1103.58	76.6099
1106.85	76.5707
1110.12	76.2155
1113.39	76.8563
1116.66	77.0609
1119.93	76.9277
1123.19	74.9378
1126.46	73.4887
1129.72	72.2616
1132.98	70.8115
1136.24	67.0532
1139.5	63.7262
1142.76	61.7506
1146.01	59.1874
1149.27	55.2064
1152.53	49.1565
1155.78	42.778
1159.03	35.6577
1162.28	30.3071
1165.53	25.9186
1168.78	22.3822
1172.02	20.1547
1175.27	17.4946
1178.51	14.4346
1181.76	14.3401
1185	13.3447
1188.24	12.0073
1191.48	11.9432
1194.71	11.6959
1197.95	13.7539
1201.19	15.8446
1204.42	18.2476
1207.65	20.9785
1210.88	25.1645
1214.12	28.5863
1217.35	34.5863
1220.57	37.897
1223.8	42.0562
1227.03	45.6206
1230.25	46.3338
1233.47	47.2655
1236.69	49.3484
1239.92	51.535
1243.13	54.4696
1246.35	55.6902
1249.57	55.5584
1252.78	56.2207
1256	54.0064
1259.21	53.0109
1262.42	51.4632
1265.63	49.3864
1268.84	48.0008
1272.05	47.0045
1275.26	45.9555
1278.46	47.5022
1281.67	46.6921
1284.87	45.7936
1288.07	48.6956
1291.27	51.1888
1294.47	54.0152
1297.67	56.7102
1300.87	60.2384
1304.06	65.7836
1307.26	71.5987
1310.45	77.7884
1313.64	83.9264
1316.83	89.0745
1320.02	93.5593
1323.21	97.1393
1326.4	100.122
1329.59	103.809
1332.77	103.967
1335.95	104.639
1339.14	105.412
1342.32	104.338
1345.5	102.433
1348.67	100.837
1351.85	97.9444
1355.03	95.041
1358.2	91.2992
1361.38	86.6732
1364.55	85.1099
1367.72	83.6959
1370.89	80.8776
1374.06	76.0476
1377.23	78.4407
1380.39	80.1257
1383.56	80.8843
1386.72	81.0333
1389.89	81.1653
1393.05	80.3375
1396.21	78.1306
1399.37	76.3005
1402.52	74.2057
1405.68	73.6775
1408.84	72.1405
1411.99	72.0269
1415.15	71.2463
1418.3	70.8769
1421.45	70.7343
1424.6	71.8858
1427.75	73.7501
1430.89	76.7867
1434.04	79.0061
1437.18	81.6375
1440.33	83.9594
1443.47	86.0601
1446.61	86.4409
1449.75	85.7374
1452.89	88.7903
1456.03	88.3837
1459.16	86.3901
1462.3	83.2413
1465.43	79.5692
1468.56	74.9479
1471.7	66.6419
1474.83	58.5809
1477.96	51.0471
1481.08	45.096
1484.21	39.2728
1487.34	33.0808
1490.46	29.5474
1493.58	25.4667
1496.71	21.3574
1499.83	19.0416
1502.95	18.4132
1506.07	18.0453
1509.18	18.043
1512.3	16.9418
1515.41	16.6552
1518.53	17.3754
1521.64	18.0586
1524.75	20.5252
1527.86	21.0814
1530.97	22.447
1534.08	24.7151
1537.19	26.8487
1540.29	29.3493
1543.4	30.8583
1546.5	32.0801
1549.6	34.199
1552.7	35.2993
1555.8	37.6592
1558.9	39.4923
1562	42.3335
1565.09	45.6404
1568.19	47.7378
1571.28	49.516
1574.37	51.1365
1577.47	55.3889
1580.56	57.979
1583.64	60.0879
1586.73	61.8494
1589.82	63.5672
1592.9	65.8586
1595.99	67.2712
1599.07	66.5516
1602.15	66.5071
1605.23	66.4369
1608.31	66.0938
1611.39	65.4007
1614.47	64.9674
1617.55	63.664
1620.62	61.4622
1623.7	60.3763
1626.77	58.5207
1629.84	57.3349
1632.91	57.0386
1635.98	56.4912
1639.05	56.8218
1642.11	57.8503
1645.18	58.678
1648.24	59.2263
1651.31	61.228
1654.37	61.4706
1657.43	60.3131
1660.49	60.1108
1663.55	58.2728
1666.61	56.9039
1669.66	55.6108
1672.72	53.4205
1675.77	49.9092
1678.83	47.8701
1681.88	44.658
1684.93	42.0322
1687.98	38.6061
1691.03	34.4752
1694.07	30.3988
1697.12	26.9694
1700.17	22.9408
1703.21	20.2851
1706.25	17.0509
1709.29	15.6413
1712.33	13.9299
1715.37	13.1161
1718.41	11.3274
1721.45	9.95273
1724.49	9.16813
1727.52	9.98754
1730.55	8.8192
1733.59	9.1097
1736.62	9.35742
1739.65	9.5517
1742.68	9.99528
1745.7	10.3653
1748.73	10.3299
1751.76	9.43086
1754.78	9.47189
1757.8	8.82383
1760.83	9.06712
1763.85	7.99738
1766.87	6.62609
1769.89	5.81759
1772.9	4.10883
1775.92	3.82355
1778.94	3.96936
1781.95	2.69653
1784.96	3.034
1787.97	3.03033
1790.99	2.7696
1794	4.00158
1797	3.58029
1800.01	4.79463
1803.02	4.95743
1806.02	5.2287
1809.03	4.17606
1812.03	3.90852
1815.03	3.61922
1818.03	3.61807
1821.03	3.92235
1824.03	3.56695
1827.03	3.11648
1830.02	2.44445
1833.02	2.83653
1836.01	2.99616
1839.01	2.50282
1842	2.34584
1844.99	3.29531
1847.98	4.04749
1850.97	4.2154
1853.95	4.51515
1856.94	4.73833
1859.93	5.42774
1862.91	6.10194
1865.89	5.79919
1868.87	6.7748
1871.85	6.69518
1874.83	6.88373
1877.81	5.88939
1880.79	6.28121
1882.52	6.49987
1885.51	5.73862
1888.5	6.51236
1891.49	6.85071
1894.47	7.16973
1897.46	6.39631
1900.44	5.80727
1903.42	6.08487
1906.4	6.24556
1909.38	5.50314
1912.36	5.25557
1915.34	4.11813
1918.32	3.89832
1921.29	3.50119
1924.27	1.96079
1927.24	1.2622
1930.21	1.31789
1933.18	0.579549
1936.15	0.14276
1939.12	0.504024
1942.09	1.10268
1945.06	0.954221
1948.02	1.59157
1950.99	2.74055
1953.95	3.85003
1956.91	4.75306
1959.88	5.45465
1962.84	5.8277
1965.8	6.94723
1968.75	6.72957
1971.71	8.21112
1974.67	8.1287
1977.62	9.0664
1980.58	8.70648
1983.53	8.09558
1986.48	8.64495
1989.43	8.09943
1992.38	8.29258
1995.33	7.42329
1998.27	6.28946
2001.22	7.49709
2004.16	6.25266
2007.11	5.06633
2010.05	5.54116
2012.99	4.79827
2015.93	5.19197
2018.87	4.65115
2021.81	5.35804
2024.75	6.98387
2027.69	7.63566
2030.62	7.66606
2033.56	8.24066
2036.49	8.67524
2039.42	9.76861
2042.35	10.0465
2045.28	10.5892
2048.21	11.6932
2051.14	12.0462
2054.07	11.8085
2056.99	10.9628
2059.92	10.9097
2062.84	9.69744
2065.76	8.78972
2068.68	7.84209
2071.6	7.94566
2074.52	7.08299
2077.44	5.88209
2080.36	5.5456
2083.27	5.21669
2086.19	4.83592
2089.1	4.67777
2092.02	4.57586
2094.93	5.19565
2097.84	5.01244
2100.75	5.22494
2103.66	5.66662
2106.56	6.53903
2109.47	7.22364
2112.38	7.79353
2115.28	7.32974
2118.18	7.95032
2121.09	7.72065
2123.99	7.70128
2126.89	7.93351
2129.79	7.87241
2132.68	7.99954
2135.58	7.97208
2138.48	8.41091
2141.37	8.274
2144.27	8.26867
2147.16	8.18921
2150.05	7.57752
2152.94	7.21013
2155.83	7.37296
2158.72	7.60059
2161.6	6.88849
2164.49	6.10007
2167.38	5.63376
2170.26	5.41482
2173.14	5.6008
2176.03	6.42708
2178.91	6.39787
2181.79	6.15774
2184.67	5.19485
2187.54	3.69369
2190.42	4.12714
2193.3	3.46858
2196.17	3.41335
2199.05	3.45196
2201.92	3.62288
2204.79	4.0017
2207.66	3.67676
2210.53	2.28902
2213.4	3.22145
2216.27	3.67226
2219.13	3.42287
2222	5.00359
2224.86	7.00456
2227.72	7.89254
2230.59	8.70273
2233.45	7.86345
2236.31	8.78316
2239.17	8.72789
2242.03	9.34777
2244.88	10.4408
2247.74	11.1784
2250.59	10.0595
2253.45	10.3456
2256.3	9.38472
2259.15	8.3287
2262	8.35133
2264.85	7.97608
2267.7	7.38606
2270.55	6.62932
2273.4	5.00532
2276.24	4.44548
2279.09	3.62996
2281.93	3.80918
2284.77	3.97029
2287.62	3.23778
2290.46	3.33179
2293.3	3.57064
2296.13	4.4414
2298.97	4.23515
2301.81	4.94411
2304.64	5.31781
2307.48	6.55002
2310.31	6.4549
2313.14	6.96151
2315.98	7.43772
2318.81	8.10306
2321.64	6.53463
2324.46	6.46423
2327.29	5.98268
2330.12	5.43
2332.94	5.48398
2335.77	5.97429
2338.59	4.79543
2341.41	4.3782
2344.23	3.58966
2347.05	3.1083
2349.87	2.79222
2352.69	2.10328
2355.51	1.66877
2358.32	1.76121
2361.14	0.77215
2363.95	2.7374
2366.76	4.69627
2369.58	5.19039
2372.39	5.18169
2375.2	4.66544
2378	4.55907
2380.81	4.00685
2383.62	4.70343
2386.43	4.81155
2389.23	4.25259
2392.03	3.88413
2394.84	4.895
2397.64	4.61391
2400.44	4.59254
2403.24	4.72965
2406.04	5.15993
2408.84	5.46347
2411.63	5.2788
2414.43	5.49553
2417.22	6.64324
2420.02	7.16147
2422.81	7.68019
2425.6	7.62179
2428.39	7.61039
2431.18	7.61777
2433.97	8.04746
2436.76	7.15794
2439.54	6.63871
2442.33	6.42096
2445.12	6.0035
2447.9	6.21507
2450.68	6.16209
2453.46	5.2431
2456.24	4.40143
2459.02	3.78995
2461.8	3.48431
2464.58	2.62728
2467.36	2.29145
2470.13	1.8063
2472.91	2.28602
2475.68	2.38904
2478.45	2.78401
2481.23	1.89043
2484	2.56508
2486.77	2.98835
2489.54	3.45637
2492.3	2.97608
2495.07	3.10599
2497.84	3.78278
2500.6	2.99585
2503.36	3.53054
2506.13	4.06701
2508.89	4.16219
2511.65	4.39267
2514.41	4.29317
2517.17	4.0845
2519.93	4.1552
2522.68	4.56531
2525.44	5.11192
2528.19	4.81648
2530.95	3.42037
2533.7	2.62586
2536.45	2.02848
2539.2	2.55121
2541.95	3.09903
2544.7	3.31763
2547.45	3.39255
2550.2	4.32029
2552.94	3.60324
2555.69	4.66174
2558.43	4.92852
2561.18	3.75337
2563.92	3.77142
2566.66	3.22501
2569.4	3.34041
2572.14	2.90773
2574.88	2.28042
2577.61	2.17192
2580.35	1.8314
2583.09	1.20813
2585.82	0.20083
2588.55	0.354824
2591.29	0.309062
2594.02	-0.0477611
2596.75	-0.680497
2599.48	-0.87836
2602.21	0.088621
2604.93	0.433175
2607.66	0.74132
2610.39	1.63204
2613.11	2.06239
2615.83	3.13732
2618.56	3.65173
2621.28	3.57718
2624	4.0428
2626.72	4.25051
2629.44	4.03156
2632.15	4.37475
2634.87	4.79154
2637.59	5.23554
2640.3	6.02042
2643.02	6.49349
2645.73	5.76673
2648.44	4.61214
2651.15	4.01146
2653.86	4.10348
2656.57	5.24634
2659.28	4.30028
2661.99	3.9093
2664.69	3.07893
2667.4	2.77338
2670.1	2.29177
2672.81	1.78323
2675.51	2.3992
2678.21	2.59294
2680.91	3.11479
2683.61	3.29211
2686.31	2.81166
2689	3.44984
2691.7	4.095
2694.4	5.05807
2697.09	5.47031
2699.79	7.56779
2702.48	9.21504
2705.17	10.6149
2707.86	11.3295
2710.55	12.2288
2713.24	12.807
2715.93	14.5057
2718.62	14.9642
2721.3	15.9911
2723.99	16.2826
2726.67	15.7086
2729.35	15.0447
2732.04	15.0716
2734.72	14.8282
2737.4	14.1068
2740.08	13.7458
2742.76	12.906
2745.43	12.1889
2748.11	11.5468
2750.79	11.0521
2753.46	10.757
2756.14	9.90977
2758.81	9.11861
2761.48	7.81164
2764.15	7.73085
2766.82	8.08704
2769.49	8.33696
2772.16	8.34962
2774.82	7.88759
2777.49	7.34273
2780.16	6.87782
2782.82	6.70766
2785.48	6.37964
2788.15	5.68998
2790.81	5.47516
2793.47	4.83489
2796.13	4.90608
2798.79	4.65358
2801.44	3.40692
2804.1	4.59284
2806.76	4.51537
2809.41	5.1868
2812.07	5.3906
2814.72	6.14106
2817.37	7.81312
2820.02	10.0615
2822.67	12.0631
2825.32	16.211
2827.97	20.4867
2830.62	25.5189
2833.26	31.8852
2835.91	36.2356
2838.56	41.3087
2841.2	47.4414
2843.84	55.499
2846.48	63.0595
2849.12	71.8878
2851.77	81.74
2854.4	90.9694
2857.04	101.035
2859.68	112.168
2862.32	122.63
2864.95	134.24
2867.59	145.76
2870.22	157.16
2872.85	168.302
2875.48	180.634
2878.11	191.607
2880.74	203.257
2883.37	214.343
2886	224.532
2888.63	235.818
2891.25	245.462
2893.88	255.176
2896.5	264.323
2899.13	271.757
2901.75	279.896
2904.37	287.949
2906.99	295.864
2909.61	302.526
2912.23	309.991
2914.85	316.421
2917.46	322.262
2920.08	326.512
2922.7	329.444
2925.31	331.058
2927.92	331.139
2930.54	329.444
2933.15	325.698
2935.76	320.818
2938.37	315.091
2940.98	307.125
2943.58	296.967
2946.19	286.074
2948.8	276.777
2951.4	266.221
2954.01	254.815
2956.61	243.015
2959.21	232.248
2961.81	221.106
2964.41	209.806
2967.01	200.384
2969.61	189.495
2972.21	178.83
2974.81	168.479
2977.4	158.953
2980	148.507
2982.59	137.15
2985.18	125.92
2987.78	114.826
2990.37	104.683
2992.96	93.2578
2995.55	81.423
2998.14	71.2548
3000.73	61.2377
3003.31	53.2149
3005.9	44.3041
3008.48	37.2701
3011.07	31.0939
3013.65	25.3838
3016.23	19.9825
3018.81	15.8023
3021.4	12.0023
3023.97	9.2675
3026.55	7.27293
3029.13	4.92343
3031.71	4.377
3034.28	3.293
3036.86	2.88761
3039.43	3.53765
3042.01	3.75057
3044.58	4.70404
3047.15	4.9966
3049.72	6.41923
3052.29	7.12022
3054.86	7.13486
3057.43	7.2977
3060	8.01057
3062.56	8.58339
3065.13	8.25565
3067.69	7.74785
3070.26	8.17572
3072.82	7.93861
3075.38	6.29251
3077.94	5.02851
3080.5	4.44535
3083.06	2.71287
3085.62	1.99826
3088.18	1.5632
3090.73	1.4484
3093.29	0.738136
3095.84	1.18224
3098.4	0.475433
3100.95	1.13462
3103.5	1.79671
3106.05	2.25531
3108.6	3.38413
3111.15	4.97935
3113.7	6.12082
3116.25	7.60953
3118.79	9.06804
3121.34	10.5838
3123.88	12.4741
3126.43	14.0666
3128.97	16.1064
3131.51	19.4293
3134.06	22.2549
3136.6	24.1281
3139.14	26.3505
3141.67	29.3452
3144.21	31.8495
3146.75	34.5904
3149.29	36.3581