File: data/SERS/sers_time_comparison/SERS_30D2O_1x_0_25s_532 nm_x100_10%_600 gr_mm_01.txt
#Acq. time (s)=	0.25
#Accumulations=	10
#Range (cm-¹)=	250...3150
#Windows=	2
#Auto scanning=	Off
#Autofocus=	Off
#Macrospot=	Off
#AutoExposure=	Off
#Spike filter=	Multiple accum.
#Delay time (s)=	0
#Binning=	1
#Readout mode=	Signal
#DeNoise=	Off
#ICS correction=	On
#Dark correction=	Off
#Inst. Process=	Off
#Detector Gain=	Best Dynamic Range
#Detector ADC=	20 kHz
#Detector temperature (°C)=	-70.08
#Instrument=	LabRAM HR Evol
#Detector=	Synapse
#Objective=	x100
#Grating=	600 gr/mm
#ND Filter=	10%
#Laser (nm)=	532
#Hole=	100.021
#Range=	Auto
#Laser Pol.=	No
#Raman. Pol.=	No
#Laser Pol. (°)=	90.0003
#Raman Pol. (°)=	89.9995
#Collection=	Microscope
#StageXY=	Marzhauser
#StageZ=	Marzhauser
#X (µm)=	0
#Y (µm)=	0
#Z (µm)=	454.9
#Full time(s)=	22
#Project=
#Sample=
#Site=
#Title=	SERS_30D2O_10x_0_25s_532 nm_x100_10%_600 gr_mm
#Remark=
#Date=	12.04.2022 10:35
#Acquired=	12.04.2022 10:35:49
#AxisType[0]=Intens
#AxisUnit[0]=Cnt
#AxisType[1]=Spectr
#AxisUnit[1]=1/cm
250.913	60.1189
254.522	60.0691
258.13	53.7432
261.738	51.3109
265.343	52.5264
268.947	45.1971
272.549	50.5121
276.15	47.2477
279.751	45.885
283.349	45.9374
286.946	44.7673
290.541	43.3623
294.135	41.2651
297.727	42.5429
301.318	40.2471
304.908	42.4809
308.496	42.4338
312.083	41.9193
315.666	44.8846
319.25	42.8803
322.833	42.9224
326.414	41.0654
329.994	39.6815
333.57	35.6486
337.148	40.6793
340.723	40.8954
344.298	40.9796
347.868	43.3399
351.44	41.1727
355.008	37.0944
358.577	42.0625
362.144	39.3865
365.708	39.4404
369.273	40.6696
372.834	41.5275
376.394	42.2591
379.955	39.5806
383.512	39.6361
387.07	40.066
390.624	43.9208
394.177	41.8016
397.73	40.7483
401.281	39.2188
404.83	42.373
408.377	37.7682
411.923	40.3215
415.47	41.5905
419.013	42.1699
422.555	40.6438
426.096	42.9832
429.635	41.7903
433.173	39.4246
436.71	38.5907
440.245	43.3806
443.779	41.5706
447.311	39.9704
450.842	39.7695
454.372	40.5076
457.899	42.7595
461.426	40.2412
464.951	42.5178
468.476	39.3793
471.997	41.5042
475.518	43.0447
479.038	39.8952
482.555	38.7102
486.073	41.2699
489.589	40.1383
493.102	44.5167
496.615	43.886
500.126	45.8295
503.636	43.4248
507.144	38.7614
510.652	42.6555
514.157	43.8201
517.662	43.6675
521.164	42.3235
524.665	44.026
528.166	42.6769
531.664	39.8075
535.161	37.168
538.656	41.4055
542.15	44.442
545.645	40.137
549.136	38.754
552.626	42.8184
556.115	43.2922
559.602	40.3159
563.089	38.7407
566.573	38.6742
570.057	42.0644
573.539	43.295
577.019	43.5251
580.499	40.3358
583.977	41.9725
587.453	41.2968
590.927	40.4866
594.401	43.3485
597.873	42.2996
601.345	41.1308
604.813	39.4841
608.281	49.3032
611.749	46.4804
615.213	43.1041
618.678	41.9134
622.139	44.2557
625.601	40.4101
629.062	46.7455
632.52	43.0759
635.976	40.9095
639.433	44.6525
642.886	40.1349
646.34	43.0042
649.791	43.7358
653.241	45.328
656.691	37.8781
660.138	39.4299
663.584	38.3383
667.028	37.7809
670.473	40.4127
673.915	37.6947
677.356	37.7542
680.795	36.669
684.232	44.5336
687.669	41.8989
691.104	40.5099
694.538	41.874
697.971	39.9986
701.402	42.3614
704.832	40.9129
708.261	41.1797
711.688	42.6987
715.112	38.8368
718.537	42.5163
721.961	44.2497
725.383	37.9075
728.802	41.0018
732.221	41.02
735.64	42.9564
739.055	41.8452
742.47	39.7392
745.883	39.0094
749.296	40.2137
752.706	39.8633
756.117	43.697
759.524	44.2955
762.932	40.289
766.337	39.2051
769.742	45.2163
773.144	39.4406
776.545	40.666
779.945	40.7776
783.345	39.8868
786.742	39.0939
790.138	41.4256
793.532	41.4525
796.925	41.0215
800.319	41.7393
803.71	43.1515
807.099	43.6618
810.487	42.0218
813.874	42.5005
817.26	40.8476
820.644	40.7641
824.027	40.9097
827.407	40.9638
830.787	38.8295
834.166	41.4135
837.544	45.3582
840.921	43.0409
844.294	39.1366
847.668	43.8441
851.041	42.887
854.411	41.5071
857.781	43.2684
861.15	39.0447
864.516	43.9143
867.882	39.8681
871.245	44.044
874.609	42.465
877.97	41.5615
881.33	36.0275
884.69	42.8985
888.047	41.8472
891.404	43.7029
894.759	42.2685
898.112	40.0355
901.464	44.1837
904.817	45.1732
908.166	41.2554
911.514	40.0372
914.861	43.0529
918.207	38.8554
921.551	39.1
924.894	45.8757
928.236	42.1806
931.577	40.3848
934.916	39.1471
938.254	46.4069
941.591	43.6488
944.927	41.3408
948.261	45.9689
951.593	46.2629
954.924	37.2943
958.255	42.369
961.585	43.5182
964.911	43.8966
968.238	41.2487
971.564	42.7707
974.886	43.8532
978.209	45.1834
981.529	46.526
984.85	41.6498
988.168	42.6071
991.486	44.094
994.801	43.9169
998.115	43.4101
1001.43	37.7252
1004.74	41.6156
1008.05	42.5277
1011.36	41.5772
1014.67	40.964
1017.98	41.1241
1021.28	43.4819
1024.59	40.281
1027.89	46.4859
1031.19	45.3597
1034.49	44.9723
1037.79	46.5227
1041.09	40.7783
1044.39	44.8449
1047.68	42.313
1050.97	44.0434
1054.27	43.6157
1057.56	39.8184
1060.85	47.1004
1064.14	45.0198
1067.42	46.2907
1070.71	44.6109
1074	42.9305
1077.28	42.0263
1080.56	48.1887
1083.84	43.7255
1087.12	47.5821
1090.4	41.1158
1093.68	44.4772
1096.96	44.2705
1100.23	42.902
1103.51	40.1681
1106.78	42.5108
1110.05	44.5257
1113.32	42.6459
1116.59	43.0019
1119.85	40.5715
1123.12	42.9766
1126.39	45.3938
1129.65	46.1115
1132.91	43.5247
1136.17	47.1345
1139.43	43.2472
1142.69	43.2967
1145.95	42.6006
1149.2	49.1632
1152.46	45.9317
1155.71	45.0395
1158.96	43.1889
1162.21	44.0104
1165.46	42.2959
1168.71	46.9556
1171.96	47.4392
1175.2	47.2527
1178.45	48.6441
1181.69	44.3305
1184.93	46.9049
1188.17	46.5031
1191.41	41.7517
1194.65	50.8558
1197.89	47.3456
1201.13	51.9272
1204.36	47.9888
1207.59	45.8694
1210.83	45.1129
1214.06	49.851
1217.29	49.3335
1220.52	44.4371
1223.74	48.4797
1226.97	47.6733
1230.19	47.9285
1233.42	47.3793
1236.64	46.7494
1239.86	48.7219
1243.08	50.3896
1246.3	49.6648
1249.51	44.8863
1252.73	46.8261
1255.94	49.0873
1259.16	46.4052
1262.37	49.6373
1265.58	47.1763
1268.79	43.4555
1272	47.594
1275.21	47.0483
1278.41	47.2108
1281.62	45.3952
1284.82	45.9619
1288.02	47.9891
1291.22	46.7244
1294.42	49.3839
1297.62	46.8565
1300.82	43.892
1304.02	45.3394
1307.21	48.7186
1310.41	47.4665
1313.6	47.4529
1316.79	48.5788
1319.98	49.9144
1323.17	48.6855
1326.36	47.8367
1329.54	47.5889
1332.73	49.1871
1335.91	47.2883
1339.09	48.0252
1342.27	48.3294
1345.45	48.7981
1348.63	51.9704
1351.81	49.3764
1354.99	50.825
1358.16	51.2818
1361.34	48.4274
1364.51	48.1548
1367.68	49.7781
1370.85	46.9434
1374.02	53.7864
1377.19	51.1908
1380.36	51.0731
1383.53	49.8364
1386.69	50.668
1389.85	48.0262
1393.01	48.8755
1396.18	49.6319
1399.33	53.0497
1402.49	52.0873
1405.65	50.0379
1408.81	52.8484
1411.96	47.6679
1415.11	47.2198
1418.27	47.8415
1421.42	53.6856
1424.57	51.0894
1427.72	49.9954
1430.87	52.0466
1434.01	46.7957
1437.16	48.1282
1440.3	51.9286
1443.44	48.573
1446.58	47.0927
1449.73	49.4489
1452.86	49.4551
1456	49.0743
1459.14	48.5827
1462.27	51.3054
1465.41	45.3436
1468.54	51.5592
1471.68	51.6981
1474.8	47.0538
1477.93	56.3406
1481.06	51.8042
1484.19	47.4642
1487.32	45.9595
1490.44	50.4977
1493.57	49.2173
1496.69	51.9978
1499.81	51.2595
1502.93	47.442
1506.05	48.4958
1509.17	48.7628
1512.28	49.2956
1515.4	49.7209
1518.51	54.7575
1521.63	49.0683
1524.74	51.703
1527.85	52.6855
1530.96	56.0238
1534.07	56.0402
1537.17	50.0332
1540.28	54.155
1543.38	51.3939
1546.49	51.4571
1549.59	50.8606
1552.69	51.7672
1555.79	56.3328
1558.89	55.5161
1561.99	56.9821
1565.08	59.5948
1568.18	56.6135
1571.27	58.8496
1574.37	57.8126
1577.46	53.8825
1580.55	61.0707
1583.64	56.5136
1586.73	58.0439
1589.81	54.4349
1592.9	59.2379
1595.98	52.7994
1599.07	55.2667
1602.15	56.5331
1605.23	54.1378
1608.31	57.7243
1611.39	54.5885
1614.47	60.2351
1617.55	58.078
1620.62	53.3289
1623.7	58.5366
1626.77	59.6248
1629.84	59.1869
1632.91	59.9396
1635.98	57.6177
1639.05	55.5064
1642.12	56.1936
1645.18	49.6921
1648.25	51.9229
1651.31	43.6702
1654.38	49.3623
1657.44	45.4234
1660.5	46.8454
1663.56	47.3134
1666.62	45.4629
1669.67	44.6506
1672.73	44.419
1675.78	42.724
1678.84	43.4095
1681.89	43.6157
1684.94	41.7044
1687.99	42.8276
1691.04	40.5681
1694.09	45.5398
1697.13	40.814
1700.18	40.655
1703.22	41.3072
1706.27	42.2201
1709.31	46.3031
1712.35	44.1176
1715.39	43.5715
1718.43	43.2972
1721.46	39.956
1724.5	41.6804
1727.54	38.8344
1730.57	40.2368
1733.6	41.1773
1736.63	37.3255
1739.67	37.4973
1742.7	39.0222
1745.72	39.4135
1748.75	40.8021
1751.78	38.4272
1754.8	38.1702
1757.82	37.7268
1760.85	37.8316
1763.87	38.3166
1766.89	36.5148
1769.91	36.4021
1772.93	37.5213
1775.94	35.9834
1778.96	36.7372
1781.97	38.8842
1784.99	37.7945
1788	37.8074
1791.01	37.1991
1794.02	37.6935
1797.03	35.7106
1800.04	37.4636
1803.05	35.67
1806.05	39.0317
1809.06	36.0964
1812.06	36.6698
1815.06	34.9217
1818.06	34.5594
1821.06	35.9142
1824.06	35.9516
1827.06	37.6718
1830.06	35.2979
1833.05	36.7263
1836.05	34.5734
1839.04	37.5655
1842.03	33.9973
1845.02	35.5308
1848.01	35.6632
2001	33.5417
2003.95	33.1684
2006.89	33.2205
2009.83	33.2007
2012.78	35.2085
2015.72	35.5275
2018.66	32.3868
2021.6	32.5187
2024.53	32.9896
2027.47	35.1528
2030.41	31.9693
2033.34	32.6577
2036.28	32.8444
2039.21	30.8401
2042.14	35.6424
2045.07	32.8046
2048	32.4984
2050.93	28.8161
2053.85	31.3517
2056.78	33.6955
2059.71	32.9075
2062.63	34.3973
2065.55	32.618
2068.47	34.4694
2071.39	36.6636
2074.31	32.627
2077.23	33.5525
2080.15	32.9567
2083.07	32.69
2085.98	35.1049
2088.9	34.1452
2091.81	32.3442
2094.72	32.0546
2097.63	34.1882
2100.54	34.7181
2103.45	33.0777
2106.36	34.1273
2109.27	32.1057
2112.17	32.7471
2115.08	35.6946
2117.98	30.7284
2120.88	33.1747
2123.79	31.4142
2126.69	32.732
2129.59	34.8658
2132.48	33.2534
2135.38	32.6347
2138.28	32.4482
2141.17	31.047
2144.07	35.2021
2146.96	31.4202
2149.85	31.2698
2152.74	31.6867
2155.63	33.0041
2158.52	32.2508
2161.41	32.5904
2164.3	28.724
2167.18	33.5799
2170.07	31.2016
2172.95	30.4583
2175.83	34.4369
2178.71	33.1766
2181.59	31.0142
2184.48	34.3474
2187.35	31.5285
2190.23	31.1212
2193.11	31.6257
2195.98	30.3663
2198.85	29.8329
2201.73	31.3627
2204.6	31.8164
2207.47	30.7905
2210.34	31.5863
2213.21	31.0462
2216.08	33.0636
2218.95	32.6985
2221.81	34.2408
2224.68	30.0912
2227.54	31.6858
2230.4	32.4362
2233.26	30.5597
2236.12	34.3367
2238.98	32.8204
2241.84	30.9261
2244.7	31.3327
2247.56	34.4233
2250.41	33.978
2253.27	29.7678
2256.12	31.013
2258.97	29.3637
2261.82	30.2664
2264.68	27.9418
2267.52	29.9202
2270.37	33.7629
2273.22	31.8205
2276.07	30.2024
2278.91	28.0957
2281.75	32.7552
2284.6	31.2988
2287.44	32.0477
2290.28	31.8229
2293.12	33.4006
2295.96	30.9711
2298.8	28.4548
2301.63	28.4776
2304.47	31.4581
2307.3	32.3901
2310.14	28.877
2312.97	29.056
2315.8	33.7675
2318.63	30.5859
2321.46	32.015
2324.29	32.9262
2327.12	30.9194
2329.95	30.222
2332.77	31.8396
2335.6	32.2326
2338.42	27.8525
2341.24	31.0212
2344.06	33.3545
2346.89	31.9985
2349.7	30.9733
2352.52	29.1246
2355.34	28.9821
2358.16	32.4136
2360.97	30.7181
2363.79	28.3007
2366.6	30.7422
2369.41	32.9396
2372.22	30.3952
2375.03	29.6405
2377.84	30.2503
2380.65	30.8389
2383.46	31.0053
2386.26	29.6483
2389.07	31.8957
2391.87	30.6498
2394.68	35.1471
2397.48	30.8273
2400.28	31.366
2403.08	32.1469
2405.88	29.5886
2408.68	29.8768
2411.48	28.4957
2414.27	30.1346
2417.07	30.3663
2419.86	30.5319
2422.65	27.5289
2425.45	29.3544
2428.24	31.4249
2431.03	32.7965
2433.82	29.3297
2436.61	32.597
2439.39	31.9515
2442.18	29.1493
2444.96	28.7257
2447.75	30.9949
2450.53	30.1723
2453.31	30.1489
2456.1	30.2157
2458.87	28.3101
2461.65	27.664
2464.43	28.9838
2467.21	28.0868
2469.99	28.6884
2472.76	29.4406
2475.54	30.5743
2478.31	26.202
2481.08	30.8613
2483.85	27.9897
2486.62	30.5085
2489.39	31.5207
2492.16	28.4828
2494.93	26.2473
2497.69	29.4559
2500.46	27.4004
2503.22	28.817
2505.99	29.2919
2508.75	28.0696
2511.51	28.6986
2514.27	32.0926
2517.03	30.135
2519.79	29.9469
2522.54	29.5274
2525.3	30.6227
2528.06	28.5154
2530.81	30.3789
2533.56	28.6917
2536.32	27.5472
2539.07	29.7378
2541.82	29.8666
2544.57	29.6948
2547.32	30.1454
2550.06	28.6349
2552.81	28.5604
2555.56	28.2451
2558.3	28.3016
2561.04	27.8304
2563.79	27.2159
2566.53	30.8506
2569.27	30.5471
2572.01	26.985
2574.75	28.8047
2577.49	29.5641
2580.22	29.5628
2582.96	28.9497
2585.69	27.6515
2588.43	29.3104
2591.16	29.9851
2593.89	28.6842
2596.62	28.6582
2599.35	29.6801
2602.08	28.8125
2604.81	29.0868
2607.53	29.5897
2610.26	31.5873
2612.99	27.8462
2615.71	29.8862
2618.43	27.8765
2621.16	25.2108
2623.88	28.3834
2626.6	26.1042
2629.32	27.2526
2632.03	27.7257
2634.75	28.1966
2637.47	26.591
2640.18	29.1341
2642.9	29.4568
2645.61	29.5595
2648.32	27.2999
2651.03	29.9637
2653.74	31.2919
2656.46	26.4736
2659.16	27.5352
2661.87	28.6004
2664.58	29.6564
2667.28	29.9706
2669.99	30.0638
2672.69	28.1295
2675.4	29.9823
2678.1	26.9093
2680.8	26.5328
2683.5	30.1592
2686.2	26.6923
2688.89	28.8086
2691.59	28.3637
2694.29	26.5937
2696.98	29.3873
2699.68	29.2978
2702.37	27.2045
2705.06	28.6023
2707.75	27.0298
2710.44	28.427
2713.13	27.4976
2715.82	27.2204
2718.51	29.1233
2721.2	29.1313
2723.88	28.9144
2726.57	28.4733
2729.25	28.6101
2731.93	29.3269
2734.61	28.7354
2737.3	30.8374
2739.98	28.0672
2742.66	27.2548
2745.33	30.2117
2748.01	27.7872
2750.69	29.7907
2753.36	27.5191
2756.03	26.8464
2758.71	27.2626
2761.38	28.6241
2764.05	28.5444
2766.72	25.4267
2769.39	28.807
2772.06	26.1687
2774.73	29.2197
2777.4	26.8619
2780.06	28.4703
2782.73	25.4862
2785.39	29.6047
2788.05	27.4169
2790.72	28.0327
2793.38	28.801
2796.04	27.2835
2798.7	26.7608
2801.35	28.8012
2804.01	26.6304
2806.67	25.3129
2809.32	29.3215
2811.98	27.8547
2814.63	27.3276
2817.28	26.7489
2819.94	27.5959
2822.59	28.0836
2825.24	26.0133
2827.88	26.8479
2830.53	28.8922
2833.18	28.0373
2835.83	29.5141
2838.47	28.4366
2841.11	31.3161
2843.76	27.4145
2846.4	31.1547
2849.04	30.5892
2851.68	28.1829
2854.32	29.1626
2856.96	27.667
2859.6	29.2088
2862.23	30.1122
2864.87	29.1763
2867.51	26.478
2870.14	31.4694
2872.77	29.3419
2875.41	29.955
2878.04	27.1779
2880.67	28.9715
2883.3	30.9804
2885.92	28.9263
2888.55	29.9621
2891.18	29.7267
2893.8	30.6758
2896.43	29.3172
2899.05	32.0282
2901.68	30.83
2904.3	30.0545
2906.92	31.7301
2909.54	29.427
2912.16	30.9767
2914.78	30.9096
2917.4	30.0557
2920.01	31.1506
2922.63	30.9917
2925.24	32.3136
2927.86	32.1742
2930.47	32.5208
2933.08	33.7708
2935.69	29.9883
2938.3	32.3567
2940.91	29.8369
2943.52	32.8453
2946.13	28.5274
2948.73	32.1165
2951.34	31.6377
2953.94	32.5396
2956.55	29.3075
2959.15	25.8838
2961.75	30.8191
2964.35	29.4589
2966.95	32.1574
2969.55	26.7589
2972.15	31.0597
2974.75	27.6254
2977.34	27.5606
2979.94	32.2641
2982.53	29.7724
2985.13	29.3952
2987.72	29.3153
2990.31	29.8086
2992.9	26.3611
2995.49	29.1518
2998.08	27.4378
3000.67	29.4438
3003.26	29.141
3005.84	29.6792
3008.43	28.7386
3011.01	27.9273
3013.6	28.0882
3016.18	26.5111
3018.76	26.2677
3021.34	29.43
3023.92	28.3387
3026.5	26.4782
3029.08	28.6386
3031.66	27.0826
3034.23	26.7148
3036.81	27.5118
3039.39	26.8369
3041.96	27.1037
3044.53	28.8037
3047.1	27.7846
3049.68	26.4577
3052.25	27.3354
3054.81	25.7567
3057.38	25.9379
3059.95	25.9029
3062.52	25.9388
3065.08	26.5344
3067.65	25.923
3070.21	25.2473
3072.78	25.5797
3075.34	27.1173
3077.9	26.2025
3080.46	26.3185
3083.02	24.9609
3085.58	26.6638
3088.14	27.6819
3090.69	27.467
3093.25	27.1801
3095.8	27.6409
3098.36	21.8661
3100.91	24.9664
3103.46	28.5361
3106.02	27.0328
3108.57	25.2027
3111.12	24.3995
3113.66	27.0587
3116.21	26.872
3118.76	27.3492
3121.31	26.9266
3123.85	27.1028
3126.4	26.8044
3128.94	26.9849
3131.48	27.3028
3134.02	25.7244
3136.57	23.8695
3139.11	25.243
3141.65	25.3292
3144.18	27.2284
3146.72	25.6418
3149.26	24.8692