File: data/SERS/sers_time_comparison/SERS_30D2O_1x_1s_532 nm_x100_10%_600 gr_mm_01.txt
#Acq. time (s)=	1
#Accumulations=	5
#Range (cm-¹)=	250...3150
#Windows=	2
#Auto scanning=	Off
#Autofocus=	Off
#Macrospot=	Off
#AutoExposure=	Off
#Spike filter=	Multiple accum.
#Delay time (s)=	0
#Binning=	1
#Readout mode=	Signal
#DeNoise=	Off
#ICS correction=	On
#Dark correction=	Off
#Inst. Process=	Off
#Detector Gain=	Best Dynamic Range
#Detector ADC=	20 kHz
#Detector temperature (°C)=	-70.08
#Instrument=	LabRAM HR Evol
#Detector=	Synapse
#Objective=	x100
#Grating=	600 gr/mm
#ND Filter=	10%
#Laser (nm)=	532
#Hole=	100.021
#Range=	Auto
#Laser Pol.=	No
#Raman. Pol.=	No
#Laser Pol. (°)=	90.0003
#Raman Pol. (°)=	89.9995
#Collection=	Microscope
#StageXY=	Marzhauser
#StageZ=	Marzhauser
#X (µm)=	0
#Y (µm)=	0
#Z (µm)=	454.9
#Full time(s)=	26
#Project=
#Sample=
#Site=
#Title=	SERS_30D2O_5x_1s_532 nm_x100_10%_600 gr_mm
#Remark=
#Date=	12.04.2022 10:35
#Acquired=	12.04.2022 10:35:09
#AxisType[0]=Intens
#AxisUnit[0]=Cnt
#AxisType[1]=Spectr
#AxisUnit[1]=1/cm
250.913	211.05
254.522	210.875
258.13	189.788
261.738	189.435
265.343	172.94
268.947	173.557
272.549	169.8
276.15	161.088
279.751	145.242
283.349	147.192
286.946	152.575
290.541	139.34
294.135	132.676
297.727	146.271
301.318	133.819
304.908	134.513
308.496	134.632
312.083	136.654
315.666	131.261
319.25	125.961
322.833	124.475
326.414	131.344
329.994	133.387
333.57	124.62
337.148	131.639
340.723	133.986
344.298	130.376
347.868	125.453
351.44	125.935
355.008	119.424
358.577	130.299
362.144	122.354
365.708	122.954
369.273	120.586
372.834	125.647
376.394	128.017
379.955	132.524
383.512	132.052
387.07	135.884
390.624	127.887
394.177	128.135
397.73	125.504
401.281	127.634
404.83	128.955
408.377	128.925
411.923	124.132
415.47	121.213
419.013	127.577
422.555	118.119
426.096	122.634
429.635	117.346
433.173	123.15
436.71	121.05
440.245	128.693
443.779	124.897
447.311	138.668
450.842	132.125
454.372	133.495
457.899	131.462
461.426	125.523
464.951	122.815
468.476	134.889
471.997	128.243
475.518	128.637
479.038	129.459
482.555	123.158
486.073	129.228
489.589	122.827
493.102	134.876
496.615	131.98
500.126	121.152
503.636	134.568
507.144	135.269
510.652	125.571
514.157	129.821
517.662	129.503
521.164	131.516
524.665	127.692
528.166	128.098
531.664	129.028
535.161	137.289
538.656	144.141
542.15	150.377
545.645	135.646
549.136	147.079
552.626	150.67
556.115	139.72
559.602	144.652
563.089	130.452
566.573	134.938
570.057	133.266
573.539	135.028
577.019	134.306
580.499	129.526
583.977	142.595
587.453	128.205
590.927	136.523
594.401	131.355
597.873	123.082
601.345	131.875
604.813	138.535
608.281	134.264
611.749	133.607
615.213	139.178
618.678	121.824
622.139	122.474
625.601	133.366
629.062	129.135
632.52	128.874
635.976	129.957
639.433	135.586
642.886	135.932
646.34	135.439
649.791	137.34
653.241	134.581
656.691	143.009
660.138	132.539
663.584	136.358
667.028	136.977
670.473	131.119
673.915	132.811
677.356	131.262
680.795	132.567
684.232	142.338
687.669	131.809
691.104	137.281
694.538	134.426
697.971	131.265
701.402	135.292
704.832	132.541
708.261	141.382
711.688	127.249
715.112	124.979
718.537	136.061
721.961	132.508
725.383	132.296
728.802	129.774
732.221	129.026
735.64	128.525
739.055	139.211
742.47	134.704
745.883	133.566
749.296	134.018
752.706	129.98
756.117	127.525
759.524	131.98
762.932	150.46
766.337	137.973
769.742	136.566
773.144	137.351
776.545	131.24
779.945	135.612
783.345	133.165
786.742	154.098
790.138	154.249
793.532	145.361
796.925	132.426
800.319	154.545
803.71	140.004
807.099	142.171
810.487	133.928
813.874	146.839
817.26	154.406
820.644	153.409
824.027	155.446
827.407	142.767
830.787	144.263
834.166	131.353
837.544	145.331
840.921	130.139
844.294	137.496
847.668	137.59
851.041	133.761
854.411	143.382
857.781	134.325
861.15	144.16
864.516	138.977
867.882	135.26
871.245	135.829
874.609	136.134
877.97	135.166
881.33	133.43
884.69	135.469
888.047	142.772
891.404	146.941
894.759	146.978
898.112	145.441
901.464	139.828
904.817	136.225
908.166	134.153
911.514	139.887
914.861	146.629
918.207	147.366
921.551	137.654
924.894	146.166
928.236	138.358
931.577	141.293
934.916	140.025
938.254	135.552
941.591	135.349
944.927	137.909
948.261	147.623
951.593	142.348
954.924	142.039
958.255	145.823
961.585	140.057
964.911	143.235
968.238	138.081
971.564	139.792
974.886	136.786
978.209	138.586
981.529	150.629
984.85	155.642
988.168	150.586
991.486	142.236
994.801	156.736
998.115	153.097
1001.43	148.711
1004.74	143.324
1008.05	160.425
1011.36	158.003
1014.67	155.855
1017.98	144.872
1021.28	150.92
1024.59	138.822
1027.89	139.049
1031.19	153.251
1034.49	140.349
1037.79	146.527
1041.09	138.483
1044.39	145.429
1047.68	138.534
1050.97	143.45
1054.27	147.188
1057.56	143.838
1060.85	150.735
1064.14	151.963
1067.42	151.666
1070.71	152.537
1074	155.594
1077.28	161.869
1080.56	158.691
1083.84	160.393
1087.12	155.425
1090.4	151.326
1093.68	146.444
1096.96	149.103
1100.23	151.82
1103.51	151.727
1106.78	154.606
1110.05	162.792
1113.32	157.105
1116.59	151.843
1119.85	163.707
1123.12	153.684
1126.39	149.025
1129.65	149.704
1132.91	147.044
1136.17	159.766
1139.43	158.002
1142.69	156.423
1145.95	157.008
1149.2	159.796
1152.46	159.734
1155.71	160.374
1158.96	158.851
1162.21	160.961
1165.46	161.927
1168.71	159.53
1171.96	156.564
1175.2	162.336
1178.45	170.677
1181.69	174.03
1184.93	179.076
1188.17	180.255
1191.41	187.463
1194.65	202.09
1197.89	200.615
1201.13	194.33
1204.36	192.473
1207.59	188.419
1210.83	186.266
1214.06	184.009
1217.29	174.824
1220.52	174.244
1223.74	180.23
1226.97	175.114
1230.19	167.54
1233.42	165.395
1236.64	169.602
1239.86	175.499
1243.08	179.086
1246.3	179.604
1249.51	169.816
1252.73	175.369
1255.94	178.402
1259.16	174.06
1262.37	169.767
1265.58	172.93
1268.79	175.121
1272	169.784
1275.21	169.515
1278.41	166.158
1281.62	181.397
1284.82	181.492
1288.02	179.313
1291.22	176.726
1294.42	177.622
1297.62	171.704
1300.82	182.397
1304.02	184.64
1307.21	179.66
1310.41	169.378
1313.6	174.576
1316.79	171.77
1319.98	180.242
1323.17	168.714
1326.36	178.377
1329.54	184.767
1332.73	186.9
1335.91	187.123
1339.09	186.703
1342.27	185.279
1345.45	187.126
1348.63	196.406
1351.81	184.66
1354.99	187.916
1358.16	183.781
1361.34	184.311
1364.51	191.514
1367.68	190.648
1370.85	187.848
1374.02	187.827
1377.19	182.927
1380.36	191.203
1383.53	183.503
1386.69	190.277
1389.85	197.937
1393.01	187.568
1396.18	182.588
1399.33	187.38
1402.49	180.075
1405.65	171.891
1408.81	167.327
1411.96	164.131
1415.11	177.779
1418.27	174.498
1421.42	182.096
1424.57	182.253
1427.72	182.933
1430.87	180.943
1434.01	170.696
1437.16	191.618
1440.3	184.485
1443.44	189.576
1446.58	191.38
1449.73	199.39
1452.86	208.763
1456	199.133
1459.14	192.994
1462.27	202.012
1465.41	187.685
1468.54	197.434
1471.68	189.345
1474.8	203.84
1477.93	195.2
1481.06	200.234
1484.19	196.219
1487.32	197.687
1490.44	191.133
1493.57	199.167
1496.69	194.321
1499.81	195.381
1502.93	199.779
1506.05	200.302
1509.17	204.48
1512.28	214.411
1515.4	217.771
1518.51	215.117
1521.63	213.167
1524.74	222.37
1527.85	213.24
1530.96	229.533
1534.07	215.524
1537.17	214.844
1540.28	237.348
1543.38	252.787
1546.49	259.273
1549.59	272.255
1552.69	284.783
1555.79	299.049
1558.89	282.828
1561.99	265.358
1565.08	235.199
1568.18	230.865
1571.27	223.769
1574.37	212.869
1577.46	208.271
1580.55	200.762
1583.64	207.387
1586.73	210.922
1589.81	199.319
1592.9	204.732
1595.98	210.765
1599.07	213.672
1602.15	206.29
1605.23	206.077
1608.31	199.207
1611.39	201.049
1614.47	205.279
1617.55	213.26
1620.62	219.201
1623.7	211.762
1626.77	207.07
1629.84	202.503
1632.91	200.391
1635.98	189.695
1639.05	184.531
1642.12	184.617
1645.18	177.308
1648.25	171.216
1651.31	168.711
1654.38	170.455
1657.44	162.855
1660.5	164.388
1663.56	161.052
1666.62	158.734
1669.67	157.311
1672.73	148.927
1675.78	159.842
1678.84	151.039
1681.89	155.634
1684.94	149.048
1687.99	157.755
1691.04	150.811
1694.09	156.026
1697.13	148.682
1700.18	144.415
1703.22	143.821
1706.27	150.158
1709.31	146.24
1712.35	139.483
1715.39	149.456
1718.43	143.738
1721.46	143.315
1724.5	138.669
1727.54	142.405
1730.57	142.543
1733.6	134.965
1736.63	138.618
1739.67	144.209
1742.7	136.743
1745.72	126.578
1748.75	136.56
1751.78	143.673
1754.8	138.866
1757.82	137.846
1760.85	129.882
1763.87	137.777
1766.89	133.752
1769.91	134.127
1772.93	131.086
1775.94	129.183
1778.96	139.161
1781.97	129.124
1784.99	134.924
1788	138.867
1791.01	133.102
1794.02	128.213
1797.03	131.008
1800.04	132.76
1803.05	135.069
1806.05	130.841
1809.06	131.696
1812.06	133.041
1815.06	134.04
1818.06	130.972
1821.06	133.965
1824.06	135.635
1827.06	130.218
1830.06	129.894
1833.05	129.982
1836.05	133.92
1839.04	131.89
1842.03	129.508
1845.02	127.411
1848.01	122.134
2001	121.77
2003.95	125.215
2006.89	119.002
2009.83	124.016
2012.78	122.239
2015.72	122.528
2018.66	129.202
2021.6	115.806
2024.53	121.137
2027.47	119.347
2030.41	112.158
2033.34	130.128
2036.28	117.134
2039.21	119.228
2042.14	124.914
2045.07	121.177
2048	117.281
2050.93	121.71
2053.85	120.189
2056.78	133.943
2059.71	118.068
2062.63	120.6
2065.55	118.255
2068.47	123.528
2071.39	122.382
2074.31	124.451
2077.23	122.715
2080.15	121.715
2083.07	119.361
2085.98	125.3
2088.9	118.149
2091.81	117.799
2094.72	118.198
2097.63	123.661
2100.54	117.976
2103.45	115.509
2106.36	116.297
2109.27	116.572
2112.17	117.202
2115.08	119.061
2117.98	120.868
2120.88	115.448
2123.79	118.336
2126.69	123.684
2129.59	119.291
2132.48	120.615
2135.38	118.58
2138.28	121.821
2141.17	115.298
2144.07	114.411
2146.96	115.582
2149.85	115.609
2152.74	121.928
2155.63	108.449
2158.52	119.761
2161.41	111.56
2164.3	114.625
2167.18	109.703
2170.07	118.388
2172.95	117.631
2175.83	114.934
2178.71	112.054
2181.59	111.272
2184.48	116.693
2187.35	112.391
2190.23	112.206
2193.11	115.379
2195.98	109.879
2198.85	118.143
2201.73	110.08
2204.6	114.373
2207.47	115.348
2210.34	111.661
2213.21	112.404
2216.08	113.879
2218.95	114.655
2221.81	111.761
2224.68	118.107
2227.54	113.074
2230.4	109.471
2233.26	122.996
2236.12	107.458
2238.98	110.581
2241.84	103.883
2244.7	114.492
2247.56	101.039
2250.41	113.542
2253.27	107.628
2256.12	111.787
2258.97	115.127
2261.82	107.652
2264.68	110.113
2267.52	109.458
2270.37	109.309
2273.22	116.097
2276.07	114.459
2278.91	102.742
2281.75	106.607
2284.6	116.347
2287.44	111.044
2290.28	108.88
2293.12	105.806
2295.96	113.223
2298.8	113.095
2301.63	101.353
2304.47	111.389
2307.3	111.277
2310.14	110.029
2312.97	108.021
2315.8	111.397
2318.63	110.178
2321.46	107.091
2324.29	108.001
2327.12	101.384
2329.95	111.789
2332.77	104.803
2335.6	108.228
2338.42	111.632
2341.24	105.925
2344.06	101.495
2346.89	107.219
2349.7	113.298
2352.52	102.969
2355.34	106.021
2358.16	98.4269
2360.97	99.0847
2363.79	98.4635
2366.6	101.48
2369.41	107.959
2372.22	102.152
2375.03	101.656
2377.84	106.936
2380.65	102.199
2383.46	104.081
2386.26	96.2305
2389.07	99.752
2391.87	91.137
2394.68	102.27
2397.48	101.796
2400.28	104.209
2403.08	103.062
2405.88	100.65
2408.68	101.589
2411.48	102.153
2414.27	101.503
2417.07	100.562
2419.86	98.597
2422.65	98.2339
2425.45	103.03
2428.24	101.787
2431.03	101.833
2433.82	100.995
2436.61	106.185
2439.39	104.87
2442.18	103.687
2444.96	95.5292
2447.75	100.392
2450.53	103.466
2453.31	89.8245
2456.1	99.1875
2458.87	97.3523
2461.65	99.9422
2464.43	96.45
2467.21	98.4523
2469.99	101.156
2472.76	98.6934
2475.54	98.8578
2478.31	96.8827
2481.08	99.8574
2483.85	102.818
2486.62	93.4244
2489.39	104.015
2492.16	96.1773
2494.93	92.2598
2497.69	97.4714
2500.46	98.6805
2503.22	94.2941
2505.99	100.286
2508.75	100.703
2511.51	99.0649
2514.27	102.294
2517.03	99.0157
2519.79	97.3183
2522.54	97.1602
2525.3	97.6526
2528.06	93.6803
2530.81	95.9196
2533.56	95.3239
2536.32	97.3276
2539.07	97.5973
2541.82	98.3427
2544.57	96.8786
2547.32	93.2497
2550.06	96.8264
2552.81	98.8503
2555.56	93.4872
2558.3	95.4377
2561.04	103.534
2563.79	95.6317
2566.53	92.8661
2569.27	96.9261
2572.01	91.9503
2574.75	92.7755
2577.49	93.6028
2580.22	93.9093
2582.96	92.4925
2585.69	96.5224
2588.43	97.6566
2591.16	90.6123
2593.89	100.083
2596.62	91.6149
2599.35	94.0135
2602.08	98.4478
2604.81	103.073
2607.53	88.1936
2610.26	89.575
2612.99	90.2191
2615.71	90.9939
2618.43	94.1322
2621.16	91.0694
2623.88	88.2083
2626.6	90.7234
2629.32	91.2075
2632.03	90.6766
2634.75	93.6516
2637.47	89.9473
2640.18	91.9169
2642.9	91.2324
2645.61	91.5532
2648.32	90.8619
2651.03	94.935
2653.74	96.1709
2656.46	87.5483
2659.16	90.3561
2661.87	89.397
2664.58	88.2528
2667.28	88.3914
2669.99	92.78
2672.69	93.2551
2675.4	87.5538
2678.1	94.7805
2680.8	91.1113
2683.5	90.1076
2686.2	96.3288
2688.89	91.77
2691.59	87.4626
2694.29	92.2282
2696.98	94.6918
2699.68	90.3681
2702.37	87.1016
2705.06	89.4252
2707.75	94.3711
2710.44	96.6947
2713.13	88.7098
2715.82	92.3253
2718.51	94.9569
2721.2	89.5518
2723.88	89.1988
2726.57	91.6098
2729.25	90.4039
2731.93	90.5015
2734.61	90.6029
2737.3	93.0041
2739.98	90.9869
2742.66	90.2585
2745.33	89.173
2748.01	91.8253
2750.69	85.8263
2753.36	88
2756.03	90.3424
2758.71	93.1793
2761.38	88.7062
2764.05	89.4655
2766.72	85.993
2769.39	91.756
2772.06	93.7056
2774.73	87.003
2777.4	91.3293
2780.06	90.3304
2782.73	91.1262
2785.39	83.8575
2788.05	86.7619
2790.72	82.2924
2793.38	93.1404
2796.04	86.4605
2798.7	90.6892
2801.35	86.8662
2804.01	90.2549
2806.67	82.5667
2809.32	89.104
2811.98	82.691
2814.63	83.0393
2817.28	85.5215
2819.94	90.5823
2822.59	85.8999
2825.24	88.5242
2827.88	86.0512
2830.53	86.4702
2833.18	91.6767
2835.83	94.3211
2838.47	85.6406
2841.11	90.002
2843.76	83.0877
2846.4	92.2625
2849.04	86.9842
2851.68	89.9633
2854.32	91.6495
2856.96	96.9811
2859.6	91.0297
2862.23	88.8871
2864.87	88.1612
2867.51	93.6224
2870.14	92.5914
2872.77	96.0057
2875.41	99.7059
2878.04	88.4763
2880.67	97.1829
2883.3	90.8914
2885.92	90.8014
2888.55	97.8187
2891.18	93.9148
2893.8	96.6136
2896.43	100.264
2899.05	97.9683
2901.68	100.111
2904.3	100.374
2906.92	96.7152
2909.54	102.369
2912.16	103.165
2914.78	98.1064
2917.4	99.6022
2920.01	100.116
2922.63	99.0762
2925.24	99.9692
2927.86	104.659
2930.47	101.788
2933.08	104.09
2935.69	101.042
2938.3	103.659
2940.91	98.7399
2943.52	95.4209
2946.13	95.4457
2948.73	95.9618
2951.34	96.2833
2953.94	90.5557
2956.55	94.2641
2959.15	94.1004
2961.75	93.2405
2964.35	95.0924
2966.95	93.8973
2969.55	93.5994
2972.15	93.7668
2974.75	89.5084
2977.34	94.5679
2979.94	87.8426
2982.53	86.6125
2985.13	89.0285
2987.72	97.6607
2990.31	87.5176
2992.9	84.9431
2995.49	86.1123
2998.08	88.6675
3000.67	81.7586
3003.26	87.9631
3005.84	82.8182
3008.43	87.5697
3011.01	82.6796
3013.6	83.9023
3016.18	86.2309
3018.76	83.8851
3021.34	85.6096
3023.92	86.9769
3026.5	79.5753
3029.08	80.1488
3031.66	79.5357
3034.23	82.5356
3036.81	80.0749
3039.39	79.7079
3041.96	76.6439
3044.53	75.7434
3047.1	78.7521
3049.68	78.3176
3052.25	76.4142
3054.81	82.9519
3057.38	73.4837
3059.95	84.6756
3062.52	78.256
3065.08	83.8298
3067.65	74.4711
3070.21	80.8812
3072.78	86.0259
3075.34	76.8852
3077.9	81.331
3080.46	82.6062
3083.02	82.4204
3085.58	74.3233
3088.14	81.0115
3090.69	76.0589
3093.25	80.5565
3095.8	79.87
3098.36	73.083
3100.91	78.0251
3103.46	76.4087
3106.02	73.5924
3108.57	73.0951
3111.12	78.8836
3113.66	77.8488
3116.21	77.7206
3118.76	77.5456
3121.31	72.5831
3123.85	77.0401
3126.4	72.961
3128.94	76.0553
3131.48	80.9782
3134.02	68.7079
3136.57	76.3131
3139.11	73.5587
3141.65	78.3596
3144.18	73.4806
3146.72	74.3657
3149.26	75.721