File: data/SERS/sers_time_comparison/SERS_30D2O_1x_0_5s_532 nm_x100_10%_600 gr_mm_01.txt
#Acq. time (s)=	0.5
#Accumulations=	10
#Range (cm-¹)=	250...3150
#Windows=	2
#Auto scanning=	Off
#Autofocus=	Off
#Macrospot=	Off
#AutoExposure=	Off
#Spike filter=	Multiple accum.
#Delay time (s)=	0
#Binning=	1
#Readout mode=	Signal
#DeNoise=	Off
#ICS correction=	On
#Dark correction=	Off
#Inst. Process=	Off
#Detector Gain=	Best Dynamic Range
#Detector ADC=	20 kHz
#Detector temperature (°C)=	-70.08
#Instrument=	LabRAM HR Evol
#Detector=	Synapse
#Objective=	x100
#Grating=	600 gr/mm
#ND Filter=	10%
#Laser (nm)=	532
#Hole=	100.021
#Range=	Auto
#Laser Pol.=	No
#Raman. Pol.=	No
#Laser Pol. (°)=	90.0003
#Raman Pol. (°)=	89.9995
#Collection=	Microscope
#StageXY=	Marzhauser
#StageZ=	Marzhauser
#X (µm)=	0
#Y (µm)=	0
#Z (µm)=	454.9
#Full time(s)=	30
#Project=
#Sample=
#Site=
#Title=	SERS_30D2O_10x_0_5s_532 nm_x100_10%_600 gr_mm
#Remark=
#Date=	12.04.2022 10:33
#Acquired=	12.04.2022 10:33:59
#AxisType[0]=Intens
#AxisUnit[0]=Cnt
#AxisType[1]=Spectr
#AxisUnit[1]=1/cm
250.913	131.948
254.522	131.838
258.13	117.126
261.738	116.955
265.343	110.233
268.947	107.629
272.549	103.315
276.15	100.642
279.751	99.4778
283.349	94.0395
286.946	90.4947
290.541	95.948
294.135	94.7304
297.727	89.2685
301.318	86.585
304.908	89.4962
308.496	89.2777
312.083	93.0084
315.666	96.5554
319.25	85.5224
322.833	84.6526
326.414	85.7122
329.994	83.0682
333.57	90.6766
337.148	88.4177
340.723	84.8998
344.298	87.5744
347.868	88.3512
351.44	87.3578
355.008	82.5379
358.577	85.6741
362.144	88.1734
365.708	87.7906
369.273	81.6949
372.834	83.6466
376.394	93.1352
379.955	89.1741
383.512	84.0944
387.07	85.8892
390.624	85.3754
394.177	88.4174
397.73	86.3113
401.281	82.446
404.83	89.4895
408.377	87.0006
411.923	87.3225
415.47	84.6106
419.013	89.203
422.555	87.0047
426.096	87.2545
429.635	90.533
433.173	84.5408
436.71	85.1335
440.245	90.167
443.779	86.6923
447.311	80.709
450.842	86.5293
454.372	80.5609
457.899	89.7553
461.426	82.1859
464.951	86.7689
468.476	86.5663
471.997	87.5974
475.518	88.7332
479.038	83.6304
482.555	91.4218
486.073	85.0439
489.589	86.5452
493.102	89.7353
496.615	91.8984
500.126	89.6084
503.636	85.7646
507.144	92.4563
510.652	89.4605
514.157	85.2324
517.662	91.4273
521.164	90.5298
524.665	88.3273
528.166	84.4884
531.664	82.0619
535.161	89.7943
538.656	90.9191
542.15	88.388
545.645	89.4574
549.136	87.5153
552.626	93.8051
556.115	89.8059
559.602	87.5673
563.089	96.0554
566.573	90.4167
570.057	88.381
573.539	86.6282
577.019	84.5947
580.499	90.0711
583.977	87.9808
587.453	88.042
590.927	85.4177
594.401	86.5711
597.873	87.4951
601.345	86.9134
604.813	92.0406
608.281	85.2874
611.749	88.9805
615.213	89.025
618.678	84.8416
622.139	89.2149
625.601	86.8107
629.062	87.9833
632.52	89.6895
635.976	87.2142
639.433	86.0582
642.886	82.4169
646.34	86.3665
649.791	87.6355
653.241	87.7814
656.691	87.9307
660.138	90.2876
663.584	86.2073
667.028	86.0429
670.473	86.3078
673.915	90.8671
677.356	88.4029
680.795	85.2497
684.232	84.5643
687.669	87.1526
691.104	85.6726
694.538	86.3586
697.971	83.099
701.402	85.2101
704.832	82.8063
708.261	88.6481
711.688	84.1558
715.112	83.7834
718.537	84.5514
721.961	78.2623
725.383	85.524
728.802	83.7883
732.221	85.7831
735.64	86.0685
739.055	85.1232
742.47	81.6204
745.883	84.0183
749.296	85.5567
752.706	84.8866
756.117	85.7223
759.524	86.4943
762.932	84.1448
766.337	82.9121
769.742	84.7913
773.144	83.446
776.545	83.3274
779.945	82.7895
783.345	79.6797
786.742	86.6126
790.138	84.8565
793.532	85.2823
796.925	82.3121
800.319	90.8733
803.71	87.9904
807.099	87.246
810.487	85.0114
813.874	88.0206
817.26	90.451
820.644	86.9568
824.027	83.9315
827.407	92.648
830.787	84.7347
834.166	89.8247
837.544	83.8007
840.921	87.5638
844.294	79.7851
847.668	88.6704
851.041	84.096
854.411	88.0864
857.781	84.6725
861.15	91.5577
864.516	88.1527
867.882	86.1772
871.245	86.4401
874.609	83.9882
877.97	82.3236
881.33	82.5727
884.69	86.7514
888.047	86.1481
891.404	86.8498
894.759	86.72
898.112	84.0861
901.464	83.5637
904.817	86.0438
908.166	82.8313
911.514	83.3273
914.861	86.8385
918.207	86.6824
921.551	86.7519
924.894	85.8589
928.236	83.3645
931.577	84.5499
934.916	85.1936
938.254	84.857
941.591	85.3247
944.927	81.8399
948.261	88.8085
951.593	90.2035
954.924	85.3111
958.255	86.7803
961.585	84.4673
964.911	87.125
968.238	89.3804
971.564	85.1555
974.886	83.4828
978.209	85.0648
981.529	85.672
984.85	88.8991
988.168	86.4195
991.486	85.1187
994.801	84.3637
998.115	85.3757
1001.43	87.4791
1004.74	87.1446
1008.05	90.6489
1011.36	88.4496
1014.67	84.6259
1017.98	87.2776
1021.28	82.8417
1024.59	90.2432
1027.89	84.9847
1031.19	87.3557
1034.49	87.2752
1037.79	82.6856
1041.09	87.1316
1044.39	85.3014
1047.68	79.5129
1050.97	84.3065
1054.27	87.9324
1057.56	86.8881
1060.85	85.7189
1064.14	89.8517
1067.42	87.4282
1070.71	85.3027
1074	88.4908
1077.28	85.8477
1080.56	86.0605
1083.84	88.0078
1087.12	85.7885
1090.4	92.0576
1093.68	88.5462
1096.96	79.6608
1100.23	84.4026
1103.51	88.0064
1106.78	84.4421
1110.05	88.5051
1113.32	92.3011
1116.59	93.2578
1119.85	89.2839
1123.12	88.5585
1126.39	94.068
1129.65	88.8004
1132.91	89.0039
1136.17	86.531
1139.43	88.9417
1142.69	90.463
1145.95	90.7032
1149.2	86.8159
1152.46	91.04
1155.71	95.8887
1158.96	94.346
1162.21	91.3419
1165.46	96.3423
1168.71	90.7039
1171.96	97.5516
1175.2	97.9579
1178.45	94.4222
1181.69	93.2434
1184.93	94.7282
1188.17	87.3184
1191.41	93.3488
1194.65	97.0931
1197.89	92.9628
1201.13	94.6537
1204.36	94.445
1207.59	96.2906
1210.83	94.9136
1214.06	98.5884
1217.29	95.5183
1220.52	95.9507
1223.74	90.806
1226.97	94.1055
1230.19	94.4473
1233.42	95.2434
1236.64	93.2906
1239.86	100.365
1243.08	95.9709
1246.3	98.4809
1249.51	97.8527
1252.73	90.49
1255.94	95.0435
1259.16	96.5344
1262.37	98.1604
1265.58	92.9519
1268.79	94.9699
1272	95.2951
1275.21	96.6207
1278.41	95.4263
1281.62	95.5575
1284.82	95.1737
1288.02	99.365
1291.22	102.24
1294.42	101.805
1297.62	100.914
1300.82	97.079
1304.02	101.855
1307.21	104.633
1310.41	97.0391
1313.6	100.635
1316.79	103.534
1319.98	101.245
1323.17	102.392
1326.36	100.023
1329.54	95.5194
1332.73	100.38
1335.91	101.768
1339.09	99.6459
1342.27	98.8849
1345.45	99.0651
1348.63	99.8485
1351.81	103.411
1354.99	101.645
1358.16	102.594
1361.34	100.117
1364.51	102.5
1367.68	102.694
1370.85	107.408
1374.02	107.295
1377.19	103.03
1380.36	107.004
1383.53	105.459
1386.69	100.501
1389.85	98.9288
1393.01	99.075
1396.18	104.39
1399.33	102.838
1402.49	100.858
1405.65	100.758
1408.81	103.057
1411.96	99.9419
1415.11	100.462
1418.27	102.331
1421.42	96.6263
1424.57	102.791
1427.72	106.243
1430.87	100.044
1434.01	102.858
1437.16	103.785
1440.3	102.376
1443.44	105.719
1446.58	107.212
1449.73	104.682
1452.86	105.117
1456	108.812
1459.14	101.464
1462.27	100.154
1465.41	100.46
1468.54	112.922
1471.68	102.146
1474.8	95.9329
1477.93	104.541
1481.06	102.07
1484.19	102.535
1487.32	102.789
1490.44	110.722
1493.57	109.462
1496.69	112.714
1499.81	107.482
1502.93	114.337
1506.05	112.491
1509.17	104.834
1512.28	106.131
1515.4	105.386
1518.51	106.2
1521.63	106.076
1524.74	105.368
1527.85	109.29
1530.96	113.073
1534.07	110.227
1537.17	118.016
1540.28	116.848
1543.38	111.266
1546.49	109.738
1549.59	110.739
1552.69	107.723
1555.79	110.172
1558.89	106.156
1561.99	111.734
1565.08	109.617
1568.18	115.065
1571.27	116.207
1574.37	113.043
1577.46	113.147
1580.55	121.578
1583.64	124.259
1586.73	125.107
1589.81	119.321
1592.9	120.532
1595.98	112.364
1599.07	120.045
1602.15	119.698
1605.23	111.364
1608.31	113.113
1611.39	108.663
1614.47	109.583
1617.55	107.671
1620.62	109.084
1623.7	115.976
1626.77	107.895
1629.84	114.548
1632.91	102.374
1635.98	107.588
1639.05	103.69
1642.12	103.34
1645.18	105.278
1648.25	101.231
1651.31	102.219
1654.38	97.1304
1657.44	94.6653
1660.5	96.1593
1663.56	95.291
1666.62	95.1455
1669.67	94.8514
1672.73	89.9108
1675.78	87.6618
1678.84	87.5078
1681.89	86.6781
1684.94	87.9492
1687.99	87.3028
1691.04	90.8817
1694.09	90.158
1697.13	82.9438
1700.18	88.5098
1703.22	85.4781
1706.27	85.8944
1709.31	84.1202
1712.35	85.7992
1715.39	86.7534
1718.43	83.3653
1721.46	77.4615
1724.5	83.3947
1727.54	85.2152
1730.57	83.3761
1733.6	85.6551
1736.63	81.5861
1739.67	80.7178
1742.7	80.9486
1745.72	82.8435
1748.75	77.1754
1751.78	81.9271
1754.8	79.2292
1757.82	79.2794
1760.85	82.6399
1763.87	80.4518
1766.89	81.8484
1769.91	80.7684
1772.93	81.8882
1775.94	76.3078
1778.96	82.6653
1781.97	82.2057
1784.99	80.7005
1788	82.5419
1791.01	82.3083
1794.02	83.577
1797.03	85.4682
1800.04	78.4842
1803.05	81.9259
1806.05	81.0045
1809.06	81.6385
1812.06	78.4747
1815.06	79.4195
1818.06	82.2304
1821.06	81.9653
1824.06	76.9496
1827.06	80.1532
1830.06	82.7843
1833.05	81.2766
1836.05	80.7678
1839.04	81.5365
1842.03	82.0559
1845.02	79.9337
1848.01	78.2231
2001	79.4858
2003.95	75.0702
2006.89	75.7243
2009.83	77.5837
2012.78	77.8608
2015.72	79.0522
2018.66	78.9527
2021.6	77.1547
2024.53	71.845
2027.47	76.7234
2030.41	80.6417
2033.34	77.7996
2036.28	76.1324
2039.21	75.0369
2042.14	75.5352
2045.07	74.7932
2048	76.3468
2050.93	74.4391
2053.85	74.7605
2056.78	75.4488
2059.71	74.4234
2062.63	77.7012
2065.55	75.7061
2068.47	77.3576
2071.39	78.0117
2074.31	73.1059
2077.23	75.9353
2080.15	78.4988
2083.07	78.8542
2085.98	78.5958
2088.9	77.4763
2091.81	75.9305
2094.72	74.3839
2097.63	76.1762
2100.54	77.3582
2103.45	74.9513
2106.36	77.3426
2109.27	74.846
2112.17	72.7558
2115.08	78.6907
2117.98	75.5229
2120.88	77.295
2123.79	76.1401
2126.69	70.5335
2129.59	75.9255
2132.48	75.8888
2135.38	70.887
2138.28	73.0394
2141.17	71.6938
2144.07	75.347
2146.96	77.2747
2149.85	76.536
2152.74	75.6002
2155.63	77.1235
2158.52	75.9137
2161.41	73.5818
2164.3	73.7057
2167.18	74.1897
2170.07	74.8973
2172.95	75.7106
2175.83	73.6518
2178.71	72.6762
2181.59	75.3023
2184.48	78.0319
2187.35	70.951
2190.23	72.6873
2193.11	73.5002
2195.98	70.9456
2198.85	72.1622
2201.73	72.9268
2204.6	72.2112
2207.47	70.0349
2210.34	74.0674
2213.21	72.6903
2216.08	72.5487
2218.95	71.6956
2221.81	70.4573
2224.68	71.2616
2227.54	72.2608
2230.4	76.7421
2233.26	73.1715
2236.12	72.3331
2238.98	68.3632
2241.84	79.545
2244.7	73.5577
2247.56	72.4467
2250.41	74.9391
2253.27	72.2438
2256.12	71.5918
2258.97	69.2251
2261.82	74.2496
2264.68	70.8044
2267.52	73.6078
2270.37	71.5042
2273.22	77.1166
2276.07	74.7509
2278.91	71.7362
2281.75	70.5112
2284.6	69.3642
2287.44	72.3853
2290.28	71.7473
2293.12	67.5198
2295.96	71.5511
2298.8	68.7076
2301.63	69.8812
2304.47	72.6246
2307.3	72.8251
2310.14	69.8853
2312.97	71.9472
2315.8	70.0708
2318.63	71.1803
2321.46	73.1931
2324.29	67.2288
2327.12	74.393
2329.95	69.9007
2332.77	74.1626
2335.6	72.442
2338.42	70.3829
2341.24	70.5099
2344.06	69.2239
2346.89	68.1921
2349.7	69.4536
2352.52	70.5253
2355.34	69.6882
2358.16	63.7171
2360.97	68.1615
2363.79	72.0196
2366.6	69.1527
2369.41	68.8155
2372.22	68.5191
2375.03	67.2086
2377.84	68.3839
2380.65	67.1017
2383.46	68.5827
2386.26	65.8116
2389.07	69.7745
2391.87	69.7831
2394.68	68.9508
2397.48	64.9654
2400.28	65.689
2403.08	65.7867
2405.88	70.3181
2408.68	71.2452
2411.48	66.2164
2414.27	65.0982
2417.07	65.3697
2419.86	69.7886
2422.65	68.6653
2425.45	66.1076
2428.24	68.5561
2431.03	64.3728
2433.82	65.1905
2436.61	67.487
2439.39	70.2125
2442.18	67.6641
2444.96	67.2491
2447.75	66.9878
2450.53	69.3395
2453.31	69.4885
2456.1	68.0825
2458.87	67.3211
2461.65	66.9391
2464.43	66.6117
2467.21	68.0097
2469.99	65.1433
2472.76	72.1152
2475.54	69.6049
2478.31	67.2457
2481.08	68.974
2483.85	63.5704
2486.62	64.2541
2489.39	68.3305
2492.16	65.3835
2494.93	66.0491
2497.69	65.5124
2500.46	61.3526
2503.22	66.3726
2505.99	67.2611
2508.75	63.6772
2511.51	63.2658
2514.27	64.7946
2517.03	63.7458
2519.79	66.0023
2522.54	66.5677
2525.3	67.335
2528.06	68.6998
2530.81	66.5229
2533.56	63.7188
2536.32	67.7772
2539.07	64.6021
2541.82	65.8068
2544.57	65.3482
2547.32	67.2779
2550.06	68.4771
2552.81	69.4361
2555.56	64.747
2558.3	65.3503
2561.04	69.6732
2563.79	67.7261
2566.53	67.6134
2569.27	64.1709
2572.01	66.7912
2574.75	65.3978
2577.49	67.7199
2580.22	68.0646
2582.96	62.6346
2585.69	67.8853
2588.43	67.4539
2591.16	64.2984
2593.89	68.0985
2596.62	63.157
2599.35	66.742
2602.08	65.4876
2604.81	68.2554
2607.53	65.5977
2610.26	65.4042
2612.99	66.5217
2615.71	67.9079
2618.43	63.1536
2621.16	62.0292
2623.88	65.8535
2626.6	68.0268
2629.32	66.0139
2632.03	64.5202
2634.75	64.2168
2637.47	64.5804
2640.18	61.2459
2642.9	68.7882
2645.61	66.43
2648.32	66.0547
2651.03	65.2134
2653.74	65.5385
2656.46	65.5927
2659.16	66.0505
2661.87	66.6693
2664.58	64.8604
2667.28	66.1656
2669.99	60.9143
2672.69	62.306
2675.4	65.8199
2678.1	65.3599
2680.8	66.8143
2683.5	68.6723
2686.2	65.2702
2688.89	66.5039
2691.59	63.4735
2694.29	64.3833
2696.98	65.8627
2699.68	64.8479
2702.37	67.0788
2705.06	64.3499
2707.75	68.5133
2710.44	64.539
2713.13	67.0163
2715.82	68.2583
2718.51	67.024
2721.2	65.4852
2723.88	66.2583
2726.57	66.8708
2729.25	65.2166
2731.93	63.9219
2734.61	68.6671
2737.3	68.7638
2739.98	66.0971
2742.66	64.0702
2745.33	68.7779
2748.01	65.9146
2750.69	67.843
2753.36	69.0527
2756.03	64.3294
2758.71	60.4866
2761.38	67.8026
2764.05	67.0292
2766.72	68.1367
2769.39	61.9821
2772.06	63.8062
2774.73	64.9404
2777.4	65.7795
2780.06	63.1131
2782.73	66.637
2785.39	65.8515
2788.05	68.5823
2790.72	64.0407
2793.38	59.4606
2796.04	68.7477
2798.7	63.3701
2801.35	64.1203
2804.01	64.4336
2806.67	68.93
2809.32	66.1438
2811.98	63.8633
2814.63	66.8717
2817.28	65.7462
2819.94	64.2891
2822.59	68.5586
2825.24	62.9592
2827.88	63.3128
2830.53	63.0476
2833.18	66.8953
2835.83	66.1324
2838.47	62.8059
2841.11	66.1913
2843.76	65.7002
2846.4	71.592
2849.04	66.4726
2851.68	63.7472
2854.32	67.8606
2856.96	64.9723
2859.6	67.5938
2862.23	68.6553
2864.87	67.5179
2867.51	71.1754
2870.14	70.7535
2872.77	68.222
2875.41	70.6016
2878.04	68.0909
2880.67	70.2847
2883.3	68.0018
2885.92	67.5734
2888.55	72.2699
2891.18	72.5921
2893.8	70.654
2896.43	74.8872
2899.05	72.6394
2901.68	72.2352
2904.3	70.5099
2906.92	75.0175
2909.54	77.4498
2912.16	77.8694
2914.78	77.6377
2917.4	78.5474
2920.01	79.9161
2922.63	78.2237
2925.24	79.0155
2927.86	82.9706
2930.47	76.5014
2933.08	75.3315
2935.69	79.5402
2938.3	78.2316
2940.91	77.5599
2943.52	74.046
2946.13	73.0809
2948.73	74.2288
2951.34	69.8869
2953.94	70.7453
2956.55	72.1517
2959.15	68.2899
2961.75	71.9922
2964.35	69.972
2966.95	74.3747
2969.55	72.0642
2972.15	66.4377
2974.75	68.9757
2977.34	69.1025
2979.94	67.9119
2982.53	70.7607
2985.13	69.5357
2987.72	72.149
2990.31	71.2794
2992.9	66.2481
2995.49	68.9039
2998.08	67.3185
3000.67	69.8059
3003.26	63.8986
3005.84	66.6824
3008.43	67.48
3011.01	66.0062
3013.6	64.3089
3016.18	66.8756
3018.76	67.5102
3021.34	63.0002
3023.92	65.5486
3026.5	68.5427
3029.08	66.7689
3031.66	62.9097
3034.23	65.5086
3036.81	65.944
3039.39	64.3138
3041.96	63.7272
3044.53	61.6303
3047.1	65.4707
3049.68	65.8349
3052.25	63.1173
3054.81	64.9703
3057.38	60.7143
3059.95	63.9912
3062.52	63.3927
3065.08	62.8406
3067.65	62.6758
3070.21	65.7863
3072.78	62.3343
3075.34	65.0184
3077.9	65.3041
3080.46	62.0292
3083.02	63.9634
3085.58	62.3927
3088.14	64.8058
3090.69	65.2193
3093.25	65.6882
3095.8	63.7208
3098.36	63.2441
3100.91	66.6183
3103.46	62.4716
3106.02	63.5531
3108.57	63.176
3111.12	60.2625
3113.66	61.3663
3116.21	61.0421
3118.76	62.9171
3121.31	61.2165
3123.85	60.2324
3126.4	60.5342
3128.94	60.9167
3131.48	60.832
3134.02	62.2879
3136.57	64.5221
3139.11	58.9074
3141.65	60.9608
3144.18	60.3243
3146.72	61.4479
3149.26	59.0381